# Goxel 0.15.1
# One line per voxel
# X Y Z RRGGBB
2 1 2 ffffff
3 1 2 ffffff
2 2 2 ffffff
3 2 2 ffffff
0 0 3 ffffff
1 0 3 ffffff
2 0 3 ffffff
3 0 3 ffffff
4 0 3 ffffff
5 0 3 ffffff
6 0 3 ffffff
7 0 3 ffffff
8 0 3 ffffff
9 0 3 ffffff
10 0 3 ffffff
11 0 3 ffffff
12 0 3 ffffff
13 0 3 ffffff
14 0 3 ffffff
15 0 3 ffffff
0 1 3 ffffff
1 1 3 ffffff
2 1 3 ffffff
3 1 3 ffffff
4 1 3 ffffff
5 1 3 ffffff
6 1 3 ffffff
7 1 3 ffffff
8 1 3 ffffff
9 1 3 ffffff
10 1 3 ffffff
11 1 3 ffffff
12 1 3 ffffff
13 1 3 ffffff
14 1 3 ffffff
15 1 3 ffffff
0 2 3 ffffff
1 2 3 ffffff
2 2 3 ffffff
3 2 3 ffffff
4 2 3 ffffff
5 2 3 ffffff
6 2 3 ffffff
7 2 3 ffffff
8 2 3 ffffff
9 2 3 ffffff
10 2 3 ffffff
11 2 3 ffffff
12 2 3 ffffff
13 2 3 ffffff
14 2 3 ffffff
15 2 3 ffffff
0 3 3 ffffff
1 3 3 ffffff
2 3 3 ffffff
3 3 3 ffffff
4 3 3 ffffff
5 3 3 ffffff
6 3 3 ffffff
7 3 3 ffffff
8 3 3 ffffff
9 3 3 ffffff
10 3 3 ffffff
11 3 3 ffffff
12 3 3 ffffff
13 3 3 ffffff
14 3 3 ffffff
15 3 3 ffffff
0 4 3 ffffff
1 4 3 ffffff
2 4 3 ffffff
3 4 3 ffffff
4 4 3 ffffff
5 4 3 ffffff
6 4 3 ffffff
7 4 3 ffffff
8 4 3 ffffff
9 4 3 ffffff
10 4 3 ffffff
11 4 3 ffffff
12 4 3 ffffff
13 4 3 ffffff
14 4 3 ffffff
15 4 3 ffffff
0 5 3 ffffff
1 5 3 ffffff
2 5 3 ffffff
3 5 3 ffffff
4 5 3 ffffff
5 5 3 ffffff
6 5 3 ffffff
7 5 3 ffffff
8 5 3 ffffff
9 5 3 ffffff
10 5 3 ffffff
11 5 3 ffffff
12 5 3 ffffff
13 5 3 ffffff
14 5 3 ffffff
15 5 3 ffffff
0 6 3 ffffff
1 6 3 ffffff
2 6 3 ffffff
3 6 3 ffffff
4 6 3 ffffff
5 6 3 ffffff
6 6 3 ffffff
7 6 3 ffffff
8 6 3 ffffff
9 6 3 ffffff
10 6 3 ffffff
11 6 3 ffffff
12 6 3 ffffff
13 6 3 ffffff
14 6 3 ffffff
15 6 3 ffffff
0 7 3 ffffff
1 7 3 ffffff
2 7 3 ffffff
3 7 3 ffffff
4 7 3 ffffff
5 7 3 ffffff
6 7 3 ffffff
7 7 3 ffffff
8 7 3 ffffff
9 7 3 ffffff
10 7 3 ffffff
11 7 3 ffffff
12 7 3 ffffff
13 7 3 ffffff
14 7 3 ffffff
15 7 3 ffffff
0 8 3 ffffff
1 8 3 ffffff
2 8 3 ffffff
3 8 3 ffffff
4 8 3 ffffff
5 8 3 ffffff
6 8 3 ffffff
7 8 3 ffffff
8 8 3 ffffff
9 8 3 ffffff
10 8 3 ffffff
11 8 3 ffffff
12 8 3 ffffff
13 8 3 ffffff
14 8 3 ffffff
15 8 3 ffffff
0 9 3 ffffff
1 9 3 ffffff
2 9 3 ffffff
3 9 3 ffffff
4 9 3 ffffff
5 9 3 ffffff
6 9 3 ffffff
7 9 3 ffffff
8 9 3 ffffff
9 9 3 ffffff
10 9 3 ffffff
11 9 3 ffffff
12 9 3 ffffff
13 9 3 ffffff
14 9 3 ffffff
15 9 3 ffffff
0 10 3 ffffff
1 10 3 ffffff
2 10 3 ffffff
3 10 3 ffffff
4 10 3 ffffff
5 10 3 ffffff
6 10 3 ffffff
7 10 3 ffffff
8 10 3 ffffff
9 10 3 ffffff
10 10 3 ffffff
11 10 3 ffffff
12 10 3 ffffff
13 10 3 ffffff
14 10 3 ffffff
15 10 3 ffffff
0 11 3 ffffff
1 11 3 ffffff
2 11 3 ffffff
3 11 3 ffffff
4 11 3 ffffff
5 11 3 ffffff
6 11 3 ffffff
7 11 3 ffffff
8 11 3 ffffff
9 11 3 ffffff
10 11 3 ffffff
11 11 3 ffffff
12 11 3 ffffff
13 11 3 ffffff
14 11 3 ffffff
15 11 3 ffffff
0 12 3 ffffff
1 12 3 ffffff
2 12 3 ffffff
3 12 3 ffffff
4 12 3 ffffff
5 12 3 ffffff
6 12 3 ffffff
7 12 3 ffffff
8 12 3 ffffff
9 12 3 ffffff
10 12 3 ffffff
11 12 3 ffffff
12 12 3 ffffff
13 12 3 ffffff
14 12 3 ffffff
15 12 3 ffffff
0 13 3 ffffff
1 13 3 ffffff
2 13 3 ffffff
3 13 3 ffffff
4 13 3 ffffff
5 13 3 ffffff
6 13 3 ffffff
7 13 3 ffffff
8 13 3 ffffff
9 13 3 ffffff
10 13 3 ffffff
11 13 3 ffffff
12 13 3 ffffff
13 13 3 ffffff
14 13 3 ffffff
15 13 3 ffffff
0 14 3 ffffff
1 14 3 ffffff
2 14 3 ffffff
3 14 3 ffffff
4 14 3 ffffff
5 14 3 ffffff
6 14 3 ffffff
7 14 3 ffffff
8 14 3 ffffff
9 14 3 ffffff
10 14 3 ffffff
11 14 3 ffffff
12 14 3 ffffff
13 14 3 ffffff
14 14 3 ffffff
15 14 3 ffffff
0 15 3 ffffff
1 15 3 ffffff
2 15 3 ffffff
3 15 3 ffffff
4 15 3 ffffff
5 15 3 ffffff
6 15 3 ffffff
7 15 3 ffffff
8 15 3 ffffff
9 15 3 ffffff
10 15 3 ffffff
11 15 3 ffffff
12 15 3 ffffff
13 15 3 ffffff
14 15 3 ffffff
15 15 3 ffffff
0 0 4 ffffff
1 0 4 ffffff
2 0 4 ffffff
3 0 4 ffffff
4 0 4 ffffff
5 0 4 ffffff
6 0 4 ffffff
7 0 4 ffffff
8 0 4 ffffff
9 0 4 ffffff
10 0 4 ffffff
11 0 4 ffffff
12 0 4 ffffff
13 0 4 ffffff
14 0 4 ffffff
15 0 4 ffffff
0 1 4 ffffff
1 1 4 ffffff
2 1 4 ffffff
3 1 4 ffffff
4 1 4 ffffff
5 1 4 ffffff
6 1 4 ffffff
7 1 4 ffffff
8 1 4 ffffff
9 1 4 ffffff
10 1 4 ffffff
11 1 4 ffffff
12 1 4 ffffff
13 1 4 ffffff
14 1 4 ffffff
15 1 4 ffffff
0 2 4 ffffff
1 2 4 ffffff
2 2 4 ffffff
3 2 4 ffffff
4 2 4 ffffff
5 2 4 ffffff
6 2 4 ffffff
7 2 4 ffffff
8 2 4 ffffff
9 2 4 ffffff
10 2 4 ffffff
11 2 4 ffffff
12 2 4 ffffff
13 2 4 ffffff
14 2 4 ffffff
15 2 4 ffffff
0 3 4 ffffff
1 3 4 ffffff
2 3 4 ffffff
3 3 4 ffffff
4 3 4 ffffff
5 3 4 ffffff
6 3 4 ffffff
7 3 4 ffffff
8 3 4 ffffff
9 3 4 ffffff
10 3 4 ffffff
11 3 4 ffffff
12 3 4 ffffff
13 3 4 ffffff
14 3 4 ffffff
15 3 4 ffffff
0 4 4 ffffff
1 4 4 ffffff
2 4 4 ffffff
3 4 4 ffffff
4 4 4 ffffff
5 4 4 ffffff
6 4 4 ffffff
7 4 4 ffffff
8 4 4 ffffff
9 4 4 ffffff
10 4 4 ffffff
11 4 4 ffffff
12 4 4 ffffff
13 4 4 ffffff
14 4 4 ffffff
15 4 4 ffffff
0 5 4 ffffff
1 5 4 ffffff
2 5 4 ffffff
3 5 4 ffffff
4 5 4 ffffff
5 5 4 ffffff
6 5 4 ffffff
7 5 4 ffffff
8 5 4 ffffff
9 5 4 ffffff
10 5 4 ffffff
11 5 4 ffffff
12 5 4 ffffff
13 5 4 ffffff
14 5 4 ffffff
15 5 4 ffffff
0 6 4 ffffff
1 6 4 ffffff
2 6 4 ffffff
3 6 4 ffffff
4 6 4 ffffff
5 6 4 ffffff
6 6 4 ffffff
7 6 4 ffffff
8 6 4 ffffff
9 6 4 ffffff
10 6 4 ffffff
11 6 4 ffffff
12 6 4 ffffff
13 6 4 ffffff
14 6 4 ffffff
15 6 4 ffffff
0 7 4 ffffff
1 7 4 ffffff
2 7 4 ffffff
3 7 4 ffffff
4 7 4 ffffff
5 7 4 ffffff
6 7 4 ffffff
7 7 4 ffffff
8 7 4 ffffff
9 7 4 ffffff
10 7 4 ffffff
11 7 4 ffffff
12 7 4 ffffff
13 7 4 ffffff
14 7 4 ffffff
15 7 4 ffffff
0 8 4 ffffff
1 8 4 ffffff
2 8 4 ffffff
3 8 4 ffffff
4 8 4 ffffff
5 8 4 ffffff
6 8 4 ffffff
7 8 4 ffffff
8 8 4 ffffff
9 8 4 ffffff
10 8 4 ffffff
11 8 4 ffffff
12 8 4 ffffff
13 8 4 ffffff
14 8 4 ffffff
15 8 4 ffffff
0 9 4 ffffff
1 9 4 ffffff
2 9 4 ffffff
3 9 4 ffffff
4 9 4 ffffff
5 9 4 ffffff
6 9 4 ffffff
7 9 4 ffffff
8 9 4 ffffff
9 9 4 ffffff
10 9 4 ffffff
11 9 4 ffffff
12 9 4 ffffff
13 9 4 ffffff
14 9 4 ffffff
15 9 4 ffffff
0 10 4 ffffff
1 10 4 ffffff
2 10 4 ffffff
3 10 4 ffffff
4 10 4 ffffff
5 10 4 ffffff
6 10 4 ffffff
7 10 4 ffffff
8 10 4 ffffff
9 10 4 ffffff
10 10 4 ffffff
11 10 4 ffffff
12 10 4 ffffff
13 10 4 ffffff
14 10 4 ffffff
15 10 4 ffffff
0 11 4 ffffff
1 11 4 ffffff
2 11 4 ffffff
3 11 4 ffffff
4 11 4 ffffff
5 11 4 ffffff
6 11 4 ffffff
7 11 4 ffffff
8 11 4 ffffff
9 11 4 ffffff
10 11 4 ffffff
11 11 4 ffffff
12 11 4 ffffff
13 11 4 ffffff
14 11 4 ffffff
15 11 4 ffffff
0 12 4 ffffff
1 12 4 ffffff
2 12 4 ffffff
3 12 4 ffffff
4 12 4 ffffff
5 12 4 ffffff
6 12 4 ffffff
7 12 4 ffffff
8 12 4 ffffff
9 12 4 ffffff
10 12 4 ffffff
11 12 4 ffffff
12 12 4 ffffff
13 12 4 ffffff
14 12 4 ffffff
15 12 4 ffffff
0 13 4 ffffff
1 13 4 ffffff
2 13 4 ffffff
3 13 4 ffffff
4 13 4 ffffff
5 13 4 ffffff
6 13 4 ffffff
7 13 4 ffffff
8 13 4 ffffff
9 13 4 ffffff
10 13 4 ffffff
11 13 4 ffffff
12 13 4 ffffff
13 13 4 ffffff
14 13 4 ffffff
15 13 4 ffffff
0 14 4 ffffff
1 14 4 ffffff
2 14 4 ffffff
3 14 4 ffffff
4 14 4 ffffff
5 14 4 ffffff
6 14 4 ffffff
7 14 4 ffffff
8 14 4 ffffff
9 14 4 ffffff
10 14 4 ffffff
11 14 4 ffffff
12 14 4 ffffff
13 14 4 ffffff
14 14 4 ffffff
15 14 4 ffffff
0 15 4 ffffff
1 15 4 ffffff
2 15 4 ffffff
3 15 4 ffffff
4 15 4 ffffff
5 15 4 ffffff
6 15 4 ffffff
7 15 4 ffffff
8 15 4 ffffff
9 15 4 ffffff
10 15 4 ffffff
11 15 4 ffffff
12 15 4 ffffff
13 15 4 ffffff
14 15 4 ffffff
15 15 4 ffffff
0 0 5 ffffff
0 1 5 ffffff
1 1 5 ffffff
2 1 5 ffffff
3 1 5 ffffff
4 1 5 ffffff
5 1 5 ffffff
6 1 5 ffffff
7 1 5 ffffff
8 1 5 ffffff
9 1 5 ffffff
10 1 5 ffffff
11 1 5 ffffff
12 1 5 ffffff
13 1 5 ffffff
14 1 5 ffffff
15 1 5 ffffff
0 2 5 ffffff
1 2 5 ffffff
2 2 5 ffffff
3 2 5 ffffff
4 2 5 ffffff
5 2 5 ffffff
6 2 5 ffffff
7 2 5 ffffff
8 2 5 ffffff
9 2 5 ffffff
10 2 5 ffffff
11 2 5 ffffff
12 2 5 ffffff
13 2 5 ffffff
14 2 5 ffffff
15 2 5 ffffff
0 3 5 ffffff
1 3 5 ffffff
2 3 5 ffffff
3 3 5 ffffff
4 3 5 ffffff
5 3 5 ffffff
6 3 5 ffffff
7 3 5 ffffff
8 3 5 ffffff
9 3 5 ffffff
10 3 5 ffffff
11 3 5 ffffff
12 3 5 ffffff
13 3 5 ffffff
14 3 5 ffffff
15 3 5 ffffff
0 4 5 ffffff
1 4 5 ffffff
2 4 5 ffffff
3 4 5 ffffff
4 4 5 ffffff
5 4 5 ffffff
6 4 5 ffffff
7 4 5 ffffff
8 4 5 ffffff
9 4 5 ffffff
10 4 5 ffffff
11 4 5 ffffff
12 4 5 ffffff
13 4 5 ffffff
14 4 5 ffffff
15 4 5 ffffff
0 5 5 ffffff
1 5 5 ffffff
2 5 5 ffffff
3 5 5 ffffff
4 5 5 ffffff
5 5 5 ffffff
6 5 5 ffffff
7 5 5 ffffff
8 5 5 ffffff
9 5 5 ffffff
10 5 5 ffffff
11 5 5 ffffff
12 5 5 ffffff
13 5 5 ffffff
14 5 5 ffffff
15 5 5 ffffff
0 6 5 ffffff
1 6 5 ffffff
2 6 5 ffffff
3 6 5 ffffff
4 6 5 ffffff
5 6 5 ffffff
6 6 5 ffffff
7 6 5 ffffff
8 6 5 ffffff
9 6 5 ffffff
10 6 5 ffffff
11 6 5 ffffff
12 6 5 ffffff
13 6 5 ffffff
14 6 5 ffffff
15 6 5 ffffff
0 7 5 ffffff
1 7 5 ffffff
2 7 5 ffffff
3 7 5 ffffff
4 7 5 ffffff
5 7 5 ffffff
6 7 5 ffffff
7 7 5 ffffff
8 7 5 ffffff
9 7 5 ffffff
10 7 5 ffffff
11 7 5 ffffff
12 7 5 ffffff
13 7 5 ffffff
14 7 5 ffffff
15 7 5 ffffff
0 8 5 ffffff
1 8 5 ffffff
2 8 5 ffffff
3 8 5 ffffff
4 8 5 ffffff
5 8 5 ffffff
6 8 5 ffffff
7 8 5 ffffff
8 8 5 ffffff
9 8 5 ffffff
10 8 5 ffffff
11 8 5 ffffff
12 8 5 ffffff
13 8 5 ffffff
14 8 5 ffffff
15 8 5 ffffff
0 9 5 ffffff
1 9 5 ffffff
2 9 5 ffffff
3 9 5 ffffff
4 9 5 ffffff
5 9 5 ffffff
6 9 5 ffffff
7 9 5 ffffff
8 9 5 ffffff
9 9 5 ffffff
10 9 5 ffffff
11 9 5 ffffff
12 9 5 ffffff
13 9 5 ffffff
14 9 5 ffffff
15 9 5 ffffff
0 10 5 ffffff
1 10 5 ffffff
2 10 5 ffffff
3 10 5 ffffff
4 10 5 ffffff
5 10 5 ffffff
6 10 5 ffffff
7 10 5 ffffff
8 10 5 ffffff
9 10 5 ffffff
10 10 5 ffffff
11 10 5 ffffff
12 10 5 ffffff
13 10 5 ffffff
14 10 5 ffffff
15 10 5 ffffff
0 11 5 ffffff
1 11 5 ffffff
2 11 5 ffffff
3 11 5 ffffff
4 11 5 ffffff
5 11 5 ffffff
6 11 5 ffffff
7 11 5 ffffff
8 11 5 ffffff
9 11 5 ffffff
10 11 5 ffffff
11 11 5 ffffff
12 11 5 ffffff
13 11 5 ffffff
14 11 5 ffffff
15 11 5 ffffff
0 12 5 ffffff
1 12 5 ffffff
2 12 5 ffffff
3 12 5 ffffff
4 12 5 ffffff
5 12 5 ffffff
6 12 5 ffffff
7 12 5 ffffff
8 12 5 ffffff
9 12 5 ffffff
10 12 5 ffffff
11 12 5 ffffff
12 12 5 ffffff
13 12 5 ffffff
14 12 5 ffffff
15 12 5 ffffff
0 13 5 ffffff
1 13 5 ffffff
2 13 5 ffffff
3 13 5 ffffff
4 13 5 ffffff
5 13 5 ffffff
6 13 5 ffffff
7 13 5 ffffff
8 13 5 ffffff
9 13 5 ffffff
10 13 5 ffffff
11 13 5 ffffff
12 13 5 ffffff
13 13 5 ffffff
14 13 5 ffffff
15 13 5 ffffff
0 14 5 ffffff
1 14 5 ffffff
2 14 5 ffffff
3 14 5 ffffff
4 14 5 ffffff
5 14 5 ffffff
6 14 5 ffffff
7 14 5 ffffff
8 14 5 ffffff
9 14 5 ffffff
10 14 5 ffffff
11 14 5 ffffff
12 14 5 ffffff
13 14 5 ffffff
14 14 5 ffffff
15 14 5 ffffff
0 15 5 ffffff
1 15 5 ffffff
2 15 5 ffffff
3 15 5 ffffff
4 15 5 ffffff
5 15 5 ffffff
6 15 5 ffffff
7 15 5 ffffff
8 15 5 ffffff
9 15 5 ffffff
10 15 5 ffffff
11 15 5 ffffff
12 15 5 ffffff
13 15 5 ffffff
14 15 5 ffffff
15 15 5 ffffff
0 0 6 ffffff
0 1 6 ffffff
1 1 6 ffffff
2 1 6 ffffff
3 1 6 ffffff
4 1 6 ffffff
5 1 6 ffffff
6 1 6 ffffff
7 1 6 ffffff
8 1 6 ffffff
9 1 6 ffffff
10 1 6 ffffff
11 1 6 ffffff
12 1 6 ffffff
13 1 6 ffffff
14 1 6 ffffff
15 1 6 ffffff
0 2 6 ffffff
1 2 6 ffffff
2 2 6 ffffff
3 2 6 ffffff
4 2 6 ffffff
5 2 6 ffffff
6 2 6 ffffff
7 2 6 ffffff
8 2 6 ffffff
9 2 6 ffffff
10 2 6 ffffff
11 2 6 ffffff
12 2 6 ffffff
13 2 6 ffffff
14 2 6 ffffff
15 2 6 ffffff
0 3 6 ffffff
1 3 6 ffffff
2 3 6 ffffff
3 3 6 ffffff
4 3 6 ffffff
5 3 6 ffffff
6 3 6 ffffff
7 3 6 ffffff
8 3 6 ffffff
9 3 6 ffffff
10 3 6 ffffff
11 3 6 ffffff
12 3 6 ffffff
13 3 6 ffffff
14 3 6 ffffff
15 3 6 ffffff
0 4 6 ffffff
1 4 6 ffffff
2 4 6 ffffff
3 4 6 ffffff
4 4 6 ffffff
5 4 6 ffffff
6 4 6 ffffff
7 4 6 ffffff
8 4 6 ffffff
9 4 6 ffffff
10 4 6 ffffff
11 4 6 ffffff
12 4 6 ffffff
13 4 6 ffffff
14 4 6 ffffff
15 4 6 ffffff
0 5 6 ffffff
1 5 6 ffffff
2 5 6 ffffff
3 5 6 ffffff
4 5 6 ffffff
5 5 6 ffffff
6 5 6 ffffff
7 5 6 ffffff
8 5 6 ffffff
9 5 6 ffffff
10 5 6 ffffff
11 5 6 ffffff
12 5 6 ffffff
13 5 6 ffffff
14 5 6 ffffff
15 5 6 ffffff
0 6 6 ffffff
1 6 6 ffffff
2 6 6 ffffff
3 6 6 ffffff
4 6 6 ffffff
5 6 6 ffffff
6 6 6 ffffff
7 6 6 ffffff
8 6 6 ffffff
9 6 6 ffffff
10 6 6 ffffff
11 6 6 ffffff
12 6 6 ffffff
13 6 6 ffffff
14 6 6 ffffff
15 6 6 ffffff
0 7 6 ffffff
1 7 6 ffffff
2 7 6 ffffff
3 7 6 ffffff
4 7 6 ffffff
5 7 6 ffffff
6 7 6 ffffff
7 7 6 ffffff
8 7 6 ffffff
9 7 6 ffffff
10 7 6 ffffff
11 7 6 ffffff
12 7 6 ffffff
13 7 6 ffffff
14 7 6 ffffff
15 7 6 ffffff
0 8 6 ffffff
1 8 6 ffffff
2 8 6 ffffff
3 8 6 ffffff
4 8 6 ffffff
5 8 6 ffffff
6 8 6 ffffff
7 8 6 ffffff
8 8 6 ffffff
9 8 6 ffffff
10 8 6 ffffff
11 8 6 ffffff
12 8 6 ffffff
13 8 6 ffffff
14 8 6 ffffff
15 8 6 ffffff
0 9 6 ffffff
1 9 6 ffffff
2 9 6 ffffff
3 9 6 ffffff
4 9 6 ffffff
5 9 6 ffffff
6 9 6 ffffff
7 9 6 ffffff
8 9 6 ffffff
9 9 6 ffffff
10 9 6 ffffff
11 9 6 ffffff
12 9 6 ffffff
13 9 6 ffffff
14 9 6 ffffff
15 9 6 ffffff
0 10 6 ffffff
1 10 6 ffffff
2 10 6 ffffff
3 10 6 ffffff
4 10 6 ffffff
5 10 6 ffffff
6 10 6 ffffff
7 10 6 ffffff
8 10 6 ffffff
9 10 6 ffffff
10 10 6 ffffff
11 10 6 ffffff
12 10 6 ffffff
13 10 6 ffffff
14 10 6 ffffff
15 10 6 ffffff
0 11 6 ffffff
1 11 6 ffffff
2 11 6 ffffff
3 11 6 ffffff
4 11 6 ffffff
5 11 6 ffffff
6 11 6 ffffff
7 11 6 ffffff
8 11 6 ffffff
9 11 6 ffffff
10 11 6 ffffff
11 11 6 ffffff
12 11 6 ffffff
13 11 6 ffffff
14 11 6 ffffff
15 11 6 ffffff
0 12 6 ffffff
1 12 6 ffffff
2 12 6 ffffff
3 12 6 ffffff
4 12 6 ffffff
5 12 6 ffffff
6 12 6 ffffff
7 12 6 ffffff
8 12 6 ffffff
9 12 6 ffffff
10 12 6 ffffff
11 12 6 ffffff
12 12 6 ffffff
13 12 6 ffffff
14 12 6 ffffff
15 12 6 ffffff
0 13 6 ffffff
1 13 6 ffffff
2 13 6 ffffff
3 13 6 ffffff
4 13 6 ffffff
5 13 6 ffffff
6 13 6 ffffff
7 13 6 ffffff
8 13 6 ffffff
9 13 6 ffffff
10 13 6 ffffff
11 13 6 ffffff
12 13 6 ffffff
13 13 6 ffffff
14 13 6 ffffff
15 13 6 ffffff
0 14 6 ffffff
1 14 6 ffffff
2 14 6 ffffff
3 14 6 ffffff
4 14 6 ffffff
5 14 6 ffffff
6 14 6 ffffff
7 14 6 ffffff
8 14 6 ffffff
9 14 6 ffffff
10 14 6 ffffff
11 14 6 ffffff
12 14 6 ffffff
13 14 6 ffffff
14 14 6 ffffff
15 14 6 ffffff
0 15 6 ffffff
1 15 6 ffffff
2 15 6 ffffff
3 15 6 ffffff
4 15 6 ffffff
5 15 6 ffffff
6 15 6 ffffff
7 15 6 ffffff
8 15 6 ffffff
9 15 6 ffffff
10 15 6 ffffff
11 15 6 ffffff
12 15 6 ffffff
13 15 6 ffffff
14 15 6 ffffff
15 15 6 ffffff
0 0 7 ffffff
0 1 7 ffffff
1 1 7 ffffff
2 1 7 ffffff
3 1 7 ffffff
4 1 7 ffffff
5 1 7 ffffff
6 1 7 ffffff
7 1 7 ffffff
8 1 7 ffffff
9 1 7 ffffff
10 1 7 ffffff
11 1 7 ffffff
12 1 7 ffffff
13 1 7 ffffff
14 1 7 ffffff
15 1 7 ffffff
0 2 7 ffffff
1 2 7 ffffff
2 2 7 ffffff
3 2 7 ffffff
4 2 7 ffffff
5 2 7 ffffff
6 2 7 ffffff
7 2 7 ffffff
8 2 7 ffffff
9 2 7 ffffff
10 2 7 ffffff
11 2 7 ffffff
12 2 7 ffffff
13 2 7 ffffff
14 2 7 ffffff
15 2 7 ffffff
0 3 7 ffffff
1 3 7 ffffff
2 3 7 ffffff
3 3 7 ffffff
4 3 7 ffffff
5 3 7 ffffff
6 3 7 ffffff
7 3 7 ffffff
8 3 7 ffffff
9 3 7 ffffff
10 3 7 ffffff
11 3 7 ffffff
12 3 7 ffffff
13 3 7 ffffff
14 3 7 ffffff
15 3 7 ffffff
0 4 7 ffffff
1 4 7 ffffff
2 4 7 ffffff
3 4 7 ffffff
4 4 7 ffffff
5 4 7 ffffff
6 4 7 ffffff
7 4 7 ffffff
8 4 7 ffffff
9 4 7 ffffff
10 4 7 ffffff
11 4 7 ffffff
12 4 7 ffffff
13 4 7 ffffff
14 4 7 ffffff
15 4 7 ffffff
0 5 7 ffffff
1 5 7 ffffff
2 5 7 ffffff
3 5 7 ffffff
4 5 7 ffffff
5 5 7 ffffff
6 5 7 ffffff
7 5 7 ffffff
8 5 7 ffffff
9 5 7 ffffff
10 5 7 ffffff
11 5 7 ffffff
12 5 7 ffffff
13 5 7 ffffff
14 5 7 ffffff
15 5 7 ffffff
0 6 7 ffffff
1 6 7 ffffff
2 6 7 ffffff
3 6 7 ffffff
4 6 7 ffffff
5 6 7 ffffff
6 6 7 ffffff
7 6 7 ffffff
8 6 7 ffffff
9 6 7 ffffff
10 6 7 ffffff
11 6 7 ffffff
12 6 7 ffffff
13 6 7 ffffff
14 6 7 ffffff
15 6 7 ffffff
0 7 7 ffffff
1 7 7 ffffff
2 7 7 ffffff
3 7 7 ffffff
4 7 7 ffffff
5 7 7 ffffff
6 7 7 ffffff
7 7 7 ffffff
8 7 7 ffffff
9 7 7 ffffff
10 7 7 ffffff
11 7 7 ffffff
12 7 7 ffffff
13 7 7 ffffff
14 7 7 ffffff
15 7 7 ffffff
0 8 7 ffffff
1 8 7 ffffff
2 8 7 ffffff
3 8 7 ffffff
4 8 7 ffffff
5 8 7 ffffff
6 8 7 ffffff
7 8 7 ffffff
8 8 7 ffffff
9 8 7 ffffff
10 8 7 ffffff
11 8 7 ffffff
12 8 7 ffffff
13 8 7 ffffff
14 8 7 ffffff
15 8 7 ffffff
0 9 7 ffffff
1 9 7 ffffff
2 9 7 ffffff
3 9 7 ffffff
4 9 7 ffffff
5 9 7 ffffff
6 9 7 ffffff
7 9 7 ffffff
8 9 7 ffffff
9 9 7 ffffff
10 9 7 ffffff
11 9 7 ffffff
12 9 7 ffffff
13 9 7 ffffff
14 9 7 ffffff
15 9 7 ffffff
0 10 7 ffffff
1 10 7 ffffff
2 10 7 ffffff
3 10 7 ffffff
4 10 7 ffffff
5 10 7 ffffff
6 10 7 ffffff
7 10 7 ffffff
8 10 7 ffffff
9 10 7 ffffff
10 10 7 ffffff
11 10 7 ffffff
12 10 7 ffffff
13 10 7 ffffff
14 10 7 ffffff
15 10 7 ffffff
0 11 7 ffffff
1 11 7 ffffff
2 11 7 ffffff
3 11 7 ffffff
4 11 7 ffffff
5 11 7 ffffff
6 11 7 ffffff
7 11 7 ffffff
8 11 7 ffffff
9 11 7 ffffff
10 11 7 ffffff
11 11 7 ffffff
12 11 7 ffffff
13 11 7 ffffff
14 11 7 ffffff
15 11 7 ffffff
0 12 7 ffffff
1 12 7 ffffff
2 12 7 ffffff
3 12 7 ffffff
4 12 7 ffffff
5 12 7 ffffff
6 12 7 ffffff
7 12 7 ffffff
8 12 7 ffffff
9 12 7 ffffff
10 12 7 ffffff
11 12 7 ffffff
12 12 7 ffffff
13 12 7 ffffff
14 12 7 ffffff
15 12 7 ffffff
0 13 7 ffffff
1 13 7 ffffff
2 13 7 ffffff
3 13 7 ffffff
4 13 7 ffffff
5 13 7 ffffff
6 13 7 ffffff
7 13 7 ffffff
8 13 7 ffffff
9 13 7 ffffff
10 13 7 ffffff
11 13 7 ffffff
12 13 7 ffffff
13 13 7 ffffff
14 13 7 ffffff
15 13 7 ffffff
0 14 7 ffffff
1 14 7 ffffff
2 14 7 ffffff
3 14 7 ffffff
4 14 7 ffffff
5 14 7 ffffff
6 14 7 ffffff
7 14 7 ffffff
8 14 7 ffffff
9 14 7 ffffff
10 14 7 ffffff
11 14 7 ffffff
12 14 7 ffffff
13 14 7 ffffff
14 14 7 ffffff
15 14 7 ffffff
0 15 7 ffffff
1 15 7 ffffff
2 15 7 ffffff
3 15 7 ffffff
4 15 7 ffffff
5 15 7 ffffff
6 15 7 ffffff
7 15 7 ffffff
8 15 7 ffffff
9 15 7 ffffff
10 15 7 ffffff
11 15 7 ffffff
12 15 7 ffffff
13 15 7 ffffff
14 15 7 ffffff
15 15 7 ffffff
0 0 8 ffffff
0 1 8 ffffff
1 1 8 ffffff
2 1 8 ffffff
3 1 8 ffffff
4 1 8 ffffff
5 1 8 ffffff
6 1 8 ffffff
7 1 8 ffffff
8 1 8 ffffff
9 1 8 ffffff
10 1 8 ffffff
11 1 8 ffffff
12 1 8 ffffff
13 1 8 ffffff
14 1 8 ffffff
15 1 8 ffffff
0 2 8 ffffff
1 2 8 ffffff
2 2 8 ffffff
3 2 8 ffffff
4 2 8 ffffff
5 2 8 ffffff
6 2 8 ffffff
7 2 8 ffffff
8 2 8 ffffff
9 2 8 ffffff
10 2 8 ffffff
11 2 8 ffffff
12 2 8 ffffff
13 2 8 ffffff
14 2 8 ffffff
15 2 8 ffffff
0 3 8 ffffff
1 3 8 ffffff
2 3 8 ffffff
3 3 8 ffffff
4 3 8 ffffff
5 3 8 ffffff
6 3 8 ffffff
7 3 8 ffffff
8 3 8 ffffff
9 3 8 ffffff
10 3 8 ffffff
11 3 8 ffffff
12 3 8 ffffff
13 3 8 ffffff
14 3 8 ffffff
15 3 8 ffffff
0 4 8 ffffff
1 4 8 ffffff
2 4 8 ffffff
3 4 8 ffffff
4 4 8 ffffff
5 4 8 ffffff
6 4 8 ffffff
7 4 8 ffffff
8 4 8 ffffff
9 4 8 ffffff
10 4 8 ffffff
11 4 8 ffffff
12 4 8 ffffff
13 4 8 ffffff
14 4 8 ffffff
15 4 8 ffffff
0 5 8 ffffff
1 5 8 ffffff
2 5 8 ffffff
3 5 8 ffffff
4 5 8 ffffff
5 5 8 ffffff
6 5 8 ffffff
7 5 8 ffffff
8 5 8 ffffff
9 5 8 ffffff
10 5 8 ffffff
11 5 8 ffffff
12 5 8 ffffff
13 5 8 ffffff
14 5 8 ffffff
15 5 8 ffffff
0 6 8 ffffff
1 6 8 ffffff
2 6 8 ffffff
3 6 8 ffffff
4 6 8 ffffff
5 6 8 ffffff
6 6 8 ffffff
7 6 8 ffffff
8 6 8 ffffff
9 6 8 ffffff
10 6 8 ffffff
11 6 8 ffffff
12 6 8 ffffff
13 6 8 ffffff
14 6 8 ffffff
15 6 8 ffffff
0 7 8 ffffff
1 7 8 ffffff
2 7 8 ffffff
3 7 8 ffffff
4 7 8 ffffff
5 7 8 ffffff
6 7 8 ffffff
7 7 8 ffffff
8 7 8 ffffff
9 7 8 ffffff
10 7 8 ffffff
11 7 8 ffffff
12 7 8 ffffff
13 7 8 ffffff
14 7 8 ffffff
15 7 8 ffffff
0 8 8 ffffff
1 8 8 ffffff
2 8 8 ffffff
3 8 8 ffffff
4 8 8 ffffff
5 8 8 ffffff
6 8 8 ffffff
7 8 8 ffffff
8 8 8 ffffff
9 8 8 ffffff
10 8 8 ffffff
11 8 8 ffffff
12 8 8 ffffff
13 8 8 ffffff
14 8 8 ffffff
15 8 8 ffffff
0 9 8 ffffff
1 9 8 ffffff
2 9 8 ffffff
3 9 8 ffffff
4 9 8 ffffff
5 9 8 ffffff
6 9 8 ffffff
7 9 8 ffffff
8 9 8 ffffff
9 9 8 ffffff
10 9 8 ffffff
11 9 8 ffffff
12 9 8 ffffff
13 9 8 ffffff
14 9 8 ffffff
15 9 8 ffffff
0 10 8 ffffff
1 10 8 ffffff
2 10 8 ffffff
3 10 8 ffffff
4 10 8 ffffff
5 10 8 ffffff
6 10 8 ffffff
7 10 8 ffffff
8 10 8 ffffff
9 10 8 ffffff
10 10 8 ffffff
11 10 8 ffffff
12 10 8 ffffff
13 10 8 ffffff
14 10 8 ffffff
15 10 8 ffffff
0 11 8 ffffff
1 11 8 ffffff
2 11 8 ffffff
3 11 8 ffffff
4 11 8 ffffff
5 11 8 ffffff
6 11 8 ffffff
7 11 8 ffffff
8 11 8 ffffff
9 11 8 ffffff
10 11 8 ffffff
11 11 8 ffffff
12 11 8 ffffff
13 11 8 ffffff
14 11 8 ffffff
15 11 8 ffffff
0 12 8 ffffff
1 12 8 ffffff
2 12 8 ffffff
3 12 8 ffffff
4 12 8 ffffff
5 12 8 ffffff
6 12 8 ffffff
7 12 8 ffffff
8 12 8 ffffff
9 12 8 ffffff
10 12 8 ffffff
11 12 8 ffffff
12 12 8 ffffff
13 12 8 ffffff
14 12 8 ffffff
15 12 8 ffffff
0 13 8 ffffff
1 13 8 ffffff
2 13 8 ffffff
3 13 8 ffffff
4 13 8 ffffff
5 13 8 ffffff
6 13 8 ffffff
7 13 8 ffffff
8 13 8 ffffff
9 13 8 ffffff
10 13 8 ffffff
11 13 8 ffffff
12 13 8 ffffff
13 13 8 ffffff
14 13 8 ffffff
15 13 8 ffffff
0 14 8 ffffff
1 14 8 ffffff
2 14 8 ffffff
3 14 8 ffffff
4 14 8 ffffff
5 14 8 ffffff
6 14 8 ffffff
7 14 8 ffffff
8 14 8 ffffff
9 14 8 ffffff
10 14 8 ffffff
11 14 8 ffffff
12 14 8 ffffff
13 14 8 ffffff
14 14 8 ffffff
15 14 8 ffffff
0 15 8 ffffff
1 15 8 ffffff
2 15 8 ffffff
3 15 8 ffffff
4 15 8 ffffff
5 15 8 ffffff
6 15 8 ffffff
7 15 8 ffffff
8 15 8 ffffff
9 15 8 ffffff
10 15 8 ffffff
11 15 8 ffffff
12 15 8 ffffff
13 15 8 ffffff
14 15 8 ffffff
15 15 8 ffffff
0 0 9 ffffff
0 1 9 ffffff
1 1 9 ffffff
2 1 9 ffffff
3 1 9 ffffff
4 1 9 ffffff
5 1 9 ffffff
6 1 9 ffffff
7 1 9 ffffff
8 1 9 ffffff
9 1 9 ffffff
10 1 9 ffffff
11 1 9 ffffff
12 1 9 ffffff
13 1 9 ffffff
14 1 9 ffffff
15 1 9 ffffff
0 2 9 ffffff
1 2 9 ffffff
2 2 9 ffffff
3 2 9 ffffff
4 2 9 ffffff
5 2 9 ffffff
6 2 9 ffffff
7 2 9 ffffff
8 2 9 ffffff
9 2 9 ffffff
10 2 9 ffffff
11 2 9 ffffff
12 2 9 ffffff
13 2 9 ffffff
14 2 9 ffffff
15 2 9 ffffff
0 3 9 ffffff
1 3 9 ffffff
2 3 9 ffffff
3 3 9 ffffff
4 3 9 ffffff
5 3 9 ffffff
6 3 9 ffffff
7 3 9 ffffff
8 3 9 ffffff
9 3 9 ffffff
10 3 9 ffffff
11 3 9 ffffff
12 3 9 ffffff
13 3 9 ffffff
14 3 9 ffffff
15 3 9 ffffff
0 4 9 ffffff
1 4 9 ffffff
2 4 9 ffffff
3 4 9 ffffff
4 4 9 ffffff
5 4 9 ffffff
6 4 9 ffffff
7 4 9 ffffff
8 4 9 ffffff
9 4 9 ffffff
10 4 9 ffffff
11 4 9 ffffff
12 4 9 ffffff
13 4 9 ffffff
14 4 9 ffffff
15 4 9 ffffff
0 5 9 ffffff
1 5 9 ffffff
2 5 9 ffffff
3 5 9 ffffff
4 5 9 ffffff
5 5 9 ffffff
6 5 9 ffffff
7 5 9 ffffff
8 5 9 ffffff
9 5 9 ffffff
10 5 9 ffffff
11 5 9 ffffff
12 5 9 ffffff
13 5 9 ffffff
14 5 9 ffffff
15 5 9 ffffff
0 6 9 ffffff
1 6 9 ffffff
2 6 9 ffffff
3 6 9 ffffff
4 6 9 ffffff
5 6 9 ffffff
6 6 9 ffffff
7 6 9 ffffff
8 6 9 ffffff
9 6 9 ffffff
10 6 9 ffffff
11 6 9 ffffff
12 6 9 ffffff
13 6 9 ffffff
14 6 9 ffffff
15 6 9 ffffff
0 7 9 ffffff
1 7 9 ffffff
2 7 9 ffffff
3 7 9 ffffff
4 7 9 ffffff
5 7 9 ffffff
6 7 9 ffffff
7 7 9 ffffff
8 7 9 ffffff
9 7 9 ffffff
10 7 9 ffffff
11 7 9 ffffff
12 7 9 ffffff
13 7 9 ffffff
14 7 9 ffffff
15 7 9 ffffff
0 8 9 ffffff
1 8 9 ffffff
2 8 9 ffffff
3 8 9 ffffff
4 8 9 ffffff
5 8 9 ffffff
6 8 9 ffffff
7 8 9 ffffff
8 8 9 ffffff
9 8 9 ffffff
10 8 9 ffffff
11 8 9 ffffff
12 8 9 ffffff
13 8 9 ffffff
14 8 9 ffffff
15 8 9 ffffff
0 9 9 ffffff
1 9 9 ffffff
2 9 9 ffffff
3 9 9 ffffff
4 9 9 ffffff
5 9 9 ffffff
6 9 9 ffffff
7 9 9 ffffff
8 9 9 ffffff
9 9 9 ffffff
10 9 9 ffffff
11 9 9 ffffff
12 9 9 ffffff
13 9 9 ffffff
14 9 9 ffffff
15 9 9 ffffff
0 10 9 ffffff
1 10 9 ffffff
2 10 9 ffffff
3 10 9 ffffff
4 10 9 ffffff
5 10 9 ffffff
6 10 9 ffffff
7 10 9 ffffff
8 10 9 ffffff
9 10 9 ffffff
10 10 9 ffffff
11 10 9 ffffff
12 10 9 ffffff
13 10 9 ffffff
14 10 9 ffffff
15 10 9 ffffff
0 11 9 ffffff
1 11 9 ffffff
2 11 9 ffffff
3 11 9 ffffff
4 11 9 ffffff
5 11 9 ffffff
6 11 9 ffffff
7 11 9 ffffff
8 11 9 ffffff
9 11 9 ffffff
10 11 9 ffffff
11 11 9 ffffff
12 11 9 ffffff
13 11 9 ffffff
14 11 9 ffffff
15 11 9 ffffff
0 12 9 ffffff
1 12 9 ffffff
2 12 9 ffffff
3 12 9 ffffff
4 12 9 ffffff
5 12 9 ffffff
6 12 9 ffffff
7 12 9 ffffff
8 12 9 ffffff
9 12 9 ffffff
10 12 9 ffffff
11 12 9 ffffff
12 12 9 ffffff
13 12 9 ffffff
14 12 9 ffffff
15 12 9 ffffff
0 13 9 ffffff
1 13 9 ffffff
2 13 9 ffffff
3 13 9 ffffff
4 13 9 ffffff
5 13 9 ffffff
6 13 9 ffffff
7 13 9 ffffff
8 13 9 ffffff
9 13 9 ffffff
10 13 9 ffffff
11 13 9 ffffff
12 13 9 ffffff
13 13 9 ffffff
14 13 9 ffffff
15 13 9 ffffff
0 14 9 ffffff
1 14 9 ffffff
2 14 9 ffffff
3 14 9 ffffff
4 14 9 ffffff
5 14 9 ffffff
6 14 9 ffffff
7 14 9 ffffff
8 14 9 ffffff
9 14 9 ffffff
10 14 9 ffffff
11 14 9 ffffff
12 14 9 ffffff
13 14 9 ffffff
14 14 9 ffffff
15 14 9 ffffff
0 15 9 ffffff
1 15 9 ffffff
2 15 9 ffffff
3 15 9 ffffff
4 15 9 ffffff
5 15 9 ffffff
6 15 9 ffffff
7 15 9 ffffff
8 15 9 ffffff
9 15 9 ffffff
10 15 9 ffffff
11 15 9 ffffff
12 15 9 ffffff
13 15 9 ffffff
14 15 9 ffffff
15 15 9 ffffff
0 0 10 ffffff
0 1 10 ffffff
1 1 10 ffffff
2 1 10 ffffff
3 1 10 ffffff
4 1 10 ffffff
5 1 10 ffffff
6 1 10 ffffff
7 1 10 ffffff
8 1 10 ffffff
9 1 10 ffffff
10 1 10 ffffff
11 1 10 ffffff
12 1 10 ffffff
13 1 10 ffffff
14 1 10 ffffff
15 1 10 ffffff
0 2 10 ffffff
1 2 10 ffffff
2 2 10 ffffff
3 2 10 ffffff
4 2 10 ffffff
5 2 10 ffffff
6 2 10 ffffff
7 2 10 ffffff
8 2 10 ffffff
9 2 10 ffffff
10 2 10 ffffff
11 2 10 ffffff
12 2 10 ffffff
13 2 10 ffffff
14 2 10 ffffff
15 2 10 ffffff
0 3 10 ffffff
1 3 10 ffffff
2 3 10 ffffff
3 3 10 ffffff
4 3 10 ffffff
5 3 10 ffffff
6 3 10 ffffff
7 3 10 ffffff
8 3 10 ffffff
9 3 10 ffffff
10 3 10 ffffff
11 3 10 ffffff
12 3 10 ffffff
13 3 10 ffffff
14 3 10 ffffff
15 3 10 ffffff
0 4 10 ffffff
1 4 10 ffffff
2 4 10 ffffff
3 4 10 ffffff
4 4 10 ffffff
5 4 10 ffffff
6 4 10 ffffff
7 4 10 ffffff
8 4 10 ffffff
9 4 10 ffffff
10 4 10 ffffff
11 4 10 ffffff
12 4 10 ffffff
13 4 10 ffffff
14 4 10 ffffff
15 4 10 ffffff
0 5 10 ffffff
1 5 10 ffffff
2 5 10 ffffff
3 5 10 ffffff
4 5 10 ffffff
5 5 10 ffffff
6 5 10 ffffff
7 5 10 ffffff
8 5 10 ffffff
9 5 10 ffffff
10 5 10 ffffff
11 5 10 ffffff
12 5 10 ffffff
13 5 10 ffffff
14 5 10 ffffff
15 5 10 ffffff
0 6 10 ffffff
1 6 10 ffffff
2 6 10 ffffff
3 6 10 ffffff
4 6 10 ffffff
5 6 10 ffffff
6 6 10 ffffff
7 6 10 ffffff
8 6 10 ffffff
9 6 10 ffffff
10 6 10 ffffff
11 6 10 ffffff
12 6 10 ffffff
13 6 10 ffffff
14 6 10 ffffff
15 6 10 ffffff
0 7 10 ffffff
1 7 10 ffffff
2 7 10 ffffff
3 7 10 ffffff
4 7 10 ffffff
5 7 10 ffffff
6 7 10 ffffff
7 7 10 ffffff
8 7 10 ffffff
9 7 10 ffffff
10 7 10 ffffff
11 7 10 ffffff
12 7 10 ffffff
13 7 10 ffffff
14 7 10 ffffff
15 7 10 ffffff
0 8 10 ffffff
1 8 10 ffffff
2 8 10 ffffff
3 8 10 ffffff
4 8 10 ffffff
5 8 10 ffffff
6 8 10 ffffff
7 8 10 ffffff
8 8 10 ffffff
9 8 10 ffffff
10 8 10 ffffff
11 8 10 ffffff
12 8 10 ffffff
13 8 10 ffffff
14 8 10 ffffff
15 8 10 ffffff
0 9 10 ffffff
1 9 10 ffffff
2 9 10 ffffff
3 9 10 ffffff
4 9 10 ffffff
5 9 10 ffffff
6 9 10 ffffff
7 9 10 ffffff
8 9 10 ffffff
9 9 10 ffffff
10 9 10 ffffff
11 9 10 ffffff
12 9 10 ffffff
13 9 10 ffffff
14 9 10 ffffff
15 9 10 ffffff
0 10 10 ffffff
1 10 10 ffffff
2 10 10 ffffff
3 10 10 ffffff
4 10 10 ffffff
5 10 10 ffffff
6 10 10 ffffff
7 10 10 ffffff
8 10 10 ffffff
9 10 10 ffffff
10 10 10 ffffff
11 10 10 ffffff
12 10 10 ffffff
13 10 10 ffffff
14 10 10 ffffff
15 10 10 ffffff
0 11 10 ffffff
1 11 10 ffffff
2 11 10 ffffff
3 11 10 ffffff
4 11 10 ffffff
5 11 10 ffffff
6 11 10 ffffff
7 11 10 ffffff
8 11 10 ffffff
9 11 10 ffffff
10 11 10 ffffff
11 11 10 ffffff
12 11 10 ffffff
13 11 10 ffffff
14 11 10 ffffff
15 11 10 ffffff
0 12 10 ffffff
1 12 10 ffffff
2 12 10 ffffff
3 12 10 ffffff
4 12 10 ffffff
5 12 10 ffffff
6 12 10 ffffff
7 12 10 ffffff
8 12 10 ffffff
9 12 10 ffffff
10 12 10 ffffff
11 12 10 ffffff
12 12 10 ffffff
13 12 10 ffffff
14 12 10 ffffff
15 12 10 ffffff
0 13 10 ffffff
1 13 10 ffffff
2 13 10 ffffff
3 13 10 ffffff
4 13 10 ffffff
5 13 10 ffffff
6 13 10 ffffff
7 13 10 ffffff
8 13 10 ffffff
9 13 10 ffffff
10 13 10 ffffff
11 13 10 ffffff
12 13 10 ffffff
13 13 10 ffffff
14 13 10 ffffff
15 13 10 ffffff
0 14 10 ffffff
1 14 10 ffffff
2 14 10 ffffff
3 14 10 ffffff
4 14 10 ffffff
5 14 10 ffffff
6 14 10 ffffff
7 14 10 ffffff
8 14 10 ffffff
9 14 10 ffffff
10 14 10 ffffff
11 14 10 ffffff
12 14 10 ffffff
13 14 10 ffffff
14 14 10 ffffff
15 14 10 ffffff
0 15 10 ffffff
1 15 10 ffffff
2 15 10 ffffff
3 15 10 ffffff
4 15 10 ffffff
5 15 10 ffffff
6 15 10 ffffff
7 15 10 ffffff
8 15 10 ffffff
9 15 10 ffffff
10 15 10 ffffff
11 15 10 ffffff
12 15 10 ffffff
13 15 10 ffffff
14 15 10 ffffff
15 15 10 ffffff
0 0 11 ffffff
0 1 11 ffffff
1 1 11 ffffff
2 1 11 ffffff
3 1 11 ffffff
4 1 11 ffffff
5 1 11 ffffff
6 1 11 ffffff
7 1 11 ffffff
8 1 11 ffffff
9 1 11 ffffff
10 1 11 ffffff
11 1 11 ffffff
12 1 11 ffffff
13 1 11 ffffff
14 1 11 ffffff
15 1 11 ffffff
0 2 11 ffffff
1 2 11 ffffff
2 2 11 ffffff
3 2 11 ffffff
4 2 11 ffffff
5 2 11 ffffff
6 2 11 ffffff
7 2 11 ffffff
8 2 11 ffffff
9 2 11 ffffff
10 2 11 ffffff
11 2 11 ffffff
12 2 11 ffffff
13 2 11 ffffff
14 2 11 ffffff
15 2 11 ffffff
0 3 11 ffffff
1 3 11 ffffff
2 3 11 ffffff
3 3 11 ffffff
4 3 11 ffffff
5 3 11 ffffff
6 3 11 ffffff
7 3 11 ffffff
8 3 11 ffffff
9 3 11 ffffff
10 3 11 ffffff
11 3 11 ffffff
12 3 11 ffffff
13 3 11 ffffff
14 3 11 ffffff
15 3 11 ffffff
0 4 11 ffffff
1 4 11 ffffff
2 4 11 ffffff
3 4 11 ffffff
4 4 11 ffffff
5 4 11 ffffff
6 4 11 ffffff
7 4 11 ffffff
8 4 11 ffffff
9 4 11 ffffff
10 4 11 ffffff
11 4 11 ffffff
12 4 11 ffffff
13 4 11 ffffff
14 4 11 ffffff
15 4 11 ffffff
0 5 11 ffffff
1 5 11 ffffff
2 5 11 ffffff
3 5 11 ffffff
4 5 11 ffffff
5 5 11 ffffff
6 5 11 ffffff
7 5 11 ffffff
8 5 11 ffffff
9 5 11 ffffff
10 5 11 ffffff
11 5 11 ffffff
12 5 11 ffffff
13 5 11 ffffff
14 5 11 ffffff
15 5 11 ffffff
0 6 11 ffffff
1 6 11 ffffff
2 6 11 ffffff
3 6 11 ffffff
4 6 11 ffffff
5 6 11 ffffff
6 6 11 ffffff
7 6 11 ffffff
8 6 11 ffffff
9 6 11 ffffff
10 6 11 ffffff
11 6 11 ffffff
12 6 11 ffffff
13 6 11 ffffff
14 6 11 ffffff
15 6 11 ffffff
0 7 11 ffffff
1 7 11 ffffff
2 7 11 ffffff
3 7 11 ffffff
4 7 11 ffffff
5 7 11 ffffff
6 7 11 ffffff
7 7 11 ffffff
8 7 11 ffffff
9 7 11 ffffff
10 7 11 ffffff
11 7 11 ffffff
12 7 11 ffffff
13 7 11 ffffff
14 7 11 ffffff
15 7 11 ffffff
0 8 11 ffffff
1 8 11 ffffff
2 8 11 ffffff
3 8 11 ffffff
4 8 11 ffffff
5 8 11 ffffff
6 8 11 ffffff
7 8 11 ffffff
8 8 11 ffffff
9 8 11 ffffff
10 8 11 ffffff
11 8 11 ffffff
12 8 11 ffffff
13 8 11 ffffff
14 8 11 ffffff
15 8 11 ffffff
0 9 11 ffffff
1 9 11 ffffff
2 9 11 ffffff
3 9 11 ffffff
4 9 11 ffffff
5 9 11 ffffff
6 9 11 ffffff
7 9 11 ffffff
8 9 11 ffffff
9 9 11 ffffff
10 9 11 ffffff
11 9 11 ffffff
12 9 11 ffffff
13 9 11 ffffff
14 9 11 ffffff
15 9 11 ffffff
0 10 11 ffffff
1 10 11 ffffff
2 10 11 ffffff
3 10 11 ffffff
4 10 11 ffffff
5 10 11 ffffff
6 10 11 ffffff
7 10 11 ffffff
8 10 11 ffffff
9 10 11 ffffff
10 10 11 ffffff
11 10 11 ffffff
12 10 11 ffffff
13 10 11 ffffff
14 10 11 ffffff
15 10 11 ffffff
0 11 11 ffffff
1 11 11 ffffff
2 11 11 ffffff
3 11 11 ffffff
4 11 11 ffffff
5 11 11 ffffff
6 11 11 ffffff
7 11 11 ffffff
8 11 11 ffffff
9 11 11 ffffff
10 11 11 ffffff
11 11 11 ffffff
12 11 11 ffffff
13 11 11 ffffff
14 11 11 ffffff
15 11 11 ffffff
0 12 11 ffffff
1 12 11 ffffff
2 12 11 ffffff
3 12 11 ffffff
4 12 11 ffffff
5 12 11 ffffff
6 12 11 ffffff
7 12 11 ffffff
8 12 11 ffffff
9 12 11 ffffff
10 12 11 ffffff
11 12 11 ffffff
12 12 11 ffffff
13 12 11 ffffff
14 12 11 ffffff
15 12 11 ffffff
0 13 11 ffffff
1 13 11 ffffff
2 13 11 ffffff
3 13 11 ffffff
4 13 11 ffffff
5 13 11 ffffff
6 13 11 ffffff
7 13 11 ffffff
8 13 11 ffffff
9 13 11 ffffff
10 13 11 ffffff
11 13 11 ffffff
12 13 11 ffffff
13 13 11 ffffff
14 13 11 ffffff
15 13 11 ffffff
0 14 11 ffffff
1 14 11 ffffff
2 14 11 ffffff
3 14 11 ffffff
4 14 11 ffffff
5 14 11 ffffff
6 14 11 ffffff
7 14 11 ffffff
8 14 11 ffffff
9 14 11 ffffff
10 14 11 ffffff
11 14 11 ffffff
12 14 11 ffffff
13 14 11 ffffff
14 14 11 ffffff
15 14 11 ffffff
0 15 11 ffffff
1 15 11 ffffff
2 15 11 ffffff
3 15 11 ffffff
4 15 11 ffffff
5 15 11 ffffff
6 15 11 ffffff
7 15 11 ffffff
8 15 11 ffffff
9 15 11 ffffff
10 15 11 ffffff
11 15 11 ffffff
12 15 11 ffffff
13 15 11 ffffff
14 15 11 ffffff
15 15 11 ffffff
0 0 12 ffffff
0 1 12 ffffff
1 1 12 ffffff
2 1 12 ffffff
3 1 12 ffffff
4 1 12 ffffff
5 1 12 ffffff
6 1 12 ffffff
7 1 12 ffffff
8 1 12 ffffff
9 1 12 ffffff
10 1 12 ffffff
11 1 12 ffffff
12 1 12 ffffff
13 1 12 ffffff
14 1 12 ffffff
15 1 12 ffffff
0 2 12 ffffff
1 2 12 ffffff
2 2 12 ffffff
3 2 12 ffffff
4 2 12 ffffff
5 2 12 ffffff
6 2 12 ffffff
7 2 12 ffffff
8 2 12 ffffff
9 2 12 ffffff
10 2 12 ffffff
11 2 12 ffffff
12 2 12 ffffff
13 2 12 ffffff
14 2 12 ffffff
15 2 12 ffffff
0 3 12 ffffff
1 3 12 ffffff
2 3 12 ffffff
3 3 12 ffffff
4 3 12 ffffff
5 3 12 ffffff
6 3 12 ffffff
7 3 12 ffffff
8 3 12 ffffff
9 3 12 ffffff
10 3 12 ffffff
11 3 12 ffffff
12 3 12 ffffff
13 3 12 ffffff
14 3 12 ffffff
15 3 12 ffffff
0 4 12 ffffff
1 4 12 ffffff
2 4 12 ffffff
3 4 12 ffffff
4 4 12 ffffff
5 4 12 ffffff
6 4 12 ffffff
7 4 12 ffffff
8 4 12 ffffff
9 4 12 ffffff
10 4 12 ffffff
11 4 12 ffffff
12 4 12 ffffff
13 4 12 ffffff
14 4 12 ffffff
15 4 12 ffffff
0 5 12 ffffff
1 5 12 ffffff
2 5 12 ffffff
3 5 12 ffffff
4 5 12 ffffff
5 5 12 ffffff
6 5 12 ffffff
7 5 12 ffffff
8 5 12 ffffff
9 5 12 ffffff
10 5 12 ffffff
11 5 12 ffffff
12 5 12 ffffff
13 5 12 ffffff
14 5 12 ffffff
15 5 12 ffffff
0 6 12 ffffff
1 6 12 ffffff
2 6 12 ffffff
3 6 12 ffffff
4 6 12 ffffff
5 6 12 ffffff
6 6 12 ffffff
7 6 12 ffffff
8 6 12 ffffff
9 6 12 ffffff
10 6 12 ffffff
11 6 12 ffffff
12 6 12 ffffff
13 6 12 ffffff
14 6 12 ffffff
15 6 12 ffffff
0 7 12 ffffff
1 7 12 ffffff
2 7 12 ffffff
3 7 12 ffffff
4 7 12 ffffff
5 7 12 ffffff
6 7 12 ffffff
7 7 12 ffffff
8 7 12 ffffff
9 7 12 ffffff
10 7 12 ffffff
11 7 12 ffffff
12 7 12 ffffff
13 7 12 ffffff
14 7 12 ffffff
15 7 12 ffffff
0 8 12 ffffff
1 8 12 ffffff
2 8 12 ffffff
3 8 12 ffffff
4 8 12 ffffff
5 8 12 ffffff
6 8 12 ffffff
7 8 12 ffffff
8 8 12 ffffff
9 8 12 ffffff
10 8 12 ffffff
11 8 12 ffffff
12 8 12 ffffff
13 8 12 ffffff
14 8 12 ffffff
15 8 12 ffffff
0 9 12 ffffff
1 9 12 ffffff
2 9 12 ffffff
3 9 12 ffffff
4 9 12 ffffff
5 9 12 ffffff
6 9 12 ffffff
7 9 12 ffffff
8 9 12 ffffff
9 9 12 ffffff
10 9 12 ffffff
11 9 12 ffffff
12 9 12 ffffff
13 9 12 ffffff
14 9 12 ffffff
15 9 12 ffffff
0 10 12 ffffff
1 10 12 ffffff
2 10 12 ffffff
3 10 12 ffffff
4 10 12 ffffff
5 10 12 ffffff
6 10 12 ffffff
7 10 12 ffffff
8 10 12 ffffff
9 10 12 ffffff
10 10 12 ffffff
11 10 12 ffffff
12 10 12 ffffff
13 10 12 ffffff
14 10 12 ffffff
15 10 12 ffffff
0 11 12 ffffff
1 11 12 ffffff
2 11 12 ffffff
3 11 12 ffffff
4 11 12 ffffff
5 11 12 ffffff
6 11 12 ffffff
7 11 12 ffffff
8 11 12 ffffff
9 11 12 ffffff
10 11 12 ffffff
11 11 12 ffffff
12 11 12 ffffff
13 11 12 ffffff
14 11 12 ffffff
15 11 12 ffffff
0 12 12 ffffff
1 12 12 ffffff
2 12 12 ffffff
3 12 12 ffffff
4 12 12 ffffff
5 12 12 ffffff
6 12 12 ffffff
7 12 12 ffffff
8 12 12 ffffff
9 12 12 ffffff
10 12 12 ffffff
11 12 12 ffffff
12 12 12 ffffff
13 12 12 ffffff
14 12 12 ffffff
15 12 12 ffffff
0 13 12 ffffff
1 13 12 ffffff
2 13 12 ffffff
3 13 12 ffffff
4 13 12 ffffff
5 13 12 ffffff
6 13 12 ffffff
7 13 12 ffffff
8 13 12 ffffff
9 13 12 ffffff
10 13 12 ffffff
11 13 12 ffffff
12 13 12 ffffff
13 13 12 ffffff
14 13 12 ffffff
15 13 12 ffffff
0 14 12 ffffff
1 14 12 ffffff
2 14 12 ffffff
3 14 12 ffffff
4 14 12 ffffff
5 14 12 ffffff
6 14 12 ffffff
7 14 12 ffffff
8 14 12 ffffff
9 14 12 ffffff
10 14 12 ffffff
11 14 12 ffffff
12 14 12 ffffff
13 14 12 ffffff
14 14 12 ffffff
15 14 12 ffffff
0 15 12 ffffff
1 15 12 ffffff
2 15 12 ffffff
3 15 12 ffffff
4 15 12 ffffff
5 15 12 ffffff
6 15 12 ffffff
7 15 12 ffffff
8 15 12 ffffff
9 15 12 ffffff
10 15 12 ffffff
11 15 12 ffffff
12 15 12 ffffff
13 15 12 ffffff
14 15 12 ffffff
15 15 12 ffffff
0 0 13 ffffff
13 0 13 ffffff
0 1 13 ffffff
1 1 13 ffffff
2 1 13 ffffff
3 1 13 ffffff
4 1 13 ffffff
5 1 13 ffffff
6 1 13 ffffff
7 1 13 ffffff
8 1 13 ffffff
9 1 13 ffffff
10 1 13 ffffff
11 1 13 ffffff
12 1 13 ffffff
13 1 13 ffffff
14 1 13 ffffff
15 1 13 ffffff
0 2 13 ffffff
1 2 13 ffffff
2 2 13 ffffff
3 2 13 ffffff
4 2 13 ffffff
5 2 13 ffffff
6 2 13 ffffff
7 2 13 ffffff
8 2 13 ffffff
9 2 13 ffffff
10 2 13 ffffff
11 2 13 ffffff
12 2 13 ffffff
13 2 13 ffffff
14 2 13 ffffff
15 2 13 ffffff
0 3 13 ffffff
1 3 13 ffffff
2 3 13 ffffff
3 3 13 ffffff
4 3 13 ffffff
5 3 13 ffffff
6 3 13 ffffff
7 3 13 ffffff
8 3 13 ffffff
9 3 13 ffffff
10 3 13 ffffff
11 3 13 ffffff
12 3 13 ffffff
13 3 13 ffffff
14 3 13 ffffff
15 3 13 ffffff
0 4 13 ffffff
1 4 13 ffffff
2 4 13 ffffff
3 4 13 ffffff
4 4 13 ffffff
5 4 13 ffffff
6 4 13 ffffff
7 4 13 ffffff
8 4 13 ffffff
9 4 13 ffffff
10 4 13 ffffff
11 4 13 ffffff
12 4 13 ffffff
13 4 13 ffffff
14 4 13 ffffff
15 4 13 ffffff
0 5 13 ffffff
1 5 13 ffffff
2 5 13 ffffff
3 5 13 ffffff
4 5 13 ffffff
5 5 13 ffffff
6 5 13 ffffff
7 5 13 ffffff
8 5 13 ffffff
9 5 13 ffffff
10 5 13 ffffff
11 5 13 ffffff
12 5 13 ffffff
13 5 13 ffffff
14 5 13 ffffff
15 5 13 ffffff
0 6 13 ffffff
1 6 13 ffffff
2 6 13 ffffff
3 6 13 ffffff
4 6 13 ffffff
5 6 13 ffffff
6 6 13 ffffff
7 6 13 ffffff
8 6 13 ffffff
9 6 13 ffffff
10 6 13 ffffff
11 6 13 ffffff
12 6 13 ffffff
13 6 13 ffffff
14 6 13 ffffff
15 6 13 ffffff
0 7 13 ffffff
1 7 13 ffffff
2 7 13 ffffff
3 7 13 ffffff
4 7 13 ffffff
5 7 13 ffffff
6 7 13 ffffff
7 7 13 ffffff
8 7 13 ffffff
9 7 13 ffffff
10 7 13 ffffff
11 7 13 ffffff
12 7 13 ffffff
13 7 13 ffffff
14 7 13 ffffff
15 7 13 ffffff
0 8 13 ffffff
1 8 13 ffffff
2 8 13 ffffff
3 8 13 ffffff
4 8 13 ffffff
5 8 13 ffffff
6 8 13 ffffff
7 8 13 ffffff
8 8 13 ffffff
9 8 13 ffffff
10 8 13 ffffff
11 8 13 ffffff
12 8 13 ffffff
13 8 13 ffffff
14 8 13 ffffff
15 8 13 ffffff
0 9 13 ffffff
1 9 13 ffffff
2 9 13 ffffff
3 9 13 ffffff
4 9 13 ffffff
5 9 13 ffffff
6 9 13 ffffff
7 9 13 ffffff
8 9 13 ffffff
9 9 13 ffffff
10 9 13 ffffff
11 9 13 ffffff
12 9 13 ffffff
13 9 13 ffffff
14 9 13 ffffff
15 9 13 ffffff
0 10 13 ffffff
1 10 13 ffffff
2 10 13 ffffff
3 10 13 ffffff
4 10 13 ffffff
5 10 13 ffffff
6 10 13 ffffff
7 10 13 ffffff
8 10 13 ffffff
9 10 13 ffffff
10 10 13 ffffff
11 10 13 ffffff
12 10 13 ffffff
13 10 13 ffffff
14 10 13 ffffff
15 10 13 ffffff
0 11 13 ffffff
1 11 13 ffffff
2 11 13 ffffff
3 11 13 ffffff
4 11 13 ffffff
5 11 13 ffffff
6 11 13 ffffff
7 11 13 ffffff
8 11 13 ffffff
9 11 13 ffffff
10 11 13 ffffff
11 11 13 ffffff
12 11 13 ffffff
13 11 13 ffffff
14 11 13 ffffff
15 11 13 ffffff
0 12 13 ffffff
1 12 13 ffffff
2 12 13 ffffff
3 12 13 ffffff
4 12 13 ffffff
5 12 13 ffffff
6 12 13 ffffff
7 12 13 ffffff
8 12 13 ffffff
9 12 13 ffffff
10 12 13 ffffff
11 12 13 ffffff
12 12 13 ffffff
13 12 13 ffffff
14 12 13 ffffff
15 12 13 ffffff
0 13 13 ffffff
1 13 13 ffffff
2 13 13 ffffff
3 13 13 ffffff
4 13 13 ffffff
5 13 13 ffffff
6 13 13 ffffff
7 13 13 ffffff
8 13 13 ffffff
9 13 13 ffffff
10 13 13 ffffff
11 13 13 ffffff
12 13 13 ffffff
13 13 13 ffffff
14 13 13 ffffff
15 13 13 ffffff
0 14 13 ffffff
1 14 13 ffffff
2 14 13 ffffff
3 14 13 ffffff
4 14 13 ffffff
5 14 13 ffffff
6 14 13 ffffff
7 14 13 ffffff
8 14 13 ffffff
9 14 13 ffffff
10 14 13 ffffff
11 14 13 ffffff
12 14 13 ffffff
13 14 13 ffffff
14 14 13 ffffff
15 14 13 ffffff
0 15 13 ffffff
1 15 13 ffffff
2 15 13 ffffff
3 15 13 ffffff
4 15 13 ffffff
5 15 13 ffffff
6 15 13 ffffff
7 15 13 ffffff
8 15 13 ffffff
9 15 13 ffffff
10 15 13 ffffff
11 15 13 ffffff
12 15 13 ffffff
13 15 13 ffffff
14 15 13 ffffff
15 15 13 ffffff
0 0 14 ffffff
13 0 14 ffffff
0 1 14 ffffff
1 1 14 ffffff
2 1 14 ffffff
3 1 14 ffffff
4 1 14 ffffff
5 1 14 ffffff
6 1 14 ffffff
7 1 14 ffffff
8 1 14 ffffff
9 1 14 ffffff
10 1 14 ffffff
11 1 14 ffffff
12 1 14 ffffff
13 1 14 ffffff
14 1 14 ffffff
15 1 14 ffffff
0 2 14 ffffff
1 2 14 ffffff
2 2 14 ffffff
3 2 14 ffffff
4 2 14 ffffff
5 2 14 ffffff
6 2 14 ffffff
7 2 14 ffffff
8 2 14 ffffff
9 2 14 ffffff
10 2 14 ffffff
11 2 14 ffffff
12 2 14 ffffff
13 2 14 ffffff
14 2 14 ffffff
15 2 14 ffffff
0 3 14 ffffff
1 3 14 ffffff
2 3 14 ffffff
3 3 14 ffffff
4 3 14 ffffff
5 3 14 ffffff
6 3 14 ffffff
7 3 14 ffffff
8 3 14 ffffff
9 3 14 ffffff
10 3 14 ffffff
11 3 14 ffffff
12 3 14 ffffff
13 3 14 ffffff
14 3 14 ffffff
15 3 14 ffffff
0 4 14 ffffff
1 4 14 ffffff
2 4 14 ffffff
3 4 14 ffffff
4 4 14 ffffff
5 4 14 ffffff
6 4 14 ffffff
7 4 14 ffffff
8 4 14 ffffff
9 4 14 ffffff
10 4 14 ffffff
11 4 14 ffffff
12 4 14 ffffff
13 4 14 ffffff
14 4 14 ffffff
15 4 14 ffffff
0 5 14 ffffff
1 5 14 ffffff
2 5 14 ffffff
3 5 14 ffffff
4 5 14 ffffff
5 5 14 ffffff
6 5 14 ffffff
7 5 14 ffffff
8 5 14 ffffff
9 5 14 ffffff
10 5 14 ffffff
11 5 14 ffffff
12 5 14 ffffff
13 5 14 ffffff
14 5 14 ffffff
15 5 14 ffffff
0 6 14 ffffff
1 6 14 ffffff
2 6 14 ffffff
3 6 14 ffffff
4 6 14 ffffff
5 6 14 ffffff
6 6 14 ffffff
7 6 14 ffffff
8 6 14 ffffff
9 6 14 ffffff
10 6 14 ffffff
11 6 14 ffffff
12 6 14 ffffff
13 6 14 ffffff
14 6 14 ffffff
15 6 14 ffffff
0 7 14 ffffff
1 7 14 ffffff
2 7 14 ffffff
3 7 14 ffffff
4 7 14 ffffff
5 7 14 ffffff
6 7 14 ffffff
7 7 14 ffffff
8 7 14 ffffff
9 7 14 ffffff
10 7 14 ffffff
11 7 14 ffffff
12 7 14 ffffff
13 7 14 ffffff
14 7 14 ffffff
15 7 14 ffffff
0 8 14 ffffff
1 8 14 ffffff
2 8 14 ffffff
3 8 14 ffffff
4 8 14 ffffff
5 8 14 ffffff
6 8 14 ffffff
7 8 14 ffffff
8 8 14 ffffff
9 8 14 ffffff
10 8 14 ffffff
11 8 14 ffffff
12 8 14 ffffff
13 8 14 ffffff
14 8 14 ffffff
15 8 14 ffffff
0 9 14 ffffff
1 9 14 ffffff
2 9 14 ffffff
3 9 14 ffffff
4 9 14 ffffff
5 9 14 ffffff
6 9 14 ffffff
7 9 14 ffffff
8 9 14 ffffff
9 9 14 ffffff
10 9 14 ffffff
11 9 14 ffffff
12 9 14 ffffff
13 9 14 ffffff
14 9 14 ffffff
15 9 14 ffffff
0 10 14 ffffff
1 10 14 ffffff
2 10 14 ffffff
3 10 14 ffffff
4 10 14 ffffff
5 10 14 ffffff
6 10 14 ffffff
7 10 14 ffffff
8 10 14 ffffff
9 10 14 ffffff
10 10 14 ffffff
11 10 14 ffffff
12 10 14 ffffff
13 10 14 ffffff
14 10 14 ffffff
15 10 14 ffffff
0 11 14 ffffff
1 11 14 ffffff
2 11 14 ffffff
3 11 14 ffffff
4 11 14 ffffff
5 11 14 ffffff
6 11 14 ffffff
7 11 14 ffffff
8 11 14 ffffff
9 11 14 ffffff
10 11 14 ffffff
11 11 14 ffffff
12 11 14 ffffff
13 11 14 ffffff
14 11 14 ffffff
15 11 14 ffffff
0 12 14 ffffff
1 12 14 ffffff
2 12 14 ffffff
3 12 14 ffffff
4 12 14 ffffff
5 12 14 ffffff
6 12 14 ffffff
7 12 14 ffffff
8 12 14 ffffff
9 12 14 ffffff
10 12 14 ffffff
11 12 14 ffffff
12 12 14 ffffff
13 12 14 ffffff
14 12 14 ffffff
15 12 14 ffffff
0 13 14 ffffff
1 13 14 ffffff
2 13 14 ffffff
3 13 14 ffffff
4 13 14 ffffff
5 13 14 ffffff
6 13 14 ffffff
7 13 14 ffffff
8 13 14 ffffff
9 13 14 ffffff
10 13 14 ffffff
11 13 14 ffffff
12 13 14 ffffff
13 13 14 ffffff
14 13 14 ffffff
15 13 14 ffffff
0 14 14 ffffff
1 14 14 ffffff
2 14 14 ffffff
3 14 14 ffffff
4 14 14 ffffff
5 14 14 ffffff
6 14 14 ffffff
7 14 14 ffffff
8 14 14 ffffff
9 14 14 ffffff
10 14 14 ffffff
11 14 14 ffffff
12 14 14 ffffff
13 14 14 ffffff
14 14 14 ffffff
15 14 14 ffffff
0 15 14 ffffff
1 15 14 ffffff
2 15 14 ffffff
3 15 14 ffffff
4 15 14 ffffff
5 15 14 ffffff
6 15 14 ffffff
7 15 14 ffffff
8 15 14 ffffff
9 15 14 ffffff
10 15 14 ffffff
11 15 14 ffffff
12 15 14 ffffff
13 15 14 ffffff
14 15 14 ffffff
15 15 14 ffffff
0 0 15 ffffff
13 0 15 ffffff
0 1 15 ffffff
1 1 15 ffffff
2 1 15 ffffff
3 1 15 ffffff
4 1 15 ffffff
5 1 15 ffffff
6 1 15 ffffff
7 1 15 ffffff
8 1 15 ffffff
9 1 15 ffffff
10 1 15 ffffff
11 1 15 ffffff
12 1 15 ffffff
13 1 15 ffffff
14 1 15 ffffff
15 1 15 ffffff
0 2 15 ffffff
1 2 15 ffffff
2 2 15 ffffff
3 2 15 ffffff
4 2 15 ffffff
5 2 15 ffffff
6 2 15 ffffff
7 2 15 ffffff
8 2 15 ffffff
9 2 15 ffffff
10 2 15 ffffff
11 2 15 ffffff
12 2 15 ffffff
13 2 15 ffffff
14 2 15 ffffff
15 2 15 ffffff
0 3 15 ffffff
1 3 15 ffffff
2 3 15 ffffff
3 3 15 ffffff
4 3 15 ffffff
5 3 15 ffffff
6 3 15 ffffff
7 3 15 ffffff
8 3 15 ffffff
9 3 15 ffffff
10 3 15 ffffff
11 3 15 ffffff
12 3 15 ffffff
13 3 15 ffffff
14 3 15 ffffff
15 3 15 ffffff
0 4 15 ffffff
1 4 15 ffffff
2 4 15 ffffff
3 4 15 ffffff
4 4 15 ffffff
5 4 15 ffffff
6 4 15 ffffff
7 4 15 ffffff
8 4 15 ffffff
9 4 15 ffffff
10 4 15 ffffff
11 4 15 ffffff
12 4 15 ffffff
13 4 15 ffffff
14 4 15 ffffff
15 4 15 ffffff
0 5 15 ffffff
1 5 15 ffffff
2 5 15 ffffff
3 5 15 ffffff
4 5 15 ffffff
5 5 15 ffffff
6 5 15 ffffff
7 5 15 ffffff
8 5 15 ffffff
9 5 15 ffffff
10 5 15 ffffff
11 5 15 ffffff
12 5 15 ffffff
13 5 15 ffffff
14 5 15 ffffff
15 5 15 ffffff
0 6 15 ffffff
1 6 15 ffffff
2 6 15 ffffff
3 6 15 ffffff
4 6 15 ffffff
5 6 15 ffffff
6 6 15 ffffff
7 6 15 ffffff
8 6 15 ffffff
9 6 15 ffffff
10 6 15 ffffff
11 6 15 ffffff
12 6 15 ffffff
13 6 15 ffffff
14 6 15 ffffff
15 6 15 ffffff
0 7 15 ffffff
1 7 15 ffffff
2 7 15 ffffff
3 7 15 ffffff
4 7 15 ffffff
5 7 15 ffffff
6 7 15 ffffff
7 7 15 ffffff
8 7 15 ffffff
9 7 15 ffffff
10 7 15 ffffff
11 7 15 ffffff
12 7 15 ffffff
13 7 15 ffffff
14 7 15 ffffff
15 7 15 ffffff
0 8 15 ffffff
1 8 15 ffffff
2 8 15 ffffff
3 8 15 ffffff
4 8 15 ffffff
5 8 15 ffffff
6 8 15 ffffff
7 8 15 ffffff
8 8 15 ffffff
9 8 15 ffffff
10 8 15 ffffff
11 8 15 ffffff
12 8 15 ffffff
13 8 15 ffffff
14 8 15 ffffff
15 8 15 ffffff
0 9 15 ffffff
1 9 15 ffffff
2 9 15 ffffff
3 9 15 ffffff
4 9 15 ffffff
5 9 15 ffffff
6 9 15 ffffff
7 9 15 ffffff
8 9 15 ffffff
9 9 15 ffffff
10 9 15 ffffff
11 9 15 ffffff
12 9 15 ffffff
13 9 15 ffffff
14 9 15 ffffff
15 9 15 ffffff
0 10 15 ffffff
1 10 15 ffffff
2 10 15 ffffff
3 10 15 ffffff
4 10 15 ffffff
5 10 15 ffffff
6 10 15 ffffff
7 10 15 ffffff
8 10 15 ffffff
9 10 15 ffffff
10 10 15 ffffff
11 10 15 ffffff
12 10 15 ffffff
13 10 15 ffffff
14 10 15 ffffff
15 10 15 ffffff
0 11 15 ffffff
1 11 15 ffffff
2 11 15 ffffff
3 11 15 ffffff
4 11 15 ffffff
5 11 15 ffffff
6 11 15 ffffff
7 11 15 ffffff
8 11 15 ffffff
9 11 15 ffffff
10 11 15 ffffff
11 11 15 ffffff
12 11 15 ffffff
13 11 15 ffffff
14 11 15 ffffff
15 11 15 ffffff
0 12 15 ffffff
1 12 15 ffffff
2 12 15 ffffff
3 12 15 ffffff
4 12 15 ffffff
5 12 15 ffffff
6 12 15 ffffff
7 12 15 ffffff
8 12 15 ffffff
9 12 15 ffffff
10 12 15 ffffff
11 12 15 ffffff
12 12 15 ffffff
13 12 15 ffffff
14 12 15 ffffff
15 12 15 ffffff
0 13 15 ffffff
1 13 15 ffffff
2 13 15 ffffff
3 13 15 ffffff
4 13 15 ffffff
5 13 15 ffffff
6 13 15 ffffff
7 13 15 ffffff
8 13 15 ffffff
9 13 15 ffffff
10 13 15 ffffff
11 13 15 ffffff
12 13 15 ffffff
13 13 15 ffffff
14 13 15 ffffff
15 13 15 ffffff
0 14 15 ffffff
1 14 15 ffffff
2 14 15 ffffff
3 14 15 ffffff
4 14 15 ffffff
5 14 15 ffffff
6 14 15 ffffff
7 14 15 ffffff
8 14 15 ffffff
9 14 15 ffffff
10 14 15 ffffff
11 14 15 ffffff
12 14 15 ffffff
13 14 15 ffffff
14 14 15 ffffff
15 14 15 ffffff
0 15 15 ffffff
1 15 15 ffffff
2 15 15 ffffff
3 15 15 ffffff
4 15 15 ffffff
5 15 15 ffffff
6 15 15 ffffff
7 15 15 ffffff
8 15 15 ffffff
9 15 15 ffffff
10 15 15 ffffff
11 15 15 ffffff
12 15 15 ffffff
13 15 15 ffffff
14 15 15 ffffff
15 15 15 ffffff
16 0 3 ffffff
17 0 3 ffffff
18 0 3 ffffff
19 0 3 ffffff
20 0 3 ffffff
21 0 3 ffffff
22 0 3 ffffff
23 0 3 ffffff
24 0 3 ffffff
25 0 3 ffffff
26 0 3 ffffff
27 0 3 ffffff
28 0 3 ffffff
29 0 3 ffffff
30 0 3 ffffff
31 0 3 ffffff
16 1 3 ffffff
17 1 3 ffffff
18 1 3 ffffff
19 1 3 ffffff
20 1 3 ffffff
21 1 3 ffffff
22 1 3 ffffff
23 1 3 ffffff
24 1 3 ffffff
25 1 3 ffffff
26 1 3 ffffff
27 1 3 ffffff
28 1 3 ffffff
29 1 3 ffffff
30 1 3 ffffff
31 1 3 ffffff
16 2 3 ffffff
17 2 3 ffffff
18 2 3 ffffff
19 2 3 ffffff
20 2 3 ffffff
21 2 3 ffffff
22 2 3 ffffff
23 2 3 ffffff
24 2 3 ffffff
25 2 3 ffffff
26 2 3 ffffff
27 2 3 ffffff
28 2 3 ffffff
29 2 3 ffffff
30 2 3 ffffff
31 2 3 ffffff
16 3 3 ffffff
17 3 3 ffffff
18 3 3 ffffff
19 3 3 ffffff
20 3 3 ffffff
21 3 3 ffffff
22 3 3 ffffff
23 3 3 ffffff
24 3 3 ffffff
25 3 3 ffffff
26 3 3 ffffff
27 3 3 ffffff
28 3 3 ffffff
29 3 3 ffffff
30 3 3 ffffff
31 3 3 ffffff
16 4 3 ffffff
17 4 3 ffffff
18 4 3 ffffff
19 4 3 ffffff
20 4 3 ffffff
21 4 3 ffffff
22 4 3 ffffff
23 4 3 ffffff
24 4 3 ffffff
25 4 3 ffffff
26 4 3 ffffff
27 4 3 ffffff
28 4 3 ffffff
29 4 3 ffffff
30 4 3 ffffff
31 4 3 ffffff
16 5 3 ffffff
17 5 3 ffffff
18 5 3 ffffff
19 5 3 ffffff
20 5 3 ffffff
21 5 3 ffffff
22 5 3 ffffff
23 5 3 ffffff
24 5 3 ffffff
25 5 3 ffffff
26 5 3 ffffff
27 5 3 ffffff
28 5 3 ffffff
29 5 3 ffffff
30 5 3 ffffff
31 5 3 ffffff
16 6 3 ffffff
17 6 3 ffffff
18 6 3 ffffff
19 6 3 ffffff
20 6 3 ffffff
21 6 3 ffffff
22 6 3 ffffff
23 6 3 ffffff
24 6 3 ffffff
25 6 3 ffffff
26 6 3 ffffff
27 6 3 ffffff
28 6 3 ffffff
29 6 3 ffffff
30 6 3 ffffff
31 6 3 ffffff
16 7 3 ffffff
17 7 3 ffffff
18 7 3 ffffff
19 7 3 ffffff
20 7 3 ffffff
21 7 3 ffffff
22 7 3 ffffff
23 7 3 ffffff
24 7 3 ffffff
25 7 3 ffffff
26 7 3 ffffff
27 7 3 ffffff
28 7 3 ffffff
29 7 3 ffffff
30 7 3 ffffff
31 7 3 ffffff
16 8 3 ffffff
17 8 3 ffffff
18 8 3 ffffff
19 8 3 ffffff
20 8 3 ffffff
21 8 3 ffffff
22 8 3 ffffff
23 8 3 ffffff
24 8 3 ffffff
25 8 3 ffffff
26 8 3 ffffff
27 8 3 ffffff
28 8 3 ffffff
29 8 3 ffffff
30 8 3 ffffff
31 8 3 ffffff
16 9 3 ffffff
17 9 3 ffffff
18 9 3 ffffff
19 9 3 ffffff
20 9 3 ffffff
21 9 3 ffffff
22 9 3 ffffff
23 9 3 ffffff
24 9 3 ffffff
25 9 3 ffffff
26 9 3 ffffff
27 9 3 ffffff
28 9 3 ffffff
29 9 3 ffffff
30 9 3 ffffff
31 9 3 ffffff
16 10 3 ffffff
17 10 3 ffffff
18 10 3 ffffff
19 10 3 ffffff
20 10 3 ffffff
21 10 3 ffffff
22 10 3 ffffff
23 10 3 ffffff
24 10 3 ffffff
25 10 3 ffffff
26 10 3 ffffff
27 10 3 ffffff
28 10 3 ffffff
29 10 3 ffffff
30 10 3 ffffff
31 10 3 ffffff
16 11 3 ffffff
17 11 3 ffffff
18 11 3 ffffff
19 11 3 ffffff
20 11 3 ffffff
21 11 3 ffffff
22 11 3 ffffff
23 11 3 ffffff
24 11 3 ffffff
25 11 3 ffffff
26 11 3 ffffff
27 11 3 ffffff
28 11 3 ffffff
29 11 3 ffffff
30 11 3 ffffff
31 11 3 ffffff
16 12 3 ffffff
17 12 3 ffffff
18 12 3 ffffff
19 12 3 ffffff
20 12 3 ffffff
21 12 3 ffffff
22 12 3 ffffff
23 12 3 ffffff
24 12 3 ffffff
25 12 3 ffffff
26 12 3 ffffff
27 12 3 ffffff
28 12 3 ffffff
29 12 3 ffffff
30 12 3 ffffff
31 12 3 ffffff
16 13 3 ffffff
17 13 3 ffffff
18 13 3 ffffff
19 13 3 ffffff
20 13 3 ffffff
21 13 3 ffffff
22 13 3 ffffff
23 13 3 ffffff
24 13 3 ffffff
25 13 3 ffffff
26 13 3 ffffff
27 13 3 ffffff
28 13 3 ffffff
29 13 3 ffffff
30 13 3 ffffff
31 13 3 ffffff
16 14 3 ffffff
17 14 3 ffffff
18 14 3 ffffff
19 14 3 ffffff
20 14 3 ffffff
21 14 3 ffffff
22 14 3 ffffff
23 14 3 ffffff
24 14 3 ffffff
25 14 3 ffffff
26 14 3 ffffff
27 14 3 ffffff
28 14 3 ffffff
29 14 3 ffffff
30 14 3 ffffff
31 14 3 ffffff
16 15 3 ffffff
17 15 3 ffffff
18 15 3 ffffff
19 15 3 ffffff
20 15 3 ffffff
21 15 3 ffffff
22 15 3 ffffff
23 15 3 ffffff
24 15 3 ffffff
25 15 3 ffffff
26 15 3 ffffff
27 15 3 ffffff
28 15 3 ffffff
29 15 3 ffffff
30 15 3 ffffff
31 15 3 ffffff
16 0 4 ffffff
17 0 4 ffffff
18 0 4 ffffff
19 0 4 ffffff
20 0 4 ffffff
21 0 4 ffffff
22 0 4 ffffff
23 0 4 ffffff
24 0 4 ffffff
25 0 4 ffffff
26 0 4 ffffff
27 0 4 ffffff
28 0 4 ffffff
29 0 4 ffffff
30 0 4 ffffff
31 0 4 ffffff
16 1 4 ffffff
17 1 4 ffffff
18 1 4 ffffff
19 1 4 ffffff
20 1 4 ffffff
21 1 4 ffffff
22 1 4 ffffff
23 1 4 ffffff
24 1 4 ffffff
25 1 4 ffffff
26 1 4 ffffff
27 1 4 ffffff
28 1 4 ffffff
29 1 4 ffffff
30 1 4 ffffff
31 1 4 ffffff
16 2 4 ffffff
17 2 4 ffffff
18 2 4 ffffff
19 2 4 ffffff
20 2 4 ffffff
21 2 4 ffffff
22 2 4 ffffff
23 2 4 ffffff
24 2 4 ffffff
25 2 4 ffffff
26 2 4 ffffff
27 2 4 ffffff
28 2 4 ffffff
29 2 4 ffffff
30 2 4 ffffff
31 2 4 ffffff
16 3 4 ffffff
17 3 4 ffffff
18 3 4 ffffff
19 3 4 ffffff
20 3 4 ffffff
21 3 4 ffffff
22 3 4 ffffff
23 3 4 ffffff
24 3 4 ffffff
25 3 4 ffffff
26 3 4 ffffff
27 3 4 ffffff
28 3 4 ffffff
29 3 4 ffffff
30 3 4 ffffff
31 3 4 ffffff
16 4 4 ffffff
17 4 4 ffffff
18 4 4 ffffff
19 4 4 ffffff
20 4 4 ffffff
21 4 4 ffffff
22 4 4 ffffff
23 4 4 ffffff
24 4 4 ffffff
25 4 4 ffffff
26 4 4 ffffff
27 4 4 ffffff
28 4 4 ffffff
29 4 4 ffffff
30 4 4 ffffff
31 4 4 ffffff
16 5 4 ffffff
17 5 4 ffffff
18 5 4 ffffff
19 5 4 ffffff
20 5 4 ffffff
21 5 4 ffffff
22 5 4 ffffff
23 5 4 ffffff
24 5 4 ffffff
25 5 4 ffffff
26 5 4 ffffff
27 5 4 ffffff
28 5 4 ffffff
29 5 4 ffffff
30 5 4 ffffff
31 5 4 ffffff
16 6 4 ffffff
17 6 4 ffffff
18 6 4 ffffff
19 6 4 ffffff
20 6 4 ffffff
21 6 4 ffffff
22 6 4 ffffff
23 6 4 ffffff
24 6 4 ffffff
25 6 4 ffffff
26 6 4 ffffff
27 6 4 ffffff
28 6 4 ffffff
29 6 4 ffffff
30 6 4 ffffff
31 6 4 ffffff
16 7 4 ffffff
17 7 4 ffffff
18 7 4 ffffff
19 7 4 ffffff
20 7 4 ffffff
21 7 4 ffffff
22 7 4 ffffff
23 7 4 ffffff
24 7 4 ffffff
25 7 4 ffffff
26 7 4 ffffff
27 7 4 ffffff
28 7 4 ffffff
29 7 4 ffffff
30 7 4 ffffff
31 7 4 ffffff
16 8 4 ffffff
17 8 4 ffffff
18 8 4 ffffff
19 8 4 ffffff
20 8 4 ffffff
21 8 4 ffffff
22 8 4 ffffff
23 8 4 ffffff
24 8 4 ffffff
25 8 4 ffffff
26 8 4 ffffff
27 8 4 ffffff
28 8 4 ffffff
29 8 4 ffffff
30 8 4 ffffff
31 8 4 ffffff
16 9 4 ffffff
17 9 4 ffffff
18 9 4 ffffff
19 9 4 ffffff
20 9 4 ffffff
21 9 4 ffffff
22 9 4 ffffff
23 9 4 ffffff
24 9 4 ffffff
25 9 4 ffffff
26 9 4 ffffff
27 9 4 ffffff
28 9 4 ffffff
29 9 4 ffffff
30 9 4 ffffff
31 9 4 ffffff
16 10 4 ffffff
17 10 4 ffffff
18 10 4 ffffff
19 10 4 ffffff
20 10 4 ffffff
21 10 4 ffffff
22 10 4 ffffff
23 10 4 ffffff
24 10 4 ffffff
25 10 4 ffffff
26 10 4 ffffff
27 10 4 ffffff
28 10 4 ffffff
29 10 4 ffffff
30 10 4 ffffff
31 10 4 ffffff
16 11 4 ffffff
17 11 4 ffffff
18 11 4 ffffff
19 11 4 ffffff
20 11 4 ffffff
21 11 4 ffffff
22 11 4 ffffff
23 11 4 ffffff
24 11 4 ffffff
25 11 4 ffffff
26 11 4 ffffff
27 11 4 ffffff
28 11 4 ffffff
29 11 4 ffffff
30 11 4 ffffff
31 11 4 ffffff
16 12 4 ffffff
17 12 4 ffffff
18 12 4 ffffff
19 12 4 ffffff
20 12 4 ffffff
21 12 4 ffffff
22 12 4 ffffff
23 12 4 ffffff
24 12 4 ffffff
25 12 4 ffffff
26 12 4 ffffff
27 12 4 ffffff
28 12 4 ffffff
29 12 4 ffffff
30 12 4 ffffff
31 12 4 ffffff
16 13 4 ffffff
17 13 4 ffffff
18 13 4 ffffff
19 13 4 ffffff
20 13 4 ffffff
21 13 4 ffffff
22 13 4 ffffff
23 13 4 ffffff
24 13 4 ffffff
25 13 4 ffffff
26 13 4 ffffff
27 13 4 ffffff
28 13 4 ffffff
29 13 4 ffffff
30 13 4 ffffff
31 13 4 ffffff
16 14 4 ffffff
17 14 4 ffffff
18 14 4 ffffff
19 14 4 ffffff
20 14 4 ffffff
21 14 4 ffffff
22 14 4 ffffff
23 14 4 ffffff
24 14 4 ffffff
25 14 4 ffffff
26 14 4 ffffff
27 14 4 ffffff
28 14 4 ffffff
29 14 4 ffffff
30 14 4 ffffff
31 14 4 ffffff
16 15 4 ffffff
17 15 4 ffffff
18 15 4 ffffff
19 15 4 ffffff
20 15 4 ffffff
21 15 4 ffffff
22 15 4 ffffff
23 15 4 ffffff
24 15 4 ffffff
25 15 4 ffffff
26 15 4 ffffff
27 15 4 ffffff
28 15 4 ffffff
29 15 4 ffffff
30 15 4 ffffff
31 15 4 ffffff
16 0 5 ffffff
17 0 5 ffffff
29 0 5 ffffff
16 1 5 ffffff
17 1 5 ffffff
18 1 5 ffffff
19 1 5 ffffff
20 1 5 ffffff
21 1 5 ffffff
22 1 5 ffffff
23 1 5 ffffff
24 1 5 ffffff
25 1 5 ffffff
26 1 5 ffffff
27 1 5 ffffff
28 1 5 ffffff
29 1 5 ffffff
30 1 5 ffffff
31 1 5 ffffff
16 2 5 ffffff
17 2 5 ffffff
18 2 5 ffffff
19 2 5 ffffff
20 2 5 ffffff
21 2 5 ffffff
22 2 5 ffffff
23 2 5 ffffff
24 2 5 ffffff
25 2 5 ffffff
26 2 5 ffffff
27 2 5 ffffff
28 2 5 ffffff
29 2 5 ffffff
30 2 5 ffffff
31 2 5 ffffff
16 3 5 ffffff
17 3 5 ffffff
18 3 5 ffffff
19 3 5 ffffff
20 3 5 ffffff
21 3 5 ffffff
22 3 5 ffffff
23 3 5 ffffff
24 3 5 ffffff
25 3 5 ffffff
26 3 5 ffffff
27 3 5 ffffff
28 3 5 ffffff
29 3 5 ffffff
30 3 5 ffffff
31 3 5 ffffff
16 4 5 ffffff
17 4 5 ffffff
18 4 5 ffffff
19 4 5 ffffff
20 4 5 ffffff
21 4 5 ffffff
22 4 5 ffffff
23 4 5 ffffff
24 4 5 ffffff
25 4 5 ffffff
26 4 5 ffffff
27 4 5 ffffff
28 4 5 ffffff
29 4 5 ffffff
30 4 5 ffffff
31 4 5 ffffff
16 5 5 ffffff
17 5 5 ffffff
18 5 5 ffffff
19 5 5 ffffff
20 5 5 ffffff
21 5 5 ffffff
22 5 5 ffffff
23 5 5 ffffff
24 5 5 ffffff
25 5 5 ffffff
26 5 5 ffffff
27 5 5 ffffff
28 5 5 ffffff
29 5 5 ffffff
30 5 5 ffffff
31 5 5 ffffff
16 6 5 ffffff
17 6 5 ffffff
18 6 5 ffffff
19 6 5 ffffff
20 6 5 ffffff
21 6 5 ffffff
22 6 5 ffffff
23 6 5 ffffff
24 6 5 ffffff
25 6 5 ffffff
26 6 5 ffffff
27 6 5 ffffff
28 6 5 ffffff
29 6 5 ffffff
30 6 5 ffffff
31 6 5 ffffff
16 7 5 ffffff
17 7 5 ffffff
18 7 5 ffffff
19 7 5 ffffff
20 7 5 ffffff
21 7 5 ffffff
22 7 5 ffffff
23 7 5 ffffff
24 7 5 ffffff
25 7 5 ffffff
26 7 5 ffffff
27 7 5 ffffff
28 7 5 ffffff
29 7 5 ffffff
30 7 5 ffffff
31 7 5 ffffff
16 8 5 ffffff
17 8 5 ffffff
18 8 5 ffffff
19 8 5 ffffff
20 8 5 ffffff
21 8 5 ffffff
22 8 5 ffffff
23 8 5 ffffff
24 8 5 ffffff
25 8 5 ffffff
26 8 5 ffffff
27 8 5 ffffff
28 8 5 ffffff
29 8 5 ffffff
30 8 5 ffffff
31 8 5 ffffff
16 9 5 ffffff
17 9 5 ffffff
18 9 5 ffffff
19 9 5 ffffff
20 9 5 ffffff
21 9 5 ffffff
22 9 5 ffffff
23 9 5 ffffff
24 9 5 ffffff
25 9 5 ffffff
26 9 5 ffffff
27 9 5 ffffff
28 9 5 ffffff
29 9 5 ffffff
30 9 5 ffffff
31 9 5 ffffff
16 10 5 ffffff
17 10 5 ffffff
18 10 5 ffffff
19 10 5 ffffff
20 10 5 ffffff
21 10 5 ffffff
22 10 5 ffffff
23 10 5 ffffff
24 10 5 ffffff
25 10 5 ffffff
26 10 5 ffffff
27 10 5 ffffff
28 10 5 ffffff
29 10 5 ffffff
30 10 5 ffffff
31 10 5 ffffff
16 11 5 ffffff
17 11 5 ffffff
18 11 5 ffffff
19 11 5 ffffff
20 11 5 ffffff
21 11 5 ffffff
22 11 5 ffffff
23 11 5 ffffff
24 11 5 ffffff
25 11 5 ffffff
26 11 5 ffffff
27 11 5 ffffff
28 11 5 ffffff
29 11 5 ffffff
30 11 5 ffffff
31 11 5 ffffff
16 12 5 ffffff
17 12 5 ffffff
18 12 5 ffffff
19 12 5 ffffff
20 12 5 ffffff
21 12 5 ffffff
22 12 5 ffffff
23 12 5 ffffff
24 12 5 ffffff
25 12 5 ffffff
26 12 5 ffffff
27 12 5 ffffff
28 12 5 ffffff
29 12 5 ffffff
30 12 5 ffffff
31 12 5 ffffff
16 13 5 ffffff
17 13 5 ffffff
18 13 5 ffffff
19 13 5 ffffff
20 13 5 ffffff
21 13 5 ffffff
22 13 5 ffffff
23 13 5 ffffff
24 13 5 ffffff
25 13 5 ffffff
26 13 5 ffffff
27 13 5 ffffff
28 13 5 ffffff
29 13 5 ffffff
30 13 5 ffffff
31 13 5 ffffff
16 14 5 ffffff
17 14 5 ffffff
18 14 5 ffffff
19 14 5 ffffff
20 14 5 ffffff
21 14 5 ffffff
22 14 5 ffffff
23 14 5 ffffff
24 14 5 ffffff
25 14 5 ffffff
26 14 5 ffffff
27 14 5 ffffff
28 14 5 ffffff
29 14 5 ffffff
30 14 5 ffffff
31 14 5 ffffff
16 15 5 ffffff
17 15 5 ffffff
18 15 5 ffffff
19 15 5 ffffff
20 15 5 ffffff
21 15 5 ffffff
22 15 5 ffffff
23 15 5 ffffff
24 15 5 ffffff
25 15 5 ffffff
26 15 5 ffffff
27 15 5 ffffff
28 15 5 ffffff
29 15 5 ffffff
30 15 5 ffffff
31 15 5 ffffff
16 0 6 ffffff
17 0 6 ffffff
29 0 6 ffffff
16 1 6 ffffff
17 1 6 ffffff
18 1 6 ffffff
19 1 6 ffffff
20 1 6 ffffff
21 1 6 ffffff
22 1 6 ffffff
23 1 6 ffffff
24 1 6 ffffff
25 1 6 ffffff
26 1 6 ffffff
27 1 6 ffffff
28 1 6 ffffff
29 1 6 ffffff
30 1 6 ffffff
31 1 6 ffffff
16 2 6 ffffff
17 2 6 ffffff
18 2 6 ffffff
19 2 6 ffffff
20 2 6 ffffff
21 2 6 ffffff
22 2 6 ffffff
23 2 6 ffffff
24 2 6 ffffff
25 2 6 ffffff
26 2 6 ffffff
27 2 6 ffffff
28 2 6 ffffff
29 2 6 ffffff
30 2 6 ffffff
31 2 6 ffffff
16 3 6 ffffff
17 3 6 ffffff
18 3 6 ffffff
19 3 6 ffffff
20 3 6 ffffff
21 3 6 ffffff
22 3 6 ffffff
23 3 6 ffffff
24 3 6 ffffff
25 3 6 ffffff
26 3 6 ffffff
27 3 6 ffffff
28 3 6 ffffff
29 3 6 ffffff
30 3 6 ffffff
31 3 6 ffffff
16 4 6 ffffff
17 4 6 ffffff
18 4 6 ffffff
19 4 6 ffffff
20 4 6 ffffff
21 4 6 ffffff
22 4 6 ffffff
23 4 6 ffffff
24 4 6 ffffff
25 4 6 ffffff
26 4 6 ffffff
27 4 6 ffffff
28 4 6 ffffff
29 4 6 ffffff
30 4 6 ffffff
31 4 6 ffffff
16 5 6 ffffff
17 5 6 ffffff
18 5 6 ffffff
19 5 6 ffffff
20 5 6 ffffff
21 5 6 ffffff
22 5 6 ffffff
23 5 6 ffffff
24 5 6 ffffff
25 5 6 ffffff
26 5 6 ffffff
27 5 6 ffffff
28 5 6 ffffff
29 5 6 ffffff
30 5 6 ffffff
31 5 6 ffffff
16 6 6 ffffff
17 6 6 ffffff
18 6 6 ffffff
19 6 6 ffffff
20 6 6 ffffff
21 6 6 ffffff
22 6 6 ffffff
23 6 6 ffffff
24 6 6 ffffff
25 6 6 ffffff
26 6 6 ffffff
27 6 6 ffffff
28 6 6 ffffff
29 6 6 ffffff
30 6 6 ffffff
31 6 6 ffffff
16 7 6 ffffff
17 7 6 ffffff
18 7 6 ffffff
19 7 6 ffffff
20 7 6 ffffff
21 7 6 ffffff
22 7 6 ffffff
23 7 6 ffffff
24 7 6 ffffff
25 7 6 ffffff
26 7 6 ffffff
27 7 6 ffffff
28 7 6 ffffff
29 7 6 ffffff
30 7 6 ffffff
31 7 6 ffffff
16 8 6 ffffff
17 8 6 ffffff
18 8 6 ffffff
19 8 6 ffffff
20 8 6 ffffff
21 8 6 ffffff
22 8 6 ffffff
23 8 6 ffffff
24 8 6 ffffff
25 8 6 ffffff
26 8 6 ffffff
27 8 6 ffffff
28 8 6 ffffff
29 8 6 ffffff
30 8 6 ffffff
31 8 6 ffffff
16 9 6 ffffff
17 9 6 ffffff
18 9 6 ffffff
19 9 6 ffffff
20 9 6 ffffff
21 9 6 ffffff
22 9 6 ffffff
23 9 6 ffffff
24 9 6 ffffff
25 9 6 ffffff
26 9 6 ffffff
27 9 6 ffffff
28 9 6 ffffff
29 9 6 ffffff
30 9 6 ffffff
31 9 6 ffffff
16 10 6 ffffff
17 10 6 ffffff
18 10 6 ffffff
19 10 6 ffffff
20 10 6 ffffff
21 10 6 ffffff
22 10 6 ffffff
23 10 6 ffffff
24 10 6 ffffff
25 10 6 ffffff
26 10 6 ffffff
27 10 6 ffffff
28 10 6 ffffff
29 10 6 ffffff
30 10 6 ffffff
31 10 6 ffffff
16 11 6 ffffff
17 11 6 ffffff
18 11 6 ffffff
19 11 6 ffffff
20 11 6 ffffff
21 11 6 ffffff
22 11 6 ffffff
23 11 6 ffffff
24 11 6 ffffff
25 11 6 ffffff
26 11 6 ffffff
27 11 6 ffffff
28 11 6 ffffff
29 11 6 ffffff
30 11 6 ffffff
31 11 6 ffffff
16 12 6 ffffff
17 12 6 ffffff
18 12 6 ffffff
19 12 6 ffffff
20 12 6 ffffff
21 12 6 ffffff
22 12 6 ffffff
23 12 6 ffffff
24 12 6 ffffff
25 12 6 ffffff
26 12 6 ffffff
27 12 6 ffffff
28 12 6 ffffff
29 12 6 ffffff
30 12 6 ffffff
31 12 6 ffffff
16 13 6 ffffff
17 13 6 ffffff
18 13 6 ffffff
19 13 6 ffffff
20 13 6 ffffff
21 13 6 ffffff
22 13 6 ffffff
23 13 6 ffffff
24 13 6 ffffff
25 13 6 ffffff
26 13 6 ffffff
27 13 6 ffffff
28 13 6 ffffff
29 13 6 ffffff
30 13 6 ffffff
31 13 6 ffffff
16 14 6 ffffff
17 14 6 ffffff
18 14 6 ffffff
19 14 6 ffffff
20 14 6 ffffff
21 14 6 ffffff
22 14 6 ffffff
23 14 6 ffffff
24 14 6 ffffff
25 14 6 ffffff
26 14 6 ffffff
27 14 6 ffffff
28 14 6 ffffff
29 14 6 ffffff
30 14 6 ffffff
31 14 6 ffffff
16 15 6 ffffff
17 15 6 ffffff
18 15 6 ffffff
19 15 6 ffffff
20 15 6 ffffff
21 15 6 ffffff
22 15 6 ffffff
23 15 6 ffffff
24 15 6 ffffff
25 15 6 ffffff
26 15 6 ffffff
27 15 6 ffffff
28 15 6 ffffff
29 15 6 ffffff
30 15 6 ffffff
31 15 6 ffffff
16 0 7 ffffff
17 0 7 ffffff
29 0 7 ffffff
16 1 7 ffffff
17 1 7 ffffff
18 1 7 ffffff
19 1 7 ffffff
20 1 7 ffffff
21 1 7 ffffff
22 1 7 ffffff
23 1 7 ffffff
24 1 7 ffffff
25 1 7 ffffff
26 1 7 ffffff
27 1 7 ffffff
28 1 7 ffffff
29 1 7 ffffff
30 1 7 ffffff
31 1 7 ffffff
16 2 7 ffffff
17 2 7 ffffff
18 2 7 ffffff
19 2 7 ffffff
20 2 7 ffffff
21 2 7 ffffff
22 2 7 ffffff
23 2 7 ffffff
24 2 7 ffffff
25 2 7 ffffff
26 2 7 ffffff
27 2 7 ffffff
28 2 7 ffffff
29 2 7 ffffff
30 2 7 ffffff
31 2 7 ffffff
16 3 7 ffffff
17 3 7 ffffff
18 3 7 ffffff
19 3 7 ffffff
20 3 7 ffffff
21 3 7 ffffff
22 3 7 ffffff
23 3 7 ffffff
24 3 7 ffffff
25 3 7 ffffff
26 3 7 ffffff
27 3 7 ffffff
28 3 7 ffffff
29 3 7 ffffff
30 3 7 ffffff
31 3 7 ffffff
16 4 7 ffffff
17 4 7 ffffff
18 4 7 ffffff
19 4 7 ffffff
20 4 7 ffffff
21 4 7 ffffff
22 4 7 ffffff
23 4 7 ffffff
24 4 7 ffffff
25 4 7 ffffff
26 4 7 ffffff
27 4 7 ffffff
28 4 7 ffffff
29 4 7 ffffff
30 4 7 ffffff
31 4 7 ffffff
16 5 7 ffffff
17 5 7 ffffff
18 5 7 ffffff
19 5 7 ffffff
20 5 7 ffffff
21 5 7 ffffff
22 5 7 ffffff
23 5 7 ffffff
24 5 7 ffffff
25 5 7 ffffff
26 5 7 ffffff
27 5 7 ffffff
28 5 7 ffffff
29 5 7 ffffff
30 5 7 ffffff
31 5 7 ffffff
16 6 7 ffffff
17 6 7 ffffff
18 6 7 ffffff
19 6 7 ffffff
20 6 7 ffffff
21 6 7 ffffff
22 6 7 ffffff
23 6 7 ffffff
24 6 7 ffffff
25 6 7 ffffff
26 6 7 ffffff
27 6 7 ffffff
28 6 7 ffffff
29 6 7 ffffff
30 6 7 ffffff
31 6 7 ffffff
16 7 7 ffffff
17 7 7 ffffff
18 7 7 ffffff
19 7 7 ffffff
20 7 7 ffffff
21 7 7 ffffff
22 7 7 ffffff
23 7 7 ffffff
24 7 7 ffffff
25 7 7 ffffff
26 7 7 ffffff
27 7 7 ffffff
28 7 7 ffffff
29 7 7 ffffff
30 7 7 ffffff
31 7 7 ffffff
16 8 7 ffffff
17 8 7 ffffff
18 8 7 ffffff
19 8 7 ffffff
20 8 7 ffffff
21 8 7 ffffff
22 8 7 ffffff
23 8 7 ffffff
24 8 7 ffffff
25 8 7 ffffff
26 8 7 ffffff
27 8 7 ffffff
28 8 7 ffffff
29 8 7 ffffff
30 8 7 ffffff
31 8 7 ffffff
16 9 7 ffffff
17 9 7 ffffff
18 9 7 ffffff
19 9 7 ffffff
20 9 7 ffffff
21 9 7 ffffff
22 9 7 ffffff
23 9 7 ffffff
24 9 7 ffffff
25 9 7 ffffff
26 9 7 ffffff
27 9 7 ffffff
28 9 7 ffffff
29 9 7 ffffff
30 9 7 ffffff
31 9 7 ffffff
16 10 7 ffffff
17 10 7 ffffff
18 10 7 ffffff
19 10 7 ffffff
20 10 7 ffffff
21 10 7 ffffff
22 10 7 ffffff
23 10 7 ffffff
24 10 7 ffffff
25 10 7 ffffff
26 10 7 ffffff
27 10 7 ffffff
28 10 7 ffffff
29 10 7 ffffff
30 10 7 ffffff
31 10 7 ffffff
16 11 7 ffffff
17 11 7 ffffff
18 11 7 ffffff
19 11 7 ffffff
20 11 7 ffffff
21 11 7 ffffff
22 11 7 ffffff
23 11 7 ffffff
24 11 7 ffffff
25 11 7 ffffff
26 11 7 ffffff
27 11 7 ffffff
28 11 7 ffffff
29 11 7 ffffff
30 11 7 ffffff
31 11 7 ffffff
16 12 7 ffffff
17 12 7 ffffff
18 12 7 ffffff
19 12 7 ffffff
20 12 7 ffffff
21 12 7 ffffff
22 12 7 ffffff
23 12 7 ffffff
24 12 7 ffffff
25 12 7 ffffff
26 12 7 ffffff
27 12 7 ffffff
28 12 7 ffffff
29 12 7 ffffff
30 12 7 ffffff
31 12 7 ffffff
16 13 7 ffffff
17 13 7 ffffff
18 13 7 ffffff
19 13 7 ffffff
20 13 7 ffffff
21 13 7 ffffff
22 13 7 ffffff
23 13 7 ffffff
24 13 7 ffffff
25 13 7 ffffff
26 13 7 ffffff
27 13 7 ffffff
28 13 7 ffffff
29 13 7 ffffff
30 13 7 ffffff
31 13 7 ffffff
16 14 7 ffffff
17 14 7 ffffff
18 14 7 ffffff
19 14 7 ffffff
20 14 7 ffffff
21 14 7 ffffff
22 14 7 ffffff
23 14 7 ffffff
24 14 7 ffffff
25 14 7 ffffff
26 14 7 ffffff
27 14 7 ffffff
28 14 7 ffffff
29 14 7 ffffff
30 14 7 ffffff
31 14 7 ffffff
16 15 7 ffffff
17 15 7 ffffff
18 15 7 ffffff
19 15 7 ffffff
20 15 7 ffffff
21 15 7 ffffff
22 15 7 ffffff
23 15 7 ffffff
24 15 7 ffffff
25 15 7 ffffff
26 15 7 ffffff
27 15 7 ffffff
28 15 7 ffffff
29 15 7 ffffff
30 15 7 ffffff
31 15 7 ffffff
16 0 8 ffffff
17 0 8 ffffff
29 0 8 ffffff
16 1 8 ffffff
17 1 8 ffffff
18 1 8 ffffff
19 1 8 ffffff
20 1 8 ffffff
21 1 8 ffffff
22 1 8 ffffff
23 1 8 ffffff
24 1 8 ffffff
25 1 8 ffffff
26 1 8 ffffff
27 1 8 ffffff
28 1 8 ffffff
29 1 8 ffffff
30 1 8 ffffff
31 1 8 ffffff
16 2 8 ffffff
17 2 8 ffffff
18 2 8 ffffff
19 2 8 ffffff
20 2 8 ffffff
21 2 8 ffffff
22 2 8 ffffff
23 2 8 ffffff
24 2 8 ffffff
25 2 8 ffffff
26 2 8 ffffff
27 2 8 ffffff
28 2 8 ffffff
29 2 8 ffffff
30 2 8 ffffff
31 2 8 ffffff
16 3 8 ffffff
17 3 8 ffffff
18 3 8 ffffff
19 3 8 ffffff
20 3 8 ffffff
21 3 8 ffffff
22 3 8 ffffff
23 3 8 ffffff
24 3 8 ffffff
25 3 8 ffffff
26 3 8 ffffff
27 3 8 ffffff
28 3 8 ffffff
29 3 8 ffffff
30 3 8 ffffff
31 3 8 ffffff
16 4 8 ffffff
17 4 8 ffffff
18 4 8 ffffff
19 4 8 ffffff
20 4 8 ffffff
21 4 8 ffffff
22 4 8 ffffff
23 4 8 ffffff
24 4 8 ffffff
25 4 8 ffffff
26 4 8 ffffff
27 4 8 ffffff
28 4 8 ffffff
29 4 8 ffffff
30 4 8 ffffff
31 4 8 ffffff
16 5 8 ffffff
17 5 8 ffffff
18 5 8 ffffff
19 5 8 ffffff
20 5 8 ffffff
21 5 8 ffffff
22 5 8 ffffff
23 5 8 ffffff
24 5 8 ffffff
25 5 8 ffffff
26 5 8 ffffff
27 5 8 ffffff
28 5 8 ffffff
29 5 8 ffffff
30 5 8 ffffff
31 5 8 ffffff
16 6 8 ffffff
17 6 8 ffffff
18 6 8 ffffff
19 6 8 ffffff
20 6 8 ffffff
21 6 8 ffffff
22 6 8 ffffff
23 6 8 ffffff
24 6 8 ffffff
25 6 8 ffffff
26 6 8 ffffff
27 6 8 ffffff
28 6 8 ffffff
29 6 8 ffffff
30 6 8 ffffff
31 6 8 ffffff
16 7 8 ffffff
17 7 8 ffffff
18 7 8 ffffff
19 7 8 ffffff
20 7 8 ffffff
21 7 8 ffffff
22 7 8 ffffff
23 7 8 ffffff
24 7 8 ffffff
25 7 8 ffffff
26 7 8 ffffff
27 7 8 ffffff
28 7 8 ffffff
29 7 8 ffffff
30 7 8 ffffff
31 7 8 ffffff
16 8 8 ffffff
17 8 8 ffffff
18 8 8 ffffff
19 8 8 ffffff
20 8 8 ffffff
21 8 8 ffffff
22 8 8 ffffff
23 8 8 ffffff
24 8 8 ffffff
25 8 8 ffffff
26 8 8 ffffff
27 8 8 ffffff
28 8 8 ffffff
29 8 8 ffffff
30 8 8 ffffff
31 8 8 ffffff
16 9 8 ffffff
17 9 8 ffffff
18 9 8 ffffff
19 9 8 ffffff
20 9 8 ffffff
21 9 8 ffffff
22 9 8 ffffff
23 9 8 ffffff
24 9 8 ffffff
25 9 8 ffffff
26 9 8 ffffff
27 9 8 ffffff
28 9 8 ffffff
29 9 8 ffffff
30 9 8 ffffff
31 9 8 ffffff
16 10 8 ffffff
17 10 8 ffffff
18 10 8 ffffff
19 10 8 ffffff
20 10 8 ffffff
21 10 8 ffffff
22 10 8 ffffff
23 10 8 ffffff
24 10 8 ffffff
25 10 8 ffffff
26 10 8 ffffff
27 10 8 ffffff
28 10 8 ffffff
29 10 8 ffffff
30 10 8 ffffff
31 10 8 ffffff
16 11 8 ffffff
17 11 8 ffffff
18 11 8 ffffff
19 11 8 ffffff
20 11 8 ffffff
21 11 8 ffffff
22 11 8 ffffff
23 11 8 ffffff
24 11 8 ffffff
25 11 8 ffffff
26 11 8 ffffff
27 11 8 ffffff
28 11 8 ffffff
29 11 8 ffffff
30 11 8 ffffff
31 11 8 ffffff
16 12 8 ffffff
17 12 8 ffffff
18 12 8 ffffff
19 12 8 ffffff
20 12 8 ffffff
21 12 8 ffffff
22 12 8 ffffff
23 12 8 ffffff
24 12 8 ffffff
25 12 8 ffffff
26 12 8 ffffff
27 12 8 ffffff
28 12 8 ffffff
29 12 8 ffffff
30 12 8 ffffff
31 12 8 ffffff
16 13 8 ffffff
17 13 8 ffffff
18 13 8 ffffff
19 13 8 ffffff
20 13 8 ffffff
21 13 8 ffffff
22 13 8 ffffff
23 13 8 ffffff
24 13 8 ffffff
25 13 8 ffffff
26 13 8 ffffff
27 13 8 ffffff
28 13 8 ffffff
29 13 8 ffffff
30 13 8 ffffff
31 13 8 ffffff
16 14 8 ffffff
17 14 8 ffffff
18 14 8 ffffff
19 14 8 ffffff
20 14 8 ffffff
21 14 8 ffffff
22 14 8 ffffff
23 14 8 ffffff
24 14 8 ffffff
25 14 8 ffffff
26 14 8 ffffff
27 14 8 ffffff
28 14 8 ffffff
29 14 8 ffffff
30 14 8 ffffff
31 14 8 ffffff
16 15 8 ffffff
17 15 8 ffffff
18 15 8 ffffff
19 15 8 ffffff
20 15 8 ffffff
21 15 8 ffffff
22 15 8 ffffff
23 15 8 ffffff
24 15 8 ffffff
25 15 8 ffffff
26 15 8 ffffff
27 15 8 ffffff
28 15 8 ffffff
29 15 8 ffffff
30 15 8 ffffff
31 15 8 ffffff
16 0 9 ffffff
17 0 9 ffffff
29 0 9 ffffff
16 1 9 ffffff
17 1 9 ffffff
18 1 9 ffffff
19 1 9 ffffff
20 1 9 ffffff
21 1 9 ffffff
22 1 9 ffffff
23 1 9 ffffff
24 1 9 ffffff
25 1 9 ffffff
26 1 9 ffffff
27 1 9 ffffff
28 1 9 ffffff
29 1 9 ffffff
30 1 9 ffffff
31 1 9 ffffff
16 2 9 ffffff
17 2 9 ffffff
18 2 9 ffffff
19 2 9 ffffff
20 2 9 ffffff
21 2 9 ffffff
22 2 9 ffffff
23 2 9 ffffff
24 2 9 ffffff
25 2 9 ffffff
26 2 9 ffffff
27 2 9 ffffff
28 2 9 ffffff
29 2 9 ffffff
30 2 9 ffffff
31 2 9 ffffff
16 3 9 ffffff
17 3 9 ffffff
18 3 9 ffffff
19 3 9 ffffff
20 3 9 ffffff
21 3 9 ffffff
22 3 9 ffffff
23 3 9 ffffff
24 3 9 ffffff
25 3 9 ffffff
26 3 9 ffffff
27 3 9 ffffff
28 3 9 ffffff
29 3 9 ffffff
30 3 9 ffffff
31 3 9 ffffff
16 4 9 ffffff
17 4 9 ffffff
18 4 9 ffffff
19 4 9 ffffff
20 4 9 ffffff
21 4 9 ffffff
22 4 9 ffffff
23 4 9 ffffff
24 4 9 ffffff
25 4 9 ffffff
26 4 9 ffffff
27 4 9 ffffff
28 4 9 ffffff
29 4 9 ffffff
30 4 9 ffffff
31 4 9 ffffff
16 5 9 ffffff
17 5 9 ffffff
18 5 9 ffffff
19 5 9 ffffff
20 5 9 ffffff
21 5 9 ffffff
22 5 9 ffffff
23 5 9 ffffff
24 5 9 ffffff
25 5 9 ffffff
26 5 9 ffffff
27 5 9 ffffff
28 5 9 ffffff
29 5 9 ffffff
30 5 9 ffffff
31 5 9 ffffff
16 6 9 ffffff
17 6 9 ffffff
18 6 9 ffffff
19 6 9 ffffff
20 6 9 ffffff
21 6 9 ffffff
22 6 9 ffffff
23 6 9 ffffff
24 6 9 ffffff
25 6 9 ffffff
26 6 9 ffffff
27 6 9 ffffff
28 6 9 ffffff
29 6 9 ffffff
30 6 9 ffffff
31 6 9 ffffff
16 7 9 ffffff
17 7 9 ffffff
18 7 9 ffffff
19 7 9 ffffff
20 7 9 ffffff
21 7 9 ffffff
22 7 9 ffffff
23 7 9 ffffff
24 7 9 ffffff
25 7 9 ffffff
26 7 9 ffffff
27 7 9 ffffff
28 7 9 ffffff
29 7 9 ffffff
30 7 9 ffffff
31 7 9 ffffff
16 8 9 ffffff
17 8 9 ffffff
18 8 9 ffffff
19 8 9 ffffff
20 8 9 ffffff
21 8 9 ffffff
22 8 9 ffffff
23 8 9 ffffff
24 8 9 ffffff
25 8 9 ffffff
26 8 9 ffffff
27 8 9 ffffff
28 8 9 ffffff
29 8 9 ffffff
30 8 9 ffffff
31 8 9 ffffff
16 9 9 ffffff
17 9 9 ffffff
18 9 9 ffffff
19 9 9 ffffff
20 9 9 ffffff
21 9 9 ffffff
22 9 9 ffffff
23 9 9 ffffff
24 9 9 ffffff
25 9 9 ffffff
26 9 9 ffffff
27 9 9 ffffff
28 9 9 ffffff
29 9 9 ffffff
30 9 9 ffffff
31 9 9 ffffff
16 10 9 ffffff
17 10 9 ffffff
18 10 9 ffffff
19 10 9 ffffff
20 10 9 ffffff
21 10 9 ffffff
22 10 9 ffffff
23 10 9 ffffff
24 10 9 ffffff
25 10 9 ffffff
26 10 9 ffffff
27 10 9 ffffff
28 10 9 ffffff
29 10 9 ffffff
30 10 9 ffffff
31 10 9 ffffff
16 11 9 ffffff
17 11 9 ffffff
18 11 9 ffffff
19 11 9 ffffff
20 11 9 ffffff
21 11 9 ffffff
22 11 9 ffffff
23 11 9 ffffff
24 11 9 ffffff
25 11 9 ffffff
26 11 9 ffffff
27 11 9 ffffff
28 11 9 ffffff
29 11 9 ffffff
30 11 9 ffffff
31 11 9 ffffff
16 12 9 ffffff
17 12 9 ffffff
18 12 9 ffffff
19 12 9 ffffff
20 12 9 ffffff
21 12 9 ffffff
22 12 9 ffffff
23 12 9 ffffff
24 12 9 ffffff
25 12 9 ffffff
26 12 9 ffffff
27 12 9 ffffff
28 12 9 ffffff
29 12 9 ffffff
30 12 9 ffffff
31 12 9 ffffff
16 13 9 ffffff
17 13 9 ffffff
18 13 9 ffffff
19 13 9 ffffff
20 13 9 ffffff
21 13 9 ffffff
22 13 9 ffffff
23 13 9 ffffff
24 13 9 ffffff
25 13 9 ffffff
26 13 9 ffffff
27 13 9 ffffff
28 13 9 ffffff
29 13 9 ffffff
30 13 9 ffffff
31 13 9 ffffff
16 14 9 ffffff
17 14 9 ffffff
18 14 9 ffffff
19 14 9 ffffff
20 14 9 ffffff
21 14 9 ffffff
22 14 9 ffffff
23 14 9 ffffff
24 14 9 ffffff
25 14 9 ffffff
26 14 9 ffffff
27 14 9 ffffff
28 14 9 ffffff
29 14 9 ffffff
30 14 9 ffffff
31 14 9 ffffff
16 15 9 ffffff
17 15 9 ffffff
18 15 9 ffffff
19 15 9 ffffff
20 15 9 ffffff
21 15 9 ffffff
22 15 9 ffffff
23 15 9 ffffff
24 15 9 ffffff
25 15 9 ffffff
26 15 9 ffffff
27 15 9 ffffff
28 15 9 ffffff
29 15 9 ffffff
30 15 9 ffffff
31 15 9 ffffff
16 0 10 ffffff
17 0 10 ffffff
29 0 10 ffffff
16 1 10 ffffff
17 1 10 ffffff
18 1 10 ffffff
19 1 10 ffffff
20 1 10 ffffff
21 1 10 ffffff
22 1 10 ffffff
23 1 10 ffffff
24 1 10 ffffff
25 1 10 ffffff
26 1 10 ffffff
27 1 10 ffffff
28 1 10 ffffff
29 1 10 ffffff
30 1 10 ffffff
31 1 10 ffffff
16 2 10 ffffff
17 2 10 ffffff
18 2 10 ffffff
19 2 10 ffffff
20 2 10 ffffff
21 2 10 ffffff
22 2 10 ffffff
23 2 10 ffffff
24 2 10 ffffff
25 2 10 ffffff
26 2 10 ffffff
27 2 10 ffffff
28 2 10 ffffff
29 2 10 ffffff
30 2 10 ffffff
31 2 10 ffffff
16 3 10 ffffff
17 3 10 ffffff
18 3 10 ffffff
19 3 10 ffffff
20 3 10 ffffff
21 3 10 ffffff
22 3 10 ffffff
23 3 10 ffffff
24 3 10 ffffff
25 3 10 ffffff
26 3 10 ffffff
27 3 10 ffffff
28 3 10 ffffff
29 3 10 ffffff
30 3 10 ffffff
31 3 10 ffffff
16 4 10 ffffff
17 4 10 ffffff
18 4 10 ffffff
19 4 10 ffffff
20 4 10 ffffff
21 4 10 ffffff
22 4 10 ffffff
23 4 10 ffffff
24 4 10 ffffff
25 4 10 ffffff
26 4 10 ffffff
27 4 10 ffffff
28 4 10 ffffff
29 4 10 ffffff
30 4 10 ffffff
31 4 10 ffffff
16 5 10 ffffff
17 5 10 ffffff
18 5 10 ffffff
19 5 10 ffffff
20 5 10 ffffff
21 5 10 ffffff
22 5 10 ffffff
23 5 10 ffffff
24 5 10 ffffff
25 5 10 ffffff
26 5 10 ffffff
27 5 10 ffffff
28 5 10 ffffff
29 5 10 ffffff
30 5 10 ffffff
31 5 10 ffffff
16 6 10 ffffff
17 6 10 ffffff
18 6 10 ffffff
19 6 10 ffffff
20 6 10 ffffff
21 6 10 ffffff
22 6 10 ffffff
23 6 10 ffffff
24 6 10 ffffff
25 6 10 ffffff
26 6 10 ffffff
27 6 10 ffffff
28 6 10 ffffff
29 6 10 ffffff
30 6 10 ffffff
31 6 10 ffffff
16 7 10 ffffff
17 7 10 ffffff
18 7 10 ffffff
19 7 10 ffffff
20 7 10 ffffff
21 7 10 ffffff
22 7 10 ffffff
23 7 10 ffffff
24 7 10 ffffff
25 7 10 ffffff
26 7 10 ffffff
27 7 10 ffffff
28 7 10 ffffff
29 7 10 ffffff
30 7 10 ffffff
31 7 10 ffffff
16 8 10 ffffff
17 8 10 ffffff
18 8 10 ffffff
19 8 10 ffffff
20 8 10 ffffff
21 8 10 ffffff
22 8 10 ffffff
23 8 10 ffffff
24 8 10 ffffff
25 8 10 ffffff
26 8 10 ffffff
27 8 10 ffffff
28 8 10 ffffff
29 8 10 ffffff
30 8 10 ffffff
31 8 10 ffffff
16 9 10 ffffff
17 9 10 ffffff
18 9 10 ffffff
19 9 10 ffffff
20 9 10 ffffff
21 9 10 ffffff
22 9 10 ffffff
23 9 10 ffffff
24 9 10 ffffff
25 9 10 ffffff
26 9 10 ffffff
27 9 10 ffffff
28 9 10 ffffff
29 9 10 ffffff
30 9 10 ffffff
31 9 10 ffffff
16 10 10 ffffff
17 10 10 ffffff
18 10 10 ffffff
19 10 10 ffffff
20 10 10 ffffff
21 10 10 ffffff
22 10 10 ffffff
23 10 10 ffffff
24 10 10 ffffff
25 10 10 ffffff
26 10 10 ffffff
27 10 10 ffffff
28 10 10 ffffff
29 10 10 ffffff
30 10 10 ffffff
31 10 10 ffffff
16 11 10 ffffff
17 11 10 ffffff
18 11 10 ffffff
19 11 10 ffffff
20 11 10 ffffff
21 11 10 ffffff
22 11 10 ffffff
23 11 10 ffffff
24 11 10 ffffff
25 11 10 ffffff
26 11 10 ffffff
27 11 10 ffffff
28 11 10 ffffff
29 11 10 ffffff
30 11 10 ffffff
31 11 10 ffffff
16 12 10 ffffff
17 12 10 ffffff
18 12 10 ffffff
19 12 10 ffffff
20 12 10 ffffff
21 12 10 ffffff
22 12 10 ffffff
23 12 10 ffffff
24 12 10 ffffff
25 12 10 ffffff
26 12 10 ffffff
27 12 10 ffffff
28 12 10 ffffff
29 12 10 ffffff
30 12 10 ffffff
31 12 10 ffffff
16 13 10 ffffff
17 13 10 ffffff
18 13 10 ffffff
19 13 10 ffffff
20 13 10 ffffff
21 13 10 ffffff
22 13 10 ffffff
23 13 10 ffffff
24 13 10 ffffff
25 13 10 ffffff
26 13 10 ffffff
27 13 10 ffffff
28 13 10 ffffff
29 13 10 ffffff
30 13 10 ffffff
31 13 10 ffffff
16 14 10 ffffff
17 14 10 ffffff
18 14 10 ffffff
19 14 10 ffffff
20 14 10 ffffff
21 14 10 ffffff
22 14 10 ffffff
23 14 10 ffffff
24 14 10 ffffff
25 14 10 ffffff
26 14 10 ffffff
27 14 10 ffffff
28 14 10 ffffff
29 14 10 ffffff
30 14 10 ffffff
31 14 10 ffffff
16 15 10 ffffff
17 15 10 ffffff
18 15 10 ffffff
19 15 10 ffffff
20 15 10 ffffff
21 15 10 ffffff
22 15 10 ffffff
23 15 10 ffffff
24 15 10 ffffff
25 15 10 ffffff
26 15 10 ffffff
27 15 10 ffffff
28 15 10 ffffff
29 15 10 ffffff
30 15 10 ffffff
31 15 10 ffffff
16 0 11 ffffff
17 0 11 ffffff
29 0 11 ffffff
16 1 11 ffffff
17 1 11 ffffff
18 1 11 ffffff
19 1 11 ffffff
20 1 11 ffffff
21 1 11 ffffff
22 1 11 ffffff
23 1 11 ffffff
24 1 11 ffffff
25 1 11 ffffff
26 1 11 ffffff
27 1 11 ffffff
28 1 11 ffffff
29 1 11 ffffff
30 1 11 ffffff
31 1 11 ffffff
16 2 11 ffffff
17 2 11 ffffff
18 2 11 ffffff
19 2 11 ffffff
20 2 11 ffffff
21 2 11 ffffff
22 2 11 ffffff
23 2 11 ffffff
24 2 11 ffffff
25 2 11 ffffff
26 2 11 ffffff
27 2 11 ffffff
28 2 11 ffffff
29 2 11 ffffff
30 2 11 ffffff
31 2 11 ffffff
16 3 11 ffffff
17 3 11 ffffff
18 3 11 ffffff
19 3 11 ffffff
20 3 11 ffffff
21 3 11 ffffff
22 3 11 ffffff
23 3 11 ffffff
24 3 11 ffffff
25 3 11 ffffff
26 3 11 ffffff
27 3 11 ffffff
28 3 11 ffffff
29 3 11 ffffff
30 3 11 ffffff
31 3 11 ffffff
16 4 11 ffffff
17 4 11 ffffff
18 4 11 ffffff
19 4 11 ffffff
20 4 11 ffffff
21 4 11 ffffff
22 4 11 ffffff
23 4 11 ffffff
24 4 11 ffffff
25 4 11 ffffff
26 4 11 ffffff
27 4 11 ffffff
28 4 11 ffffff
29 4 11 ffffff
30 4 11 ffffff
31 4 11 ffffff
16 5 11 ffffff
17 5 11 ffffff
18 5 11 ffffff
19 5 11 ffffff
20 5 11 ffffff
21 5 11 ffffff
22 5 11 ffffff
23 5 11 ffffff
24 5 11 ffffff
25 5 11 ffffff
26 5 11 ffffff
27 5 11 ffffff
28 5 11 ffffff
29 5 11 ffffff
30 5 11 ffffff
31 5 11 ffffff
16 6 11 ffffff
17 6 11 ffffff
18 6 11 ffffff
19 6 11 ffffff
20 6 11 ffffff
21 6 11 ffffff
22 6 11 ffffff
23 6 11 ffffff
24 6 11 ffffff
25 6 11 ffffff
26 6 11 ffffff
27 6 11 ffffff
28 6 11 ffffff
29 6 11 ffffff
30 6 11 ffffff
31 6 11 ffffff
16 7 11 ffffff
17 7 11 ffffff
18 7 11 ffffff
19 7 11 ffffff
20 7 11 ffffff
21 7 11 ffffff
22 7 11 ffffff
23 7 11 ffffff
24 7 11 ffffff
25 7 11 ffffff
26 7 11 ffffff
27 7 11 ffffff
28 7 11 ffffff
29 7 11 ffffff
30 7 11 ffffff
31 7 11 ffffff
16 8 11 ffffff
17 8 11 ffffff
18 8 11 ffffff
19 8 11 ffffff
20 8 11 ffffff
21 8 11 ffffff
22 8 11 ffffff
23 8 11 ffffff
24 8 11 ffffff
25 8 11 ffffff
26 8 11 ffffff
27 8 11 ffffff
28 8 11 ffffff
29 8 11 ffffff
30 8 11 ffffff
31 8 11 ffffff
16 9 11 ffffff
17 9 11 ffffff
18 9 11 ffffff
19 9 11 ffffff
20 9 11 ffffff
21 9 11 ffffff
22 9 11 ffffff
23 9 11 ffffff
24 9 11 ffffff
25 9 11 ffffff
26 9 11 ffffff
27 9 11 ffffff
28 9 11 ffffff
29 9 11 ffffff
30 9 11 ffffff
31 9 11 ffffff
16 10 11 ffffff
17 10 11 ffffff
18 10 11 ffffff
19 10 11 ffffff
20 10 11 ffffff
21 10 11 ffffff
22 10 11 ffffff
23 10 11 ffffff
24 10 11 ffffff
25 10 11 ffffff
26 10 11 ffffff
27 10 11 ffffff
28 10 11 ffffff
29 10 11 ffffff
30 10 11 ffffff
31 10 11 ffffff
16 11 11 ffffff
17 11 11 ffffff
18 11 11 ffffff
19 11 11 ffffff
20 11 11 ffffff
21 11 11 ffffff
22 11 11 ffffff
23 11 11 ffffff
24 11 11 ffffff
25 11 11 ffffff
26 11 11 ffffff
27 11 11 ffffff
28 11 11 ffffff
29 11 11 ffffff
30 11 11 ffffff
31 11 11 ffffff
16 12 11 ffffff
17 12 11 ffffff
18 12 11 ffffff
19 12 11 ffffff
20 12 11 ffffff
21 12 11 ffffff
22 12 11 ffffff
23 12 11 ffffff
24 12 11 ffffff
25 12 11 ffffff
26 12 11 ffffff
27 12 11 ffffff
28 12 11 ffffff
29 12 11 ffffff
30 12 11 ffffff
31 12 11 ffffff
16 13 11 ffffff
17 13 11 ffffff
18 13 11 ffffff
19 13 11 ffffff
20 13 11 ffffff
21 13 11 ffffff
22 13 11 ffffff
23 13 11 ffffff
24 13 11 ffffff
25 13 11 ffffff
26 13 11 ffffff
27 13 11 ffffff
28 13 11 ffffff
29 13 11 ffffff
30 13 11 ffffff
31 13 11 ffffff
16 14 11 ffffff
17 14 11 ffffff
18 14 11 ffffff
19 14 11 ffffff
20 14 11 ffffff
21 14 11 ffffff
22 14 11 ffffff
23 14 11 ffffff
24 14 11 ffffff
25 14 11 ffffff
26 14 11 ffffff
27 14 11 ffffff
28 14 11 ffffff
29 14 11 ffffff
30 14 11 ffffff
31 14 11 ffffff
16 15 11 ffffff
17 15 11 ffffff
18 15 11 ffffff
19 15 11 ffffff
20 15 11 ffffff
21 15 11 ffffff
22 15 11 ffffff
23 15 11 ffffff
24 15 11 ffffff
25 15 11 ffffff
26 15 11 ffffff
27 15 11 ffffff
28 15 11 ffffff
29 15 11 ffffff
30 15 11 ffffff
31 15 11 ffffff
16 0 12 ffffff
17 0 12 ffffff
29 0 12 ffffff
16 1 12 ffffff
17 1 12 ffffff
18 1 12 ffffff
19 1 12 ffffff
20 1 12 ffffff
21 1 12 ffffff
22 1 12 ffffff
23 1 12 ffffff
24 1 12 ffffff
25 1 12 ffffff
26 1 12 ffffff
27 1 12 ffffff
28 1 12 ffffff
29 1 12 ffffff
30 1 12 ffffff
31 1 12 ffffff
16 2 12 ffffff
17 2 12 ffffff
18 2 12 ffffff
19 2 12 ffffff
20 2 12 ffffff
21 2 12 ffffff
22 2 12 ffffff
23 2 12 ffffff
24 2 12 ffffff
25 2 12 ffffff
26 2 12 ffffff
27 2 12 ffffff
28 2 12 ffffff
29 2 12 ffffff
30 2 12 ffffff
31 2 12 ffffff
16 3 12 ffffff
17 3 12 ffffff
18 3 12 ffffff
19 3 12 ffffff
20 3 12 ffffff
21 3 12 ffffff
22 3 12 ffffff
23 3 12 ffffff
24 3 12 ffffff
25 3 12 ffffff
26 3 12 ffffff
27 3 12 ffffff
28 3 12 ffffff
29 3 12 ffffff
30 3 12 ffffff
31 3 12 ffffff
16 4 12 ffffff
17 4 12 ffffff
18 4 12 ffffff
19 4 12 ffffff
20 4 12 ffffff
21 4 12 ffffff
22 4 12 ffffff
23 4 12 ffffff
24 4 12 ffffff
25 4 12 ffffff
26 4 12 ffffff
27 4 12 ffffff
28 4 12 ffffff
29 4 12 ffffff
30 4 12 ffffff
31 4 12 ffffff
16 5 12 ffffff
17 5 12 ffffff
18 5 12 ffffff
19 5 12 ffffff
20 5 12 ffffff
21 5 12 ffffff
22 5 12 ffffff
23 5 12 ffffff
24 5 12 ffffff
25 5 12 ffffff
26 5 12 ffffff
27 5 12 ffffff
28 5 12 ffffff
29 5 12 ffffff
30 5 12 ffffff
31 5 12 ffffff
16 6 12 ffffff
17 6 12 ffffff
18 6 12 ffffff
19 6 12 ffffff
20 6 12 ffffff
21 6 12 ffffff
22 6 12 ffffff
23 6 12 ffffff
24 6 12 ffffff
25 6 12 ffffff
26 6 12 ffffff
27 6 12 ffffff
28 6 12 ffffff
29 6 12 ffffff
30 6 12 ffffff
31 6 12 ffffff
16 7 12 ffffff
17 7 12 ffffff
18 7 12 ffffff
19 7 12 ffffff
20 7 12 ffffff
21 7 12 ffffff
22 7 12 ffffff
23 7 12 ffffff
24 7 12 ffffff
25 7 12 ffffff
26 7 12 ffffff
27 7 12 ffffff
28 7 12 ffffff
29 7 12 ffffff
30 7 12 ffffff
31 7 12 ffffff
16 8 12 ffffff
17 8 12 ffffff
18 8 12 ffffff
19 8 12 ffffff
20 8 12 ffffff
21 8 12 ffffff
22 8 12 ffffff
23 8 12 ffffff
24 8 12 ffffff
25 8 12 ffffff
26 8 12 ffffff
27 8 12 ffffff
28 8 12 ffffff
29 8 12 ffffff
30 8 12 ffffff
31 8 12 ffffff
16 9 12 ffffff
17 9 12 ffffff
18 9 12 ffffff
19 9 12 ffffff
20 9 12 ffffff
21 9 12 ffffff
22 9 12 ffffff
23 9 12 ffffff
24 9 12 ffffff
25 9 12 ffffff
26 9 12 ffffff
27 9 12 ffffff
28 9 12 ffffff
29 9 12 ffffff
30 9 12 ffffff
31 9 12 ffffff
16 10 12 ffffff
17 10 12 ffffff
18 10 12 ffffff
19 10 12 ffffff
20 10 12 ffffff
21 10 12 ffffff
22 10 12 ffffff
23 10 12 ffffff
24 10 12 ffffff
25 10 12 ffffff
26 10 12 ffffff
27 10 12 ffffff
28 10 12 ffffff
29 10 12 ffffff
30 10 12 ffffff
31 10 12 ffffff
16 11 12 ffffff
17 11 12 ffffff
18 11 12 ffffff
19 11 12 ffffff
20 11 12 ffffff
21 11 12 ffffff
22 11 12 ffffff
23 11 12 ffffff
24 11 12 ffffff
25 11 12 ffffff
26 11 12 ffffff
27 11 12 ffffff
28 11 12 ffffff
29 11 12 ffffff
30 11 12 ffffff
31 11 12 ffffff
16 12 12 ffffff
17 12 12 ffffff
18 12 12 ffffff
19 12 12 ffffff
20 12 12 ffffff
21 12 12 ffffff
22 12 12 ffffff
23 12 12 ffffff
24 12 12 ffffff
25 12 12 ffffff
26 12 12 ffffff
27 12 12 ffffff
28 12 12 ffffff
29 12 12 ffffff
30 12 12 ffffff
31 12 12 ffffff
16 13 12 ffffff
17 13 12 ffffff
18 13 12 ffffff
19 13 12 ffffff
20 13 12 ffffff
21 13 12 ffffff
22 13 12 ffffff
23 13 12 ffffff
24 13 12 ffffff
25 13 12 ffffff
26 13 12 ffffff
27 13 12 ffffff
28 13 12 ffffff
29 13 12 ffffff
30 13 12 ffffff
31 13 12 ffffff
16 14 12 ffffff
17 14 12 ffffff
18 14 12 ffffff
19 14 12 ffffff
20 14 12 ffffff
21 14 12 ffffff
22 14 12 ffffff
23 14 12 ffffff
24 14 12 ffffff
25 14 12 ffffff
26 14 12 ffffff
27 14 12 ffffff
28 14 12 ffffff
29 14 12 ffffff
30 14 12 ffffff
31 14 12 ffffff
16 15 12 ffffff
17 15 12 ffffff
18 15 12 ffffff
19 15 12 ffffff
20 15 12 ffffff
21 15 12 ffffff
22 15 12 ffffff
23 15 12 ffffff
24 15 12 ffffff
25 15 12 ffffff
26 15 12 ffffff
27 15 12 ffffff
28 15 12 ffffff
29 15 12 ffffff
30 15 12 ffffff
31 15 12 ffffff
16 0 13 ffffff
17 0 13 ffffff
27 0 13 ffffff
29 0 13 ffffff
31 0 13 ffffff
16 1 13 ffffff
17 1 13 ffffff
18 1 13 ffffff
19 1 13 ffffff
20 1 13 ffffff
21 1 13 ffffff
22 1 13 ffffff
23 1 13 ffffff
24 1 13 ffffff
25 1 13 ffffff
26 1 13 ffffff
27 1 13 ffffff
28 1 13 ffffff
29 1 13 ffffff
30 1 13 ffffff
31 1 13 ffffff
16 2 13 ffffff
17 2 13 ffffff
18 2 13 ffffff
19 2 13 ffffff
20 2 13 ffffff
21 2 13 ffffff
22 2 13 ffffff
23 2 13 ffffff
24 2 13 ffffff
25 2 13 ffffff
26 2 13 ffffff
27 2 13 ffffff
28 2 13 ffffff
29 2 13 ffffff
30 2 13 ffffff
31 2 13 ffffff
16 3 13 ffffff
17 3 13 ffffff
18 3 13 ffffff
19 3 13 ffffff
20 3 13 ffffff
21 3 13 ffffff
22 3 13 ffffff
23 3 13 ffffff
24 3 13 ffffff
25 3 13 ffffff
26 3 13 ffffff
27 3 13 ffffff
28 3 13 ffffff
29 3 13 ffffff
30 3 13 ffffff
31 3 13 ffffff
16 4 13 ffffff
17 4 13 ffffff
18 4 13 ffffff
19 4 13 ffffff
20 4 13 ffffff
21 4 13 ffffff
22 4 13 ffffff
23 4 13 ffffff
24 4 13 ffffff
25 4 13 ffffff
26 4 13 ffffff
27 4 13 ffffff
28 4 13 ffffff
29 4 13 ffffff
30 4 13 ffffff
31 4 13 ffffff
16 5 13 ffffff
17 5 13 ffffff
18 5 13 ffffff
19 5 13 ffffff
20 5 13 ffffff
21 5 13 ffffff
22 5 13 ffffff
23 5 13 ffffff
24 5 13 ffffff
25 5 13 ffffff
26 5 13 ffffff
27 5 13 ffffff
28 5 13 ffffff
29 5 13 ffffff
30 5 13 ffffff
31 5 13 ffffff
16 6 13 ffffff
17 6 13 ffffff
18 6 13 ffffff
19 6 13 ffffff
20 6 13 ffffff
21 6 13 ffffff
22 6 13 ffffff
23 6 13 ffffff
24 6 13 ffffff
25 6 13 ffffff
26 6 13 ffffff
27 6 13 ffffff
28 6 13 ffffff
29 6 13 ffffff
30 6 13 ffffff
31 6 13 ffffff
16 7 13 ffffff
17 7 13 ffffff
18 7 13 ffffff
19 7 13 ffffff
20 7 13 ffffff
21 7 13 ffffff
22 7 13 ffffff
23 7 13 ffffff
24 7 13 ffffff
25 7 13 ffffff
26 7 13 ffffff
27 7 13 ffffff
28 7 13 ffffff
29 7 13 ffffff
30 7 13 ffffff
31 7 13 ffffff
16 8 13 ffffff
17 8 13 ffffff
18 8 13 ffffff
19 8 13 ffffff
20 8 13 ffffff
21 8 13 ffffff
22 8 13 ffffff
23 8 13 ffffff
24 8 13 ffffff
25 8 13 ffffff
26 8 13 ffffff
27 8 13 ffffff
28 8 13 ffffff
29 8 13 ffffff
30 8 13 ffffff
31 8 13 ffffff
16 9 13 ffffff
17 9 13 ffffff
18 9 13 ffffff
19 9 13 ffffff
20 9 13 ffffff
21 9 13 ffffff
22 9 13 ffffff
23 9 13 ffffff
24 9 13 ffffff
25 9 13 ffffff
26 9 13 ffffff
27 9 13 ffffff
28 9 13 ffffff
29 9 13 ffffff
30 9 13 ffffff
31 9 13 ffffff
16 10 13 ffffff
17 10 13 ffffff
18 10 13 ffffff
19 10 13 ffffff
20 10 13 ffffff
21 10 13 ffffff
22 10 13 ffffff
23 10 13 ffffff
24 10 13 ffffff
25 10 13 ffffff
26 10 13 ffffff
27 10 13 ffffff
28 10 13 ffffff
29 10 13 ffffff
30 10 13 ffffff
31 10 13 ffffff
16 11 13 ffffff
17 11 13 ffffff
18 11 13 ffffff
19 11 13 ffffff
20 11 13 ffffff
21 11 13 ffffff
22 11 13 ffffff
23 11 13 ffffff
24 11 13 ffffff
25 11 13 ffffff
26 11 13 ffffff
27 11 13 ffffff
28 11 13 ffffff
29 11 13 ffffff
30 11 13 ffffff
31 11 13 ffffff
16 12 13 ffffff
17 12 13 ffffff
18 12 13 ffffff
19 12 13 ffffff
20 12 13 ffffff
21 12 13 ffffff
22 12 13 ffffff
23 12 13 ffffff
24 12 13 ffffff
25 12 13 ffffff
26 12 13 ffffff
27 12 13 ffffff
28 12 13 ffffff
29 12 13 ffffff
30 12 13 ffffff
31 12 13 ffffff
16 13 13 ffffff
17 13 13 ffffff
18 13 13 ffffff
19 13 13 ffffff
20 13 13 ffffff
21 13 13 ffffff
22 13 13 ffffff
23 13 13 ffffff
24 13 13 ffffff
25 13 13 ffffff
26 13 13 ffffff
27 13 13 ffffff
28 13 13 ffffff
29 13 13 ffffff
30 13 13 ffffff
31 13 13 ffffff
16 14 13 ffffff
17 14 13 ffffff
18 14 13 ffffff
19 14 13 ffffff
20 14 13 ffffff
21 14 13 ffffff
22 14 13 ffffff
23 14 13 ffffff
24 14 13 ffffff
25 14 13 ffffff
26 14 13 ffffff
27 14 13 ffffff
28 14 13 ffffff
29 14 13 ffffff
30 14 13 ffffff
31 14 13 ffffff
16 15 13 ffffff
17 15 13 ffffff
18 15 13 ffffff
19 15 13 ffffff
20 15 13 ffffff
21 15 13 ffffff
22 15 13 ffffff
23 15 13 ffffff
24 15 13 ffffff
25 15 13 ffffff
26 15 13 ffffff
27 15 13 ffffff
28 15 13 ffffff
29 15 13 ffffff
30 15 13 ffffff
31 15 13 ffffff
16 0 14 ffffff
17 0 14 ffffff
27 0 14 ffffff
29 0 14 ffffff
31 0 14 ffffff
16 1 14 ffffff
17 1 14 ffffff
18 1 14 ffffff
19 1 14 ffffff
20 1 14 ffffff
21 1 14 ffffff
22 1 14 ffffff
23 1 14 ffffff
24 1 14 ffffff
25 1 14 ffffff
26 1 14 ffffff
27 1 14 ffffff
28 1 14 ffffff
29 1 14 ffffff
30 1 14 ffffff
31 1 14 ffffff
16 2 14 ffffff
17 2 14 ffffff
18 2 14 ffffff
19 2 14 ffffff
20 2 14 ffffff
21 2 14 ffffff
22 2 14 ffffff
23 2 14 ffffff
24 2 14 ffffff
25 2 14 ffffff
26 2 14 ffffff
27 2 14 ffffff
28 2 14 ffffff
29 2 14 ffffff
30 2 14 ffffff
31 2 14 ffffff
16 3 14 ffffff
17 3 14 ffffff
18 3 14 ffffff
19 3 14 ffffff
20 3 14 ffffff
21 3 14 ffffff
22 3 14 ffffff
23 3 14 ffffff
24 3 14 ffffff
25 3 14 ffffff
26 3 14 ffffff
27 3 14 ffffff
28 3 14 ffffff
29 3 14 ffffff
30 3 14 ffffff
31 3 14 ffffff
16 4 14 ffffff
17 4 14 ffffff
18 4 14 ffffff
19 4 14 ffffff
20 4 14 ffffff
21 4 14 ffffff
22 4 14 ffffff
23 4 14 ffffff
24 4 14 ffffff
25 4 14 ffffff
26 4 14 ffffff
27 4 14 ffffff
28 4 14 ffffff
29 4 14 ffffff
30 4 14 ffffff
31 4 14 ffffff
16 5 14 ffffff
17 5 14 ffffff
18 5 14 ffffff
19 5 14 ffffff
20 5 14 ffffff
21 5 14 ffffff
22 5 14 ffffff
23 5 14 ffffff
24 5 14 ffffff
25 5 14 ffffff
26 5 14 ffffff
27 5 14 ffffff
28 5 14 ffffff
29 5 14 ffffff
30 5 14 ffffff
31 5 14 ffffff
16 6 14 ffffff
17 6 14 ffffff
18 6 14 ffffff
19 6 14 ffffff
20 6 14 ffffff
21 6 14 ffffff
22 6 14 ffffff
23 6 14 ffffff
24 6 14 ffffff
25 6 14 ffffff
26 6 14 ffffff
27 6 14 ffffff
28 6 14 ffffff
29 6 14 ffffff
30 6 14 ffffff
31 6 14 ffffff
16 7 14 ffffff
17 7 14 ffffff
18 7 14 ffffff
19 7 14 ffffff
20 7 14 ffffff
21 7 14 ffffff
22 7 14 ffffff
23 7 14 ffffff
24 7 14 ffffff
25 7 14 ffffff
26 7 14 ffffff
27 7 14 ffffff
28 7 14 ffffff
29 7 14 ffffff
30 7 14 ffffff
31 7 14 ffffff
16 8 14 ffffff
17 8 14 ffffff
18 8 14 ffffff
19 8 14 ffffff
20 8 14 ffffff
21 8 14 ffffff
22 8 14 ffffff
23 8 14 ffffff
24 8 14 ffffff
25 8 14 ffffff
26 8 14 ffffff
27 8 14 ffffff
28 8 14 ffffff
29 8 14 ffffff
30 8 14 ffffff
31 8 14 ffffff
16 9 14 ffffff
17 9 14 ffffff
18 9 14 ffffff
19 9 14 ffffff
20 9 14 ffffff
21 9 14 ffffff
22 9 14 ffffff
23 9 14 ffffff
24 9 14 ffffff
25 9 14 ffffff
26 9 14 ffffff
27 9 14 ffffff
28 9 14 ffffff
29 9 14 ffffff
30 9 14 ffffff
31 9 14 ffffff
16 10 14 ffffff
17 10 14 ffffff
18 10 14 ffffff
19 10 14 ffffff
20 10 14 ffffff
21 10 14 ffffff
22 10 14 ffffff
23 10 14 ffffff
24 10 14 ffffff
25 10 14 ffffff
26 10 14 ffffff
27 10 14 ffffff
28 10 14 ffffff
29 10 14 ffffff
30 10 14 ffffff
31 10 14 ffffff
16 11 14 ffffff
17 11 14 ffffff
18 11 14 ffffff
19 11 14 ffffff
20 11 14 ffffff
21 11 14 ffffff
22 11 14 ffffff
23 11 14 ffffff
24 11 14 ffffff
25 11 14 ffffff
26 11 14 ffffff
27 11 14 ffffff
28 11 14 ffffff
29 11 14 ffffff
30 11 14 ffffff
31 11 14 ffffff
16 12 14 ffffff
17 12 14 ffffff
18 12 14 ffffff
19 12 14 ffffff
20 12 14 ffffff
21 12 14 ffffff
22 12 14 ffffff
23 12 14 ffffff
24 12 14 ffffff
25 12 14 ffffff
26 12 14 ffffff
27 12 14 ffffff
28 12 14 ffffff
29 12 14 ffffff
30 12 14 ffffff
31 12 14 ffffff
16 13 14 ffffff
17 13 14 ffffff
18 13 14 ffffff
19 13 14 ffffff
20 13 14 ffffff
21 13 14 ffffff
22 13 14 ffffff
23 13 14 ffffff
24 13 14 ffffff
25 13 14 ffffff
26 13 14 ffffff
27 13 14 ffffff
28 13 14 ffffff
29 13 14 ffffff
30 13 14 ffffff
31 13 14 ffffff
16 14 14 ffffff
17 14 14 ffffff
18 14 14 ffffff
19 14 14 ffffff
20 14 14 ffffff
21 14 14 ffffff
22 14 14 ffffff
23 14 14 ffffff
24 14 14 ffffff
25 14 14 ffffff
26 14 14 ffffff
27 14 14 ffffff
28 14 14 ffffff
29 14 14 ffffff
30 14 14 ffffff
31 14 14 ffffff
16 15 14 ffffff
17 15 14 ffffff
18 15 14 ffffff
19 15 14 ffffff
20 15 14 ffffff
21 15 14 ffffff
22 15 14 ffffff
23 15 14 ffffff
24 15 14 ffffff
25 15 14 ffffff
26 15 14 ffffff
27 15 14 ffffff
28 15 14 ffffff
29 15 14 ffffff
30 15 14 ffffff
31 15 14 ffffff
16 0 15 ffffff
17 0 15 ffffff
27 0 15 ffffff
29 0 15 ffffff
31 0 15 ffffff
16 1 15 ffffff
17 1 15 ffffff
18 1 15 ffffff
19 1 15 ffffff
20 1 15 ffffff
21 1 15 ffffff
22 1 15 ffffff
23 1 15 ffffff
24 1 15 ffffff
25 1 15 ffffff
26 1 15 ffffff
27 1 15 ffffff
28 1 15 ffffff
29 1 15 ffffff
30 1 15 ffffff
31 1 15 ffffff
16 2 15 ffffff
17 2 15 ffffff
18 2 15 ffffff
19 2 15 ffffff
20 2 15 ffffff
21 2 15 ffffff
22 2 15 ffffff
23 2 15 ffffff
24 2 15 ffffff
25 2 15 ffffff
26 2 15 ffffff
27 2 15 ffffff
28 2 15 ffffff
29 2 15 ffffff
30 2 15 ffffff
31 2 15 ffffff
16 3 15 ffffff
17 3 15 ffffff
18 3 15 ffffff
19 3 15 ffffff
20 3 15 ffffff
21 3 15 ffffff
22 3 15 ffffff
23 3 15 ffffff
24 3 15 ffffff
25 3 15 ffffff
26 3 15 ffffff
27 3 15 ffffff
28 3 15 ffffff
29 3 15 ffffff
30 3 15 ffffff
31 3 15 ffffff
16 4 15 ffffff
17 4 15 ffffff
18 4 15 ffffff
19 4 15 ffffff
20 4 15 ffffff
21 4 15 ffffff
22 4 15 ffffff
23 4 15 ffffff
24 4 15 ffffff
25 4 15 ffffff
26 4 15 ffffff
27 4 15 ffffff
28 4 15 ffffff
29 4 15 ffffff
30 4 15 ffffff
31 4 15 ffffff
16 5 15 ffffff
17 5 15 ffffff
18 5 15 ffffff
19 5 15 ffffff
20 5 15 ffffff
21 5 15 ffffff
22 5 15 ffffff
23 5 15 ffffff
24 5 15 ffffff
25 5 15 ffffff
26 5 15 ffffff
27 5 15 ffffff
28 5 15 ffffff
29 5 15 ffffff
30 5 15 ffffff
31 5 15 ffffff
16 6 15 ffffff
17 6 15 ffffff
18 6 15 ffffff
19 6 15 ffffff
20 6 15 ffffff
21 6 15 ffffff
22 6 15 ffffff
23 6 15 ffffff
24 6 15 ffffff
25 6 15 ffffff
26 6 15 ffffff
27 6 15 ffffff
28 6 15 ffffff
29 6 15 ffffff
30 6 15 ffffff
31 6 15 ffffff
16 7 15 ffffff
17 7 15 ffffff
18 7 15 ffffff
19 7 15 ffffff
20 7 15 ffffff
21 7 15 ffffff
22 7 15 ffffff
23 7 15 ffffff
24 7 15 ffffff
25 7 15 ffffff
26 7 15 ffffff
27 7 15 ffffff
28 7 15 ffffff
29 7 15 ffffff
30 7 15 ffffff
31 7 15 ffffff
16 8 15 ffffff
17 8 15 ffffff
18 8 15 ffffff
19 8 15 ffffff
20 8 15 ffffff
21 8 15 ffffff
22 8 15 ffffff
23 8 15 ffffff
24 8 15 ffffff
25 8 15 ffffff
26 8 15 ffffff
27 8 15 ffffff
28 8 15 ffffff
29 8 15 ffffff
30 8 15 ffffff
31 8 15 ffffff
16 9 15 ffffff
17 9 15 ffffff
18 9 15 ffffff
19 9 15 ffffff
20 9 15 ffffff
21 9 15 ffffff
22 9 15 ffffff
23 9 15 ffffff
24 9 15 ffffff
25 9 15 ffffff
26 9 15 ffffff
27 9 15 ffffff
28 9 15 ffffff
29 9 15 ffffff
30 9 15 ffffff
31 9 15 ffffff
16 10 15 ffffff
17 10 15 ffffff
18 10 15 ffffff
19 10 15 ffffff
20 10 15 ffffff
21 10 15 ffffff
22 10 15 ffffff
23 10 15 ffffff
24 10 15 ffffff
25 10 15 ffffff
26 10 15 ffffff
27 10 15 ffffff
28 10 15 ffffff
29 10 15 ffffff
30 10 15 ffffff
31 10 15 ffffff
16 11 15 ffffff
17 11 15 ffffff
18 11 15 ffffff
19 11 15 ffffff
20 11 15 ffffff
21 11 15 ffffff
22 11 15 ffffff
23 11 15 ffffff
24 11 15 ffffff
25 11 15 ffffff
26 11 15 ffffff
27 11 15 ffffff
28 11 15 ffffff
29 11 15 ffffff
30 11 15 ffffff
31 11 15 ffffff
16 12 15 ffffff
17 12 15 ffffff
18 12 15 ffffff
19 12 15 ffffff
20 12 15 ffffff
21 12 15 ffffff
22 12 15 ffffff
23 12 15 ffffff
24 12 15 ffffff
25 12 15 ffffff
26 12 15 ffffff
27 12 15 ffffff
28 12 15 ffffff
29 12 15 ffffff
30 12 15 ffffff
31 12 15 ffffff
16 13 15 ffffff
17 13 15 ffffff
18 13 15 ffffff
19 13 15 ffffff
20 13 15 ffffff
21 13 15 ffffff
22 13 15 ffffff
23 13 15 ffffff
24 13 15 ffffff
25 13 15 ffffff
26 13 15 ffffff
27 13 15 ffffff
28 13 15 ffffff
29 13 15 ffffff
30 13 15 ffffff
31 13 15 ffffff
16 14 15 ffffff
17 14 15 ffffff
18 14 15 ffffff
19 14 15 ffffff
20 14 15 ffffff
21 14 15 ffffff
22 14 15 ffffff
23 14 15 ffffff
24 14 15 ffffff
25 14 15 ffffff
26 14 15 ffffff
27 14 15 ffffff
28 14 15 ffffff
29 14 15 ffffff
30 14 15 ffffff
31 14 15 ffffff
16 15 15 ffffff
17 15 15 ffffff
18 15 15 ffffff
19 15 15 ffffff
20 15 15 ffffff
21 15 15 ffffff
22 15 15 ffffff
23 15 15 ffffff
24 15 15 ffffff
25 15 15 ffffff
26 15 15 ffffff
27 15 15 ffffff
28 15 15 ffffff
29 15 15 ffffff
30 15 15 ffffff
31 15 15 ffffff
32 0 3 ffffff
33 0 3 ffffff
34 0 3 ffffff
35 0 3 ffffff
36 0 3 ffffff
37 0 3 ffffff
38 0 3 ffffff
39 0 3 ffffff
40 0 3 ffffff
41 0 3 ffffff
42 0 3 ffffff
43 0 3 ffffff
44 0 3 ffffff
45 0 3 ffffff
46 0 3 ffffff
47 0 3 ffffff
32 1 3 ffffff
33 1 3 ffffff
34 1 3 ffffff
35 1 3 ffffff
36 1 3 ffffff
37 1 3 ffffff
38 1 3 ffffff
39 1 3 ffffff
40 1 3 ffffff
41 1 3 ffffff
42 1 3 ffffff
43 1 3 ffffff
44 1 3 ffffff
45 1 3 ffffff
46 1 3 ffffff
47 1 3 ffffff
32 2 3 ffffff
33 2 3 ffffff
34 2 3 ffffff
35 2 3 ffffff
36 2 3 ffffff
37 2 3 ffffff
38 2 3 ffffff
39 2 3 ffffff
40 2 3 ffffff
41 2 3 ffffff
42 2 3 ffffff
43 2 3 ffffff
44 2 3 ffffff
45 2 3 ffffff
46 2 3 ffffff
47 2 3 ffffff
32 3 3 ffffff
33 3 3 ffffff
34 3 3 ffffff
35 3 3 ffffff
36 3 3 ffffff
37 3 3 ffffff
38 3 3 ffffff
39 3 3 ffffff
40 3 3 ffffff
41 3 3 ffffff
42 3 3 ffffff
43 3 3 ffffff
44 3 3 ffffff
45 3 3 ffffff
46 3 3 ffffff
47 3 3 ffffff
32 4 3 ffffff
33 4 3 ffffff
34 4 3 ffffff
35 4 3 ffffff
36 4 3 ffffff
37 4 3 ffffff
38 4 3 ffffff
39 4 3 ffffff
40 4 3 ffffff
41 4 3 ffffff
42 4 3 ffffff
43 4 3 ffffff
44 4 3 ffffff
45 4 3 ffffff
46 4 3 ffffff
47 4 3 ffffff
32 5 3 ffffff
33 5 3 ffffff
34 5 3 ffffff
35 5 3 ffffff
36 5 3 ffffff
37 5 3 ffffff
38 5 3 ffffff
39 5 3 ffffff
40 5 3 ffffff
41 5 3 ffffff
42 5 3 ffffff
43 5 3 ffffff
44 5 3 ffffff
45 5 3 ffffff
46 5 3 ffffff
47 5 3 ffffff
32 6 3 ffffff
33 6 3 ffffff
34 6 3 ffffff
35 6 3 ffffff
36 6 3 ffffff
37 6 3 ffffff
38 6 3 ffffff
39 6 3 ffffff
40 6 3 ffffff
41 6 3 ffffff
42 6 3 ffffff
43 6 3 ffffff
44 6 3 ffffff
45 6 3 ffffff
46 6 3 ffffff
47 6 3 ffffff
32 7 3 ffffff
33 7 3 ffffff
34 7 3 ffffff
35 7 3 ffffff
36 7 3 ffffff
37 7 3 ffffff
38 7 3 ffffff
39 7 3 ffffff
40 7 3 ffffff
41 7 3 ffffff
42 7 3 ffffff
43 7 3 ffffff
44 7 3 ffffff
45 7 3 ffffff
46 7 3 ffffff
47 7 3 ffffff
32 8 3 ffffff
33 8 3 ffffff
34 8 3 ffffff
35 8 3 ffffff
36 8 3 ffffff
37 8 3 ffffff
38 8 3 ffffff
39 8 3 ffffff
40 8 3 ffffff
41 8 3 ffffff
42 8 3 ffffff
43 8 3 ffffff
44 8 3 ffffff
45 8 3 ffffff
46 8 3 ffffff
47 8 3 ffffff
32 9 3 ffffff
33 9 3 ffffff
34 9 3 ffffff
35 9 3 ffffff
36 9 3 ffffff
37 9 3 ffffff
38 9 3 ffffff
39 9 3 ffffff
40 9 3 ffffff
41 9 3 ffffff
42 9 3 ffffff
43 9 3 ffffff
44 9 3 ffffff
45 9 3 ffffff
46 9 3 ffffff
47 9 3 ffffff
32 10 3 ffffff
33 10 3 ffffff
34 10 3 ffffff
35 10 3 ffffff
36 10 3 ffffff
37 10 3 ffffff
38 10 3 ffffff
39 10 3 ffffff
40 10 3 ffffff
41 10 3 ffffff
42 10 3 ffffff
43 10 3 ffffff
44 10 3 ffffff
45 10 3 ffffff
46 10 3 ffffff
47 10 3 ffffff
32 11 3 ffffff
33 11 3 ffffff
34 11 3 ffffff
35 11 3 ffffff
36 11 3 ffffff
37 11 3 ffffff
38 11 3 ffffff
39 11 3 ffffff
40 11 3 ffffff
41 11 3 ffffff
42 11 3 ffffff
43 11 3 ffffff
44 11 3 ffffff
45 11 3 ffffff
46 11 3 ffffff
47 11 3 ffffff
32 12 3 ffffff
33 12 3 ffffff
34 12 3 ffffff
35 12 3 ffffff
36 12 3 ffffff
37 12 3 ffffff
38 12 3 ffffff
39 12 3 ffffff
40 12 3 ffffff
41 12 3 ffffff
42 12 3 ffffff
43 12 3 ffffff
44 12 3 ffffff
45 12 3 ffffff
46 12 3 ffffff
47 12 3 ffffff
32 13 3 ffffff
33 13 3 ffffff
34 13 3 ffffff
35 13 3 ffffff
36 13 3 ffffff
37 13 3 ffffff
38 13 3 ffffff
39 13 3 ffffff
40 13 3 ffffff
41 13 3 ffffff
42 13 3 ffffff
43 13 3 ffffff
44 13 3 ffffff
45 13 3 ffffff
46 13 3 ffffff
47 13 3 ffffff
32 14 3 ffffff
33 14 3 ffffff
34 14 3 ffffff
35 14 3 ffffff
36 14 3 ffffff
37 14 3 ffffff
38 14 3 ffffff
39 14 3 ffffff
40 14 3 ffffff
41 14 3 ffffff
42 14 3 ffffff
43 14 3 ffffff
44 14 3 ffffff
45 14 3 ffffff
46 14 3 ffffff
47 14 3 ffffff
32 15 3 ffffff
33 15 3 ffffff
34 15 3 ffffff
35 15 3 ffffff
36 15 3 ffffff
37 15 3 ffffff
38 15 3 ffffff
39 15 3 ffffff
40 15 3 ffffff
41 15 3 ffffff
42 15 3 ffffff
43 15 3 ffffff
44 15 3 ffffff
45 15 3 ffffff
46 15 3 ffffff
47 15 3 ffffff
32 0 4 ffffff
33 0 4 ffffff
34 0 4 ffffff
35 0 4 ffffff
36 0 4 ffffff
37 0 4 ffffff
38 0 4 ffffff
39 0 4 ffffff
40 0 4 ffffff
41 0 4 ffffff
42 0 4 ffffff
43 0 4 ffffff
44 0 4 ffffff
45 0 4 ffffff
46 0 4 ffffff
47 0 4 ffffff
32 1 4 ffffff
33 1 4 ffffff
34 1 4 ffffff
35 1 4 ffffff
36 1 4 ffffff
37 1 4 ffffff
38 1 4 ffffff
39 1 4 ffffff
40 1 4 ffffff
41 1 4 ffffff
42 1 4 ffffff
43 1 4 ffffff
44 1 4 ffffff
45 1 4 ffffff
46 1 4 ffffff
47 1 4 ffffff
32 2 4 ffffff
33 2 4 ffffff
34 2 4 ffffff
35 2 4 ffffff
36 2 4 ffffff
37 2 4 ffffff
38 2 4 ffffff
39 2 4 ffffff
40 2 4 ffffff
41 2 4 ffffff
42 2 4 ffffff
43 2 4 ffffff
44 2 4 ffffff
45 2 4 ffffff
46 2 4 ffffff
47 2 4 ffffff
32 3 4 ffffff
33 3 4 ffffff
34 3 4 ffffff
35 3 4 ffffff
36 3 4 ffffff
37 3 4 ffffff
38 3 4 ffffff
39 3 4 ffffff
40 3 4 ffffff
41 3 4 ffffff
42 3 4 ffffff
43 3 4 ffffff
44 3 4 ffffff
45 3 4 ffffff
46 3 4 ffffff
47 3 4 ffffff
32 4 4 ffffff
33 4 4 ffffff
34 4 4 ffffff
35 4 4 ffffff
36 4 4 ffffff
37 4 4 ffffff
38 4 4 ffffff
39 4 4 ffffff
40 4 4 ffffff
41 4 4 ffffff
42 4 4 ffffff
43 4 4 ffffff
44 4 4 ffffff
45 4 4 ffffff
46 4 4 ffffff
47 4 4 ffffff
32 5 4 ffffff
33 5 4 ffffff
34 5 4 ffffff
35 5 4 ffffff
36 5 4 ffffff
37 5 4 ffffff
38 5 4 ffffff
39 5 4 ffffff
40 5 4 ffffff
41 5 4 ffffff
42 5 4 ffffff
43 5 4 ffffff
44 5 4 ffffff
45 5 4 ffffff
46 5 4 ffffff
47 5 4 ffffff
32 6 4 ffffff
33 6 4 ffffff
34 6 4 ffffff
35 6 4 ffffff
36 6 4 ffffff
37 6 4 ffffff
38 6 4 ffffff
39 6 4 ffffff
40 6 4 ffffff
41 6 4 ffffff
42 6 4 ffffff
43 6 4 ffffff
44 6 4 ffffff
45 6 4 ffffff
46 6 4 ffffff
47 6 4 ffffff
32 7 4 ffffff
33 7 4 ffffff
34 7 4 ffffff
35 7 4 ffffff
36 7 4 ffffff
37 7 4 ffffff
38 7 4 ffffff
39 7 4 ffffff
40 7 4 ffffff
41 7 4 ffffff
42 7 4 ffffff
43 7 4 ffffff
44 7 4 ffffff
45 7 4 ffffff
46 7 4 ffffff
47 7 4 ffffff
32 8 4 ffffff
33 8 4 ffffff
34 8 4 ffffff
35 8 4 ffffff
36 8 4 ffffff
37 8 4 ffffff
38 8 4 ffffff
39 8 4 ffffff
40 8 4 ffffff
41 8 4 ffffff
42 8 4 ffffff
43 8 4 ffffff
44 8 4 ffffff
45 8 4 ffffff
46 8 4 ffffff
47 8 4 ffffff
32 9 4 ffffff
33 9 4 ffffff
34 9 4 ffffff
35 9 4 ffffff
36 9 4 ffffff
37 9 4 ffffff
38 9 4 ffffff
39 9 4 ffffff
40 9 4 ffffff
41 9 4 ffffff
42 9 4 ffffff
43 9 4 ffffff
44 9 4 ffffff
45 9 4 ffffff
46 9 4 ffffff
47 9 4 ffffff
32 10 4 ffffff
33 10 4 ffffff
34 10 4 ffffff
35 10 4 ffffff
36 10 4 ffffff
37 10 4 ffffff
38 10 4 ffffff
39 10 4 ffffff
40 10 4 ffffff
41 10 4 ffffff
42 10 4 ffffff
43 10 4 ffffff
44 10 4 ffffff
45 10 4 ffffff
46 10 4 ffffff
47 10 4 ffffff
32 11 4 ffffff
33 11 4 ffffff
34 11 4 ffffff
35 11 4 ffffff
36 11 4 ffffff
37 11 4 ffffff
38 11 4 ffffff
39 11 4 ffffff
40 11 4 ffffff
41 11 4 ffffff
42 11 4 ffffff
43 11 4 ffffff
44 11 4 ffffff
45 11 4 ffffff
46 11 4 ffffff
47 11 4 ffffff
32 12 4 ffffff
33 12 4 ffffff
34 12 4 ffffff
35 12 4 ffffff
36 12 4 ffffff
37 12 4 ffffff
38 12 4 ffffff
39 12 4 ffffff
40 12 4 ffffff
41 12 4 ffffff
42 12 4 ffffff
43 12 4 ffffff
44 12 4 ffffff
45 12 4 ffffff
46 12 4 ffffff
47 12 4 ffffff
32 13 4 ffffff
33 13 4 ffffff
34 13 4 ffffff
35 13 4 ffffff
36 13 4 ffffff
37 13 4 ffffff
38 13 4 ffffff
39 13 4 ffffff
40 13 4 ffffff
41 13 4 ffffff
42 13 4 ffffff
43 13 4 ffffff
44 13 4 ffffff
45 13 4 ffffff
46 13 4 ffffff
47 13 4 ffffff
32 14 4 ffffff
33 14 4 ffffff
34 14 4 ffffff
35 14 4 ffffff
36 14 4 ffffff
37 14 4 ffffff
38 14 4 ffffff
39 14 4 ffffff
40 14 4 ffffff
41 14 4 ffffff
42 14 4 ffffff
43 14 4 ffffff
44 14 4 ffffff
45 14 4 ffffff
46 14 4 ffffff
47 14 4 ffffff
32 15 4 ffffff
33 15 4 ffffff
34 15 4 ffffff
35 15 4 ffffff
36 15 4 ffffff
37 15 4 ffffff
38 15 4 ffffff
39 15 4 ffffff
40 15 4 ffffff
41 15 4 ffffff
42 15 4 ffffff
43 15 4 ffffff
44 15 4 ffffff
45 15 4 ffffff
46 15 4 ffffff
47 15 4 ffffff
41 0 5 ffffff
42 0 5 ffffff
32 1 5 ffffff
33 1 5 ffffff
34 1 5 ffffff
35 1 5 ffffff
36 1 5 ffffff
