# Goxel 0.15.1
# One line per voxel
# X Y Z RRGGBB
32 36 1 ff00aa
33 36 1 ff00aa
34 36 1 ffffaa
35 36 1 ffffaa
36 36 1 ffffaa
37 36 1 ffffaa
38 36 1 ffffaa
46 36 1 ff00aa
47 36 1 ff00aa
33 37 1 ff00aa
39 37 1 aabbff
46 37 1 ff00aa
33 38 1 ff00aa
39 38 1 aabbff
46 38 1 ff00aa
33 39 1 ff00aa
39 39 1 aabbff
46 39 1 ff00aa
33 40 1 ff00aa
39 40 1 aabbff
46 40 1 ff00aa
33 41 1 ff00aa
39 41 1 aabbff
46 41 1 ff00aa
33 42 1 ff00aa
39 42 1 aabbff
46 42 1 ff00aa
33 43 1 ff00aa
39 43 1 aabbff
46 43 1 ff00aa
33 44 1 ff00aa
39 44 1 aabbff
46 44 1 ff00aa
33 45 1 ff00aa
46 45 1 ff00aa
33 46 1 ff00aa
46 46 1 ff00aa
32 47 1 ff0000
33 47 1 ff0000
34 47 1 ff0000
35 47 1 ff0000
36 47 1 ff0000
37 47 1 ff0000
38 47 1 ff0000
39 47 1 ff0000
40 47 1 ff0000
41 47 1 ff0000
42 47 1 ff0000
43 47 1 ff0000
44 47 1 ff0000
45 47 1 ff0000
46 47 1 ff0000
47 47 1 ff0000
32 36 2 ff00aa
33 36 2 ff00aa
46 36 2 ff00aa
47 36 2 ff00aa
33 37 2 ff00aa
34 37 2 ffffaa
35 37 2 ffffaa
36 37 2 ffffaa
37 37 2 ffffaa
38 37 2 ffffaa
39 37 2 aabbff
46 37 2 ff00aa
33 38 2 ff00aa
39 38 2 aabbff
46 38 2 ff00aa
33 39 2 ff00aa
39 39 2 aabbff
46 39 2 ff00aa
33 40 2 ff00aa
39 40 2 aabbff
46 40 2 ff00aa
33 41 2 ff00aa
39 41 2 aabbff
46 41 2 ff00aa
33 42 2 ff00aa
39 42 2 aabbff
46 42 2 ff00aa
33 43 2 ff00aa
39 43 2 aabbff
46 43 2 ff00aa
33 44 2 ff00aa
39 44 2 aabbff
46 44 2 ff00aa
33 45 2 ff00aa
46 45 2 ff00aa
33 46 2 ff00aa
46 46 2 ff00aa
32 47 2 ff0000
33 47 2 ff0000
34 47 2 ff0000
35 47 2 ff0000
36 47 2 ff0000
37 47 2 ff0000
38 47 2 ff0000
39 47 2 ff0000
40 47 2 ff0000
41 47 2 ff0000
42 47 2 ff0000
43 47 2 ff0000
44 47 2 ff0000
45 47 2 ff0000
46 47 2 ff0000
47 47 2 ff0000
32 36 3 ff00aa
33 36 3 ff00aa
46 36 3 ff00aa
47 36 3 ff00aa
33 37 3 ff00aa
39 37 3 aabbff
46 37 3 ff00aa
33 38 3 ff00aa
34 38 3 ffbbaa
35 38 3 ffbbaa
36 38 3 ffbbaa
37 38 3 ffbbaa
38 38 3 ffbbaa
39 38 3 aabbff
46 38 3 ff00aa
33 39 3 ff00aa
39 39 3 aabbff
46 39 3 ff00aa
33 40 3 ff00aa
39 40 3 aabbff
46 40 3 ff00aa
33 41 3 ff00aa
39 41 3 aabbff
46 41 3 ff00aa
33 42 3 ff00aa
39 42 3 aabbff
46 42 3 ff00aa
33 43 3 ff00aa
39 43 3 aabbff
46 43 3 ff00aa
33 44 3 ff00aa
39 44 3 aabbff
46 44 3 ff00aa
33 45 3 ff00aa
46 45 3 ff00aa
33 46 3 ff00aa
46 46 3 ff00aa
32 47 3 ff0000
33 47 3 ff0000
34 47 3 ff0000
35 47 3 ff0000
36 47 3 ff0000
37 47 3 ff0000
38 47 3 ff0000
39 47 3 ff0000
40 47 3 ff0000
41 47 3 ff0000
42 47 3 ff0000
43 47 3 ff0000
44 47 3 ff0000
45 47 3 ff0000
46 47 3 ff0000
47 47 3 ff0000
32 36 4 ff00aa
33 36 4 ff00aa
46 36 4 ff00aa
47 36 4 ff00aa
33 37 4 ff00aa
39 37 4 aabbff
46 37 4 ff00aa
33 38 4 ff00aa
39 38 4 aabbff
46 38 4 ff00aa
33 39 4 ff00aa
34 39 4 ffbbaa
35 39 4 ffbbaa
36 39 4 ffbbaa
37 39 4 ffbbaa
38 39 4 ffbbaa
39 39 4 aabbff
46 39 4 ff00aa
33 40 4 ff00aa
39 40 4 aabbff
46 40 4 ff00aa
33 41 4 ff00aa
39 41 4 aabbff
46 41 4 ff00aa
33 42 4 ff00aa
39 42 4 aabbff
46 42 4 ff00aa
33 43 4 ff00aa
39 43 4 aabbff
46 43 4 ff00aa
33 44 4 ff00aa
39 44 4 aabbff
46 44 4 ff00aa
33 45 4 ff00aa
46 45 4 ff00aa
33 46 4 ff00aa
46 46 4 ff00aa
32 47 4 ff0000
33 47 4 ff0000
34 47 4 ff0000
35 47 4 ff0000
36 47 4 ff0000
37 47 4 ff0000
38 47 4 ff0000
39 47 4 ff0000
40 47 4 ff0000
41 47 4 ff0000
42 47 4 ff0000
43 47 4 ff0000
44 47 4 ff0000
45 47 4 ff0000
46 47 4 ff0000
47 47 4 ff0000
32 36 5 ff00aa
33 36 5 ff00aa
46 36 5 ff00aa
47 36 5 ff00aa
33 37 5 ff00aa
39 37 5 aabbff
46 37 5 ff00aa
33 38 5 ff00aa
39 38 5 aabbff
46 38 5 ff00aa
33 39 5 ff00aa
39 39 5 aabbff
46 39 5 ff00aa
33 40 5 ff00aa
34 40 5 ffba0a
35 40 5 ffba0a
36 40 5 ffba0a
37 40 5 ffba0a
38 40 5 ffba0a
39 40 5 aabbff
46 40 5 ff00aa
33 41 5 ff00aa
39 41 5 aabbff
46 41 5 ff00aa
33 42 5 ff00aa
39 42 5 aabbff
46 42 5 ff00aa
33 43 5 ff00aa
39 43 5 aabbff
46 43 5 ff00aa
33 44 5 ff00aa
39 44 5 aabbff
46 44 5 ff00aa
33 45 5 ff00aa
46 45 5 ff00aa
33 46 5 ff00aa
46 46 5 ff00aa
32 47 5 ff0000
33 47 5 ff0000
34 47 5 ff0000
35 47 5 ff0000
36 47 5 ff0000
37 47 5 ff0000
38 47 5 ff0000
39 47 5 ff0000
40 47 5 ff0000
41 47 5 ff0000
42 47 5 ff0000
43 47 5 ff0000
44 47 5 ff0000
45 47 5 ff0000
46 47 5 ff0000
47 47 5 ff0000
32 36 6 ff00aa
33 36 6 ff00aa
46 36 6 ff00aa
47 36 6 ff00aa
33 37 6 ff00aa
39 37 6 aabbff
46 37 6 ff00aa
33 38 6 ff00aa
39 38 6 aabbff
46 38 6 ff00aa
33 39 6 ff00aa
39 39 6 aabbff
46 39 6 ff00aa
33 40 6 ff00aa
39 40 6 aabbff
46 40 6 ff00aa
33 41 6 ff00aa
34 41 6 ffba0a
35 41 6 ffba0a
36 41 6 ffba0a
37 41 6 ffba0a
38 41 6 ffba0a
39 41 6 aabbff
46 41 6 ff00aa
33 42 6 ff00aa
39 42 6 aabbff
46 42 6 ff00aa
33 43 6 ff00aa
39 43 6 aabbff
46 43 6 ff00aa
33 44 6 ff00aa
39 44 6 aabbff
46 44 6 ff00aa
33 45 6 ff00aa
46 45 6 ff00aa
33 46 6 ff00aa
46 46 6 ff00aa
32 47 6 ff0000
33 47 6 ff0000
34 47 6 ff0000
35 47 6 ff0000
36 47 6 ff0000
37 47 6 ff0000
38 47 6 ff0000
39 47 6 ff0000
40 47 6 ff0000
41 47 6 ff0000
42 47 6 ff0000
43 47 6 ff0000
44 47 6 ff0000
45 47 6 ff0000
46 47 6 ff0000
47 47 6 ff0000
32 36 7 ff00aa
33 36 7 ff00aa
46 36 7 ff00aa
47 36 7 ff00aa
33 37 7 ff00aa
39 37 7 aabbff
46 37 7 ff00aa
33 38 7 ff00aa
39 38 7 aabbff
46 38 7 ff00aa
33 39 7 ff00aa
39 39 7 aabbff
46 39 7 ff00aa
33 40 7 ff00aa
39 40 7 aabbff
46 40 7 ff00aa
33 41 7 ff00aa
39 41 7 aabbff
46 41 7 ff00aa
33 42 7 ff00aa
34 42 7 ffba0a
35 42 7 ffba0a
36 42 7 ffba0a
37 42 7 ffba0a
38 42 7 ffba0a
39 42 7 aabbff
46 42 7 ff00aa
33 43 7 ff00aa
39 43 7 aabbff
46 43 7 ff00aa
33 44 7 ff00aa
39 44 7 aabbff
46 44 7 ff00aa
33 45 7 ff00aa
46 45 7 ff00aa
33 46 7 ff00aa
46 46 7 ff00aa
32 47 7 ff0000
33 47 7 ff0000
34 47 7 ff0000
35 47 7 ff0000
36 47 7 ff0000
37 47 7 ff0000
38 47 7 ff0000
39 47 7 ff0000
40 47 7 ff0000
41 47 7 ff0000
42 47 7 ff0000
43 47 7 ff0000
44 47 7 ff0000
45 47 7 ff0000
46 47 7 ff0000
47 47 7 ff0000
32 36 8 ff00aa
33 36 8 ff00aa
46 36 8 ff00aa
47 36 8 ff00aa
33 37 8 ff00aa
39 37 8 aabbff
46 37 8 ff00aa
33 38 8 ff00aa
39 38 8 aabbff
46 38 8 ff00aa
33 39 8 ff00aa
39 39 8 aabbff
46 39 8 ff00aa
33 40 8 ff00aa
39 40 8 aabbff
46 40 8 ff00aa
33 41 8 ff00aa
39 41 8 aabbff
46 41 8 ff00aa
33 42 8 ff00aa
39 42 8 aabbff
46 42 8 ff00aa
33 43 8 ff00aa
34 43 8 ffba0a
35 43 8 ffba0a
36 43 8 ffba0a
37 43 8 ffba0a
38 43 8 ffba0a
39 43 8 aabbff
46 43 8 ff00aa
33 44 8 ff00aa
39 44 8 aabbff
46 44 8 ff00aa
33 45 8 ff00aa
46 45 8 ff00aa
33 46 8 ff00aa
46 46 8 ff00aa
32 47 8 ff0000
33 47 8 ff0000
34 47 8 ff0000
35 47 8 ff0000
36 47 8 ff0000
37 47 8 ff0000
38 47 8 ff0000
39 47 8 ff0000
40 47 8 ff0000
41 47 8 ff0000
42 47 8 ff0000
43 47 8 ff0000
44 47 8 ff0000
45 47 8 ff0000
46 47 8 ff0000
47 47 8 ff0000
32 36 9 ff00aa
33 36 9 ff00aa
46 36 9 ff00aa
47 36 9 ff00aa
33 37 9 ff00aa
39 37 9 aabbff
46 37 9 ff00aa
33 38 9 ff00aa
39 38 9 aabbff
46 38 9 ff00aa
33 39 9 ff00aa
39 39 9 aabbff
46 39 9 ff00aa
33 40 9 ff00aa
39 40 9 aabbff
46 40 9 ff00aa
33 41 9 ff00aa
39 41 9 aabbff
46 41 9 ff00aa
33 42 9 ff00aa
39 42 9 aabbff
46 42 9 ff00aa
33 43 9 ff00aa
39 43 9 aabbff
46 43 9 ff00aa
33 44 9 ff00aa
34 44 9 ffba0a
35 44 9 ffba0a
36 44 9 ffba0a
37 44 9 ffba0a
38 44 9 ffba0a
39 44 9 aabbff
46 44 9 ff00aa
33 45 9 ff00aa
46 45 9 ff00aa
33 46 9 ff00aa
46 46 9 ff00aa
32 47 9 ff0000
33 47 9 ff0000
34 47 9 ff0000
35 47 9 ff0000
36 47 9 ff0000
37 47 9 ff0000
38 47 9 ff0000
39 47 9 ff0000
40 47 9 ff0000
41 47 9 ff0000
42 47 9 ff0000
43 47 9 ff0000
44 47 9 ff0000
45 47 9 ff0000
46 47 9 ff0000
47 47 9 ff0000
32 36 10 ff00aa
33 36 10 ff00aa
46 36 10 ff00aa
47 36 10 ff00aa
33 37 10 ff00aa
39 37 10 aabbff
46 37 10 ff00aa
33 38 10 ff00aa
39 38 10 aabbff
46 38 10 ff00aa
33 39 10 ff00aa
39 39 10 aabbff
46 39 10 ff00aa
33 40 10 ff00aa
39 40 10 aabbff
46 40 10 ff00aa
33 41 10 ff00aa
39 41 10 aabbff
46 41 10 ff00aa
33 42 10 ff00aa
39 42 10 aabbff
46 42 10 ff00aa
33 43 10 ff00aa
39 43 10 aabbff
46 43 10 ff00aa
33 44 10 ff00aa
39 44 10 aabbff
46 44 10 ff00aa
33 45 10 ff00aa
34 45 10 ffba0a
35 45 10 ffba0a
36 45 10 ffba0a
37 45 10 ffba0a
38 45 10 ffba0a
39 45 10 ffba0a
40 45 10 ffba0a
41 45 10 ffba0a
42 45 10 ffba0a
43 45 10 ffba0a
44 45 10 ffba0a
45 45 10 ffba0a
46 45 10 ff00aa
33 46 10 ff00aa
34 46 10 ffba0a
35 46 10 ffba0a
36 46 10 ffba0a
37 46 10 ffba0a
38 46 10 ffba0a
39 46 10 ffba0a
40 46 10 ffba0a
41 46 10 ffba0a
42 46 10 ffba0a
43 46 10 ffba0a
44 46 10 ffba0a
45 46 10 ffba0a
46 46 10 ff00aa
32 47 10 ff0000
33 47 10 ff0000
34 47 10 ff0000
35 47 10 ff0000
36 47 10 ff0000
37 47 10 ff0000
38 47 10 ff0000
39 47 10 ff0000
40 47 10 ff0000
41 47 10 ff0000
42 47 10 ff0000
43 47 10 ff0000
44 47 10 ff0000
45 47 10 ff0000
46 47 10 ff0000
47 47 10 ff0000
16 32 1 ff0000
17 32 1 ff0000
21 32 1 ff0000
22 32 1 ff0000
23 32 1 ff0000
23 33 1 ff0000
23 34 1 ff0000
23 35 1 ff0000
23 36 1 ff0000
24 36 1 ff00aa
25 36 1 ff00aa
26 36 1 ff00aa
27 36 1 ff00aa
28 36 1 ff00aa
29 36 1 ff00aa
23 37 1 ff0000
23 38 1 ff0000
23 39 1 ff0000
23 40 1 ff0000
24 40 1 ff00aa
25 40 1 ff00aa
26 40 1 ff00aa
27 40 1 ff00aa
28 40 1 ff00aa
23 41 1 ff0000
28 41 1 ff00aa
23 42 1 ff0000
23 43 1 ff0000
23 44 1 ff0000
24 44 1 ff00aa
25 44 1 ff00aa
26 44 1 ff00aa
27 44 1 ff00aa
28 44 1 ff00aa
23 45 1 ff0000
23 46 1 ff0000
16 47 1 ff0000
17 47 1 ff0000
18 47 1 ff0000
19 47 1 ff0000
20 47 1 ff0000
21 47 1 ff0000
22 47 1 ff0000
23 47 1 ff0000
24 47 1 ff0000
25 47 1 ff0000
26 47 1 ff0000
27 47 1 ff0000
28 47 1 ff0000
29 47 1 ff0000
30 47 1 ff0000
31 47 1 ff0000
16 32 2 ff0000
17 32 2 ff0000
21 32 2 ff0000
22 32 2 ff0000
23 32 2 ff0000
23 33 2 ff0000
23 34 2 ff0000
23 35 2 ff0000
23 36 2 ff0000
24 36 2 ff00aa
25 36 2 ff00aa
26 36 2 ff00aa
27 36 2 ff00aa
28 36 2 ff00aa
29 36 2 ff00aa
23 37 2 ff0000
23 38 2 ff0000
23 39 2 ff0000
23 40 2 ff0000
24 40 2 ff00aa
25 40 2 ff00aa
26 40 2 ff00aa
27 40 2 ff00aa
28 40 2 ff00aa
23 41 2 ff0000
28 41 2 ff00aa
23 42 2 ff0000
23 43 2 ff0000
23 44 2 ff0000
24 44 2 ff00aa
25 44 2 ff00aa
26 44 2 ff00aa
27 44 2 ff00aa
28 44 2 ff00aa
23 45 2 ff0000
23 46 2 ff0000
16 47 2 ff0000
17 47 2 ff0000
18 47 2 ff0000
19 47 2 ff0000
20 47 2 ff0000
21 47 2 ff0000
22 47 2 ff0000
23 47 2 ff0000
24 47 2 ff0000
25 47 2 ff0000
26 47 2 ff0000
27 47 2 ff0000
28 47 2 ff0000
29 47 2 ff0000
30 47 2 ff0000
31 47 2 ff0000
16 32 3 ff0000
17 32 3 ff0000
21 32 3 ff0000
22 32 3 ff0000
23 32 3 ff0000
23 33 3 ff0000
23 34 3 ff0000
23 35 3 ff0000
23 36 3 ff0000
24 36 3 ff00aa
25 36 3 ff00aa
26 36 3 ff00aa
27 36 3 ff00aa
28 36 3 ff00aa
29 36 3 ff00aa
23 37 3 ff0000
23 38 3 ff0000
23 39 3 ff0000
23 40 3 ff0000
24 40 3 ff00aa
25 40 3 ff00aa
26 40 3 ff00aa
27 40 3 ff00aa
28 40 3 ff00aa
23 41 3 ff0000
28 41 3 ff00aa
23 42 3 ff0000
23 43 3 ff0000
23 44 3 ff0000
24 44 3 ff00aa
25 44 3 ff00aa
26 44 3 ff00aa
27 44 3 ff00aa
28 44 3 ff00aa
23 45 3 ff0000
23 46 3 ff0000
16 47 3 ff0000
17 47 3 ff0000
18 47 3 ff0000
19 47 3 ff0000
20 47 3 ff0000
21 47 3 ff0000
22 47 3 ff0000
23 47 3 ff0000
24 47 3 ff0000
25 47 3 ff0000
26 47 3 ff0000
27 47 3 ff0000
28 47 3 ff0000
29 47 3 ff0000
30 47 3 ff0000
31 47 3 ff0000
16 32 4 ff0000
17 32 4 ff0000
21 32 4 ff0000
22 32 4 ff0000
23 32 4 ff0000
23 33 4 ff0000
23 34 4 ff0000
23 35 4 ff0000
23 36 4 ff0000
24 36 4 ff00aa
25 36 4 ff00aa
26 36 4 ff00aa
27 36 4 ff00aa
28 36 4 ff00aa
29 36 4 ff00aa
23 37 4 ff0000
23 38 4 ff0000
23 39 4 ff0000
23 40 4 ff0000
24 40 4 ff00aa
25 40 4 ff00aa
26 40 4 ff00aa
27 40 4 ff00aa
28 40 4 ff00aa
23 41 4 ff0000
28 41 4 ff00aa
23 42 4 ff0000
23 43 4 ff0000
23 44 4 ff0000
24 44 4 ff00aa
25 44 4 ff00aa
26 44 4 ff00aa
27 44 4 ff00aa
28 44 4 ff00aa
23 45 4 ff0000
23 46 4 ff0000
16 47 4 ff0000
17 47 4 ff0000
18 47 4 ff0000
19 47 4 ff0000
20 47 4 ff0000
21 47 4 ff0000
22 47 4 ff0000
23 47 4 ff0000
24 47 4 ff0000
25 47 4 ff0000
26 47 4 ff0000
27 47 4 ff0000
28 47 4 ff0000
29 47 4 ff0000
30 47 4 ff0000
16 32 5 ff0000
17 32 5 ff0000
21 32 5 ff0000
22 32 5 ff0000
23 32 5 ff0000
23 33 5 ff0000
23 34 5 ff0000
23 35 5 ff0000
23 36 5 ff0000
24 36 5 ff00aa
25 36 5 ff00aa
26 36 5 ff00aa
27 36 5 ff00aa
28 36 5 ff00aa
29 36 5 ff00aa
23 37 5 ff0000
23 38 5 ff0000
23 39 5 ff0000
23 40 5 ff0000
24 40 5 ff00aa
25 40 5 ff00aa
26 40 5 ff00aa
27 40 5 ff00aa
28 40 5 ff00aa
23 41 5 ff0000
28 41 5 ff00aa
23 42 5 ff0000
23 43 5 ff0000
23 44 5 ff0000
24 44 5 ff00aa
25 44 5 ff00aa
26 44 5 ff00aa
27 44 5 ff00aa
28 44 5 ff00aa
23 45 5 ff0000
23 46 5 ff0000
16 47 5 ff0000
17 47 5 ff0000
18 47 5 ff0000
19 47 5 ff0000
20 47 5 ff0000
21 47 5 ff0000
22 47 5 ff0000
23 47 5 ff0000
24 47 5 ff0000
25 47 5 ff0000
26 47 5 ff0000
27 47 5 ff0000
28 47 5 ff0000
29 47 5 ff0000
30 47 5 ff0000
16 32 6 ff0000
17 32 6 ff0000
18 32 6 ff0000
19 32 6 ff0000
20 32 6 ff0000
21 32 6 ff0000
22 32 6 ff0000
23 32 6 ff0000
23 33 6 ff0000
23 34 6 ff0000
23 35 6 ff0000
23 36 6 ff0000
24 36 6 ff00aa
25 36 6 ff00aa
26 36 6 ff00aa
27 36 6 ff00aa
28 36 6 ff00aa
29 36 6 ff00aa
23 37 6 ff0000
23 38 6 ff0000
23 39 6 ff0000
23 40 6 ff0000
24 40 6 ff00aa
25 40 6 ff00aa
26 40 6 ff00aa
27 40 6 ff00aa
28 40 6 ff00aa
23 41 6 ff0000
28 41 6 ff00aa
23 42 6 ff0000
23 43 6 ff0000
23 44 6 ff0000
24 44 6 ff00aa
25 44 6 ff00aa
26 44 6 ff00aa
27 44 6 ff00aa
28 44 6 ff00aa
23 45 6 ff0000
23 46 6 ff0000
16 47 6 ff0000
17 47 6 ff0000
18 47 6 ff0000
19 47 6 ff0000
20 47 6 ff0000
21 47 6 ff0000
22 47 6 ff0000
23 47 6 ff0000
24 47 6 ff0000
25 47 6 ff0000
26 47 6 ff0000
27 47 6 ff0000
28 47 6 ff0000
29 47 6 ff0000
30 47 6 ff0000
16 32 7 ff0000
17 32 7 ff0000
18 32 7 ff0000
19 32 7 ff0000
20 32 7 ff0000
21 32 7 ff0000
22 32 7 ff0000
23 32 7 ff0000
23 33 7 ff0000
23 34 7 ff0000
23 35 7 ff0000
23 36 7 ff0000
24 36 7 ff00aa
25 36 7 ff00aa
26 36 7 ff00aa
27 36 7 ff00aa
28 36 7 ff00aa
29 36 7 ff00aa
30 36 7 ff00aa
31 36 7 ff00aa
23 37 7 ff0000
23 38 7 ff0000
23 39 7 ff0000
23 40 7 ff0000
24 40 7 ff00aa
25 40 7 ff00aa
26 40 7 ff00aa
27 40 7 ff00aa
28 40 7 ff00aa
23 41 7 ff0000
28 41 7 ff00aa
23 42 7 ff0000
23 43 7 ff0000
23 44 7 ff0000
24 44 7 ff00aa
25 44 7 ff00aa
26 44 7 ff00aa
27 44 7 ff00aa
28 44 7 ff00aa
23 45 7 ff0000
23 46 7 ff0000
16 47 7 ff0000
17 47 7 ff0000
18 47 7 ff0000
19 47 7 ff0000
20 47 7 ff0000
21 47 7 ff0000
22 47 7 ff0000
23 47 7 ff0000
24 47 7 ff0000
25 47 7 ff0000
26 47 7 ff0000
27 47 7 ff0000
28 47 7 ff0000
29 47 7 ff0000
30 47 7 ff0000
31 47 7 ff0000
16 32 8 ff0000
17 32 8 ff0000
18 32 8 ff0000
19 32 8 ff0000
20 32 8 ff0000
21 32 8 ff0000
22 32 8 ff0000
23 32 8 ff0000
23 33 8 ff0000
23 34 8 ff0000
23 35 8 ff0000
23 36 8 ff0000
24 36 8 ff00aa
25 36 8 ff00aa
26 36 8 ff00aa
27 36 8 ff00aa
28 36 8 ff00aa
29 36 8 ff00aa
30 36 8 ff00aa
31 36 8 ff00aa
23 37 8 ff0000
23 38 8 ff0000
23 39 8 ff0000
23 40 8 ff0000
24 40 8 ff00aa
25 40 8 ff00aa
26 40 8 ff00aa
27 40 8 ff00aa
28 40 8 ff00aa
23 41 8 ff0000
28 41 8 ff00aa
23 42 8 ff0000
23 43 8 ff0000
23 44 8 ff0000
24 44 8 ff00aa
25 44 8 ff00aa
26 44 8 ff00aa
27 44 8 ff00aa
28 44 8 ff00aa
23 45 8 ff0000
23 46 8 ff0000
16 47 8 ff0000
17 47 8 ff0000
18 47 8 ff0000
19 47 8 ff0000
20 47 8 ff0000
21 47 8 ff0000
22 47 8 ff0000
23 47 8 ff0000
24 47 8 ff0000
25 47 8 ff0000
26 47 8 ff0000
27 47 8 ff0000
28 47 8 ff0000
29 47 8 ff0000
30 47 8 ff0000
31 47 8 ff0000
16 32 9 ff0000
17 32 9 ff0000
18 32 9 ff0000
19 32 9 ff0000
20 32 9 ff0000
21 32 9 ff0000
22 32 9 ff0000
23 32 9 ff0000
23 33 9 ff0000
23 34 9 ff0000
23 35 9 ff0000
23 36 9 ff0000
24 36 9 ff00aa
25 36 9 ff00aa
26 36 9 ff00aa
27 36 9 ff00aa
28 36 9 ff00aa
29 36 9 ff00aa
30 36 9 ff00aa
31 36 9 ff00aa
23 37 9 ff0000
23 38 9 ff0000
23 39 9 ff0000
23 40 9 ff0000
24 40 9 ff00aa
25 40 9 ff00aa
26 40 9 ff00aa
27 40 9 ff00aa
28 40 9 ff00aa
23 41 9 ff0000
28 41 9 ff00aa
23 42 9 ff0000
23 43 9 ff0000
23 44 9 ff0000
24 44 9 ff00aa
25 44 9 ff00aa
26 44 9 ff00aa
27 44 9 ff00aa
28 44 9 ff00aa
23 45 9 ff0000
23 46 9 ff0000
16 47 9 ff0000
17 47 9 ff0000
18 47 9 ff0000
19 47 9 ff0000
20 47 9 ff0000
21 47 9 ff0000
22 47 9 ff0000
23 47 9 ff0000
24 47 9 ff0000
25 47 9 ff0000
26 47 9 ff0000
27 47 9 ff0000
28 47 9 ff0000
29 47 9 ff0000
30 47 9 ff0000
31 47 9 ff0000
16 32 10 ff0000
17 32 10 ff0000
18 32 10 ff0000
19 32 10 ff0000
20 32 10 ff0000
21 32 10 ff0000
22 32 10 ff0000
23 32 10 ff0000
23 33 10 ff0000
23 34 10 ff0000
23 35 10 ff0000
23 36 10 ff0000
24 36 10 ff00aa
25 36 10 ff00aa
26 36 10 ff00aa
27 36 10 ff00aa
28 36 10 ff00aa
29 36 10 ff00aa
30 36 10 ff00aa
31 36 10 ff00aa
23 37 10 ff0000
23 38 10 ff0000
23 39 10 ff0000
23 40 10 ff0000
24 40 10 ff00aa
25 40 10 ff00aa
26 40 10 ff00aa
27 40 10 ff00aa
28 40 10 ff00aa
23 41 10 ff0000
28 41 10 ff00aa
23 42 10 ff0000
23 43 10 ff0000
23 44 10 ff0000
24 44 10 ff00aa
25 44 10 ff00aa
26 44 10 ff00aa
27 44 10 ff00aa
28 44 10 ff00aa
23 45 10 ff0000
23 46 10 ff0000
16 47 10 ff0000
17 47 10 ff0000
18 47 10 ff0000
19 47 10 ff0000
20 47 10 ff0000
21 47 10 ff0000
22 47 10 ff0000
23 47 10 ff0000
24 47 10 ff0000
25 47 10 ff0000
26 47 10 ff0000
27 47 10 ff0000
28 47 10 ff0000
29 47 10 ff0000
30 47 10 ff0000
31 47 10 ff0000
56 32 1 ff0000
57 32 1 ffffaa
58 32 1 ffffaa
59 32 1 ffffaa
60 32 1 ffffaa
61 32 1 ffffaa
62 32 1 ffffaa
63 32 1 ffffaa
56 33 1 ff0000
56 34 1 ff0000
56 35 1 ff0000
50 36 1 ff00aa
51 36 1 ff00aa
52 36 1 ff00aa
53 36 1 ff00aa
54 36 1 ff00aa
55 36 1 ff00aa
56 36 1 ff0000
56 37 1 ff0000
51 40 1 ffccaa
52 40 1 ffccaa
53 40 1 ffccaa
54 40 1 ffccaa
55 40 1 ffccaa
56 40 1 ff0000
51 41 1 ffccaa
56 41 1 ff0000
56 42 1 ff0000
56 43 1 ff0000
51 44 1 ffccaa
52 44 1 ffccaa
53 44 1 ffccaa
54 44 1 ffccaa
55 44 1 ffccaa
56 44 1 ff0000
56 45 1 ff0000
56 46 1 ff0000
48 47 1 ff0000
49 47 1 ff0000
50 47 1 ff0000
51 47 1 ff0000
52 47 1 ff0000
53 47 1 ff0000
54 47 1 ff0000
55 47 1 ff0000
56 47 1 ff0000
57 47 1 ff0000
58 47 1 ff0000
59 47 1 ff0000
60 47 1 ff0000
61 47 1 ff0000
62 47 1 ff0000
63 47 1 ff0000
56 32 2 ff0000
57 32 2 ffffaa
58 32 2 ffffaa
59 32 2 ffffaa
60 32 2 ffffaa
61 32 2 ffffaa
62 32 2 ffffaa
63 32 2 ffffaa
56 33 2 ff0000
56 34 2 ff0000
56 35 2 ff0000
50 36 2 ff00aa
51 36 2 ff00aa
52 36 2 ff00aa
53 36 2 ff00aa
54 36 2 ff00aa
55 36 2 ff00aa
56 36 2 ff0000
56 37 2 ff0000
51 40 2 ffccaa
52 40 2 ffccaa
53 40 2 ffccaa
54 40 2 ffccaa
55 40 2 ffccaa
56 40 2 ff0000
51 41 2 ffccaa
56 41 2 ff0000
56 42 2 ff0000
56 43 2 ff0000
51 44 2 ffccaa
52 44 2 ffccaa
53 44 2 ffccaa
54 44 2 ffccaa
55 44 2 ffccaa
56 44 2 ff0000
56 45 2 ff0000
56 46 2 ff0000
48 47 2 ff0000
49 47 2 ff0000
50 47 2 ff0000
51 47 2 ff0000
52 47 2 ff0000
53 47 2 ff0000
54 47 2 ff0000
55 47 2 ff0000
56 47 2 ff0000
57 47 2 ff0000
58 47 2 ff0000
59 47 2 ff0000
60 47 2 ff0000
61 47 2 ff0000
62 47 2 ff0000
63 47 2 ff0000
56 32 3 ff0000
57 32 3 ffffaa
58 32 3 ffffaa
59 32 3 ffffaa
60 32 3 ffffaa
61 32 3 ffffaa
62 32 3 ffffaa
63 32 3 ffffaa
56 33 3 ff0000
56 34 3 ff0000
56 35 3 ff0000
50 36 3 ff00aa
51 36 3 ff00aa
52 36 3 ff00aa
53 36 3 ff00aa
54 36 3 ff00aa
55 36 3 ff00aa
56 36 3 ff0000
56 37 3 ff0000
51 40 3 ffccaa
52 40 3 ffccaa
53 40 3 ffccaa
54 40 3 ffccaa
55 40 3 ffccaa
56 40 3 ff0000
51 41 3 ffccaa
56 41 3 ff0000
56 42 3 ff0000
56 43 3 ff0000
51 44 3 ffccaa
52 44 3 ffccaa
53 44 3 ffccaa
54 44 3 ffccaa
55 44 3 ffccaa
56 44 3 ff0000
56 45 3 ff0000
56 46 3 ff0000
48 47 3 ff0000
49 47 3 ff0000
50 47 3 ff0000
51 47 3 ff0000
52 47 3 ff0000
53 47 3 ff0000
54 47 3 ff0000
55 47 3 ff0000
56 47 3 ff0000
57 47 3 ff0000
58 47 3 ff0000
59 47 3 ff0000
60 47 3 ff0000
61 47 3 ff0000
62 47 3 ff0000
63 47 3 ff0000
56 32 4 ff0000
57 32 4 ffffaa
58 32 4 ffffaa
59 32 4 ffffaa
60 32 4 ffffaa
61 32 4 ffffaa
62 32 4 ffffaa
63 32 4 ffffaa
56 33 4 ff0000
56 34 4 ff0000
56 35 4 ff0000
50 36 4 ff00aa
51 36 4 ff00aa
52 36 4 ff00aa
53 36 4 ff00aa
54 36 4 ff00aa
55 36 4 ff00aa
56 36 4 ff0000
56 37 4 ff0000
51 40 4 ffccaa
52 40 4 ffccaa
53 40 4 ffccaa
54 40 4 ffccaa
55 40 4 ffccaa
56 40 4 ff0000
51 41 4 ffccaa
56 41 4 ff0000
56 42 4 ff0000
56 43 4 ff0000
51 44 4 ffccaa
52 44 4 ffccaa
53 44 4 ffccaa
54 44 4 ffccaa
55 44 4 ffccaa
56 44 4 ff0000
56 45 4 ff0000
56 46 4 ff0000
48 47 4 ff0000
50 47 4 ff0000
51 47 4 ff0000
52 47 4 ff0000
53 47 4 ff0000
54 47 4 ff0000
55 47 4 ff0000
56 47 4 ff0000
57 47 4 ff0000
58 47 4 ff0000
59 47 4 ff0000
60 47 4 ff0000
61 47 4 ff0000
62 47 4 ff0000
63 47 4 ff0000
56 32 5 ff0000
57 32 5 ffffaa
58 32 5 ffffaa
59 32 5 ffffaa
60 32 5 ffffaa
61 32 5 ffffaa
62 32 5 ffffaa
63 32 5 ffffaa
56 33 5 ff0000
56 34 5 ff0000
56 35 5 ff0000
50 36 5 ff00aa
51 36 5 ff00aa
52 36 5 ff00aa
53 36 5 ff00aa
54 36 5 ff00aa
55 36 5 ff00aa
56 36 5 ff0000
56 37 5 ff0000
51 40 5 ffccaa
52 40 5 ffccaa
53 40 5 ffccaa
54 40 5 ffccaa
55 40 5 ffccaa
56 40 5 ff0000
51 41 5 ffccaa
56 41 5 ff0000
56 42 5 ff0000
56 43 5 ff0000
51 44 5 ffccaa
52 44 5 ffccaa
53 44 5 ffccaa
54 44 5 ffccaa
55 44 5 ffccaa
56 44 5 ff0000
56 45 5 ff0000
56 46 5 ff0000
48 47 5 ff0000
50 47 5 ff0000
51 47 5 ff0000
52 47 5 ff0000
53 47 5 ff0000
54 47 5 ff0000
55 47 5 ff0000
56 47 5 ff0000
57 47 5 ff0000
58 47 5 ff0000
59 47 5 ff0000
60 47 5 ff0000
61 47 5 ff0000
62 47 5 ff0000
63 47 5 ff0000
56 32 6 ff0000
57 32 6 ffffaa
58 32 6 ffffaa
59 32 6 ffffaa
60 32 6 ffffaa
61 32 6 ffffaa
62 32 6 ffffaa
63 32 6 ffffaa
56 33 6 ff0000
56 34 6 ff0000
56 35 6 ff0000
50 36 6 ff00aa
51 36 6 ff00aa
52 36 6 ff00aa
53 36 6 ff00aa
54 36 6 ff00aa
55 36 6 ff00aa
56 36 6 ff0000
56 37 6 ff0000
56 38 6 ff0000
56 39 6 ff0000
51 40 6 ffccaa
52 40 6 ffccaa
53 40 6 ffccaa
54 40 6 ffccaa
55 40 6 ffccaa
56 40 6 ff0000
51 41 6 ffccaa
56 41 6 ff0000
56 42 6 ff0000
56 43 6 ff0000
51 44 6 ffccaa
52 44 6 ffccaa
53 44 6 ffccaa
54 44 6 ffccaa
55 44 6 ffccaa
56 44 6 ff0000
56 45 6 ff0000
56 46 6 ff0000
48 47 6 ff0000
50 47 6 ff0000
51 47 6 ff0000
52 47 6 ff0000
53 47 6 ff0000
54 47 6 ff0000
55 47 6 ff0000
56 47 6 ff0000
57 47 6 ff0000
58 47 6 ff0000
59 47 6 ff0000
60 47 6 ff0000
61 47 6 ff0000
62 47 6 ff0000
63 47 6 ff0000
56 32 7 ff0000
57 32 7 ffffaa
58 32 7 ffffaa
59 32 7 ffffaa
60 32 7 ffffaa
61 32 7 ffffaa
62 32 7 ffffaa
63 32 7 ffffaa
56 33 7 ff0000
56 34 7 ff0000
56 35 7 ff0000
48 36 7 ff00aa
49 36 7 ff00aa
50 36 7 ff00aa
51 36 7 ff00aa
52 36 7 ff00aa
53 36 7 ff00aa
54 36 7 ff00aa
55 36 7 ff00aa
56 36 7 ff0000
56 37 7 ff0000
56 38 7 ff0000
56 39 7 ff0000
51 40 7 ffccaa
52 40 7 ffccaa
53 40 7 ffccaa
54 40 7 ffccaa
55 40 7 ffccaa
56 40 7 ff0000
51 41 7 ffccaa
56 41 7 ff0000
56 42 7 ff0000
56 43 7 ff0000
51 44 7 ffccaa
52 44 7 ffccaa
53 44 7 ffccaa
54 44 7 ffccaa
55 44 7 ffccaa
56 44 7 ff0000
56 45 7 ff0000
56 46 7 ff0000
48 47 7 ff0000
49 47 7 ff0000
50 47 7 ff0000
51 47 7 ff0000
52 47 7 ff0000
53 47 7 ff0000
54 47 7 ff0000
55 47 7 ff0000
56 47 7 ff0000
57 47 7 ff0000
58 47 7 ff0000
59 47 7 ff0000
60 47 7 ff0000
61 47 7 ff0000
62 47 7 ff0000
63 47 7 ff0000
56 32 8 ff0000
57 32 8 ffffaa
58 32 8 ffffaa
59 32 8 ffffaa
60 32 8 ffffaa
61 32 8 ffffaa
62 32 8 ffffaa
63 32 8 ffffaa
56 33 8 ff0000
56 34 8 ff0000
56 35 8 ff0000
48 36 8 ff00aa
49 36 8 ff00aa
50 36 8 ff00aa
51 36 8 ff00aa
52 36 8 ff00aa
53 36 8 ff00aa
54 36 8 ff00aa
55 36 8 ff00aa
56 36 8 ff0000
56 37 8 ff0000
56 38 8 ff0000
56 39 8 ff0000
51 40 8 ffccaa
52 40 8 ffccaa
53 40 8 ffccaa
54 40 8 ffccaa
55 40 8 ffccaa
56 40 8 ff0000
51 41 8 ffccaa
56 41 8 ff0000
56 42 8 ff0000
56 43 8 ff0000
51 44 8 ffccaa
52 44 8 ffccaa
53 44 8 ffccaa
54 44 8 ffccaa
55 44 8 ffccaa
56 44 8 ff0000
56 45 8 ff0000
56 46 8 ff0000
48 47 8 ff0000
49 47 8 ff0000
50 47 8 ff0000
51 47 8 ff0000
52 47 8 ff0000
53 47 8 ff0000
54 47 8 ff0000
55 47 8 ff0000
56 47 8 ff0000
57 47 8 ff0000
58 47 8 ff0000
59 47 8 ff0000
60 47 8 ff0000
61 47 8 ff0000
62 47 8 ff0000
63 47 8 ff0000
56 32 9 ff0000
57 32 9 ffffaa
58 32 9 ffffaa
59 32 9 ffffaa
60 32 9 ffffaa
61 32 9 ffffaa
62 32 9 ffffaa
63 32 9 ffffaa
56 33 9 ff0000
56 34 9 ff0000
56 35 9 ff0000
48 36 9 ff00aa
49 36 9 ff00aa
50 36 9 ff00aa
51 36 9 ff00aa
52 36 9 ff00aa
53 36 9 ff00aa
54 36 9 ff00aa
55 36 9 ff00aa
56 36 9 ff0000
56 37 9 ff0000
56 38 9 ff0000
56 39 9 ff0000
51 40 9 ffccaa
52 40 9 ffccaa
53 40 9 ffccaa
54 40 9 ffccaa
55 40 9 ffccaa
56 40 9 ff0000
51 41 9 ffccaa
56 41 9 ff0000
56 42 9 ff0000
56 43 9 ff0000
51 44 9 ffccaa
52 44 9 ffccaa
53 44 9 ffccaa
54 44 9 ffccaa
55 44 9 ffccaa
56 44 9 ff0000
56 45 9 ff0000
56 46 9 ff0000
48 47 9 ff0000
49 47 9 ff0000
50 47 9 ff0000
51 47 9 ff0000
52 47 9 ff0000
53 47 9 ff0000
54 47 9 ff0000
55 47 9 ff0000
56 47 9 ff0000
57 47 9 ff0000
58 47 9 ff0000
59 47 9 ff0000
60 47 9 ff0000
61 47 9 ff0000
62 47 9 ff0000
63 47 9 ff0000
56 32 10 ff0000
57 32 10 ffffaa
58 32 10 ffffaa
59 32 10 ffffaa
60 32 10 ffffaa
61 32 10 ffffaa
62 32 10 ffffaa
63 32 10 ffffaa
56 33 10 ff0000
56 34 10 ff0000
56 35 10 ff0000
48 36 10 ff00aa
49 36 10 ff00aa
50 36 10 ff00aa
51 36 10 ff00aa
52 36 10 ff00aa
53 36 10 ff00aa
54 36 10 ff00aa
55 36 10 ff00aa
56 36 10 ff0000
56 37 10 ff0000
56 38 10 ff0000
56 39 10 ff0000
51 40 10 ffccaa
52 40 10 ffccaa
53 40 10 ffccaa
54 40 10 ffccaa
55 40 10 ffccaa
56 40 10 ff0000
51 41 10 ffccaa
56 41 10 ff0000
56 42 10 ff0000
56 43 10 ff0000
51 44 10 ffccaa
52 44 10 ffccaa
53 44 10 ffccaa
54 44 10 ffccaa
55 44 10 ffccaa
56 44 10 ff0000
56 45 10 ff0000
56 46 10 ff0000
48 47 10 ff0000
49 47 10 ff0000
50 47 10 ff0000
51 47 10 ff0000
52 47 10 ff0000
53 47 10 ff0000
54 47 10 ff0000
55 47 10 ff0000
56 47 10 ff0000
57 47 10 ff0000
58 47 10 ff0000
59 47 10 ff0000
60 47 10 ff0000
61 47 10 ff0000
62 47 10 ff0000
63 47 10 ff0000
48 0 1 ff0000
49 0 1 ff0000
50 0 1 ff0000
51 0 1 ff0000
52 0 1 ff0000
53 0 1 ff0000
54 0 1 ff0000
55 0 1 ff0000
56 0 1 ff0000
57 0 1 ff0000
58 0 1 ff0000
59 0 1 ff0000
60 0 1 ff0000
61 0 1 ff0000
62 0 1 ff0000
63 0 1 ff0000
56 1 1 ff0000
56 2 1 ff0000
56 3 1 ff0000
56 4 1 ff0000
56 5 1 ff0000
56 6 1 ff0000
56 7 1 ff0000
56 8 1 ff0000
56 9 1 ff0000
56 10 1 ff0000
56 11 1 ff0000
56 12 1 ff0000
56 13 1 ff0000
56 14 1 ff0000
56 15 1 ff0000
48 0 2 ff0000
49 0 2 ff0000
50 0 2 ff0000
51 0 2 ff0000
52 0 2 ff0000
53 0 2 ff0000
54 0 2 ff0000
55 0 2 ff0000
56 0 2 ff0000
57 0 2 ff0000
58 0 2 ff0000
59 0 2 ff0000
60 0 2 ff0000
61 0 2 ff0000
62 0 2 ff0000
63 0 2 ff0000
56 1 2 ff0000
56 2 2 ff0000
56 3 2 ff0000
56 4 2 ff0000
56 5 2 ff0000
56 6 2 ff0000
56 7 2 ff0000
56 8 2 ff0000
56 9 2 ff0000
56 10 2 ff0000
56 11 2 ff0000
56 12 2 ff0000
56 13 2 ff0000
56 14 2 ff0000
56 15 2 ff0000
48 0 3 ff0000
49 0 3 ff0000
50 0 3 ff0000
51 0 3 ff0000
52 0 3 ff0000
53 0 3 ff0000
54 0 3 ff0000
55 0 3 ff0000
56 0 3 ff0000
57 0 3 ff0000
58 0 3 ff0000
59 0 3 ff0000
60 0 3 ff0000
61 0 3 ff0000
62 0 3 ff0000
63 0 3 ff0000
56 1 3 ff0000
56 2 3 ff0000
56 3 3 ff0000
56 4 3 ff0000
56 5 3 ff0000
56 6 3 ff0000
56 7 3 ff0000
56 8 3 ff0000
56 9 3 ff0000
56 10 3 ff0000
56 11 3 ff0000
56 12 3 ff0000
56 13 3 ff0000
56 14 3 ff0000
56 15 3 ff0000
48 0 4 ff0000
49 0 4 ff0000
50 0 4 ff0000
51 0 4 ff0000
52 0 4 ff0000
53 0 4 ff0000
54 0 4 ff0000
55 0 4 ff0000
56 0 4 ff0000
57 0 4 ff0000
58 0 4 ff0000
59 0 4 ff0000
60 0 4 ff0000
61 0 4 ff0000
62 0 4 ff0000
63 0 4 ff0000
56 1 4 ff0000
56 2 4 ff0000
56 3 4 ff0000
56 4 4 ff0000
56 5 4 ff0000
56 6 4 ff0000
56 7 4 ff0000
56 8 4 ff0000
56 9 4 ff0000
56 10 4 ff0000
56 11 4 ff0000
56 12 4 ff0000
56 13 4 ff0000
56 14 4 ff0000
56 15 4 ff0000
48 0 5 ff0000
49 0 5 ff0000
50 0 5 ff0000
51 0 5 ff0000
52 0 5 ff0000
53 0 5 ff0000
54 0 5 ff0000
55 0 5 ff0000
56 0 5 ff0000
57 0 5 ff0000
58 0 5 ff0000
59 0 5 ff0000
60 0 5 ff0000
61 0 5 ff0000
62 0 5 ff0000
63 0 5 ff0000
56 1 5 ff0000
56 2 5 ff0000
56 3 5 ff0000
56 4 5 ff0000
56 5 5 ff0000
56 6 5 ff0000
56 7 5 ff0000
56 8 5 ff0000
56 9 5 ff0000
56 10 5 ff0000
56 11 5 ff0000
56 12 5 ff0000
56 13 5 ff0000
56 14 5 ff0000
56 15 5 ff0000
48 0 6 ff0000
49 0 6 ff0000
50 0 6 ff0000
51 0 6 ff0000
52 0 6 ff0000
53 0 6 ff0000
54 0 6 ff0000
55 0 6 ff0000
56 0 6 ff0000
57 0 6 ff0000
58 0 6 ff0000
59 0 6 ff0000
60 0 6 ff0000
61 0 6 ff0000
62 0 6 ff0000
63 0 6 ff0000
56 1 6 ff0000
56 2 6 ff0000
56 3 6 ff0000
56 4 6 ff0000
56 5 6 ff0000
56 6 6 ff0000
56 7 6 ff0000
56 8 6 ff0000
56 9 6 ff0000
56 10 6 ff0000
56 11 6 ff0000
56 12 6 ff0000
56 13 6 ff0000
56 14 6 ff0000
56 15 6 ff0000
48 0 7 ff0000
49 0 7 ff0000
50 0 7 ff0000
51 0 7 ff0000
52 0 7 ff0000
53 0 7 ff0000
54 0 7 ff0000
55 0 7 ff0000
56 0 7 ff0000
57 0 7 ff0000
58 0 7 ff0000
59 0 7 ff0000
60 0 7 ff0000
61 0 7 ff0000
62 0 7 ff0000
63 0 7 ff0000
56 1 7 ff0000
56 2 7 ff0000
56 3 7 ff0000
56 4 7 ff0000
56 5 7 ff0000
56 6 7 ff0000
56 7 7 ff0000
56 8 7 ff0000
56 9 7 ff0000
56 10 7 ff0000
56 11 7 ff0000
56 12 7 ff0000
56 13 7 ff0000
56 14 7 ff0000
56 15 7 ff0000
48 0 8 ff0000
49 0 8 ff0000
50 0 8 ff0000
51 0 8 ff0000
52 0 8 ff0000
53 0 8 ff0000
54 0 8 ff0000
55 0 8 ff0000
56 0 8 ff0000
57 0 8 ff0000
58 0 8 ff0000
59 0 8 ff0000
60 0 8 ff0000
61 0 8 ff0000
62 0 8 ff0000
63 0 8 ff0000
56 1 8 ff0000
56 2 8 ff0000
56 3 8 ff0000
56 4 8 ff0000
56 5 8 ff0000
56 6 8 ff0000
56 7 8 ff0000
56 8 8 ff0000
56 9 8 ff0000
56 10 8 ff0000
56 11 8 ff0000
56 12 8 ff0000
56 13 8 ffffff
56 14 8 ff0000
56 15 8 ff0000
48 0 9 ff0000
49 0 9 ff0000
50 0 9 ff0000
51 0 9 ff0000
52 0 9 ff0000
53 0 9 ff0000
54 0 9 ff0000
55 0 9 ff0000
56 0 9 ff0000
57 0 9 ff0000
58 0 9 ff0000
59 0 9 ff0000
60 0 9 ff0000
61 0 9 ff0000
62 0 9 ff0000
63 0 9 ff0000
56 1 9 ff0000
56 2 9 ff0000
56 3 9 ff0000
56 4 9 ff0000
56 5 9 ff0000
56 6 9 ff0000
56 7 9 ff0000
56 8 9 ff0000
56 9 9 ff0000
56 10 9 ff0000
56 11 9 ff0000
56 12 9 ff0000
56 13 9 ff0000
56 14 9 ffffff
56 15 9 ffffff
48 0 10 ff0000
49 0 10 ff0000
50 0 10 ff0000
51 0 10 ff0000
52 0 10 ff0000
53 0 10 ff0000
54 0 10 ff0000
55 0 10 ff0000
56 0 10 ff0000
57 0 10 ff0000
58 0 10 ff0000
59 0 10 ff0000
60 0 10 ff0000
61 0 10 ff0000
62 0 10 ff0000
63 0 10 ff0000
56 1 10 ff0000
56 2 10 ff0000
56 3 10 ff0000
56 4 10 ff0000
56 5 10 ff0000
56 6 10 ff0000
56 7 10 ff0000
56 8 10 ff0000
56 9 10 ff0000
56 10 10 ff0000
56 11 10 ff0000
56 12 10 ff0000
56 13 10 ff0000
56 14 10 ff0000
56 15 10 ffffff
56 16 1 ff0000
56 17 1 ff0000
56 18 1 ff0000
56 19 1 ff0000
56 20 1 ff0000
56 21 1 ff0000
56 22 1 ff0000
56 23 1 ff0000
56 24 1 ff0000
56 25 1 ff0000
56 26 1 ff0000
56 30 1 ff0000
56 31 1 ff0000
56 16 2 ff0000
56 17 2 ff0000
56 18 2 ff0000
56 19 2 ff0000
56 20 2 ff0000
56 21 2 ff0000
56 22 2 ff0000
56 23 2 ff0000
56 24 2 ff0000
56 25 2 ff0000
56 26 2 ff0000
56 30 2 ff0000
56 31 2 ff0000
56 16 3 ff0000
56 17 3 ff0000
56 18 3 ff0000
56 19 3 ff0000
56 20 3 ff0000
56 21 3 ff0000
56 22 3 ff0000
56 23 3 ff0000
56 24 3 ff0000
56 25 3 ff0000
56 26 3 ff0000
56 30 3 ff0000
56 31 3 ff0000
56 16 4 ff0000
56 17 4 ff0000
56 18 4 ff0000
56 19 4 ff0000
56 20 4 ff0000
56 21 4 ff0000
56 22 4 ff0000
56 23 4 ff0000
56 24 4 ff0000
56 25 4 ff0000
56 26 4 ff0000
56 30 4 ff0000
56 31 4 ff0000
56 16 5 ff0000
56 17 5 ff0000
56 18 5 ff0000
56 19 5 ff0000
56 20 5 ff0000
56 21 5 ff0000
56 22 5 ff0000
56 23 5 ff0000
56 24 5 ff0000
56 25 5 ff0000
56 26 5 ff0000
56 30 5 ff0000
56 31 5 ff0000
56 16 6 ff0000
56 17 6 ff0000
56 18 6 ff0000
56 19 6 ff0000
56 20 6 ff0000
56 21 6 ff0000
56 22 6 ff0000
56 23 6 ff0000
56 24 6 ff0000
56 25 6 ff0000
56 26 6 ff0000
56 27 6 ff0000
56 28 6 ff0000
56 29 6 ff0000
56 30 6 ff0000
56 31 6 ff0000
56 16 7 ff0000
56 17 7 ff0000
56 18 7 ff0000
56 19 7 ff0000
56 20 7 ff0000
56 21 7 ff0000
56 22 7 ff0000
56 23 7 ff0000
56 24 7 ff0000
56 25 7 ff0000
56 26 7 ff0000
56 27 7 ff0000
56 28 7 ff0000
56 29 7 ff0000
56 30 7 ff0000
56 31 7 ff0000
56 16 8 ff0000
56 17 8 ff0000
56 18 8 ff0000
56 19 8 ff0000
56 20 8 ff0000
56 21 8 ff0000
56 22 8 ff0000
56 23 8 ff0000
56 24 8 ff0000
56 25 8 ff0000
56 26 8 ff0000
56 27 8 ff0000
56 28 8 ff0000
56 29 8 ff0000
56 30 8 ff0000
56 31 8 ff0000
56 16 9 ff0000
56 17 9 ff0000
56 18 9 ff0000
56 19 9 ff0000
56 20 9 ff0000
56 21 9 ff0000
56 22 9 ff0000
56 23 9 ff0000
56 24 9 ff0000
56 25 9 ff0000
56 26 9 ff0000
56 27 9 ff0000
56 28 9 ff0000
56 29 9 ff0000
56 30 9 ff0000
56 31 9 ff0000
56 16 10 ffffff
56 17 10 ff0000
56 18 10 ff0000
56 19 10 ff0000
56 20 10 ff0000
56 21 10 ff0000
56 22 10 ff0000
56 23 10 ff0000
56 24 10 ff0000
56 25 10 ff0000
56 26 10 ff0000
56 27 10 ff0000
56 28 10 ff0000
56 29 10 ff0000
56 30 10 ff0000
56 31 10 ff0000
16 0 1 ff0000
17 0 1 ff0000
18 0 1 ff0000
19 0 1 ff0000
20 0 1 ff0000
21 0 1 ff0000
22 0 1 ff0000
23 0 1 ff0000
24 0 1 ff0000
25 0 1 ff0000
26 0 1 ff0000
27 0 1 ff0000
28 0 1 ff0000
29 0 1 ff0000
30 0 1 ff0000
31 0 1 ff0000
23 1 1 ff0000
23 2 1 ff0000
23 3 1 ff0000
23 4 1 ff0000
23 5 1 ff0000
23 6 1 ff0000
23 7 1 ff0000
23 8 1 ff0000
23 9 1 ff0000
23 10 1 ff0000
23 11 1 ff0000
23 12 1 ff0000
23 13 1 ff0000
16 0 2 ff0000
17 0 2 ff0000
18 0 2 ff0000
19 0 2 ff0000
20 0 2 ff0000
21 0 2 ff0000
22 0 2 ff0000
23 0 2 ff0000
24 0 2 ff0000
25 0 2 ff0000
26 0 2 ff0000
27 0 2 ff0000
28 0 2 ff0000
29 0 2 ff0000
30 0 2 ff0000
31 0 2 ff0000
23 1 2 ff0000
23 2 2 ff0000
23 3 2 ff0000
23 4 2 ff0000
23 5 2 ff0000
23 6 2 ff0000
23 7 2 ff0000
23 8 2 ff0000
23 9 2 ff0000
23 10 2 ff0000
23 11 2 ff0000
23 12 2 ff0000
23 13 2 ff0000
16 0 3 ff0000
17 0 3 ff0000
18 0 3 ff0000
19 0 3 ff0000
20 0 3 ff0000
21 0 3 ff0000
22 0 3 ff0000
23 0 3 ff0000
24 0 3 ff0000
25 0 3 ff0000
26 0 3 ff0000
27 0 3 ff0000
28 0 3 ff0000
29 0 3 ff0000
30 0 3 ff0000
31 0 3 ff0000
23 1 3 ff0000
23 2 3 ff0000
23 3 3 ff0000
23 4 3 ff0000
23 5 3 ff0000
23 6 3 ff0000
23 7 3 ff0000
23 8 3 ff0000
23 9 3 ff0000
23 10 3 ff0000
23 11 3 ff0000
23 12 3 ff0000
23 13 3 ff0000
16 0 4 ff0000
17 0 4 ff0000
18 0 4 ff0000
19 0 4 ff0000
20 0 4 ff0000
21 0 4 ff0000
22 0 4 ff0000
23 0 4 ff0000
24 0 4 ff0000
25 0 4 ff0000
26 0 4 ff0000
27 0 4 ff0000
28 0 4 ff0000
29 0 4 ff0000
30 0 4 ff0000
31 0 4 ff0000
23 1 4 ff0000
23 2 4 ff0000
23 3 4 ff0000
23 4 4 ff0000
23 5 4 ff0000
23 6 4 ff0000
23 7 4 ff0000
23 8 4 ff0000
23 9 4 ff0000
23 10 4 ff0000
23 11 4 ff0000
23 12 4 ff0000
23 13 4 ff0000
16 0 5 ff0000
17 0 5 ff0000
18 0 5 ff0000
19 0 5 ff0000
20 0 5 ff0000
21 0 5 ff0000
22 0 5 ff0000
23 0 5 ff0000
24 0 5 ff0000
25 0 5 ff0000
26 0 5 ff0000
27 0 5 ff0000
28 0 5 ff0000
29 0 5 ff0000
30 0 5 ff0000
31 0 5 ff0000
23 1 5 ff0000
23 2 5 ff0000
23 3 5 ff0000
23 4 5 ff0000
23 5 5 ff0000
23 6 5 ff0000
23 7 5 ff0000
23 8 5 ff0000
23 9 5 ff0000
23 10 5 ff0000
23 11 5 ff0000
23 12 5 ff0000
23 13 5 ff0000
16 0 6 ff0000
17 0 6 ff0000
18 0 6 ff0000
19 0 6 ff0000
20 0 6 ff0000
21 0 6 ff0000
22 0 6 ff0000
23 0 6 ff0000
24 0 6 ff0000
25 0 6 ff0000
26 0 6 ff0000
27 0 6 ff0000
28 0 6 ff0000
29 0 6 ff0000
30 0 6 ff0000
31 0 6 ff0000
23 1 6 ff0000
23 2 6 ff0000
23 3 6 ff0000
23 4 6 ff0000
23 5 6 ff0000
23 6 6 ff0000
23 7 6 ff0000
23 8 6 ff0000
23 9 6 ff0000
23 10 6 ff0000
23 11 6 ff0000
23 12 6 ff0000
23 13 6 ff0000
16 0 7 ff0000
17 0 7 ff0000
18 0 7 ff0000
19 0 7 ff0000
20 0 7 ff0000
21 0 7 ff0000
22 0 7 ff0000
23 0 7 ff0000
24 0 7 ff0000
25 0 7 ff0000
26 0 7 ff0000
27 0 7 ff0000
28 0 7 ff0000
29 0 7 ff0000
30 0 7 ff0000
31 0 7 ff0000
23 1 7 ff0000
23 2 7 ff0000
23 3 7 ff0000
23 4 7 ff0000
23 5 7 ff0000
23 6 7 ff0000
23 7 7 ff0000
23 8 7 ff0000
23 9 7 ff0000
23 10 7 ff0000
23 11 7 ff0000
23 12 7 ff0000
23 13 7 ff0000
23 14 7 ff0000
23 15 7 ff0000
16 0 8 ff0000
17 0 8 ff0000
18 0 8 ff0000
19 0 8 ff0000
20 0 8 ff0000
21 0 8 ff0000
22 0 8 ff0000
23 0 8 ff0000
24 0 8 ff0000
25 0 8 ff0000
26 0 8 ff0000
27 0 8 ff0000
28 0 8 ff0000
29 0 8 ff0000
30 0 8 ff0000
31 0 8 ff0000
23 1 8 ff0000
23 2 8 ff0000
23 3 8 ff0000
23 4 8 ff0000
23 5 8 ff0000
23 6 8 ff0000
23 7 8 ff0000
23 8 8 ff0000
23 9 8 ff0000
23 10 8 ff0000
23 11 8 ff0000
23 12 8 ff0000
23 13 8 ff0000
23 14 8 ff0000
23 15 8 ff0000
16 0 9 ff0000
17 0 9 ff0000
18 0 9 ff0000
19 0 9 ff0000
20 0 9 ff0000
21 0 9 ff0000
22 0 9 ff0000
23 0 9 ff0000
24 0 9 ff0000
25 0 9 ff0000
26 0 9 ff0000
27 0 9 ff0000
28 0 9 ff0000
29 0 9 ff0000
30 0 9 ff0000
31 0 9 ff0000
23 1 9 ff0000
23 2 9 ff0000
23 3 9 ff0000
23 4 9 ff0000
23 5 9 ff0000
23 6 9 ff0000
23 7 9 ff0000
23 8 9 ff0000
23 9 9 ff0000
23 10 9 ff0000
23 11 9 ff0000
23 12 9 ff0000
23 13 9 ff0000
23 14 9 ff0000
23 15 9 ff0000
16 0 10 ff0000
17 0 10 ff0000
18 0 10 ff0000
19 0 10 ff0000
20 0 10 ff0000
21 0 10 ff0000
22 0 10 ff0000
23 0 10 ff0000
24 0 10 ff0000
25 0 10 ff0000
26 0 10 ff0000
27 0 10 ff0000
28 0 10 ff0000
29 0 10 ff0000
30 0 10 ff0000
31 0 10 ff0000
23 1 10 ff0000
23 2 10 ff0000
23 3 10 ff0000
23 4 10 ff0000
23 5 10 ff0000
23 6 10 ff0000
23 7 10 ff0000
23 8 10 ff0000
23 9 10 ff0000
23 10 10 ff0000
23 11 10 ff0000
23 12 10 ff0000
23 13 10 ff0000
23 14 10 ff0000
23 15 10 ff0000
23 17 1 ff0000
23 18 1 ff0000
23 19 1 ff0000
23 20 1 ff0000
23 21 1 ff0000
23 22 1 ff0000
23 23 1 ff0000
23 24 1 ff0000
23 25 1 ff0000
23 26 1 ff0000
23 27 1 ff0000
23 28 1 ff0000
23 29 1 ff0000
23 30 1 ff0000
23 31 1 ff0000
23 17 2 ff0000
23 18 2 ff0000
23 19 2 ff0000
23 20 2 ff0000
23 21 2 ff0000
23 22 2 ff0000
23 23 2 ff0000
23 24 2 ff0000
23 25 2 ff0000
23 26 2 ff0000
23 27 2 ff0000
23 28 2 ff0000
23 29 2 ff0000
23 30 2 ff0000
23 31 2 ff0000
23 17 3 ff0000
23 18 3 ff0000
23 19 3 ff0000
23 20 3 ff0000
23 21 3 ff0000
23 22 3 ff0000
23 23 3 ff0000
23 24 3 ff0000
23 25 3 ff0000
23 26 3 ff0000
23 27 3 ff0000
23 28 3 ff0000
23 29 3 ff0000
23 30 3 ff0000
23 31 3 ff0000
23 17 4 ff0000
23 18 4 ff0000
23 19 4 ff0000
23 20 4 ff0000
23 21 4 ff0000
23 22 4 ff0000
23 23 4 ff0000
23 24 4 ff0000
23 25 4 ff0000
23 26 4 ff0000
23 27 4 ff0000
23 28 4 ff0000
23 29 4 ff0000
23 30 4 ff0000
23 31 4 ff0000
23 17 5 ff0000
23 18 5 ff0000
23 19 5 ff0000
23 20 5 ff0000
23 21 5 ff0000
23 22 5 ff0000
23 23 5 ff0000
23 24 5 ff0000
23 25 5 ff0000
23 26 5 ff0000
23 27 5 ff0000
23 28 5 ff0000
23 29 5 ff0000
23 30 5 ff0000
23 31 5 ff0000
23 17 6 ff0000
23 18 6 ff0000
23 19 6 ff0000
23 20 6 ff0000
23 21 6 ff0000
23 22 6 ff0000
23 23 6 ff0000
23 24 6 ff0000
23 25 6 ff0000
23 26 6 ff0000
23 27 6 ff0000
23 28 6 ff0000
23 29 6 ff0000
23 30 6 ff0000
23 31 6 ff0000
23 16 7 ff0000
23 17 7 ff0000
23 18 7 ff0000
23 19 7 ff0000
23 20 7 ff0000
23 21 7 ff0000
23 22 7 ff0000
23 23 7 ff0000
23 24 7 ff0000
23 25 7 ff0000
23 26 7 ff0000
23 27 7 ff0000
23 28 7 ff0000
23 29 7 ff0000
23 30 7 ff0000
23 31 7 ff0000
23 16 8 ff0000
23 17 8 ff0000
23 18 8 ff0000
23 19 8 ff0000
23 20 8 ff0000
23 21 8 ff0000
23 22 8 ff0000
23 23 8 ff0000
23 24 8 ff0000
23 25 8 ff0000
23 26 8 ff0000
23 27 8 ff0000
23 28 8 ff0000
23 29 8 ff0000
23 30 8 ff0000
23 31 8 ff0000
23 16 9 ff0000
23 17 9 ff0000
23 18 9 ff0000
23 19 9 ff0000
23 20 9 ff0000
23 21 9 ff0000
23 22 9 ff0000
23 23 9 ff0000
23 24 9 ff0000
23 25 9 ff0000
23 26 9 ff0000
23 27 9 ff0000
23 28 9 ff0000
23 29 9 ff0000
23 30 9 ff0000
23 31 9 ff0000
23 16 10 ff0000
23 17 10 ff0000
23 18 10 ff0000
23 19 10 ff0000
23 20 10 ff0000
23 21 10 ff0000
23 22 10 ff0000
23 23 10 ff0000
23 24 10 ff0000
23 25 10 ff0000
23 26 10 ff0000
23 27 10 ff0000
23 28 10 ff0000
23 29 10 ff0000
23 30 10 ff0000
23 31 10 ff0000
0 32 1 ff0000
1 32 1 ff0000
2 32 1 ff0000
3 32 1 ff0000
4 32 1 ff0000
5 32 1 ff0000
6 32 1 ff0000
7 32 1 ff0000
8 32 1 ff0000
9 32 1 ff0000
10 32 1 ff0000
11 32 1 ff0000
12 32 1 ff0000
13 32 1 ff0000
14 32 1 ff0000
15 32 1 ff0000
0 33 1 ff0000
0 34 1 ff0000
0 35 1 ff0000
0 36 1 ff0000
0 37 1 ff0000
0 38 1 ff0000
0 39 1 ff0000
0 40 1 ff0000
0 41 1 ff0000
0 42 1 ff0000
0 43 1 ff0000
0 44 1 ff0000
0 45 1 ff0000
0 46 1 ff0000
0 47 1 ff0000
1 47 1 ff0000
2 47 1 ff0000
3 47 1 ff0000
4 47 1 ff0000
5 47 1 ff0000
6 47 1 ff0000
7 47 1 ff0000
8 47 1 ff0000
9 47 1 ff0000
10 47 1 ff0000
11 47 1 ff0000
15 47 1 ff0000
0 32 2 ff0000
1 32 2 ff0000
2 32 2 ff0000
3 32 2 ff0000
4 32 2 ff0000
5 32 2 ff0000
6 32 2 ff0000
7 32 2 ff0000
8 32 2 ff0000
9 32 2 ff0000
10 32 2 ff0000
11 32 2 ff0000
12 32 2 ff0000
13 32 2 ff0000
14 32 2 ff0000
15 32 2 ff0000
0 33 2 ff0000
0 34 2 ff0000
0 35 2 ff0000
0 36 2 ff0000
0 37 2 ff0000
0 38 2 ff0000
0 39 2 ff0000
0 40 2 ff0000
0 41 2 ff0000
0 42 2 ff0000
0 43 2 ff0000
0 44 2 ff0000
0 45 2 ff0000
0 46 2 ff0000
0 47 2 ff0000
1 47 2 ff0000
2 47 2 ff0000
3 47 2 ff0000
4 47 2 ff0000
5 47 2 ff0000
6 47 2 ff0000
7 47 2 ff0000
8 47 2 ff0000
9 47 2 ff0000
10 47 2 ff0000
11 47 2 ff0000
15 47 2 ff0000
0 32 3 ff0000
1 32 3 ff0000
2 32 3 ff0000
3 32 3 ff0000
4 32 3 ff0000
5 32 3 ff0000
6 32 3 ff0000
7 32 3 ff0000
8 32 3 ff0000
9 32 3 ff0000
10 32 3 ff0000
11 32 3 ff0000
12 32 3 ff0000
13 32 3 ff0000
14 32 3 ff0000
15 32 3 ff0000
0 33 3 ff0000
0 34 3 ff0000
0 35 3 ff0000
0 36 3 ff0000
0 37 3 ff0000
0 38 3 ff0000
0 39 3 ff0000
0 40 3 ff0000
0 41 3 ff0000
0 42 3 ff0000
0 43 3 ff0000
0 44 3 ff0000
0 45 3 ff0000
0 46 3 ff0000
0 47 3 ff0000
1 47 3 ff0000
2 47 3 ff0000
3 47 3 ff0000
4 47 3 ff0000
5 47 3 ff0000
6 47 3 ff0000
7 47 3 ff0000
8 47 3 ff0000
9 47 3 ff0000
10 47 3 ff0000
11 47 3 ff0000
15 47 3 ff0000
0 32 4 ff0000
1 32 4 ff0000
2 32 4 ff0000
3 32 4 ff0000
4 32 4 ff0000
5 32 4 ff0000
6 32 4 ff0000
7 32 4 ff0000
8 32 4 ff0000
9 32 4 ff0000
10 32 4 ff0000
11 32 4 ff0000
12 32 4 ff0000
13 32 4 ff0000
14 32 4 ff0000
15 32 4 ff0000
0 33 4 ff0000
0 34 4 ff0000
0 38 4 ff0000
0 39 4 ff0000
0 40 4 ff0000
0 41 4 ff0000
0 45 4 ff0000
0 46 4 ff0000
0 47 4 ff0000
1 47 4 ff0000
2 47 4 ff0000
3 47 4 ff0000
4 47 4 ff0000
8 47 4 ff0000
9 47 4 ff0000
10 47 4 ff0000
11 47 4 ff0000
15 47 4 ff0000
0 32 5 ff0000
1 32 5 ff0000
2 32 5 ff0000
3 32 5 ff0000
4 32 5 ff0000
5 32 5 ff0000
6 32 5 ff0000
7 32 5 ff0000
8 32 5 ff0000
9 32 5 ff0000
10 32 5 ff0000
11 32 5 ff0000
12 32 5 ff0000
13 32 5 ff0000
14 32 5 ff0000
15 32 5 ff0000
0 33 5 ff0000
0 34 5 ff0000
0 38 5 ff0000
0 39 5 ff0000
0 40 5 ff0000
0 41 5 ff0000
0 45 5 ff0000
0 46 5 ff0000
0 47 5 ff0000
1 47 5 ff0000
2 47 5 ff0000
3 47 5 ff0000
4 47 5 ff0000
8 47 5 ff0000
9 47 5 ff0000
10 47 5 ff0000
11 47 5 ff0000
12 47 5 ff0000
13 47 5 ff0000
14 47 5 ff0000
15 47 5 ff0000
0 32 6 ff0000
1 32 6 ff0000
2 32 6 ff0000
3 32 6 ff0000
4 32 6 ff0000
5 32 6 ff0000
6 32 6 ff0000
7 32 6 ff0000
8 32 6 ff0000
9 32 6 ff0000
10 32 6 ff0000
11 32 6 ff0000
12 32 6 ff0000
13 32 6 ff0000
14 32 6 ff0000
15 32 6 ff0000
0 33 6 ff0000
0 34 6 ff0000
0 38 6 ff0000
0 39 6 ff0000
0 40 6 ff0000
0 41 6 ff0000
0 45 6 ff0000
0 46 6 ff0000
0 47 6 ff0000
1 47 6 ff0000
2 47 6 ff0000
3 47 6 ff0000
4 47 6 ff0000
8 47 6 ff0000
9 47 6 ff0000
10 47 6 ff0000
11 47 6 ff0000
12 47 6 ff0000
13 47 6 ff0000
14 47 6 ff0000
15 47 6 ff0000
0 32 7 ff0000
1 32 7 ff0000
2 32 7 ff0000
3 32 7 ff0000
4 32 7 ff0000
5 32 7 ff0000
6 32 7 ff0000
7 32 7 ff0000
8 32 7 ff0000
9 32 7 ff0000
10 32 7 ff0000
11 32 7 ff0000
12 32 7 ff0000
13 32 7 ff0000
14 32 7 ff0000
15 32 7 ff0000
0 33 7 ff0000
0 34 7 ff0000
0 38 7 ff0000
0 39 7 ff0000
0 40 7 ff0000
0 41 7 ff0000
0 45 7 ff0000
0 46 7 ff0000
0 47 7 ff0000
1 47 7 ff0000
2 47 7 ff0000
3 47 7 ff0000
4 47 7 ff0000
5 47 7 ff0000
6 47 7 ff0000
7 47 7 ff0000
8 47 7 ff0000
9 47 7 ff0000
10 47 7 ff0000
11 47 7 ff0000
12 47 7 ff0000
13 47 7 ff0000
14 47 7 ff0000
15 47 7 ff0000
0 32 8 ff0000
1 32 8 ff0000
2 32 8 ff0000
3 32 8 ff0000
4 32 8 ff0000
5 32 8 ff0000
6 32 8 ff0000
7 32 8 ff0000
8 32 8 ff0000
9 32 8 ff0000
10 32 8 ff0000
11 32 8 ff0000
12 32 8 ff0000
13 32 8 ff0000
14 32 8 ff0000
15 32 8 ff0000
0 33 8 ff0000
0 34 8 ff0000
0 35 8 ff0000
0 36 8 ff0000
0 37 8 ff0000
0 38 8 ff0000
0 39 8 ff0000
0 40 8 ff0000
0 41 8 ff0000
0 42 8 ff0000
0 43 8 ff0000
0 44 8 ff0000
0 45 8 ff0000
0 46 8 ff0000
0 47 8 ff0000
1 47 8 ff0000
2 47 8 ff0000
3 47 8 ff0000
4 47 8 ff0000
5 47 8 ff0000
6 47 8 ff0000
7 47 8 ff0000
8 47 8 ff0000
9 47 8 ff0000
10 47 8 ff0000
11 47 8 ff0000
12 47 8 ff0000
13 47 8 ff0000
14 47 8 ff0000
15 47 8 ff0000
0 32 9 ff0000
1 32 9 ff0000
2 32 9 ff0000
3 32 9 ff0000
4 32 9 ff0000
5 32 9 ff0000
6 32 9 ff0000
7 32 9 ff0000
8 32 9 ff0000
9 32 9 ff0000
10 32 9 ff0000
11 32 9 ff0000
12 32 9 ff0000
13 32 9 ff0000
14 32 9 ff0000
15 32 9 ff0000
0 33 9 ff0000
0 34 9 ff0000
0 35 9 ff0000
0 36 9 ff0000
0 37 9 ff0000
0 38 9 ff0000
0 39 9 ff0000
0 40 9 ff0000
0 41 9 ff0000
0 42 9 ff0000
0 43 9 ff0000
0 44 9 ff0000
0 45 9 ff0000
0 46 9 ff0000
0 47 9 ff0000
1 47 9 ff0000
2 47 9 ff0000
3 47 9 ff0000
4 47 9 ff0000
5 47 9 ff0000
6 47 9 ff0000
7 47 9 ff0000
8 47 9 ff0000
9 47 9 ff0000
10 47 9 ff0000
11 47 9 ff0000
12 47 9 ff0000
13 47 9 ff0000
14 47 9 ff0000
15 47 9 ff0000
0 32 10 ff0000
1 32 10 ff0000
2 32 10 ff0000
3 32 10 ff0000
4 32 10 ff0000
5 32 10 ff0000
6 32 10 ff0000
7 32 10 ff0000
8 32 10 ff0000
9 32 10 ff0000
10 32 10 ff0000
11 32 10 ff0000
12 32 10 ff0000
13 32 10 ff0000
14 32 10 ff0000
15 32 10 ff0000
0 33 10 ff0000
0 34 10 ff0000
0 35 10 ff0000
0 36 10 ff0000
0 37 10 ff0000
0 38 10 ff0000
0 39 10 ff0000
0 40 10 ff0000
0 41 10 ff0000
0 42 10 ff0000
0 43 10 ff0000
0 44 10 ff0000
0 45 10 ff0000
0 46 10 ff0000
0 47 10 ff0000
1 47 10 ff0000
2 47 10 ff0000
3 47 10 ff0000
4 47 10 ff0000
5 47 10 ff0000
6 47 10 ff0000
7 47 10 ff0000
8 47 10 ff0000
9 47 10 ff0000
10 47 10 ff0000
11 47 10 ff0000
12 47 10 ff0000
13 47 10 ff0000
14 47 10 ff0000
15 47 10 ff0000
0 0 1 ff0000
1 0 1 ff0000
2 0 1 ff0000
3 0 1 ff0000
4 0 1 ff0000
5 0 1 ff0000
6 0 1 ff0000
7 0 1 ff0000
8 0 1 ff0000
9 0 1 ff0000
10 0 1 ff0000
11 0 1 ff0000
12 0 1 ff0000
13 0 1 ff0000
14 0 1 ff0000
15 0 1 ff0000
0 1 1 ff0000
0 2 1 ff0000
0 3 1 ff0000
0 4 1 ff0000
0 5 1 ff0000
0 6 1 ff0000
0 7 1 ff0000
0 8 1 ff0000
0 9 1 ff0000
0 10 1 ff0000
0 11 1 ff0000
0 12 1 ff0000
0 13 1 ff0000
0 14 1 ff0000
0 15 1 ff0000
0 0 2 ff0000
1 0 2 ff0000
2 0 2 ff0000
3 0 2 ff0000
4 0 2 ff0000
5 0 2 ff0000
6 0 2 ff0000
7 0 2 ff0000
8 0 2 ff0000
9 0 2 ff0000
10 0 2 ff0000
11 0 2 ff0000
12 0 2 ff0000
13 0 2 ff0000
14 0 2 ff0000
15 0 2 ff0000
0 1 2 ff0000
0 2 2 ff0000
0 3 2 ff0000
0 4 2 ff0000
0 5 2 ff0000
0 6 2 ff0000
0 7 2 ff0000
0 8 2 ff0000
0 9 2 ff0000
0 10 2 ff0000
0 11 2 ff0000
0 12 2 ff0000
0 13 2 ff0000
0 14 2 ff0000
0 15 2 ff0000
0 0 3 ff0000
1 0 3 ff0000
2 0 3 ff0000
3 0 3 ff0000
4 0 3 ff0000
5 0 3 ff0000
6 0 3 ff0000
7 0 3 ff0000
8 0 3 ff0000
9 0 3 ff0000
10 0 3 ff0000
11 0 3 ff0000
12 0 3 ff0000
13 0 3 ff0000
14 0 3 ff0000
15 0 3 ff0000
0 1 3 ff0000
0 2 3 ff0000
0 3 3 ff0000
0 4 3 ff0000
0 5 3 ff0000
0 6 3 ff0000
0 7 3 ff0000
0 8 3 ff0000
0 9 3 ff0000
0 10 3 ff0000
0 11 3 ff0000
0 12 3 ff0000
0 13 3 ff0000
0 14 3 ff0000
0 15 3 ff0000
0 0 4 ff0000
1 0 4 ff0000
2 0 4 ff0000
3 0 4 ff0000
4 0 4 ff0000
5 0 4 ff0000
6 0 4 ff0000
7 0 4 ff0000
8 0 4 ff0000
9 0 4 ff0000
10 0 4 ff0000
11 0 4 ff0000
12 0 4 ff0000
13 0 4 ff0000
14 0 4 ff0000
15 0 4 ff0000
0 1 4 ff0000
0 2 4 ff0000
0 3 4 ff0000
0 4 4 ff0000
0 5 4 ff0000
0 6 4 ff0000
0 10 4 ff0000
0 11 4 ff0000
0 12 4 ff0000
0 13 4 ff0000
0 14 4 ff0000
0 15 4 ff0000
0 0 5 ff0000
1 0 5 ff0000
2 0 5 ff0000
3 0 5 ff0000
4 0 5 ff0000
5 0 5 ff0000
6 0 5 ff0000
7 0 5 ff0000
8 0 5 ff0000
9 0 5 ff0000
10 0 5 ff0000
11 0 5 ff0000
12 0 5 ff0000
13 0 5 ff0000
14 0 5 ff0000
15 0 5 ff0000
0 1 5 ff0000
0 2 5 ff0000
0 3 5 ff0000
0 4 5 ff0000
0 5 5 ff0000
0 6 5 ff0000
0 10 5 ff0000
0 11 5 ff0000
0 12 5 ff0000
0 13 5 ff0000
0 14 5 ff0000
0 15 5 ff0000
0 0 6 ff0000
1 0 6 ff0000
2 0 6 ff0000
3 0 6 ff0000
4 0 6 ff0000
5 0 6 ff0000
6 0 6 ff0000
7 0 6 ff0000
8 0 6 ff0000
9 0 6 ff0000
10 0 6 ff0000
11 0 6 ff0000
12 0 6 ff0000
13 0 6 ff0000
14 0 6 ff0000
15 0 6 ff0000
0 1 6 ff0000
0 2 6 ff0000
0 3 6 ff0000
0 4 6 ff0000
0 5 6 ff0000
0 6 6 ff0000
0 10 6 ff0000
0 11 6 ff0000
0 12 6 ff0000
0 13 6 ff0000
0 14 6 ff0000
0 15 6 ff0000
0 0 7 ff0000
1 0 7 ff0000
2 0 7 ff0000
3 0 7 ff0000
4 0 7 ff0000
5 0 7 ff0000
6 0 7 ff0000
7 0 7 ff0000
8 0 7 ff0000
9 0 7 ff0000
10 0 7 ff0000
11 0 7 ff0000
12 0 7 ff0000
13 0 7 ff0000
14 0 7 ff0000
15 0 7 ff0000
0 1 7 ff0000
0 2 7 ff0000
0 3 7 ff0000
0 4 7 ff0000
0 5 7 ff0000
0 6 7 ff0000
0 10 7 ff0000
0 11 7 ff0000
0 12 7 ff0000
0 13 7 ff0000
0 14 7 ff0000
0 15 7 ff0000
0 0 8 ff0000
1 0 8 ff0000
2 0 8 ff0000
3 0 8 ff0000
4 0 8 ff0000
5 0 8 ff0000
6 0 8 ff0000
7 0 8 ff0000
8 0 8 ff0000
9 0 8 ff0000
10 0 8 ff0000
11 0 8 ff0000
12 0 8 ff0000
13 0 8 ff0000
14 0 8 ff0000
15 0 8 ff0000
0 1 8 ff0000
0 2 8 ff0000
0 3 8 ff0000
0 4 8 ff0000
0 5 8 ff0000
0 6 8 ff0000
0 7 8 ff0000
0 8 8 ff0000
0 9 8 ff0000
0 10 8 ff0000
0 11 8 ff0000
0 12 8 ff0000
0 13 8 ff0000
0 14 8 ff0000
0 15 8 ff0000
0 0 9 ff0000
1 0 9 ff0000
2 0 9 ff0000
3 0 9 ff0000
4 0 9 ff0000
5 0 9 ff0000
6 0 9 ff0000
7 0 9 ff0000
8 0 9 ff0000
9 0 9 ff0000
10 0 9 ff0000
11 0 9 ff0000
12 0 9 ff0000
13 0 9 ff0000
14 0 9 ff0000
15 0 9 ff0000
0 1 9 ff0000
0 2 9 ff0000
0 3 9 ff0000
0 4 9 ff0000
0 5 9 ff0000
0 6 9 ff0000
0 7 9 ff0000
0 8 9 ff0000
0 9 9 ff0000
0 10 9 ff0000
0 11 9 ff0000
0 12 9 ff0000
0 13 9 ff0000
0 14 9 ff0000
0 15 9 ff0000
0 0 10 ff0000
1 0 10 ff0000
2 0 10 ff0000
3 0 10 ff0000
4 0 10 ff0000
5 0 10 ff0000
6 0 10 ff0000
7 0 10 ff0000
8 0 10 ff0000
9 0 10 ff0000
10 0 10 ff0000
11 0 10 ff0000
12 0 10 ff0000
13 0 10 ff0000
14 0 10 ff0000
15 0 10 ff0000
0 1 10 ff0000
0 2 10 ff0000
0 3 10 ff0000
0 4 10 ff0000
0 5 10 ff0000
0 6 10 ff0000
0 7 10 ff0000
0 8 10 ff0000
0 9 10 ff0000
0 10 10 ff0000
0 11 10 ff0000
0 12 10 ff0000
0 13 10 ff0000
0 14 10 ff0000
0 15 10 ff0000
32 0 1 ff0000
33 0 1 ff0000
34 0 1 ff0000
35 0 1 ff0000
36 0 1 ff0000
43 0 1 ff0000
44 0 1 ff0000
45 0 1 ff0000
46 0 1 ff0000
47 0 1 ff0000
32 0 2 ff0000
33 0 2 ff0000
34 0 2 ff0000
35 0 2 ff0000
36 0 2 ff0000
43 0 2 ff0000
44 0 2 ff0000
45 0 2 ff0000
46 0 2 ff0000
47 0 2 ff0000
32 0 3 ff0000
33 0 3 ff0000
34 0 3 ff0000
35 0 3 ff0000
36 0 3 ff0000
43 0 3 ff0000
44 0 3 ff0000
45 0 3 ff0000
46 0 3 ff0000
47 0 3 ff0000
32 0 4 ff0000
33 0 4 ff0000
34 0 4 ff0000
35 0 4 ff0000
36 0 4 ff0000
43 0 4 ff0000
44 0 4 ff0000
45 0 4 ff0000
46 0 4 ff0000
47 0 4 ff0000
32 0 5 ff0000
33 0 5 ff0000
34 0 5 ff0000
35 0 5 ff0000
36 0 5 ff0000
43 0 5 ff0000
44 0 5 ff0000
45 0 5 ff0000
46 0 5 ff0000
47 0 5 ff0000
32 0 6 ff0000
33 0 6 ff0000
34 0 6 ff0000
35 0 6 ff0000
36 0 6 ff0000
37 0 6 ff0000
38 0 6 ff0000
39 0 6 ff0000
40 0 6 ff0000
41 0 6 ff0000
42 0 6 ff0000
43 0 6 ff0000
44 0 6 ff0000
45 0 6 ff0000
46 0 6 ff0000
47 0 6 ff0000
32 0 7 ff0000
33 0 7 ff0000
34 0 7 ff0000
35 0 7 ff0000
36 0 7 ff0000
37 0 7 ff0000
38 0 7 ff0000
39 0 7 ff0000
40 0 7 ff0000
41 0 7 ff0000
42 0 7 ff0000
43 0 7 ff0000
44 0 7 ff0000
45 0 7 ff0000
46 0 7 ff0000
47 0 7 ff0000
32 0 8 ff0000
33 0 8 ff0000
34 0 8 ff0000
35 0 8 ff0000
36 0 8 ff0000
37 0 8 ff0000
38 0 8 ff0000
39 0 8 ff0000
40 0 8 ff0000
41 0 8 ff0000
42 0 8 ff0000
43 0 8 ff0000
44 0 8 ff0000
45 0 8 ff0000
46 0 8 ff0000
47 0 8 ff0000
32 0 9 ff0000
33 0 9 ff0000
34 0 9 ff0000
35 0 9 ff0000
36 0 9 ff0000
37 0 9 ff0000
38 0 9 ff0000
39 0 9 ff0000
40 0 9 ff0000
41 0 9 ff0000
42 0 9 ff0000
43 0 9 ff0000
44 0 9 ff0000
45 0 9 ff0000
46 0 9 ff0000
47 0 9 ff0000
32 0 10 ff0000
33 0 10 ff0000
34 0 10 ff0000
35 0 10 ff0000
36 0 10 ff0000
37 0 10 ff0000
38 0 10 ff0000
39 0 10 ff0000
40 0 10 ff0000
41 0 10 ff0000
42 0 10 ff0000
43 0 10 ff0000
44 0 10 ff0000
45 0 10 ff0000
46 0 10 ff0000
47 0 10 ff0000
64 0 1 ff0000
65 0 1 ff0000
66 0 1 ff0000
67 0 1 ff0000
68 0 1 ff0000
69 0 1 ff0000
70 0 1 ff0000
71 0 1 ff0000
72 0 1 ff0000
73 0 1 ff0000
74 0 1 ff0000
75 0 1 ff0000
76 0 1 ff0000
77 0 1 ff0000
78 0 1 ff0000
79 0 1 ff0000
79 1 1 ff0000
79 2 1 ff0000
79 3 1 ff0000
79 4 1 ff0000
79 5 1 ff0000
79 6 1 ff0000
79 7 1 ff0000
79 8 1 ff0000
79 9 1 ff0000
79 10 1 ff0000
79 11 1 ff0000
79 12 1 ff0000
79 13 1 ff0000
79 14 1 ff0000
79 15 1 ff0000
64 0 2 ff0000
65 0 2 ff0000
66 0 2 ff0000
67 0 2 ff0000
68 0 2 ff0000
69 0 2 ff0000
70 0 2 ff0000
71 0 2 ff0000
72 0 2 ff0000
73 0 2 ff0000
74 0 2 ff0000
75 0 2 ff0000
76 0 2 ff0000
77 0 2 ff0000
78 0 2 ff0000
79 0 2 ff0000
79 1 2 ff0000
79 2 2 ff0000
79 3 2 ff0000
79 4 2 ff0000
79 5 2 ff0000
79 6 2 ff0000
79 7 2 ff0000
79 8 2 ff0000
79 9 2 ff0000
79 10 2 ff0000
79 11 2 ff0000
79 12 2 ff0000
79 13 2 ff0000
79 14 2 ff0000
79 15 2 ff0000
64 0 3 ff0000
65 0 3 ff0000
66 0 3 ff0000
67 0 3 ff0000
68 0 3 ff0000
69 0 3 ff0000
70 0 3 ff0000
71 0 3 ff0000
72 0 3 ff0000
73 0 3 ff0000
74 0 3 ff0000
75 0 3 ff0000
76 0 3 ff0000
77 0 3 ff0000
78 0 3 ff0000
79 0 3 ff0000
79 1 3 ff0000
79 2 3 ff0000
79 3 3 ff0000
79 4 3 ff0000
79 5 3 ff0000
79 6 3 ff0000
79 7 3 ff0000
79 8 3 ff0000
79 9 3 ff0000
79 10 3 ff0000
79 11 3 ff0000
79 12 3 ff0000
79 13 3 ff0000
79 14 3 ff0000
79 15 3 ff0000
64 0 4 ff0000
65 0 4 ff0000
66 0 4 ff0000
67 0 4 ff0000
68 0 4 ff0000
69 0 4 ff0000
70 0 4 ff0000
71 0 4 ff0000
72 0 4 ff0000
73 0 4 ff0000
74 0 4 ff0000
75 0 4 ff0000
76 0 4 ff0000
77 0 4 ff0000
78 0 4 ff0000
79 0 4 ff0000
79 1 4 ff0000
79 2 4 ff0000
79 3 4 ff0000
79 4 4 ff0000
79 5 4 ff0000
79 6 4 ff0000
79 7 4 ff0000
79 8 4 ff0000
79 9 4 ff0000
79 10 4 ff0000
79 11 4 ff0000
79 12 4 ff0000
79 13 4 ff0000
79 14 4 ff0000
79 15 4 ff0000
64 0 5 ff0000
65 0 5 ff0000
66 0 5 ff0000
67 0 5 ff0000
68 0 5 ff0000
69 0 5 ff0000
70 0 5 ff0000
71 0 5 ff0000
72 0 5 ff0000
73 0 5 ff0000
74 0 5 ff0000
75 0 5 ff0000
76 0 5 ff0000
77 0 5 ff0000
78 0 5 ff0000
79 0 5 ff0000
79 1 5 ff0000
79 2 5 ff0000
79 3 5 ff0000
79 4 5 ff0000
79 5 5 ff0000
79 6 5 ff0000
79 7 5 ff0000
79 8 5 ff0000
79 9 5 ff0000
79 10 5 ff0000
79 11 5 ff0000
79 12 5 ff0000
79 13 5 ff0000
79 14 5 ff0000
79 15 5 ff0000
64 0 6 ff0000
65 0 6 ff0000
66 0 6 ff0000
67 0 6 ff0000
68 0 6 ff0000
69 0 6 ff0000
70 0 6 ff0000
71 0 6 ff0000
72 0 6 ff0000
73 0 6 ff0000
74 0 6 ff0000
75 0 6 ff0000
76 0 6 ff0000
77 0 6 ff0000
78 0 6 ff0000
79 0 6 ff0000
79 1 6 ff0000
79 2 6 ff0000
79 3 6 ff0000
79 4 6 ff0000
79 5 6 ff0000
79 6 6 ff0000
79 7 6 ff0000
79 8 6 ff0000
79 9 6 ff0000
79 10 6 ff0000
79 11 6 ff0000
79 12 6 ff0000
79 13 6 ff0000
79 14 6 ff0000
79 15 6 ff0000
64 0 7 ff0000
65 0 7 ff0000
66 0 7 ff0000
67 0 7 ff0000
68 0 7 ff0000
69 0 7 ff0000
70 0 7 ff0000
71 0 7 ff0000
72 0 7 ff0000
73 0 7 ff0000
74 0 7 ff0000
75 0 7 ff0000
76 0 7 ff0000
77 0 7 ff0000
78 0 7 ff0000
79 0 7 ff0000
79 1 7 ff0000
79 2 7 ff0000
79 3 7 ff0000
79 6 7 ff0000
79 7 7 ff0000
79 8 7 ff0000
79 9 7 ff0000
79 12 7 ff0000
79 13 7 ff0000
79 14 7 ff0000
79 15 7 ff0000
64 0 8 ff0000
65 0 8 ff0000
66 0 8 ff0000
67 0 8 ff0000
68 0 8 ff0000
69 0 8 ff0000
70 0 8 ff0000
71 0 8 ff0000
72 0 8 ff0000
73 0 8 ff0000
74 0 8 ff0000
75 0 8 ff0000
76 0 8 ff0000
77 0 8 ff0000
78 0 8 ff0000
79 0 8 ff0000
79 1 8 ff0000
79 2 8 ff0000
79 3 8 ff0000
79 6 8 ff0000
79 7 8 ff0000
79 8 8 ff0000
79 9 8 ff0000
79 12 8 ff0000
79 13 8 ff0000
79 14 8 ff0000
79 15 8 ff0000
64 0 9 ff0000
65 0 9 ff0000
66 0 9 ff0000
67 0 9 ff0000
68 0 9 ff0000
69 0 9 ff0000
70 0 9 ff0000
71 0 9 ff0000
72 0 9 ff0000
73 0 9 ff0000
74 0 9 ff0000
75 0 9 ff0000
76 0 9 ff0000
77 0 9 ff0000
78 0 9 ff0000
79 0 9 ff0000
79 1 9 ff0000
79 2 9 ff0000
79 3 9 ff0000
79 4 9 ff0000
79 5 9 ff0000
79 6 9 ff0000
79 7 9 ff0000
79 8 9 ff0000
79 9 9 ff0000
79 10 9 ff0000
79 11 9 ff0000
79 12 9 ff0000
79 13 9 ff0000
79 14 9 ff0000
79 15 9 ff0000
64 0 10 ff0000
65 0 10 ff0000
66 0 10 ff0000
67 0 10 ff0000
68 0 10 ff0000
69 0 10 ff0000
70 0 10 ff0000
71 0 10 ff0000
72 0 10 ff0000
73 0 10 ff0000
74 0 10 ff0000
75 0 10 ff0000
76 0 10 ff0000
77 0 10 ff0000
78 0 10 ff0000
79 0 10 ff0000
79 1 10 ff0000
79 2 10 ff0000
79 3 10 ff0000
79 4 10 ff0000
79 5 10 ff0000
79 6 10 ff0000
79 7 10 ff0000
79 8 10 ff0000
79 9 10 ff0000
79 10 10 ff0000
79 11 10 ff0000
79 12 10 ff0000
79 13 10 ff0000
79 14 10 ff0000
79 15 10 ff0000
64 32 1 ffffaa
65 32 1 ffffaa
66 32 1 ffffaa
67 32 1 ffffaa
68 32 1 ffffaa
69 32 1 ffffaa
70 32 1 ffffaa
71 32 1 ffffaa
72 32 1 ffffaa
73 32 1 ffffaa
74 32 1 ffffaa
75 32 1 ffffaa
76 32 1 ffffaa
77 32 1 ffffaa
78 32 1 ffffaa
79 32 1 ff0000
64 33 1 ffffaa
79 33 1 ff0000
64 34 1 ffffaa
79 34 1 ff0000
64 35 1 ffffaa
79 35 1 ff0000
64 36 1 ffffaa
79 36 1 ff0000
64 37 1 ffffaa
79 37 1 ff0000
64 38 1 ffffaa
79 38 1 ff0000
64 39 1 ffffaa
79 39 1 ff0000
64 40 1 ffffaa
79 40 1 ff0000
64 41 1 ffffaa
79 41 1 ff0000
64 42 1 ffffaa
79 42 1 ff0000
64 43 1 ffffaa
79 43 1 ff0000
64 44 1 ffffaa
79 44 1 ff0000
79 45 1 ff0000
79 46 1 ff0000
64 47 1 ff0000
65 47 1 ff0000
66 47 1 ff0000
67 47 1 ff0000
68 47 1 ff0000
69 47 1 ff0000
70 47 1 ff0000
71 47 1 ff0000
75 47 1 ff0000
76 47 1 ff0000
77 47 1 ff0000
78 47 1 ff0000
79 47 1 ff0000
64 32 2 ffffaa
65 32 2 ffffaa
66 32 2 ffffaa
67 32 2 ffffaa
68 32 2 ffffaa
69 32 2 ffffaa
70 32 2 ffffaa
71 32 2 ffffaa
72 32 2 ffffaa
73 32 2 ffffaa
74 32 2 ffffaa
75 32 2 ffffaa
76 32 2 ffffaa
77 32 2 ffffaa
78 32 2 ffffaa
79 32 2 ff0000
64 33 2 ffffaa
79 33 2 ff0000
64 34 2 ffffaa
79 34 2 ff0000
64 35 2 ffffaa
79 35 2 ff0000
64 36 2 ffffaa
79 36 2 ff0000
64 37 2 ffffaa
79 37 2 ff0000
64 38 2 ffffaa
79 38 2 ff0000
64 39 2 ffffaa
79 39 2 ff0000
64 40 2 ffffaa
79 40 2 ff0000
64 41 2 ffffaa
79 41 2 ff0000
64 42 2 ffffaa
79 42 2 ff0000
64 43 2 ffffaa
79 43 2 ff0000
64 44 2 ffffaa
79 44 2 ff0000
79 45 2 ff0000
79 46 2 ff0000
64 47 2 ff0000
65 47 2 ff0000
66 47 2 ff0000
67 47 2 ff0000
68 47 2 ff0000
69 47 2 ff0000
70 47 2 ff0000
71 47 2 ff0000
75 47 2 ff0000
76 47 2 ff0000
77 47 2 ff0000
78 47 2 ff0000
79 47 2 ff0000
64 32 3 ffffaa
65 32 3 ffffaa
66 32 3 ffffaa
67 32 3 ffffaa
68 32 3 ffffaa
69 32 3 ffffaa
70 32 3 ffffaa
71 32 3 ffffaa
72 32 3 ffffaa
73 32 3 ffffaa
74 32 3 ffffaa
75 32 3 ffffaa
76 32 3 ffffaa
77 32 3 ffffaa
78 32 3 ffffaa
79 32 3 ff0000
64 33 3 ffffaa
79 33 3 ff0000
64 34 3 ffffaa
79 34 3 ff0000
64 35 3 ffffaa
79 35 3 ff0000
64 36 3 ffffaa
79 36 3 ff0000
64 37 3 ffffaa
79 37 3 ff0000
64 38 3 ffffaa
79 38 3 ff0000
64 39 3 ffffaa
79 39 3 ff0000
64 40 3 ffffaa
79 40 3 ff0000
64 41 3 ffffaa
79 41 3 ff0000
64 42 3 ffffaa
79 42 3 ff0000
64 43 3 ffffaa
79 43 3 ff0000
64 44 3 ffffaa
79 44 3 ff0000
79 45 3 ff0000
79 46 3 ff0000
64 47 3 ff0000
65 47 3 ff0000
66 47 3 ff0000
67 47 3 ff0000
68 47 3 ff0000
69 47 3 ff0000
70 47 3 ff0000
71 47 3 ff0000
75 47 3 ff0000
76 47 3 ff0000
77 47 3 ff0000
78 47 3 ff0000
79 47 3 ff0000
64 32 4 ffffaa
65 32 4 ffffaa
66 32 4 ffffaa
67 32 4 ffffaa
68 32 4 ffffaa
69 32 4 ffffaa
70 32 4 ffffaa
71 32 4 ffffaa
72 32 4 ffffaa
73 32 4 ffffaa
74 32 4 ffffaa
75 32 4 ffffaa
76 32 4 ffffaa
77 32 4 ffffaa
78 32 4 ffffaa
79 32 4 ff0000
64 33 4 ffffaa
79 33 4 ff0000
64 34 4 ffffaa
79 34 4 ff0000
64 35 4 ffffaa
79 35 4 ff0000
64 36 4 ffffaa
79 36 4 ff0000
64 37 4 ffffaa
79 37 4 ff0000
64 38 4 ffffaa
79 38 4 ff0000
64 39 4 ffffaa
79 39 4 ff0000
64 40 4 ffffaa
79 40 4 ff0000
64 41 4 ffffaa
79 41 4 ff0000
64 42 4 ffffaa
79 42 4 ff0000
64 43 4 ffffaa
79 43 4 ff0000
64 44 4 ffffaa
79 44 4 ff0000
79 45 4 ff0000
79 46 4 ff0000
64 47 4 ff0000
65 47 4 ff0000
66 47 4 ff0000
67 47 4 ff0000
68 47 4 ff0000
69 47 4 ff0000
70 47 4 ff0000
71 47 4 ff0000
75 47 4 ff0000
76 47 4 ff0000
77 47 4 ff0000
78 47 4 ff0000
79 47 4 ff0000
64 32 5 ffffaa
65 32 5 ffffaa
66 32 5 ffffaa
67 32 5 ffffaa
68 32 5 ffffaa
69 32 5 ffffaa
70 32 5 ffffaa
71 32 5 ffffaa
72 32 5 ffffaa
73 32 5 ffffaa
74 32 5 ffffaa
75 32 5 ffffaa
76 32 5 ffffaa
77 32 5 ffffaa
78 32 5 ffffaa
79 32 5 ff0000
64 33 5 ffffaa
79 33 5 ff0000
64 34 5 ffffaa
79 34 5 ff0000
64 35 5 ffffaa
79 35 5 ff0000
64 36 5 ffffaa
79 36 5 ff0000
64 37 5 ffffaa
79 37 5 ff0000
64 38 5 ffffaa
79 38 5 ff0000
64 39 5 ffffaa
79 39 5 ff0000
64 40 5 ffffaa
79 40 5 ff0000
64 41 5 ffffaa
79 41 5 ff0000
64 42 5 ffffaa
79 42 5 ff0000
64 43 5 ffffaa
79 43 5 ff0000
64 44 5 ffffaa
79 44 5 ff0000
79 45 5 ff0000
79 46 5 ff0000
64 47 5 ff0000
65 47 5 ff0000
66 47 5 ff0000
67 47 5 ff0000
68 47 5 ff0000
69 47 5 ff0000
70 47 5 ff0000
71 47 5 ff0000
72 47 5 ff0000
73 47 5 ff0000
74 47 5 ff0000
75 47 5 ff0000
76 47 5 ff0000
77 47 5 ff0000
78 47 5 ff0000
79 47 5 ff0000
64 32 6 ffffaa
65 32 6 ffffaa
66 32 6 ffffaa
67 32 6 ffffaa
68 32 6 ffffaa
69 32 6 ffffaa
70 32 6 ffffaa
71 32 6 ffffaa
72 32 6 ffffaa
73 32 6 ffffaa
74 32 6 ffffaa
75 32 6 ffffaa
76 32 6 ffffaa
77 32 6 ffffaa
78 32 6 ffffaa
79 32 6 ff0000
64 33 6 ffffaa
79 33 6 ff0000
64 34 6 ffffaa
79 34 6 ff0000
64 35 6 ffffaa
79 35 6 ff0000
64 36 6 ffffaa
79 36 6 ff0000
64 37 6 ffffaa
79 37 6 ff0000
64 38 6 ffffaa
79 38 6 ff0000
64 39 6 ffffaa
79 39 6 ff0000
64 40 6 ffffaa
79 40 6 ff0000
64 41 6 ffffaa
79 41 6 ff0000
64 42 6 ffffaa
79 42 6 ff0000
64 43 6 ffffaa
79 43 6 ff0000
64 44 6 ffffaa
79 44 6 ff0000
79 45 6 ff0000
79 46 6 ff0000
64 47 6 ff0000
65 47 6 ff0000
66 47 6 ff0000
67 47 6 ff0000
68 47 6 ff0000
69 47 6 ff0000
70 47 6 ff0000
71 47 6 ff0000
72 47 6 ff0000
73 47 6 ff0000
74 47 6 ff0000
75 47 6 ff0000
76 47 6 ff0000
77 47 6 ff0000
78 47 6 ff0000
79 47 6 ff0000
64 32 7 ffffaa
65 32 7 ffffaa
66 32 7 ffffaa
67 32 7 ffffaa
68 32 7 ffffaa
69 32 7 ffffaa
70 32 7 ffffaa
71 32 7 ffffaa
72 32 7 ffffaa
73 32 7 ffffaa
74 32 7 ffffaa
75 32 7 ffffaa
76 32 7 ffffaa
77 32 7 ffffaa
78 32 7 ffffaa
79 32 7 ff0000
64 33 7 ffffaa
79 33 7 ff0000
64 34 7 ffffaa
79 34 7 ff0000
64 35 7 ffffaa
79 35 7 ff0000
64 36 7 ffffaa
79 36 7 ff0000
64 37 7 ffffaa
79 37 7 ff0000
64 38 7 ffffaa
79 38 7 ff0000
64 39 7 ffffaa
79 39 7 ff0000
64 40 7 ffffaa
79 40 7 ff0000
64 41 7 ffffaa
79 41 7 ff0000
64 42 7 ffffaa
64 43 7 ffffaa
64 44 7 ffffaa
79 44 7 ff0000
64 45 7 ffffaa
79 45 7 ff0000
64 46 7 ffffaa
79 46 7 ff0000
64 47 7 ffffaa
65 47 7 ff0000
66 47 7 ff0000
67 47 7 ff0000
68 47 7 ff0000
69 47 7 ff0000
70 47 7 ff0000
71 47 7 ff0000
72 47 7 ff0000
73 47 7 ff0000
74 47 7 ff0000
75 47 7 ff0000
76 47 7 ff0000
77 47 7 ff0000
78 47 7 ff0000
79 47 7 ff0000
64 32 8 ffffaa
65 32 8 ffffaa
66 32 8 ffffaa
67 32 8 ffffaa
68 32 8 ffffaa
69 32 8 ffffaa
70 32 8 ffffaa
71 32 8 ffffaa
72 32 8 ffffaa
73 32 8 ffffaa
74 32 8 ffffaa
75 32 8 ffffaa
76 32 8 ffffaa
77 32 8 ffffaa
78 32 8 ffffaa
79 32 8 ff0000
64 33 8 ffffaa
79 33 8 ff0000
64 34 8 ffffaa
79 34 8 ff0000
64 35 8 ffffaa
79 35 8 ff0000
64 36 8 ffffaa
79 36 8 ff0000
64 37 8 ffffaa
79 37 8 ff0000
64 38 8 ffffaa
79 38 8 ff0000
64 39 8 ffffaa
79 39 8 ff0000
64 40 8 ffffaa
79 40 8 ff0000
64 41 8 ffffaa
79 41 8 ff0000
64 42 8 ffffaa
64 43 8 ffffaa
64 44 8 ffffaa
79 44 8 ff0000
64 45 8 ffffaa
79 45 8 ff0000
64 46 8 ffffaa
79 46 8 ff0000
64 47 8 ffffaa
65 47 8 ff0000
66 47 8 ff0000
67 47 8 ff0000
68 47 8 ff0000
69 47 8 ff0000
70 47 8 ff0000
71 47 8 ff0000
72 47 8 ff0000
73 47 8 ff0000
74 47 8 ff0000
75 47 8 ff0000
76 47 8 ff0000
77 47 8 ff0000
78 47 8 ff0000
79 47 8 ff0000
64 32 9 ffffaa
65 32 9 ffffaa
66 32 9 ffffaa
67 32 9 ffffaa
68 32 9 ffffaa
69 32 9 ffffaa
70 32 9 ffffaa
71 32 9 ffffaa
72 32 9 ffffaa
73 32 9 ffffaa
74 32 9 ffffaa
75 32 9 ffffaa
76 32 9 ffffaa
77 32 9 ffffaa
78 32 9 ffffaa
79 32 9 ff0000
64 33 9 ffffaa
79 33 9 ff0000
64 34 9 ffffaa
79 34 9 ff0000
64 35 9 ffffaa
79 35 9 ff0000
64 36 9 ffffaa
79 36 9 ff0000
64 37 9 ffffaa
79 37 9 ff0000
64 38 9 ffffaa
79 38 9 ff0000
64 39 9 ffffaa
79 39 9 ff0000
64 40 9 ffffaa
79 40 9 ff0000
64 41 9 ffffaa
79 41 9 ff0000
64 42 9 ffffaa
79 42 9 ff0000
64 43 9 ffffaa
79 43 9 ff0000
64 44 9 ffffaa
79 44 9 ff0000
64 45 9 ffffaa
79 45 9 ff0000
64 46 9 ffffaa
79 46 9 ff0000
64 47 9 ffffaa
65 47 9 ff0000
66 47 9 ff0000
67 47 9 ff0000
68 47 9 ff0000
69 47 9 ff0000
70 47 9 ff0000
71 47 9 ff0000
72 47 9 ff0000
73 47 9 ff0000
74 47 9 ff0000
75 47 9 ff0000
76 47 9 ff0000
77 47 9 ff0000
78 47 9 ff0000
79 47 9 ff0000
64 32 10 ffffaa
65 32 10 ffffaa
66 32 10 ffffaa
67 32 10 ffffaa
68 32 10 ffffaa
69 32 10 ffffaa
70 32 10 ffffaa
71 32 10 ffffaa
72 32 10 ffffaa
73 32 10 ffffaa
74 32 10 ffffaa
75 32 10 ffffaa
76 32 10 ffffaa
77 32 10 ffffaa
78 32 10 ffffaa
79 32 10 ff0000
64 33 10 ffffaa
79 33 10 ff0000
64 34 10 ffffaa
79 34 10 ff0000
64 35 10 ffffaa
79 35 10 ff0000
64 36 10 ffffaa
79 36 10 ff0000
64 37 10 ffffaa
79 37 10 ff0000
64 38 10 ffffaa
79 38 10 ff0000
64 39 10 ffffaa
79 39 10 ff0000
64 40 10 ffffaa
79 40 10 ff0000
64 41 10 ffffaa
79 41 10 ff0000
64 42 10 ffffaa
79 42 10 ff0000
64 43 10 ffffaa
79 43 10 ff0000
64 44 10 ffffaa
79 44 10 ff0000
64 45 10 ffffaa
79 45 10 ff0000
64 46 10 ffffaa
79 46 10 ff0000
64 47 10 ffffaa
65 47 10 ff0000
66 47 10 ff0000
67 47 10 ff0000
68 47 10 ff0000
69 47 10 ff0000
70 47 10 ff0000
71 47 10 ff0000
72 47 10 ff0000
73 47 10 ff0000
74 47 10 ff0000
75 47 10 ff0000
76 47 10 ff0000
77 47 10 ff0000
78 47 10 ff0000
79 47 10 ff0000
79 16 1 ff0000
79 17 1 ff0000
79 18 1 ff0000
79 19 1 ff0000
79 20 1 ff0000
79 21 1 ff0000
79 22 1 ff0000
79 23 1 ff0000
79 24 1 ff0000
79 25 1 ff0000
79 26 1 ff0000
79 27 1 ff0000
79 28 1 ff0000
79 29 1 ff0000
79 30 1 ff0000
79 31 1 ff0000
79 16 2 ff0000
79 17 2 ff0000
79 18 2 ff0000
79 19 2 ff0000
79 20 2 ff0000
79 21 2 ff0000
79 22 2 ff0000
79 23 2 ff0000
79 24 2 ff0000
79 25 2 ff0000
79 26 2 ff0000
79 27 2 ff0000
79 28 2 ff0000
79 29 2 ff0000
79 30 2 ff0000
79 31 2 ff0000
79 16 3 ff0000
79 17 3 ff0000
79 18 3 ff0000
79 19 3 ff0000
79 20 3 ff0000
79 21 3 ff0000
79 22 3 ff0000
79 23 3 ff0000
79 24 3 ff0000
79 25 3 ff0000
79 26 3 ff0000
79 27 3 ff0000
79 28 3 ff0000
79 29 3 ff0000
79 30 3 ff0000
79 31 3 ff0000
79 16 4 ff0000
79 17 4 ff0000
79 18 4 ff0000
79 19 4 ff0000
79 20 4 ff0000
79 21 4 ff0000
79 22 4 ff0000
79 23 4 ff0000
79 24 4 ff0000
79 25 4 ff0000
79 26 4 ff0000
79 27 4 ff0000
79 28 4 ff0000
79 29 4 ff0000
79 30 4 ff0000
79 31 4 ff0000
79 16 5 ff0000
79 17 5 ff0000
79 18 5 ff0000
79 19 5 ff0000
79 20 5 ff0000
79 21 5 ff0000
79 22 5 ff0000
79 23 5 ff0000
79 24 5 ff0000
79 25 5 ff0000
79 26 5 ff0000
79 27 5 ff0000
79 28 5 ff0000
79 29 5 ff0000
79 30 5 ff0000
79 31 5 ff0000
79 16 6 ff0000
79 17 6 ff0000
79 18 6 ff0000
79 19 6 ff0000
79 20 6 ff0000
79 21 6 ff0000
79 22 6 ff0000
79 23 6 ff0000
79 24 6 ff0000
79 25 6 ff0000
79 26 6 ff0000
79 27 6 ff0000
79 28 6 ff0000
79 29 6 ff0000
79 30 6 ff0000
79 31 6 ff0000
79 18 7 ff0000
79 19 7 ff0000
79 20 7 ff0000
79 21 7 ff0000
79 24 7 ff0000
79 25 7 ff0000
79 26 7 ff0000
79 27 7 ff0000
79 30 7 ff0000
79 31 7 ff0000
79 18 8 ff0000
79 19 8 ff0000
79 20 8 ff0000
79 21 8 ff0000
79 24 8 ff0000
79 25 8 ff0000
79 26 8 ff0000
79 27 8 ff0000
79 30 8 ff0000
79 31 8 ff0000
79 16 9 ff0000
79 17 9 ff0000
79 18 9 ff0000
79 19 9 ff0000
79 20 9 ff0000
79 21 9 ff0000
79 22 9 ff0000
79 23 9 ff0000
79 24 9 ff0000
79 25 9 ff0000
79 26 9 ff0000
79 27 9 ff0000
79 28 9 ff0000
79 29 9 ff0000
79 30 9 ff0000
79 31 9 ff0000
79 16 10 ff0000
79 17 10 ff0000
79 18 10 ff0000
79 19 10 ff0000
79 20 10 ff0000
79 21 10 ff0000
79 22 10 ff0000
79 23 10 ff0000
79 24 10 ff0000
79 25 10 ff0000
79 26 10 ff0000
79 27 10 ff0000
79 28 10 ff0000
79 29 10 ff0000
79 30 10 ff0000
79 31 10 ff0000
0 16 1 ff0000
0 17 1 ff0000
0 18 1 ff0000
0 19 1 ff0000
0 20 1 ff0000
0 21 1 ff0000
0 22 1 ff0000
0 23 1 ff0000
0 24 1 ff0000
0 25 1 ff0000
0 26 1 ff0000
0 27 1 ff0000
0 28 1 ff0000
0 29 1 ff0000
0 30 1 ff0000
0 31 1 ff0000
0 16 2 ff0000
0 17 2 ff0000
0 18 2 ff0000
0 19 2 ff0000
0 20 2 ff0000
0 21 2 ff0000
0 22 2 ff0000
0 23 2 ff0000
0 24 2 ff0000
0 25 2 ff0000
0 26 2 ff0000
0 27 2 ff0000
0 28 2 ff0000
0 29 2 ff0000
0 30 2 ff0000
0 31 2 ff0000
0 16 3 ff0000
0 17 3 ff0000
0 18 3 ff0000
0 19 3 ff0000
0 20 3 ff0000
0 21 3 ff0000
0 22 3 ff0000
0 23 3 ff0000
0 24 3 ff0000
0 25 3 ff0000
0 26 3 ff0000
0 27 3 ff0000
0 28 3 ff0000
0 29 3 ff0000
0 30 3 ff0000
0 31 3 ff0000
0 19 4 ff0000
0 20 4 ff0000
0 21 4 ff0000
0 22 4 ff0000
0 23 4 ff0000
0 24 4 ff0000
0 28 4 ff0000
0 29 4 ff0000
0 30 4 ff0000
0 31 4 ff0000
0 19 5 ff0000
0 20 5 ff0000
0 21 5 ff0000
0 22 5 ff0000
0 23 5 ff0000
0 24 5 ff0000
0 28 5 ff0000
0 29 5 ff0000
0 30 5 ff0000
0 31 5 ff0000
0 19 6 ff0000
0 20 6 ff0000
0 21 6 ff0000
0 22 6 ff0000
0 23 6 ff0000
0 24 6 ff0000
0 28 6 ff0000
0 29 6 ff0000
0 30 6 ff0000
0 31 6 ff0000
0 19 7 ff0000
0 20 7 ff0000
0 21 7 ff0000
0 22 7 ff0000
0 23 7 ff0000
0 24 7 ff0000
0 28 7 ff0000
0 29 7 ff0000
0 30 7 ff0000
0 31 7 ff0000
0 16 8 ff0000
0 17 8 ff0000
0 18 8 ff0000
0 19 8 ff0000
0 20 8 ff0000
0 21 8 ff0000
0 22 8 ff0000
0 23 8 ff0000
0 24 8 ff0000
0 25 8 ff0000
0 26 8 ff0000
0 27 8 ff0000
0 28 8 ff0000
0 29 8 ff0000
0 30 8 ff0000
0 31 8 ff0000
0 16 9 ff0000
0 17 9 ff0000
0 18 9 ff0000
0 19 9 ff0000
0 20 9 ff0000
0 21 9 ff0000
0 22 9 ff0000
0 23 9 ff0000
0 24 9 ff0000
0 25 9 ff0000
0 26 9 ff0000
0 27 9 ff0000
0 28 9 ff0000
0 29 9 ff0000
0 30 9 ff0000
0 31 9 ff0000
0 16 10 ff0000
0 17 10 ff0000
0 18 10 ff0000
0 19 10 ff0000
0 20 10 ff0000
0 21 10 ff0000
0 22 10 ff0000
0 23 10 ff0000
0 24 10 ff0000
0 25 10 ff0000
0 26 10 ff0000
0 27 10 ff0000
0 28 10 ff0000
0 29 10 ff0000
0 30 10 ff0000
0 31 10 ff0000
