# Goxel 0.15.1
# One line per voxel
# X Y Z RRGGBB
1 1 0 c0c0c0
1 1 1 c0c0c0
1 1 2 c0c0c0
1 2 0 c0c0c0
1 2 1 c0c0c0
1 2 2 c0c0c0
1 3 0 c0c0c0
1 3 1 c0c0c0
1 3 2 c0c0c0
1 4 0 c0c0c0
1 4 1 c0c0c0
1 4 2 c0c0c0
1 5 0 c0c0c0
1 5 1 c0c0c0
1 5 2 c0c0c0
1 6 0 c0c0c0
1 6 1 c0c0c0
1 6 2 c0c0c0
1 7 0 c0c0c0
1 7 1 c0c0c0
1 7 2 c0c0c0
1 8 0 c0c0c0
1 8 1 c0c0c0
1 8 2 c0c0c0
1 9 0 c0c0c0
1 9 1 c0c0c0
1 9 2 c0c0c0
1 10 0 c0c0c0
1 10 1 c0c0c0
1 10 2 c0c0c0
1 11 0 c0c0c0
1 11 1 c0c0c0
1 11 2 c0c0c0
1 12 0 c0c0c0
1 12 1 c0c0c0
1 12 2 c0c0c0
1 13 0 c0c0c0
1 13 1 c0c0c0
1 13 2 c0c0c0
1 14 0 c0c0c0
1 14 1 c0c0c0
1 14 2 c0c0c0
1 15 0 c0c0c0
1 15 1 c0c0c0
1 15 2 c0c0c0
2 1 0 c0c0c0
2 1 1 c0c0c0
2 1 2 c0c0c0
2 2 0 c0c0c0
2 2 1 c0c0c0
2 2 2 c0c0c0
2 3 0 c0c0c0
2 3 1 c0c0c0
2 3 2 c0c0c0
2 4 0 c0c0c0
2 4 1 c0c0c0
2 4 2 c0c0c0
2 5 0 c0c0c0
2 5 1 c0c0c0
2 5 2 c0c0c0
2 6 0 c0c0c0
2 6 1 c0c0c0
2 6 2 c0c0c0
2 7 0 c0c0c0
2 7 1 c0c0c0
2 7 2 c0c0c0
2 8 0 c0c0c0
2 8 1 c0c0c0
2 8 2 c0c0c0
2 9 0 c0c0c0
2 9 1 c0c0c0
2 9 2 c0c0c0
2 10 0 c0c0c0
2 10 1 c0c0c0
2 10 2 c0c0c0
2 11 0 c0c0c0
2 11 1 c0c0c0
2 11 2 c0c0c0
2 12 0 c0c0c0
2 12 1 c0c0c0
2 12 2 c0c0c0
2 13 0 c0c0c0
2 13 1 c0c0c0
2 13 2 c0c0c0
2 14 0 c0c0c0
2 14 1 c0c0c0
2 14 2 c0c0c0
2 15 0 c0c0c0
2 15 1 c0c0c0
2 15 2 c0c0c0
3 1 0 c0c0c0
3 1 1 c0c0c0
3 1 2 c0c0c0
3 2 0 c0c0c0
3 2 1 c0c0c0
3 2 2 c0c0c0
3 3 0 c0c0c0
3 3 1 c0c0c0
3 3 2 c0c0c0
3 4 0 c0c0c0
3 4 1 c0c0c0
3 4 2 c0c0c0
3 5 0 c0c0c0
3 5 1 c0c0c0
3 5 2 c0c0c0
3 6 0 c0c0c0
3 6 1 c0c0c0
3 6 2 c0c0c0
3 7 0 c0c0c0
3 7 1 c0c0c0
3 7 2 c0c0c0
3 8 0 c0c0c0
3 8 1 c0c0c0
3 8 2 c0c0c0
3 9 0 c0c0c0
3 9 1 c0c0c0
3 9 2 c0c0c0
3 10 0 c0c0c0
3 10 1 c0c0c0
3 10 2 c0c0c0
3 11 0 c0c0c0
3 11 1 c0c0c0
3 11 2 c0c0c0
3 12 0 c0c0c0
3 12 1 c0c0c0
3 12 2 c0c0c0
3 13 0 c0c0c0
3 13 1 c0c0c0
3 13 2 c0c0c0
3 14 0 c0c0c0
3 14 1 c0c0c0
3 14 2 c0c0c0
3 15 0 c0c0c0
3 15 1 c0c0c0
3 15 2 c0c0c0
4 1 0 c0c0c0
4 1 1 c0c0c0
4 1 2 c0c0c0
4 2 0 c0c0c0
4 2 1 c0c0c0
4 2 2 c0c0c0
4 3 0 c0c0c0
4 3 1 c0c0c0
4 3 2 c0c0c0
4 4 0 c0c0c0
4 4 1 c0c0c0
4 4 2 c0c0c0
4 5 0 c0c0c0
4 5 1 c0c0c0
4 5 2 c0c0c0
4 6 0 c0c0c0
4 6 1 c0c0c0
4 6 2 c0c0c0
4 7 0 c0c0c0
4 7 1 c0c0c0
4 7 2 c0c0c0
4 8 0 c0c0c0
4 8 1 c0c0c0
4 8 2 c0c0c0
4 9 0 c0c0c0
4 9 1 c0c0c0
4 9 2 c0c0c0
4 10 0 c0c0c0
4 10 1 c0c0c0
4 10 2 c0c0c0
4 11 0 c0c0c0
4 11 1 c0c0c0
4 11 2 c0c0c0
4 12 0 c0c0c0
4 12 1 c0c0c0
4 12 2 c0c0c0
4 13 0 c0c0c0
4 13 1 c0c0c0
4 13 2 c0c0c0
4 14 0 c0c0c0
4 14 1 c0c0c0
4 14 2 c0c0c0
4 15 0 c0c0c0
4 15 1 c0c0c0
4 15 2 c0c0c0
5 1 0 c0c0c0
5 1 1 c0c0c0
5 1 2 c0c0c0
5 2 0 c0c0c0
5 2 1 c0c0c0
5 2 2 c0c0c0
5 3 0 c0c0c0
5 3 1 c0c0c0
5 3 2 c0c0c0
5 4 0 c0c0c0
5 4 1 c0c0c0
5 4 2 c0c0c0
5 5 0 c0c0c0
5 5 1 c0c0c0
5 5 2 c0c0c0
5 6 0 c0c0c0
5 6 1 c0c0c0
5 6 2 c0c0c0
5 7 0 c0c0c0
5 7 1 c0c0c0
5 7 2 c0c0c0
5 8 0 c0c0c0
5 8 1 c0c0c0
5 8 2 c0c0c0
5 9 0 c0c0c0
5 9 1 c0c0c0
5 9 2 c0c0c0
5 10 0 c0c0c0
5 10 1 c0c0c0
5 10 2 c0c0c0
5 11 0 c0c0c0
5 11 1 c0c0c0
5 11 2 c0c0c0
5 12 0 c0c0c0
5 12 1 c0c0c0
5 12 2 c0c0c0
5 13 0 c0c0c0
5 13 1 c0c0c0
5 13 2 c0c0c0
5 14 0 c0c0c0
5 14 1 c0c0c0
5 14 2 c0c0c0
5 15 0 c0c0c0
5 15 1 c0c0c0
5 15 2 c0c0c0
6 1 0 c0c0c0
6 1 1 c0c0c0
6 1 2 c0c0c0
6 2 0 c0c0c0
6 2 1 c0c0c0
6 2 2 c0c0c0
6 3 0 c0c0c0
6 3 1 c0c0c0
6 3 2 c0c0c0
6 4 0 c0c0c0
6 4 1 c0c0c0
6 4 2 c0c0c0
6 5 0 c0c0c0
6 5 1 c0c0c0
6 5 2 c0c0c0
6 6 0 c0c0c0
6 6 1 c0c0c0
6 6 2 c0c0c0
6 7 0 c0c0c0
6 7 1 c0c0c0
6 7 2 c0c0c0
6 8 0 c0c0c0
6 8 1 c0c0c0
6 8 2 c0c0c0
6 9 0 c0c0c0
6 9 1 c0c0c0
6 9 2 c0c0c0
6 10 0 c0c0c0
6 10 1 c0c0c0
6 10 2 c0c0c0
6 11 0 c0c0c0
6 11 1 c0c0c0
6 11 2 c0c0c0
6 12 0 c0c0c0
6 12 1 c0c0c0
6 12 2 c0c0c0
6 13 0 c0c0c0
6 13 1 c0c0c0
6 13 2 c0c0c0
6 14 0 c0c0c0
6 14 1 c0c0c0
6 14 2 c0c0c0
6 15 0 c0c0c0
6 15 1 c0c0c0
6 15 2 c0c0c0
7 1 0 c0c0c0
7 1 1 c0c0c0
7 1 2 c0c0c0
7 2 0 c0c0c0
7 2 1 c0c0c0
7 2 2 c0c0c0
7 3 0 c0c0c0
7 3 1 c0c0c0
7 3 2 c0c0c0
7 4 0 c0c0c0
7 4 1 c0c0c0
7 4 2 c0c0c0
7 5 0 c0c0c0
7 5 1 c0c0c0
7 5 2 c0c0c0
7 6 0 c0c0c0
7 6 1 c0c0c0
7 6 2 c0c0c0
7 7 0 c0c0c0
7 7 1 c0c0c0
7 7 2 c0c0c0
7 8 0 c0c0c0
7 8 1 c0c0c0
7 8 2 c0c0c0
7 9 0 c0c0c0
7 9 1 c0c0c0
7 9 2 c0c0c0
7 10 0 c0c0c0
7 10 1 c0c0c0
7 10 2 c0c0c0
7 11 0 c0c0c0
7 11 1 c0c0c0
7 11 2 c0c0c0
7 12 0 c0c0c0
7 12 1 c0c0c0
7 12 2 c0c0c0
7 13 0 c0c0c0
7 13 1 c0c0c0
7 13 2 c0c0c0
7 14 0 c0c0c0
7 14 1 c0c0c0
7 14 2 c0c0c0
7 15 0 c0c0c0
7 15 1 c0c0c0
7 15 2 c0c0c0
8 1 0 c0c0c0
8 1 1 c0c0c0
8 1 2 c0c0c0
8 2 0 c0c0c0
8 2 1 c0c0c0
8 2 2 c0c0c0
8 3 0 c0c0c0
8 3 1 c0c0c0
8 3 2 c0c0c0
8 4 0 c0c0c0
8 4 1 c0c0c0
8 4 2 c0c0c0
8 5 0 c0c0c0
8 5 1 c0c0c0
8 5 2 c0c0c0
8 6 0 c0c0c0
8 6 1 c0c0c0
8 6 2 c0c0c0
8 7 0 c0c0c0
8 7 1 c0c0c0
8 7 2 c0c0c0
8 8 0 c0c0c0
8 8 1 c0c0c0
8 8 2 c0c0c0
8 9 0 c0c0c0
8 9 1 c0c0c0
8 9 2 c0c0c0
8 10 0 c0c0c0
8 10 1 c0c0c0
8 10 2 c0c0c0
8 11 0 c0c0c0
8 11 1 c0c0c0
8 11 2 c0c0c0
8 12 0 c0c0c0
8 12 1 c0c0c0
8 12 2 c0c0c0
8 13 0 c0c0c0
8 13 1 c0c0c0
8 13 2 c0c0c0
8 14 0 c0c0c0
8 14 1 c0c0c0
8 14 2 c0c0c0
8 15 0 c0c0c0
8 15 1 c0c0c0
8 15 2 c0c0c0
9 1 0 c0c0c0
9 1 1 c0c0c0
9 1 2 c0c0c0
9 2 0 c0c0c0
9 2 1 c0c0c0
9 2 2 c0c0c0
9 3 0 c0c0c0
9 3 1 c0c0c0
9 3 2 c0c0c0
9 4 0 c0c0c0
9 4 1 c0c0c0
9 4 2 c0c0c0
9 5 0 c0c0c0
9 5 1 c0c0c0
9 5 2 c0c0c0
9 6 0 c0c0c0
9 6 1 c0c0c0
9 6 2 c0c0c0
9 7 0 c0c0c0
9 7 1 c0c0c0
9 7 2 c0c0c0
9 8 0 c0c0c0
9 8 1 c0c0c0
9 8 2 c0c0c0
9 9 0 c0c0c0
9 9 1 c0c0c0
9 9 2 c0c0c0
9 10 0 c0c0c0
9 10 1 c0c0c0
9 10 2 c0c0c0
9 11 0 c0c0c0
9 11 1 c0c0c0
9 11 2 c0c0c0
9 12 0 c0c0c0
9 12 1 c0c0c0
9 12 2 c0c0c0
9 13 0 c0c0c0
9 13 1 c0c0c0
9 13 2 c0c0c0
9 14 0 c0c0c0
9 14 1 c0c0c0
9 14 2 c0c0c0
9 15 0 c0c0c0
9 15 1 c0c0c0
9 15 2 c0c0c0
10 1 0 c0c0c0
10 1 1 c0c0c0
10 1 2 c0c0c0
10 2 0 c0c0c0
10 2 1 c0c0c0
10 2 2 c0c0c0
10 3 0 c0c0c0
10 3 1 c0c0c0
10 3 2 c0c0c0
10 4 0 c0c0c0
10 4 1 c0c0c0
10 4 2 c0c0c0
10 5 0 c0c0c0
10 5 1 c0c0c0
10 5 2 c0c0c0
10 6 0 c0c0c0
10 6 1 c0c0c0
10 6 2 c0c0c0
10 7 0 c0c0c0
10 7 1 c0c0c0
10 7 2 c0c0c0
10 8 0 c0c0c0
10 8 1 c0c0c0
10 8 2 c0c0c0
10 9 0 c0c0c0
10 9 1 c0c0c0
10 9 2 c0c0c0
10 10 0 c0c0c0
10 10 1 c0c0c0
10 10 2 c0c0c0
10 11 0 c0c0c0
10 11 1 c0c0c0
10 11 2 c0c0c0
10 12 0 c0c0c0
10 12 1 c0c0c0
10 12 2 c0c0c0
10 13 0 c0c0c0
10 13 1 c0c0c0
10 13 2 c0c0c0
10 14 0 c0c0c0
10 14 1 c0c0c0
10 14 2 c0c0c0
10 15 0 c0c0c0
10 15 1 c0c0c0
10 15 2 c0c0c0
11 1 0 c0c0c0
11 1 1 c0c0c0
11 1 2 c0c0c0
11 2 0 c0c0c0
11 2 1 c0c0c0
11 2 2 c0c0c0
11 3 0 c0c0c0
11 3 1 c0c0c0
11 3 2 c0c0c0
11 4 0 c0c0c0
11 4 1 c0c0c0
11 4 2 c0c0c0
11 5 0 c0c0c0
11 5 1 c0c0c0
11 5 2 c0c0c0
11 6 0 c0c0c0
11 6 1 c0c0c0
11 6 2 c0c0c0
11 7 0 c0c0c0
11 7 1 c0c0c0
11 7 2 c0c0c0
11 8 0 c0c0c0
11 8 1 c0c0c0
11 8 2 c0c0c0
11 9 0 c0c0c0
11 9 1 c0c0c0
11 9 2 c0c0c0
11 10 0 c0c0c0
11 10 1 c0c0c0
11 10 2 c0c0c0
11 11 0 c0c0c0
11 11 1 c0c0c0
11 11 2 c0c0c0
11 12 0 c0c0c0
11 12 1 c0c0c0
11 12 2 c0c0c0
11 13 0 c0c0c0
11 13 1 c0c0c0
11 13 2 c0c0c0
11 14 0 c0c0c0
11 14 1 c0c0c0
11 14 2 c0c0c0
11 15 0 c0c0c0
11 15 1 c0c0c0
11 15 2 c0c0c0
12 1 0 c0c0c0
12 1 1 c0c0c0
12 1 2 c0c0c0
12 2 0 c0c0c0
12 2 1 c0c0c0
12 2 2 c0c0c0
12 3 0 c0c0c0
12 3 1 c0c0c0
12 3 2 c0c0c0
12 4 0 c0c0c0
12 4 1 c0c0c0
12 4 2 c0c0c0
12 5 0 c0c0c0
12 5 1 c0c0c0
12 5 2 c0c0c0
12 6 0 c0c0c0
12 6 1 c0c0c0
12 6 2 c0c0c0
12 7 0 c0c0c0
12 7 1 c0c0c0
12 7 2 c0c0c0
12 8 0 c0c0c0
12 8 1 c0c0c0
12 8 2 c0c0c0
12 9 0 c0c0c0
12 9 1 c0c0c0
12 9 2 c0c0c0
12 10 0 c0c0c0
12 10 1 c0c0c0
12 10 2 c0c0c0
12 11 0 c0c0c0
12 11 1 c0c0c0
12 11 2 c0c0c0
12 12 0 c0c0c0
12 12 1 c0c0c0
12 12 2 c0c0c0
12 13 0 c0c0c0
12 13 1 c0c0c0
12 13 2 c0c0c0
12 14 0 c0c0c0
12 14 1 c0c0c0
12 14 2 c0c0c0
12 15 0 c0c0c0
12 15 1 c0c0c0
12 15 2 c0c0c0
13 1 0 c0c0c0
13 1 1 c0c0c0
13 1 2 c0c0c0
13 2 0 c0c0c0
13 2 1 c0c0c0
13 2 2 c0c0c0
13 3 0 c0c0c0
13 3 1 c0c0c0
13 3 2 c0c0c0
13 4 0 c0c0c0
13 4 1 c0c0c0
13 4 2 c0c0c0
13 5 0 c0c0c0
13 5 1 c0c0c0
13 5 2 c0c0c0
13 6 0 c0c0c0
13 6 1 c0c0c0
13 6 2 c0c0c0
13 7 0 c0c0c0
13 7 1 c0c0c0
13 7 2 c0c0c0
13 8 0 c0c0c0
13 8 1 c0c0c0
13 8 2 c0c0c0
13 9 0 c0c0c0
13 9 1 c0c0c0
13 9 2 c0c0c0
13 10 0 c0c0c0
13 10 1 c0c0c0
13 10 2 c0c0c0
13 11 0 c0c0c0
13 11 1 c0c0c0
13 11 2 c0c0c0
13 12 0 c0c0c0
13 12 1 c0c0c0
13 12 2 c0c0c0
13 13 0 c0c0c0
13 13 1 c0c0c0
13 13 2 c0c0c0
13 14 0 c0c0c0
13 14 1 c0c0c0
13 14 2 c0c0c0
13 15 0 c0c0c0
13 15 1 c0c0c0
13 15 2 c0c0c0
14 1 0 c0c0c0
14 1 1 c0c0c0
14 1 2 c0c0c0
14 2 0 c0c0c0
14 2 1 c0c0c0
14 2 2 c0c0c0
14 3 0 c0c0c0
14 3 1 c0c0c0
14 3 2 c0c0c0
14 4 0 c0c0c0
14 4 1 c0c0c0
14 4 2 c0c0c0
14 5 0 c0c0c0
14 5 1 c0c0c0
14 5 2 c0c0c0
14 6 0 c0c0c0
14 6 1 c0c0c0
14 6 2 c0c0c0
14 7 0 c0c0c0
14 7 1 c0c0c0
14 7 2 c0c0c0
14 8 0 c0c0c0
14 8 1 c0c0c0
14 8 2 c0c0c0
14 9 0 c0c0c0
14 9 1 c0c0c0
14 9 2 c0c0c0
14 10 0 c0c0c0
14 10 1 c0c0c0
14 10 2 c0c0c0
14 11 0 c0c0c0
14 11 1 c0c0c0
14 11 2 c0c0c0
14 12 0 c0c0c0
14 12 1 c0c0c0
14 12 2 c0c0c0
14 13 0 c0c0c0
14 13 1 c0c0c0
14 13 2 c0c0c0
14 14 0 c0c0c0
14 14 1 c0c0c0
14 14 2 c0c0c0
14 15 0 c0c0c0
14 15 1 c0c0c0
14 15 2 c0c0c0
15 1 0 c0c0c0
15 1 1 c0c0c0
15 1 2 c0c0c0
15 2 0 c0c0c0
15 2 1 c0c0c0
15 2 2 c0c0c0
15 3 0 c0c0c0
15 3 1 c0c0c0
15 3 2 c0c0c0
15 4 0 c0c0c0
15 4 1 c0c0c0
15 4 2 c0c0c0
15 5 0 c0c0c0
15 5 1 c0c0c0
15 5 2 c0c0c0
15 6 0 c0c0c0
15 6 1 c0c0c0
15 6 2 c0c0c0
15 7 0 c0c0c0
15 7 1 c0c0c0
15 7 2 c0c0c0
15 8 0 c0c0c0
15 8 1 c0c0c0
15 8 2 c0c0c0
15 9 0 c0c0c0
15 9 1 c0c0c0
15 9 2 c0c0c0
15 10 0 c0c0c0
15 10 1 c0c0c0
15 10 2 c0c0c0
15 11 0 c0c0c0
15 11 1 c0c0c0
15 11 2 c0c0c0
15 12 0 c0c0c0
15 12 1 c0c0c0
15 12 2 c0c0c0
15 13 0 c0c0c0
15 13 1 c0c0c0
15 13 2 c0c0c0
15 14 0 c0c0c0
15 14 1 c0c0c0
15 14 2 c0c0c0
15 15 0 c0c0c0
15 15 1 c0c0c0
15 15 2 c0c0c0
1 1 3 c0c0c0
1 2 3 c0c0c0
1 3 3 c0c0c0
2 1 3 c0c0c0
2 2 3 c0c0c0
2 3 3 c0c0c0
3 1 3 c0c0c0
3 2 3 c0c0c0
3 3 3 c0c0c0
4 1 3 c0c0c0
4 2 3 c0c0c0
4 3 3 c0c0c0
5 1 3 c0c0c0
5 2 3 c0c0c0
5 3 3 c0c0c0
6 1 3 c0c0c0
6 2 3 c0c0c0
6 3 3 c0c0c0
7 1 3 c0c0c0
7 2 3 c0c0c0
7 3 3 c0c0c0
8 1 3 c0c0c0
8 2 3 c0c0c0
8 3 3 c0c0c0
9 1 3 c0c0c0
9 2 3 c0c0c0
9 3 3 c0c0c0
10 1 3 c0c0c0
10 2 3 c0c0c0
10 3 3 c0c0c0
11 1 3 c0c0c0
11 2 3 c0c0c0
11 3 3 c0c0c0
12 1 3 c0c0c0
12 2 3 c0c0c0
12 3 3 c0c0c0
13 1 3 c0c0c0
13 2 3 c0c0c0
13 3 3 c0c0c0
14 1 3 c0c0c0
14 2 3 c0c0c0
14 3 3 c0c0c0
15 1 3 c0c0c0
15 2 3 c0c0c0
15 3 3 c0c0c0
1 1 3 c0c0c0
1 2 3 c0c0c0
1 3 3 c0c0c0
1 4 3 c0c0c0
1 5 3 c0c0c0
1 6 3 c0c0c0
1 7 3 c0c0c0
1 8 3 c0c0c0
1 9 3 c0c0c0
1 10 3 c0c0c0
1 11 3 c0c0c0
1 12 3 c0c0c0
1 13 3 c0c0c0
1 14 3 c0c0c0
1 15 3 c0c0c0
2 1 3 c0c0c0
2 2 3 c0c0c0
2 3 3 c0c0c0
2 4 3 c0c0c0
2 5 3 c0c0c0
2 6 3 c0c0c0
2 7 3 c0c0c0
2 8 3 c0c0c0
2 9 3 c0c0c0
2 10 3 c0c0c0
2 11 3 c0c0c0
2 12 3 c0c0c0
2 13 3 c0c0c0
2 14 3 c0c0c0
2 15 3 c0c0c0
14 1 3 c0c0c0
14 2 3 c0c0c0
14 3 3 c0c0c0
14 4 3 c0c0c0
14 5 3 c0c0c0
14 6 3 c0c0c0
14 7 3 c0c0c0
14 8 3 c0c0c0
14 9 3 c0c0c0
14 10 3 c0c0c0
14 11 3 c0c0c0
14 12 3 c0c0c0
14 13 3 c0c0c0
14 14 3 c0c0c0
14 15 3 c0c0c0
15 1 3 c0c0c0
15 2 3 c0c0c0
15 3 3 c0c0c0
15 4 3 c0c0c0
15 5 3 c0c0c0
15 6 3 c0c0c0
15 7 3 c0c0c0
15 8 3 c0c0c0
15 9 3 c0c0c0
15 10 3 c0c0c0
15 11 3 c0c0c0
15 12 3 c0c0c0
15 13 3 c0c0c0
15 14 3 c0c0c0
15 15 3 c0c0c0
1 15 3 c0c0c0
2 15 3 c0c0c0
3 15 3 c0c0c0
4 15 3 c0c0c0
5 15 3 c0c0c0
6 15 3 c0c0c0
7 15 3 c0c0c0
8 15 3 c0c0c0
9 15 3 c0c0c0
10 15 3 c0c0c0
11 15 3 c0c0c0
12 15 3 c0c0c0
13 15 3 c0c0c0
14 15 3 c0c0c0
15 15 3 c0c0c0
3 13 3 606060
3 14 3 606060
4 13 3 606060
4 14 3 606060
5 13 3 606060
5 14 3 606060
6 13 3 606060
6 14 3 606060
7 13 3 606060
7 14 3 606060
8 13 3 606060
8 14 3 606060
9 13 3 606060
9 14 3 606060
10 13 3 606060
10 14 3 606060
11 13 3 606060
11 14 3 606060
12 13 3 606060
12 14 3 606060
13 13 3 606060
13 14 3 606060
3 11 3 606060
3 12 3 606060
4 11 3 606060
4 12 3 606060
12 11 3 606060
12 12 3 606060
13 11 3 606060
13 12 3 606060
3 7 3 606060
3 8 3 606060
3 9 3 606060
3 10 3 606060
4 7 3 606060
4 8 3 606060
4 9 3 606060
4 10 3 606060
5 7 3 606060
5 8 3 606060
5 9 3 606060
5 10 3 606060
6 7 3 606060
6 8 3 606060
6 9 3 606060
6 10 3 606060
7 7 3 606060
7 8 3 606060
7 9 3 606060
7 10 3 606060
8 7 3 606060
8 8 3 606060
8 9 3 606060
8 10 3 606060
9 7 3 606060
9 8 3 606060
9 9 3 606060
9 10 3 606060
10 7 3 606060
10 8 3 606060
10 9 3 606060
10 10 3 606060
11 7 3 606060
11 8 3 606060
11 9 3 606060
11 10 3 606060
12 7 3 606060
12 8 3 606060
12 9 3 606060
12 10 3 606060
13 7 3 606060
13 8 3 606060
13 9 3 606060
13 10 3 606060
3 5 3 606060
3 6 3 606060
6 5 3 606060
6 6 3 606060
10 5 3 606060
10 6 3 606060
13 5 3 606060
13 6 3 606060
3 4 3 606060
4 4 3 606060
5 4 3 606060
6 4 3 606060
7 4 3 606060
8 4 3 606060
9 4 3 606060
10 4 3 606060
11 4 3 606060
12 4 3 606060
13 4 3 606060
4 6 3 ff0000
4 6 4 ff0000
5 6 3 ff0000
5 6 4 ff0000
11 6 3 00bb00
11 6 4 00bb00
12 6 3 00bb00
12 6 4 00bb00
7 6 3 202020
7 5 3 202020
8 6 3 202020
8 5 3 202020
9 6 3 202020
9 5 3 202020
2 0 1 000000
3 0 1 000000
4 0 1 000000
