# Goxel 0.15.1
# One line per voxel
# X Y Z RRGGBB
16 32 0 0000ff
17 32 0 0000ff
18 32 0 0000ff
19 32 0 0000ff
20 32 0 0000ff
21 32 0 0000ff
22 32 0 0000ff
23 32 0 0000ff
24 32 0 0000ff
25 32 0 0000ff
26 32 0 0000ff
27 32 0 0000ff
28 32 0 0000ff
29 32 0 0000ff
30 32 0 0000ff
31 32 0 0000ff
16 33 0 0000ff
17 33 0 0000ff
18 33 0 0000ff
19 33 0 0000ff
20 33 0 0000ff
21 33 0 0000ff
22 33 0 0000ff
23 33 0 0000ff
24 33 0 0000ff
25 33 0 0000ff
26 33 0 0000ff
27 33 0 0000ff
28 33 0 0000ff
29 33 0 0000ff
30 33 0 0000ff
31 33 0 0000ff
16 34 0 0000ff
17 34 0 0000ff
18 34 0 0000ff
19 34 0 0000ff
20 34 0 0000ff
21 34 0 0000ff
22 34 0 0000ff
23 34 0 0000ff
24 34 0 0000ff
25 34 0 0000ff
26 34 0 0000ff
27 34 0 0000ff
28 34 0 0000ff
29 34 0 0000ff
30 34 0 0000ff
31 34 0 0000ff
16 35 0 0000ff
17 35 0 0000ff
18 35 0 0000ff
19 35 0 0000ff
20 35 0 0000ff
21 35 0 0000ff
22 35 0 0000ff
23 35 0 0000ff
24 35 0 0000ff
25 35 0 0000ff
26 35 0 0000ff
27 35 0 0000ff
28 35 0 0000ff
29 35 0 0000ff
30 35 0 0000ff
31 35 0 0000ff
16 36 0 0000ff
17 36 0 0000ff
18 36 0 0000ff
19 36 0 0000ff
20 36 0 0000ff
21 36 0 0000ff
22 36 0 0000ff
23 36 0 0000ff
24 36 0 0000ff
25 36 0 0000ff
26 36 0 0000ff
27 36 0 0000ff
28 36 0 0000ff
29 36 0 0000ff
30 36 0 0000ff
31 36 0 0000ff
16 37 0 0000ff
17 37 0 0000ff
18 37 0 0000ff
19 37 0 0000ff
20 37 0 0000ff
21 37 0 0000ff
22 37 0 0000ff
23 37 0 0000ff
24 37 0 0000ff
25 37 0 0000ff
26 37 0 0000ff
27 37 0 0000ff
28 37 0 0000ff
29 37 0 0000ff
30 37 0 0000ff
31 37 0 0000ff
16 38 0 0000ff
17 38 0 0000ff
18 38 0 0000ff
19 38 0 0000ff
20 38 0 0000ff
21 38 0 0000ff
22 38 0 0000ff
23 38 0 0000ff
24 38 0 0000ff
25 38 0 0000ff
26 38 0 0000ff
27 38 0 0000ff
28 38 0 0000ff
29 38 0 0000ff
30 38 0 0000ff
31 38 0 0000ff
16 39 0 0000ff
17 39 0 0000ff
18 39 0 0000ff
19 39 0 0000ff
20 39 0 0000ff
21 39 0 0000ff
22 39 0 0000ff
23 39 0 0000ff
24 39 0 0000ff
25 39 0 0000ff
26 39 0 0000ff
27 39 0 0000ff
28 39 0 0000ff
29 39 0 0000ff
30 39 0 0000ff
31 39 0 0000ff
16 40 0 0000ff
17 40 0 0000ff
18 40 0 0000ff
19 40 0 0000ff
20 40 0 0000ff
21 40 0 0000ff
22 40 0 0000ff
23 40 0 0000ff
24 40 0 0000ff
25 40 0 0000ff
26 40 0 0000ff
27 40 0 0000ff
28 40 0 0000ff
29 40 0 0000ff
30 40 0 0000ff
31 40 0 0000ff
16 41 0 0000ff
17 41 0 0000ff
18 41 0 0000ff
19 41 0 0000ff
20 41 0 0000ff
21 41 0 0000ff
22 41 0 0000ff
23 41 0 0000ff
24 41 0 0000ff
25 41 0 0000ff
26 41 0 0000ff
27 41 0 0000ff
28 41 0 0000ff
29 41 0 0000ff
30 41 0 0000ff
31 41 0 0000ff
16 42 0 0000ff
17 42 0 0000ff
18 42 0 0000ff
19 42 0 0000ff
20 42 0 0000ff
21 42 0 0000ff
22 42 0 0000ff
23 42 0 0000ff
24 42 0 0000ff
25 42 0 0000ff
26 42 0 0000ff
27 42 0 0000ff
28 42 0 0000ff
29 42 0 0000ff
30 42 0 0000ff
31 42 0 0000ff
16 43 0 0000ff
17 43 0 0000ff
18 43 0 0000ff
19 43 0 0000ff
20 43 0 0000ff
21 43 0 0000ff
22 43 0 0000ff
23 43 0 0000ff
24 43 0 0000ff
25 43 0 0000ff
26 43 0 0000ff
27 43 0 0000ff
28 43 0 0000ff
29 43 0 0000ff
30 43 0 0000ff
31 43 0 0000ff
16 44 0 0000ff
17 44 0 0000ff
18 44 0 0000ff
19 44 0 0000ff
20 44 0 0000ff
21 44 0 0000ff
22 44 0 0000ff
23 44 0 0000ff
24 44 0 0000ff
25 44 0 0000ff
26 44 0 0000ff
27 44 0 0000ff
28 44 0 0000ff
29 44 0 0000ff
30 44 0 0000ff
31 44 0 0000ff
16 45 0 0000ff
17 45 0 0000ff
18 45 0 0000ff
19 45 0 0000ff
20 45 0 0000ff
21 45 0 0000ff
22 45 0 0000ff
23 45 0 0000ff
24 45 0 0000ff
25 45 0 0000ff
26 45 0 0000ff
27 45 0 0000ff
28 45 0 0000ff
29 45 0 0000ff
30 45 0 0000ff
31 45 0 0000ff
16 46 0 0000ff
17 46 0 0000ff
18 46 0 0000ff
19 46 0 0000ff
20 46 0 0000ff
21 46 0 0000ff
22 46 0 0000ff
23 46 0 0000ff
24 46 0 0000ff
25 46 0 0000ff
26 46 0 0000ff
27 46 0 0000ff
28 46 0 0000ff
29 46 0 0000ff
30 46 0 0000ff
31 46 0 0000ff
16 47 0 0000ff
17 47 0 0000ff
18 47 0 0000ff
19 47 0 0000ff
20 47 0 0000ff
21 47 0 0000ff
22 47 0 0000ff
23 47 0 0000ff
24 47 0 0000ff
25 47 0 0000ff
26 47 0 0000ff
27 47 0 0000ff
28 47 0 0000ff
29 47 0 0000ff
30 47 0 0000ff
31 47 0 0000ff
16 32 1 ff0000
17 32 1 ff0000
21 32 1 ff0000
22 32 1 ff0000
23 32 1 ff0000
23 33 1 ff0000
23 34 1 ff0000
23 35 1 ff0000
23 36 1 ff0000
24 36 1 ff00aa
25 36 1 ff00aa
26 36 1 ff00aa
27 36 1 ff00aa
28 36 1 ff00aa
29 36 1 ff00aa
23 37 1 ff0000
23 38 1 ff0000
23 39 1 ff0000
23 40 1 ff0000
24 40 1 ff00aa
25 40 1 ff00aa
26 40 1 ff00aa
27 40 1 ff00aa
28 40 1 ff00aa
23 41 1 ff0000
28 41 1 ff00aa
23 42 1 ff0000
23 43 1 ff0000
23 44 1 ff0000
24 44 1 ff00aa
25 44 1 ff00aa
26 44 1 ff00aa
27 44 1 ff00aa
28 44 1 ff00aa
23 45 1 ff0000
23 46 1 ff0000
16 47 1 ff0000
17 47 1 ff0000
18 47 1 ff0000
19 47 1 ff0000
20 47 1 ff0000
21 47 1 ff0000
22 47 1 ff0000
23 47 1 ff0000
24 47 1 ff0000
25 47 1 ff0000
26 47 1 ff0000
27 47 1 ff0000
28 47 1 ff0000
29 47 1 ff0000
30 47 1 ff0000
31 47 1 ff0000
16 32 2 ff0000
17 32 2 ff0000
21 32 2 ff0000
22 32 2 ff0000
23 32 2 ff0000
23 33 2 ff0000
23 34 2 ff0000
23 35 2 ff0000
23 36 2 ff0000
24 36 2 ff00aa
25 36 2 ff00aa
26 36 2 ff00aa
27 36 2 ff00aa
28 36 2 ff00aa
29 36 2 ff00aa
23 37 2 ff0000
23 38 2 ff0000
23 39 2 ff0000
23 40 2 ff0000
24 40 2 ff00aa
25 40 2 ff00aa
26 40 2 ff00aa
27 40 2 ff00aa
28 40 2 ff00aa
23 41 2 ff0000
28 41 2 ff00aa
23 42 2 ff0000
23 43 2 ff0000
23 44 2 ff0000
24 44 2 ff00aa
25 44 2 ff00aa
26 44 2 ff00aa
27 44 2 ff00aa
28 44 2 ff00aa
23 45 2 ff0000
23 46 2 ff0000
16 47 2 ff0000
17 47 2 ff0000
18 47 2 ff0000
19 47 2 ff0000
20 47 2 ff0000
21 47 2 ff0000
22 47 2 ff0000
23 47 2 ff0000
24 47 2 ff0000
25 47 2 ff0000
26 47 2 ff0000
27 47 2 ff0000
28 47 2 ff0000
29 47 2 ff0000
30 47 2 ff0000
31 47 2 ff0000
16 32 3 ff0000
17 32 3 ff0000
21 32 3 ff0000
22 32 3 ff0000
23 32 3 ff0000
23 33 3 ff0000
23 34 3 ff0000
23 35 3 ff0000
23 36 3 ff0000
24 36 3 ff00aa
25 36 3 ff00aa
26 36 3 ff00aa
27 36 3 ff00aa
28 36 3 ff00aa
29 36 3 ff00aa
23 37 3 ff0000
23 38 3 ff0000
23 39 3 ff0000
23 40 3 ff0000
24 40 3 ff00aa
25 40 3 ff00aa
26 40 3 ff00aa
27 40 3 ff00aa
28 40 3 ff00aa
23 41 3 ff0000
28 41 3 ff00aa
23 42 3 ff0000
23 43 3 ff0000
23 44 3 ff0000
24 44 3 ff00aa
25 44 3 ff00aa
26 44 3 ff00aa
27 44 3 ff00aa
28 44 3 ff00aa
23 45 3 ff0000
23 46 3 ff0000
16 47 3 ff0000
17 47 3 ff0000
18 47 3 ff0000
19 47 3 ff0000
20 47 3 ff0000
21 47 3 ff0000
22 47 3 ff0000
23 47 3 ff0000
24 47 3 ff0000
25 47 3 ff0000
26 47 3 ff0000
27 47 3 ff0000
28 47 3 ff0000
29 47 3 ff0000
30 47 3 ff0000
31 47 3 ff0000
16 32 4 ff0000
17 32 4 ff0000
21 32 4 ff0000
22 32 4 ff0000
23 32 4 ff0000
23 33 4 ff0000
23 34 4 ff0000
23 35 4 ff0000
23 36 4 ff0000
24 36 4 ff00aa
25 36 4 ff00aa
26 36 4 ff00aa
27 36 4 ff00aa
28 36 4 ff00aa
29 36 4 ff00aa
23 37 4 ff0000
23 38 4 ff0000
23 39 4 ff0000
23 40 4 ff0000
24 40 4 ff00aa
25 40 4 ff00aa
26 40 4 ff00aa
27 40 4 ff00aa
28 40 4 ff00aa
23 41 4 ff0000
28 41 4 ff00aa
23 42 4 ff0000
23 43 4 ff0000
23 44 4 ff0000
24 44 4 ff00aa
25 44 4 ff00aa
26 44 4 ff00aa
27 44 4 ff00aa
28 44 4 ff00aa
23 45 4 ff0000
23 46 4 ff0000
16 47 4 ff0000
17 47 4 ff0000
18 47 4 ff0000
19 47 4 ff0000
20 47 4 ff0000
21 47 4 ff0000
22 47 4 ff0000
23 47 4 ff0000
24 47 4 ff0000
25 47 4 ff0000
26 47 4 ff0000
27 47 4 ff0000
28 47 4 ff0000
29 47 4 ff0000
30 47 4 ff0000
16 32 5 ff0000
17 32 5 ff0000
21 32 5 ff0000
22 32 5 ff0000
23 32 5 ff0000
23 33 5 ff0000
23 34 5 ff0000
23 35 5 ff0000
23 36 5 ff0000
24 36 5 ff00aa
25 36 5 ff00aa
26 36 5 ff00aa
27 36 5 ff00aa
28 36 5 ff00aa
29 36 5 ff00aa
23 37 5 ff0000
23 38 5 ff0000
23 39 5 ff0000
23 40 5 ff0000
24 40 5 ff00aa
25 40 5 ff00aa
26 40 5 ff00aa
27 40 5 ff00aa
28 40 5 ff00aa
23 41 5 ff0000
28 41 5 ff00aa
23 42 5 ff0000
23 43 5 ff0000
23 44 5 ff0000
24 44 5 ff00aa
25 44 5 ff00aa
26 44 5 ff00aa
27 44 5 ff00aa
28 44 5 ff00aa
23 45 5 ff0000
23 46 5 ff0000
16 47 5 ff0000
17 47 5 ff0000
18 47 5 ff0000
19 47 5 ff0000
20 47 5 ff0000
21 47 5 ff0000
22 47 5 ff0000
23 47 5 ff0000
24 47 5 ff0000
25 47 5 ff0000
26 47 5 ff0000
27 47 5 ff0000
28 47 5 ff0000
29 47 5 ff0000
30 47 5 ff0000
16 32 6 ff0000
17 32 6 ff0000
18 32 6 ff0000
19 32 6 ff0000
20 32 6 ff0000
21 32 6 ff0000
22 32 6 ff0000
23 32 6 ff0000
23 33 6 ff0000
23 34 6 ff0000
23 35 6 ff0000
23 36 6 ff0000
24 36 6 ff00aa
25 36 6 ff00aa
26 36 6 ff00aa
27 36 6 ff00aa
28 36 6 ff00aa
29 36 6 ff00aa
23 37 6 ff0000
23 38 6 ff0000
23 39 6 ff0000
23 40 6 ff0000
24 40 6 ff00aa
25 40 6 ff00aa
26 40 6 ff00aa
27 40 6 ff00aa
28 40 6 ff00aa
23 41 6 ff0000
28 41 6 ff00aa
23 42 6 ff0000
23 43 6 ff0000
23 44 6 ff0000
24 44 6 ff00aa
25 44 6 ff00aa
26 44 6 ff00aa
27 44 6 ff00aa
28 44 6 ff00aa
23 45 6 ff0000
23 46 6 ff0000
16 47 6 ff0000
17 47 6 ff0000
18 47 6 ff0000
19 47 6 ff0000
20 47 6 ff0000
21 47 6 ff0000
22 47 6 ff0000
23 47 6 ff0000
24 47 6 ff0000
25 47 6 ff0000
26 47 6 ff0000
27 47 6 ff0000
28 47 6 ff0000
29 47 6 ff0000
30 47 6 ff0000
16 32 7 ff0000
17 32 7 ff0000
18 32 7 ff0000
19 32 7 ff0000
20 32 7 ff0000
21 32 7 ff0000
22 32 7 ff0000
23 32 7 ff0000
23 33 7 ff0000
23 34 7 ff0000
23 35 7 ff0000
23 36 7 ff0000
24 36 7 ff00aa
25 36 7 ff00aa
26 36 7 ff00aa
27 36 7 ff00aa
28 36 7 ff00aa
29 36 7 ff00aa
30 36 7 ff00aa
31 36 7 ff00aa
23 37 7 ff0000
23 38 7 ff0000
23 39 7 ff0000
23 40 7 ff0000
24 40 7 ff00aa
25 40 7 ff00aa
26 40 7 ff00aa
27 40 7 ff00aa
28 40 7 ff00aa
23 41 7 ff0000
28 41 7 ff00aa
23 42 7 ff0000
23 43 7 ff0000
23 44 7 ff0000
24 44 7 ff00aa
25 44 7 ff00aa
26 44 7 ff00aa
27 44 7 ff00aa
28 44 7 ff00aa
23 45 7 ff0000
23 46 7 ff0000
16 47 7 ff0000
17 47 7 ff0000
18 47 7 ff0000
19 47 7 ff0000
20 47 7 ff0000
21 47 7 ff0000
22 47 7 ff0000
23 47 7 ff0000
24 47 7 ff0000
25 47 7 ff0000
26 47 7 ff0000
27 47 7 ff0000
28 47 7 ff0000
29 47 7 ff0000
30 47 7 ff0000
31 47 7 ff0000
16 32 8 ff0000
17 32 8 ff0000
18 32 8 ff0000
19 32 8 ff0000
20 32 8 ff0000
21 32 8 ff0000
22 32 8 ff0000
23 32 8 ff0000
23 33 8 ff0000
23 34 8 ff0000
23 35 8 ff0000
23 36 8 ff0000
24 36 8 ff00aa
25 36 8 ff00aa
26 36 8 ff00aa
27 36 8 ff00aa
28 36 8 ff00aa
29 36 8 ff00aa
30 36 8 ff00aa
31 36 8 ff00aa
23 37 8 ff0000
23 38 8 ff0000
23 39 8 ff0000
23 40 8 ff0000
24 40 8 ff00aa
25 40 8 ff00aa
26 40 8 ff00aa
27 40 8 ff00aa
28 40 8 ff00aa
23 41 8 ff0000
28 41 8 ff00aa
23 42 8 ff0000
23 43 8 ff0000
23 44 8 ff0000
24 44 8 ff00aa
25 44 8 ff00aa
26 44 8 ff00aa
27 44 8 ff00aa
28 44 8 ff00aa
23 45 8 ff0000
23 46 8 ff0000
16 47 8 ff0000
17 47 8 ff0000
18 47 8 ff0000
19 47 8 ff0000
20 47 8 ff0000
21 47 8 ff0000
22 47 8 ff0000
23 47 8 ff0000
24 47 8 ff0000
25 47 8 ff0000
26 47 8 ff0000
27 47 8 ff0000
28 47 8 ff0000
29 47 8 ff0000
30 47 8 ff0000
31 47 8 ff0000
16 32 9 ff0000
17 32 9 ff0000
18 32 9 ff0000
19 32 9 ff0000
20 32 9 ff0000
21 32 9 ff0000
22 32 9 ff0000
23 32 9 ff0000
23 33 9 ff0000
23 34 9 ff0000
23 35 9 ff0000
23 36 9 ff0000
24 36 9 ff00aa
25 36 9 ff00aa
26 36 9 ff00aa
27 36 9 ff00aa
28 36 9 ff00aa
29 36 9 ff00aa
30 36 9 ff00aa
31 36 9 ff00aa
23 37 9 ff0000
23 38 9 ff0000
23 39 9 ff0000
23 40 9 ff0000
24 40 9 ff00aa
25 40 9 ff00aa
26 40 9 ff00aa
27 40 9 ff00aa
28 40 9 ff00aa
23 41 9 ff0000
28 41 9 ff00aa
23 42 9 ff0000
23 43 9 ff0000
23 44 9 ff0000
24 44 9 ff00aa
25 44 9 ff00aa
26 44 9 ff00aa
27 44 9 ff00aa
28 44 9 ff00aa
23 45 9 ff0000
23 46 9 ff0000
16 47 9 ff0000
17 47 9 ff0000
18 47 9 ff0000
19 47 9 ff0000
20 47 9 ff0000
21 47 9 ff0000
22 47 9 ff0000
23 47 9 ff0000
24 47 9 ff0000
25 47 9 ff0000
26 47 9 ff0000
27 47 9 ff0000
28 47 9 ff0000
29 47 9 ff0000
30 47 9 ff0000
31 47 9 ff0000
16 32 10 ff0000
17 32 10 ff0000
18 32 10 ff0000
19 32 10 ff0000
20 32 10 ff0000
21 32 10 ff0000
22 32 10 ff0000
23 32 10 ff0000
23 33 10 ff0000
23 34 10 ff0000
23 35 10 ff0000
23 36 10 ff0000
24 36 10 ff00aa
25 36 10 ff00aa
26 36 10 ff00aa
27 36 10 ff00aa
28 36 10 ff00aa
29 36 10 ff00aa
30 36 10 ff00aa
31 36 10 ff00aa
23 37 10 ff0000
23 38 10 ff0000
23 39 10 ff0000
23 40 10 ff0000
24 40 10 ff00aa
25 40 10 ff00aa
26 40 10 ff00aa
27 40 10 ff00aa
28 40 10 ff00aa
23 41 10 ff0000
28 41 10 ff00aa
23 42 10 ff0000
23 43 10 ff0000
23 44 10 ff0000
24 44 10 ff00aa
25 44 10 ff00aa
26 44 10 ff00aa
27 44 10 ff00aa
28 44 10 ff00aa
23 45 10 ff0000
23 46 10 ff0000
16 47 10 ff0000
17 47 10 ff0000
18 47 10 ff0000
19 47 10 ff0000
20 47 10 ff0000
21 47 10 ff0000
22 47 10 ff0000
23 47 10 ff0000
24 47 10 ff0000
25 47 10 ff0000
26 47 10 ff0000
27 47 10 ff0000
28 47 10 ff0000
29 47 10 ff0000
30 47 10 ff0000
31 47 10 ff0000
32 32 0 0000ff
33 32 0 0000ff
34 32 0 0000ff
35 32 0 0000ff
36 32 0 0000ff
37 32 0 0000ff
38 32 0 0000ff
39 32 0 0000ff
40 32 0 0000ff
41 32 0 0000ff
42 32 0 0000ff
43 32 0 0000ff
44 32 0 0000ff
45 32 0 0000ff
46 32 0 0000ff
47 32 0 0000ff
32 33 0 0000ff
33 33 0 0000ff
34 33 0 0000ff
35 33 0 0000ff
36 33 0 0000ff
37 33 0 0000ff
38 33 0 0000ff
39 33 0 0000ff
40 33 0 0000ff
41 33 0 0000ff
42 33 0 0000ff
43 33 0 0000ff
44 33 0 0000ff
45 33 0 0000ff
46 33 0 0000ff
47 33 0 0000ff
32 34 0 0000ff
33 34 0 0000ff
34 34 0 0000ff
35 34 0 0000ff
36 34 0 0000ff
37 34 0 0000ff
38 34 0 0000ff
39 34 0 0000ff
40 34 0 0000ff
41 34 0 0000ff
42 34 0 0000ff
43 34 0 0000ff
44 34 0 0000ff
45 34 0 0000ff
46 34 0 0000ff
47 34 0 0000ff
32 35 0 0000ff
33 35 0 0000ff
34 35 0 0000ff
35 35 0 0000ff
36 35 0 0000ff
37 35 0 0000ff
38 35 0 0000ff
39 35 0 0000ff
40 35 0 0000ff
41 35 0 0000ff
42 35 0 0000ff
43 35 0 0000ff
44 35 0 0000ff
45 35 0 0000ff
46 35 0 0000ff
47 35 0 0000ff
32 36 0 0000ff
33 36 0 0000ff
34 36 0 0000ff
35 36 0 0000ff
36 36 0 0000ff
37 36 0 0000ff
38 36 0 0000ff
39 36 0 0000ff
40 36 0 0000ff
41 36 0 0000ff
42 36 0 0000ff
43 36 0 0000ff
44 36 0 0000ff
45 36 0 0000ff
46 36 0 0000ff
47 36 0 0000ff
32 37 0 0000ff
33 37 0 0000ff
34 37 0 0000ff
35 37 0 0000ff
36 37 0 0000ff
37 37 0 0000ff
38 37 0 0000ff
39 37 0 0000ff
40 37 0 0000ff
41 37 0 0000ff
42 37 0 0000ff
43 37 0 0000ff
44 37 0 0000ff
45 37 0 0000ff
46 37 0 0000ff
47 37 0 0000ff
32 38 0 0000ff
33 38 0 0000ff
34 38 0 0000ff
35 38 0 0000ff
36 38 0 0000ff
37 38 0 0000ff
38 38 0 0000ff
39 38 0 0000ff
40 38 0 0000ff
41 38 0 0000ff
42 38 0 0000ff
43 38 0 0000ff
44 38 0 0000ff
45 38 0 0000ff
46 38 0 0000ff
47 38 0 0000ff
32 39 0 0000ff
33 39 0 0000ff
34 39 0 0000ff
35 39 0 0000ff
36 39 0 0000ff
37 39 0 0000ff
38 39 0 0000ff
39 39 0 0000ff
40 39 0 0000ff
41 39 0 0000ff
42 39 0 0000ff
43 39 0 0000ff
44 39 0 0000ff
45 39 0 0000ff
46 39 0 0000ff
47 39 0 0000ff
32 40 0 0000ff
33 40 0 0000ff
34 40 0 0000ff
35 40 0 0000ff
36 40 0 0000ff
37 40 0 0000ff
38 40 0 0000ff
39 40 0 0000ff
40 40 0 0000ff
41 40 0 0000ff
42 40 0 0000ff
43 40 0 0000ff
44 40 0 0000ff
45 40 0 0000ff
46 40 0 0000ff
47 40 0 0000ff
32 41 0 0000ff
33 41 0 0000ff
34 41 0 0000ff
35 41 0 0000ff
36 41 0 0000ff
37 41 0 0000ff
38 41 0 0000ff
39 41 0 0000ff
40 41 0 0000ff
41 41 0 0000ff
42 41 0 0000ff
43 41 0 0000ff
44 41 0 0000ff
45 41 0 0000ff
46 41 0 0000ff
47 41 0 0000ff
32 42 0 0000ff
33 42 0 0000ff
34 42 0 0000ff
35 42 0 0000ff
36 42 0 0000ff
37 42 0 0000ff
38 42 0 0000ff
39 42 0 0000ff
40 42 0 0000ff
41 42 0 0000ff
42 42 0 0000ff
43 42 0 0000ff
44 42 0 0000ff
45 42 0 0000ff
46 42 0 0000ff
47 42 0 0000ff
32 43 0 0000ff
33 43 0 0000ff
34 43 0 0000ff
35 43 0 0000ff
36 43 0 0000ff
37 43 0 0000ff
38 43 0 0000ff
39 43 0 0000ff
40 43 0 0000ff
41 43 0 0000ff
42 43 0 0000ff
43 43 0 0000ff
44 43 0 0000ff
45 43 0 0000ff
46 43 0 0000ff
47 43 0 0000ff
32 44 0 0000ff
33 44 0 0000ff
34 44 0 0000ff
35 44 0 0000ff
36 44 0 0000ff
37 44 0 0000ff
38 44 0 0000ff
39 44 0 0000ff
40 44 0 0000ff
41 44 0 0000ff
42 44 0 0000ff
43 44 0 0000ff
44 44 0 0000ff
45 44 0 0000ff
46 44 0 0000ff
47 44 0 0000ff
32 45 0 0000ff
33 45 0 0000ff
34 45 0 0000ff
35 45 0 0000ff
36 45 0 0000ff
37 45 0 0000ff
38 45 0 0000ff
39 45 0 0000ff
40 45 0 0000ff
41 45 0 0000ff
42 45 0 0000ff
43 45 0 0000ff
44 45 0 0000ff
45 45 0 0000ff
46 45 0 0000ff
47 45 0 0000ff
32 46 0 0000ff
33 46 0 0000ff
34 46 0 0000ff
35 46 0 0000ff
36 46 0 0000ff
37 46 0 0000ff
38 46 0 0000ff
39 46 0 0000ff
40 46 0 0000ff
41 46 0 0000ff
42 46 0 0000ff
43 46 0 0000ff
44 46 0 0000ff
45 46 0 0000ff
46 46 0 0000ff
47 46 0 0000ff
32 47 0 0000ff
33 47 0 0000ff
34 47 0 0000ff
35 47 0 0000ff
36 47 0 0000ff
37 47 0 0000ff
38 47 0 0000ff
39 47 0 0000ff
40 47 0 0000ff
41 47 0 0000ff
42 47 0 0000ff
43 47 0 0000ff
44 47 0 0000ff
45 47 0 0000ff
46 47 0 0000ff
47 47 0 0000ff
32 36 1 ff00aa
33 36 1 ff00aa
46 36 1 ff00aa
47 36 1 ff00aa
33 37 1 ff00aa
46 37 1 ff00aa
33 38 1 ff00aa
46 38 1 ff00aa
33 39 1 ff00aa
46 39 1 ff00aa
33 40 1 ff00aa
46 40 1 ff00aa
33 41 1 ff00aa
46 41 1 ff00aa
33 42 1 ff00aa
46 42 1 ff00aa
33 43 1 ff00aa
46 43 1 ff00aa
33 44 1 ff00aa
46 44 1 ff00aa
33 45 1 ff00aa
46 45 1 ff00aa
33 46 1 ff00aa
46 46 1 ff00aa
32 47 1 ff0000
33 47 1 ff0000
34 47 1 ff0000
35 47 1 ff0000
36 47 1 ff0000
37 47 1 ff0000
38 47 1 ff0000
39 47 1 ff0000
40 47 1 ff0000
41 47 1 ff0000
42 47 1 ff0000
43 47 1 ff0000
44 47 1 ff0000
45 47 1 ff0000
46 47 1 ff0000
47 47 1 ff0000
32 36 2 ff00aa
33 36 2 ff00aa
46 36 2 ff00aa
47 36 2 ff00aa
33 37 2 ff00aa
46 37 2 ff00aa
33 38 2 ff00aa
46 38 2 ff00aa
33 39 2 ff00aa
46 39 2 ff00aa
33 40 2 ff00aa
46 40 2 ff00aa
33 41 2 ff00aa
46 41 2 ff00aa
33 42 2 ff00aa
46 42 2 ff00aa
33 43 2 ff00aa
46 43 2 ff00aa
33 44 2 ff00aa
46 44 2 ff00aa
33 45 2 ff00aa
46 45 2 ff00aa
33 46 2 ff00aa
46 46 2 ff00aa
32 47 2 ff0000
33 47 2 ff0000
34 47 2 ff0000
35 47 2 ff0000
36 47 2 ff0000
37 47 2 ff0000
38 47 2 ff0000
39 47 2 ff0000
40 47 2 ff0000
41 47 2 ff0000
42 47 2 ff0000
43 47 2 ff0000
44 47 2 ff0000
45 47 2 ff0000
46 47 2 ff0000
47 47 2 ff0000
32 36 3 ff00aa
33 36 3 ff00aa
46 36 3 ff00aa
47 36 3 ff00aa
33 37 3 ff00aa
46 37 3 ff00aa
33 38 3 ff00aa
46 38 3 ff00aa
33 39 3 ff00aa
46 39 3 ff00aa
33 40 3 ff00aa
46 40 3 ff00aa
33 41 3 ff00aa
46 41 3 ff00aa
33 42 3 ff00aa
46 42 3 ff00aa
33 43 3 ff00aa
46 43 3 ff00aa
33 44 3 ff00aa
46 44 3 ff00aa
33 45 3 ff00aa
46 45 3 ff00aa
33 46 3 ff00aa
46 46 3 ff00aa
32 47 3 ff0000
33 47 3 ff0000
34 47 3 ff0000
35 47 3 ff0000
36 47 3 ff0000
37 47 3 ff0000
38 47 3 ff0000
39 47 3 ff0000
40 47 3 ff0000
41 47 3 ff0000
42 47 3 ff0000
43 47 3 ff0000
44 47 3 ff0000
45 47 3 ff0000
46 47 3 ff0000
47 47 3 ff0000
32 36 4 ff00aa
33 36 4 ff00aa
46 36 4 ff00aa
47 36 4 ff00aa
33 37 4 ff00aa
46 37 4 ff00aa
33 38 4 ff00aa
46 38 4 ff00aa
33 39 4 ff00aa
46 39 4 ff00aa
33 40 4 ff00aa
46 40 4 ff00aa
33 41 4 ff00aa
46 41 4 ff00aa
33 42 4 ff00aa
46 42 4 ff00aa
33 43 4 ff00aa
46 43 4 ff00aa
33 44 4 ff00aa
46 44 4 ff00aa
33 45 4 ff00aa
46 45 4 ff00aa
33 46 4 ff00aa
46 46 4 ff00aa
32 47 4 ff0000
33 47 4 ff0000
34 47 4 ff0000
35 47 4 ff0000
36 47 4 ff0000
37 47 4 ff0000
38 47 4 ff0000
39 47 4 ff0000
40 47 4 ff0000
41 47 4 ff0000
42 47 4 ff0000
43 47 4 ff0000
44 47 4 ff0000
45 47 4 ff0000
46 47 4 ff0000
47 47 4 ff0000
32 36 5 ff00aa
33 36 5 ff00aa
46 36 5 ff00aa
47 36 5 ff00aa
33 37 5 ff00aa
46 37 5 ff00aa
33 38 5 ff00aa
46 38 5 ff00aa
33 39 5 ff00aa
46 39 5 ff00aa
33 40 5 ff00aa
46 40 5 ff00aa
33 41 5 ff00aa
46 41 5 ff00aa
33 42 5 ff00aa
46 42 5 ff00aa
33 43 5 ff00aa
46 43 5 ff00aa
33 44 5 ff00aa
46 44 5 ff00aa
33 45 5 ff00aa
46 45 5 ff00aa
33 46 5 ff00aa
46 46 5 ff00aa
32 47 5 ff0000
33 47 5 ff0000
34 47 5 ff0000
35 47 5 ff0000
36 47 5 ff0000
37 47 5 ff0000
38 47 5 ff0000
39 47 5 ff0000
40 47 5 ff0000
41 47 5 ff0000
42 47 5 ff0000
43 47 5 ff0000
44 47 5 ff0000
45 47 5 ff0000
46 47 5 ff0000
47 47 5 ff0000
32 36 6 ff00aa
33 36 6 ff00aa
46 36 6 ff00aa
47 36 6 ff00aa
33 37 6 ff00aa
46 37 6 ff00aa
33 38 6 ff00aa
46 38 6 ff00aa
33 39 6 ff00aa
46 39 6 ff00aa
33 40 6 ff00aa
46 40 6 ff00aa
33 41 6 ff00aa
46 41 6 ff00aa
33 42 6 ff00aa
46 42 6 ff00aa
33 43 6 ff00aa
46 43 6 ff00aa
33 44 6 ff00aa
46 44 6 ff00aa
33 45 6 ff00aa
46 45 6 ff00aa
33 46 6 ff00aa
46 46 6 ff00aa
32 47 6 ff0000
33 47 6 ff0000
34 47 6 ff0000
35 47 6 ff0000
36 47 6 ff0000
37 47 6 ff0000
38 47 6 ff0000
39 47 6 ff0000
40 47 6 ff0000
41 47 6 ff0000
42 47 6 ff0000
43 47 6 ff0000
44 47 6 ff0000
45 47 6 ff0000
46 47 6 ff0000
47 47 6 ff0000
32 36 7 ff00aa
33 36 7 ff00aa
46 36 7 ff00aa
47 36 7 ff00aa
33 37 7 ff00aa
46 37 7 ff00aa
33 38 7 ff00aa
46 38 7 ff00aa
33 39 7 ff00aa
46 39 7 ff00aa
33 40 7 ff00aa
46 40 7 ff00aa
33 41 7 ff00aa
46 41 7 ff00aa
33 42 7 ff00aa
46 42 7 ff00aa
33 43 7 ff00aa
46 43 7 ff00aa
33 44 7 ff00aa
46 44 7 ff00aa
33 45 7 ff00aa
46 45 7 ff00aa
33 46 7 ff00aa
46 46 7 ff00aa
32 47 7 ff0000
33 47 7 ff0000
34 47 7 ff0000
35 47 7 ff0000
36 47 7 ff0000
37 47 7 ff0000
38 47 7 ff0000
39 47 7 ff0000
40 47 7 ff0000
41 47 7 ff0000
42 47 7 ff0000
43 47 7 ff0000
44 47 7 ff0000
45 47 7 ff0000
46 47 7 ff0000
47 47 7 ff0000
32 36 8 ff00aa
33 36 8 ff00aa
46 36 8 ff00aa
47 36 8 ff00aa
33 37 8 ff00aa
46 37 8 ff00aa
33 38 8 ff00aa
46 38 8 ff00aa
33 39 8 ff00aa
46 39 8 ff00aa
33 40 8 ff00aa
46 40 8 ff00aa
33 41 8 ff00aa
46 41 8 ff00aa
33 42 8 ff00aa
46 42 8 ff00aa
33 43 8 ff00aa
46 43 8 ff00aa
33 44 8 ff00aa
46 44 8 ff00aa
33 45 8 ff00aa
46 45 8 ff00aa
33 46 8 ff00aa
46 46 8 ff00aa
32 47 8 ff0000
33 47 8 ff0000
34 47 8 ff0000
35 47 8 ff0000
36 47 8 ff0000
37 47 8 ff0000
38 47 8 ff0000
39 47 8 ff0000
40 47 8 ff0000
41 47 8 ff0000
42 47 8 ff0000
43 47 8 ff0000
44 47 8 ff0000
45 47 8 ff0000
46 47 8 ff0000
47 47 8 ff0000
32 36 9 ff00aa
33 36 9 ff00aa
46 36 9 ff00aa
47 36 9 ff00aa
33 37 9 ff00aa
46 37 9 ff00aa
33 38 9 ff00aa
46 38 9 ff00aa
33 39 9 ff00aa
46 39 9 ff00aa
33 40 9 ff00aa
46 40 9 ff00aa
33 41 9 ff00aa
46 41 9 ff00aa
33 42 9 ff00aa
46 42 9 ff00aa
33 43 9 ff00aa
46 43 9 ff00aa
33 44 9 ff00aa
46 44 9 ff00aa
33 45 9 ff00aa
46 45 9 ff00aa
33 46 9 ff00aa
46 46 9 ff00aa
32 47 9 ff0000
33 47 9 ff0000
34 47 9 ff0000
35 47 9 ff0000
36 47 9 ff0000
37 47 9 ff0000
38 47 9 ff0000
39 47 9 ff0000
40 47 9 ff0000
41 47 9 ff0000
42 47 9 ff0000
43 47 9 ff0000
44 47 9 ff0000
45 47 9 ff0000
46 47 9 ff0000
47 47 9 ff0000
32 36 10 ff00aa
33 36 10 ff00aa
46 36 10 ff00aa
47 36 10 ff00aa
33 37 10 ff00aa
46 37 10 ff00aa
33 38 10 ff00aa
46 38 10 ff00aa
33 39 10 ff00aa
46 39 10 ff00aa
33 40 10 ff00aa
46 40 10 ff00aa
33 41 10 ff00aa
46 41 10 ff00aa
33 42 10 ff00aa
46 42 10 ff00aa
33 43 10 ff00aa
46 43 10 ff00aa
33 44 10 ff00aa
46 44 10 ff00aa
33 45 10 ff00aa
46 45 10 ff00aa
33 46 10 ff00aa
46 46 10 ff00aa
32 47 10 ff0000
33 47 10 ff0000
34 47 10 ff0000
35 47 10 ff0000
36 47 10 ff0000
37 47 10 ff0000
38 47 10 ff0000
39 47 10 ff0000
40 47 10 ff0000
41 47 10 ff0000
42 47 10 ff0000
43 47 10 ff0000
44 47 10 ff0000
45 47 10 ff0000
46 47 10 ff0000
47 47 10 ff0000
48 32 0 0000ff
49 32 0 0000ff
50 32 0 0000ff
51 32 0 0000ff
52 32 0 0000ff
53 32 0 0000ff
54 32 0 0000ff
55 32 0 0000ff
56 32 0 0000ff
57 32 0 0000ff
58 32 0 0000ff
59 32 0 0000ff
60 32 0 0000ff
61 32 0 0000ff
62 32 0 0000ff
63 32 0 0000ff
48 33 0 0000ff
49 33 0 0000ff
50 33 0 0000ff
51 33 0 0000ff
52 33 0 0000ff
53 33 0 0000ff
54 33 0 0000ff
55 33 0 0000ff
56 33 0 0000ff
57 33 0 0000ff
58 33 0 0000ff
59 33 0 0000ff
60 33 0 0000ff
61 33 0 0000ff
62 33 0 0000ff
63 33 0 0000ff
48 34 0 0000ff
49 34 0 0000ff
50 34 0 0000ff
51 34 0 0000ff
52 34 0 0000ff
53 34 0 0000ff
54 34 0 0000ff
55 34 0 0000ff
56 34 0 0000ff
57 34 0 0000ff
58 34 0 0000ff
59 34 0 0000ff
60 34 0 0000ff
61 34 0 0000ff
62 34 0 0000ff
63 34 0 0000ff
48 35 0 0000ff
49 35 0 0000ff
50 35 0 0000ff
51 35 0 0000ff
52 35 0 0000ff
53 35 0 0000ff
54 35 0 0000ff
55 35 0 0000ff
56 35 0 0000ff
57 35 0 0000ff
58 35 0 0000ff
59 35 0 0000ff
60 35 0 0000ff
61 35 0 0000ff
62 35 0 0000ff
63 35 0 0000ff
48 36 0 0000ff
49 36 0 0000ff
50 36 0 0000ff
51 36 0 0000ff
52 36 0 0000ff
53 36 0 0000ff
54 36 0 0000ff
55 36 0 0000ff
56 36 0 0000ff
57 36 0 0000ff
58 36 0 0000ff
59 36 0 0000ff
60 36 0 0000ff
61 36 0 0000ff
62 36 0 0000ff
63 36 0 0000ff
48 37 0 0000ff
49 37 0 0000ff
50 37 0 0000ff
51 37 0 0000ff
52 37 0 0000ff
53 37 0 0000ff
54 37 0 0000ff
55 37 0 0000ff
56 37 0 0000ff
57 37 0 0000ff
58 37 0 0000ff
59 37 0 0000ff
60 37 0 0000ff
61 37 0 0000ff
62 37 0 0000ff
63 37 0 0000ff
48 38 0 0000ff
49 38 0 0000ff
50 38 0 0000ff
51 38 0 0000ff
52 38 0 0000ff
53 38 0 0000ff
54 38 0 0000ff
55 38 0 0000ff
56 38 0 0000ff
57 38 0 0000ff
58 38 0 0000ff
59 38 0 0000ff
60 38 0 0000ff
61 38 0 0000ff
62 38 0 0000ff
63 38 0 0000ff
48 39 0 0000ff
49 39 0 0000ff
50 39 0 0000ff
51 39 0 0000ff
52 39 0 0000ff
53 39 0 0000ff
54 39 0 0000ff
55 39 0 0000ff
56 39 0 0000ff
57 39 0 0000ff
58 39 0 0000ff
59 39 0 0000ff
60 39 0 0000ff
61 39 0 0000ff
62 39 0 0000ff
63 39 0 0000ff
48 40 0 0000ff
49 40 0 0000ff
50 40 0 0000ff
51 40 0 0000ff
52 40 0 0000ff
53 40 0 0000ff
54 40 0 0000ff
55 40 0 0000ff
56 40 0 0000ff
57 40 0 0000ff
58 40 0 0000ff
59 40 0 0000ff
60 40 0 0000ff
61 40 0 0000ff
62 40 0 0000ff
63 40 0 0000ff
48 41 0 0000ff
49 41 0 0000ff
50 41 0 0000ff
51 41 0 0000ff
52 41 0 0000ff
53 41 0 0000ff
54 41 0 0000ff
55 41 0 0000ff
56 41 0 0000ff
57 41 0 0000ff
58 41 0 0000ff
59 41 0 0000ff
60 41 0 0000ff
61 41 0 0000ff
62 41 0 0000ff
63 41 0 0000ff
48 42 0 0000ff
49 42 0 0000ff
50 42 0 0000ff
51 42 0 0000ff
52 42 0 0000ff
53 42 0 0000ff
54 42 0 0000ff
55 42 0 0000ff
56 42 0 0000ff
57 42 0 0000ff
58 42 0 0000ff
59 42 0 0000ff
60 42 0 0000ff
61 42 0 0000ff
62 42 0 0000ff
63 42 0 0000ff
48 43 0 0000ff
49 43 0 0000ff
50 43 0 0000ff
51 43 0 0000ff
52 43 0 0000ff
53 43 0 0000ff
54 43 0 0000ff
55 43 0 0000ff
56 43 0 0000ff
57 43 0 0000ff
58 43 0 0000ff
59 43 0 0000ff
60 43 0 0000ff
61 43 0 0000ff
62 43 0 0000ff
63 43 0 0000ff
48 44 0 0000ff
49 44 0 0000ff
50 44 0 0000ff
51 44 0 0000ff
52 44 0 0000ff
53 44 0 0000ff
54 44 0 0000ff
55 44 0 0000ff
56 44 0 0000ff
57 44 0 0000ff
58 44 0 0000ff
59 44 0 0000ff
60 44 0 0000ff
61 44 0 0000ff
62 44 0 0000ff
63 44 0 0000ff
48 45 0 0000ff
49 45 0 0000ff
50 45 0 0000ff
51 45 0 0000ff
52 45 0 0000ff
53 45 0 0000ff
54 45 0 0000ff
55 45 0 0000ff
56 45 0 0000ff
57 45 0 0000ff
58 45 0 0000ff
59 45 0 0000ff
60 45 0 0000ff
61 45 0 0000ff
62 45 0 0000ff
63 45 0 0000ff
48 46 0 0000ff
49 46 0 0000ff
50 46 0 0000ff
51 46 0 0000ff
52 46 0 0000ff
53 46 0 0000ff
54 46 0 0000ff
55 46 0 0000ff
56 46 0 0000ff
57 46 0 0000ff
58 46 0 0000ff
59 46 0 0000ff
60 46 0 0000ff
61 46 0 0000ff
62 46 0 0000ff
63 46 0 0000ff
48 47 0 0000ff
49 47 0 0000ff
50 47 0 0000ff
51 47 0 0000ff
52 47 0 0000ff
53 47 0 0000ff
54 47 0 0000ff
55 47 0 0000ff
56 47 0 0000ff
57 47 0 0000ff
58 47 0 0000ff
59 47 0 0000ff
60 47 0 0000ff
61 47 0 0000ff
62 47 0 0000ff
63 47 0 0000ff
56 32 1 ff0000
57 32 1 ffffaa
58 32 1 ffffaa
59 32 1 ffffaa
60 32 1 ffffaa
61 32 1 ffffaa
62 32 1 ffffaa
63 32 1 ffffaa
56 33 1 ff0000
56 34 1 ff0000
56 35 1 ff0000
50 36 1 ff00aa
51 36 1 ff00aa
52 36 1 ff00aa
53 36 1 ff00aa
54 36 1 ff00aa
55 36 1 ff00aa
56 36 1 ff0000
56 37 1 ff0000
51 40 1 ffccaa
52 40 1 ffccaa
53 40 1 ffccaa
54 40 1 ffccaa
55 40 1 ffccaa
56 40 1 ff0000
51 41 1 ffccaa
56 41 1 ff0000
56 42 1 ff0000
56 43 1 ff0000
51 44 1 ffccaa
52 44 1 ffccaa
53 44 1 ffccaa
54 44 1 ffccaa
55 44 1 ffccaa
56 44 1 ff0000
56 45 1 ff0000
56 46 1 ff0000
48 47 1 ff0000
49 47 1 ff0000
50 47 1 ff0000
51 47 1 ff0000
52 47 1 ff0000
53 47 1 ff0000
54 47 1 ff0000
55 47 1 ff0000
56 47 1 ff0000
57 47 1 ff0000
58 47 1 ff0000
59 47 1 ff0000
60 47 1 ff0000
61 47 1 ff0000
62 47 1 ff0000
63 47 1 ff0000
56 32 2 ff0000
57 32 2 ffffaa
58 32 2 ffffaa
59 32 2 ffffaa
60 32 2 ffffaa
61 32 2 ffffaa
62 32 2 ffffaa
63 32 2 ffffaa
56 33 2 ff0000
56 34 2 ff0000
56 35 2 ff0000
50 36 2 ff00aa
51 36 2 ff00aa
52 36 2 ff00aa
53 36 2 ff00aa
54 36 2 ff00aa
55 36 2 ff00aa
56 36 2 ff0000
56 37 2 ff0000
51 40 2 ffccaa
52 40 2 ffccaa
53 40 2 ffccaa
54 40 2 ffccaa
55 40 2 ffccaa
56 40 2 ff0000
51 41 2 ffccaa
56 41 2 ff0000
56 42 2 ff0000
56 43 2 ff0000
51 44 2 ffccaa
52 44 2 ffccaa
53 44 2 ffccaa
54 44 2 ffccaa
55 44 2 ffccaa
56 44 2 ff0000
56 45 2 ff0000
56 46 2 ff0000
48 47 2 ff0000
49 47 2 ff0000
50 47 2 ff0000
51 47 2 ff0000
52 47 2 ff0000
53 47 2 ff0000
54 47 2 ff0000
55 47 2 ff0000
56 47 2 ff0000
57 47 2 ff0000
58 47 2 ff0000
59 47 2 ff0000
60 47 2 ff0000
61 47 2 ff0000
62 47 2 ff0000
63 47 2 ff0000
56 32 3 ff0000
57 32 3 ffffaa
58 32 3 ffffaa
59 32 3 ffffaa
60 32 3 ffffaa
61 32 3 ffffaa
62 32 3 ffffaa
63 32 3 ffffaa
56 33 3 ff0000
56 34 3 ff0000
56 35 3 ff0000
50 36 3 ff00aa
51 36 3 ff00aa
52 36 3 ff00aa
53 36 3 ff00aa
54 36 3 ff00aa
55 36 3 ff00aa
56 36 3 ff0000
56 37 3 ff0000
51 40 3 ffccaa
52 40 3 ffccaa
53 40 3 ffccaa
54 40 3 ffccaa
55 40 3 ffccaa
56 40 3 ff0000
51 41 3 ffccaa
56 41 3 ff0000
56 42 3 ff0000
56 43 3 ff0000
51 44 3 ffccaa
52 44 3 ffccaa
53 44 3 ffccaa
54 44 3 ffccaa
55 44 3 ffccaa
56 44 3 ff0000
56 45 3 ff0000
56 46 3 ff0000
48 47 3 ff0000
49 47 3 ff0000
50 47 3 ff0000
51 47 3 ff0000
52 47 3 ff0000
53 47 3 ff0000
54 47 3 ff0000
55 47 3 ff0000
56 47 3 ff0000
57 47 3 ff0000
58 47 3 ff0000
59 47 3 ff0000
60 47 3 ff0000
61 47 3 ff0000
62 47 3 ff0000
63 47 3 ff0000
56 32 4 ff0000
57 32 4 ffffaa
58 32 4 ffffaa
59 32 4 ffffaa
60 32 4 ffffaa
61 32 4 ffffaa
62 32 4 ffffaa
63 32 4 ffffaa
56 33 4 ff0000
56 34 4 ff0000
56 35 4 ff0000
50 36 4 ff00aa
51 36 4 ff00aa
52 36 4 ff00aa
53 36 4 ff00aa
54 36 4 ff00aa
55 36 4 ff00aa
56 36 4 ff0000
56 37 4 ff0000
51 40 4 ffccaa
52 40 4 ffccaa
53 40 4 ffccaa
54 40 4 ffccaa
55 40 4 ffccaa
56 40 4 ff0000
51 41 4 ffccaa
56 41 4 ff0000
56 42 4 ff0000
56 43 4 ff0000
51 44 4 ffccaa
52 44 4 ffccaa
53 44 4 ffccaa
54 44 4 ffccaa
55 44 4 ffccaa
56 44 4 ff0000
56 45 4 ff0000
56 46 4 ff0000
48 47 4 ff0000
50 47 4 ff0000
51 47 4 ff0000
52 47 4 ff0000
53 47 4 ff0000
54 47 4 ff0000
55 47 4 ff0000
56 47 4 ff0000
57 47 4 ff0000
58 47 4 ff0000
59 47 4 ff0000
60 47 4 ff0000
61 47 4 ff0000
62 47 4 ff0000
63 47 4 ff0000
56 32 5 ff0000
57 32 5 ffffaa
58 32 5 ffffaa
59 32 5 ffffaa
60 32 5 ffffaa
61 32 5 ffffaa
62 32 5 ffffaa
63 32 5 ffffaa
56 33 5 ff0000
56 34 5 ff0000
56 35 5 ff0000
50 36 5 ff00aa
51 36 5 ff00aa
52 36 5 ff00aa
53 36 5 ff00aa
54 36 5 ff00aa
55 36 5 ff00aa
56 36 5 ff0000
56 37 5 ff0000
51 40 5 ffccaa
52 40 5 ffccaa
53 40 5 ffccaa
54 40 5 ffccaa
55 40 5 ffccaa
56 40 5 ff0000
51 41 5 ffccaa
56 41 5 ff0000
56 42 5 ff0000
56 43 5 ff0000
51 44 5 ffccaa
52 44 5 ffccaa
53 44 5 ffccaa
54 44 5 ffccaa
55 44 5 ffccaa
56 44 5 ff0000
56 45 5 ff0000
56 46 5 ff0000
48 47 5 ff0000
50 47 5 ff0000
51 47 5 ff0000
52 47 5 ff0000
53 47 5 ff0000
54 47 5 ff0000
55 47 5 ff0000
56 47 5 ff0000
57 47 5 ff0000
58 47 5 ff0000
59 47 5 ff0000
60 47 5 ff0000
61 47 5 ff0000
62 47 5 ff0000
63 47 5 ff0000
56 32 6 ff0000
57 32 6 ffffaa
58 32 6 ffffaa
59 32 6 ffffaa
60 32 6 ffffaa
61 32 6 ffffaa
62 32 6 ffffaa
63 32 6 ffffaa
56 33 6 ff0000
56 34 6 ff0000
56 35 6 ff0000
50 36 6 ff00aa
51 36 6 ff00aa
52 36 6 ff00aa
53 36 6 ff00aa
54 36 6 ff00aa
55 36 6 ff00aa
56 36 6 ff0000
56 37 6 ff0000
56 38 6 ff0000
56 39 6 ff0000
51 40 6 ffccaa
52 40 6 ffccaa
53 40 6 ffccaa
54 40 6 ffccaa
55 40 6 ffccaa
56 40 6 ff0000
51 41 6 ffccaa
56 41 6 ff0000
56 42 6 ff0000
56 43 6 ff0000
51 44 6 ffccaa
52 44 6 ffccaa
53 44 6 ffccaa
54 44 6 ffccaa
55 44 6 ffccaa
56 44 6 ff0000
56 45 6 ff0000
56 46 6 ff0000
48 47 6 ff0000
50 47 6 ff0000
51 47 6 ff0000
52 47 6 ff0000
53 47 6 ff0000
54 47 6 ff0000
55 47 6 ff0000
56 47 6 ff0000
57 47 6 ff0000
58 47 6 ff0000
59 47 6 ff0000
60 47 6 ff0000
61 47 6 ff0000
62 47 6 ff0000
63 47 6 ff0000
56 32 7 ff0000
57 32 7 ffffaa
58 32 7 ffffaa
59 32 7 ffffaa
60 32 7 ffffaa
61 32 7 ffffaa
62 32 7 ffffaa
63 32 7 ffffaa
56 33 7 ff0000
56 34 7 ff0000
56 35 7 ff0000
48 36 7 ff00aa
49 36 7 ff00aa
50 36 7 ff00aa
51 36 7 ff00aa
52 36 7 ff00aa
53 36 7 ff00aa
54 36 7 ff00aa
55 36 7 ff00aa
56 36 7 ff0000
56 37 7 ff0000
56 38 7 ff0000
56 39 7 ff0000
51 40 7 ffccaa
52 40 7 ffccaa
53 40 7 ffccaa
54 40 7 ffccaa
55 40 7 ffccaa
56 40 7 ff0000
51 41 7 ffccaa
56 41 7 ff0000
56 42 7 ff0000
56 43 7 ff0000
51 44 7 ffccaa
52 44 7 ffccaa
53 44 7 ffccaa
54 44 7 ffccaa
55 44 7 ffccaa
56 44 7 ff0000
56 45 7 ff0000
56 46 7 ff0000
48 47 7 ff0000
49 47 7 ff0000
50 47 7 ff0000
51 47 7 ff0000
52 47 7 ff0000
53 47 7 ff0000
54 47 7 ff0000
55 47 7 ff0000
56 47 7 ff0000
57 47 7 ff0000
58 47 7 ff0000
59 47 7 ff0000
60 47 7 ff0000
61 47 7 ff0000
62 47 7 ff0000
63 47 7 ff0000
56 32 8 ff0000
57 32 8 ffffaa
58 32 8 ffffaa
59 32 8 ffffaa
60 32 8 ffffaa
61 32 8 ffffaa
62 32 8 ffffaa
63 32 8 ffffaa
56 33 8 ff0000
56 34 8 ff0000
56 35 8 ff0000
48 36 8 ff00aa
49 36 8 ff00aa
50 36 8 ff00aa
51 36 8 ff00aa
52 36 8 ff00aa
53 36 8 ff00aa
54 36 8 ff00aa
55 36 8 ff00aa
56 36 8 ff0000
56 37 8 ff0000
56 38 8 ff0000
56 39 8 ff0000
51 40 8 ffccaa
52 40 8 ffccaa
53 40 8 ffccaa
54 40 8 ffccaa
55 40 8 ffccaa
56 40 8 ff0000
51 41 8 ffccaa
56 41 8 ff0000
56 42 8 ff0000
56 43 8 ff0000
51 44 8 ffccaa
52 44 8 ffccaa
53 44 8 ffccaa
54 44 8 ffccaa
55 44 8 ffccaa
56 44 8 ff0000
56 45 8 ff0000
56 46 8 ff0000
48 47 8 ff0000
49 47 8 ff0000
50 47 8 ff0000
51 47 8 ff0000
52 47 8 ff0000
53 47 8 ff0000
54 47 8 ff0000
55 47 8 ff0000
56 47 8 ff0000
57 47 8 ff0000
58 47 8 ff0000
59 47 8 ff0000
60 47 8 ff0000
61 47 8 ff0000
62 47 8 ff0000
63 47 8 ff0000
56 32 9 ff0000
57 32 9 ffffaa
58 32 9 ffffaa
59 32 9 ffffaa
60 32 9 ffffaa
61 32 9 ffffaa
62 32 9 ffffaa
63 32 9 ffffaa
56 33 9 ff0000
56 34 9 ff0000
56 35 9 ff0000
48 36 9 ff00aa
49 36 9 ff00aa
50 36 9 ff00aa
51 36 9 ff00aa
52 36 9 ff00aa
53 36 9 ff00aa
54 36 9 ff00aa
55 36 9 ff00aa
56 36 9 ff0000
56 37 9 ff0000
56 38 9 ff0000
56 39 9 ff0000
51 40 9 ffccaa
52 40 9 ffccaa
53 40 9 ffccaa
54 40 9 ffccaa
55 40 9 ffccaa
56 40 9 ff0000
51 41 9 ffccaa
56 41 9 ff0000
56 42 9 ff0000
56 43 9 ff0000
51 44 9 ffccaa
52 44 9 ffccaa
53 44 9 ffccaa
54 44 9 ffccaa
55 44 9 ffccaa
56 44 9 ff0000
56 45 9 ff0000
56 46 9 ff0000
48 47 9 ff0000
49 47 9 ff0000
50 47 9 ff0000
51 47 9 ff0000
52 47 9 ff0000
53 47 9 ff0000
54 47 9 ff0000
55 47 9 ff0000
56 47 9 ff0000
57 47 9 ff0000
58 47 9 ff0000
59 47 9 ff0000
60 47 9 ff0000
61 47 9 ff0000
62 47 9 ff0000
63 47 9 ff0000
56 32 10 ff0000
57 32 10 ffffaa
58 32 10 ffffaa
59 32 10 ffffaa
60 32 10 ffffaa
61 32 10 ffffaa
62 32 10 ffffaa
63 32 10 ffffaa
56 33 10 ff0000
56 34 10 ff0000
56 35 10 ff0000
48 36 10 ff00aa
49 36 10 ff00aa
50 36 10 ff00aa
51 36 10 ff00aa
52 36 10 ff00aa
53 36 10 ff00aa
54 36 10 ff00aa
55 36 10 ff00aa
56 36 10 ff0000
56 37 10 ff0000
56 38 10 ff0000
56 39 10 ff0000
51 40 10 ffccaa
52 40 10 ffccaa
53 40 10 ffccaa
54 40 10 ffccaa
55 40 10 ffccaa
56 40 10 ff0000
51 41 10 ffccaa
56 41 10 ff0000
56 42 10 ff0000
56 43 10 ff0000
51 44 10 ffccaa
52 44 10 ffccaa
53 44 10 ffccaa
54 44 10 ffccaa
55 44 10 ffccaa
56 44 10 ff0000
56 45 10 ff0000
56 46 10 ff0000
48 47 10 ff0000
49 47 10 ff0000
50 47 10 ff0000
51 47 10 ff0000
52 47 10 ff0000
53 47 10 ff0000
54 47 10 ff0000
55 47 10 ff0000
56 47 10 ff0000
57 47 10 ff0000
58 47 10 ff0000
59 47 10 ff0000
60 47 10 ff0000
61 47 10 ff0000
62 47 10 ff0000
63 47 10 ff0000
48 0 0 0000ff
49 0 0 0000ff
50 0 0 0000ff
51 0 0 0000ff
52 0 0 0000ff
53 0 0 0000ff
54 0 0 0000ff
55 0 0 0000ff
56 0 0 0000ff
57 0 0 0000ff
58 0 0 0000ff
59 0 0 0000ff
60 0 0 0000ff
61 0 0 0000ff
62 0 0 0000ff
63 0 0 0000ff
48 1 0 0000ff
49 1 0 0000ff
50 1 0 0000ff
51 1 0 0000ff
52 1 0 0000ff
53 1 0 0000ff
54 1 0 0000ff
55 1 0 0000ff
56 1 0 0000ff
57 1 0 0000ff
58 1 0 0000ff
59 1 0 0000ff
60 1 0 0000ff
61 1 0 0000ff
62 1 0 0000ff
63 1 0 0000ff
48 2 0 0000ff
49 2 0 0000ff
50 2 0 0000ff
51 2 0 0000ff
52 2 0 0000ff
53 2 0 0000ff
54 2 0 0000ff
55 2 0 0000ff
56 2 0 0000ff
57 2 0 0000ff
58 2 0 0000ff
59 2 0 0000ff
60 2 0 0000ff
61 2 0 0000ff
62 2 0 0000ff
63 2 0 0000ff
48 3 0 0000ff
49 3 0 0000ff
50 3 0 0000ff
51 3 0 0000ff
52 3 0 0000ff
53 3 0 0000ff
54 3 0 0000ff
55 3 0 0000ff
56 3 0 0000ff
57 3 0 0000ff
58 3 0 0000ff
59 3 0 0000ff
60 3 0 0000ff
61 3 0 0000ff
62 3 0 0000ff
63 3 0 0000ff
48 4 0 0000ff
49 4 0 0000ff
50 4 0 0000ff
51 4 0 0000ff
52 4 0 0000ff
53 4 0 0000ff
54 4 0 0000ff
55 4 0 0000ff
56 4 0 0000ff
57 4 0 0000ff
58 4 0 0000ff
59 4 0 0000ff
60 4 0 0000ff
61 4 0 0000ff
62 4 0 0000ff
63 4 0 0000ff
48 5 0 0000ff
49 5 0 0000ff
50 5 0 0000ff
51 5 0 0000ff
52 5 0 0000ff
53 5 0 0000ff
54 5 0 0000ff
55 5 0 0000ff
56 5 0 0000ff
57 5 0 0000ff
58 5 0 0000ff
59 5 0 0000ff
60 5 0 0000ff
61 5 0 0000ff
62 5 0 0000ff
63 5 0 0000ff
48 6 0 0000ff
49 6 0 0000ff
50 6 0 0000ff
51 6 0 0000ff
52 6 0 0000ff
53 6 0 0000ff
54 6 0 0000ff
55 6 0 0000ff
56 6 0 0000ff
57 6 0 0000ff
58 6 0 0000ff
59 6 0 0000ff
60 6 0 0000ff
61 6 0 0000ff
62 6 0 0000ff
63 6 0 0000ff
48 7 0 0000ff
49 7 0 0000ff
50 7 0 0000ff
51 7 0 0000ff
52 7 0 0000ff
53 7 0 0000ff
54 7 0 0000ff
55 7 0 0000ff
56 7 0 0000ff
57 7 0 0000ff
58 7 0 0000ff
59 7 0 0000ff
60 7 0 0000ff
61 7 0 0000ff
62 7 0 0000ff
63 7 0 0000ff
48 8 0 0000ff
49 8 0 0000ff
50 8 0 0000ff
51 8 0 0000ff
52 8 0 0000ff
53 8 0 0000ff
54 8 0 0000ff
55 8 0 0000ff
56 8 0 0000ff
57 8 0 0000ff
58 8 0 0000ff
59 8 0 0000ff
60 8 0 0000ff
61 8 0 0000ff
62 8 0 0000ff
63 8 0 0000ff
48 9 0 0000ff
49 9 0 0000ff
50 9 0 0000ff
51 9 0 0000ff
52 9 0 0000ff
53 9 0 0000ff
54 9 0 0000ff
55 9 0 0000ff
56 9 0 0000ff
57 9 0 0000ff
58 9 0 0000ff
59 9 0 0000ff
60 9 0 0000ff
61 9 0 0000ff
62 9 0 0000ff
63 9 0 0000ff
48 10 0 0000ff
49 10 0 0000ff
50 10 0 0000ff
51 10 0 0000ff
52 10 0 0000ff
53 10 0 0000ff
54 10 0 0000ff
55 10 0 0000ff
56 10 0 0000ff
57 10 0 0000ff
58 10 0 0000ff
59 10 0 0000ff
60 10 0 0000ff
61 10 0 0000ff
62 10 0 0000ff
63 10 0 0000ff
48 11 0 0000ff
49 11 0 0000ff
50 11 0 0000ff
51 11 0 0000ff
52 11 0 0000ff
53 11 0 0000ff
54 11 0 0000ff
55 11 0 0000ff
56 11 0 0000ff
57 11 0 0000ff
58 11 0 0000ff
59 11 0 0000ff
60 11 0 0000ff
61 11 0 0000ff
62 11 0 0000ff
63 11 0 0000ff
48 12 0 0000ff
49 12 0 0000ff
50 12 0 0000ff
51 12 0 0000ff
52 12 0 0000ff
53 12 0 0000ff
54 12 0 0000ff
55 12 0 0000ff
56 12 0 0000ff
57 12 0 0000ff
58 12 0 0000ff
59 12 0 0000ff
60 12 0 0000ff
61 12 0 0000ff
62 12 0 0000ff
63 12 0 0000ff
48 13 0 0000ff
49 13 0 0000ff
50 13 0 0000ff
51 13 0 0000ff
52 13 0 0000ff
53 13 0 0000ff
54 13 0 0000ff
55 13 0 0000ff
56 13 0 0000ff
57 13 0 0000ff
58 13 0 0000ff
59 13 0 0000ff
60 13 0 0000ff
61 13 0 0000ff
62 13 0 0000ff
63 13 0 0000ff
48 14 0 0000ff
49 14 0 0000ff
50 14 0 0000ff
51 14 0 0000ff
52 14 0 0000ff
53 14 0 0000ff
54 14 0 0000ff
55 14 0 0000ff
56 14 0 0000ff
57 14 0 0000ff
58 14 0 0000ff
59 14 0 0000ff
60 14 0 0000ff
61 14 0 0000ff
62 14 0 0000ff
63 14 0 0000ff
48 15 0 0000ff
49 15 0 0000ff
50 15 0 0000ff
51 15 0 0000ff
52 15 0 0000ff
53 15 0 0000ff
54 15 0 0000ff
55 15 0 0000ff
56 15 0 0000ff
57 15 0 0000ff
58 15 0 0000ff
59 15 0 0000ff
60 15 0 0000ff
61 15 0 0000ff
62 15 0 0000ff
63 15 0 0000ff
48 0 1 ff0000
49 0 1 ff0000
50 0 1 ff0000
51 0 1 ff0000
52 0 1 ff0000
53 0 1 ff0000
54 0 1 ff0000
55 0 1 ff0000
56 0 1 ff0000
57 0 1 ff0000
58 0 1 ff0000
59 0 1 ff0000
60 0 1 ff0000
61 0 1 ff0000
62 0 1 ff0000
63 0 1 ff0000
56 1 1 ff0000
56 2 1 ff0000
56 3 1 ff0000
56 4 1 ff0000
56 5 1 ff0000
56 6 1 ff0000
56 7 1 ff0000
56 8 1 ff0000
56 9 1 ff0000
56 10 1 ff0000
56 11 1 ff0000
56 12 1 ff0000
56 13 1 ff0000
56 14 1 ff0000
56 15 1 ff0000
48 0 2 ff0000
49 0 2 ff0000
50 0 2 ff0000
51 0 2 ff0000
52 0 2 ff0000
53 0 2 ff0000
54 0 2 ff0000
55 0 2 ff0000
56 0 2 ff0000
57 0 2 ff0000
58 0 2 ff0000
59 0 2 ff0000
60 0 2 ff0000
61 0 2 ff0000
62 0 2 ff0000
63 0 2 ff0000
56 1 2 ff0000
56 2 2 ff0000
56 3 2 ff0000
56 4 2 ff0000
56 5 2 ff0000
56 6 2 ff0000
56 7 2 ff0000
56 8 2 ff0000
56 9 2 ff0000
56 10 2 ff0000
56 11 2 ff0000
56 12 2 ff0000
56 13 2 ff0000
56 14 2 ff0000
56 15 2 ff0000
48 0 3 ff0000
49 0 3 ff0000
50 0 3 ff0000
51 0 3 ff0000
52 0 3 ff0000
53 0 3 ff0000
54 0 3 ff0000
55 0 3 ff0000
56 0 3 ff0000
57 0 3 ff0000
58 0 3 ff0000
59 0 3 ff0000
60 0 3 ff0000
61 0 3 ff0000
62 0 3 ff0000
63 0 3 ff0000
56 1 3 ff0000
56 2 3 ff0000
56 3 3 ff0000
56 4 3 ff0000
56 5 3 ff0000
56 6 3 ff0000
56 7 3 ff0000
56 8 3 ff0000
56 9 3 ff0000
56 10 3 ff0000
56 11 3 ff0000
56 12 3 ff0000
56 13 3 ff0000
56 14 3 ff0000
56 15 3 ff0000
48 0 4 ff0000
49 0 4 ff0000
50 0 4 ff0000
51 0 4 ff0000
52 0 4 ff0000
53 0 4 ff0000
54 0 4 ff0000
55 0 4 ff0000
56 0 4 ff0000
57 0 4 ff0000
58 0 4 ff0000
59 0 4 ff0000
60 0 4 ff0000
61 0 4 ff0000
62 0 4 ff0000
63 0 4 ff0000
56 1 4 ff0000
56 2 4 ff0000
56 3 4 ff0000
56 4 4 ff0000
56 5 4 ff0000
56 6 4 ff0000
56 7 4 ff0000
56 8 4 ff0000
56 9 4 ff0000
56 10 4 ff0000
56 11 4 ff0000
56 12 4 ff0000
56 13 4 ff0000
56 14 4 ff0000
56 15 4 ff0000
48 0 5 ff0000
49 0 5 ff0000
50 0 5 ff0000
51 0 5 ff0000
52 0 5 ff0000
53 0 5 ff0000
54 0 5 ff0000
55 0 5 ff0000
56 0 5 ff0000
57 0 5 ff0000
58 0 5 ff0000
59 0 5 ff0000
60 0 5 ff0000
61 0 5 ff0000
62 0 5 ff0000
63 0 5 ff0000
56 1 5 ff0000
56 2 5 ff0000
56 3 5 ff0000
56 4 5 ff0000
56 5 5 ff0000
56 6 5 ff0000
56 7 5 ff0000
56 8 5 ff0000
56 9 5 ff0000
56 10 5 ff0000
56 11 5 ff0000
56 12 5 ff0000
56 13 5 ff0000
56 14 5 ff0000
56 15 5 ff0000
48 0 6 ff0000
49 0 6 ff0000
50 0 6 ff0000
51 0 6 ff0000
52 0 6 ff0000
53 0 6 ff0000
54 0 6 ff0000
55 0 6 ff0000
56 0 6 ff0000
57 0 6 ff0000
58 0 6 ff0000
59 0 6 ff0000
60 0 6 ff0000
61 0 6 ff0000
62 0 6 ff0000
63 0 6 ff0000
56 1 6 ff0000
56 2 6 ff0000
56 3 6 ff0000
56 4 6 ff0000
56 5 6 ff0000
56 6 6 ff0000
56 7 6 ff0000
56 8 6 ff0000
56 9 6 ff0000
56 10 6 ff0000
56 11 6 ff0000
56 12 6 ff0000
56 13 6 ff0000
56 14 6 ff0000
56 15 6 ff0000
48 0 7 ff0000
49 0 7 ff0000
50 0 7 ff0000
51 0 7 ff0000
52 0 7 ff0000
53 0 7 ff0000
54 0 7 ff0000
55 0 7 ff0000
56 0 7 ff0000
57 0 7 ff0000
58 0 7 ff0000
59 0 7 ff0000
60 0 7 ff0000
61 0 7 ff0000
62 0 7 ff0000
63 0 7 ff0000
56 1 7 ff0000
56 2 7 ff0000
56 3 7 ff0000
56 4 7 ff0000
56 5 7 ff0000
56 6 7 ff0000
56 7 7 ff0000
56 8 7 ff0000
56 9 7 ff0000
56 10 7 ff0000
56 11 7 ff0000
56 12 7 ff0000
56 13 7 ff0000
56 14 7 ff0000
56 15 7 ff0000
48 0 8 ff0000
49 0 8 ff0000
50 0 8 ff0000
51 0 8 ff0000
52 0 8 ff0000
53 0 8 ff0000
54 0 8 ff0000
55 0 8 ff0000
56 0 8 ff0000
57 0 8 ff0000
58 0 8 ff0000
59 0 8 ff0000
60 0 8 ff0000
61 0 8 ff0000
62 0 8 ff0000
63 0 8 ff0000
56 1 8 ff0000
56 2 8 ff0000
56 3 8 ff0000
56 4 8 ff0000
56 5 8 ff0000
56 6 8 ff0000
56 7 8 ff0000
56 8 8 ff0000
56 9 8 ff0000
56 10 8 ff0000
56 11 8 ff0000
56 12 8 ff0000
56 13 8 ffffff
56 14 8 ff0000
56 15 8 ff0000
48 0 9 ff0000
49 0 9 ff0000
50 0 9 ff0000
51 0 9 ff0000
52 0 9 ff0000
53 0 9 ff0000
54 0 9 ff0000
55 0 9 ff0000
56 0 9 ff0000
57 0 9 ff0000
58 0 9 ff0000
59 0 9 ff0000
60 0 9 ff0000
61 0 9 ff0000
62 0 9 ff0000
63 0 9 ff0000
56 1 9 ff0000
56 2 9 ff0000
56 3 9 ff0000
56 4 9 ff0000
56 5 9 ff0000
56 6 9 ff0000
56 7 9 ff0000
56 8 9 ff0000
56 9 9 ff0000
56 10 9 ff0000
56 11 9 ff0000
56 12 9 ff0000
56 13 9 ff0000
56 14 9 ffffff
56 15 9 ffffff
48 0 10 ff0000
49 0 10 ff0000
50 0 10 ff0000
51 0 10 ff0000
52 0 10 ff0000
53 0 10 ff0000
54 0 10 ff0000
55 0 10 ff0000
56 0 10 ff0000
57 0 10 ff0000
58 0 10 ff0000
59 0 10 ff0000
60 0 10 ff0000
61 0 10 ff0000
62 0 10 ff0000
63 0 10 ff0000
56 1 10 ff0000
56 2 10 ff0000
56 3 10 ff0000
56 4 10 ff0000
56 5 10 ff0000
56 6 10 ff0000
56 7 10 ff0000
56 8 10 ff0000
56 9 10 ff0000
56 10 10 ff0000
56 11 10 ff0000
56 12 10 ff0000
56 13 10 ff0000
56 14 10 ff0000
56 15 10 ffffff
48 16 0 0000ff
49 16 0 0000ff
50 16 0 0000ff
51 16 0 0000ff
52 16 0 0000ff
53 16 0 0000ff
54 16 0 0000ff
55 16 0 0000ff
56 16 0 0000ff
57 16 0 0000ff
58 16 0 0000ff
59 16 0 0000ff
60 16 0 0000ff
61 16 0 0000ff
62 16 0 0000ff
63 16 0 0000ff
48 17 0 0000ff
49 17 0 0000ff
50 17 0 0000ff
51 17 0 0000ff
52 17 0 0000ff
53 17 0 0000ff
54 17 0 0000ff
55 17 0 0000ff
56 17 0 0000ff
57 17 0 0000ff
58 17 0 0000ff
59 17 0 0000ff
60 17 0 0000ff
61 17 0 0000ff
62 17 0 0000ff
63 17 0 0000ff
48 18 0 0000ff
49 18 0 0000ff
50 18 0 0000ff
51 18 0 0000ff
52 18 0 0000ff
53 18 0 0000ff
54 18 0 0000ff
55 18 0 0000ff
56 18 0 0000ff
57 18 0 0000ff
58 18 0 0000ff
59 18 0 0000ff
60 18 0 0000ff
61 18 0 0000ff
62 18 0 0000ff
63 18 0 0000ff
48 19 0 0000ff
49 19 0 0000ff
50 19 0 0000ff
51 19 0 0000ff
52 19 0 0000ff
53 19 0 0000ff
54 19 0 0000ff
55 19 0 0000ff
56 19 0 0000ff
57 19 0 0000ff
58 19 0 0000ff
59 19 0 0000ff
60 19 0 0000ff
61 19 0 0000ff
62 19 0 0000ff
63 19 0 0000ff
48 20 0 0000ff
49 20 0 0000ff
50 20 0 0000ff
51 20 0 0000ff
52 20 0 0000ff
53 20 0 0000ff
54 20 0 0000ff
55 20 0 0000ff
56 20 0 0000ff
57 20 0 0000ff
58 20 0 0000ff
59 20 0 0000ff
60 20 0 0000ff
61 20 0 0000ff
62 20 0 0000ff
63 20 0 0000ff
48 21 0 0000ff
49 21 0 0000ff
50 21 0 0000ff
51 21 0 0000ff
52 21 0 0000ff
53 21 0 0000ff
54 21 0 0000ff
55 21 0 0000ff
56 21 0 0000ff
57 21 0 0000ff
58 21 0 0000ff
59 21 0 0000ff
60 21 0 0000ff
61 21 0 0000ff
62 21 0 0000ff
63 21 0 0000ff
48 22 0 0000ff
49 22 0 0000ff
50 22 0 0000ff
51 22 0 0000ff
52 22 0 0000ff
53 22 0 0000ff
54 22 0 0000ff
55 22 0 0000ff
56 22 0 0000ff
57 22 0 0000ff
58 22 0 0000ff
59 22 0 0000ff
60 22 0 0000ff
61 22 0 0000ff
62 22 0 0000ff
63 22 0 0000ff
48 23 0 0000ff
49 23 0 0000ff
50 23 0 0000ff
51 23 0 0000ff
52 23 0 0000ff
53 23 0 0000ff
54 23 0 0000ff
55 23 0 0000ff
56 23 0 0000ff
57 23 0 0000ff
58 23 0 0000ff
59 23 0 0000ff
60 23 0 0000ff
61 23 0 0000ff
62 23 0 0000ff
63 23 0 0000ff
48 24 0 0000ff
49 24 0 0000ff
50 24 0 0000ff
51 24 0 0000ff
52 24 0 0000ff
53 24 0 0000ff
54 24 0 0000ff
55 24 0 0000ff
56 24 0 0000ff
57 24 0 0000ff
58 24 0 0000ff
59 24 0 0000ff
60 24 0 0000ff
61 24 0 0000ff
62 24 0 0000ff
63 24 0 0000ff
48 25 0 0000ff
49 25 0 0000ff
50 25 0 0000ff
51 25 0 0000ff
52 25 0 0000ff
53 25 0 0000ff
54 25 0 0000ff
55 25 0 0000ff
56 25 0 0000ff
57 25 0 0000ff
58 25 0 0000ff
59 25 0 0000ff
60 25 0 0000ff
61 25 0 0000ff
62 25 0 0000ff
63 25 0 0000ff
48 26 0 0000ff
49 26 0 0000ff
50 26 0 0000ff
51 26 0 0000ff
52 26 0 0000ff
53 26 0 0000ff
54 26 0 0000ff
55 26 0 0000ff
56 26 0 0000ff
57 26 0 0000ff
58 26 0 0000ff
59 26 0 0000ff
60 26 0 0000ff
61 26 0 0000ff
62 26 0 0000ff
63 26 0 0000ff
48 27 0 0000ff
49 27 0 0000ff
50 27 0 0000ff
51 27 0 0000ff
52 27 0 0000ff
53 27 0 0000ff
54 27 0 0000ff
55 27 0 0000ff
56 27 0 0000ff
57 27 0 0000ff
58 27 0 0000ff
59 27 0 0000ff
60 27 0 0000ff
61 27 0 0000ff
62 27 0 0000ff
63 27 0 0000ff
48 28 0 0000ff
49 28 0 0000ff
50 28 0 0000ff
51 28 0 0000ff
52 28 0 0000ff
53 28 0 0000ff
54 28 0 0000ff
55 28 0 0000ff
56 28 0 0000ff
57 28 0 0000ff
58 28 0 0000ff
59 28 0 0000ff
60 28 0 0000ff
61 28 0 0000ff
62 28 0 0000ff
63 28 0 0000ff
48 29 0 0000ff
49 29 0 0000ff
50 29 0 0000ff
51 29 0 0000ff
52 29 0 0000ff
53 29 0 0000ff
54 29 0 0000ff
55 29 0 0000ff
56 29 0 0000ff
57 29 0 0000ff
58 29 0 0000ff
59 29 0 0000ff
60 29 0 0000ff
61 29 0 0000ff
62 29 0 0000ff
63 29 0 0000ff
48 30 0 0000ff
49 30 0 0000ff
50 30 0 0000ff
51 30 0 0000ff
52 30 0 0000ff
53 30 0 0000ff
54 30 0 0000ff
55 30 0 0000ff
56 30 0 0000ff
57 30 0 0000ff
58 30 0 0000ff
59 30 0 0000ff
60 30 0 0000ff
61 30 0 0000ff
62 30 0 0000ff
63 30 0 0000ff
48 31 0 0000ff
49 31 0 0000ff
50 31 0 0000ff
51 31 0 0000ff
52 31 0 0000ff
53 31 0 0000ff
54 31 0 0000ff
55 31 0 0000ff
56 31 0 0000ff
57 31 0 0000ff
58 31 0 0000ff
59 31 0 0000ff
60 31 0 0000ff
61 31 0 0000ff
62 31 0 0000ff
63 31 0 0000ff
56 16 1 ff0000
56 17 1 ff0000
56 18 1 ff0000
56 19 1 ff0000
56 20 1 ff0000
56 21 1 ff0000
56 22 1 ff0000
56 23 1 ff0000
56 24 1 ff0000
56 25 1 ff0000
56 26 1 ff0000
56 30 1 ff0000
56 31 1 ff0000
56 16 2 ff0000
56 17 2 ff0000
56 18 2 ff0000
56 19 2 ff0000
56 20 2 ff0000
56 21 2 ff0000
56 22 2 ff0000
56 23 2 ff0000
56 24 2 ff0000
56 25 2 ff0000
56 26 2 ff0000
56 30 2 ff0000
56 31 2 ff0000
56 16 3 ff0000
56 17 3 ff0000
56 18 3 ff0000
56 19 3 ff0000
56 20 3 ff0000
56 21 3 ff0000
56 22 3 ff0000
56 23 3 ff0000
56 24 3 ff0000
56 25 3 ff0000
56 26 3 ff0000
56 30 3 ff0000
56 31 3 ff0000
56 16 4 ff0000
56 17 4 ff0000
56 18 4 ff0000
56 19 4 ff0000
56 20 4 ff0000
56 21 4 ff0000
56 22 4 ff0000
56 23 4 ff0000
56 24 4 ff0000
56 25 4 ff0000
56 26 4 ff0000
56 30 4 ff0000
56 31 4 ff0000
56 16 5 ff0000
56 17 5 ff0000
56 18 5 ff0000
56 19 5 ff0000
56 20 5 ff0000
56 21 5 ff0000
56 22 5 ff0000
56 23 5 ff0000
56 24 5 ff0000
56 25 5 ff0000
56 26 5 ff0000
56 30 5 ff0000
56 31 5 ff0000
56 16 6 ff0000
56 17 6 ff0000
56 18 6 ff0000
56 19 6 ff0000
56 20 6 ff0000
56 21 6 ff0000
56 22 6 ff0000
56 23 6 ff0000
56 24 6 ff0000
56 25 6 ff0000
56 26 6 ff0000
56 27 6 ff0000
56 28 6 ff0000
56 29 6 ff0000
56 30 6 ff0000
56 31 6 ff0000
56 16 7 ff0000
56 17 7 ff0000
56 18 7 ff0000
56 19 7 ff0000
56 20 7 ff0000
56 21 7 ff0000
56 22 7 ff0000
56 23 7 ff0000
56 24 7 ff0000
56 25 7 ff0000
56 26 7 ff0000
56 27 7 ff0000
56 28 7 ff0000
56 29 7 ff0000
56 30 7 ff0000
56 31 7 ff0000
56 16 8 ff0000
56 17 8 ff0000
56 18 8 ff0000
56 19 8 ff0000
56 20 8 ff0000
56 21 8 ff0000
56 22 8 ff0000
56 23 8 ff0000
56 24 8 ff0000
56 25 8 ff0000
56 26 8 ff0000
56 27 8 ff0000
56 28 8 ff0000
56 29 8 ff0000
56 30 8 ff0000
56 31 8 ff0000
56 16 9 ff0000
56 17 9 ff0000
56 18 9 ff0000
56 19 9 ff0000
56 20 9 ff0000
56 21 9 ff0000
56 22 9 ff0000
56 23 9 ff0000
56 24 9 ff0000
56 25 9 ff0000
56 26 9 ff0000
56 27 9 ff0000
56 28 9 ff0000
56 29 9 ff0000
56 30 9 ff0000
56 31 9 ff0000
56 16 10 ffffff
56 17 10 ff0000
56 18 10 ff0000
56 19 10 ff0000
56 20 10 ff0000
56 21 10 ff0000
56 22 10 ff0000
56 23 10 ff0000
56 24 10 ff0000
56 25 10 ff0000
56 26 10 ff0000
56 27 10 ff0000
56 28 10 ff0000
56 29 10 ff0000
56 30 10 ff0000
56 31 10 ff0000
16 0 0 0000ff
17 0 0 0000ff
18 0 0 0000ff
19 0 0 0000ff
20 0 0 0000ff
21 0 0 0000ff
22 0 0 0000ff
23 0 0 0000ff
24 0 0 0000ff
25 0 0 0000ff
26 0 0 0000ff
27 0 0 0000ff
28 0 0 0000ff
29 0 0 0000ff
30 0 0 0000ff
31 0 0 0000ff
16 1 0 0000ff
17 1 0 0000ff
18 1 0 0000ff
19 1 0 0000ff
20 1 0 0000ff
21 1 0 0000ff
22 1 0 0000ff
23 1 0 0000ff
24 1 0 0000ff
25 1 0 0000ff
26 1 0 0000ff
27 1 0 0000ff
28 1 0 0000ff
29 1 0 0000ff
30 1 0 0000ff
31 1 0 0000ff
16 2 0 0000ff
17 2 0 0000ff
18 2 0 0000ff
19 2 0 0000ff
20 2 0 0000ff
21 2 0 0000ff
22 2 0 0000ff
23 2 0 0000ff
24 2 0 0000ff
25 2 0 0000ff
26 2 0 0000ff
27 2 0 0000ff
28 2 0 0000ff
29 2 0 0000ff
30 2 0 0000ff
31 2 0 0000ff
16 3 0 0000ff
17 3 0 0000ff
18 3 0 0000ff
19 3 0 0000ff
20 3 0 0000ff
21 3 0 0000ff
22 3 0 0000ff
23 3 0 0000ff
24 3 0 0000ff
25 3 0 0000ff
26 3 0 0000ff
27 3 0 0000ff
28 3 0 0000ff
29 3 0 0000ff
30 3 0 0000ff
31 3 0 0000ff
16 4 0 0000ff
17 4 0 0000ff
18 4 0 0000ff
19 4 0 0000ff
20 4 0 0000ff
21 4 0 0000ff
22 4 0 0000ff
23 4 0 0000ff
24 4 0 0000ff
25 4 0 0000ff
26 4 0 0000ff
27 4 0 0000ff
28 4 0 0000ff
29 4 0 0000ff
30 4 0 0000ff
31 4 0 0000ff
16 5 0 0000ff
17 5 0 0000ff
18 5 0 0000ff
19 5 0 0000ff
20 5 0 0000ff
21 5 0 0000ff
22 5 0 0000ff
23 5 0 0000ff
24 5 0 0000ff
25 5 0 0000ff
26 5 0 0000ff
27 5 0 0000ff
28 5 0 0000ff
29 5 0 0000ff
30 5 0 0000ff
31 5 0 0000ff
16 6 0 0000ff
17 6 0 0000ff
18 6 0 0000ff
19 6 0 0000ff
20 6 0 0000ff
21 6 0 0000ff
22 6 0 0000ff
23 6 0 0000ff
24 6 0 0000ff
25 6 0 0000ff
26 6 0 0000ff
27 6 0 0000ff
28 6 0 0000ff
29 6 0 0000ff
30 6 0 0000ff
31 6 0 0000ff
16 7 0 0000ff
17 7 0 0000ff
18 7 0 0000ff
19 7 0 0000ff
20 7 0 0000ff
21 7 0 0000ff
22 7 0 0000ff
23 7 0 0000ff
24 7 0 0000ff
25 7 0 0000ff
26 7 0 0000ff
27 7 0 0000ff
28 7 0 0000ff
29 7 0 0000ff
30 7 0 0000ff
31 7 0 0000ff
16 8 0 0000ff
17 8 0 0000ff
18 8 0 0000ff
19 8 0 0000ff
20 8 0 0000ff
21 8 0 0000ff
22 8 0 0000ff
23 8 0 0000ff
24 8 0 0000ff
25 8 0 0000ff
26 8 0 0000ff
27 8 0 0000ff
28 8 0 0000ff
29 8 0 0000ff
30 8 0 0000ff
31 8 0 0000ff
16 9 0 0000ff
17 9 0 0000ff
18 9 0 0000ff
19 9 0 0000ff
20 9 0 0000ff
21 9 0 0000ff
22 9 0 0000ff
23 9 0 0000ff
24 9 0 0000ff
25 9 0 0000ff
26 9 0 0000ff
27 9 0 0000ff
28 9 0 0000ff
29 9 0 0000ff
30 9 0 0000ff
31 9 0 0000ff
16 10 0 0000ff
17 10 0 0000ff
18 10 0 0000ff
19 10 0 0000ff
20 10 0 0000ff
21 10 0 0000ff
22 10 0 0000ff
23 10 0 0000ff
24 10 0 0000ff
25 10 0 0000ff
26 10 0 0000ff
27 10 0 0000ff
28 10 0 0000ff
29 10 0 0000ff
30 10 0 0000ff
31 10 0 0000ff
16 11 0 0000ff
17 11 0 0000ff
18 11 0 0000ff
19 11 0 0000ff
20 11 0 0000ff
21 11 0 0000ff
22 11 0 0000ff
23 11 0 0000ff
24 11 0 0000ff
25 11 0 0000ff
26 11 0 0000ff
27 11 0 0000ff
28 11 0 0000ff
29 11 0 0000ff
30 11 0 0000ff
31 11 0 0000ff
16 12 0 0000ff
17 12 0 0000ff
18 12 0 0000ff
19 12 0 0000ff
20 12 0 0000ff
21 12 0 0000ff
22 12 0 0000ff
23 12 0 0000ff
24 12 0 0000ff
25 12 0 0000ff
26 12 0 0000ff
27 12 0 0000ff
28 12 0 0000ff
29 12 0 0000ff
30 12 0 0000ff
31 12 0 0000ff
16 13 0 0000ff
17 13 0 0000ff
18 13 0 0000ff
19 13 0 0000ff
20 13 0 0000ff
21 13 0 0000ff
22 13 0 0000ff
23 13 0 0000ff
24 13 0 0000ff
25 13 0 0000ff
26 13 0 0000ff
27 13 0 0000ff
28 13 0 0000ff
29 13 0 0000ff
30 13 0 0000ff
31 13 0 0000ff
16 14 0 0000ff
17 14 0 0000ff
18 14 0 0000ff
19 14 0 0000ff
20 14 0 0000ff
21 14 0 0000ff
22 14 0 0000ff
23 14 0 0000ff
24 14 0 0000ff
25 14 0 0000ff
26 14 0 0000ff
27 14 0 0000ff
28 14 0 0000ff
29 14 0 0000ff
30 14 0 0000ff
31 14 0 0000ff
16 15 0 0000ff
17 15 0 0000ff
18 15 0 0000ff
19 15 0 0000ff
20 15 0 0000ff
21 15 0 0000ff
22 15 0 0000ff
23 15 0 0000ff
24 15 0 0000ff
25 15 0 0000ff
26 15 0 0000ff
27 15 0 0000ff
28 15 0 0000ff
29 15 0 0000ff
30 15 0 0000ff
31 15 0 0000ff
16 0 1 ff0000
17 0 1 ff0000
18 0 1 ff0000
19 0 1 ff0000
20 0 1 ff0000
21 0 1 ff0000
22 0 1 ff0000
23 0 1 ff0000
24 0 1 ff0000
25 0 1 ff0000
26 0 1 ff0000
27 0 1 ff0000
28 0 1 ff0000
29 0 1 ff0000
30 0 1 ff0000
31 0 1 ff0000
23 1 1 ff0000
23 2 1 ff0000
23 3 1 ff0000
23 4 1 ff0000
23 5 1 ff0000
23 6 1 ff0000
23 7 1 ff0000
23 8 1 ff0000
23 9 1 ff0000
23 10 1 ff0000
23 11 1 ff0000
23 12 1 ff0000
23 13 1 ff0000
16 0 2 ff0000
17 0 2 ff0000
18 0 2 ff0000
19 0 2 ff0000
20 0 2 ff0000
21 0 2 ff0000
22 0 2 ff0000
23 0 2 ff0000
24 0 2 ff0000
25 0 2 ff0000
26 0 2 ff0000
27 0 2 ff0000
28 0 2 ff0000
29 0 2 ff0000
30 0 2 ff0000
31 0 2 ff0000
23 1 2 ff0000
23 2 2 ff0000
23 3 2 ff0000
23 4 2 ff0000
23 5 2 ff0000
23 6 2 ff0000
23 7 2 ff0000
23 8 2 ff0000
23 9 2 ff0000
23 10 2 ff0000
23 11 2 ff0000
23 12 2 ff0000
23 13 2 ff0000
16 0 3 ff0000
17 0 3 ff0000
18 0 3 ff0000
19 0 3 ff0000
20 0 3 ff0000
21 0 3 ff0000
22 0 3 ff0000
23 0 3 ff0000
24 0 3 ff0000
25 0 3 ff0000
26 0 3 ff0000
27 0 3 ff0000
28 0 3 ff0000
29 0 3 ff0000
30 0 3 ff0000
31 0 3 ff0000
23 1 3 ff0000
23 2 3 ff0000
23 3 3 ff0000
23 4 3 ff0000
23 5 3 ff0000
23 6 3 ff0000
23 7 3 ff0000
23 8 3 ff0000
23 9 3 ff0000
23 10 3 ff0000
23 11 3 ff0000
23 12 3 ff0000
23 13 3 ff0000
16 0 4 ff0000
17 0 4 ff0000
18 0 4 ff0000
19 0 4 ff0000
20 0 4 ff0000
21 0 4 ff0000
22 0 4 ff0000
23 0 4 ff0000
24 0 4 ff0000
25 0 4 ff0000
26 0 4 ff0000
27 0 4 ff0000
28 0 4 ff0000
29 0 4 ff0000
30 0 4 ff0000
31 0 4 ff0000
23 1 4 ff0000
23 2 4 ff0000
23 3 4 ff0000
23 4 4 ff0000
23 5 4 ff0000
23 6 4 ff0000
23 7 4 ff0000
23 8 4 ff0000
23 9 4 ff0000
23 10 4 ff0000
23 11 4 ff0000
23 12 4 ff0000
23 13 4 ff0000
16 0 5 ff0000
17 0 5 ff0000
18 0 5 ff0000
19 0 5 ff0000
20 0 5 ff0000
21 0 5 ff0000
22 0 5 ff0000
23 0 5 ff0000
24 0 5 ff0000
25 0 5 ff0000
26 0 5 ff0000
27 0 5 ff0000
28 0 5 ff0000
29 0 5 ff0000
30 0 5 ff0000
31 0 5 ff0000
23 1 5 ff0000
23 2 5 ff0000
23 3 5 ff0000
23 4 5 ff0000
23 5 5 ff0000
23 6 5 ff0000
23 7 5 ff0000
23 8 5 ff0000
23 9 5 ff0000
23 10 5 ff0000
23 11 5 ff0000
23 12 5 ff0000
23 13 5 ff0000
16 0 6 ff0000
17 0 6 ff0000
18 0 6 ff0000
19 0 6 ff0000
20 0 6 ff0000
21 0 6 ff0000
22 0 6 ff0000
23 0 6 ff0000
24 0 6 ff0000
25 0 6 ff0000
26 0 6 ff0000
27 0 6 ff0000
28 0 6 ff0000
29 0 6 ff0000
30 0 6 ff0000
31 0 6 ff0000
23 1 6 ff0000
23 2 6 ff0000
23 3 6 ff0000
23 4 6 ff0000
23 5 6 ff0000
23 6 6 ff0000
23 7 6 ff0000
23 8 6 ff0000
23 9 6 ff0000
23 10 6 ff0000
23 11 6 ff0000
23 12 6 ff0000
23 13 6 ff0000
16 0 7 ff0000
17 0 7 ff0000
18 0 7 ff0000
19 0 7 ff0000
20 0 7 ff0000
21 0 7 ff0000
22 0 7 ff0000
23 0 7 ff0000
24 0 7 ff0000
25 0 7 ff0000
26 0 7 ff0000
27 0 7 ff0000
28 0 7 ff0000
29 0 7 ff0000
30 0 7 ff0000
31 0 7 ff0000
23 1 7 ff0000
23 2 7 ff0000
23 3 7 ff0000
23 4 7 ff0000
23 5 7 ff0000
23 6 7 ff0000
23 7 7 ff0000
23 8 7 ff0000
23 9 7 ff0000
23 10 7 ff0000
23 11 7 ff0000
23 12 7 ff0000
23 13 7 ff0000
23 14 7 ff0000
23 15 7 ff0000
16 0 8 ff0000
17 0 8 ff0000
18 0 8 ff0000
19 0 8 ff0000
20 0 8 ff0000
21 0 8 ff0000
22 0 8 ff0000
23 0 8 ff0000
24 0 8 ff0000
25 0 8 ff0000
26 0 8 ff0000
27 0 8 ff0000
28 0 8 ff0000
29 0 8 ff0000
30 0 8 ff0000
31 0 8 ff0000
23 1 8 ff0000
23 2 8 ff0000
23 3 8 ff0000
23 4 8 ff0000
23 5 8 ff0000
23 6 8 ff0000
23 7 8 ff0000
23 8 8 ff0000
23 9 8 ff0000
23 10 8 ff0000
23 11 8 ff0000
23 12 8 ff0000
23 13 8 ff0000
23 14 8 ff0000
23 15 8 ff0000
16 0 9 ff0000
17 0 9 ff0000
18 0 9 ff0000
19 0 9 ff0000
20 0 9 ff0000
21 0 9 ff0000
22 0 9 ff0000
23 0 9 ff0000
24 0 9 ff0000
25 0 9 ff0000
26 0 9 ff0000
27 0 9 ff0000
28 0 9 ff0000
29 0 9 ff0000
30 0 9 ff0000
31 0 9 ff0000
23 1 9 ff0000
23 2 9 ff0000
23 3 9 ff0000
23 4 9 ff0000
23 5 9 ff0000
23 6 9 ff0000
23 7 9 ff0000
23 8 9 ff0000
23 9 9 ff0000
23 10 9 ff0000
23 11 9 ff0000
23 12 9 ff0000
23 13 9 ff0000
23 14 9 ff0000
23 15 9 ff0000
16 0 10 ff0000
17 0 10 ff0000
18 0 10 ff0000
19 0 10 ff0000
20 0 10 ff0000
21 0 10 ff0000
22 0 10 ff0000
23 0 10 ff0000
24 0 10 ff0000
25 0 10 ff0000
26 0 10 ff0000
27 0 10 ff0000
28 0 10 ff0000
29 0 10 ff0000
30 0 10 ff0000
31 0 10 ff0000
23 1 10 ff0000
23 2 10 ff0000
23 3 10 ff0000
23 4 10 ff0000
23 5 10 ff0000
23 6 10 ff0000
23 7 10 ff0000
23 8 10 ff0000
23 9 10 ff0000
23 10 10 ff0000
23 11 10 ff0000
23 12 10 ff0000
23 13 10 ff0000
23 14 10 ff0000
23 15 10 ff0000
16 16 0 0000ff
17 16 0 0000ff
18 16 0 0000ff
19 16 0 0000ff
20 16 0 0000ff
21 16 0 0000ff
22 16 0 0000ff
23 16 0 0000ff
24 16 0 0000ff
25 16 0 0000ff
26 16 0 0000ff
27 16 0 0000ff
28 16 0 0000ff
29 16 0 0000ff
30 16 0 0000ff
31 16 0 0000ff
16 17 0 0000ff
17 17 0 0000ff
18 17 0 0000ff
19 17 0 0000ff
20 17 0 0000ff
21 17 0 0000ff
22 17 0 0000ff
23 17 0 0000ff
24 17 0 0000ff
25 17 0 0000ff
26 17 0 0000ff
27 17 0 0000ff
28 17 0 0000ff
29 17 0 0000ff
30 17 0 0000ff
31 17 0 0000ff
16 18 0 0000ff
17 18 0 0000ff
18 18 0 0000ff
19 18 0 0000ff
20 18 0 0000ff
21 18 0 0000ff
22 18 0 0000ff
23 18 0 0000ff
24 18 0 0000ff
25 18 0 0000ff
26 18 0 0000ff
27 18 0 0000ff
28 18 0 0000ff
29 18 0 0000ff
30 18 0 0000ff
31 18 0 0000ff
16 19 0 0000ff
17 19 0 0000ff
18 19 0 0000ff
19 19 0 0000ff
20 19 0 0000ff
21 19 0 0000ff
22 19 0 0000ff
23 19 0 0000ff
24 19 0 0000ff
25 19 0 0000ff
26 19 0 0000ff
27 19 0 0000ff
28 19 0 0000ff
29 19 0 0000ff
30 19 0 0000ff
31 19 0 0000ff
16 20 0 0000ff
17 20 0 0000ff
18 20 0 0000ff
19 20 0 0000ff
20 20 0 0000ff
21 20 0 0000ff
22 20 0 0000ff
23 20 0 0000ff
24 20 0 0000ff
25 20 0 0000ff
26 20 0 0000ff
27 20 0 0000ff
28 20 0 0000ff
29 20 0 0000ff
30 20 0 0000ff
31 20 0 0000ff
16 21 0 0000ff
17 21 0 0000ff
18 21 0 0000ff
19 21 0 0000ff
20 21 0 0000ff
21 21 0 0000ff
22 21 0 0000ff
23 21 0 0000ff
24 21 0 0000ff
25 21 0 0000ff
26 21 0 0000ff
27 21 0 0000ff
28 21 0 0000ff
29 21 0 0000ff
30 21 0 0000ff
31 21 0 0000ff
16 22 0 0000ff
17 22 0 0000ff
18 22 0 0000ff
19 22 0 0000ff
20 22 0 0000ff
21 22 0 0000ff
22 22 0 0000ff
23 22 0 0000ff
24 22 0 0000ff
25 22 0 0000ff
26 22 0 0000ff
27 22 0 0000ff
28 22 0 0000ff
29 22 0 0000ff
30 22 0 0000ff
31 22 0 0000ff
16 23 0 0000ff
17 23 0 0000ff
18 23 0 0000ff
19 23 0 0000ff
20 23 0 0000ff
21 23 0 0000ff
22 23 0 0000ff
23 23 0 0000ff
24 23 0 0000ff
25 23 0 0000ff
26 23 0 0000ff
27 23 0 0000ff
28 23 0 0000ff
29 23 0 0000ff
30 23 0 0000ff
31 23 0 0000ff
16 24 0 0000ff
17 24 0 0000ff
18 24 0 0000ff
19 24 0 0000ff
20 24 0 0000ff
21 24 0 0000ff
22 24 0 0000ff
23 24 0 0000ff
24 24 0 0000ff
25 24 0 0000ff
26 24 0 0000ff
27 24 0 0000ff
28 24 0 0000ff
29 24 0 0000ff
30 24 0 0000ff
31 24 0 0000ff
16 25 0 0000ff
17 25 0 0000ff
18 25 0 0000ff
19 25 0 0000ff
20 25 0 0000ff
21 25 0 0000ff
22 25 0 0000ff
23 25 0 0000ff
24 25 0 0000ff
25 25 0 0000ff
26 25 0 0000ff
27 25 0 0000ff
28 25 0 0000ff
29 25 0 0000ff
30 25 0 0000ff
31 25 0 0000ff
16 26 0 0000ff
17 26 0 0000ff
18 26 0 0000ff
19 26 0 0000ff
20 26 0 0000ff
21 26 0 0000ff
22 26 0 0000ff
23 26 0 0000ff
24 26 0 0000ff
25 26 0 0000ff
26 26 0 0000ff
27 26 0 0000ff
28 26 0 0000ff
29 26 0 0000ff
30 26 0 0000ff
31 26 0 0000ff
16 27 0 0000ff
17 27 0 0000ff
18 27 0 0000ff
19 27 0 0000ff
20 27 0 0000ff
21 27 0 0000ff
22 27 0 0000ff
23 27 0 0000ff
24 27 0 0000ff
25 27 0 0000ff
26 27 0 0000ff
27 27 0 0000ff
28 27 0 0000ff
29 27 0 0000ff
30 27 0 0000ff
31 27 0 0000ff
16 28 0 0000ff
17 28 0 0000ff
18 28 0 0000ff
19 28 0 0000ff
20 28 0 0000ff
21 28 0 0000ff
22 28 0 0000ff
23 28 0 0000ff
24 28 0 0000ff
25 28 0 0000ff
26 28 0 0000ff
27 28 0 0000ff
28 28 0 0000ff
29 28 0 0000ff
30 28 0 0000ff
31 28 0 0000ff
16 29 0 0000ff
17 29 0 0000ff
18 29 0 0000ff
19 29 0 0000ff
20 29 0 0000ff
21 29 0 0000ff
22 29 0 0000ff
23 29 0 0000ff
24 29 0 0000ff
25 29 0 0000ff
26 29 0 0000ff
27 29 0 0000ff
28 29 0 0000ff
29 29 0 0000ff
30 29 0 0000ff
31 29 0 0000ff
16 30 0 0000ff
17 30 0 0000ff
18 30 0 0000ff
19 30 0 0000ff
20 30 0 0000ff
21 30 0 0000ff
22 30 0 0000ff
23 30 0 0000ff
24 30 0 0000ff
25 30 0 0000ff
26 30 0 0000ff
27 30 0 0000ff
28 30 0 0000ff
29 30 0 0000ff
30 30 0 0000ff
31 30 0 0000ff
16 31 0 0000ff
17 31 0 0000ff
18 31 0 0000ff
19 31 0 0000ff
20 31 0 0000ff
21 31 0 0000ff
22 31 0 0000ff
23 31 0 0000ff
24 31 0 0000ff
25 31 0 0000ff
26 31 0 0000ff
27 31 0 0000ff
28 31 0 0000ff
29 31 0 0000ff
30 31 0 0000ff
31 31 0 0000ff
23 17 1 ff0000
23 18 1 ff0000
23 19 1 ff0000
23 20 1 ff0000
23 21 1 ff0000
23 22 1 ff0000
23 23 1 ff0000
23 24 1 ff0000
23 25 1 ff0000
23 26 1 ff0000
23 27 1 ff0000
23 28 1 ff0000
23 29 1 ff0000
23 30 1 ff0000
23 31 1 ff0000
23 17 2 ff0000
23 18 2 ff0000
23 19 2 ff0000
23 20 2 ff0000
23 21 2 ff0000
23 22 2 ff0000
23 23 2 ff0000
23 24 2 ff0000
23 25 2 ff0000
23 26 2 ff0000
23 27 2 ff0000
23 28 2 ff0000
23 29 2 ff0000
23 30 2 ff0000
23 31 2 ff0000
23 17 3 ff0000
23 18 3 ff0000
23 19 3 ff0000
23 20 3 ff0000
23 21 3 ff0000
23 22 3 ff0000
23 23 3 ff0000
23 24 3 ff0000
23 25 3 ff0000
23 26 3 ff0000
23 27 3 ff0000
23 28 3 ff0000
23 29 3 ff0000
23 30 3 ff0000
23 31 3 ff0000
23 17 4 ff0000
23 18 4 ff0000
23 19 4 ff0000
23 20 4 ff0000
23 21 4 ff0000
23 22 4 ff0000
23 23 4 ff0000
23 24 4 ff0000
23 25 4 ff0000
23 26 4 ff0000
23 27 4 ff0000
23 28 4 ff0000
23 29 4 ff0000
23 30 4 ff0000
23 31 4 ff0000
23 17 5 ff0000
23 18 5 ff0000
23 19 5 ff0000
23 20 5 ff0000
23 21 5 ff0000
23 22 5 ff0000
23 23 5 ff0000
23 24 5 ff0000
23 25 5 ff0000
23 26 5 ff0000
23 27 5 ff0000
23 28 5 ff0000
23 29 5 ff0000
23 30 5 ff0000
23 31 5 ff0000
23 17 6 ff0000
23 18 6 ff0000
23 19 6 ff0000
23 20 6 ff0000
23 21 6 ff0000
23 22 6 ff0000
23 23 6 ff0000
23 24 6 ff0000
23 25 6 ff0000
23 26 6 ff0000
23 27 6 ff0000
23 28 6 ff0000
23 29 6 ff0000
23 30 6 ff0000
23 31 6 ff0000
23 16 7 ff0000
23 17 7 ff0000
23 18 7 ff0000
23 19 7 ff0000
23 20 7 ff0000
23 21 7 ff0000
23 22 7 ff0000
23 23 7 ff0000
23 24 7 ff0000
23 25 7 ff0000
23 26 7 ff0000
23 27 7 ff0000
23 28 7 ff0000
23 29 7 ff0000
23 30 7 ff0000
23 31 7 ff0000
23 16 8 ff0000
23 17 8 ff0000
23 18 8 ff0000
23 19 8 ff0000
23 20 8 ff0000
23 21 8 ff0000
23 22 8 ff0000
23 23 8 ff0000
23 24 8 ff0000
23 25 8 ff0000
23 26 8 ff0000
23 27 8 ff0000
23 28 8 ff0000
23 29 8 ff0000
23 30 8 ff0000
23 31 8 ff0000
23 16 9 ff0000
23 17 9 ff0000
23 18 9 ff0000
23 19 9 ff0000
23 20 9 ff0000
23 21 9 ff0000
23 22 9 ff0000
23 23 9 ff0000
23 24 9 ff0000
23 25 9 ff0000
23 26 9 ff0000
23 27 9 ff0000
23 28 9 ff0000
23 29 9 ff0000
23 30 9 ff0000
23 31 9 ff0000
23 16 10 ff0000
23 17 10 ff0000
23 18 10 ff0000
23 19 10 ff0000
23 20 10 ff0000
23 21 10 ff0000
23 22 10 ff0000
23 23 10 ff0000
23 24 10 ff0000
23 25 10 ff0000
23 26 10 ff0000
23 27 10 ff0000
23 28 10 ff0000
23 29 10 ff0000
23 30 10 ff0000
23 31 10 ff0000
0 32 0 0000ff
1 32 0 0000ff
2 32 0 0000ff
3 32 0 0000ff
4 32 0 0000ff
5 32 0 0000ff
6 32 0 0000ff
7 32 0 0000ff
8 32 0 0000ff
9 32 0 0000ff
10 32 0 0000ff
11 32 0 0000ff
12 32 0 0000ff
13 32 0 0000ff
14 32 0 0000ff
15 32 0 0000ff
0 33 0 0000ff
1 33 0 0000ff
2 33 0 0000ff
3 33 0 0000ff
4 33 0 0000ff
5 33 0 0000ff
6 33 0 0000ff
7 33 0 0000ff
8 33 0 0000ff
9 33 0 0000ff
10 33 0 0000ff
11 33 0 0000ff
12 33 0 0000ff
13 33 0 0000ff
14 33 0 0000ff
15 33 0 0000ff
0 34 0 0000ff
1 34 0 0000ff
2 34 0 0000ff
3 34 0 0000ff
4 34 0 0000ff
5 34 0 0000ff
6 34 0 0000ff
7 34 0 0000ff
8 34 0 0000ff
9 34 0 0000ff
10 34 0 0000ff
11 34 0 0000ff
12 34 0 0000ff
13 34 0 0000ff
14 34 0 0000ff
15 34 0 0000ff
0 35 0 0000ff
1 35 0 0000ff
2 35 0 0000ff
3 35 0 0000ff
4 35 0 0000ff
5 35 0 0000ff
6 35 0 0000ff
7 35 0 0000ff
8 35 0 0000ff
9 35 0 0000ff
10 35 0 0000ff
11 35 0 0000ff
12 35 0 0000ff
13 35 0 0000ff
14 35 0 0000ff
15 35 0 0000ff
0 36 0 0000ff
1 36 0 0000ff
2 36 0 0000ff
3 36 0 0000ff
4 36 0 0000ff
5 36 0 0000ff
6 36 0 0000ff
7 36 0 0000ff
8 36 0 0000ff
9 36 0 0000ff
10 36 0 0000ff
11 36 0 0000ff
12 36 0 0000ff
13 36 0 0000ff
14 36 0 0000ff
15 36 0 0000ff
0 37 0 0000ff
1 37 0 0000ff
2 37 0 0000ff
3 37 0 0000ff
4 37 0 0000ff
5 37 0 0000ff
6 37 0 0000ff
7 37 0 0000ff
8 37 0 0000ff
9 37 0 0000ff
10 37 0 0000ff
11 37 0 0000ff
12 37 0 0000ff
13 37 0 0000ff
14 37 0 0000ff
15 37 0 0000ff
0 38 0 0000ff
1 38 0 0000ff
2 38 0 0000ff
3 38 0 0000ff
4 38 0 0000ff
5 38 0 0000ff
6 38 0 0000ff
7 38 0 0000ff
8 38 0 0000ff
9 38 0 0000ff
10 38 0 0000ff
11 38 0 0000ff
12 38 0 0000ff
13 38 0 0000ff
14 38 0 0000ff
15 38 0 0000ff
0 39 0 0000ff
1 39 0 0000ff
2 39 0 0000ff
3 39 0 0000ff
4 39 0 0000ff
5 39 0 0000ff
6 39 0 0000ff
7 39 0 0000ff
8 39 0 0000ff
9 39 0 0000ff
10 39 0 0000ff
11 39 0 0000ff
12 39 0 0000ff
13 39 0 0000ff
14 39 0 0000ff
15 39 0 0000ff
0 40 0 0000ff
1 40 0 0000ff
2 40 0 0000ff
3 40 0 0000ff
4 40 0 0000ff
5 40 0 0000ff
6 40 0 0000ff
7 40 0 0000ff
8 40 0 0000ff
9 40 0 0000ff
10 40 0 0000ff
11 40 0 0000ff
12 40 0 0000ff
13 40 0 0000ff
14 40 0 0000ff
15 40 0 0000ff
0 41 0 0000ff
1 41 0 0000ff
2 41 0 0000ff
3 41 0 0000ff
4 41 0 0000ff
5 41 0 0000ff
6 41 0 0000ff
7 41 0 0000ff
8 41 0 0000ff
9 41 0 0000ff
10 41 0 0000ff
11 41 0 0000ff
12 41 0 0000ff
13 41 0 0000ff
14 41 0 0000ff
15 41 0 0000ff
0 42 0 0000ff
1 42 0 0000ff
2 42 0 0000ff
3 42 0 0000ff
4 42 0 0000ff
5 42 0 0000ff
6 42 0 0000ff
7 42 0 0000ff
8 42 0 0000ff
9 42 0 0000ff
10 42 0 0000ff
11 42 0 0000ff
12 42 0 0000ff
13 42 0 0000ff
14 42 0 0000ff
15 42 0 0000ff
0 43 0 0000ff
1 43 0 0000ff
2 43 0 0000ff
3 43 0 0000ff
4 43 0 0000ff
5 43 0 0000ff
6 43 0 0000ff
7 43 0 0000ff
8 43 0 0000ff
9 43 0 0000ff
10 43 0 0000ff
11 43 0 0000ff
12 43 0 0000ff
13 43 0 0000ff
14 43 0 0000ff
15 43 0 0000ff
0 44 0 0000ff
1 44 0 0000ff
2 44 0 0000ff
3 44 0 0000ff
4 44 0 0000ff
5 44 0 0000ff
6 44 0 0000ff
7 44 0 0000ff
8 44 0 0000ff
9 44 0 0000ff
10 44 0 0000ff
11 44 0 0000ff
12 44 0 0000ff
13 44 0 0000ff
14 44 0 0000ff
15 44 0 0000ff
0 45 0 0000ff
1 45 0 0000ff
2 45 0 0000ff
3 45 0 0000ff
4 45 0 0000ff
5 45 0 0000ff
6 45 0 0000ff
7 45 0 0000ff
8 45 0 0000ff
9 45 0 0000ff
10 45 0 0000ff
11 45 0 0000ff
12 45 0 0000ff
13 45 0 0000ff
14 45 0 0000ff
15 45 0 0000ff
0 46 0 0000ff
1 46 0 0000ff
2 46 0 0000ff
3 46 0 0000ff
4 46 0 0000ff
5 46 0 0000ff
6 46 0 0000ff
7 46 0 0000ff
8 46 0 0000ff
9 46 0 0000ff
10 46 0 0000ff
11 46 0 0000ff
12 46 0 0000ff
13 46 0 0000ff
14 46 0 0000ff
15 46 0 0000ff
0 47 0 0000ff
1 47 0 0000ff
2 47 0 0000ff
3 47 0 0000ff
4 47 0 0000ff
5 47 0 0000ff
6 47 0 0000ff
7 47 0 0000ff
8 47 0 0000ff
9 47 0 0000ff
10 47 0 0000ff
11 47 0 0000ff
12 47 0 0000ff
13 47 0 0000ff
14 47 0 0000ff
15 47 0 0000ff
0 32 1 ff0000
1 32 1 ff0000
2 32 1 ff0000
3 32 1 ff0000
4 32 1 ff0000
5 32 1 ff0000
6 32 1 ff0000
7 32 1 ff0000
8 32 1 ff0000
9 32 1 ff0000
10 32 1 ff0000
11 32 1 ff0000
12 32 1 ff0000
13 32 1 ff0000
14 32 1 ff0000
15 32 1 ff0000
0 33 1 ff0000
0 34 1 ff0000
0 35 1 ff0000
0 36 1 ff0000
0 37 1 ff0000
0 38 1 ff0000
0 39 1 ff0000
0 40 1 ff0000
0 41 1 ff0000
0 42 1 ff0000
0 43 1 ff0000
0 44 1 ff0000
0 45 1 ff0000
0 46 1 ff0000
0 47 1 ff0000
1 47 1 ff0000
2 47 1 ff0000
3 47 1 ff0000
4 47 1 ff0000
5 47 1 ff0000
6 47 1 ff0000
7 47 1 ff0000
8 47 1 ff0000
9 47 1 ff0000
10 47 1 ff0000
11 47 1 ff0000
15 47 1 ff0000
0 32 2 ff0000
1 32 2 ff0000
2 32 2 ff0000
3 32 2 ff0000
4 32 2 ff0000
5 32 2 ff0000
6 32 2 ff0000
7 32 2 ff0000
8 32 2 ff0000
9 32 2 ff0000
10 32 2 ff0000
11 32 2 ff0000
12 32 2 ff0000
13 32 2 ff0000
14 32 2 ff0000
15 32 2 ff0000
0 33 2 ff0000
0 34 2 ff0000
0 35 2 ff0000
0 36 2 ff0000
0 37 2 ff0000
0 38 2 ff0000
0 39 2 ff0000
0 40 2 ff0000
0 41 2 ff0000
0 42 2 ff0000
0 43 2 ff0000
0 44 2 ff0000
0 45 2 ff0000
0 46 2 ff0000
0 47 2 ff0000
1 47 2 ff0000
2 47 2 ff0000
3 47 2 ff0000
4 47 2 ff0000
5 47 2 ff0000
6 47 2 ff0000
7 47 2 ff0000
8 47 2 ff0000
9 47 2 ff0000
10 47 2 ff0000
11 47 2 ff0000
15 47 2 ff0000
0 32 3 ff0000
1 32 3 ff0000
2 32 3 ff0000
3 32 3 ff0000
4 32 3 ff0000
5 32 3 ff0000
6 32 3 ff0000
7 32 3 ff0000
8 32 3 ff0000
9 32 3 ff0000
10 32 3 ff0000
11 32 3 ff0000
12 32 3 ff0000
13 32 3 ff0000
14 32 3 ff0000
15 32 3 ff0000
0 33 3 ff0000
0 34 3 ff0000
0 35 3 ff0000
0 36 3 ff0000
0 37 3 ff0000
0 38 3 ff0000
0 39 3 ff0000
0 40 3 ff0000
0 41 3 ff0000
0 42 3 ff0000
0 43 3 ff0000
0 44 3 ff0000
0 45 3 ff0000
0 46 3 ff0000
0 47 3 ff0000
1 47 3 ff0000
2 47 3 ff0000
3 47 3 ff0000
4 47 3 ff0000
5 47 3 ff0000
6 47 3 ff0000
7 47 3 ff0000
8 47 3 ff0000
9 47 3 ff0000
10 47 3 ff0000
11 47 3 ff0000
15 47 3 ff0000
0 32 4 ff0000
1 32 4 ff0000
2 32 4 ff0000
3 32 4 ff0000
4 32 4 ff0000
5 32 4 ff0000
6 32 4 ff0000
7 32 4 ff0000
8 32 4 ff0000
9 32 4 ff0000
10 32 4 ff0000
11 32 4 ff0000
12 32 4 ff0000
13 32 4 ff0000
14 32 4 ff0000
15 32 4 ff0000
0 33 4 ff0000
0 34 4 ff0000
0 38 4 ff0000
0 39 4 ff0000
0 40 4 ff0000
0 41 4 ff0000
0 45 4 ff0000
0 46 4 ff0000
0 47 4 ff0000
1 47 4 ff0000
2 47 4 ff0000
3 47 4 ff0000
4 47 4 ff0000
8 47 4 ff0000
9 47 4 ff0000
10 47 4 ff0000
11 47 4 ff0000
15 47 4 ff0000
0 32 5 ff0000
1 32 5 ff0000
2 32 5 ff0000
3 32 5 ff0000
4 32 5 ff0000
5 32 5 ff0000
6 32 5 ff0000
7 32 5 ff0000
8 32 5 ff0000
9 32 5 ff0000
10 32 5 ff0000
11 32 5 ff0000
12 32 5 ff0000
13 32 5 ff0000
14 32 5 ff0000
15 32 5 ff0000
0 33 5 ff0000
0 34 5 ff0000
0 38 5 ff0000
0 39 5 ff0000
0 40 5 ff0000
0 41 5 ff0000
0 45 5 ff0000
0 46 5 ff0000
0 47 5 ff0000
1 47 5 ff0000
2 47 5 ff0000
3 47 5 ff0000
4 47 5 ff0000
8 47 5 ff0000
9 47 5 ff0000
10 47 5 ff0000
11 47 5 ff0000
12 47 5 ff0000
13 47 5 ff0000
14 47 5 ff0000
15 47 5 ff0000
0 32 6 ff0000
1 32 6 ff0000
2 32 6 ff0000
3 32 6 ff0000
4 32 6 ff0000
5 32 6 ff0000
6 32 6 ff0000
7 32 6 ff0000
8 32 6 ff0000
9 32 6 ff0000
10 32 6 ff0000
11 32 6 ff0000
12 32 6 ff0000
13 32 6 ff0000
14 32 6 ff0000
15 32 6 ff0000
0 33 6 ff0000
0 34 6 ff0000
0 38 6 ff0000
0 39 6 ff0000
0 40 6 ff0000
0 41 6 ff0000
0 45 6 ff0000
0 46 6 ff0000
0 47 6 ff0000
1 47 6 ff0000
2 47 6 ff0000
3 47 6 ff0000
4 47 6 ff0000
8 47 6 ff0000
9 47 6 ff0000
10 47 6 ff0000
11 47 6 ff0000
12 47 6 ff0000
13 47 6 ff0000
14 47 6 ff0000
15 47 6 ff0000
0 32 7 ff0000
1 32 7 ff0000
2 32 7 ff0000
3 32 7 ff0000
4 32 7 ff0000
5 32 7 ff0000
6 32 7 ff0000
7 32 7 ff0000
8 32 7 ff0000
9 32 7 ff0000
10 32 7 ff0000
11 32 7 ff0000
12 32 7 ff0000
13 32 7 ff0000
14 32 7 ff0000
15 32 7 ff0000
0 33 7 ff0000
0 34 7 ff0000
0 38 7 ff0000
0 39 7 ff0000
0 40 7 ff0000
0 41 7 ff0000
0 45 7 ff0000
0 46 7 ff0000
0 47 7 ff0000
1 47 7 ff0000
2 47 7 ff0000
3 47 7 ff0000
4 47 7 ff0000
5 47 7 ff0000
6 47 7 ff0000
7 47 7 ff0000
8 47 7 ff0000
9 47 7 ff0000
10 47 7 ff0000
11 47 7 ff0000
12 47 7 ff0000
13 47 7 ff0000
14 47 7 ff0000
15 47 7 ff0000
0 32 8 ff0000
1 32 8 ff0000
2 32 8 ff0000
3 32 8 ff0000
4 32 8 ff0000
5 32 8 ff0000
6 32 8 ff0000
7 32 8 ff0000
8 32 8 ff0000
9 32 8 ff0000
10 32 8 ff0000
11 32 8 ff0000
12 32 8 ff0000
13 32 8 ff0000
14 32 8 ff0000
15 32 8 ff0000
0 33 8 ff0000
0 34 8 ff0000
0 35 8 ff0000
0 36 8 ff0000
0 37 8 ff0000
0 38 8 ff0000
0 39 8 ff0000
0 40 8 ff0000
0 41 8 ff0000
0 42 8 ff0000
0 43 8 ff0000
0 44 8 ff0000
0 45 8 ff0000
0 46 8 ff0000
0 47 8 ff0000
1 47 8 ff0000
2 47 8 ff0000
3 47 8 ff0000
4 47 8 ff0000
5 47 8 ff0000
6 47 8 ff0000
7 47 8 ff0000
8 47 8 ff0000
9 47 8 ff0000
10 47 8 ff0000
11 47 8 ff0000
12 47 8 ff0000
13 47 8 ff0000
14 47 8 ff0000
15 47 8 ff0000
0 32 9 ff0000
1 32 9 ff0000
2 32 9 ff0000
3 32 9 ff0000
4 32 9 ff0000
5 32 9 ff0000
6 32 9 ff0000
7 32 9 ff0000
8 32 9 ff0000
9 32 9 ff0000
10 32 9 ff0000
11 32 9 ff0000
12 32 9 ff0000
13 32 9 ff0000
14 32 9 ff0000
15 32 9 ff0000
0 33 9 ff0000
0 34 9 ff0000
0 35 9 ff0000
0 36 9 ff0000
0 37 9 ff0000
0 38 9 ff0000
0 39 9 ff0000
0 40 9 ff0000
0 41 9 ff0000
0 42 9 ff0000
0 43 9 ff0000
0 44 9 ff0000
0 45 9 ff0000
0 46 9 ff0000
0 47 9 ff0000
1 47 9 ff0000
2 47 9 ff0000
3 47 9 ff0000
4 47 9 ff0000
5 47 9 ff0000
6 47 9 ff0000
7 47 9 ff0000
8 47 9 ff0000
9 47 9 ff0000
10 47 9 ff0000
11 47 9 ff0000
12 47 9 ff0000
13 47 9 ff0000
14 47 9 ff0000
15 47 9 ff0000
0 32 10 ff0000
1 32 10 ff0000
2 32 10 ff0000
3 32 10 ff0000
4 32 10 ff0000
5 32 10 ff0000
6 32 10 ff0000
7 32 10 ff0000
8 32 10 ff0000
9 32 10 ff0000
10 32 10 ff0000
11 32 10 ff0000
12 32 10 ff0000
13 32 10 ff0000
14 32 10 ff0000
15 32 10 ff0000
0 33 10 ff0000
0 34 10 ff0000
0 35 10 ff0000
0 36 10 ff0000
0 37 10 ff0000
0 38 10 ff0000
0 39 10 ff0000
0 40 10 ff0000
0 41 10 ff0000
0 42 10 ff0000
0 43 10 ff0000
0 44 10 ff0000
0 45 10 ff0000
0 46 10 ff0000
0 47 10 ff0000
1 47 10 ff0000
2 47 10 ff0000
3 47 10 ff0000
4 47 10 ff0000
5 47 10 ff0000
6 47 10 ff0000
7 47 10 ff0000
8 47 10 ff0000
9 47 10 ff0000
10 47 10 ff0000
11 47 10 ff0000
12 47 10 ff0000
13 47 10 ff0000
14 47 10 ff0000
15 47 10 ff0000
0 0 0 0000ff
1 0 0 0000ff
2 0 0 0000ff
3 0 0 0000ff
4 0 0 0000ff
5 0 0 0000ff
6 0 0 0000ff
7 0 0 0000ff
8 0 0 0000ff
9 0 0 0000ff
10 0 0 0000ff
11 0 0 0000ff
12 0 0 0000ff
13 0 0 0000ff
14 0 0 0000ff
15 0 0 0000ff
0 1 0 0000ff
1 1 0 0000ff
2 1 0 0000ff
3 1 0 0000ff
4 1 0 0000ff
5 1 0 0000ff
6 1 0 0000ff
7 1 0 0000ff
8 1 0 0000ff
9 1 0 0000ff
10 1 0 0000ff
11 1 0 0000ff
12 1 0 0000ff
13 1 0 0000ff
14 1 0 0000ff
15 1 0 0000ff
0 2 0 0000ff
1 2 0 0000ff
2 2 0 0000ff
3 2 0 0000ff
4 2 0 0000ff
5 2 0 0000ff
6 2 0 0000ff
7 2 0 0000ff
8 2 0 0000ff
9 2 0 0000ff
10 2 0 0000ff
11 2 0 0000ff
12 2 0 0000ff
13 2 0 0000ff
14 2 0 0000ff
15 2 0 0000ff
0 3 0 0000ff
1 3 0 0000ff
2 3 0 0000ff
3 3 0 0000ff
4 3 0 0000ff
5 3 0 0000ff
6 3 0 0000ff
7 3 0 0000ff
8 3 0 0000ff
9 3 0 0000ff
10 3 0 0000ff
11 3 0 0000ff
12 3 0 0000ff
13 3 0 0000ff
14 3 0 0000ff
15 3 0 0000ff
0 4 0 0000ff
1 4 0 0000ff
2 4 0 0000ff
3 4 0 0000ff
4 4 0 0000ff
5 4 0 0000ff
6 4 0 0000ff
7 4 0 0000ff
8 4 0 0000ff
9 4 0 0000ff
10 4 0 0000ff
11 4 0 0000ff
12 4 0 0000ff
13 4 0 0000ff
14 4 0 0000ff
15 4 0 0000ff
0 5 0 0000ff
1 5 0 0000ff
2 5 0 0000ff
3 5 0 0000ff
4 5 0 0000ff
5 5 0 0000ff
6 5 0 0000ff
7 5 0 0000ff
8 5 0 0000ff
9 5 0 0000ff
10 5 0 0000ff
11 5 0 0000ff
12 5 0 0000ff
13 5 0 0000ff
14 5 0 0000ff
15 5 0 0000ff
0 6 0 0000ff
1 6 0 0000ff
2 6 0 0000ff
3 6 0 0000ff
4 6 0 0000ff
5 6 0 0000ff
6 6 0 0000ff
7 6 0 0000ff
8 6 0 0000ff
9 6 0 0000ff
10 6 0 0000ff
11 6 0 0000ff
12 6 0 0000ff
13 6 0 0000ff
14 6 0 0000ff
15 6 0 0000ff
0 7 0 0000ff
1 7 0 0000ff
2 7 0 0000ff
3 7 0 0000ff
4 7 0 0000ff
5 7 0 0000ff
6 7 0 0000ff
7 7 0 0000ff
8 7 0 0000ff
9 7 0 0000ff
10 7 0 0000ff
11 7 0 0000ff
12 7 0 0000ff
13 7 0 0000ff
14 7 0 0000ff
15 7 0 0000ff
0 8 0 0000ff
1 8 0 0000ff
2 8 0 0000ff
3 8 0 0000ff
4 8 0 0000ff
5 8 0 0000ff
6 8 0 0000ff
7 8 0 0000ff
8 8 0 0000ff
9 8 0 0000ff
10 8 0 0000ff
11 8 0 0000ff
12 8 0 0000ff
13 8 0 0000ff
14 8 0 0000ff
15 8 0 0000ff
0 9 0 0000ff
1 9 0 0000ff
2 9 0 0000ff
3 9 0 0000ff
4 9 0 0000ff
5 9 0 0000ff
6 9 0 0000ff
7 9 0 0000ff
8 9 0 0000ff
9 9 0 0000ff
10 9 0 0000ff
11 9 0 0000ff
12 9 0 0000ff
13 9 0 0000ff
14 9 0 0000ff
15 9 0 0000ff
0 10 0 0000ff
1 10 0 0000ff
2 10 0 0000ff
3 10 0 0000ff
4 10 0 0000ff
5 10 0 0000ff
6 10 0 0000ff
7 10 0 0000ff
8 10 0 0000ff
9 10 0 0000ff
10 10 0 0000ff
11 10 0 0000ff
12 10 0 0000ff
13 10 0 0000ff
14 10 0 0000ff
15 10 0 0000ff
0 11 0 0000ff
1 11 0 0000ff
2 11 0 0000ff
3 11 0 0000ff
4 11 0 0000ff
5 11 0 0000ff
6 11 0 0000ff
7 11 0 0000ff
8 11 0 0000ff
9 11 0 0000ff
10 11 0 0000ff
11 11 0 0000ff
12 11 0 0000ff
13 11 0 0000ff
14 11 0 0000ff
15 11 0 0000ff
0 12 0 0000ff
1 12 0 0000ff
2 12 0 0000ff
3 12 0 0000ff
4 12 0 0000ff
5 12 0 0000ff
6 12 0 0000ff
7 12 0 0000ff
8 12 0 0000ff
9 12 0 0000ff
10 12 0 0000ff
11 12 0 0000ff
12 12 0 0000ff
13 12 0 0000ff
14 12 0 0000ff
15 12 0 0000ff
0 13 0 0000ff
1 13 0 0000ff
2 13 0 0000ff
3 13 0 0000ff
4 13 0 0000ff
5 13 0 0000ff
6 13 0 0000ff
7 13 0 0000ff
8 13 0 0000ff
9 13 0 0000ff
10 13 0 0000ff
11 13 0 0000ff
12 13 0 0000ff
13 13 0 0000ff
14 13 0 0000ff
15 13 0 0000ff
0 14 0 0000ff
1 14 0 0000ff
2 14 0 0000ff
3 14 0 0000ff
4 14 0 0000ff
5 14 0 0000ff
6 14 0 0000ff
7 14 0 0000ff
8 14 0 0000ff
9 14 0 0000ff
10 14 0 0000ff
11 14 0 0000ff
12 14 0 0000ff
13 14 0 0000ff
14 14 0 0000ff
15 14 0 0000ff
0 15 0 0000ff
1 15 0 0000ff
2 15 0 0000ff
3 15 0 0000ff
4 15 0 0000ff
5 15 0 0000ff
6 15 0 0000ff
7 15 0 0000ff
8 15 0 0000ff
9 15 0 0000ff
10 15 0 0000ff
11 15 0 0000ff
12 15 0 0000ff
13 15 0 0000ff
14 15 0 0000ff
15 15 0 0000ff
0 0 1 ff0000
1 0 1 ff0000
2 0 1 ff0000
3 0 1 ff0000
4 0 1 ff0000
5 0 1 ff0000
6 0 1 ff0000
7 0 1 ff0000
8 0 1 ff0000
9 0 1 ff0000
10 0 1 ff0000
11 0 1 ff0000
12 0 1 ff0000
13 0 1 ff0000
14 0 1 ff0000
15 0 1 ff0000
0 1 1 ff0000
0 2 1 ff0000
0 3 1 ff0000
0 4 1 ff0000
0 5 1 ff0000
0 6 1 ff0000
0 7 1 ff0000
0 8 1 ff0000
0 9 1 ff0000
0 10 1 ff0000
0 11 1 ff0000
0 12 1 ff0000
0 13 1 ff0000
0 14 1 ff0000
0 15 1 ff0000
0 0 2 ff0000
1 0 2 ff0000
2 0 2 ff0000
3 0 2 ff0000
4 0 2 ff0000
5 0 2 ff0000
6 0 2 ff0000
7 0 2 ff0000
8 0 2 ff0000
9 0 2 ff0000
10 0 2 ff0000
11 0 2 ff0000
12 0 2 ff0000
13 0 2 ff0000
14 0 2 ff0000
15 0 2 ff0000
0 1 2 ff0000
0 2 2 ff0000
0 3 2 ff0000
0 4 2 ff0000
0 5 2 ff0000
0 6 2 ff0000
0 7 2 ff0000
0 8 2 ff0000
0 9 2 ff0000
0 10 2 ff0000
0 11 2 ff0000
0 12 2 ff0000
0 13 2 ff0000
0 14 2 ff0000
0 15 2 ff0000
0 0 3 ff0000
1 0 3 ff0000
2 0 3 ff0000
3 0 3 ff0000
4 0 3 ff0000
5 0 3 ff0000
6 0 3 ff0000
7 0 3 ff0000
8 0 3 ff0000
9 0 3 ff0000
10 0 3 ff0000
11 0 3 ff0000
12 0 3 ff0000
13 0 3 ff0000
14 0 3 ff0000
15 0 3 ff0000
0 1 3 ff0000
0 2 3 ff0000
0 3 3 ff0000
0 4 3 ff0000
0 5 3 ff0000
0 6 3 ff0000
0 7 3 ff0000
0 8 3 ff0000
0 9 3 ff0000
0 10 3 ff0000
0 11 3 ff0000
0 12 3 ff0000
0 13 3 ff0000
0 14 3 ff0000
0 15 3 ff0000
0 0 4 ff0000
1 0 4 ff0000
2 0 4 ff0000
3 0 4 ff0000
4 0 4 ff0000
5 0 4 ff0000
6 0 4 ff0000
7 0 4 ff0000
8 0 4 ff0000
9 0 4 ff0000
10 0 4 ff0000
11 0 4 ff0000
12 0 4 ff0000
13 0 4 ff0000
14 0 4 ff0000
15 0 4 ff0000
0 1 4 ff0000
0 2 4 ff0000
0 3 4 ff0000
0 4 4 ff0000
0 5 4 ff0000
0 6 4 ff0000
0 10 4 ff0000
0 11 4 ff0000
0 12 4 ff0000
0 13 4 ff0000
0 14 4 ff0000
0 15 4 ff0000
0 0 5 ff0000
1 0 5 ff0000
2 0 5 ff0000
3 0 5 ff0000
4 0 5 ff0000
5 0 5 ff0000
6 0 5 ff0000
7 0 5 ff0000
8 0 5 ff0000
9 0 5 ff0000
10 0 5 ff0000
11 0 5 ff0000
12 0 5 ff0000
13 0 5 ff0000
14 0 5 ff0000
15 0 5 ff0000
0 1 5 ff0000
0 2 5 ff0000
0 3 5 ff0000
0 4 5 ff0000
0 5 5 ff0000
0 6 5 ff0000
0 10 5 ff0000
0 11 5 ff0000
0 12 5 ff0000
0 13 5 ff0000
0 14 5 ff0000
0 15 5 ff0000
0 0 6 ff0000
1 0 6 ff0000
2 0 6 ff0000
3 0 6 ff0000
4 0 6 ff0000
5 0 6 ff0000
6 0 6 ff0000
7 0 6 ff0000
8 0 6 ff0000
9 0 6 ff0000
10 0 6 ff0000
11 0 6 ff0000
12 0 6 ff0000
13 0 6 ff0000
14 0 6 ff0000
15 0 6 ff0000
0 1 6 ff0000
0 2 6 ff0000
0 3 6 ff0000
0 4 6 ff0000
0 5 6 ff0000
0 6 6 ff0000
0 10 6 ff0000
0 11 6 ff0000
0 12 6 ff0000
0 13 6 ff0000
0 14 6 ff0000
0 15 6 ff0000
0 0 7 ff0000
1 0 7 ff0000
2 0 7 ff0000
3 0 7 ff0000
4 0 7 ff0000
5 0 7 ff0000
6 0 7 ff0000
7 0 7 ff0000
8 0 7 ff0000
9 0 7 ff0000
10 0 7 ff0000
11 0 7 ff0000
12 0 7 ff0000
13 0 7 ff0000
14 0 7 ff0000
15 0 7 ff0000
0 1 7 ff0000
0 2 7 ff0000
0 3 7 ff0000
0 4 7 ff0000
0 5 7 ff0000
0 6 7 ff0000
0 10 7 ff0000
0 11 7 ff0000
0 12 7 ff0000
0 13 7 ff0000
0 14 7 ff0000
0 15 7 ff0000
0 0 8 ff0000
1 0 8 ff0000
2 0 8 ff0000
3 0 8 ff0000
4 0 8 ff0000
5 0 8 ff0000
6 0 8 ff0000
7 0 8 ff0000
8 0 8 ff0000
9 0 8 ff0000
10 0 8 ff0000
11 0 8 ff0000
12 0 8 ff0000
13 0 8 ff0000
14 0 8 ff0000
15 0 8 ff0000
0 1 8 ff0000
0 2 8 ff0000
0 3 8 ff0000
0 4 8 ff0000
0 5 8 ff0000
0 6 8 ff0000
0 7 8 ff0000
0 8 8 ff0000
0 9 8 ff0000
0 10 8 ff0000
0 11 8 ff0000
0 12 8 ff0000
0 13 8 ff0000
0 14 8 ff0000
0 15 8 ff0000
0 0 9 ff0000
1 0 9 ff0000
2 0 9 ff0000
3 0 9 ff0000
4 0 9 ff0000
5 0 9 ff0000
6 0 9 ff0000
7 0 9 ff0000
8 0 9 ff0000
9 0 9 ff0000
10 0 9 ff0000
11 0 9 ff0000
12 0 9 ff0000
13 0 9 ff0000
14 0 9 ff0000
15 0 9 ff0000
0 1 9 ff0000
0 2 9 ff0000
0 3 9 ff0000
0 4 9 ff0000
0 5 9 ff0000
0 6 9 ff0000
0 7 9 ff0000
0 8 9 ff0000
0 9 9 ff0000
0 10 9 ff0000
0 11 9 ff0000
0 12 9 ff0000
0 13 9 ff0000
0 14 9 ff0000
0 15 9 ff0000
0 0 10 ff0000
1 0 10 ff0000
2 0 10 ff0000
3 0 10 ff0000
4 0 10 ff0000
5 0 10 ff0000
6 0 10 ff0000
7 0 10 ff0000
8 0 10 ff0000
9 0 10 ff0000
10 0 10 ff0000
11 0 10 ff0000
12 0 10 ff0000
13 0 10 ff0000
14 0 10 ff0000
15 0 10 ff0000
0 1 10 ff0000
0 2 10 ff0000
0 3 10 ff0000
0 4 10 ff0000
0 5 10 ff0000
0 6 10 ff0000
0 7 10 ff0000
0 8 10 ff0000
0 9 10 ff0000
0 10 10 ff0000
0 11 10 ff0000
0 12 10 ff0000
0 13 10 ff0000
0 14 10 ff0000
0 15 10 ff0000
32 0 0 0000ff
33 0 0 0000ff
34 0 0 0000ff
35 0 0 0000ff
36 0 0 0000ff
37 0 0 0000ff
38 0 0 0000ff
39 0 0 0000ff
40 0 0 0000ff
41 0 0 0000ff
42 0 0 0000ff
43 0 0 0000ff
44 0 0 0000ff
45 0 0 0000ff
46 0 0 0000ff
47 0 0 0000ff
32 1 0 0000ff
33 1 0 0000ff
34 1 0 0000ff
35 1 0 0000ff
36 1 0 0000ff
37 1 0 0000ff
38 1 0 0000ff
39 1 0 0000ff
40 1 0 0000ff
41 1 0 0000ff
42 1 0 0000ff
43 1 0 0000ff
44 1 0 0000ff
45 1 0 0000ff
46 1 0 0000ff
47 1 0 0000ff
32 2 0 0000ff
33 2 0 0000ff
34 2 0 0000ff
35 2 0 0000ff
36 2 0 0000ff
37 2 0 0000ff
38 2 0 0000ff
39 2 0 0000ff
40 2 0 0000ff
41 2 0 0000ff
42 2 0 0000ff
43 2 0 0000ff
44 2 0 0000ff
45 2 0 0000ff
46 2 0 0000ff
47 2 0 0000ff
32 3 0 0000ff
33 3 0 0000ff
34 3 0 0000ff
35 3 0 0000ff
36 3 0 0000ff
37 3 0 0000ff
38 3 0 0000ff
39 3 0 0000ff
40 3 0 0000ff
41 3 0 0000ff
42 3 0 0000ff
43 3 0 0000ff
44 3 0 0000ff
45 3 0 0000ff
46 3 0 0000ff
47 3 0 0000ff
32 4 0 0000ff
33 4 0 0000ff
34 4 0 0000ff
35 4 0 0000ff
36 4 0 0000ff
37 4 0 0000ff
38 4 0 0000ff
39 4 0 0000ff
40 4 0 0000ff
41 4 0 0000ff
42 4 0 0000ff
43 4 0 0000ff
44 4 0 0000ff
45 4 0 0000ff
46 4 0 0000ff
47 4 0 0000ff
32 5 0 0000ff
33 5 0 0000ff
34 5 0 0000ff
35 5 0 0000ff
36 5 0 0000ff
37 5 0 0000ff
38 5 0 0000ff
39 5 0 0000ff
40 5 0 0000ff
41 5 0 0000ff
42 5 0 0000ff
43 5 0 0000ff
44 5 0 0000ff
45 5 0 0000ff
46 5 0 0000ff
47 5 0 0000ff
32 6 0 0000ff
33 6 0 0000ff
34 6 0 0000ff
35 6 0 0000ff
36 6 0 0000ff
37 6 0 0000ff
38 6 0 0000ff
39 6 0 0000ff
40 6 0 0000ff
41 6 0 0000ff
42 6 0 0000ff
43 6 0 0000ff
44 6 0 0000ff
45 6 0 0000ff
46 6 0 0000ff
47 6 0 0000ff
32 7 0 0000ff
33 7 0 0000ff
34 7 0 0000ff
35 7 0 0000ff
36 7 0 0000ff
37 7 0 0000ff
38 7 0 0000ff
39 7 0 0000ff
40 7 0 0000ff
41 7 0 0000ff
42 7 0 0000ff
43 7 0 0000ff
44 7 0 0000ff
45 7 0 0000ff
46 7 0 0000ff
47 7 0 0000ff
32 8 0 0000ff
33 8 0 0000ff
34 8 0 0000ff
35 8 0 0000ff
36 8 0 0000ff
37 8 0 0000ff
38 8 0 0000ff
39 8 0 0000ff
40 8 0 0000ff
41 8 0 0000ff
42 8 0 0000ff
43 8 0 0000ff
44 8 0 0000ff
45 8 0 0000ff
46 8 0 0000ff
47 8 0 0000ff
32 9 0 0000ff
33 9 0 0000ff
34 9 0 0000ff
35 9 0 0000ff
36 9 0 0000ff
37 9 0 0000ff
38 9 0 0000ff
39 9 0 0000ff
40 9 0 0000ff
41 9 0 0000ff
42 9 0 0000ff
43 9 0 0000ff
44 9 0 0000ff
45 9 0 0000ff
46 9 0 0000ff
47 9 0 0000ff
32 10 0 0000ff
33 10 0 0000ff
34 10 0 0000ff
35 10 0 0000ff
36 10 0 0000ff
37 10 0 0000ff
38 10 0 0000ff
39 10 0 0000ff
40 10 0 0000ff
41 10 0 0000ff
42 10 0 0000ff
43 10 0 0000ff
44 10 0 0000ff
45 10 0 0000ff
46 10 0 0000ff
47 10 0 0000ff
32 11 0 0000ff
33 11 0 0000ff
34 11 0 0000ff
35 11 0 0000ff
36 11 0 0000ff
37 11 0 0000ff
38 11 0 0000ff
39 11 0 0000ff
40 11 0 0000ff
41 11 0 0000ff
42 11 0 0000ff
43 11 0 0000ff
44 11 0 0000ff
45 11 0 0000ff
46 11 0 0000ff
47 11 0 0000ff
32 12 0 0000ff
33 12 0 0000ff
34 12 0 0000ff
35 12 0 0000ff
36 12 0 0000ff
37 12 0 0000ff
38 12 0 0000ff
39 12 0 0000ff
40 12 0 0000ff
41 12 0 0000ff
42 12 0 0000ff
43 12 0 0000ff
44 12 0 0000ff
45 12 0 0000ff
46 12 0 0000ff
47 12 0 0000ff
32 13 0 0000ff
33 13 0 0000ff
34 13 0 0000ff
35 13 0 0000ff
36 13 0 0000ff
37 13 0 0000ff
38 13 0 0000ff
39 13 0 0000ff
40 13 0 0000ff
41 13 0 0000ff
42 13 0 0000ff
43 13 0 0000ff
44 13 0 0000ff
45 13 0 0000ff
46 13 0 0000ff
47 13 0 0000ff
32 14 0 0000ff
33 14 0 0000ff
34 14 0 0000ff
35 14 0 0000ff
36 14 0 0000ff
37 14 0 0000ff
38 14 0 0000ff
39 14 0 0000ff
40 14 0 0000ff
41 14 0 0000ff
42 14 0 0000ff
43 14 0 0000ff
44 14 0 0000ff
45 14 0 0000ff
46 14 0 0000ff
47 14 0 0000ff
32 15 0 0000ff
33 15 0 0000ff
34 15 0 0000ff
35 15 0 0000ff
36 15 0 0000ff
37 15 0 0000ff
38 15 0 0000ff
39 15 0 0000ff
40 15 0 0000ff
41 15 0 0000ff
42 15 0 0000ff
43 15 0 0000ff
44 15 0 0000ff
45 15 0 0000ff
46 15 0 0000ff
47 15 0 0000ff
32 0 1 ff0000
33 0 1 ff0000
34 0 1 ff0000
35 0 1 ff0000
36 0 1 ff0000
43 0 1 ff0000
44 0 1 ff0000
45 0 1 ff0000
46 0 1 ff0000
47 0 1 ff0000
32 0 2 ff0000
33 0 2 ff0000
34 0 2 ff0000
35 0 2 ff0000
36 0 2 ff0000
43 0 2 ff0000
44 0 2 ff0000
45 0 2 ff0000
46 0 2 ff0000
47 0 2 ff0000
32 0 3 ff0000
33 0 3 ff0000
34 0 3 ff0000
35 0 3 ff0000
36 0 3 ff0000
43 0 3 ff0000
44 0 3 ff0000
45 0 3 ff0000
46 0 3 ff0000
47 0 3 ff0000
32 0 4 ff0000
33 0 4 ff0000
34 0 4 ff0000
35 0 4 ff0000
36 0 4 ff0000
43 0 4 ff0000
44 0 4 ff0000
45 0 4 ff0000
46 0 4 ff0000
47 0 4 ff0000
32 0 5 ff0000
33 0 5 ff0000
34 0 5 ff0000
35 0 5 ff0000
36 0 5 ff0000
43 0 5 ff0000
44 0 5 ff0000
45 0 5 ff0000
46 0 5 ff0000
47 0 5 ff0000
32 0 6 ff0000
33 0 6 ff0000
34 0 6 ff0000
35 0 6 ff0000
36 0 6 ff0000
37 0 6 ff0000
38 0 6 ff0000
39 0 6 ff0000
40 0 6 ff0000
41 0 6 ff0000
42 0 6 ff0000
43 0 6 ff0000
44 0 6 ff0000
45 0 6 ff0000
46 0 6 ff0000
47 0 6 ff0000
32 0 7 ff0000
33 0 7 ff0000
34 0 7 ff0000
35 0 7 ff0000
36 0 7 ff0000
37 0 7 ff0000
38 0 7 ff0000
39 0 7 ff0000
40 0 7 ff0000
41 0 7 ff0000
42 0 7 ff0000
43 0 7 ff0000
44 0 7 ff0000
45 0 7 ff0000
46 0 7 ff0000
47 0 7 ff0000
32 0 8 ff0000
33 0 8 ff0000
34 0 8 ff0000
35 0 8 ff0000
36 0 8 ff0000
37 0 8 ff0000
38 0 8 ff0000
39 0 8 ff0000
40 0 8 ff0000
41 0 8 ff0000
42 0 8 ff0000
43 0 8 ff0000
44 0 8 ff0000
45 0 8 ff0000
46 0 8 ff0000
47 0 8 ff0000
32 0 9 ff0000
33 0 9 ff0000
34 0 9 ff0000
35 0 9 ff0000
36 0 9 ff0000
37 0 9 ff0000
38 0 9 ff0000
39 0 9 ff0000
40 0 9 ff0000
41 0 9 ff0000
42 0 9 ff0000
43 0 9 ff0000
44 0 9 ff0000
45 0 9 ff0000
46 0 9 ff0000
47 0 9 ff0000
32 0 10 ff0000
33 0 10 ff0000
34 0 10 ff0000
35 0 10 ff0000
36 0 10 ff0000
37 0 10 ff0000
38 0 10 ff0000
39 0 10 ff0000
40 0 10 ff0000
41 0 10 ff0000
42 0 10 ff0000
43 0 10 ff0000
44 0 10 ff0000
45 0 10 ff0000
46 0 10 ff0000
47 0 10 ff0000
64 0 0 0000ff
65 0 0 0000ff
66 0 0 0000ff
67 0 0 0000ff
68 0 0 0000ff
69 0 0 0000ff
70 0 0 0000ff
71 0 0 0000ff
72 0 0 0000ff
73 0 0 0000ff
74 0 0 0000ff
75 0 0 0000ff
76 0 0 0000ff
77 0 0 0000ff
78 0 0 0000ff
79 0 0 0000ff
64 1 0 0000ff
65 1 0 0000ff
66 1 0 0000ff
67 1 0 0000ff
68 1 0 0000ff
69 1 0 0000ff
70 1 0 0000ff
71 1 0 0000ff
72 1 0 0000ff
73 1 0 0000ff
74 1 0 0000ff
75 1 0 0000ff
76 1 0 0000ff
77 1 0 0000ff
78 1 0 0000ff
79 1 0 0000ff
64 2 0 0000ff
65 2 0 0000ff
66 2 0 0000ff
67 2 0 0000ff
68 2 0 0000ff
69 2 0 0000ff
70 2 0 0000ff
71 2 0 0000ff
72 2 0 0000ff
73 2 0 0000ff
74 2 0 0000ff
75 2 0 0000ff
76 2 0 0000ff
77 2 0 0000ff
78 2 0 0000ff
79 2 0 0000ff
64 3 0 0000ff
65 3 0 0000ff
66 3 0 0000ff
67 3 0 0000ff
68 3 0 0000ff
69 3 0 0000ff
70 3 0 0000ff
71 3 0 0000ff
72 3 0 0000ff
73 3 0 0000ff
74 3 0 0000ff
75 3 0 0000ff
76 3 0 0000ff
77 3 0 0000ff
78 3 0 0000ff
79 3 0 0000ff
64 4 0 0000ff
65 4 0 0000ff
66 4 0 0000ff
67 4 0 0000ff
68 4 0 0000ff
69 4 0 0000ff
70 4 0 0000ff
71 4 0 0000ff
72 4 0 0000ff
73 4 0 0000ff
74 4 0 0000ff
75 4 0 0000ff
76 4 0 0000ff
77 4 0 0000ff
78 4 0 0000ff
79 4 0 0000ff
64 5 0 0000ff
65 5 0 0000ff
66 5 0 0000ff
67 5 0 0000ff
68 5 0 0000ff
69 5 0 0000ff
70 5 0 0000ff
71 5 0 0000ff
72 5 0 0000ff
73 5 0 0000ff
74 5 0 0000ff
75 5 0 0000ff
76 5 0 0000ff
77 5 0 0000ff
78 5 0 0000ff
79 5 0 0000ff
64 6 0 0000ff
65 6 0 0000ff
66 6 0 0000ff
67 6 0 0000ff
68 6 0 0000ff
69 6 0 0000ff
70 6 0 0000ff
71 6 0 0000ff
72 6 0 0000ff
73 6 0 0000ff
74 6 0 0000ff
75 6 0 0000ff
76 6 0 0000ff
77 6 0 0000ff
78 6 0 0000ff
79 6 0 0000ff
64 7 0 0000ff
65 7 0 0000ff
66 7 0 0000ff
67 7 0 0000ff
68 7 0 0000ff
69 7 0 0000ff
70 7 0 0000ff
71 7 0 0000ff
72 7 0 0000ff
73 7 0 0000ff
74 7 0 0000ff
75 7 0 0000ff
76 7 0 0000ff
77 7 0 0000ff
78 7 0 0000ff
79 7 0 0000ff
64 8 0 0000ff
65 8 0 0000ff
66 8 0 0000ff
67 8 0 0000ff
68 8 0 0000ff
69 8 0 0000ff
70 8 0 0000ff
71 8 0 0000ff
72 8 0 0000ff
73 8 0 0000ff
74 8 0 0000ff
75 8 0 0000ff
76 8 0 0000ff
77 8 0 0000ff
78 8 0 0000ff
79 8 0 0000ff
64 9 0 0000ff
65 9 0 0000ff
66 9 0 0000ff
67 9 0 0000ff
68 9 0 0000ff
69 9 0 0000ff
70 9 0 0000ff
71 9 0 0000ff
72 9 0 0000ff
73 9 0 0000ff
74 9 0 0000ff
75 9 0 0000ff
76 9 0 0000ff
77 9 0 0000ff
78 9 0 0000ff
79 9 0 0000ff
64 10 0 0000ff
65 10 0 0000ff
66 10 0 0000ff
67 10 0 0000ff
68 10 0 0000ff
69 10 0 0000ff
70 10 0 0000ff
71 10 0 0000ff
72 10 0 0000ff
73 10 0 0000ff
74 10 0 0000ff
75 10 0 0000ff
76 10 0 0000ff
77 10 0 0000ff
78 10 0 0000ff
79 10 0 0000ff
64 11 0 0000ff
65 11 0 0000ff
66 11 0 0000ff
67 11 0 0000ff
68 11 0 0000ff
69 11 0 0000ff
70 11 0 0000ff
71 11 0 0000ff
72 11 0 0000ff
73 11 0 0000ff
74 11 0 0000ff
75 11 0 0000ff
76 11 0 0000ff
77 11 0 0000ff
78 11 0 0000ff
79 11 0 0000ff
64 12 0 0000ff
65 12 0 0000ff
66 12 0 0000ff
67 12 0 0000ff
68 12 0 0000ff
69 12 0 0000ff
70 12 0 0000ff
71 12 0 0000ff
72 12 0 0000ff
73 12 0 0000ff
74 12 0 0000ff
75 12 0 0000ff
76 12 0 0000ff
77 12 0 0000ff
78 12 0 0000ff
79 12 0 0000ff
64 13 0 0000ff
65 13 0 0000ff
66 13 0 0000ff
67 13 0 0000ff
68 13 0 0000ff
69 13 0 0000ff
70 13 0 0000ff
71 13 0 0000ff
72 13 0 0000ff
73 13 0 0000ff
74 13 0 0000ff
75 13 0 0000ff
76 13 0 0000ff
77 13 0 0000ff
78 13 0 0000ff
79 13 0 0000ff
64 14 0 0000ff
65 14 0 0000ff
66 14 0 0000ff
67 14 0 0000ff
68 14 0 0000ff
69 14 0 0000ff
70 14 0 0000ff
71 14 0 0000ff
72 14 0 0000ff
73 14 0 0000ff
74 14 0 0000ff
75 14 0 0000ff
76 14 0 0000ff
77 14 0 0000ff
78 14 0 0000ff
79 14 0 0000ff
64 15 0 0000ff
65 15 0 0000ff
66 15 0 0000ff
67 15 0 0000ff
68 15 0 0000ff
69 15 0 0000ff
70 15 0 0000ff
71 15 0 0000ff
72 15 0 0000ff
73 15 0 0000ff
74 15 0 0000ff
75 15 0 0000ff
76 15 0 0000ff
77 15 0 0000ff
78 15 0 0000ff
79 15 0 0000ff
64 0 1 ff0000
65 0 1 ff0000
66 0 1 ff0000
67 0 1 ff0000
68 0 1 ff0000
69 0 1 ff0000
70 0 1 ff0000
71 0 1 ff0000
72 0 1 ff0000
73 0 1 ff0000
74 0 1 ff0000
75 0 1 ff0000
76 0 1 ff0000
77 0 1 ff0000
78 0 1 ff0000
79 0 1 ff0000
79 1 1 ff0000
79 2 1 ff0000
79 3 1 ff0000
79 4 1 ff0000
79 5 1 ff0000
79 6 1 ff0000
79 7 1 ff0000
79 8 1 ff0000
79 9 1 ff0000
79 10 1 ff0000
79 11 1 ff0000
79 12 1 ff0000
79 13 1 ff0000
79 14 1 ff0000
79 15 1 ff0000
64 0 2 ff0000
65 0 2 ff0000
66 0 2 ff0000
67 0 2 ff0000
68 0 2 ff0000
69 0 2 ff0000
70 0 2 ff0000
71 0 2 ff0000
72 0 2 ff0000
73 0 2 ff0000
74 0 2 ff0000
75 0 2 ff0000
76 0 2 ff0000
77 0 2 ff0000
78 0 2 ff0000
79 0 2 ff0000
79 1 2 ff0000
79 2 2 ff0000
79 3 2 ff0000
79 4 2 ff0000
79 5 2 ff0000
79 6 2 ff0000
79 7 2 ff0000
79 8 2 ff0000
79 9 2 ff0000
79 10 2 ff0000
79 11 2 ff0000
79 12 2 ff0000
79 13 2 ff0000
79 14 2 ff0000
79 15 2 ff0000
64 0 3 ff0000
65 0 3 ff0000
66 0 3 ff0000
67 0 3 ff0000
68 0 3 ff0000
69 0 3 ff0000
70 0 3 ff0000
71 0 3 ff0000
72 0 3 ff0000
73 0 3 ff0000
74 0 3 ff0000
75 0 3 ff0000
76 0 3 ff0000
77 0 3 ff0000
78 0 3 ff0000
79 0 3 ff0000
79 1 3 ff0000
79 2 3 ff0000
79 3 3 ff0000
79 4 3 ff0000
79 5 3 ff0000
79 6 3 ff0000
79 7 3 ff0000
79 8 3 ff0000
79 9 3 ff0000
79 10 3 ff0000
79 11 3 ff0000
79 12 3 ff0000
79 13 3 ff0000
79 14 3 ff0000
79 15 3 ff0000
64 0 4 ff0000
65 0 4 ff0000
66 0 4 ff0000
67 0 4 ff0000
68 0 4 ff0000
69 0 4 ff0000
70 0 4 ff0000
71 0 4 ff0000
72 0 4 ff0000
73 0 4 ff0000
74 0 4 ff0000
75 0 4 ff0000
76 0 4 ff0000
77 0 4 ff0000
78 0 4 ff0000
79 0 4 ff0000
79 1 4 ff0000
79 2 4 ff0000
79 3 4 ff0000
79 4 4 ff0000
79 5 4 ff0000
79 6 4 ff0000
79 7 4 ff0000
79 8 4 ff0000
79 9 4 ff0000
79 10 4 ff0000
79 11 4 ff0000
79 12 4 ff0000
79 13 4 ff0000
79 14 4 ff0000
79 15 4 ff0000
64 0 5 ff0000
65 0 5 ff0000
66 0 5 ff0000
67 0 5 ff0000
68 0 5 ff0000
69 0 5 ff0000
70 0 5 ff0000
71 0 5 ff0000
72 0 5 ff0000
73 0 5 ff0000
74 0 5 ff0000
75 0 5 ff0000
76 0 5 ff0000
77 0 5 ff0000
78 0 5 ff0000
79 0 5 ff0000
79 1 5 ff0000
79 2 5 ff0000
79 3 5 ff0000
79 4 5 ff0000
79 5 5 ff0000
79 6 5 ff0000
79 7 5 ff0000
79 8 5 ff0000
79 9 5 ff0000
79 10 5 ff0000
79 11 5 ff0000
79 12 5 ff0000
79 13 5 ff0000
79 14 5 ff0000
79 15 5 ff0000
64 0 6 ff0000
65 0 6 ff0000
66 0 6 ff0000
67 0 6 ff0000
68 0 6 ff0000
69 0 6 ff0000
70 0 6 ff0000
71 0 6 ff0000
72 0 6 ff0000
73 0 6 ff0000
74 0 6 ff0000
75 0 6 ff0000
76 0 6 ff0000
77 0 6 ff0000
78 0 6 ff0000
79 0 6 ff0000
79 1 6 ff0000
79 2 6 ff0000
79 3 6 ff0000
79 4 6 ff0000
79 5 6 ff0000
79 6 6 ff0000
79 7 6 ff0000
79 8 6 ff0000
79 9 6 ff0000
79 10 6 ff0000
79 11 6 ff0000
79 12 6 ff0000
79 13 6 ff0000
79 14 6 ff0000
79 15 6 ff0000
64 0 7 ff0000
65 0 7 ff0000
66 0 7 ff0000
67 0 7 ff0000
68 0 7 ff0000
69 0 7 ff0000
70 0 7 ff0000
71 0 7 ff0000
72 0 7 ff0000
73 0 7 ff0000
74 0 7 ff0000
75 0 7 ff0000
76 0 7 ff0000
77 0 7 ff0000
78 0 7 ff0000
79 0 7 ff0000
79 1 7 ff0000
79 2 7 ff0000
79 3 7 ff0000
79 6 7 ff0000
79 7 7 ff0000
79 8 7 ff0000
79 9 7 ff0000
79 12 7 ff0000
79 13 7 ff0000
79 14 7 ff0000
79 15 7 ff0000
64 0 8 ff0000
65 0 8 ff0000
66 0 8 ff0000
67 0 8 ff0000
68 0 8 ff0000
69 0 8 ff0000
70 0 8 ff0000
71 0 8 ff0000
72 0 8 ff0000
73 0 8 ff0000
74 0 8 ff0000
75 0 8 ff0000
76 0 8 ff0000
77 0 8 ff0000
78 0 8 ff0000
79 0 8 ff0000
79 1 8 ff0000
79 2 8 ff0000
79 3 8 ff0000
79 6 8 ff0000
79 7 8 ff0000
79 8 8 ff0000
79 9 8 ff0000
79 12 8 ff0000
79 13 8 ff0000
79 14 8 ff0000
79 15 8 ff0000
64 0 9 ff0000
65 0 9 ff0000
66 0 9 ff0000
67 0 9 ff0000
68 0 9 ff0000
69 0 9 ff0000
70 0 9 ff0000
71 0 9 ff0000
72 0 9 ff0000
73 0 9 ff0000
74 0 9 ff0000
75 0 9 ff0000
76 0 9 ff0000
77 0 9 ff0000
78 0 9 ff0000
79 0 9 ff0000
79 1 9 ff0000
79 2 9 ff0000
79 3 9 ff0000
79 4 9 ff0000
79 5 9 ff0000
79 6 9 ff0000
79 7 9 ff0000
79 8 9 ff0000
79 9 9 ff0000
79 10 9 ff0000
79 11 9 ff0000
79 12 9 ff0000
79 13 9 ff0000
79 14 9 ff0000
79 15 9 ff0000
64 0 10 ff0000
65 0 10 ff0000
66 0 10 ff0000
67 0 10 ff0000
68 0 10 ff0000
69 0 10 ff0000
70 0 10 ff0000
71 0 10 ff0000
72 0 10 ff0000
73 0 10 ff0000
74 0 10 ff0000
75 0 10 ff0000
76 0 10 ff0000
77 0 10 ff0000
78 0 10 ff0000
79 0 10 ff0000
79 1 10 ff0000
79 2 10 ff0000
79 3 10 ff0000
79 4 10 ff0000
79 5 10 ff0000
79 6 10 ff0000
79 7 10 ff0000
79 8 10 ff0000
79 9 10 ff0000
79 10 10 ff0000
79 11 10 ff0000
79 12 10 ff0000
79 13 10 ff0000
79 14 10 ff0000
79 15 10 ff0000
64 32 0 0000ff
65 32 0 0000ff
66 32 0 0000ff
67 32 0 0000ff
68 32 0 0000ff
69 32 0 0000ff
70 32 0 0000ff
71 32 0 0000ff
72 32 0 0000ff
73 32 0 0000ff
74 32 0 0000ff
75 32 0 0000ff
76 32 0 0000ff
77 32 0 0000ff
78 32 0 0000ff
79 32 0 0000ff
64 33 0 0000ff
65 33 0 0000ff
66 33 0 0000ff
67 33 0 0000ff
68 33 0 0000ff
69 33 0 0000ff
70 33 0 0000ff
71 33 0 0000ff
72 33 0 0000ff
73 33 0 0000ff
74 33 0 0000ff
75 33 0 0000ff
76 33 0 0000ff
77 33 0 0000ff
78 33 0 0000ff
79 33 0 0000ff
64 34 0 0000ff
65 34 0 0000ff
66 34 0 0000ff
67 34 0 0000ff
68 34 0 0000ff
69 34 0 0000ff
70 34 0 0000ff
71 34 0 0000ff
72 34 0 0000ff
73 34 0 0000ff
74 34 0 0000ff
75 34 0 0000ff
76 34 0 0000ff
77 34 0 0000ff
78 34 0 0000ff
79 34 0 0000ff
64 35 0 0000ff
65 35 0 0000ff
66 35 0 0000ff
67 35 0 0000ff
68 35 0 0000ff
69 35 0 0000ff
70 35 0 0000ff
71 35 0 0000ff
72 35 0 0000ff
73 35 0 0000ff
74 35 0 0000ff
75 35 0 0000ff
76 35 0 0000ff
77 35 0 0000ff
78 35 0 0000ff
79 35 0 0000ff
64 36 0 0000ff
65 36 0 0000ff
66 36 0 0000ff
67 36 0 0000ff
68 36 0 0000ff
69 36 0 0000ff
70 36 0 0000ff
71 36 0 0000ff
72 36 0 0000ff
73 36 0 0000ff
74 36 0 0000ff
75 36 0 0000ff
76 36 0 0000ff
77 36 0 0000ff
78 36 0 0000ff
79 36 0 0000ff
64 37 0 0000ff
65 37 0 0000ff
66 37 0 0000ff
67 37 0 0000ff
68 37 0 0000ff
69 37 0 0000ff
70 37 0 0000ff
71 37 0 0000ff
72 37 0 0000ff
73 37 0 0000ff
74 37 0 0000ff
75 37 0 0000ff
76 37 0 0000ff
77 37 0 0000ff
78 37 0 0000ff
79 37 0 0000ff
64 38 0 0000ff
65 38 0 0000ff
66 38 0 0000ff
67 38 0 0000ff
68 38 0 0000ff
69 38 0 0000ff
70 38 0 0000ff
71 38 0 0000ff
72 38 0 0000ff
73 38 0 0000ff
74 38 0 0000ff
75 38 0 0000ff
76 38 0 0000ff
77 38 0 0000ff
78 38 0 0000ff
79 38 0 0000ff
64 39 0 0000ff
65 39 0 0000ff
66 39 0 0000ff
67 39 0 0000ff
68 39 0 0000ff
69 39 0 0000ff
70 39 0 0000ff
71 39 0 0000ff
72 39 0 0000ff
73 39 0 0000ff
74 39 0 0000ff
75 39 0 0000ff
76 39 0 0000ff
77 39 0 0000ff
78 39 0 0000ff
79 39 0 0000ff
64 40 0 0000ff
65 40 0 0000ff
66 40 0 0000ff
67 40 0 0000ff
68 40 0 0000ff
69 40 0 0000ff
70 40 0 0000ff
71 40 0 0000ff
72 40 0 0000ff
73 40 0 0000ff
74 40 0 0000ff
75 40 0 0000ff
76 40 0 0000ff
77 40 0 0000ff
78 40 0 0000ff
79 40 0 0000ff
64 41 0 0000ff
65 41 0 0000ff
66 41 0 0000ff
67 41 0 0000ff
68 41 0 0000ff
69 41 0 0000ff
70 41 0 0000ff
71 41 0 0000ff
72 41 0 0000ff
73 41 0 0000ff
74 41 0 0000ff
75 41 0 0000ff
76 41 0 0000ff
77 41 0 0000ff
78 41 0 0000ff
79 41 0 0000ff
64 42 0 0000ff
65 42 0 0000ff
66 42 0 0000ff
67 42 0 0000ff
68 42 0 0000ff
69 42 0 0000ff
70 42 0 0000ff
71 42 0 0000ff
72 42 0 0000ff
73 42 0 0000ff
74 42 0 0000ff
75 42 0 0000ff
76 42 0 0000ff
77 42 0 0000ff
78 42 0 0000ff
79 42 0 0000ff
64 43 0 0000ff
65 43 0 0000ff
66 43 0 0000ff
67 43 0 0000ff
68 43 0 0000ff
69 43 0 0000ff
70 43 0 0000ff
71 43 0 0000ff
72 43 0 0000ff
73 43 0 0000ff
74 43 0 0000ff
75 43 0 0000ff
76 43 0 0000ff
77 43 0 0000ff
78 43 0 0000ff
79 43 0 0000ff
64 44 0 0000ff
65 44 0 0000ff
66 44 0 0000ff
67 44 0 0000ff
68 44 0 0000ff
69 44 0 0000ff
70 44 0 0000ff
71 44 0 0000ff
72 44 0 0000ff
73 44 0 0000ff
74 44 0 0000ff
75 44 0 0000ff
76 44 0 0000ff
77 44 0 0000ff
78 44 0 0000ff
79 44 0 0000ff
64 45 0 0000ff
65 45 0 0000ff
66 45 0 0000ff
67 45 0 0000ff
68 45 0 0000ff
69 45 0 0000ff
70 45 0 0000ff
71 45 0 0000ff
72 45 0 0000ff
73 45 0 0000ff
74 45 0 0000ff
75 45 0 0000ff
76 45 0 0000ff
77 45 0 0000ff
78 45 0 0000ff
79 45 0 0000ff
64 46 0 0000ff
65 46 0 0000ff
66 46 0 0000ff
67 46 0 0000ff
68 46 0 0000ff
69 46 0 0000ff
70 46 0 0000ff
71 46 0 0000ff
72 46 0 0000ff
73 46 0 0000ff
74 46 0 0000ff
75 46 0 0000ff
76 46 0 0000ff
77 46 0 0000ff
78 46 0 0000ff
79 46 0 0000ff
64 47 0 0000ff
65 47 0 0000ff
66 47 0 0000ff
67 47 0 0000ff
68 47 0 0000ff
69 47 0 0000ff
70 47 0 0000ff
71 47 0 0000ff
72 47 0 0000ff
73 47 0 0000ff
74 47 0 0000ff
75 47 0 0000ff
76 47 0 0000ff
77 47 0 0000ff
78 47 0 0000ff
79 47 0 0000ff
64 32 1 ffffaa
65 32 1 ffffaa
66 32 1 ffffaa
67 32 1 ffffaa
68 32 1 ffffaa
69 32 1 ffffaa
70 32 1 ffffaa
71 32 1 ffffaa
72 32 1 ffffaa
73 32 1 ffffaa
74 32 1 ffffaa
75 32 1 ffffaa
76 32 1 ffffaa
77 32 1 ffffaa
78 32 1 ffffaa
79 32 1 ff0000
64 33 1 ffffaa
79 33 1 ff0000
64 34 1 ffffaa
79 34 1 ff0000
64 35 1 ffffaa
79 35 1 ff0000
64 36 1 ffffaa
79 36 1 ff0000
64 37 1 ffffaa
79 37 1 ff0000
64 38 1 ffffaa
79 38 1 ff0000
64 39 1 ffffaa
79 39 1 ff0000
64 40 1 ffffaa
79 40 1 ff0000
64 41 1 ffffaa
79 41 1 ff0000
64 42 1 ffffaa
79 42 1 ff0000
64 43 1 ffffaa
79 43 1 ff0000
64 44 1 ffffaa
79 44 1 ff0000
79 45 1 ff0000
79 46 1 ff0000
64 47 1 ff0000
65 47 1 ff0000
66 47 1 ff0000
67 47 1 ff0000
68 47 1 ff0000
69 47 1 ff0000
70 47 1 ff0000
71 47 1 ff0000
75 47 1 ff0000
76 47 1 ff0000
77 47 1 ff0000
78 47 1 ff0000
79 47 1 ff0000
64 32 2 ffffaa
65 32 2 ffffaa
66 32 2 ffffaa
67 32 2 ffffaa
68 32 2 ffffaa
69 32 2 ffffaa
70 32 2 ffffaa
71 32 2 ffffaa
72 32 2 ffffaa
73 32 2 ffffaa
74 32 2 ffffaa
75 32 2 ffffaa
76 32 2 ffffaa
77 32 2 ffffaa
78 32 2 ffffaa
79 32 2 ff0000
64 33 2 ffffaa
79 33 2 ff0000
64 34 2 ffffaa
79 34 2 ff0000
64 35 2 ffffaa
79 35 2 ff0000
64 36 2 ffffaa
79 36 2 ff0000
64 37 2 ffffaa
79 37 2 ff0000
64 38 2 ffffaa
79 38 2 ff0000
64 39 2 ffffaa
79 39 2 ff0000
64 40 2 ffffaa
79 40 2 ff0000
64 41 2 ffffaa
79 41 2 ff0000
64 42 2 ffffaa
79 42 2 ff0000
64 43 2 ffffaa
79 43 2 ff0000
64 44 2 ffffaa
79 44 2 ff0000
79 45 2 ff0000
79 46 2 ff0000
64 47 2 ff0000
65 47 2 ff0000
66 47 2 ff0000
67 47 2 ff0000
68 47 2 ff0000
69 47 2 ff0000
70 47 2 ff0000
71 47 2 ff0000
75 47 2 ff0000
76 47 2 ff0000
77 47 2 ff0000
78 47 2 ff0000
79 47 2 ff0000
64 32 3 ffffaa
65 32 3 ffffaa
66 32 3 ffffaa
67 32 3 ffffaa
68 32 3 ffffaa
69 32 3 ffffaa
70 32 3 ffffaa
71 32 3 ffffaa
72 32 3 ffffaa
73 32 3 ffffaa
74 32 3 ffffaa
75 32 3 ffffaa
76 32 3 ffffaa
77 32 3 ffffaa
78 32 3 ffffaa
79 32 3 ff0000
64 33 3 ffffaa
79 33 3 ff0000
64 34 3 ffffaa
79 34 3 ff0000
64 35 3 ffffaa
79 35 3 ff0000
64 36 3 ffffaa
79 36 3 ff0000
64 37 3 ffffaa
79 37 3 ff0000
64 38 3 ffffaa
79 38 3 ff0000
64 39 3 ffffaa
79 39 3 ff0000
64 40 3 ffffaa
79 40 3 ff0000
64 41 3 ffffaa
79 41 3 ff0000
64 42 3 ffffaa
79 42 3 ff0000
64 43 3 ffffaa
79 43 3 ff0000
64 44 3 ffffaa
79 44 3 ff0000
79 45 3 ff0000
79 46 3 ff0000
64 47 3 ff0000
65 47 3 ff0000
66 47 3 ff0000
67 47 3 ff0000
68 47 3 ff0000
69 47 3 ff0000
70 47 3 ff0000
71 47 3 ff0000
75 47 3 ff0000
76 47 3 ff0000
77 47 3 ff0000
78 47 3 ff0000
79 47 3 ff0000
64 32 4 ffffaa
65 32 4 ffffaa
66 32 4 ffffaa
67 32 4 ffffaa
68 32 4 ffffaa
69 32 4 ffffaa
70 32 4 ffffaa
71 32 4 ffffaa
72 32 4 ffffaa
73 32 4 ffffaa
74 32 4 ffffaa
75 32 4 ffffaa
76 32 4 ffffaa
77 32 4 ffffaa
78 32 4 ffffaa
79 32 4 ff0000
64 33 4 ffffaa
79 33 4 ff0000
64 34 4 ffffaa
79 34 4 ff0000
64 35 4 ffffaa
79 35 4 ff0000
64 36 4 ffffaa
79 36 4 ff0000
64 37 4 ffffaa
79 37 4 ff0000
64 38 4 ffffaa
79 38 4 ff0000
64 39 4 ffffaa
79 39 4 ff0000
64 40 4 ffffaa
79 40 4 ff0000
64 41 4 ffffaa
79 41 4 ff0000
64 42 4 ffffaa
79 42 4 ff0000
64 43 4 ffffaa
79 43 4 ff0000
64 44 4 ffffaa
79 44 4 ff0000
79 45 4 ff0000
79 46 4 ff0000
64 47 4 ff0000
65 47 4 ff0000
66 47 4 ff0000
67 47 4 ff0000
68 47 4 ff0000
69 47 4 ff0000
70 47 4 ff0000
