# Goxel 0.15.1
# One line per voxel
# X Y Z RRGGBB
1 0 0 ffffff
2 0 0 ffffff
3 0 0 ffffff
4 0 0 ffffff
5 0 0 ffffff
6 0 0 ffffff
7 0 0 ffffff
8 0 0 ffffff
9 0 0 ffffff
10 0 0 ffffff
11 0 0 ffffff
12 0 0 ffffff
13 0 0 ffffff
14 0 0 ffffff
15 0 0 ffffff
0 1 0 ffffff
1 1 0 ffffff
2 1 0 ffffff
3 1 0 ffffff
4 1 0 ffffff
5 1 0 ffffff
6 1 0 ffffff
7 1 0 ffffff
8 1 0 ffffff
9 1 0 ffffff
10 1 0 ffffff
11 1 0 ffffff
12 1 0 ffffff
13 1 0 ffffff
14 1 0 ffffff
15 1 0 ffffff
0 2 0 ffffff
1 2 0 ffffff
2 2 0 ffffff
3 2 0 ffffff
4 2 0 ffffff
5 2 0 ffffff
6 2 0 ffffff
7 2 0 ffffff
8 2 0 ffffff
9 2 0 ffffff
10 2 0 ffffff
11 2 0 ffffff
12 2 0 ffffff
13 2 0 ffffff
14 2 0 ffffff
15 2 0 ffffff
0 3 0 ffffff
1 3 0 ffffff
2 3 0 ffffff
3 3 0 ffffff
4 3 0 ffffff
5 3 0 ffffff
6 3 0 ffffff
7 3 0 ffffff
8 3 0 ffffff
9 3 0 ffffff
10 3 0 ffffff
11 3 0 ffffff
12 3 0 ffffff
13 3 0 ffffff
14 3 0 ffffff
15 3 0 ffffff
0 4 0 ffffff
1 4 0 ffffff
2 4 0 ffffff
3 4 0 ffffff
4 4 0 ffffff
5 4 0 ffffff
6 4 0 ffffff
7 4 0 ffffff
8 4 0 ffffff
9 4 0 ffffff
10 4 0 ffffff
11 4 0 ffffff
12 4 0 ffffff
13 4 0 ffffff
14 4 0 ffffff
15 4 0 ffffff
0 5 0 ffffff
1 5 0 ffffff
2 5 0 ffffff
3 5 0 ffffff
4 5 0 ffffff
5 5 0 ffffff
6 5 0 ffffff
7 5 0 ffffff
8 5 0 ffffff
9 5 0 ffffff
10 5 0 ffffff
11 5 0 ffffff
12 5 0 ffffff
13 5 0 ffffff
14 5 0 ffffff
15 5 0 ffffff
0 6 0 ffffff
1 6 0 ffffff
2 6 0 ffffff
3 6 0 ffffff
4 6 0 ffffff
5 6 0 ffffff
6 6 0 ffffff
7 6 0 ffffff
8 6 0 ffffff
9 6 0 ffffff
10 6 0 ffffff
11 6 0 ffffff
12 6 0 ffffff
13 6 0 ffffff
14 6 0 ffffff
15 6 0 ffffff
0 7 0 ffffff
1 7 0 ffffff
2 7 0 ffffff
3 7 0 ffffff
4 7 0 ffffff
5 7 0 ffffff
6 7 0 ffffff
7 7 0 ffffff
8 7 0 ffffff
9 7 0 ffffff
10 7 0 ffffff
11 7 0 ffffff
12 7 0 ffffff
13 7 0 ffffff
14 7 0 ffffff
15 7 0 ffffff
0 8 0 ffffff
1 8 0 ffffff
2 8 0 ffffff
3 8 0 ffffff
4 8 0 ffffff
5 8 0 ffffff
6 8 0 ffffff
7 8 0 ffffff
8 8 0 ffffff
9 8 0 ffffff
10 8 0 ffffff
11 8 0 ffffff
12 8 0 ffffff
13 8 0 ffffff
14 8 0 ffffff
15 8 0 ffffff
0 9 0 ffffff
1 9 0 ffffff
2 9 0 ffffff
3 9 0 ffffff
4 9 0 ffffff
5 9 0 ffffff
6 9 0 ffffff
7 9 0 ffffff
8 9 0 ffffff
9 9 0 ffffff
10 9 0 ffffff
11 9 0 ffffff
12 9 0 ffffff
13 9 0 ffffff
14 9 0 ffffff
15 9 0 ffffff
0 10 0 ffffff
1 10 0 ffffff
2 10 0 ffffff
3 10 0 ffffff
4 10 0 ffffff
5 10 0 ffffff
6 10 0 ffffff
7 10 0 ffffff
8 10 0 ffffff
9 10 0 ffffff
10 10 0 ffffff
11 10 0 ffffff
12 10 0 ffffff
13 10 0 ffffff
14 10 0 ffffff
15 10 0 ffffff
0 11 0 ffffff
1 11 0 ffffff
2 11 0 ffffff
3 11 0 ffffff
4 11 0 ffffff
5 11 0 ffffff
6 11 0 ffffff
7 11 0 ffffff
8 11 0 ffffff
9 11 0 ffffff
10 11 0 ffffff
11 11 0 ffffff
12 11 0 ffffff
13 11 0 ffffff
14 11 0 ffffff
15 11 0 ffffff
0 12 0 ffffff
1 12 0 ffffff
2 12 0 ffffff
3 12 0 ffffff
4 12 0 ffffff
5 12 0 ffffff
6 12 0 ffffff
7 12 0 ffffff
8 12 0 ffffff
9 12 0 ffffff
10 12 0 ffffff
11 12 0 ffffff
12 12 0 ffffff
13 12 0 ffffff
14 12 0 ffffff
15 12 0 ffffff
0 13 0 ffffff
1 13 0 ffffff
2 13 0 ffffff
3 13 0 ffffff
4 13 0 ffffff
5 13 0 ffffff
6 13 0 ffffff
7 13 0 ffffff
8 13 0 ffffff
9 13 0 ffffff
10 13 0 ffffff
11 13 0 ffffff
12 13 0 ffffff
13 13 0 ffffff
14 13 0 ffffff
15 13 0 ffffff
0 14 0 ffffff
1 14 0 ffffff
2 14 0 ffffff
3 14 0 ffffff
4 14 0 ffffff
5 14 0 ffffff
6 14 0 ffffff
7 14 0 ffffff
8 14 0 ffffff
9 14 0 ffffff
10 14 0 ffffff
11 14 0 ffffff
12 14 0 ffffff
13 14 0 ffffff
14 14 0 ffffff
15 14 0 ffffff
0 15 0 ffffff
1 15 0 ffffff
2 15 0 ffffff
3 15 0 ffffff
4 15 0 ffffff
5 15 0 ffffff
6 15 0 ffffff
7 15 0 ffffff
8 15 0 ffffff
9 15 0 ffffff
10 15 0 ffffff
11 15 0 ffffff
12 15 0 ffffff
13 15 0 ffffff
14 15 0 ffffff
15 15 0 ffffff
1 0 1 ffffff
2 0 1 ffffff
3 0 1 ffffff
4 0 1 ffffff
5 0 1 ffffff
6 0 1 ffffff
7 0 1 ffffff
8 0 1 ffffff
9 0 1 ffffff
10 0 1 ffffff
11 0 1 ffffff
12 0 1 ffffff
13 0 1 ffffff
14 0 1 ffffff
15 0 1 ffffff
0 1 1 ffffff
1 1 1 ffffff
2 1 1 ffffff
3 1 1 ffffff
4 1 1 ffffff
5 1 1 ffffff
6 1 1 ffffff
7 1 1 ffffff
8 1 1 ffffff
9 1 1 ffffff
10 1 1 ffffff
11 1 1 ffffff
12 1 1 ffffff
13 1 1 ffffff
14 1 1 ffffff
15 1 1 ffffff
0 2 1 ffffff
1 2 1 ffffff
2 2 1 ffffff
3 2 1 ffffff
4 2 1 ffffff
5 2 1 ffffff
6 2 1 ffffff
7 2 1 ffffff
8 2 1 ffffff
9 2 1 ffffff
10 2 1 ffffff
11 2 1 ffffff
12 2 1 ffffff
13 2 1 ffffff
14 2 1 ffffff
15 2 1 ffffff
0 3 1 ffffff
1 3 1 ffffff
2 3 1 ffffff
3 3 1 ffffff
4 3 1 ffffff
5 3 1 ffffff
6 3 1 ffffff
7 3 1 ffffff
8 3 1 ffffff
9 3 1 ffffff
10 3 1 ffffff
11 3 1 ffffff
12 3 1 ffffff
13 3 1 ffffff
14 3 1 ffffff
15 3 1 ffffff
0 4 1 ffffff
1 4 1 ffffff
2 4 1 ffffff
3 4 1 ffffff
4 4 1 ffffff
5 4 1 ffffff
6 4 1 ffffff
7 4 1 ffffff
8 4 1 ffffff
9 4 1 ffffff
10 4 1 ffffff
11 4 1 ffffff
12 4 1 ffffff
13 4 1 ffffff
14 4 1 ffffff
15 4 1 ffffff
0 5 1 ffffff
1 5 1 ffffff
2 5 1 ffffff
3 5 1 ffffff
4 5 1 ffffff
5 5 1 ffffff
6 5 1 ffffff
7 5 1 ffffff
8 5 1 ffffff
9 5 1 ffffff
10 5 1 ffffff
11 5 1 ffffff
12 5 1 ffffff
13 5 1 ffffff
14 5 1 ffffff
15 5 1 ffffff
0 6 1 ffffff
1 6 1 ffffff
2 6 1 ffffff
3 6 1 ffffff
4 6 1 ffffff
5 6 1 ffffff
6 6 1 ffffff
7 6 1 ffffff
8 6 1 ffffff
9 6 1 ffffff
10 6 1 ffffff
11 6 1 ffffff
12 6 1 ffffff
13 6 1 ffffff
14 6 1 ffffff
15 6 1 ffffff
0 7 1 ffffff
1 7 1 ffffff
2 7 1 ffffff
3 7 1 ffffff
4 7 1 ffffff
5 7 1 ffffff
6 7 1 ffffff
7 7 1 ffffff
8 7 1 ffffff
9 7 1 ffffff
10 7 1 ffffff
11 7 1 ffffff
12 7 1 ffffff
13 7 1 ffffff
14 7 1 ffffff
15 7 1 ffffff
0 8 1 ffffff
1 8 1 ffffff
2 8 1 ffffff
3 8 1 ffffff
4 8 1 ffffff
5 8 1 ffffff
6 8 1 ffffff
7 8 1 ffffff
8 8 1 ffffff
9 8 1 ffffff
10 8 1 ffffff
11 8 1 ffffff
12 8 1 ffffff
13 8 1 ffffff
14 8 1 ffffff
15 8 1 ffffff
0 9 1 ffffff
1 9 1 ffffff
2 9 1 ffffff
3 9 1 ffffff
4 9 1 ffffff
5 9 1 ffffff
6 9 1 ffffff
7 9 1 ffffff
8 9 1 ffffff
9 9 1 ffffff
10 9 1 ffffff
11 9 1 ffffff
12 9 1 ffffff
13 9 1 ffffff
14 9 1 ffffff
15 9 1 ffffff
0 10 1 ffffff
1 10 1 ffffff
2 10 1 ffffff
3 10 1 ffffff
4 10 1 ffffff
5 10 1 ffffff
6 10 1 ffffff
7 10 1 ffffff
8 10 1 ffffff
9 10 1 ffffff
10 10 1 ffffff
11 10 1 ffffff
12 10 1 ffffff
13 10 1 ffffff
14 10 1 ffffff
15 10 1 ffffff
0 11 1 ffffff
1 11 1 ffffff
2 11 1 ffffff
3 11 1 ffffff
4 11 1 ffffff
5 11 1 ffffff
6 11 1 ffffff
7 11 1 ffffff
8 11 1 ffffff
9 11 1 ffffff
10 11 1 ffffff
11 11 1 ffffff
12 11 1 ffffff
13 11 1 ffffff
14 11 1 ffffff
15 11 1 ffffff
0 12 1 ffffff
1 12 1 ffffff
2 12 1 ffffff
3 12 1 ffffff
4 12 1 ffffff
5 12 1 ffffff
6 12 1 ffffff
7 12 1 ffffff
8 12 1 ffffff
9 12 1 ffffff
10 12 1 ffffff
11 12 1 ffffff
12 12 1 ffffff
13 12 1 ffffff
14 12 1 ffffff
15 12 1 ffffff
0 13 1 ffffff
1 13 1 ffffff
2 13 1 ffffff
3 13 1 ffffff
4 13 1 ffffff
5 13 1 ffffff
6 13 1 ffffff
7 13 1 ffffff
8 13 1 ffffff
9 13 1 ffffff
10 13 1 ffffff
11 13 1 ffffff
12 13 1 ffffff
13 13 1 ffffff
14 13 1 ffffff
15 13 1 ffffff
0 14 1 ffffff
1 14 1 ffffff
2 14 1 ffffff
3 14 1 ffffff
4 14 1 ffffff
5 14 1 ffffff
6 14 1 ffffff
7 14 1 ffffff
8 14 1 ffffff
9 14 1 ffffff
10 14 1 ffffff
11 14 1 ffffff
12 14 1 ffffff
13 14 1 ffffff
14 14 1 ffffff
15 14 1 ffffff
0 15 1 ffffff
1 15 1 ffffff
2 15 1 ffffff
3 15 1 ffffff
4 15 1 ffffff
5 15 1 ffffff
6 15 1 ffffff
7 15 1 ffffff
8 15 1 ffffff
9 15 1 ffffff
10 15 1 ffffff
11 15 1 ffffff
12 15 1 ffffff
13 15 1 ffffff
14 15 1 ffffff
15 15 1 ffffff
1 0 2 ffffff
2 0 2 ffffff
3 0 2 ffffff
4 0 2 ffffff
5 0 2 ffffff
6 0 2 ffffff
7 0 2 ffffff
8 0 2 ffffff
9 0 2 ffffff
10 0 2 ffffff
11 0 2 ffffff
12 0 2 ffffff
13 0 2 ffffff
14 0 2 ffffff
15 0 2 ffffff
0 1 2 ffffff
1 1 2 ffffff
2 1 2 ffffff
3 1 2 ffffff
4 1 2 ffffff
5 1 2 ffffff
6 1 2 ffffff
7 1 2 ffffff
8 1 2 ffffff
9 1 2 ffffff
10 1 2 ffffff
11 1 2 ffffff
12 1 2 ffffff
13 1 2 ffffff
14 1 2 ffffff
15 1 2 ffffff
0 2 2 ffffff
1 2 2 ffffff
2 2 2 ffffff
3 2 2 ffffff
4 2 2 ffffff
5 2 2 ffffff
6 2 2 ffffff
7 2 2 ffffff
8 2 2 ffffff
9 2 2 ffffff
10 2 2 ffffff
11 2 2 ffffff
12 2 2 ffffff
13 2 2 ffffff
14 2 2 ffffff
15 2 2 ffffff
0 3 2 ffffff
1 3 2 ffffff
2 3 2 ffffff
3 3 2 ffffff
4 3 2 ffffff
5 3 2 ffffff
6 3 2 ffffff
7 3 2 ffffff
8 3 2 ffffff
9 3 2 ffffff
10 3 2 ffffff
11 3 2 ffffff
12 3 2 ffffff
13 3 2 ffffff
14 3 2 ffffff
15 3 2 ffffff
0 4 2 ffffff
1 4 2 ffffff
2 4 2 ffffff
3 4 2 ffffff
4 4 2 ffffff
5 4 2 ffffff
6 4 2 ffffff
7 4 2 ffffff
8 4 2 ffffff
9 4 2 ffffff
10 4 2 ffffff
11 4 2 ffffff
12 4 2 ffffff
13 4 2 ffffff
14 4 2 ffffff
15 4 2 ffffff
0 5 2 ffffff
1 5 2 ffffff
2 5 2 ffffff
3 5 2 ffffff
4 5 2 ffffff
5 5 2 ffffff
6 5 2 ffffff
7 5 2 ffffff
8 5 2 ffffff
9 5 2 ffffff
10 5 2 ffffff
11 5 2 ffffff
12 5 2 ffffff
13 5 2 ffffff
14 5 2 ffffff
15 5 2 ffffff
0 6 2 ffffff
1 6 2 ffffff
2 6 2 ffffff
3 6 2 ffffff
4 6 2 ffffff
5 6 2 ffffff
6 6 2 ffffff
7 6 2 ffffff
8 6 2 ffffff
9 6 2 ffffff
10 6 2 ffffff
11 6 2 ffffff
12 6 2 ffffff
13 6 2 ffffff
14 6 2 ffffff
15 6 2 ffffff
0 7 2 ffffff
1 7 2 ffffff
2 7 2 ffffff
3 7 2 ffffff
4 7 2 ffffff
5 7 2 ffffff
6 7 2 ffffff
7 7 2 ffffff
8 7 2 ffffff
9 7 2 ffffff
10 7 2 ffffff
11 7 2 ffffff
12 7 2 ffffff
13 7 2 ffffff
14 7 2 ffffff
15 7 2 ffffff
0 8 2 ffffff
1 8 2 ffffff
2 8 2 ffffff
3 8 2 ffffff
4 8 2 ffffff
5 8 2 ffffff
6 8 2 ffffff
7 8 2 ffffff
8 8 2 ffffff
9 8 2 ffffff
10 8 2 ffffff
11 8 2 ffffff
12 8 2 ffffff
13 8 2 ffffff
14 8 2 ffffff
15 8 2 ffffff
0 9 2 ffffff
1 9 2 ffffff
2 9 2 ffffff
3 9 2 ffffff
4 9 2 ffffff
5 9 2 ffffff
6 9 2 ffffff
7 9 2 ffffff
8 9 2 ffffff
9 9 2 ffffff
10 9 2 ffffff
11 9 2 ffffff
12 9 2 ffffff
13 9 2 ffffff
14 9 2 ffffff
15 9 2 ffffff
0 10 2 ffffff
1 10 2 ffffff
2 10 2 ffffff
3 10 2 ffffff
4 10 2 ffffff
5 10 2 ffffff
6 10 2 ffffff
7 10 2 ffffff
8 10 2 ffffff
9 10 2 ffffff
10 10 2 ffffff
11 10 2 ffffff
12 10 2 ffffff
13 10 2 ffffff
14 10 2 ffffff
15 10 2 ffffff
0 11 2 ffffff
1 11 2 ffffff
2 11 2 ffffff
3 11 2 ffffff
4 11 2 ffffff
5 11 2 ffffff
6 11 2 ffffff
7 11 2 ffffff
8 11 2 ffffff
9 11 2 ffffff
10 11 2 ffffff
11 11 2 ffffff
12 11 2 ffffff
13 11 2 ffffff
14 11 2 ffffff
15 11 2 ffffff
0 12 2 ffffff
1 12 2 ffffff
2 12 2 ffffff
3 12 2 ffffff
4 12 2 ffffff
5 12 2 ffffff
6 12 2 ffffff
7 12 2 ffffff
8 12 2 ffffff
9 12 2 ffffff
10 12 2 ffffff
11 12 2 ffffff
12 12 2 ffffff
13 12 2 ffffff
14 12 2 ffffff
15 12 2 ffffff
0 13 2 ffffff
1 13 2 ffffff
2 13 2 ffffff
3 13 2 ffffff
4 13 2 ffffff
5 13 2 ffffff
6 13 2 ffffff
7 13 2 ffffff
8 13 2 ffffff
9 13 2 ffffff
10 13 2 ffffff
11 13 2 ffffff
12 13 2 ffffff
13 13 2 ffffff
14 13 2 ffffff
15 13 2 ffffff
0 14 2 ffffff
1 14 2 ffffff
2 14 2 ffffff
3 14 2 ffffff
4 14 2 ffffff
5 14 2 ffffff
6 14 2 ffffff
7 14 2 ffffff
8 14 2 ffffff
9 14 2 ffffff
10 14 2 ffffff
11 14 2 ffffff
12 14 2 ffffff
13 14 2 ffffff
14 14 2 ffffff
15 14 2 ffffff
0 15 2 ffffff
1 15 2 ffffff
2 15 2 ffffff
3 15 2 ffffff
4 15 2 ffffff
5 15 2 ffffff
6 15 2 ffffff
7 15 2 ffffff
8 15 2 ffffff
9 15 2 ffffff
10 15 2 ffffff
11 15 2 ffffff
12 15 2 ffffff
13 15 2 ffffff
14 15 2 ffffff
15 15 2 ffffff
1 0 3 ffffff
2 0 3 ffffff
3 0 3 ffffff
4 0 3 ffffff
5 0 3 ffffff
6 0 3 ffffff
7 0 3 ffffff
8 0 3 ffffff
9 0 3 ffffff
10 0 3 ffffff
11 0 3 ffffff
12 0 3 ffffff
13 0 3 ffffff
14 0 3 ffffff
15 0 3 ffffff
0 1 3 ffffff
1 1 3 ffffff
2 1 3 ffffff
3 1 3 ffffff
4 1 3 ffffff
5 1 3 ffffff
6 1 3 ffffff
7 1 3 ffffff
8 1 3 ffffff
9 1 3 ffffff
10 1 3 ffffff
11 1 3 ffffff
12 1 3 ffffff
13 1 3 ffffff
14 1 3 ffffff
15 1 3 ffffff
0 2 3 ffffff
1 2 3 ffffff
2 2 3 ffffff
3 2 3 ffffff
4 2 3 ffffff
5 2 3 ffffff
6 2 3 ffffff
7 2 3 ffffff
8 2 3 ffffff
9 2 3 ffffff
10 2 3 ffffff
11 2 3 ffffff
12 2 3 ffffff
13 2 3 ffffff
14 2 3 ffffff
15 2 3 ffffff
0 3 3 ffffff
1 3 3 ffffff
2 3 3 ffffff
3 3 3 ffffff
4 3 3 ffffff
5 3 3 ffffff
6 3 3 ffffff
7 3 3 ffffff
8 3 3 ffffff
9 3 3 ffffff
10 3 3 ffffff
11 3 3 ffffff
12 3 3 ffffff
13 3 3 ffffff
14 3 3 ffffff
15 3 3 ffffff
0 4 3 ffffff
1 4 3 ffffff
2 4 3 ffffff
3 4 3 ffffff
4 4 3 ffffff
5 4 3 ffffff
6 4 3 ffffff
7 4 3 ffffff
8 4 3 ffffff
9 4 3 ffffff
10 4 3 ffffff
11 4 3 ffffff
12 4 3 ffffff
13 4 3 ffffff
14 4 3 ffffff
15 4 3 ffffff
0 5 3 ffffff
1 5 3 ffffff
2 5 3 ffffff
3 5 3 ffffff
4 5 3 ffffff
5 5 3 ffffff
6 5 3 ffffff
7 5 3 ffffff
8 5 3 ffffff
9 5 3 ffffff
10 5 3 ffffff
11 5 3 ffffff
12 5 3 ffffff
13 5 3 ffffff
14 5 3 ffffff
15 5 3 ffffff
0 6 3 ffffff
1 6 3 ffffff
2 6 3 ffffff
3 6 3 ffffff
4 6 3 ffffff
5 6 3 ffffff
6 6 3 ffffff
7 6 3 ffffff
8 6 3 ffffff
9 6 3 ffffff
10 6 3 ffffff
11 6 3 ffffff
12 6 3 ffffff
13 6 3 ffffff
14 6 3 ffffff
15 6 3 ffffff
0 7 3 ffffff
1 7 3 ffffff
2 7 3 ffffff
3 7 3 ffffff
4 7 3 ffffff
5 7 3 ffffff
6 7 3 ffffff
7 7 3 ffffff
8 7 3 ffffff
9 7 3 ffffff
10 7 3 ffffff
11 7 3 ffffff
12 7 3 ffffff
13 7 3 ffffff
14 7 3 ffffff
15 7 3 ffffff
0 8 3 ffffff
1 8 3 ffffff
2 8 3 ffffff
3 8 3 ffffff
4 8 3 ffffff
5 8 3 ffffff
6 8 3 ffffff
7 8 3 ffffff
8 8 3 ffffff
9 8 3 ffffff
10 8 3 ffffff
11 8 3 ffffff
12 8 3 ffffff
13 8 3 ffffff
14 8 3 ffffff
15 8 3 ffffff
0 9 3 ffffff
1 9 3 ffffff
2 9 3 ffffff
3 9 3 ffffff
4 9 3 ffffff
5 9 3 ffffff
6 9 3 ffffff
7 9 3 ffffff
8 9 3 ffffff
9 9 3 ffffff
10 9 3 ffffff
11 9 3 ffffff
12 9 3 ffffff
13 9 3 ffffff
14 9 3 ffffff
15 9 3 ffffff
0 10 3 ffffff
1 10 3 ffffff
2 10 3 ffffff
3 10 3 ffffff
4 10 3 ffffff
5 10 3 ffffff
6 10 3 ffffff
7 10 3 ffffff
8 10 3 ffffff
9 10 3 ffffff
10 10 3 ffffff
11 10 3 ffffff
12 10 3 ffffff
13 10 3 ffffff
14 10 3 ffffff
15 10 3 ffffff
0 11 3 ffffff
1 11 3 ffffff
2 11 3 ffffff
3 11 3 ffffff
4 11 3 ffffff
5 11 3 ffffff
6 11 3 ffffff
7 11 3 ffffff
8 11 3 ffffff
9 11 3 ffffff
10 11 3 ffffff
11 11 3 ffffff
12 11 3 ffffff
13 11 3 ffffff
14 11 3 ffffff
15 11 3 ffffff
0 12 3 ffffff
1 12 3 ffffff
2 12 3 ffffff
3 12 3 ffffff
4 12 3 ffffff
5 12 3 ffffff
6 12 3 ffffff
7 12 3 ffffff
8 12 3 ffffff
9 12 3 ffffff
10 12 3 ffffff
11 12 3 ffffff
12 12 3 ffffff
13 12 3 ffffff
14 12 3 ffffff
15 12 3 ffffff
0 13 3 ffffff
1 13 3 ffffff
2 13 3 ffffff
3 13 3 ffffff
4 13 3 ffffff
5 13 3 ffffff
6 13 3 ffffff
7 13 3 ffffff
8 13 3 ffffff
9 13 3 ffffff
10 13 3 ffffff
11 13 3 ffffff
12 13 3 ffffff
13 13 3 ffffff
14 13 3 ffffff
15 13 3 ffffff
0 14 3 ffffff
1 14 3 ffffff
2 14 3 ffffff
3 14 3 ffffff
4 14 3 ffffff
5 14 3 ffffff
6 14 3 ffffff
7 14 3 ffffff
8 14 3 ffffff
9 14 3 ffffff
10 14 3 ffffff
11 14 3 ffffff
12 14 3 ffffff
13 14 3 ffffff
14 14 3 ffffff
15 14 3 ffffff
0 15 3 ffffff
1 15 3 ffffff
2 15 3 ffffff
3 15 3 ffffff
4 15 3 ffffff
5 15 3 ffffff
6 15 3 ffffff
7 15 3 ffffff
8 15 3 ffffff
9 15 3 ffffff
10 15 3 ffffff
11 15 3 ffffff
12 15 3 ffffff
13 15 3 ffffff
14 15 3 ffffff
15 15 3 ffffff
1 0 4 ffffff
2 0 4 ffffff
3 0 4 ffffff
4 0 4 ffffff
5 0 4 ffffff
6 0 4 ffffff
7 0 4 ffffff
8 0 4 ffffff
9 0 4 ffffff
10 0 4 ffffff
11 0 4 ffffff
12 0 4 ffffff
13 0 4 ffffff
14 0 4 ffffff
15 0 4 ffffff
0 1 4 ffffff
1 1 4 ffffff
2 1 4 ffffff
3 1 4 ffffff
4 1 4 ffffff
5 1 4 ffffff
6 1 4 ffffff
7 1 4 ffffff
8 1 4 ffffff
9 1 4 ffffff
10 1 4 ffffff
11 1 4 ffffff
12 1 4 ffffff
13 1 4 ffffff
14 1 4 ffffff
15 1 4 ffffff
0 2 4 ffffff
1 2 4 ffffff
2 2 4 ffffff
3 2 4 ffffff
4 2 4 ffffff
5 2 4 ffffff
6 2 4 ffffff
7 2 4 ffffff
8 2 4 ffffff
9 2 4 ffffff
10 2 4 ffffff
11 2 4 ffffff
12 2 4 ffffff
13 2 4 ffffff
14 2 4 ffffff
15 2 4 ffffff
0 3 4 ffffff
1 3 4 ffffff
2 3 4 ffffff
3 3 4 ffffff
4 3 4 ffffff
5 3 4 ffffff
6 3 4 ffffff
7 3 4 ffffff
8 3 4 ffffff
9 3 4 ffffff
10 3 4 ffffff
11 3 4 ffffff
12 3 4 ffffff
13 3 4 ffffff
14 3 4 ffffff
15 3 4 ffffff
0 4 4 ffffff
1 4 4 ffffff
2 4 4 ffffff
3 4 4 ffffff
4 4 4 ffffff
5 4 4 ffffff
6 4 4 ffffff
7 4 4 ffffff
8 4 4 ffffff
9 4 4 ffffff
10 4 4 ffffff
11 4 4 ffffff
12 4 4 ffffff
13 4 4 ffffff
14 4 4 ffffff
15 4 4 ffffff
0 5 4 ffffff
1 5 4 ffffff
2 5 4 ffffff
3 5 4 ffffff
4 5 4 ffffff
5 5 4 ffffff
6 5 4 ffffff
7 5 4 ffffff
8 5 4 ffffff
9 5 4 ffffff
10 5 4 ffffff
11 5 4 ffffff
12 5 4 ffffff
13 5 4 ffffff
14 5 4 ffffff
15 5 4 ffffff
0 6 4 ffffff
1 6 4 ffffff
2 6 4 ffffff
3 6 4 ffffff
4 6 4 ffffff
5 6 4 ffffff
6 6 4 ffffff
7 6 4 ffffff
8 6 4 ffffff
9 6 4 ffffff
10 6 4 ffffff
11 6 4 ffffff
12 6 4 ffffff
13 6 4 ffffff
14 6 4 ffffff
15 6 4 ffffff
0 7 4 ffffff
1 7 4 ffffff
2 7 4 ffffff
3 7 4 ffffff
4 7 4 ffffff
5 7 4 ffffff
6 7 4 ffffff
7 7 4 ffffff
8 7 4 ffffff
9 7 4 ffffff
10 7 4 ffffff
11 7 4 ffffff
12 7 4 ffffff
13 7 4 ffffff
14 7 4 ffffff
15 7 4 ffffff
0 8 4 ffffff
1 8 4 ffffff
2 8 4 ffffff
3 8 4 ffffff
4 8 4 ffffff
5 8 4 ffffff
6 8 4 ffffff
7 8 4 ffffff
8 8 4 ffffff
9 8 4 ffffff
10 8 4 ffffff
11 8 4 ffffff
12 8 4 ffffff
13 8 4 ffffff
14 8 4 ffffff
15 8 4 ffffff
0 9 4 ffffff
1 9 4 ffffff
2 9 4 ffffff
3 9 4 ffffff
4 9 4 ffffff
5 9 4 ffffff
6 9 4 ffffff
7 9 4 ffffff
8 9 4 ffffff
9 9 4 ffffff
10 9 4 ffffff
11 9 4 ffffff
12 9 4 ffffff
13 9 4 ffffff
14 9 4 ffffff
15 9 4 ffffff
0 10 4 ffffff
1 10 4 ffffff
2 10 4 ffffff
3 10 4 ffffff
4 10 4 ffffff
5 10 4 ffffff
6 10 4 ffffff
7 10 4 ffffff
8 10 4 ffffff
9 10 4 ffffff
10 10 4 ffffff
11 10 4 ffffff
12 10 4 ffffff
13 10 4 ffffff
14 10 4 ffffff
15 10 4 ffffff
0 11 4 ffffff
1 11 4 ffffff
2 11 4 ffffff
3 11 4 ffffff
4 11 4 ffffff
5 11 4 ffffff
6 11 4 ffffff
7 11 4 ffffff
8 11 4 ffffff
9 11 4 ffffff
10 11 4 ffffff
11 11 4 ffffff
12 11 4 ffffff
13 11 4 ffffff
14 11 4 ffffff
15 11 4 ffffff
0 12 4 ffffff
1 12 4 ffffff
2 12 4 ffffff
3 12 4 ffffff
4 12 4 ffffff
5 12 4 ffffff
6 12 4 ffffff
7 12 4 ffffff
8 12 4 ffffff
9 12 4 ffffff
10 12 4 ffffff
11 12 4 ffffff
12 12 4 ffffff
13 12 4 ffffff
14 12 4 ffffff
15 12 4 ffffff
0 13 4 ffffff
1 13 4 ffffff
2 13 4 ffffff
3 13 4 ffffff
4 13 4 ffffff
5 13 4 ffffff
6 13 4 ffffff
7 13 4 ffffff
8 13 4 ffffff
9 13 4 ffffff
10 13 4 ffffff
11 13 4 ffffff
12 13 4 ffffff
13 13 4 ffffff
14 13 4 ffffff
15 13 4 ffffff
0 14 4 ffffff
1 14 4 ffffff
2 14 4 ffffff
3 14 4 ffffff
4 14 4 ffffff
5 14 4 ffffff
6 14 4 ffffff
7 14 4 ffffff
8 14 4 ffffff
9 14 4 ffffff
10 14 4 ffffff
11 14 4 ffffff
12 14 4 ffffff
13 14 4 ffffff
14 14 4 ffffff
15 14 4 ffffff
0 15 4 ffffff
1 15 4 ffffff
2 15 4 ffffff
3 15 4 ffffff
4 15 4 ffffff
5 15 4 ffffff
6 15 4 ffffff
7 15 4 ffffff
8 15 4 ffffff
9 15 4 ffffff
10 15 4 ffffff
11 15 4 ffffff
12 15 4 ffffff
13 15 4 ffffff
14 15 4 ffffff
15 15 4 ffffff
1 0 5 ffffff
2 0 5 ffffff
3 0 5 ffffff
4 0 5 ffffff
5 0 5 ffffff
6 0 5 ffffff
7 0 5 ffffff
8 0 5 ffffff
9 0 5 ffffff
10 0 5 ffffff
11 0 5 ffffff
12 0 5 ffffff
13 0 5 ffffff
14 0 5 ffffff
15 0 5 ffffff
0 1 5 ffffff
1 1 5 ffffff
2 1 5 ffffff
3 1 5 ffffff
4 1 5 ffffff
5 1 5 ffffff
6 1 5 ffffff
7 1 5 ffffff
8 1 5 ffffff
9 1 5 ffffff
10 1 5 ffffff
11 1 5 ffffff
12 1 5 ffffff
13 1 5 ffffff
14 1 5 ffffff
15 1 5 ffffff
0 2 5 ffffff
1 2 5 ffffff
2 2 5 ffffff
3 2 5 ffffff
4 2 5 ffffff
5 2 5 ffffff
6 2 5 ffffff
7 2 5 ffffff
8 2 5 ffffff
9 2 5 ffffff
10 2 5 ffffff
11 2 5 ffffff
12 2 5 ffffff
13 2 5 ffffff
14 2 5 ffffff
15 2 5 ffffff
0 3 5 ffffff
1 3 5 ffffff
2 3 5 ffffff
3 3 5 ffffff
4 3 5 ffffff
5 3 5 ffffff
6 3 5 ffffff
7 3 5 ffffff
8 3 5 ffffff
9 3 5 ffffff
10 3 5 ffffff
11 3 5 ffffff
12 3 5 ffffff
13 3 5 ffffff
14 3 5 ffffff
15 3 5 ffffff
0 4 5 ffffff
1 4 5 ffffff
2 4 5 ffffff
3 4 5 ffffff
4 4 5 ffffff
5 4 5 ffffff
6 4 5 ffffff
7 4 5 ffffff
8 4 5 ffffff
9 4 5 ffffff
10 4 5 ffffff
11 4 5 ffffff
12 4 5 ffffff
13 4 5 ffffff
14 4 5 ffffff
15 4 5 ffffff
0 5 5 ffffff
1 5 5 ffffff
2 5 5 ffffff
3 5 5 ffffff
4 5 5 ffffff
5 5 5 ffffff
6 5 5 ffffff
7 5 5 ffffff
8 5 5 ffffff
9 5 5 ffffff
10 5 5 ffffff
11 5 5 ffffff
12 5 5 ffffff
13 5 5 ffffff
14 5 5 ffffff
15 5 5 ffffff
0 6 5 ffffff
1 6 5 ffffff
2 6 5 ffffff
3 6 5 ffffff
4 6 5 ffffff
5 6 5 ffffff
6 6 5 ffffff
7 6 5 ffffff
8 6 5 ffffff
9 6 5 ffffff
10 6 5 ffffff
11 6 5 ffffff
12 6 5 ffffff
13 6 5 ffffff
14 6 5 ffffff
15 6 5 ffffff
0 7 5 ffffff
1 7 5 ffffff
2 7 5 ffffff
3 7 5 ffffff
4 7 5 ffffff
5 7 5 ffffff
6 7 5 ffffff
7 7 5 ffffff
8 7 5 ffffff
9 7 5 ffffff
10 7 5 ffffff
11 7 5 ffffff
12 7 5 ffffff
13 7 5 ffffff
14 7 5 ffffff
15 7 5 ffffff
0 8 5 ffffff
1 8 5 ffffff
2 8 5 ffffff
3 8 5 ffffff
4 8 5 ffffff
5 8 5 ffffff
6 8 5 ffffff
7 8 5 ffffff
8 8 5 ffffff
9 8 5 ffffff
10 8 5 ffffff
11 8 5 ffffff
12 8 5 ffffff
13 8 5 ffffff
14 8 5 ffffff
15 8 5 ffffff
0 9 5 ffffff
1 9 5 ffffff
2 9 5 ffffff
3 9 5 ffffff
4 9 5 ffffff
5 9 5 ffffff
6 9 5 ffffff
7 9 5 ffffff
8 9 5 ffffff
9 9 5 ffffff
10 9 5 ffffff
11 9 5 ffffff
12 9 5 ffffff
13 9 5 ffffff
14 9 5 ffffff
15 9 5 ffffff
0 10 5 ffffff
1 10 5 ffffff
2 10 5 ffffff
3 10 5 ffffff
4 10 5 ffffff
5 10 5 ffffff
6 10 5 ffffff
7 10 5 ffffff
8 10 5 ffffff
9 10 5 ffffff
10 10 5 ffffff
11 10 5 ffffff
12 10 5 ffffff
13 10 5 ffffff
14 10 5 ffffff
15 10 5 ffffff
0 11 5 ffffff
1 11 5 ffffff
2 11 5 ffffff
3 11 5 ffffff
4 11 5 ffffff
5 11 5 ffffff
6 11 5 ffffff
7 11 5 ffffff
8 11 5 ffffff
9 11 5 ffffff
10 11 5 ffffff
11 11 5 ffffff
12 11 5 ffffff
13 11 5 ffffff
14 11 5 ffffff
15 11 5 ffffff
0 12 5 ffffff
1 12 5 ffffff
2 12 5 ffffff
3 12 5 ffffff
4 12 5 ffffff
5 12 5 ffffff
6 12 5 ffffff
7 12 5 ffffff
8 12 5 ffffff
9 12 5 ffffff
10 12 5 ffffff
11 12 5 ffffff
12 12 5 ffffff
13 12 5 ffffff
14 12 5 ffffff
15 12 5 ffffff
0 13 5 ffffff
1 13 5 ffffff
2 13 5 ffffff
3 13 5 ffffff
4 13 5 ffffff
5 13 5 ffffff
6 13 5 ffffff
7 13 5 ffffff
8 13 5 ffffff
9 13 5 ffffff
10 13 5 ffffff
11 13 5 ffffff
12 13 5 ffffff
13 13 5 ffffff
14 13 5 ffffff
15 13 5 ffffff
0 14 5 ffffff
1 14 5 ffffff
2 14 5 ffffff
3 14 5 ffffff
4 14 5 ffffff
5 14 5 ffffff
6 14 5 ffffff
7 14 5 ffffff
8 14 5 ffffff
9 14 5 ffffff
10 14 5 ffffff
11 14 5 ffffff
12 14 5 ffffff
13 14 5 ffffff
14 14 5 ffffff
15 14 5 ffffff
0 15 5 ffffff
1 15 5 ffffff
2 15 5 ffffff
3 15 5 ffffff
4 15 5 ffffff
5 15 5 ffffff
6 15 5 ffffff
7 15 5 ffffff
8 15 5 ffffff
9 15 5 ffffff
10 15 5 ffffff
11 15 5 ffffff
12 15 5 ffffff
13 15 5 ffffff
14 15 5 ffffff
15 15 5 ffffff
1 0 6 ffffff
2 0 6 ffffff
3 0 6 ffffff
4 0 6 ffffff
5 0 6 ffffff
6 0 6 ffffff
7 0 6 ffffff
8 0 6 ffffff
9 0 6 ffffff
10 0 6 ffffff
11 0 6 ffffff
12 0 6 ffffff
13 0 6 ffffff
14 0 6 ffffff
15 0 6 ffffff
0 1 6 ffffff
1 1 6 ffffff
2 1 6 ffffff
3 1 6 ffffff
4 1 6 ffffff
5 1 6 ffffff
6 1 6 ffffff
7 1 6 ffffff
8 1 6 ffffff
9 1 6 ffffff
10 1 6 ffffff
11 1 6 ffffff
12 1 6 ffffff
13 1 6 ffffff
14 1 6 ffffff
15 1 6 ffffff
0 2 6 ffffff
1 2 6 ffffff
2 2 6 ffffff
3 2 6 ffffff
4 2 6 ffffff
5 2 6 ffffff
6 2 6 ffffff
7 2 6 ffffff
8 2 6 ffffff
9 2 6 ffffff
10 2 6 ffffff
11 2 6 ffffff
12 2 6 ffffff
13 2 6 ffffff
14 2 6 ffffff
15 2 6 ffffff
0 3 6 ffffff
1 3 6 ffffff
2 3 6 ffffff
3 3 6 ffffff
4 3 6 ffffff
5 3 6 ffffff
6 3 6 ffffff
7 3 6 ffffff
8 3 6 ffffff
9 3 6 ffffff
10 3 6 ffffff
11 3 6 ffffff
12 3 6 ffffff
13 3 6 ffffff
14 3 6 ffffff
15 3 6 ffffff
0 4 6 ffffff
1 4 6 ffffff
2 4 6 ffffff
3 4 6 ffffff
4 4 6 ffffff
5 4 6 ffffff
6 4 6 ffffff
7 4 6 ffffff
8 4 6 ffffff
9 4 6 ffffff
10 4 6 ffffff
11 4 6 ffffff
12 4 6 ffffff
13 4 6 ffffff
14 4 6 ffffff
15 4 6 ffffff
0 5 6 ffffff
1 5 6 ffffff
2 5 6 ffffff
3 5 6 ffffff
4 5 6 ffffff
5 5 6 ffffff
6 5 6 ffffff
7 5 6 ffffff
8 5 6 ffffff
9 5 6 ffffff
10 5 6 ffffff
11 5 6 ffffff
12 5 6 ffffff
13 5 6 ffffff
14 5 6 ffffff
15 5 6 ffffff
0 6 6 ffffff
1 6 6 ffffff
2 6 6 ffffff
3 6 6 ffffff
4 6 6 ffffff
5 6 6 ffffff
6 6 6 ffffff
7 6 6 ffffff
8 6 6 ffffff
9 6 6 ffffff
10 6 6 ffffff
11 6 6 ffffff
12 6 6 ffffff
13 6 6 ffffff
14 6 6 ffffff
15 6 6 ffffff
0 7 6 ffffff
1 7 6 ffffff
2 7 6 ffffff
3 7 6 ffffff
4 7 6 ffffff
5 7 6 ffffff
6 7 6 ffffff
7 7 6 ffffff
8 7 6 ffffff
9 7 6 ffffff
10 7 6 ffffff
11 7 6 ffffff
12 7 6 ffffff
13 7 6 ffffff
14 7 6 ffffff
15 7 6 ffffff
0 8 6 ffffff
1 8 6 ffffff
2 8 6 ffffff
3 8 6 ffffff
4 8 6 ffffff
5 8 6 ffffff
6 8 6 ffffff
7 8 6 ffffff
8 8 6 ffffff
9 8 6 ffffff
10 8 6 ffffff
11 8 6 ffffff
12 8 6 ffffff
13 8 6 ffffff
14 8 6 ffffff
15 8 6 ffffff
0 9 6 ffffff
1 9 6 ffffff
2 9 6 ffffff
3 9 6 ffffff
4 9 6 ffffff
5 9 6 ffffff
6 9 6 ffffff
7 9 6 ffffff
8 9 6 ffffff
0 10 6 ffffff
1 10 6 ffffff
2 10 6 ffffff
3 10 6 ffffff
4 10 6 ffffff
5 10 6 ffffff
6 10 6 ffffff
7 10 6 ffffff
8 10 6 ffffff
0 11 6 ffffff
1 11 6 ffffff
2 11 6 ffffff
3 11 6 ffffff
4 11 6 ffffff
5 11 6 ffffff
6 11 6 ffffff
7 11 6 ffffff
8 11 6 ffffff
0 12 6 ffffff
1 12 6 ffffff
2 12 6 ffffff
3 12 6 ffffff
4 12 6 ffffff
5 12 6 ffffff
6 12 6 ffffff
7 12 6 ffffff
8 12 6 ffffff
0 13 6 ffffff
1 13 6 ffffff
2 13 6 ffffff
3 13 6 ffffff
4 13 6 ffffff
5 13 6 ffffff
6 13 6 ffffff
7 13 6 ffffff
8 13 6 ffffff
0 14 6 ffffff
1 14 6 ffffff
2 14 6 ffffff
3 14 6 ffffff
4 14 6 ffffff
5 14 6 ffffff
6 14 6 ffffff
7 14 6 ffffff
8 14 6 ffffff
0 15 6 ffffff
1 15 6 ffffff
2 15 6 ffffff
3 15 6 ffffff
4 15 6 ffffff
5 15 6 ffffff
6 15 6 ffffff
7 15 6 ffffff
8 15 6 ffffff
1 0 7 ffffff
2 0 7 ffffff
3 0 7 ffffff
4 0 7 ffffff
5 0 7 ffffff
6 0 7 ffffff
7 0 7 ffffff
8 0 7 ffffff
9 0 7 ffffff
10 0 7 ffffff
11 0 7 ffffff
12 0 7 ffffff
13 0 7 ffffff
14 0 7 ffffff
15 0 7 ffffff
0 1 7 ffffff
1 1 7 ffffff
2 1 7 ffffff
3 1 7 ffffff
4 1 7 ffffff
5 1 7 ffffff
6 1 7 ffffff
7 1 7 ffffff
8 1 7 ffffff
9 1 7 ffffff
10 1 7 ffffff
11 1 7 ffffff
12 1 7 ffffff
13 1 7 ffffff
14 1 7 ffffff
15 1 7 ffffff
0 2 7 ffffff
1 2 7 ffffff
2 2 7 ffffff
3 2 7 ffffff
4 2 7 ffffff
5 2 7 ffffff
6 2 7 ffffff
7 2 7 ffffff
8 2 7 ffffff
9 2 7 ffffff
10 2 7 ffffff
11 2 7 ffffff
12 2 7 ffffff
13 2 7 ffffff
14 2 7 ffffff
15 2 7 ffffff
0 3 7 ffffff
1 3 7 ffffff
2 3 7 ffffff
3 3 7 ffffff
4 3 7 ffffff
5 3 7 ffffff
6 3 7 ffffff
7 3 7 ffffff
8 3 7 ffffff
9 3 7 ffffff
10 3 7 ffffff
11 3 7 ffffff
12 3 7 ffffff
13 3 7 ffffff
14 3 7 ffffff
15 3 7 ffffff
0 4 7 ffffff
1 4 7 ffffff
2 4 7 ffffff
3 4 7 ffffff
4 4 7 ffffff
5 4 7 ffffff
6 4 7 ffffff
7 4 7 ffffff
8 4 7 ffffff
9 4 7 ffffff
10 4 7 ffffff
11 4 7 ffffff
12 4 7 ffffff
13 4 7 ffffff
14 4 7 ffffff
15 4 7 ffffff
0 5 7 ffffff
1 5 7 ffffff
2 5 7 ffffff
3 5 7 ffffff
4 5 7 ffffff
5 5 7 ffffff
6 5 7 ffffff
7 5 7 ffffff
8 5 7 ffffff
9 5 7 ffffff
10 5 7 ffffff
11 5 7 ffffff
12 5 7 ffffff
13 5 7 ffffff
14 5 7 ffffff
15 5 7 ffffff
0 6 7 ffffff
1 6 7 ffffff
2 6 7 ffffff
3 6 7 ffffff
4 6 7 ffffff
5 6 7 ffffff
6 6 7 ffffff
7 6 7 ffffff
8 6 7 ffffff
9 6 7 ffffff
10 6 7 ffffff
11 6 7 ffffff
12 6 7 ffffff
13 6 7 ffffff
14 6 7 ffffff
15 6 7 ffffff
0 7 7 ffffff
1 7 7 ffffff
2 7 7 ffffff
3 7 7 ffffff
4 7 7 ffffff
5 7 7 ffffff
6 7 7 ffffff
7 7 7 ffffff
8 7 7 ffffff
9 7 7 ffffff
10 7 7 ffffff
11 7 7 ffffff
12 7 7 ffffff
13 7 7 ffffff
14 7 7 ffffff
15 7 7 ffffff
0 8 7 ffffff
1 8 7 ffffff
2 8 7 ffffff
3 8 7 ffffff
4 8 7 ffffff
5 8 7 ffffff
6 8 7 ffffff
7 8 7 ffffff
0 9 7 ffffff
1 9 7 ffffff
2 9 7 ffffff
3 9 7 ffffff
4 9 7 ffffff
5 9 7 ffffff
6 9 7 ffffff
7 9 7 ffffff
0 10 7 ffffff
1 10 7 ffffff
2 10 7 ffffff
3 10 7 ffffff
4 10 7 ffffff
5 10 7 ffffff
6 10 7 ffffff
7 10 7 ffffff
0 11 7 ffffff
1 11 7 ffffff
2 11 7 ffffff
3 11 7 ffffff
4 11 7 ffffff
5 11 7 ffffff
6 11 7 ffffff
7 11 7 ffffff
0 12 7 ffffff
1 12 7 ffffff
2 12 7 ffffff
3 12 7 ffffff
4 12 7 ffffff
5 12 7 ffffff
6 12 7 ffffff
7 12 7 ffffff
0 13 7 ffffff
1 13 7 ffffff
2 13 7 ffffff
3 13 7 ffffff
4 13 7 ffffff
5 13 7 ffffff
6 13 7 ffffff
7 13 7 ffffff
0 14 7 ffffff
1 14 7 ffffff
2 14 7 ffffff
3 14 7 ffffff
4 14 7 ffffff
5 14 7 ffffff
6 14 7 ffffff
7 14 7 ffffff
0 15 7 ffffff
1 15 7 ffffff
2 15 7 ffffff
3 15 7 ffffff
4 15 7 ffffff
5 15 7 ffffff
6 15 7 ffffff
7 15 7 ffffff
1 0 8 ffffff
2 0 8 ffffff
3 0 8 ffffff
4 0 8 ffffff
5 0 8 ffffff
6 0 8 ffffff
7 0 8 ffffff
8 0 8 ffffff
9 0 8 ffffff
10 0 8 ffffff
11 0 8 ffffff
12 0 8 ffffff
13 0 8 ffffff
14 0 8 ffffff
15 0 8 ffffff
0 1 8 ffffff
1 1 8 ffffff
2 1 8 ffffff
3 1 8 ffffff
4 1 8 ffffff
5 1 8 ffffff
6 1 8 ffffff
7 1 8 ffffff
8 1 8 ffffff
9 1 8 ffffff
10 1 8 ffffff
11 1 8 ffffff
12 1 8 ffffff
13 1 8 ffffff
14 1 8 ffffff
15 1 8 ffffff
0 2 8 ffffff
1 2 8 ffffff
2 2 8 ffffff
3 2 8 ffffff
4 2 8 ffffff
5 2 8 ffffff
6 2 8 ffffff
7 2 8 ffffff
8 2 8 ffffff
9 2 8 ffffff
10 2 8 ffffff
11 2 8 ffffff
12 2 8 ffffff
13 2 8 ffffff
14 2 8 ffffff
15 2 8 ffffff
0 3 8 ffffff
1 3 8 ffffff
2 3 8 ffffff
3 3 8 ffffff
4 3 8 ffffff
5 3 8 ffffff
6 3 8 ffffff
7 3 8 ffffff
8 3 8 ffffff
9 3 8 ffffff
10 3 8 ffffff
11 3 8 ffffff
12 3 8 ffffff
13 3 8 ffffff
14 3 8 ffffff
15 3 8 ffffff
0 4 8 ffffff
1 4 8 ffffff
2 4 8 ffffff
3 4 8 ffffff
4 4 8 ffffff
5 4 8 ffffff
6 4 8 ffffff
7 4 8 ffffff
8 4 8 ffffff
9 4 8 ffffff
10 4 8 ffffff
11 4 8 ffffff
12 4 8 ffffff
13 4 8 ffffff
14 4 8 ffffff
15 4 8 ffffff
0 5 8 ffffff
1 5 8 ffffff
2 5 8 ffffff
3 5 8 ffffff
4 5 8 ffffff
5 5 8 ffffff
6 5 8 ffffff
7 5 8 ffffff
8 5 8 ffffff
9 5 8 ffffff
10 5 8 ffffff
11 5 8 ffffff
12 5 8 ffffff
13 5 8 ffffff
14 5 8 ffffff
15 5 8 ffffff
0 6 8 ffffff
1 6 8 ffffff
2 6 8 ffffff
3 6 8 ffffff
4 6 8 ffffff
5 6 8 ffffff
6 6 8 ffffff
7 6 8 ffffff
8 6 8 ffffff
9 6 8 ffffff
10 6 8 ffffff
11 6 8 ffffff
12 6 8 ffffff
13 6 8 ffffff
14 6 8 ffffff
15 6 8 ffffff
0 7 8 ffffff
1 7 8 ffffff
2 7 8 ffffff
3 7 8 ffffff
4 7 8 ffffff
5 7 8 ffffff
6 7 8 ffffff
0 8 8 ffffff
1 8 8 ffffff
2 8 8 ffffff
3 8 8 ffffff
4 8 8 ffffff
5 8 8 ffffff
6 8 8 ffffff
0 9 8 ffffff
1 9 8 ffffff
2 9 8 ffffff
3 9 8 ffffff
4 9 8 ffffff
5 9 8 ffffff
6 9 8 ffffff
0 10 8 ffffff
1 10 8 ffffff
2 10 8 ffffff
3 10 8 ffffff
4 10 8 ffffff
5 10 8 ffffff
6 10 8 ffffff
0 11 8 ffffff
1 11 8 ffffff
2 11 8 ffffff
3 11 8 ffffff
4 11 8 ffffff
5 11 8 ffffff
6 11 8 ffffff
0 12 8 ffffff
1 12 8 ffffff
2 12 8 ffffff
3 12 8 ffffff
4 12 8 ffffff
5 12 8 ffffff
6 12 8 ffffff
0 13 8 ffffff
1 13 8 ffffff
2 13 8 ffffff
3 13 8 ffffff
4 13 8 ffffff
5 13 8 ffffff
6 13 8 ffffff
0 14 8 ffffff
1 14 8 ffffff
2 14 8 ffffff
3 14 8 ffffff
4 14 8 ffffff
5 14 8 ffffff
6 14 8 ffffff
0 15 8 ffffff
1 15 8 ffffff
2 15 8 ffffff
3 15 8 ffffff
4 15 8 ffffff
5 15 8 ffffff
6 15 8 ffffff
1 0 9 ffffff
2 0 9 ffffff
3 0 9 ffffff
4 0 9 ffffff
5 0 9 ffffff
6 0 9 ffffff
7 0 9 ffffff
8 0 9 ffffff
9 0 9 ffffff
10 0 9 ffffff
11 0 9 ffffff
12 0 9 ffffff
13 0 9 ffffff
14 0 9 ffffff
15 0 9 ffffff
0 1 9 ffffff
1 1 9 ffffff
2 1 9 ffffff
3 1 9 ffffff
4 1 9 ffffff
5 1 9 ffffff
6 1 9 ffffff
7 1 9 ffffff
8 1 9 ffffff
9 1 9 ffffff
10 1 9 ffffff
11 1 9 ffffff
12 1 9 ffffff
13 1 9 ffffff
14 1 9 ffffff
15 1 9 ffffff
0 2 9 ffffff
1 2 9 ffffff
2 2 9 ffffff
3 2 9 ffffff
4 2 9 ffffff
5 2 9 ffffff
6 2 9 ffffff
7 2 9 ffffff
8 2 9 ffffff
9 2 9 ffffff
10 2 9 ffffff
11 2 9 ffffff
12 2 9 ffffff
13 2 9 ffffff
14 2 9 ffffff
15 2 9 ffffff
0 3 9 ffffff
1 3 9 ffffff
2 3 9 ffffff
3 3 9 ffffff
4 3 9 ffffff
5 3 9 ffffff
6 3 9 ffffff
7 3 9 ffffff
8 3 9 ffffff
9 3 9 ffffff
10 3 9 ffffff
11 3 9 ffffff
12 3 9 ffffff
13 3 9 ffffff
14 3 9 ffffff
15 3 9 ffffff
0 4 9 ffffff
1 4 9 ffffff
2 4 9 ffffff
3 4 9 ffffff
4 4 9 ffffff
5 4 9 ffffff
6 4 9 ffffff
7 4 9 ffffff
8 4 9 ffffff
9 4 9 ffffff
10 4 9 ffffff
11 4 9 ffffff
12 4 9 ffffff
13 4 9 ffffff
14 4 9 ffffff
15 4 9 ffffff
0 5 9 ffffff
1 5 9 ffffff
2 5 9 ffffff
3 5 9 ffffff
4 5 9 ffffff
5 5 9 ffffff
6 5 9 ffffff
7 5 9 ffffff
8 5 9 ffffff
9 5 9 ffffff
10 5 9 ffffff
11 5 9 ffffff
12 5 9 ffffff
13 5 9 ffffff
14 5 9 ffffff
15 5 9 ffffff
0 6 9 ffffff
1 6 9 ffffff
2 6 9 ffffff
3 6 9 ffffff
4 6 9 ffffff
5 6 9 ffffff
0 7 9 ffffff
1 7 9 ffffff
2 7 9 ffffff
3 7 9 ffffff
4 7 9 ffffff
5 7 9 ffffff
0 8 9 ffffff
1 8 9 ffffff
2 8 9 ffffff
3 8 9 ffffff
4 8 9 ffffff
5 8 9 ffffff
0 9 9 ffffff
1 9 9 ffffff
2 9 9 ffffff
3 9 9 ffffff
4 9 9 ffffff
5 9 9 ffffff
0 10 9 ffffff
1 10 9 ffffff
2 10 9 ffffff
3 10 9 ffffff
4 10 9 ffffff
5 10 9 ffffff
0 11 9 ffffff
1 11 9 ffffff
2 11 9 ffffff
3 11 9 ffffff
4 11 9 ffffff
5 11 9 ffffff
0 12 9 ffffff
1 12 9 ffffff
2 12 9 ffffff
3 12 9 ffffff
4 12 9 ffffff
5 12 9 ffffff
0 13 9 ffffff
1 13 9 ffffff
2 13 9 ffffff
3 13 9 ffffff
4 13 9 ffffff
5 13 9 ffffff
0 14 9 ffffff
1 14 9 ffffff
2 14 9 ffffff
3 14 9 ffffff
4 14 9 ffffff
5 14 9 ffffff
0 15 9 ffffff
1 15 9 ffffff
2 15 9 ffffff
3 15 9 ffffff
4 15 9 ffffff
5 15 9 ffffff
0 16 0 ffffff
1 16 0 ffffff
2 16 0 ffffff
3 16 0 ffffff
4 16 0 ffffff
5 16 0 ffffff
6 16 0 ffffff
7 16 0 ffffff
8 16 0 ffffff
9 16 0 ffffff
10 16 0 ffffff
11 16 0 ffffff
12 16 0 ffffff
13 16 0 ffffff
14 16 0 ffffff
15 16 0 ffffff
0 17 0 ffffff
1 17 0 ffffff
2 17 0 ffffff
3 17 0 ffffff
4 17 0 ffffff
5 17 0 ffffff
6 17 0 ffffff
7 17 0 ffffff
8 17 0 ffffff
9 17 0 ffffff
10 17 0 ffffff
11 17 0 ffffff
12 17 0 ffffff
13 17 0 ffffff
14 17 0 ffffff
15 17 0 ffffff
0 18 0 ffffff
1 18 0 ffffff
2 18 0 ffffff
3 18 0 ffffff
4 18 0 ffffff
5 18 0 ffffff
6 18 0 ffffff
7 18 0 ffffff
8 18 0 ffffff
9 18 0 ffffff
10 18 0 ffffff
11 18 0 ffffff
12 18 0 ffffff
13 18 0 ffffff
14 18 0 ffffff
15 18 0 ffffff
0 19 0 ffffff
1 19 0 ffffff
2 19 0 ffffff
3 19 0 ffffff
4 19 0 ffffff
5 19 0 ffffff
6 19 0 ffffff
7 19 0 ffffff
8 19 0 ffffff
9 19 0 ffffff
10 19 0 ffffff
11 19 0 ffffff
12 19 0 ffffff
13 19 0 ffffff
14 19 0 ffffff
15 19 0 ffffff
0 20 0 ffffff
1 20 0 ffffff
2 20 0 ffffff
3 20 0 ffffff
4 20 0 ffffff
5 20 0 ffffff
6 20 0 ffffff
7 20 0 ffffff
8 20 0 ffffff
9 20 0 ffffff
10 20 0 ffffff
11 20 0 ffffff
12 20 0 ffffff
13 20 0 ffffff
14 20 0 ffffff
15 20 0 ffffff
0 21 0 ffffff
1 21 0 ffffff
2 21 0 ffffff
3 21 0 ffffff
4 21 0 ffffff
5 21 0 ffffff
6 21 0 ffffff
7 21 0 ffffff
8 21 0 ffffff
9 21 0 ffffff
10 21 0 ffffff
11 21 0 ffffff
12 21 0 ffffff
13 21 0 ffffff
14 21 0 ffffff
15 21 0 ffffff
0 22 0 ffffff
1 22 0 ffffff
2 22 0 ffffff
3 22 0 ffffff
4 22 0 ffffff
5 22 0 ffffff
6 22 0 ffffff
7 22 0 ffffff
8 22 0 ffffff
9 22 0 ffffff
10 22 0 ffffff
11 22 0 ffffff
12 22 0 ffffff
13 22 0 ffffff
14 22 0 ffffff
15 22 0 ffffff
0 23 0 ffffff
1 23 0 ffffff
2 23 0 ffffff
3 23 0 ffffff
4 23 0 ffffff
5 23 0 ffffff
6 23 0 ffffff
7 23 0 ffffff
8 23 0 ffffff
9 23 0 ffffff
10 23 0 ffffff
11 23 0 ffffff
12 23 0 ffffff
13 23 0 ffffff
14 23 0 ffffff
15 23 0 ffffff
0 24 0 ffffff
1 24 0 ffffff
2 24 0 ffffff
3 24 0 ffffff
4 24 0 ffffff
5 24 0 ffffff
6 24 0 ffffff
7 24 0 ffffff
8 24 0 ffffff
9 24 0 ffffff
10 24 0 ffffff
11 24 0 ffffff
12 24 0 ffffff
13 24 0 ffffff
14 24 0 ffffff
15 24 0 ffffff
0 25 0 ffffff
1 25 0 ffffff
2 25 0 ffffff
3 25 0 ffffff
4 25 0 ffffff
5 25 0 ffffff
6 25 0 ffffff
7 25 0 ffffff
8 25 0 ffffff
9 25 0 ffffff
10 25 0 ffffff
11 25 0 ffffff
12 25 0 ffffff
13 25 0 ffffff
14 25 0 ffffff
15 25 0 ffffff
0 26 0 ffffff
1 26 0 ffffff
2 26 0 ffffff
3 26 0 ffffff
4 26 0 ffffff
5 26 0 ffffff
6 26 0 ffffff
7 26 0 ffffff
8 26 0 ffffff
9 26 0 ffffff
10 26 0 ffffff
11 26 0 ffffff
12 26 0 ffffff
13 26 0 ffffff
14 26 0 ffffff
15 26 0 ffffff
0 27 0 ffffff
1 27 0 ffffff
2 27 0 ffffff
3 27 0 ffffff
4 27 0 ffffff
5 27 0 ffffff
6 27 0 ffffff
7 27 0 ffffff
8 27 0 ffffff
9 27 0 ffffff
10 27 0 ffffff
11 27 0 ffffff
12 27 0 ffffff
13 27 0 ffffff
14 27 0 ffffff
15 27 0 ffffff
0 28 0 ffffff
1 28 0 ffffff
2 28 0 ffffff
3 28 0 ffffff
4 28 0 ffffff
5 28 0 ffffff
6 28 0 ffffff
7 28 0 ffffff
8 28 0 ffffff
9 28 0 ffffff
10 28 0 ffffff
11 28 0 ffffff
12 28 0 ffffff
13 28 0 ffffff
14 28 0 ffffff
15 28 0 ffffff
0 29 0 ffffff
1 29 0 ffffff
2 29 0 ffffff
3 29 0 ffffff
4 29 0 ffffff
5 29 0 ffffff
6 29 0 ffffff
7 29 0 ffffff
8 29 0 ffffff
9 29 0 ffffff
10 29 0 ffffff
11 29 0 ffffff
12 29 0 ffffff
13 29 0 ffffff
14 29 0 ffffff
15 29 0 ffffff
0 30 0 ffffff
1 30 0 ffffff
2 30 0 ffffff
3 30 0 ffffff
4 30 0 ffffff
5 30 0 ffffff
6 30 0 ffffff
7 30 0 ffffff
8 30 0 ffffff
9 30 0 ffffff
10 30 0 ffffff
11 30 0 ffffff
12 30 0 ffffff
13 30 0 ffffff
14 30 0 ffffff
15 30 0 ffffff
0 31 0 ffffff
1 31 0 ffffff
2 31 0 ffffff
3 31 0 ffffff
4 31 0 ffffff
5 31 0 ffffff
6 31 0 ffffff
7 31 0 ffffff
8 31 0 ffffff
9 31 0 ffffff
10 31 0 ffffff
11 31 0 ffffff
12 31 0 ffffff
13 31 0 ffffff
14 31 0 ffffff
15 31 0 ffffff
0 16 1 ffffff
1 16 1 ffffff
2 16 1 ffffff
3 16 1 ffffff
4 16 1 ffffff
5 16 1 ffffff
6 16 1 ffffff
7 16 1 ffffff
8 16 1 ffffff
9 16 1 ffffff
10 16 1 ffffff
11 16 1 ffffff
12 16 1 ffffff
13 16 1 ffffff
14 16 1 ffffff
15 16 1 ffffff
0 17 1 ffffff
1 17 1 ffffff
2 17 1 ffffff
3 17 1 ffffff
4 17 1 ffffff
5 17 1 ffffff
6 17 1 ffffff
7 17 1 ffffff
8 17 1 ffffff
9 17 1 ffffff
10 17 1 ffffff
11 17 1 ffffff
12 17 1 ffffff
13 17 1 ffffff
14 17 1 ffffff
15 17 1 ffffff
0 18 1 ffffff
1 18 1 ffffff
2 18 1 ffffff
3 18 1 ffffff
4 18 1 ffffff
5 18 1 ffffff
6 18 1 ffffff
7 18 1 ffffff
8 18 1 ffffff
9 18 1 ffffff
10 18 1 ffffff
11 18 1 ffffff
12 18 1 ffffff
13 18 1 ffffff
14 18 1 ffffff
15 18 1 ffffff
0 19 1 ffffff
1 19 1 ffffff
2 19 1 ffffff
3 19 1 ffffff
4 19 1 ffffff
5 19 1 ffffff
6 19 1 ffffff
7 19 1 ffffff
8 19 1 ffffff
9 19 1 ffffff
10 19 1 ffffff
11 19 1 ffffff
12 19 1 ffffff
13 19 1 ffffff
14 19 1 ffffff
15 19 1 ffffff
0 20 1 ffffff
1 20 1 ffffff
2 20 1 ffffff
3 20 1 ffffff
4 20 1 ffffff
5 20 1 ffffff
6 20 1 ffffff
7 20 1 ffffff
8 20 1 ffffff
9 20 1 ffffff
10 20 1 ffffff
11 20 1 ffffff
12 20 1 ffffff
13 20 1 ffffff
14 20 1 ffffff
15 20 1 ffffff
0 21 1 ffffff
1 21 1 ffffff
2 21 1 ffffff
3 21 1 ffffff
4 21 1 ffffff
5 21 1 ffffff
6 21 1 ffffff
7 21 1 ffffff
8 21 1 ffffff
9 21 1 ffffff
10 21 1 ffffff
11 21 1 ffffff
12 21 1 ffffff
13 21 1 ffffff
14 21 1 ffffff
15 21 1 ffffff
0 22 1 ffffff
1 22 1 ffffff
2 22 1 ffffff
3 22 1 ffffff
4 22 1 ffffff
5 22 1 ffffff
6 22 1 ffffff
7 22 1 ffffff
8 22 1 ffffff
9 22 1 ffffff
10 22 1 ffffff
11 22 1 ffffff
12 22 1 ffffff
13 22 1 ffffff
14 22 1 ffffff
15 22 1 ffffff
0 23 1 ffffff
1 23 1 ffffff
2 23 1 ffffff
3 23 1 ffffff
4 23 1 ffffff
5 23 1 ffffff
6 23 1 ffffff
7 23 1 ffffff
8 23 1 ffffff
9 23 1 ffffff
10 23 1 ffffff
11 23 1 ffffff
12 23 1 ffffff
13 23 1 ffffff
14 23 1 ffffff
15 23 1 ffffff
0 24 1 ffffff
1 24 1 ffffff
2 24 1 ffffff
3 24 1 ffffff
4 24 1 ffffff
5 24 1 ffffff
6 24 1 ffffff
7 24 1 ffffff
8 24 1 ffffff
9 24 1 ffffff
10 24 1 ffffff
11 24 1 ffffff
12 24 1 ffffff
13 24 1 ffffff
14 24 1 ffffff
15 24 1 ffffff
0 25 1 ffffff
1 25 1 ffffff
2 25 1 ffffff
3 25 1 ffffff
4 25 1 ffffff
5 25 1 ffffff
6 25 1 ffffff
7 25 1 ffffff
8 25 1 ffffff
9 25 1 ffffff
10 25 1 ffffff
11 25 1 ffffff
12 25 1 ffffff
13 25 1 ffffff
14 25 1 ffffff
15 25 1 ffffff
0 26 1 ffffff
1 26 1 ffffff
2 26 1 ffffff
3 26 1 ffffff
4 26 1 ffffff
5 26 1 ffffff
6 26 1 ffffff
7 26 1 ffffff
8 26 1 ffffff
9 26 1 ffffff
10 26 1 ffffff
11 26 1 ffffff
12 26 1 ffffff
13 26 1 ffffff
14 26 1 ffffff
15 26 1 ffffff
0 27 1 ffffff
1 27 1 ffffff
2 27 1 ffffff
3 27 1 ffffff
4 27 1 ffffff
5 27 1 ffffff
6 27 1 ffffff
7 27 1 ffffff
8 27 1 ffffff
9 27 1 ffffff
10 27 1 ffffff
11 27 1 ffffff
12 27 1 ffffff
13 27 1 ffffff
14 27 1 ffffff
15 27 1 ffffff
0 28 1 ffffff
1 28 1 ffffff
2 28 1 ffffff
3 28 1 ffffff
4 28 1 ffffff
5 28 1 ffffff
6 28 1 ffffff
7 28 1 ffffff
8 28 1 ffffff
9 28 1 ffffff
10 28 1 ffffff
11 28 1 ffffff
12 28 1 ffffff
13 28 1 ffffff
14 28 1 ffffff
15 28 1 ffffff
0 29 1 ffffff
1 29 1 ffffff
2 29 1 ffffff
3 29 1 ffffff
4 29 1 ffffff
5 29 1 ffffff
6 29 1 ffffff
7 29 1 ffffff
8 29 1 ffffff
9 29 1 ffffff
10 29 1 ffffff
11 29 1 ffffff
12 29 1 ffffff
13 29 1 ffffff
14 29 1 ffffff
15 29 1 ffffff
0 30 1 ffffff
1 30 1 ffffff
2 30 1 ffffff
3 30 1 ffffff
4 30 1 ffffff
5 30 1 ffffff
6 30 1 ffffff
7 30 1 ffffff
8 30 1 ffffff
9 30 1 ffffff
10 30 1 ffffff
11 30 1 ffffff
12 30 1 ffffff
13 30 1 ffffff
14 30 1 ffffff
15 30 1 ffffff
0 31 1 ffffff
1 31 1 ffffff
2 31 1 ffffff
3 31 1 ffffff
4 31 1 ffffff
5 31 1 ffffff
6 31 1 ffffff
7 31 1 ffffff
8 31 1 ffffff
9 31 1 ffffff
10 31 1 ffffff
11 31 1 ffffff
12 31 1 ffffff
13 31 1 ffffff
14 31 1 ffffff
15 31 1 ffffff
0 16 2 ffffff
1 16 2 ffffff
2 16 2 ffffff
3 16 2 ffffff
4 16 2 ffffff
5 16 2 ffffff
6 16 2 ffffff
7 16 2 ffffff
8 16 2 ffffff
9 16 2 ffffff
10 16 2 ffffff
11 16 2 ffffff
12 16 2 ffffff
13 16 2 ffffff
14 16 2 ffffff
15 16 2 ffffff
0 17 2 ffffff
1 17 2 ffffff
2 17 2 ffffff
3 17 2 ffffff
4 17 2 ffffff
5 17 2 ffffff
6 17 2 ffffff
7 17 2 ffffff
8 17 2 ffffff
9 17 2 ffffff
10 17 2 ffffff
11 17 2 ffffff
12 17 2 ffffff
13 17 2 ffffff
14 17 2 ffffff
15 17 2 ffffff
0 18 2 ffffff
1 18 2 ffffff
2 18 2 ffffff
3 18 2 ffffff
4 18 2 ffffff
5 18 2 ffffff
6 18 2 ffffff
7 18 2 ffffff
8 18 2 ffffff
9 18 2 ffffff
10 18 2 ffffff
11 18 2 ffffff
12 18 2 ffffff
13 18 2 ffffff
14 18 2 ffffff
15 18 2 ffffff
0 19 2 ffffff
1 19 2 ffffff
2 19 2 ffffff
3 19 2 ffffff
4 19 2 ffffff
5 19 2 ffffff
6 19 2 ffffff
7 19 2 ffffff
8 19 2 ffffff
9 19 2 ffffff
10 19 2 ffffff
11 19 2 ffffff
12 19 2 ffffff
13 19 2 ffffff
14 19 2 ffffff
15 19 2 ffffff
0 20 2 ffffff
1 20 2 ffffff
2 20 2 ffffff
3 20 2 ffffff
4 20 2 ffffff
5 20 2 ffffff
6 20 2 ffffff
7 20 2 ffffff
8 20 2 ffffff
9 20 2 ffffff
10 20 2 ffffff
11 20 2 ffffff
12 20 2 ffffff
13 20 2 ffffff
14 20 2 ffffff
15 20 2 ffffff
0 21 2 ffffff
1 21 2 ffffff
2 21 2 ffffff
3 21 2 ffffff
4 21 2 ffffff
5 21 2 ffffff
6 21 2 ffffff
7 21 2 ffffff
8 21 2 ffffff
9 21 2 ffffff
10 21 2 ffffff
11 21 2 ffffff
12 21 2 ffffff
13 21 2 ffffff
14 21 2 ffffff
15 21 2 ffffff
0 22 2 ffffff
1 22 2 ffffff
2 22 2 ffffff
3 22 2 ffffff
4 22 2 ffffff
5 22 2 ffffff
6 22 2 ffffff
7 22 2 ffffff
8 22 2 ffffff
9 22 2 ffffff
10 22 2 ffffff
11 22 2 ffffff
12 22 2 ffffff
13 22 2 ffffff
14 22 2 ffffff
15 22 2 ffffff
0 23 2 ffffff
1 23 2 ffffff
2 23 2 ffffff
3 23 2 ffffff
4 23 2 ffffff
5 23 2 ffffff
6 23 2 ffffff
7 23 2 ffffff
8 23 2 ffffff
9 23 2 ffffff
10 23 2 ffffff
11 23 2 ffffff
12 23 2 ffffff
13 23 2 ffffff
14 23 2 ffffff
15 23 2 ffffff
0 24 2 ffffff
1 24 2 ffffff
2 24 2 ffffff
3 24 2 ffffff
4 24 2 ffffff
5 24 2 ffffff
6 24 2 ffffff
7 24 2 ffffff
8 24 2 ffffff
9 24 2 ffffff
10 24 2 ffffff
11 24 2 ffffff
12 24 2 ffffff
13 24 2 ffffff
14 24 2 ffffff
15 24 2 ffffff
0 25 2 ffffff
1 25 2 ffffff
2 25 2 ffffff
3 25 2 ffffff
4 25 2 ffffff
5 25 2 ffffff
6 25 2 ffffff
7 25 2 ffffff
8 25 2 ffffff
9 25 2 ffffff
10 25 2 ffffff
11 25 2 ffffff
12 25 2 ffffff
13 25 2 ffffff
14 25 2 ffffff
15 25 2 ffffff
0 26 2 ffffff
1 26 2 ffffff
2 26 2 ffffff
3 26 2 ffffff
4 26 2 ffffff
5 26 2 ffffff
6 26 2 ffffff
7 26 2 ffffff
8 26 2 ffffff
9 26 2 ffffff
10 26 2 ffffff
11 26 2 ffffff
12 26 2 ffffff
13 26 2 ffffff
14 26 2 ffffff
15 26 2 ffffff
0 27 2 ffffff
1 27 2 ffffff
2 27 2 ffffff
3 27 2 ffffff
4 27 2 ffffff
5 27 2 ffffff
6 27 2 ffffff
7 27 2 ffffff
8 27 2 ffffff
9 27 2 ffffff
10 27 2 ffffff
11 27 2 ffffff
12 27 2 ffffff
13 27 2 ffffff
14 27 2 ffffff
15 27 2 ffffff
0 28 2 ffffff
1 28 2 ffffff
2 28 2 ffffff
3 28 2 ffffff
4 28 2 ffffff
5 28 2 ffffff
6 28 2 ffffff
7 28 2 ffffff
8 28 2 ffffff
9 28 2 ffffff
10 28 2 ffffff
11 28 2 ffffff
12 28 2 ffffff
13 28 2 ffffff
14 28 2 ffffff
15 28 2 ffffff
0 29 2 ffffff
1 29 2 ffffff
2 29 2 ffffff
3 29 2 ffffff
4 29 2 ffffff
5 29 2 ffffff
6 29 2 ffffff
7 29 2 ffffff
8 29 2 ffffff
9 29 2 ffffff
10 29 2 ffffff
11 29 2 ffffff
12 29 2 ffffff
13 29 2 ffffff
14 29 2 ffffff
15 29 2 ffffff
0 30 2 ffffff
1 30 2 ffffff
2 30 2 ffffff
3 30 2 ffffff
4 30 2 ffffff
5 30 2 ffffff
6 30 2 ffffff
7 30 2 ffffff
8 30 2 ffffff
9 30 2 ffffff
10 30 2 ffffff
11 30 2 ffffff
12 30 2 ffffff
13 30 2 ffffff
14 30 2 ffffff
15 30 2 ffffff
0 31 2 ffffff
1 31 2 ffffff
2 31 2 ffffff
3 31 2 ffffff
4 31 2 ffffff
5 31 2 ffffff
6 31 2 ffffff
7 31 2 ffffff
8 31 2 ffffff
9 31 2 ffffff
10 31 2 ffffff
11 31 2 ffffff
12 31 2 ffffff
13 31 2 ffffff
14 31 2 ffffff
15 31 2 ffffff
0 16 3 ffffff
1 16 3 ffffff
2 16 3 ffffff
3 16 3 ffffff
4 16 3 ffffff
5 16 3 ffffff
6 16 3 ffffff
7 16 3 ffffff
8 16 3 ffffff
9 16 3 ffffff
10 16 3 ffffff
11 16 3 ffffff
12 16 3 ffffff
13 16 3 ffffff
14 16 3 ffffff
15 16 3 ffffff
0 17 3 ffffff
1 17 3 ffffff
2 17 3 ffffff
3 17 3 ffffff
4 17 3 ffffff
5 17 3 ffffff
6 17 3 ffffff
7 17 3 ffffff
8 17 3 ffffff
9 17 3 ffffff
10 17 3 ffffff
11 17 3 ffffff
12 17 3 ffffff
13 17 3 ffffff
14 17 3 ffffff
15 17 3 ffffff
0 18 3 ffffff
1 18 3 ffffff
2 18 3 ffffff
3 18 3 ffffff
4 18 3 ffffff
5 18 3 ffffff
6 18 3 ffffff
7 18 3 ffffff
8 18 3 ffffff
9 18 3 ffffff
10 18 3 ffffff
11 18 3 ffffff
12 18 3 ffffff
13 18 3 ffffff
14 18 3 ffffff
15 18 3 ffffff
0 19 3 ffffff
1 19 3 ffffff
2 19 3 ffffff
3 19 3 ffffff
4 19 3 ffffff
5 19 3 ffffff
6 19 3 ffffff
7 19 3 ffffff
8 19 3 ffffff
9 19 3 ffffff
10 19 3 ffffff
11 19 3 ffffff
12 19 3 ffffff
13 19 3 ffffff
14 19 3 ffffff
15 19 3 ffffff
0 20 3 ffffff
1 20 3 ffffff
2 20 3 ffffff
3 20 3 ffffff
4 20 3 ffffff
5 20 3 ffffff
6 20 3 ffffff
7 20 3 ffffff
8 20 3 ffffff
9 20 3 ffffff
10 20 3 ffffff
11 20 3 ffffff
12 20 3 ffffff
13 20 3 ffffff
14 20 3 ffffff
15 20 3 ffffff
0 21 3 ffffff
1 21 3 ffffff
2 21 3 ffffff
3 21 3 ffffff
4 21 3 ffffff
5 21 3 ffffff
6 21 3 ffffff
7 21 3 ffffff
8 21 3 ffffff
9 21 3 ffffff
10 21 3 ffffff
11 21 3 ffffff
12 21 3 ffffff
13 21 3 ffffff
14 21 3 ffffff
15 21 3 ffffff
0 22 3 ffffff
1 22 3 ffffff
2 22 3 ffffff
3 22 3 ffffff
4 22 3 ffffff
5 22 3 ffffff
6 22 3 ffffff
7 22 3 ffffff
8 22 3 ffffff
9 22 3 ffffff
10 22 3 ffffff
11 22 3 ffffff
12 22 3 ffffff
13 22 3 ffffff
14 22 3 ffffff
15 22 3 ffffff
0 23 3 ffffff
1 23 3 ffffff
2 23 3 ffffff
3 23 3 ffffff
4 23 3 ffffff
5 23 3 ffffff
6 23 3 ffffff
7 23 3 ffffff
8 23 3 ffffff
9 23 3 ffffff
10 23 3 ffffff
11 23 3 ffffff
12 23 3 ffffff
13 23 3 ffffff
14 23 3 ffffff
15 23 3 ffffff
0 24 3 ffffff
1 24 3 ffffff
2 24 3 ffffff
3 24 3 ffffff
4 24 3 ffffff
5 24 3 ffffff
6 24 3 ffffff
7 24 3 ffffff
8 24 3 ffffff
9 24 3 ffffff
10 24 3 ffffff
11 24 3 ffffff
12 24 3 ffffff
13 24 3 ffffff
14 24 3 ffffff
15 24 3 ffffff
0 25 3 ffffff
1 25 3 ffffff
2 25 3 ffffff
3 25 3 ffffff
4 25 3 ffffff
5 25 3 ffffff
6 25 3 ffffff
7 25 3 ffffff
8 25 3 ffffff
9 25 3 ffffff
10 25 3 ffffff
11 25 3 ffffff
12 25 3 ffffff
13 25 3 ffffff
14 25 3 ffffff
15 25 3 ffffff
0 26 3 ffffff
1 26 3 ffffff
2 26 3 ffffff
3 26 3 ffffff
4 26 3 ffffff
5 26 3 ffffff
6 26 3 ffffff
7 26 3 ffffff
8 26 3 ffffff
9 26 3 ffffff
10 26 3 ffffff
11 26 3 ffffff
12 26 3 ffffff
13 26 3 ffffff
14 26 3 ffffff
15 26 3 ffffff
0 27 3 ffffff
1 27 3 ffffff
2 27 3 ffffff
3 27 3 ffffff
4 27 3 ffffff
5 27 3 ffffff
6 27 3 ffffff
7 27 3 ffffff
8 27 3 ffffff
9 27 3 ffffff
10 27 3 ffffff
11 27 3 ffffff
12 27 3 ffffff
13 27 3 ffffff
14 27 3 ffffff
15 27 3 ffffff
0 28 3 ffffff
1 28 3 ffffff
2 28 3 ffffff
3 28 3 ffffff
4 28 3 ffffff
5 28 3 ffffff
6 28 3 ffffff
7 28 3 ffffff
8 28 3 ffffff
9 28 3 ffffff
10 28 3 ffffff
11 28 3 ffffff
12 28 3 ffffff
13 28 3 ffffff
14 28 3 ffffff
15 28 3 ffffff
0 29 3 ffffff
1 29 3 ffffff
2 29 3 ffffff
3 29 3 ffffff
4 29 3 ffffff
5 29 3 ffffff
6 29 3 ffffff
7 29 3 ffffff
8 29 3 ffffff
9 29 3 ffffff
10 29 3 ffffff
11 29 3 ffffff
12 29 3 ffffff
13 29 3 ffffff
14 29 3 ffffff
15 29 3 ffffff
0 30 3 ffffff
1 30 3 ffffff
2 30 3 ffffff
3 30 3 ffffff
4 30 3 ffffff
5 30 3 ffffff
6 30 3 ffffff
7 30 3 ffffff
8 30 3 ffffff
9 30 3 ffffff
10 30 3 ffffff
11 30 3 ffffff
12 30 3 ffffff
13 30 3 ffffff
14 30 3 ffffff
15 30 3 ffffff
0 31 3 ffffff
1 31 3 ffffff
2 31 3 ffffff
3 31 3 ffffff
4 31 3 ffffff
5 31 3 ffffff
6 31 3 ffffff
7 31 3 ffffff
8 31 3 ffffff
9 31 3 ffffff
10 31 3 ffffff
11 31 3 ffffff
12 31 3 ffffff
13 31 3 ffffff
14 31 3 ffffff
15 31 3 ffffff
0 16 4 ffffff
1 16 4 ffffff
2 16 4 ffffff
3 16 4 ffffff
4 16 4 ffffff
5 16 4 ffffff
6 16 4 ffffff
7 16 4 ffffff
8 16 4 ffffff
9 16 4 ffffff
10 16 4 ffffff
11 16 4 ffffff
12 16 4 ffffff
13 16 4 ffffff
14 16 4 ffffff
15 16 4 ffffff
0 17 4 ffffff
1 17 4 ffffff
2 17 4 ffffff
3 17 4 ffffff
4 17 4 ffffff
5 17 4 ffffff
6 17 4 ffffff
7 17 4 ffffff
8 17 4 ffffff
9 17 4 ffffff
10 17 4 ffffff
11 17 4 ffffff
12 17 4 ffffff
13 17 4 ffffff
14 17 4 ffffff
15 17 4 ffffff
0 18 4 ffffff
1 18 4 ffffff
2 18 4 ffffff
3 18 4 ffffff
4 18 4 ffffff
5 18 4 ffffff
6 18 4 ffffff
7 18 4 ffffff
8 18 4 ffffff
9 18 4 ffffff
10 18 4 ffffff
11 18 4 ffffff
12 18 4 ffffff
13 18 4 ffffff
14 18 4 ffffff
15 18 4 ffffff
0 19 4 ffffff
1 19 4 ffffff
2 19 4 ffffff
3 19 4 ffffff
4 19 4 ffffff
5 19 4 ffffff
6 19 4 ffffff
7 19 4 ffffff
8 19 4 ffffff
9 19 4 ffffff
10 19 4 ffffff
11 19 4 ffffff
12 19 4 ffffff
13 19 4 ffffff
14 19 4 ffffff
15 19 4 ffffff
0 20 4 ffffff
1 20 4 ffffff
2 20 4 ffffff
3 20 4 ffffff
4 20 4 ffffff
5 20 4 ffffff
6 20 4 ffffff
7 20 4 ffffff
8 20 4 ffffff
9 20 4 ffffff
10 20 4 ffffff
11 20 4 ffffff
12 20 4 ffffff
13 20 4 ffffff
14 20 4 ffffff
15 20 4 ffffff
0 21 4 ffffff
1 21 4 ffffff
2 21 4 ffffff
3 21 4 ffffff
4 21 4 ffffff
5 21 4 ffffff
6 21 4 ffffff
7 21 4 ffffff
8 21 4 ffffff
9 21 4 ffffff
10 21 4 ffffff
11 21 4 ffffff
12 21 4 ffffff
13 21 4 ffffff
14 21 4 ffffff
15 21 4 ffffff
0 22 4 ffffff
1 22 4 ffffff
2 22 4 ffffff
3 22 4 ffffff
4 22 4 ffffff
5 22 4 ffffff
6 22 4 ffffff
7 22 4 ffffff
8 22 4 ffffff
9 22 4 ffffff
10 22 4 ffffff
11 22 4 ffffff
12 22 4 ffffff
13 22 4 ffffff
14 22 4 ffffff
15 22 4 ffffff
0 23 4 ffffff
1 23 4 ffffff
2 23 4 ffffff
3 23 4 ffffff
4 23 4 ffffff
5 23 4 ffffff
6 23 4 ffffff
7 23 4 ffffff
8 23 4 ffffff
9 23 4 ffffff
10 23 4 ffffff
11 23 4 ffffff
12 23 4 ffffff
13 23 4 ffffff
14 23 4 ffffff
15 23 4 ffffff
0 24 4 ffffff
1 24 4 ffffff
2 24 4 ffffff
3 24 4 ffffff
4 24 4 ffffff
5 24 4 ffffff
6 24 4 ffffff
7 24 4 ffffff
8 24 4 ffffff
9 24 4 ffffff
10 24 4 ffffff
11 24 4 ffffff
12 24 4 ffffff
13 24 4 ffffff
14 24 4 ffffff
15 24 4 ffffff
0 25 4 ffffff
1 25 4 ffffff
2 25 4 ffffff
3 25 4 ffffff
4 25 4 ffffff
5 25 4 ffffff
6 25 4 ffffff
7 25 4 ffffff
8 25 4 ffffff
9 25 4 ffffff
10 25 4 ffffff
11 25 4 ffffff
12 25 4 ffffff
13 25 4 ffffff
14 25 4 ffffff
15 25 4 ffffff
0 26 4 ffffff
1 26 4 ffffff
2 26 4 ffffff
3 26 4 ffffff
4 26 4 ffffff
5 26 4 ffffff
6 26 4 ffffff
7 26 4 ffffff
8 26 4 ffffff
9 26 4 ffffff
10 26 4 ffffff
11 26 4 ffffff
12 26 4 ffffff
13 26 4 ffffff
14 26 4 ffffff
15 26 4 ffffff
0 27 4 ffffff
1 27 4 ffffff
2 27 4 ffffff
3 27 4 ffffff
4 27 4 ffffff
5 27 4 ffffff
6 27 4 ffffff
7 27 4 ffffff
8 27 4 ffffff
9 27 4 ffffff
10 27 4 ffffff
11 27 4 ffffff
12 27 4 ffffff
13 27 4 ffffff
14 27 4 ffffff
15 27 4 ffffff
0 28 4 ffffff
1 28 4 ffffff
2 28 4 ffffff
3 28 4 ffffff
4 28 4 ffffff
5 28 4 ffffff
6 28 4 ffffff
7 28 4 ffffff
8 28 4 ffffff
9 28 4 ffffff
10 28 4 ffffff
11 28 4 ffffff
12 28 4 ffffff
13 28 4 ffffff
14 28 4 ffffff
15 28 4 ffffff
0 29 4 ffffff
1 29 4 ffffff
2 29 4 ffffff
3 29 4 ffffff
4 29 4 ffffff
5 29 4 ffffff
6 29 4 ffffff
7 29 4 ffffff
8 29 4 ffffff
9 29 4 ffffff
10 29 4 ffffff
11 29 4 ffffff
12 29 4 ffffff
13 29 4 ffffff
14 29 4 ffffff
15 29 4 ffffff
0 30 4 ffffff
1 30 4 ffffff
2 30 4 ffffff
3 30 4 ffffff
4 30 4 ffffff
5 30 4 ffffff
6 30 4 ffffff
7 30 4 ffffff
8 30 4 ffffff
9 30 4 ffffff
10 30 4 ffffff
11 30 4 ffffff
12 30 4 ffffff
13 30 4 ffffff
14 30 4 ffffff
15 30 4 ffffff
0 31 4 ffffff
1 31 4 ffffff
2 31 4 ffffff
3 31 4 ffffff
4 31 4 ffffff
5 31 4 ffffff
6 31 4 ffffff
7 31 4 ffffff
8 31 4 ffffff
9 31 4 ffffff
10 31 4 ffffff
11 31 4 ffffff
12 31 4 ffffff
13 31 4 ffffff
14 31 4 ffffff
15 31 4 ffffff
0 16 5 ffffff
1 16 5 ffffff
2 16 5 ffffff
3 16 5 ffffff
4 16 5 ffffff
5 16 5 ffffff
6 16 5 ffffff
7 16 5 ffffff
8 16 5 ffffff
9 16 5 ffffff
10 16 5 ffffff
11 16 5 ffffff
12 16 5 ffffff
13 16 5 ffffff
14 16 5 ffffff
15 16 5 ffffff
0 17 5 ffffff
1 17 5 ffffff
2 17 5 ffffff
3 17 5 ffffff
4 17 5 ffffff
5 17 5 ffffff
6 17 5 ffffff
7 17 5 ffffff
8 17 5 ffffff
9 17 5 ffffff
10 17 5 ffffff
11 17 5 ffffff
12 17 5 ffffff
13 17 5 ffffff
14 17 5 ffffff
15 17 5 ffffff
0 18 5 ffffff
1 18 5 ffffff
2 18 5 ffffff
3 18 5 ffffff
4 18 5 ffffff
5 18 5 ffffff
6 18 5 ffffff
7 18 5 ffffff
8 18 5 ffffff
9 18 5 ffffff
10 18 5 ffffff
11 18 5 ffffff
12 18 5 ffffff
13 18 5 ffffff
14 18 5 ffffff
15 18 5 ffffff
0 19 5 ffffff
1 19 5 ffffff
2 19 5 ffffff
3 19 5 ffffff
4 19 5 ffffff
5 19 5 ffffff
6 19 5 ffffff
7 19 5 ffffff
8 19 5 ffffff
9 19 5 ffffff
10 19 5 ffffff
11 19 5 ffffff
12 19 5 ffffff
13 19 5 ffffff
14 19 5 ffffff
15 19 5 ffffff
0 20 5 ffffff
1 20 5 ffffff
2 20 5 ffffff
3 20 5 ffffff
4 20 5 ffffff
5 20 5 ffffff
6 20 5 ffffff
7 20 5 ffffff
8 20 5 ffffff
9 20 5 ffffff
10 20 5 ffffff
11 20 5 ffffff
12 20 5 ffffff
13 20 5 ffffff
14 20 5 ffffff
15 20 5 ffffff
0 21 5 ffffff
1 21 5 ffffff
2 21 5 ffffff
3 21 5 ffffff
4 21 5 ffffff
5 21 5 ffffff
6 21 5 ffffff
7 21 5 ffffff
8 21 5 ffffff
9 21 5 ffffff
10 21 5 ffffff
11 21 5 ffffff
12 21 5 ffffff
13 21 5 ffffff
14 21 5 ffffff
15 21 5 ffffff
0 22 5 ffffff
1 22 5 ffffff
2 22 5 ffffff
3 22 5 ffffff
4 22 5 ffffff
5 22 5 ffffff
6 22 5 ffffff
7 22 5 ffffff
8 22 5 ffffff
9 22 5 ffffff
10 22 5 ffffff
11 22 5 ffffff
12 22 5 ffffff
13 22 5 ffffff
14 22 5 ffffff
15 22 5 ffffff
0 23 5 ffffff
1 23 5 ffffff
2 23 5 ffffff
3 23 5 ffffff
4 23 5 ffffff
5 23 5 ffffff
6 23 5 ffffff
7 23 5 ffffff
8 23 5 ffffff
9 23 5 ffffff
10 23 5 ffffff
11 23 5 ffffff
12 23 5 ffffff
13 23 5 ffffff
14 23 5 ffffff
15 23 5 ffffff
0 24 5 ffffff
1 24 5 ffffff
2 24 5 ffffff
3 24 5 ffffff
4 24 5 ffffff
5 24 5 ffffff
6 24 5 ffffff
7 24 5 ffffff
8 24 5 ffffff
9 24 5 ffffff
10 24 5 ffffff
11 24 5 ffffff
12 24 5 ffffff
13 24 5 ffffff
14 24 5 ffffff
15 24 5 ffffff
0 25 5 ffffff
1 25 5 ffffff
2 25 5 ffffff
3 25 5 ffffff
4 25 5 ffffff
5 25 5 ffffff
6 25 5 ffffff
7 25 5 ffffff
8 25 5 ffffff
9 25 5 ffffff
10 25 5 ffffff
11 25 5 ffffff
12 25 5 ffffff
13 25 5 ffffff
14 25 5 ffffff
15 25 5 ffffff
0 26 5 ffffff
1 26 5 ffffff
2 26 5 ffffff
3 26 5 ffffff
4 26 5 ffffff
5 26 5 ffffff
6 26 5 ffffff
7 26 5 ffffff
8 26 5 ffffff
9 26 5 ffffff
10 26 5 ffffff
11 26 5 ffffff
12 26 5 ffffff
13 26 5 ffffff
14 26 5 ffffff
15 26 5 ffffff
0 27 5 ffffff
1 27 5 ffffff
2 27 5 ffffff
3 27 5 ffffff
4 27 5 ffffff
5 27 5 ffffff
6 27 5 ffffff
7 27 5 ffffff
8 27 5 ffffff
9 27 5 ffffff
10 27 5 ffffff
11 27 5 ffffff
12 27 5 ffffff
13 27 5 ffffff
14 27 5 ffffff
15 27 5 ffffff
0 28 5 ffffff
1 28 5 ffffff
2 28 5 ffffff
3 28 5 ffffff
4 28 5 ffffff
5 28 5 ffffff
6 28 5 ffffff
7 28 5 ffffff
8 28 5 ffffff
9 28 5 ffffff
10 28 5 ffffff
11 28 5 ffffff
12 28 5 ffffff
13 28 5 ffffff
14 28 5 ffffff
15 28 5 ffffff
0 29 5 ffffff
1 29 5 ffffff
2 29 5 ffffff
3 29 5 ffffff
4 29 5 ffffff
5 29 5 ffffff
6 29 5 ffffff
7 29 5 ffffff
8 29 5 ffffff
9 29 5 ffffff
10 29 5 ffffff
11 29 5 ffffff
12 29 5 ffffff
13 29 5 ffffff
14 29 5 ffffff
15 29 5 ffffff
0 30 5 ffffff
1 30 5 ffffff
2 30 5 ffffff
3 30 5 ffffff
4 30 5 ffffff
5 30 5 ffffff
6 30 5 ffffff
7 30 5 ffffff
8 30 5 ffffff
9 30 5 ffffff
10 30 5 ffffff
11 30 5 ffffff
12 30 5 ffffff
13 30 5 ffffff
14 30 5 ffffff
15 30 5 ffffff
0 31 5 ffffff
1 31 5 ffffff
2 31 5 ffffff
3 31 5 ffffff
4 31 5 ffffff
5 31 5 ffffff
6 31 5 ffffff
7 31 5 ffffff
8 31 5 ffffff
9 31 5 ffffff
10 31 5 ffffff
11 31 5 ffffff
12 31 5 ffffff
13 31 5 ffffff
14 31 5 ffffff
15 31 5 ffffff
0 16 6 ffffff
1 16 6 ffffff
2 16 6 ffffff
3 16 6 ffffff
4 16 6 ffffff
5 16 6 ffffff
6 16 6 ffffff
7 16 6 ffffff
8 16 6 ffffff
0 17 6 ffffff
1 17 6 ffffff
2 17 6 ffffff
3 17 6 ffffff
4 17 6 ffffff
5 17 6 ffffff
6 17 6 ffffff
7 17 6 ffffff
8 17 6 ffffff
0 18 6 ffffff
1 18 6 ffffff
2 18 6 ffffff
3 18 6 ffffff
4 18 6 ffffff
5 18 6 ffffff
6 18 6 ffffff
7 18 6 ffffff
8 18 6 ffffff
0 19 6 ffffff
1 19 6 ffffff
2 19 6 ffffff
3 19 6 ffffff
4 19 6 ffffff
5 19 6 ffffff
6 19 6 ffffff
7 19 6 ffffff
8 19 6 ffffff
0 20 6 ffffff
1 20 6 ffffff
2 20 6 ffffff
3 20 6 ffffff
4 20 6 ffffff
5 20 6 ffffff
6 20 6 ffffff
7 20 6 ffffff
8 20 6 ffffff
0 21 6 ffffff
1 21 6 ffffff
2 21 6 ffffff
3 21 6 ffffff
4 21 6 ffffff
5 21 6 ffffff
6 21 6 ffffff
7 21 6 ffffff
8 21 6 ffffff
0 22 6 ffffff
1 22 6 ffffff
2 22 6 ffffff
3 22 6 ffffff
4 22 6 ffffff
5 22 6 ffffff
6 22 6 ffffff
7 22 6 ffffff
8 22 6 ffffff
0 23 6 ffffff
1 23 6 ffffff
2 23 6 ffffff
3 23 6 ffffff
4 23 6 ffffff
5 23 6 ffffff
6 23 6 ffffff
7 23 6 ffffff
8 23 6 ffffff
0 24 6 ffffff
1 24 6 ffffff
2 24 6 ffffff
3 24 6 ffffff
4 24 6 ffffff
5 24 6 ffffff
6 24 6 ffffff
7 24 6 ffffff
8 24 6 ffffff
0 25 6 ffffff
1 25 6 ffffff
2 25 6 ffffff
3 25 6 ffffff
4 25 6 ffffff
5 25 6 ffffff
6 25 6 ffffff
7 25 6 ffffff
8 25 6 ffffff
0 26 6 ffffff
1 26 6 ffffff
2 26 6 ffffff
3 26 6 ffffff
4 26 6 ffffff
5 26 6 ffffff
6 26 6 ffffff
7 26 6 ffffff
8 26 6 ffffff
0 27 6 ffffff
1 27 6 ffffff
2 27 6 ffffff
3 27 6 ffffff
4 27 6 ffffff
5 27 6 ffffff
6 27 6 ffffff
7 27 6 ffffff
8 27 6 ffffff
0 28 6 ffffff
1 28 6 ffffff
2 28 6 ffffff
3 28 6 ffffff
4 28 6 ffffff
5 28 6 ffffff
6 28 6 ffffff
7 28 6 ffffff
8 28 6 ffffff
0 29 6 ffffff
1 29 6 ffffff
2 29 6 ffffff
3 29 6 ffffff
4 29 6 ffffff
5 29 6 ffffff
6 29 6 ffffff
7 29 6 ffffff
8 29 6 ffffff
0 30 6 ffffff
1 30 6 ffffff
2 30 6 ffffff
3 30 6 ffffff
4 30 6 ffffff
5 30 6 ffffff
6 30 6 ffffff
7 30 6 ffffff
8 30 6 ffffff
0 31 6 ffffff
1 31 6 ffffff
2 31 6 ffffff
3 31 6 ffffff
4 31 6 ffffff
5 31 6 ffffff
6 31 6 ffffff
7 31 6 ffffff
8 31 6 ffffff
0 16 7 ffffff
1 16 7 ffffff
2 16 7 ffffff
3 16 7 ffffff
4 16 7 ffffff
5 16 7 ffffff
6 16 7 ffffff
7 16 7 ffffff
0 17 7 ffffff
1 17 7 ffffff
2 17 7 ffffff
3 17 7 ffffff
4 17 7 ffffff
5 17 7 ffffff
6 17 7 ffffff
7 17 7 ffffff
0 18 7 ffffff
1 18 7 ffffff
2 18 7 ffffff
3 18 7 ffffff
4 18 7 ffffff
5 18 7 ffffff
6 18 7 ffffff
7 18 7 ffffff
0 19 7 ffffff
1 19 7 ffffff
2 19 7 ffffff
3 19 7 ffffff
4 19 7 ffffff
5 19 7 ffffff
6 19 7 ffffff
7 19 7 ffffff
0 20 7 ffffff
1 20 7 ffffff
2 20 7 ffffff
3 20 7 ffffff
4 20 7 ffffff
5 20 7 ffffff
6 20 7 ffffff
7 20 7 ffffff
0 21 7 ffffff
1 21 7 ffffff
2 21 7 ffffff
3 21 7 ffffff
4 21 7 ffffff
5 21 7 ffffff
6 21 7 ffffff
7 21 7 ffffff
0 22 7 ffffff
1 22 7 ffffff
2 22 7 ffffff
3 22 7 ffffff
4 22 7 ffffff
5 22 7 ffffff
6 22 7 ffffff
7 22 7 ffffff
0 23 7 ffffff
1 23 7 ffffff
2 23 7 ffffff
3 23 7 ffffff
4 23 7 ffffff
5 23 7 ffffff
6 23 7 ffffff
7 23 7 ffffff
0 24 7 ffffff
1 24 7 ffffff
2 24 7 ffffff
3 24 7 ffffff
4 24 7 ffffff
5 24 7 ffffff
6 24 7 ffffff
7 24 7 ffffff
0 25 7 ffffff
1 25 7 ffffff
2 25 7 ffffff
3 25 7 ffffff
4 25 7 ffffff
5 25 7 ffffff
6 25 7 ffffff
7 25 7 ffffff
0 26 7 ffffff
1 26 7 ffffff
2 26 7 ffffff
3 26 7 ffffff
4 26 7 ffffff
5 26 7 ffffff
6 26 7 ffffff
7 26 7 ffffff
0 27 7 ffffff
1 27 7 ffffff
2 27 7 ffffff
3 27 7 ffffff
4 27 7 ffffff
5 27 7 ffffff
6 27 7 ffffff
7 27 7 ffffff
0 28 7 ffffff
1 28 7 ffffff
2 28 7 ffffff
3 28 7 ffffff
4 28 7 ffffff
5 28 7 ffffff
6 28 7 ffffff
7 28 7 ffffff
0 29 7 ffffff
1 29 7 ffffff
2 29 7 ffffff
3 29 7 ffffff
4 29 7 ffffff
5 29 7 ffffff
6 29 7 ffffff
7 29 7 ffffff
0 30 7 ffffff
1 30 7 ffffff
2 30 7 ffffff
3 30 7 ffffff
4 30 7 ffffff
5 30 7 ffffff
6 30 7 ffffff
7 30 7 ffffff
0 31 7 ffffff
1 31 7 ffffff
2 31 7 ffffff
3 31 7 ffffff
4 31 7 ffffff
5 31 7 ffffff
6 31 7 ffffff
7 31 7 ffffff
0 16 8 ffffff
1 16 8 ffffff
2 16 8 ffffff
3 16 8 ffffff
4 16 8 ffffff
5 16 8 ffffff
6 16 8 ffffff
0 17 8 ffffff
1 17 8 ffffff
2 17 8 ffffff
3 17 8 ffffff
4 17 8 ffffff
5 17 8 ffffff
6 17 8 ffffff
0 18 8 ffffff
1 18 8 ffffff
2 18 8 ffffff
3 18 8 ffffff
4 18 8 ffffff
5 18 8 ffffff
6 18 8 ffffff
0 19 8 ffffff
1 19 8 ffffff
2 19 8 ffffff
3 19 8 ffffff
4 19 8 ffffff
5 19 8 ffffff
6 19 8 ffffff
0 20 8 ffffff
1 20 8 ffffff
2 20 8 ffffff
3 20 8 ffffff
4 20 8 ffffff
5 20 8 ffffff
6 20 8 ffffff
0 21 8 ffffff
1 21 8 ffffff
2 21 8 ffffff
3 21 8 ffffff
4 21 8 ffffff
5 21 8 ffffff
6 21 8 ffffff
0 22 8 ffffff
1 22 8 ffffff
2 22 8 ffffff
3 22 8 ffffff
4 22 8 ffffff
5 22 8 ffffff
6 22 8 ffffff
0 23 8 ffffff
1 23 8 ffffff
2 23 8 ffffff
3 23 8 ffffff
4 23 8 ffffff
5 23 8 ffffff
6 23 8 ffffff
0 24 8 ffffff
1 24 8 ffffff
2 24 8 ffffff
3 24 8 ffffff
4 24 8 ffffff
5 24 8 ffffff
6 24 8 ffffff
0 25 8 ffffff
1 25 8 ffffff
2 25 8 ffffff
3 25 8 ffffff
4 25 8 ffffff
5 25 8 ffffff
6 25 8 ffffff
0 26 8 ffffff
1 26 8 ffffff
2 26 8 ffffff
3 26 8 ffffff
4 26 8 ffffff
5 26 8 ffffff
6 26 8 ffffff
0 27 8 ffffff
1 27 8 ffffff
2 27 8 ffffff
3 27 8 ffffff
4 27 8 ffffff
5 27 8 ffffff
6 27 8 ffffff
0 28 8 ffffff
1 28 8 ffffff
2 28 8 ffffff
3 28 8 ffffff
4 28 8 ffffff
5 28 8 ffffff
6 28 8 ffffff
0 29 8 ffffff
1 29 8 ffffff
2 29 8 ffffff
3 29 8 ffffff
4 29 8 ffffff
5 29 8 ffffff
6 29 8 ffffff
0 30 8 ffffff
1 30 8 ffffff
2 30 8 ffffff
3 30 8 ffffff
4 30 8 ffffff
5 30 8 ffffff
6 30 8 ffffff
0 31 8 ffffff
1 31 8 ffffff
2 31 8 ffffff
3 31 8 ffffff
4 31 8 ffffff
5 31 8 ffffff
6 31 8 ffffff
0 16 9 ffffff
1 16 9 ffffff
2 16 9 ffffff
3 16 9 ffffff
4 16 9 ffffff
5 16 9 ffffff
0 17 9 ffffff
1 17 9 ffffff
2 17 9 ffffff
3 17 9 ffffff
4 17 9 ffffff
5 17 9 ffffff
0 18 9 ffffff
1 18 9 ffffff
2 18 9 ffffff
3 18 9 ffffff
4 18 9 ffffff
5 18 9 ffffff
0 19 9 ffffff
1 19 9 ffffff
2 19 9 ffffff
3 19 9 ffffff
4 19 9 ffffff
5 19 9 ffffff
0 20 9 ffffff
1 20 9 ffffff
2 20 9 ffffff
3 20 9 ffffff
4 20 9 ffffff
5 20 9 ffffff
0 21 9 ffffff
1 21 9 ffffff
2 21 9 ffffff
3 21 9 ffffff
4 21 9 ffffff
5 21 9 ffffff
0 22 9 ffffff
1 22 9 ffffff
2 22 9 ffffff
3 22 9 ffffff
4 22 9 ffffff
5 22 9 ffffff
0 23 9 ffffff
1 23 9 ffffff
2 23 9 ffffff
3 23 9 ffffff
4 23 9 ffffff
5 23 9 ffffff
0 24 9 ffffff
1 24 9 ffffff
2 24 9 ffffff
3 24 9 ffffff
4 24 9 ffffff
5 24 9 ffffff
0 25 9 ffffff
1 25 9 ffffff
2 25 9 ffffff
3 25 9 ffffff
4 25 9 ffffff
5 25 9 ffffff
0 26 9 ffffff
1 26 9 ffffff
2 26 9 ffffff
3 26 9 ffffff
4 26 9 ffffff
5 26 9 ffffff
0 27 9 ffffff
1 27 9 ffffff
2 27 9 ffffff
3 27 9 ffffff
4 27 9 ffffff
5 27 9 ffffff
0 28 9 ffffff
1 28 9 ffffff
2 28 9 ffffff
3 28 9 ffffff
4 28 9 ffffff
5 28 9 ffffff
0 29 9 ffffff
1 29 9 ffffff
2 29 9 ffffff
3 29 9 ffffff
4 29 9 ffffff
5 29 9 ffffff
0 30 9 ffffff
1 30 9 ffffff
2 30 9 ffffff
3 30 9 ffffff
4 30 9 ffffff
5 30 9 ffffff
0 31 9 ffffff
1 31 9 ffffff
2 31 9 ffffff
3 31 9 ffffff
4 31 9 ffffff
5 31 9 ffffff
0 32 0 ffffff
1 32 0 ffffff
2 32 0 ffffff
3 32 0 ffffff
4 32 0 ffffff
5 32 0 ffffff
6 32 0 ffffff
7 32 0 ffffff
8 32 0 ffffff
9 32 0 ffffff
10 32 0 ffffff
11 32 0 ffffff
12 32 0 ffffff
13 32 0 ffffff
14 32 0 ffffff
15 32 0 ffffff
0 33 0 ffffff
1 33 0 ffffff
2 33 0 ffffff
3 33 0 ffffff
4 33 0 ffffff
5 33 0 ffffff
6 33 0 ffffff
7 33 0 ffffff
8 33 0 ffffff
9 33 0 ffffff
10 33 0 ffffff
11 33 0 ffffff
12 33 0 ffffff
13 33 0 ffffff
14 33 0 ffffff
15 33 0 ffffff
0 34 0 ffffff
1 34 0 ffffff
2 34 0 ffffff
3 34 0 ffffff
4 34 0 ffffff
5 34 0 ffffff
6 34 0 ffffff
7 34 0 ffffff
8 34 0 ffffff
9 34 0 ffffff
10 34 0 ffffff
11 34 0 ffffff
12 34 0 ffffff
13 34 0 ffffff
14 34 0 ffffff
15 34 0 ffffff
0 35 0 ffffff
1 35 0 ffffff
2 35 0 ffffff
3 35 0 ffffff
4 35 0 ffffff
5 35 0 ffffff
6 35 0 ffffff
7 35 0 ffffff
8 35 0 ffffff
9 35 0 ffffff
10 35 0 ffffff
11 35 0 ffffff
12 35 0 ffffff
13 35 0 ffffff
14 35 0 ffffff
15 35 0 ffffff
0 36 0 ffffff
1 36 0 ffffff
2 36 0 ffffff
3 36 0 ffffff
4 36 0 ffffff
5 36 0 ffffff
6 36 0 ffffff
7 36 0 ffffff
8 36 0 ffffff
9 36 0 ffffff
10 36 0 ffffff
11 36 0 ffffff
12 36 0 ffffff
13 36 0 ffffff
14 36 0 ffffff
15 36 0 ffffff
0 37 0 ffffff
1 37 0 ffffff
2 37 0 ffffff
3 37 0 ffffff
4 37 0 ffffff
5 37 0 ffffff
6 37 0 ffffff
7 37 0 ffffff
8 37 0 ffffff
9 37 0 ffffff
10 37 0 ffffff
11 37 0 ffffff
12 37 0 ffffff
13 37 0 ffffff
14 37 0 ffffff
15 37 0 ffffff
0 38 0 ffffff
1 38 0 ffffff
2 38 0 ffffff
3 38 0 ffffff
4 38 0 ffffff
5 38 0 ffffff
6 38 0 ffffff
7 38 0 ffffff
8 38 0 ffffff
9 38 0 ffffff
10 38 0 ffffff
11 38 0 ffffff
12 38 0 ffffff
13 38 0 ffffff
14 38 0 ffffff
15 38 0 ffffff
0 39 0 ffffff
1 39 0 ffffff
2 39 0 ffffff
3 39 0 ffffff
4 39 0 ffffff
5 39 0 ffffff
6 39 0 ffffff
7 39 0 ffffff
8 39 0 ffffff
9 39 0 ffffff
10 39 0 ffffff
11 39 0 ffffff
12 39 0 ffffff
13 39 0 ffffff
14 39 0 ffffff
15 39 0 ffffff
0 40 0 ffffff
1 40 0 ffffff
2 40 0 ffffff
3 40 0 ffffff
4 40 0 ffffff
5 40 0 ffffff
6 40 0 ffffff
7 40 0 ffffff
8 40 0 ffffff
9 40 0 ffffff
10 40 0 ffffff
11 40 0 ffffff
12 40 0 ffffff
13 40 0 ffffff
14 40 0 ffffff
15 40 0 ffffff
0 41 0 ffffff
1 41 0 ffffff
2 41 0 ffffff
3 41 0 ffffff
4 41 0 ffffff
5 41 0 ffffff
6 41 0 ffffff
7 41 0 ffffff
8 41 0 ffffff
9 41 0 ffffff
10 41 0 ffffff
11 41 0 ffffff
12 41 0 ffffff
13 41 0 ffffff
14 41 0 ffffff
15 41 0 ffffff
0 42 0 ffffff
1 42 0 ffffff
2 42 0 ffffff
3 42 0 ffffff
4 42 0 ffffff
5 42 0 ffffff
6 42 0 ffffff
7 42 0 ffffff
8 42 0 ffffff
9 42 0 ffffff
10 42 0 ffffff
11 42 0 ffffff
12 42 0 ffffff
13 42 0 ffffff
14 42 0 ffffff
15 42 0 ffffff
0 43 0 ffffff
1 43 0 ffffff
2 43 0 ffffff
3 43 0 ffffff
4 43 0 ffffff
5 43 0 ffffff
6 43 0 ffffff
7 43 0 ffffff
8 43 0 ffffff
9 43 0 ffffff
10 43 0 ffffff
11 43 0 ffffff
12 43 0 ffffff
13 43 0 ffffff
14 43 0 ffffff
15 43 0 ffffff
0 44 0 ffffff
1 44 0 ffffff
2 44 0 ffffff
3 44 0 ffffff
4 44 0 ffffff
5 44 0 ffffff
6 44 0 ffffff
7 44 0 ffffff
8 44 0 ffffff
9 44 0 ffffff
10 44 0 ffffff
11 44 0 ffffff
12 44 0 ffffff
13 44 0 ffffff
14 44 0 ffffff
15 44 0 ffffff
0 45 0 ffffff
1 45 0 ffffff
2 45 0 ffffff
3 45 0 ffffff
4 45 0 ffffff
5 45 0 ffffff
6 45 0 ffffff
7 45 0 ffffff
8 45 0 ffffff
9 45 0 ffffff
10 45 0 ffffff
11 45 0 ffffff
12 45 0 ffffff
13 45 0 ffffff
14 45 0 ffffff
15 45 0 ffffff
0 46 0 ffffff
1 46 0 ffffff
2 46 0 ffffff
3 46 0 ffffff
4 46 0 ffffff
5 46 0 ffffff
6 46 0 ffffff
7 46 0 ffffff
8 46 0 ffffff
9 46 0 ffffff
10 46 0 ffffff
11 46 0 ffffff
12 46 0 ffffff
13 46 0 ffffff
14 46 0 ffffff
15 46 0 ffffff
0 47 0 ffffff
1 47 0 ffffff
2 47 0 ffffff
3 47 0 ffffff
4 47 0 ffffff
5 47 0 ffffff
6 47 0 ffffff
7 47 0 ffffff
8 47 0 ffffff
9 47 0 ffffff
10 47 0 ffffff
11 47 0 ffffff
12 47 0 ffffff
13 47 0 ffffff
14 47 0 ffffff
15 47 0 ffffff
0 32 1 ffffff
1 32 1 ffffff
2 32 1 ffffff
3 32 1 ffffff
4 32 1 ffffff
5 32 1 ffffff
6 32 1 ffffff
7 32 1 ffffff
8 32 1 ffffff
9 32 1 ffffff
10 32 1 ffffff
11 32 1 ffffff
12 32 1 ffffff
13 32 1 ffffff
14 32 1 ffffff
15 32 1 ffffff
0 33 1 ffffff
1 33 1 ffffff
2 33 1 ffffff
3 33 1 ffffff
4 33 1 ffffff
5 33 1 ffffff
6 33 1 ffffff
7 33 1 ffffff
8 33 1 ffffff
9 33 1 ffffff
10 33 1 ffffff
11 33 1 ffffff
12 33 1 ffffff
13 33 1 ffffff
14 33 1 ffffff
15 33 1 ffffff
0 34 1 ffffff
1 34 1 ffffff
2 34 1 ffffff
3 34 1 ffffff
4 34 1 ffffff
5 34 1 ffffff
6 34 1 ffffff
7 34 1 ffffff
8 34 1 ffffff
9 34 1 ffffff
10 34 1 ffffff
11 34 1 ffffff
12 34 1 ffffff
13 34 1 ffffff
14 34 1 ffffff
15 34 1 ffffff
0 35 1 ffffff
1 35 1 ffffff
2 35 1 ffffff
3 35 1 ffffff
4 35 1 ffffff
5 35 1 ffffff
6 35 1 ffffff
7 35 1 ffffff
8 35 1 ffffff
9 35 1 ffffff
10 35 1 ffffff
11 35 1 ffffff
12 35 1 ffffff
13 35 1 ffffff
14 35 1 ffffff
15 35 1 ffffff
0 36 1 ffffff
1 36 1 ffffff
2 36 1 ffffff
3 36 1 ffffff
4 36 1 ffffff
5 36 1 ffffff
6 36 1 ffffff
7 36 1 ffffff
8 36 1 ffffff
9 36 1 ffffff
10 36 1 ffffff
11 36 1 ffffff
12 36 1 ffffff
13 36 1 ffffff
14 36 1 ffffff
15 36 1 ffffff
0 37 1 ffffff
1 37 1 ffffff
2 37 1 ffffff
3 37 1 ffffff
4 37 1 ffffff
5 37 1 ffffff
6 37 1 ffffff
7 37 1 ffffff
8 37 1 ffffff
9 37 1 ffffff
10 37 1 ffffff
11 37 1 ffffff
12 37 1 ffffff
13 37 1 ffffff
14 37 1 ffffff
15 37 1 ffffff
0 38 1 ffffff
1 38 1 ffffff
2 38 1 ffffff
3 38 1 ffffff
4 38 1 ffffff
5 38 1 ffffff
6 38 1 ffffff
7 38 1 ffffff
8 38 1 ffffff
9 38 1 ffffff
10 38 1 ffffff
11 38 1 ffffff
12 38 1 ffffff
13 38 1 ffffff
14 38 1 ffffff
15 38 1 ffffff
0 39 1 ffffff
1 39 1 ffffff
2 39 1 ffffff
3 39 1 ffffff
4 39 1 ffffff
5 39 1 ffffff
6 39 1 ffffff
7 39 1 ffffff
8 39 1 ffffff
9 39 1 ffffff
10 39 1 ffffff
11 39 1 ffffff
12 39 1 ffffff
13 39 1 ffffff
14 39 1 ffffff
15 39 1 ffffff
0 40 1 ffffff
1 40 1 ffffff
2 40 1 ffffff
3 40 1 ffffff
4 40 1 ffffff
5 40 1 ffffff
6 40 1 ffffff
7 40 1 ffffff
8 40 1 ffffff
9 40 1 ffffff
10 40 1 ffffff
11 40 1 ffffff
12 40 1 ffffff
13 40 1 ffffff
14 40 1 ffffff
15 40 1 ffffff
0 41 1 ffffff
1 41 1 ffffff
2 41 1 ffffff
3 41 1 ffffff
4 41 1 ffffff
5 41 1 ffffff
6 41 1 ffffff
7 41 1 ffffff
8 41 1 ffffff
9 41 1 ffffff
10 41 1 ffffff
11 41 1 ffffff
12 41 1 ffffff
13 41 1 ffffff
14 41 1 ffffff
15 41 1 ffffff
0 42 1 ffffff
1 42 1 ffffff
2 42 1 ffffff
3 42 1 ffffff
4 42 1 ffffff
5 42 1 ffffff
6 42 1 ffffff
7 42 1 ffffff
8 42 1 ffffff
9 42 1 ffffff
10 42 1 ffffff
11 42 1 ffffff
12 42 1 ffffff
13 42 1 ffffff
14 42 1 ffffff
15 42 1 ffffff
0 43 1 ffffff
1 43 1 ffffff
2 43 1 ffffff
3 43 1 ffffff
4 43 1 ffffff
5 43 1 ffffff
6 43 1 ffffff
7 43 1 ffffff
8 43 1 ffffff
9 43 1 ffffff
10 43 1 ffffff
11 43 1 ffffff
12 43 1 ffffff
13 43 1 ffffff
14 43 1 ffffff
15 43 1 ffffff
0 44 1 ffffff
1 44 1 ffffff
2 44 1 ffffff
3 44 1 ffffff
4 44 1 ffffff
5 44 1 ffffff
6 44 1 ffffff
7 44 1 ffffff
8 44 1 ffffff
9 44 1 ffffff
10 44 1 ffffff
11 44 1 ffffff
12 44 1 ffffff
13 44 1 ffffff
14 44 1 ffffff
15 44 1 ffffff
0 45 1 ffffff
1 45 1 ffffff
2 45 1 ffffff
3 45 1 ffffff
4 45 1 ffffff
5 45 1 ffffff
6 45 1 ffffff
7 45 1 ffffff
8 45 1 ffffff
9 45 1 ffffff
10 45 1 ffffff
11 45 1 ffffff
12 45 1 ffffff
13 45 1 ffffff
14 45 1 ffffff
15 45 1 ffffff
0 46 1 ffffff
1 46 1 ffffff
2 46 1 ffffff
3 46 1 ffffff
4 46 1 ffffff
5 46 1 ffffff
6 46 1 ffffff
7 46 1 ffffff
8 46 1 ffffff
9 46 1 ffffff
10 46 1 ffffff
11 46 1 ffffff
12 46 1 ffffff
13 46 1 ffffff
14 46 1 ffffff
15 46 1 ffffff
0 47 1 ffffff
1 47 1 ffffff
2 47 1 ffffff
3 47 1 ffffff
4 47 1 ffffff
5 47 1 ffffff
6 47 1 ffffff
7 47 1 ffffff
8 47 1 ffffff
9 47 1 ffffff
10 47 1 ffffff
11 47 1 ffffff
12 47 1 ffffff
13 47 1 ffffff
14 47 1 ffffff
15 47 1 ffffff
0 32 2 ffffff
1 32 2 ffffff
2 32 2 ffffff
3 32 2 ffffff
4 32 2 ffffff
5 32 2 ffffff
6 32 2 ffffff
7 32 2 ffffff
8 32 2 ffffff
9 32 2 ffffff
10 32 2 ffffff
11 32 2 ffffff
12 32 2 ffffff
13 32 2 ffffff
14 32 2 ffffff
15 32 2 ffffff
0 33 2 ffffff
1 33 2 ffffff
2 33 2 ffffff
3 33 2 ffffff
4 33 2 ffffff
5 33 2 ffffff
6 33 2 ffffff
7 33 2 ffffff
8 33 2 ffffff
9 33 2 ffffff
10 33 2 ffffff
11 33 2 ffffff
12 33 2 ffffff
13 33 2 ffffff
14 33 2 ffffff
15 33 2 ffffff
0 34 2 ffffff
1 34 2 ffffff
2 34 2 ffffff
3 34 2 ffffff
4 34 2 ffffff
5 34 2 ffffff
6 34 2 ffffff
7 34 2 ffffff
8 34 2 ffffff
9 34 2 ffffff
10 34 2 ffffff
11 34 2 ffffff
12 34 2 ffffff
13 34 2 ffffff
14 34 2 ffffff
15 34 2 ffffff
0 35 2 ffffff
1 35 2 ffffff
2 35 2 ffffff
3 35 2 ffffff
4 35 2 ffffff
5 35 2 ffffff
6 35 2 ffffff
7 35 2 ffffff
8 35 2 ffffff
9 35 2 ffffff
10 35 2 ffffff
11 35 2 ffffff
12 35 2 ffffff
13 35 2 ffffff
14 35 2 ffffff
15 35 2 ffffff
0 36 2 ffffff
1 36 2 ffffff
2 36 2 ffffff
3 36 2 ffffff
4 36 2 ffffff
5 36 2 ffffff
6 36 2 ffffff
7 36 2 ffffff
8 36 2 ffffff
9 36 2 ffffff
10 36 2 ffffff
11 36 2 ffffff
12 36 2 ffffff
13 36 2 ffffff
14 36 2 ffffff
15 36 2 ffffff
0 37 2 ffffff
1 37 2 ffffff
2 37 2 ffffff
3 37 2 ffffff
4 37 2 ffffff
5 37 2 ffffff
6 37 2 ffffff
7 37 2 ffffff
8 37 2 ffffff
9 37 2 ffffff
10 37 2 ffffff
11 37 2 ffffff
12 37 2 ffffff
13 37 2 ffffff
14 37 2 ffffff
15 37 2 ffffff
0 38 2 ffffff
1 38 2 ffffff
2 38 2 ffffff
3 38 2 ffffff
4 38 2 ffffff
5 38 2 ffffff
6 38 2 ffffff
7 38 2 ffffff
8 38 2 ffffff
9 38 2 ffffff
10 38 2 ffffff
11 38 2 ffffff
12 38 2 ffffff
13 38 2 ffffff
14 38 2 ffffff
15 38 2 ffffff
0 39 2 ffffff
1 39 2 ffffff
2 39 2 ffffff
3 39 2 ffffff
4 39 2 ffffff
5 39 2 ffffff
6 39 2 ffffff
7 39 2 ffffff
8 39 2 ffffff
9 39 2 ffffff
10 39 2 ffffff
11 39 2 ffffff
12 39 2 ffffff
13 39 2 ffffff
14 39 2 ffffff
15 39 2 ffffff
0 40 2 ffffff
1 40 2 ffffff
2 40 2 ffffff
3 40 2 ffffff
4 40 2 ffffff
5 40 2 ffffff
6 40 2 ffffff
7 40 2 ffffff
8 40 2 ffffff
9 40 2 ffffff
10 40 2 ffffff
11 40 2 ffffff
12 40 2 ffffff
13 40 2 ffffff
14 40 2 ffffff
15 40 2 ffffff
0 41 2 ffffff
1 41 2 ffffff
2 41 2 ffffff
3 41 2 ffffff
4 41 2 ffffff
5 41 2 ffffff
6 41 2 ffffff
7 41 2 ffffff
8 41 2 ffffff
9 41 2 ffffff
10 41 2 ffffff
11 41 2 ffffff
12 41 2 ffffff
13 41 2 ffffff
14 41 2 ffffff
15 41 2 ffffff
0 42 2 ffffff
1 42 2 ffffff
2 42 2 ffffff
3 42 2 ffffff
4 42 2 ffffff
5 42 2 ffffff
6 42 2 ffffff
7 42 2 ffffff
8 42 2 ffffff
9 42 2 ffffff
10 42 2 ffffff
11 42 2 ffffff
12 42 2 ffffff
13 42 2 ffffff
14 42 2 ffffff
15 42 2 ffffff
0 43 2 ffffff
1 43 2 ffffff
2 43 2 ffffff
3 43 2 ffffff
4 43 2 ffffff
5 43 2 ffffff
6 43 2 ffffff
7 43 2 ffffff
8 43 2 ffffff
9 43 2 ffffff
10 43 2 ffffff
11 43 2 ffffff
12 43 2 ffffff
13 43 2 ffffff
14 43 2 ffffff
15 43 2 ffffff
0 44 2 ffffff
1 44 2 ffffff
2 44 2 ffffff
3 44 2 ffffff
4 44 2 ffffff
5 44 2 ffffff
6 44 2 ffffff
7 44 2 ffffff
8 44 2 ffffff
9 44 2 ffffff
10 44 2 ffffff
11 44 2 ffffff
12 44 2 ffffff
13 44 2 ffffff
14 44 2 ffffff
15 44 2 ffffff
0 45 2 ffffff
1 45 2 ffffff
2 45 2 ffffff
3 45 2 ffffff
4 45 2 ffffff
5 45 2 ffffff
6 45 2 ffffff
7 45 2 ffffff
8 45 2 ffffff
9 45 2 ffffff
10 45 2 ffffff
11 45 2 ffffff
12 45 2 ffffff
13 45 2 ffffff
14 45 2 ffffff
15 45 2 ffffff
0 46 2 ffffff
1 46 2 ffffff
2 46 2 ffffff
3 46 2 ffffff
4 46 2 ffffff
5 46 2 ffffff
6 46 2 ffffff
7 46 2 ffffff
8 46 2 ffffff
9 46 2 ffffff
10 46 2 ffffff
11 46 2 ffffff
12 46 2 ffffff
13 46 2 ffffff
14 46 2 ffffff
15 46 2 ffffff
0 47 2 ffffff
1 47 2 ffffff
2 47 2 ffffff
3 47 2 ffffff
4 47 2 ffffff
5 47 2 ffffff
6 47 2 ffffff
7 47 2 ffffff
8 47 2 ffffff
9 47 2 ffffff
10 47 2 ffffff
11 47 2 ffffff
12 47 2 ffffff
13 47 2 ffffff
14 47 2 ffffff
15 47 2 ffffff
0 32 3 ffffff
1 32 3 ffffff
2 32 3 ffffff
3 32 3 ffffff
4 32 3 ffffff
5 32 3 ffffff
6 32 3 ffffff
7 32 3 ffffff
8 32 3 ffffff
9 32 3 ffffff
10 32 3 ffffff
11 32 3 ffffff
12 32 3 ffffff
13 32 3 ffffff
14 32 3 ffffff
15 32 3 ffffff
0 33 3 ffffff
1 33 3 ffffff
2 33 3 ffffff
3 33 3 ffffff
4 33 3 ffffff
5 33 3 ffffff
6 33 3 ffffff
7 33 3 ffffff
8 33 3 ffffff
9 33 3 ffffff
10 33 3 ffffff
11 33 3 ffffff
12 33 3 ffffff
13 33 3 ffffff
14 33 3 ffffff
15 33 3 ffffff
0 34 3 ffffff
1 34 3 ffffff
2 34 3 ffffff
3 34 3 ffffff
4 34 3 ffffff
5 34 3 ffffff
6 34 3 ffffff
7 34 3 ffffff
8 34 3 ffffff
9 34 3 ffffff
10 34 3 ffffff
11 34 3 ffffff
12 34 3 ffffff
13 34 3 ffffff
14 34 3 ffffff
15 34 3 ffffff
0 35 3 ffffff
1 35 3 ffffff
2 35 3 ffffff
3 35 3 ffffff
4 35 3 ffffff
5 35 3 ffffff
6 35 3 ffffff
7 35 3 ffffff
8 35 3 ffffff
9 35 3 ffffff
10 35 3 ffffff
11 35 3 ffffff
12 35 3 ffffff
13 35 3 ffffff
14 35 3 ffffff
15 35 3 ffffff
0 36 3 ffffff
1 36 3 ffffff
2 36 3 ffffff
3 36 3 ffffff
4 36 3 ffffff
5 36 3 ffffff
6 36 3 ffffff
7 36 3 ffffff
8 36 3 ffffff
9 36 3 ffffff
10 36 3 ffffff
11 36 3 ffffff
12 36 3 ffffff
13 36 3 ffffff
14 36 3 ffffff
15 36 3 ffffff
0 37 3 ffffff
1 37 3 ffffff
2 37 3 ffffff
3 37 3 ffffff
4 37 3 ffffff
5 37 3 ffffff
6 37 3 ffffff
7 37 3 ffffff
8 37 3 ffffff
9 37 3 ffffff
10 37 3 ffffff
11 37 3 ffffff
12 37 3 ffffff
13 37 3 ffffff
14 37 3 ffffff
15 37 3 ffffff
0 38 3 ffffff
1 38 3 ffffff
2 38 3 ffffff
3 38 3 ffffff
4 38 3 ffffff
5 38 3 ffffff
6 38 3 ffffff
7 38 3 ffffff
8 38 3 ffffff
9 38 3 ffffff
10 38 3 ffffff
11 38 3 ffffff
12 38 3 ffffff
13 38 3 ffffff
14 38 3 ffffff
15 38 3 ffffff
0 39 3 ffffff
1 39 3 ffffff
2 39 3 ffffff
3 39 3 ffffff
4 39 3 ffffff
5 39 3 ffffff
6 39 3 ffffff
7 39 3 ffffff
8 39 3 ffffff
9 39 3 ffffff
10 39 3 ffffff
11 39 3 ffffff
12 39 3 ffffff
13 39 3 ffffff
14 39 3 ffffff
15 39 3 ffffff
0 40 3 ffffff
1 40 3 ffffff
2 40 3 ffffff
3 40 3 ffffff
4 40 3 ffffff
5 40 3 ffffff
6 40 3 ffffff
7 40 3 ffffff
8 40 3 ffffff
9 40 3 ffffff
10 40 3 ffffff
11 40 3 ffffff
12 40 3 ffffff
13 40 3 ffffff
14 40 3 ffffff
15 40 3 ffffff
0 41 3 ffffff
1 41 3 ffffff
2 41 3 ffffff
3 41 3 ffffff
4 41 3 ffffff
5 41 3 ffffff
6 41 3 ffffff
7 41 3 ffffff
8 41 3 ffffff
9 41 3 ffffff
10 41 3 ffffff
11 41 3 ffffff
12 41 3 ffffff
13 41 3 ffffff
14 41 3 ffffff
15 41 3 ffffff
0 42 3 ffffff
1 42 3 ffffff
2 42 3 ffffff
3 42 3 ffffff
4 42 3 ffffff
5 42 3 ffffff
6 42 3 ffffff
7 42 3 ffffff
8 42 3 ffffff
9 42 3 ffffff
10 42 3 ffffff
11 42 3 ffffff
12 42 3 ffffff
13 42 3 ffffff
14 42 3 ffffff
15 42 3 ffffff
0 43 3 ffffff
1 43 3 ffffff
2 43 3 ffffff
3 43 3 ffffff
4 43 3 ffffff
5 43 3 ffffff
6 43 3 ffffff
7 43 3 ffffff
8 43 3 ffffff
9 43 3 ffffff
10 43 3 ffffff
11 43 3 ffffff
12 43 3 ffffff
13 43 3 ffffff
14 43 3 ffffff
15 43 3 ffffff
0 44 3 ffffff
1 44 3 ffffff
2 44 3 ffffff
3 44 3 ffffff
4 44 3 ffffff
5 44 3 ffffff
6 44 3 ffffff
7 44 3 ffffff
8 44 3 ffffff
9 44 3 ffffff
10 44 3 ffffff
11 44 3 ffffff
12 44 3 ffffff
13 44 3 ffffff
14 44 3 ffffff
15 44 3 ffffff
0 45 3 ffffff
1 45 3 ffffff
2 45 3 ffffff
3 45 3 ffffff
4 45 3 ffffff
5 45 3 ffffff
6 45 3 ffffff
7 45 3 ffffff
8 45 3 ffffff
9 45 3 ffffff
10 45 3 ffffff
11 45 3 ffffff
12 45 3 ffffff
13 45 3 ffffff
14 45 3 ffffff
15 45 3 ffffff
0 46 3 ffffff
1 46 3 ffffff
2 46 3 ffffff
3 46 3 ffffff
4 46 3 ffffff
5 46 3 ffffff
6 46 3 ffffff
7 46 3 ffffff
8 46 3 ffffff
9 46 3 ffffff
10 46 3 ffffff
11 46 3 ffffff
12 46 3 ffffff
13 46 3 ffffff
14 46 3 ffffff
15 46 3 ffffff
0 47 3 ffffff
1 47 3 ffffff
2 47 3 ffffff
3 47 3 ffffff
4 47 3 ffffff
5 47 3 ffffff
6 47 3 ffffff
7 47 3 ffffff
8 47 3 ffffff
9 47 3 ffffff
10 47 3 ffffff
11 47 3 ffffff
12 47 3 ffffff
13 47 3 ffffff
14 47 3 ffffff
15 47 3 ffffff
0 32 4 ffffff
1 32 4 ffffff
2 32 4 ffffff
3 32 4 ffffff
4 32 4 ffffff
5 32 4 ffffff
6 32 4 ffffff
7 32 4 ffffff
8 32 4 ffffff
9 32 4 ffffff
10 32 4 ffffff
11 32 4 ffffff
12 32 4 ffffff
13 32 4 ffffff
14 32 4 ffffff
15 32 4 ffffff
0 33 4 ffffff
1 33 4 ffffff
2 33 4 ffffff
3 33 4 ffffff
4 33 4 ffffff
5 33 4 ffffff
6 33 4 ffffff
7 33 4 ffffff
8 33 4 ffffff
9 33 4 ffffff
10 33 4 ffffff
11 33 4 ffffff
12 33 4 ffffff
13 33 4 ffffff
14 33 4 ffffff
15 33 4 ffffff
0 34 4 ffffff
1 34 4 ffffff
2 34 4 ffffff
3 34 4 ffffff
4 34 4 ffffff
5 34 4 ffffff
6 34 4 ffffff
7 34 4 ffffff
8 34 4 ffffff
9 34 4 ffffff
10 34 4 ffffff
11 34 4 ffffff
12 34 4 ffffff
13 34 4 ffffff
14 34 4 ffffff
15 34 4 ffffff
0 35 4 ffffff
1 35 4 ffffff
2 35 4 ffffff
3 35 4 ffffff
4 35 4 ffffff
5 35 4 ffffff
6 35 4 ffffff
7 35 4 ffffff
8 35 4 ffffff
9 35 4 ffffff
10 35 4 ffffff
11 35 4 ffffff
12 35 4 ffffff
13 35 4 ffffff
14 35 4 ffffff
15 35 4 ffffff
0 36 4 ffffff
1 36 4 ffffff
2 36 4 ffffff
3 36 4 ffffff
4 36 4 ffffff
5 36 4 ffffff
6 36 4 ffffff
7 36 4 ffffff
8 36 4 ffffff
9 36 4 ffffff
10 36 4 ffffff
11 36 4 ffffff
12 36 4 ffffff
13 36 4 ffffff
14 36 4 ffffff
15 36 4 ffffff
0 37 4 ffffff
1 37 4 ffffff
2 37 4 ffffff
3 37 4 ffffff
4 37 4 ffffff
5 37 4 ffffff
6 37 4 ffffff
7 37 4 ffffff
8 37 4 ffffff
9 37 4 ffffff
10 37 4 ffffff
11 37 4 ffffff
12 37 4 ffffff
13 37 4 ffffff
14 37 4 ffffff
15 37 4 ffffff
0 38 4 ffffff
1 38 4 ffffff
2 38 4 ffffff
3 38 4 ffffff
4 38 4 ffffff
5 38 4 ffffff
6 38 4 ffffff
7 38 4 ffffff
8 38 4 ffffff
9 38 4 ffffff
10 38 4 ffffff
11 38 4 ffffff
12 38 4 ffffff
13 38 4 ffffff
14 38 4 ffffff
15 38 4 ffffff
0 39 4 ffffff
1 39 4 ffffff
2 39 4 ffffff
3 39 4 ffffff
4 39 4 ffffff
5 39 4 ffffff
6 39 4 ffffff
7 39 4 ffffff
8 39 4 ffffff
9 39 4 ffffff
10 39 4 ffffff
11 39 4 ffffff
12 39 4 ffffff
13 39 4 ffffff
14 39 4 ffffff
15 39 4 ffffff
0 40 4 ffffff
1 40 4 ffffff
2 40 4 ffffff
3 40 4 ffffff
4 40 4 ffffff
5 40 4 ffffff
6 40 4 ffffff
7 40 4 ffffff
8 40 4 ffffff
9 40 4 ffffff
10 40 4 ffffff
11 40 4 ffffff
12 40 4 ffffff
13 40 4 ffffff
14 40 4 ffffff
15 40 4 ffffff
0 41 4 ffffff
1 41 4 ffffff
2 41 4 ffffff
3 41 4 ffffff
4 41 4 ffffff
5 41 4 ffffff
6 41 4 ffffff
7 41 4 ffffff
8 41 4 ffffff
9 41 4 ffffff
10 41 4 ffffff
11 41 4 ffffff
12 41 4 ffffff
13 41 4 ffffff
14 41 4 ffffff
15 41 4 ffffff
0 42 4 ffffff
1 42 4 ffffff
2 42 4 ffffff
3 42 4 ffffff
4 42 4 ffffff
5 42 4 ffffff
6 42 4 ffffff
7 42 4 ffffff
8 42 4 ffffff
9 42 4 ffffff
10 42 4 ffffff
11 42 4 ffffff
12 42 4 ffffff
13 42 4 ffffff
14 42 4 ffffff
15 42 4 ffffff
0 43 4 ffffff
1 43 4 ffffff
2 43 4 ffffff
3 43 4 ffffff
4 43 4 ffffff
5 43 4 ffffff
6 43 4 ffffff
7 43 4 ffffff
8 43 4 ffffff
9 43 4 ffffff
10 43 4 ffffff
11 43 4 ffffff
12 43 4 ffffff
13 43 4 ffffff
14 43 4 ffffff
15 43 4 ffffff
0 44 4 ffffff
1 44 4 ffffff
2 44 4 ffffff
3 44 4 ffffff
4 44 4 ffffff
5 44 4 ffffff
6 44 4 ffffff
7 44 4 ffffff
8 44 4 ffffff
9 44 4 ffffff
10 44 4 ffffff
11 44 4 ffffff
12 44 4 ffffff
13 44 4 ffffff
14 44 4 ffffff
15 44 4 ffffff
0 45 4 ffffff
1 45 4 ffffff
2 45 4 ffffff
3 45 4 ffffff
4 45 4 ffffff
5 45 4 ffffff
6 45 4 ffffff
7 45 4 ffffff
8 45 4 ffffff
9 45 4 ffffff
10 45 4 ffffff
11 45 4 ffffff
12 45 4 ffffff
13 45 4 ffffff
14 45 4 ffffff
15 45 4 ffffff
0 46 4 ffffff
1 46 4 ffffff
2 46 4 ffffff
3 46 4 ffffff
4 46 4 ffffff
5 46 4 ffffff
6 46 4 ffffff
7 46 4 ffffff
8 46 4 ffffff
9 46 4 ffffff
10 46 4 ffffff
11 46 4 ffffff
12 46 4 ffffff
13 46 4 ffffff
14 46 4 ffffff
15 46 4 ffffff
0 47 4 ffffff
1 47 4 ffffff
2 47 4 ffffff
3 47 4 ffffff
4 47 4 ffffff
5 47 4 ffffff
6 47 4 ffffff
7 47 4 ffffff
8 47 4 ffffff
9 47 4 ffffff
10 47 4 ffffff
11 47 4 ffffff
12 47 4 ffffff
13 47 4 ffffff
14 47 4 ffffff
15 47 4 ffffff
0 32 5 ffffff
1 32 5 ffffff
2 32 5 ffffff
3 32 5 ffffff
4 32 5 ffffff
5 32 5 ffffff
6 32 5 ffffff
7 32 5 ffffff
8 32 5 ffffff
9 32 5 ffffff
10 32 5 ffffff
11 32 5 ffffff
12 32 5 ffffff
13 32 5 ffffff
14 32 5 ffffff
15 32 5 ffffff
0 33 5 ffffff
1 33 5 ffffff
2 33 5 ffffff
3 33 5 ffffff
4 33 5 ffffff
5 33 5 ffffff
6 33 5 ffffff
7 33 5 ffffff
8 33 5 ffffff
9 33 5 ffffff
10 33 5 ffffff
11 33 5 ffffff
12 33 5 ffffff
13 33 5 ffffff
14 33 5 ffffff
15 33 5 ffffff
0 34 5 ffffff
1 34 5 ffffff
2 34 5 ffffff
3 34 5 ffffff
4 34 5 ffffff
5 34 5 ffffff
6 34 5 ffffff
7 34 5 ffffff
8 34 5 ffffff
9 34 5 ffffff
10 34 5 ffffff
11 34 5 ffffff
12 34 5 ffffff
13 34 5 ffffff
14 34 5 ffffff
15 34 5 ffffff
0 35 5 ffffff
1 35 5 ffffff
2 35 5 ffffff
3 35 5 ffffff
4 35 5 ffffff
5 35 5 ffffff
6 35 5 ffffff
7 35 5 ffffff
8 35 5 ffffff
9 35 5 ffffff
10 35 5 ffffff
11 35 5 ffffff
12 35 5 ffffff
13 35 5 ffffff
14 35 5 ffffff
15 35 5 ffffff
0 36 5 ffffff
1 36 5 ffffff
2 36 5 ffffff
3 36 5 ffffff
4 36 5 ffffff
5 36 5 ffffff
6 36 5 ffffff
7 36 5 ffffff
8 36 5 ffffff
9 36 5 ffffff
10 36 5 ffffff
11 36 5 ffffff
12 36 5 ffffff
13 36 5 ffffff
14 36 5 ffffff
15 36 5 ffffff
0 37 5 ffffff
1 37 5 ffffff
2 37 5 ffffff
3 37 5 ffffff
4 37 5 ffffff
5 37 5 ffffff
6 37 5 ffffff
7 37 5 ffffff
8 37 5 ffffff
9 37 5 ffffff
10 37 5 ffffff
11 37 5 ffffff
12 37 5 ffffff
13 37 5 ffffff
14 37 5 ffffff
15 37 5 ffffff
0 38 5 ffffff
1 38 5 ffffff
2 38 5 ffffff
3 38 5 ffffff
4 38 5 ffffff
5 38 5 ffffff
6 38 5 ffffff
7 38 5 ffffff
8 38 5 ffffff
9 38 5 ffffff
10 38 5 ffffff
11 38 5 ffffff
12 38 5 ffffff
13 38 5 ffffff
14 38 5 ffffff
15 38 5 ffffff
0 39 5 ffffff
1 39 5 ffffff
2 39 5 ffffff
3 39 5 ffffff
4 39 5 ffffff
5 39 5 ffffff
6 39 5 ffffff
7 39 5 ffffff
8 39 5 ffffff
9 39 5 ffffff
10 39 5 ffffff
11 39 5 ffffff
12 39 5 ffffff
13 39 5 ffffff
14 39 5 ffffff
15 39 5 ffffff
0 40 5 ffffff
1 40 5 ffffff
2 40 5 ffffff
3 40 5 ffffff
4 40 5 ffffff
5 40 5 ffffff
6 40 5 ffffff
7 40 5 ffffff
8 40 5 ffffff
9 40 5 ffffff
10 40 5 ffffff
11 40 5 ffffff
12 40 5 ffffff
13 40 5 ffffff
14 40 5 ffffff
15 40 5 ffffff
0 41 5 ffffff
1 41 5 ffffff
2 41 5 ffffff
3 41 5 ffffff
4 41 5 ffffff
5 41 5 ffffff
6 41 5 ffffff
7 41 5 ffffff
8 41 5 ffffff
9 41 5 ffffff
10 41 5 ffffff
11 41 5 ffffff
12 41 5 ffffff
13 41 5 ffffff
14 41 5 ffffff
15 41 5 ffffff
0 42 5 ffffff
1 42 5 ffffff
2 42 5 ffffff
3 42 5 ffffff
4 42 5 ffffff
5 42 5 ffffff
6 42 5 ffffff
7 42 5 ffffff
8 42 5 ffffff
9 42 5 ffffff
10 42 5 ffffff
11 42 5 ffffff
12 42 5 ffffff
13 42 5 ffffff
14 42 5 ffffff
15 42 5 ffffff
0 43 5 ffffff
1 43 5 ffffff
2 43 5 ffffff
3 43 5 ffffff
4 43 5 ffffff
5 43 5 ffffff
6 43 5 ffffff
7 43 5 ffffff
8 43 5 ffffff
9 43 5 ffffff
10 43 5 ffffff
11 43 5 ffffff
12 43 5 ffffff
13 43 5 ffffff
14 43 5 ffffff
15 43 5 ffffff
0 44 5 ffffff
1 44 5 ffffff
2 44 5 ffffff
3 44 5 ffffff
4 44 5 ffffff
5 44 5 ffffff
6 44 5 ffffff
7 44 5 ffffff
8 44 5 ffffff
9 44 5 ffffff
10 44 5 ffffff
11 44 5 ffffff
12 44 5 ffffff
13 44 5 ffffff
14 44 5 ffffff
15 44 5 ffffff
0 45 5 ffffff
1 45 5 ffffff
2 45 5 ffffff
3 45 5 ffffff
4 45 5 ffffff
5 45 5 ffffff
6 45 5 ffffff
7 45 5 ffffff
8 45 5 ffffff
9 45 5 ffffff
10 45 5 ffffff
11 45 5 ffffff
12 45 5 ffffff
13 45 5 ffffff
14 45 5 ffffff
15 45 5 ffffff
0 46 5 ffffff
1 46 5 ffffff
2 46 5 ffffff
3 46 5 ffffff
4 46 5 ffffff
5 46 5 ffffff
6 46 5 ffffff
7 46 5 ffffff
8 46 5 ffffff
9 46 5 ffffff
10 46 5 ffffff
11 46 5 ffffff
12 46 5 ffffff
13 46 5 ffffff
14 46 5 ffffff
15 46 5 ffffff
0 47 5 ffffff
1 47 5 ffffff
2 47 5 ffffff
3 47 5 ffffff
4 47 5 ffffff
5 47 5 ffffff
6 47 5 ffffff
7 47 5 ffffff
8 47 5 ffffff
9 47 5 ffffff
10 47 5 ffffff
11 47 5 ffffff
12 47 5 ffffff
13 47 5 ffffff
14 47 5 ffffff
15 47 5 ffffff
0 32 6 ffffff
1 32 6 ffffff
2 32 6 ffffff
3 32 6 ffffff
4 32 6 ffffff
5 32 6 ffffff
6 32 6 ffffff
7 32 6 ffffff
8 32 6 ffffff
0 33 6 ffffff
1 33 6 ffffff
2 33 6 ffffff
3 33 6 ffffff
4 33 6 ffffff
5 33 6 ffffff
6 33 6 ffffff
7 33 6 ffffff
8 33 6 ffffff
0 34 6 ffffff
1 34 6 ffffff
2 34 6 ffffff
3 34 6 ffffff
4 34 6 ffffff
5 34 6 ffffff
6 34 6 ffffff
7 34 6 ffffff
8 34 6 ffffff
0 35 6 ffffff
1 35 6 ffffff
2 35 6 ffffff
3 35 6 ffffff
4 35 6 ffffff
5 35 6 ffffff
6 35 6 ffffff
7 35 6 ffffff
8 35 6 ffffff
0 36 6 ffffff
1 36 6 ffffff
2 36 6 ffffff
3 36 6 ffffff
4 36 6 ffffff
5 36 6 ffffff
6 36 6 ffffff
7 36 6 ffffff
8 36 6 ffffff
0 37 6 ffffff
1 37 6 ffffff
2 37 6 ffffff
3 37 6 ffffff
4 37 6 ffffff
5 37 6 ffffff
6 37 6 ffffff
7 37 6 ffffff
8 37 6 ffffff
0 38 6 ffffff
1 38 6 ffffff
2 38 6 ffffff
3 38 6 ffffff
4 38 6 ffffff
5 38 6 ffffff
6 38 6 ffffff
7 38 6 ffffff
8 38 6 ffffff
0 39 6 ffffff
1 39 6 ffffff
2 39 6 ffffff
3 39 6 ffffff
4 39 6 ffffff
5 39 6 ffffff
6 39 6 ffffff
7 39 6 ffffff
8 39 6 ffffff
0 40 6 ffffff
1 40 6 ffffff
2 40 6 ffffff
3 40 6 ffffff
4 40 6 ffffff
5 40 6 ffffff
6 40 6 ffffff
7 40 6 ffffff
8 40 6 ffffff
0 41 6 ffffff
1 41 6 ffffff
2 41 6 ffffff
3 41 6 ffffff
4 41 6 ffffff
5 41 6 ffffff
6 41 6 ffffff
7 41 6 ffffff
8 41 6 ffffff
0 42 6 ffffff
1 42 6 ffffff
2 42 6 ffffff
3 42 6 ffffff
4 42 6 ffffff
5 42 6 ffffff
6 42 6 ffffff
7 42 6 ffffff
8 42 6 ffffff
0 43 6 ffffff
1 43 6 ffffff
2 43 6 ffffff
3 43 6 ffffff
4 43 6 ffffff
5 43 6 ffffff
6 43 6 ffffff
7 43 6 ffffff
8 43 6 ffffff
0 44 6 ffffff
1 44 6 ffffff
2 44 6 ffffff
3 44 6 ffffff
4 44 6 ffffff
5 44 6 ffffff
6 44 6 ffffff
7 44 6 ffffff
8 44 6 ffffff
0 45 6 ffffff
1 45 6 ffffff
2 45 6 ffffff
3 45 6 ffffff
4 45 6 ffffff
5 45 6 ffffff
6 45 6 ffffff
7 45 6 ffffff
8 45 6 ffffff
0 46 6 ffffff
1 46 6 ffffff
2 46 6 ffffff
3 46 6 ffffff
4 46 6 ffffff
5 46 6 ffffff
6 46 6 ffffff
7 46 6 ffffff
8 46 6 ffffff
0 47 6 ffffff
1 47 6 ffffff
2 47 6 ffffff
3 47 6 ffffff
4 47 6 ffffff
5 47 6 ffffff
6 47 6 ffffff
7 47 6 ffffff
8 47 6 ffffff
0 32 7 ffffff
1 32 7 ffffff
2 32 7 ffffff
3 32 7 ffffff
4 32 7 ffffff
5 32 7 ffffff
6 32 7 ffffff
7 32 7 ffffff
0 33 7 ffffff
1 33 7 ffffff
2 33 7 ffffff
3 33 7 ffffff
4 33 7 ffffff
5 33 7 ffffff
6 33 7 ffffff
7 33 7 ffffff
0 34 7 ffffff
1 34 7 ffffff
2 34 7 ffffff
3 34 7 ffffff
4 34 7 ffffff
5 34 7 ffffff
6 34 7 ffffff
7 34 7 ffffff
0 35 7 ffffff
1 35 7 ffffff
2 35 7 ffffff
3 35 7 ffffff
4 35 7 ffffff
5 35 7 ffffff
6 35 7 ffffff
7 35 7 ffffff
0 36 7 ffffff
1 36 7 ffffff
2 36 7 ffffff
3 36 7 ffffff
4 36 7 ffffff
5 36 7 ffffff
6 36 7 ffffff
7 36 7 ffffff
0 37 7 ffffff
1 37 7 ffffff
2 37 7 ffffff
3 37 7 ffffff
4 37 7 ffffff
5 37 7 ffffff
6 37 7 ffffff
7 37 7 ffffff
0 38 7 ffffff
1 38 7 ffffff
2 38 7 ffffff
3 38 7 ffffff
4 38 7 ffffff
5 38 7 ffffff
6 38 7 ffffff
7 38 7 ffffff
0 39 7 ffffff
1 39 7 ffffff
2 39 7 ffffff
3 39 7 ffffff
4 39 7 ffffff
5 39 7 ffffff
6 39 7 ffffff
7 39 7 ffffff
0 40 7 ffffff
1 40 7 ffffff
2 40 7 ffffff
3 40 7 ffffff
4 40 7 ffffff
5 40 7 ffffff
6 40 7 ffffff
7 40 7 ffffff
0 41 7 ffffff
1 41 7 ffffff
2 41 7 ffffff
3 41 7 ffffff
4 41 7 ffffff
5 41 7 ffffff
6 41 7 ffffff
7 41 7 ffffff
0 42 7 ffffff
1 42 7 ffffff
2 42 7 ffffff
3 42 7 ffffff
4 42 7 ffffff
5 42 7 ffffff
6 42 7 ffffff
7 42 7 ffffff
0 43 7 ffffff
1 43 7 ffffff
2 43 7 ffffff
3 43 7 ffffff
4 43 7 ffffff
5 43 7 ffffff
6 43 7 ffffff
7 43 7 ffffff
0 44 7 ffffff
1 44 7 ffffff
2 44 7 ffffff
3 44 7 ffffff
4 44 7 ffffff
5 44 7 ffffff
6 44 7 ffffff
7 44 7 ffffff
0 45 7 ffffff
1 45 7 ffffff
2 45 7 ffffff
3 45 7 ffffff
4 45 7 ffffff
5 45 7 ffffff
6 45 7 ffffff
7 45 7 ffffff
0 46 7 ffffff
1 46 7 ffffff
2 46 7 ffffff
3 46 7 ffffff
4 46 7 ffffff
5 46 7 ffffff
6 46 7 ffffff
7 46 7 ffffff
0 47 7 ffffff
1 47 7 ffffff
2 47 7 ffffff
3 47 7 ffffff
4 47 7 ffffff
5 47 7 ffffff
6 47 7 ffffff
7 47 7 ffffff
0 32 8 ffffff
1 32 8 ffffff
2 32 8 ffffff
3 32 8 ffffff
4 32 8 ffffff
5 32 8 ffffff
6 32 8 ffffff
0 33 8 ffffff
1 33 8 ffffff
2 33 8 ffffff
3 33 8 ffffff
4 33 8 ffffff
5 33 8 ffffff
6 33 8 ffffff
0 34 8 ffffff
1 34 8 ffffff
2 34 8 ffffff
3 34 8 ffffff
4 34 8 ffffff
5 34 8 ffffff
6 34 8 ffffff
0 35 8 ffffff
1 35 8 ffffff
2 35 8 ffffff
3 35 8 ffffff
4 35 8 ffffff
5 35 8 ffffff
6 35 8 ffffff
0 36 8 ffffff
1 36 8 ffffff
2 36 8 ffffff
3 36 8 ffffff
4 36 8 ffffff
5 36 8 ffffff
6 36 8 ffffff
0 37 8 ffffff
1 37 8 ffffff
2 37 8 ffffff
3 37 8 ffffff
4 37 8 ffffff
5 37 8 ffffff
6 37 8 ffffff
0 38 8 ffffff
1 38 8 ffffff
2 38 8 ffffff
3 38 8 ffffff
4 38 8 ffffff
5 38 8 ffffff
6 38 8 ffffff
0 39 8 ffffff
1 39 8 ffffff
2 39 8 ffffff
3 39 8 ffffff
4 39 8 ffffff
5 39 8 ffffff
6 39 8 ffffff
0 40 8 ffffff
1 40 8 ffffff
2 40 8 ffffff
3 40 8 ffffff
4 40 8 ffffff
5 40 8 ffffff
6 40 8 ffffff
0 41 8 ffffff
1 41 8 ffffff
2 41 8 ffffff
3 41 8 ffffff
4 41 8 ffffff
5 41 8 ffffff
6 41 8 ffffff
0 42 8 ffffff
1 42 8 ffffff
2 42 8 ffffff
3 42 8 ffffff
4 42 8 ffffff
5 42 8 ffffff
6 42 8 ffffff
0 43 8 ffffff
1 43 8 ffffff
2 43 8 ffffff
3 43 8 ffffff
4 43 8 ffffff
5 43 8 ffffff
6 43 8 ffffff
0 44 8 ffffff
1 44 8 ffffff
2 44 8 ffffff
3 44 8 ffffff
4 44 8 ffffff
5 44 8 ffffff
6 44 8 ffffff
0 45 8 ffffff
1 45 8 ffffff
2 45 8 ffffff
3 45 8 ffffff
4 45 8 ffffff
5 45 8 ffffff
6 45 8 ffffff
0 46 8 ffffff
1 46 8 ffffff
2 46 8 ffffff
3 46 8 ffffff
4 46 8 ffffff
5 46 8 ffffff
6 46 8 ffffff
0 47 8 ffffff
1 47 8 ffffff
2 47 8 ffffff
3 47 8 ffffff
4 47 8 ffffff
5 47 8 ffffff
6 47 8 ffffff
0 32 9 ffffff
1 32 9 ffffff
2 32 9 ffffff
3 32 9 ffffff
4 32 9 ffffff
5 32 9 ffffff
0 33 9 ffffff
1 33 9 ffffff
2 33 9 ffffff
3 33 9 ffffff
4 33 9 ffffff
5 33 9 ffffff
0 34 9 ffffff
1 34 9 ffffff
2 34 9 ffffff
3 34 9 ffffff
4 34 9 ffffff
5 34 9 ffffff
0 35 9 ffffff
1 35 9 ffffff
2 35 9 ffffff
3 35 9 ffffff
4 35 9 ffffff
5 35 9 ffffff
0 36 9 ffffff
1 36 9 ffffff
2 36 9 ffffff
3 36 9 ffffff
4 36 9 ffffff
5 36 9 ffffff
0 37 9 ffffff
1 37 9 ffffff
2 37 9 ffffff
3 37 9 ffffff
4 37 9 ffffff
5 37 9 ffffff
0 38 9 ffffff
1 38 9 ffffff
2 38 9 ffffff
3 38 9 ffffff
4 38 9 ffffff
5 38 9 ffffff
0 39 9 ffffff
1 39 9 ffffff
2 39 9 ffffff
3 39 9 ffffff
4 39 9 ffffff
5 39 9 ffffff
0 40 9 ffffff
1 40 9 ffffff
2 40 9 ffffff
3 40 9 ffffff
4 40 9 ffffff
5 40 9 ffffff
0 41 9 ffffff
1 41 9 ffffff
2 41 9 ffffff
3 41 9 ffffff
4 41 9 ffffff
5 41 9 ffffff
0 42 9 ffffff
1 42 9 ffffff
2 42 9 ffffff
3 42 9 ffffff
4 42 9 ffffff
5 42 9 ffffff
0 43 9 ffffff
1 43 9 ffffff
2 43 9 ffffff
3 43 9 ffffff
4 43 9 ffffff
5 43 9 ffffff
0 44 9 ffffff
1 44 9 ffffff
2 44 9 ffffff
3 44 9 ffffff
4 44 9 ffffff
5 44 9 ffffff
0 45 9 ffffff
1 45 9 ffffff
2 45 9 ffffff
3 45 9 ffffff
4 45 9 ffffff
5 45 9 ffffff
0 46 9 ffffff
1 46 9 ffffff
2 46 9 ffffff
3 46 9 ffffff
4 46 9 ffffff
5 46 9 ffffff
0 47 9 ffffff
1 47 9 ffffff
2 47 9 ffffff
3 47 9 ffffff
4 47 9 ffffff
5 47 9 ffffff
0 48 0 ffffff
1 48 0 ffffff
2 48 0 ffffff
3 48 0 ffffff
4 48 0 ffffff
5 48 0 ffffff
6 48 0 ffffff
7 48 0 ffffff
8 48 0 ffffff
9 48 0 ffffff
10 48 0 ffffff
11 48 0 ffffff
12 48 0 ffffff
13 48 0 ffffff
14 48 0 ffffff
15 48 0 ffffff
0 49 0 ffffff
1 49 0 ffffff
2 49 0 ffffff
3 49 0 ffffff
4 49 0 ffffff
5 49 0 ffffff
6 49 0 ffffff
7 49 0 ffffff
8 49 0 ffffff
9 49 0 ffffff
10 49 0 ffffff
11 49 0 ffffff
12 49 0 ffffff
13 49 0 ffffff
14 49 0 ffffff
15 49 0 ffffff
0 50 0 ffffff
1 50 0 ffffff
2 50 0 ffffff
3 50 0 ffffff
4 50 0 ffffff
5 50 0 ffffff
6 50 0 ffffff
7 50 0 ffffff
8 50 0 ffffff
9 50 0 ffffff
10 50 0 ffffff
11 50 0 ffffff
12 50 0 ffffff
13 50 0 ffffff
14 50 0 ffffff
15 50 0 ffffff
0 51 0 ffffff
1 51 0 ffffff
2 51 0 ffffff
3 51 0 ffffff
4 51 0 ffffff
5 51 0 ffffff
6 51 0 ffffff
7 51 0 ffffff
8 51 0 ffffff
9 51 0 ffffff
10 51 0 ffffff
11 51 0 ffffff
12 51 0 ffffff
13 51 0 ffffff
14 51 0 ffffff
15 51 0 ffffff
0 52 0 ffffff
1 52 0 ffffff
2 52 0 ffffff
3 52 0 ffffff
4 52 0 ffffff
5 52 0 ffffff
6 52 0 ffffff
7 52 0 ffffff
8 52 0 ffffff
9 52 0 ffffff
10 52 0 ffffff
11 52 0 ffffff
12 52 0 ffffff
13 52 0 ffffff
14 52 0 ffffff
15 52 0 ffffff
0 53 0 ffffff
1 53 0 ffffff
2 53 0 ffffff
3 53 0 ffffff
4 53 0 ffffff
5 53 0 ffffff
6 53 0 ffffff
7 53 0 ffffff
8 53 0 ffffff
9 53 0 ffffff
10 53 0 ffffff
11 53 0 ffffff
12 53 0 ffffff
13 53 0 ffffff
14 53 0 ffffff
15 53 0 ffffff
0 54 0 ffffff
1 54 0 ffffff
2 54 0 ffffff
3 54 0 ffffff
4 54 0 ffffff
5 54 0 ffffff
6 54 0 ffffff
7 54 0 ffffff
8 54 0 ffffff
9 54 0 ffffff
10 54 0 ffffff
11 54 0 ffffff
12 54 0 ffffff
13 54 0 ffffff
14 54 0 ffffff
15 54 0 ffffff
0 55 0 ffffff
1 55 0 ffffff
2 55 0 ffffff
3 55 0 ffffff
4 55 0 ffffff
5 55 0 ffffff
6 55 0 ffffff
7 55 0 ffffff
8 55 0 ffffff
9 55 0 ffffff
10 55 0 ffffff
11 55 0 ffffff
12 55 0 ffffff
13 55 0 ffffff
14 55 0 ffffff
15 55 0 ffffff
0 56 0 ffffff
1 56 0 ffffff
2 56 0 ffffff
3 56 0 ffffff
4 56 0 ffffff
5 56 0 ffffff
6 56 0 ffffff
7 56 0 ffffff
8 56 0 ffffff
9 56 0 ffffff
10 56 0 ffffff
11 56 0 ffffff
12 56 0 ffffff
13 56 0 ffffff
14 56 0 ffffff
15 56 0 ffffff
0 57 0 ffffff
1 57 0 ffffff
2 57 0 ffffff
3 57 0 ffffff
4 57 0 ffffff
5 57 0 ffffff
6 57 0 ffffff
7 57 0 ffffff
8 57 0 ffffff
9 57 0 ffffff
10 57 0 ffffff
11 57 0 ffffff
12 57 0 ffffff
13 57 0 ffffff
14 57 0 ffffff
15 57 0 ffffff
0 58 0 ffffff
1 58 0 ffffff
2 58 0 ffffff
3 58 0 ffffff
4 58 0 ffffff
5 58 0 ffffff
6 58 0 ffffff
7 58 0 ffffff
8 58 0 ffffff
9 58 0 ffffff
10 58 0 ffffff
11 58 0 ffffff
12 58 0 ffffff
13 58 0 ffffff
14 58 0 ffffff
15 58 0 ffffff
0 59 0 ffffff
1 59 0 ffffff
2 59 0 ffffff
3 59 0 ffffff
4 59 0 ffffff
5 59 0 ffffff
6 59 0 ffffff
7 59 0 ffffff
8 59 0 ffffff
9 59 0 ffffff
10 59 0 ffffff
11 59 0 ffffff
12 59 0 ffffff
13 59 0 ffffff
14 59 0 ffffff
15 59 0 ffffff
0 60 0 ffffff
1 60 0 ffffff
2 60 0 ffffff
3 60 0 ffffff
4 60 0 ffffff
5 60 0 ffffff
6 60 0 ffffff
7 60 0 ffffff
8 60 0 ffffff
9 60 0 ffffff
10 60 0 ffffff
11 60 0 ffffff
12 60 0 ffffff
13 60 0 ffffff
14 60 0 ffffff
15 60 0 ffffff
0 61 0 ffffff
1 61 0 ffffff
2 61 0 ffffff
3 61 0 ffffff
4 61 0 ffffff
5 61 0 ffffff
6 61 0 ffffff
7 61 0 ffffff
8 61 0 ffffff
9 61 0 ffffff
10 61 0 ffffff
11 61 0 ffffff
12 61 0 ffffff
13 61 0 ffffff
14 61 0 ffffff
15 61 0 ffffff
0 62 0 ffffff
1 62 0 ffffff
2 62 0 ffffff
3 62 0 ffffff
4 62 0 ffffff
5 62 0 ffffff
6 62 0 ffffff
7 62 0 ffffff
8 62 0 ffffff
9 62 0 ffffff
10 62 0 ffffff
11 62 0 ffffff
12 62 0 ffffff
13 62 0 ffffff
14 62 0 ffffff
15 62 0 ffffff
0 63 0 ffffff
1 63 0 ffffff
2 63 0 ffffff
3 63 0 ffffff
4 63 0 ffffff
5 63 0 ffffff
6 63 0 ffffff
7 63 0 ffffff
8 63 0 ffffff
9 63 0 ffffff
10 63 0 ffffff
11 63 0 ffffff
12 63 0 ffffff
13 63 0 ffffff
14 63 0 ffffff
15 63 0 ffffff
0 48 1 ffffff
1 48 1 ffffff
2 48 1 ffffff
3 48 1 ffffff
4 48 1 ffffff
5 48 1 ffffff
6 48 1 ffffff
7 48 1 ffffff
8 48 1 ffffff
9 48 1 ffffff
10 48 1 ffffff
11 48 1 ffffff
12 48 1 ffffff
13 48 1 ffffff
14 48 1 ffffff
15 48 1 ffffff
0 49 1 ffffff
1 49 1 ffffff
2 49 1 ffffff
3 49 1 ffffff
4 49 1 ffffff
5 49 1 ffffff
6 49 1 ffffff
7 49 1 ffffff
8 49 1 ffffff
9 49 1 ffffff
10 49 1 ffffff
11 49 1 ffffff
12 49 1 ffffff
13 49 1 ffffff
14 49 1 ffffff
15 49 1 ffffff
0 50 1 ffffff
1 50 1 ffffff
2 50 1 ffffff
3 50 1 ffffff
4 50 1 ffffff
5 50 1 ffffff
6 50 1 ffffff
7 50 1 ffffff
8 50 1 ffffff
9 50 1 ffffff
10 50 1 ffffff
11 50 1 ffffff
12 50 1 ffffff
13 50 1 ffffff
14 50 1 ffffff
15 50 1 ffffff
0 51 1 ffffff
1 51 1 ffffff
2 51 1 ffffff
3 51 1 ffffff
4 51 1 ffffff
5 51 1 ffffff
6 51 1 ffffff
7 51 1 ffffff
8 51 1 ffffff
9 51 1 ffffff
10 51 1 ffffff
11 51 1 ffffff
12 51 1 ffffff
13 51 1 ffffff
14 51 1 ffffff
15 51 1 ffffff
0 52 1 ffffff
1 52 1 ffffff
2 52 1 ffffff
3 52 1 ffffff
4 52 1 ffffff
5 52 1 ffffff
6 52 1 ffffff
7 52 1 ffffff
8 52 1 ffffff
9 52 1 ffffff
10 52 1 ffffff
11 52 1 ffffff
12 52 1 ffffff
13 52 1 ffffff
14 52 1 ffffff
15 52 1 ffffff
0 53 1 ffffff
1 53 1 ffffff
2 53 1 ffffff
3 53 1 ffffff
4 53 1 ffffff
5 53 1 ffffff
6 53 1 ffffff
7 53 1 ffffff
8 53 1 ffffff
9 53 1 ffffff
10 53 1 ffffff
11 53 1 ffffff
12 53 1 ffffff
13 53 1 ffffff
14 53 1 ffffff
15 53 1 ffffff
0 54 1 ffffff
1 54 1 ffffff
2 54 1 ffffff
3 54 1 ffffff
4 54 1 ffffff
5 54 1 ffffff
6 54 1 ffffff
7 54 1 ffffff
8 54 1 ffffff
9 54 1 ffffff
10 54 1 ffffff
11 54 1 ffffff
12 54 1 ffffff
13 54 1 ffffff
14 54 1 ffffff
15 54 1 ffffff
0 55 1 ffffff
1 55 1 ffffff
2 55 1 ffffff
3 55 1 ffffff
4 55 1 ffffff
5 55 1 ffffff
6 55 1 ffffff
7 55 1 ffffff
8 55 1 ffffff
9 55 1 ffffff
10 55 1 ffffff
11 55 1 ffffff
12 55 1 ffffff
13 55 1 ffffff
14 55 1 ffffff
15 55 1 ffffff
0 56 1 ffffff
1 56 1 ffffff
2 56 1 ffffff
3 56 1 ffffff
4 56 1 ffffff
5 56 1 ffffff
6 56 1 ffffff
7 56 1 ffffff
8 56 1 ffffff
9 56 1 ffffff
10 56 1 ffffff
11 56 1 ffffff
12 56 1 ffffff
13 56 1 ffffff
14 56 1 ffffff
15 56 1 ffffff
0 57 1 ffffff
1 57 1 ffffff
2 57 1 ffffff
3 57 1 ffffff
4 57 1 ffffff
5 57 1 ffffff
6 57 1 ffffff
7 57 1 ffffff
8 57 1 ffffff
9 57 1 ffffff
10 57 1 ffffff
11 57 1 ffffff
12 57 1 ffffff
13 57 1 ffffff
14 57 1 ffffff
15 57 1 ffffff
0 58 1 ffffff
1 58 1 ffffff
2 58 1 ffffff
3 58 1 ffffff
4 58 1 ffffff
5 58 1 ffffff
6 58 1 ffffff
7 58 1 ffffff
8 58 1 ffffff
9 58 1 ffffff
10 58 1 ffffff
11 58 1 ffffff
12 58 1 ffffff
13 58 1 ffffff
14 58 1 ffffff
15 58 1 ffffff
0 59 1 ffffff
1 59 1 ffffff
2 59 1 ffffff
3 59 1 ffffff
4 59 1 ffffff
5 59 1 ffffff
6 59 1 ffffff
7 59 1 ffffff
8 59 1 ffffff
9 59 1 ffffff
10 59 1 ffffff
11 59 1 ffffff
12 59 1 ffffff
13 59 1 ffffff
14 59 1 ffffff
15 59 1 ffffff
0 60 1 ffffff
1 60 1 ffffff
2 60 1 ffffff
3 60 1 ffffff
4 60 1 ffffff
5 60 1 ffffff
6 60 1 ffffff
7 60 1 ffffff
8 60 1 ffffff
9 60 1 ffffff
10 60 1 ffffff
11 60 1 ffffff
12 60 1 ffffff
13 60 1 ffffff
14 60 1 ffffff
15 60 1 ffffff
0 61 1 ffffff
1 61 1 ffffff
2 61 1 ffffff
3 61 1 ffffff
4 61 1 ffffff
5 61 1 ffffff
6 61 1 ffffff
7 61 1 ffffff
8 61 1 ffffff
9 61 1 ffffff
10 61 1 ffffff
11 61 1 ffffff
12 61 1 ffffff
13 61 1 ffffff
14 61 1 ffffff
15 61 1 ffffff
0 62 1 ffffff
1 62 1 ffffff
2 62 1 ffffff
3 62 1 ffffff
4 62 1 ffffff
5 62 1 ffffff
6 62 1 ffffff
7 62 1 ffffff
8 62 1 ffffff
9 62 1 ffffff
10 62 1 ffffff
11 62 1 ffffff
12 62 1 ffffff
13 62 1 ffffff
14 62 1 ffffff
15 62 1 ffffff
0 63 1 ffffff
1 63 1 ffffff
2 63 1 ffffff
3 63 1 ffffff
4 63 1 ffffff
5 63 1 ffffff
6 63 1 ffffff
7 63 1 ffffff
8 63 1 ffffff
9 63 1 ffffff
10 63 1 ffffff
11 63 1 ffffff
12 63 1 ffffff
13 63 1 ffffff
14 63 1 ffffff
15 63 1 ffffff
0 48 2 ffffff
1 48 2 ffffff
2 48 2 ffffff
3 48 2 ffffff
4 48 2 ffffff
5 48 2 ffffff
6 48 2 ffffff
7 48 2 ffffff
8 48 2 ffffff
9 48 2 ffffff
10 48 2 ffffff
11 48 2 ffffff
12 48 2 ffffff
13 48 2 ffffff
14 48 2 ffffff
15 48 2 ffffff
0 49 2 ffffff
1 49 2 ffffff
2 49 2 ffffff
3 49 2 ffffff
4 49 2 ffffff
5 49 2 ffffff
6 49 2 ffffff
7 49 2 ffffff
8 49 2 ffffff
9 49 2 ffffff
10 49 2 ffffff
11 49 2 ffffff
12 49 2 ffffff
13 49 2 ffffff
14 49 2 ffffff
15 49 2 ffffff
0 50 2 ffffff
1 50 2 ffffff
2 50 2 ffffff
3 50 2 ffffff
4 50 2 ffffff
5 50 2 ffffff
6 50 2 ffffff
7 50 2 ffffff
8 50 2 ffffff
9 50 2 ffffff
10 50 2 ffffff
11 50 2 ffffff
12 50 2 ffffff
13 50 2 ffffff
14 50 2 ffffff
15 50 2 ffffff
0 51 2 ffffff
1 51 2 ffffff
2 51 2 ffffff
3 51 2 ffffff
4 51 2 ffffff
5 51 2 ffffff
6 51 2 ffffff
7 51 2 ffffff
8 51 2 ffffff
9 51 2 ffffff
10 51 2 ffffff
11 51 2 ffffff
12 51 2 ffffff
13 51 2 ffffff
14 51 2 ffffff
15 51 2 ffffff
0 52 2 ffffff
1 52 2 ffffff
2 52 2 ffffff
3 52 2 ffffff
4 52 2 ffffff
5 52 2 ffffff
6 52 2 ffffff
7 52 2 ffffff
8 52 2 ffffff
9 52 2 ffffff
10 52 2 ffffff
11 52 2 ffffff
12 52 2 ffffff
13 52 2 ffffff
14 52 2 ffffff
15 52 2 ffffff
0 53 2 ffffff
1 53 2 ffffff
2 53 2 ffffff
3 53 2 ffffff
4 53 2 ffffff
5 53 2 ffffff
6 53 2 ffffff
7 53 2 ffffff
8 53 2 ffffff
9 53 2 ffffff
10 53 2 ffffff
11 53 2 ffffff
12 53 2 ffffff
13 53 2 ffffff
14 53 2 ffffff
15 53 2 ffffff
0 54 2 ffffff
1 54 2 ffffff
2 54 2 ffffff
3 54 2 ffffff
4 54 2 ffffff
5 54 2 ffffff
6 54 2 ffffff
7 54 2 ffffff
8 54 2 ffffff
9 54 2 ffffff
10 54 2 ffffff
11 54 2 ffffff
12 54 2 ffffff
13 54 2 ffffff
14 54 2 ffffff
15 54 2 ffffff
0 55 2 ffffff
1 55 2 ffffff
2 55 2 ffffff
3 55 2 ffffff
4 55 2 ffffff
5 55 2 ffffff
6 55 2 ffffff
7 55 2 ffffff
8 55 2 ffffff
9 55 2 ffffff
10 55 2 ffffff
11 55 2 ffffff
12 55 2 ffffff
13 55 2 ffffff
14 55 2 ffffff
15 55 2 ffffff
0 56 2 ffffff
1 56 2 ffffff
2 56 2 ffffff
3 56 2 ffffff
4 56 2 ffffff
5 56 2 ffffff
6 56 2 ffffff
7 56 2 ffffff
8 56 2 ffffff
9 56 2 ffffff
10 56 2 ffffff
11 56 2 ffffff
12 56 2 ffffff
13 56 2 ffffff
14 56 2 ffffff
15 56 2 ffffff
0 57 2 ffffff
1 57 2 ffffff
2 57 2 ffffff
3 57 2 ffffff
4 57 2 ffffff
5 57 2 ffffff
6 57 2 ffffff
7 57 2 ffffff
8 57 2 ffffff
9 57 2 ffffff
10 57 2 ffffff
11 57 2 ffffff
12 57 2 ffffff
13 57 2 ffffff
14 57 2 ffffff
15 57 2 ffffff
0 58 2 ffffff
1 58 2 ffffff
2 58 2 ffffff
3 58 2 ffffff
4 58 2 ffffff
5 58 2 ffffff
6 58 2 ffffff
7 58 2 ffffff
8 58 2 ffffff
9 58 2 ffffff
10 58 2 ffffff
11 58 2 ffffff
12 58 2 ffffff
13 58 2 ffffff
14 58 2 ffffff
15 58 2 ffffff
0 59 2 ffffff
1 59 2 ffffff
2 59 2 ffffff
3 59 2 ffffff
4 59 2 ffffff
5 59 2 ffffff
6 59 2 ffffff
7 59 2 ffffff
8 59 2 ffffff
9 59 2 ffffff
10 59 2 ffffff
11 59 2 ffffff
12 59 2 ffffff
13 59 2 ffffff
14 59 2 ffffff
15 59 2 ffffff
0 60 2 ffffff
1 60 2 ffffff
2 60 2 ffffff
3 60 2 ffffff
4 60 2 ffffff
5 60 2 ffffff
6 60 2 ffffff
7 60 2 ffffff
8 60 2 ffffff
9 60 2 ffffff
10 60 2 ffffff
11 60 2 ffffff
12 60 2 ffffff
13 60 2 ffffff
14 60 2 ffffff
15 60 2 ffffff
0 61 2 ffffff
1 61 2 ffffff
2 61 2 ffffff
3 61 2 ffffff
4 61 2 ffffff
5 61 2 ffffff
6 61 2 ffffff
7 61 2 ffffff
8 61 2 ffffff
9 61 2 ffffff
10 61 2 ffffff
11 61 2 ffffff
12 61 2 ffffff
13 61 2 ffffff
14 61 2 ffffff
15 61 2 ffffff
0 62 2 ffffff
1 62 2 ffffff
2 62 2 ffffff
3 62 2 ffffff
4 62 2 ffffff
5 62 2 ffffff
6 62 2 ffffff
7 62 2 ffffff
8 62 2 ffffff
9 62 2 ffffff
10 62 2 ffffff
11 62 2 ffffff
12 62 2 ffffff
13 62 2 ffffff
14 62 2 ffffff
15 62 2 ffffff
0 63 2 ffffff
1 63 2 ffffff
2 63 2 ffffff
3 63 2 ffffff
4 63 2 ffffff
5 63 2 ffffff
6 63 2 ffffff
7 63 2 ffffff
8 63 2 ffffff
9 63 2 ffffff
10 63 2 ffffff
11 63 2 ffffff
12 63 2 ffffff
13 63 2 ffffff
14 63 2 ffffff
15 63 2 ffffff
0 48 3 ffffff
1 48 3 ffffff
2 48 3 ffffff
3 48 3 ffffff
4 48 3 ffffff
5 48 3 ffffff
6 48 3 ffffff
7 48 3 ffffff
8 48 3 ffffff
9 48 3 ffffff
10 48 3 ffffff
11 48 3 ffffff
12 48 3 ffffff
13 48 3 ffffff
14 48 3 ffffff
15 48 3 ffffff
0 49 3 ffffff
1 49 3 ffffff
2 49 3 ffffff
3 49 3 ffffff
4 49 3 ffffff
5 49 3 ffffff
6 49 3 ffffff
7 49 3 ffffff
8 49 3 ffffff
9 49 3 ffffff
10 49 3 ffffff
11 49 3 ffffff
12 49 3 ffffff
13 49 3 ffffff
14 49 3 ffffff
15 49 3 ffffff
