# Goxel 0.15.1
# One line per voxel
# X Y Z RRGGBB
0 0 0 222222
1 0 0 222222
2 0 0 222222
3 0 0 222222
4 0 0 222222
5 0 0 222222
6 0 0 222222
7 0 0 222222
8 0 0 222222
9 0 0 222222
10 0 0 222222
11 0 0 222222
12 0 0 222222
13 0 0 222222
14 0 0 222222
15 0 0 222222
0 1 0 442222
0 2 0 442222
0 3 0 442222
0 4 0 442222
0 5 0 442222
0 6 0 442222
0 7 0 442222
0 8 0 442222
0 9 0 442222
0 10 0 442222
0 11 0 442222
0 12 0 442222
0 13 0 442222
0 14 0 442222
0 15 0 442222
0 0 1 222222
1 0 1 222222
2 0 1 222222
3 0 1 222222
4 0 1 222222
5 0 1 222222
6 0 1 222222
7 0 1 222222
8 0 1 222222
9 0 1 222222
10 0 1 222222
11 0 1 222222
12 0 1 222222
13 0 1 222222
14 0 1 222222
15 0 1 222222
0 1 1 442222
0 2 1 442222
0 3 1 442222
0 4 1 442222
0 5 1 442222
0 6 1 442222
0 7 1 442222
0 8 1 442222
0 9 1 442222
0 10 1 442222
0 11 1 442222
0 12 1 442222
0 13 1 442222
0 14 1 442222
0 15 1 442222
0 0 2 222222
1 0 2 222222
2 0 2 222222
3 0 2 222222
4 0 2 222222
5 0 2 222222
6 0 2 222222
7 0 2 222222
8 0 2 222222
9 0 2 222222
10 0 2 222222
11 0 2 222222
12 0 2 222222
13 0 2 222222
14 0 2 222222
15 0 2 222222
0 1 2 442222
0 2 2 442222
0 3 2 442222
0 4 2 442222
0 5 2 442222
0 6 2 442222
0 7 2 442222
0 8 2 442222
0 9 2 442222
0 10 2 442222
0 11 2 442222
0 12 2 442222
0 13 2 442222
0 14 2 442222
0 15 2 442222
0 0 3 222222
1 0 3 222222
2 0 3 222222
3 0 3 222222
6 0 3 222222
7 0 3 222222
8 0 3 222222
9 0 3 222222
10 0 3 222222
11 0 3 222222
12 0 3 222222
13 0 3 222222
14 0 3 222222
15 0 3 222222
0 1 3 442222
0 2 3 442222
0 3 3 442222
0 4 3 442222
0 5 3 442222
0 6 3 442222
0 7 3 442222
0 8 3 442222
0 9 3 442222
0 10 3 442222
0 11 3 442222
0 12 3 442222
0 13 3 442222
0 14 3 442222
0 15 3 442222
0 0 4 222222
1 0 4 222222
2 0 4 222222
3 0 4 222222
6 0 4 222222
7 0 4 222222
8 0 4 222222
9 0 4 222222
10 0 4 222222
11 0 4 222222
12 0 4 222222
13 0 4 222222
14 0 4 222222
15 0 4 222222
0 1 4 442222
0 2 4 442222
0 3 4 442222
0 4 4 442222
0 5 4 442222
0 6 4 442222
0 7 4 442222
0 8 4 442222
0 9 4 442222
0 10 4 442222
0 11 4 442222
0 12 4 442222
0 13 4 442222
0 14 4 442222
0 15 4 442222
0 0 5 222222
1 0 5 222222
2 0 5 222222
3 0 5 222222
6 0 5 222222
7 0 5 222222
8 0 5 222222
9 0 5 222222
10 0 5 222222
11 0 5 222222
12 0 5 222222
13 0 5 222222
14 0 5 222222
15 0 5 222222
0 1 5 442222
0 2 5 442222
0 3 5 442222
0 4 5 442222
0 5 5 442222
0 6 5 442222
0 7 5 442222
0 8 5 442222
0 9 5 442222
0 10 5 442222
0 11 5 442222
0 12 5 442222
0 13 5 442222
0 14 5 442222
0 15 5 442222
0 0 6 222222
1 0 6 222222
2 0 6 222222
3 0 6 222222
6 0 6 222222
7 0 6 222222
8 0 6 222222
9 0 6 222222
10 0 6 222222
11 0 6 222222
12 0 6 222222
13 0 6 222222
14 0 6 222222
15 0 6 222222
0 1 6 442222
0 2 6 442222
0 3 6 442222
0 4 6 442222
0 5 6 442222
0 6 6 442222
0 7 6 442222
0 8 6 442222
0 9 6 442222
0 10 6 442222
0 11 6 442222
0 12 6 442222
0 13 6 442222
0 14 6 442222
0 15 6 442222
0 0 7 222222
1 0 7 222222
2 0 7 222222
3 0 7 222222
6 0 7 222222
7 0 7 222222
8 0 7 222222
9 0 7 222222
10 0 7 222222
11 0 7 222222
12 0 7 222222
13 0 7 222222
14 0 7 222222
15 0 7 222222
0 1 7 442222
0 2 7 442222
0 3 7 442222
0 4 7 442222
0 5 7 442222
0 6 7 442222
0 7 7 442222
0 8 7 442222
0 9 7 442222
0 10 7 442222
0 11 7 442222
0 12 7 442222
0 13 7 442222
0 14 7 442222
0 15 7 442222
0 0 8 222222
1 0 8 222222
2 0 8 222222
3 0 8 222222
4 0 8 222222
5 0 8 222222
6 0 8 222222
7 0 8 222222
8 0 8 222222
9 0 8 222222
10 0 8 222222
11 0 8 222222
12 0 8 222222
13 0 8 222222
14 0 8 222222
15 0 8 222222
0 1 8 442222
0 2 8 442222
0 3 8 442222
0 4 8 442222
0 5 8 442222
0 6 8 442222
0 7 8 442222
0 8 8 442222
0 9 8 442222
0 10 8 442222
0 11 8 442222
0 12 8 442222
0 13 8 442222
0 14 8 442222
0 15 8 442222
0 0 9 222222
1 0 9 222222
2 0 9 222222
3 0 9 222222
4 0 9 222222
5 0 9 222222
6 0 9 222222
7 0 9 222222
8 0 9 222222
9 0 9 222222
10 0 9 222222
11 0 9 222222
12 0 9 222222
13 0 9 222222
14 0 9 222222
15 0 9 222222
0 1 9 442222
0 2 9 442222
0 3 9 442222
0 4 9 442222
0 5 9 442222
0 6 9 442222
0 7 9 442222
0 8 9 442222
0 9 9 442222
0 10 9 442222
0 11 9 442222
0 12 9 442222
0 13 9 442222
0 14 9 442222
0 15 9 442222
16 0 0 222222
17 0 0 222222
18 0 0 222222
19 0 0 222222
20 0 0 222222
21 0 0 222222
22 0 0 222222
23 0 0 222222
24 0 0 222222
25 0 0 222222
26 0 0 222222
27 0 0 222222
28 0 0 222222
29 0 0 222222
30 0 0 222222
31 0 0 222222
20 1 0 446622
20 2 0 446622
20 3 0 446622
20 4 0 446622
20 5 0 446622
20 6 0 446622
20 7 0 446622
20 8 0 446622
20 9 0 446622
20 10 0 446622
20 11 0 446622
20 12 0 446622
20 13 0 446622
20 14 0 446622
20 15 0 446622
16 0 1 222222
17 0 1 222222
18 0 1 222222
19 0 1 222222
20 0 1 222222
21 0 1 222222
22 0 1 222222
23 0 1 222222
24 0 1 222222
25 0 1 222222
26 0 1 222222
27 0 1 222222
28 0 1 222222
29 0 1 222222
30 0 1 222222
31 0 1 222222
20 1 1 446622
20 2 1 446622
20 3 1 446622
20 4 1 446622
20 5 1 446622
20 6 1 446622
20 7 1 446622
20 8 1 446622
20 9 1 446622
20 10 1 446622
20 11 1 446622
20 12 1 446622
20 13 1 446622
20 14 1 446622
20 15 1 446622
16 0 2 222222
17 0 2 222222
18 0 2 222222
19 0 2 222222
20 0 2 222222
21 0 2 222222
22 0 2 222222
23 0 2 222222
24 0 2 222222
25 0 2 222222
26 0 2 222222
27 0 2 222222
28 0 2 222222
29 0 2 222222
30 0 2 222222
31 0 2 222222
20 1 2 446622
20 2 2 446622
20 3 2 446622
20 4 2 446622
20 5 2 446622
20 6 2 446622
20 7 2 446622
20 8 2 446622
20 9 2 446622
20 10 2 446622
20 11 2 446622
20 12 2 446622
20 13 2 446622
20 14 2 446622
20 15 2 446622
16 0 3 222222
17 0 3 222222
18 0 3 222222
19 0 3 222222
20 0 3 222222
21 0 3 222222
24 0 3 222222
25 0 3 222222
26 0 3 222222
27 0 3 222222
28 0 3 222222
29 0 3 222222
30 0 3 222222
31 0 3 222222
20 1 3 446622
20 2 3 446622
20 3 3 446622
20 4 3 446622
20 5 3 446622
20 6 3 446622
20 7 3 446622
20 8 3 446622
20 9 3 446622
20 10 3 446622
20 11 3 446622
20 12 3 446622
20 13 3 446622
20 14 3 446622
20 15 3 446622
16 0 4 222222
17 0 4 222222
18 0 4 222222
19 0 4 222222
20 0 4 222222
21 0 4 222222
24 0 4 222222
25 0 4 222222
26 0 4 222222
27 0 4 222222
28 0 4 222222
29 0 4 222222
30 0 4 222222
31 0 4 222222
20 1 4 446622
20 2 4 446622
20 3 4 446622
20 4 4 446622
20 5 4 446622
20 6 4 446622
20 7 4 446622
20 8 4 446622
20 9 4 446622
20 10 4 446622
20 11 4 446622
20 12 4 446622
20 13 4 446622
20 14 4 446622
20 15 4 446622
16 0 5 222222
17 0 5 222222
18 0 5 222222
19 0 5 222222
20 0 5 222222
21 0 5 222222
24 0 5 222222
25 0 5 222222
26 0 5 222222
27 0 5 222222
28 0 5 222222
29 0 5 222222
30 0 5 222222
31 0 5 222222
20 1 5 446622
20 2 5 446622
20 3 5 446622
20 4 5 446622
20 5 5 446622
20 6 5 446622
20 7 5 446622
20 8 5 446622
20 9 5 446622
20 10 5 446622
20 11 5 446622
20 12 5 446622
20 13 5 446622
20 14 5 446622
20 15 5 446622
16 0 6 222222
17 0 6 222222
18 0 6 222222
19 0 6 222222
20 0 6 222222
21 0 6 222222
24 0 6 222222
25 0 6 222222
26 0 6 222222
27 0 6 222222
28 0 6 222222
29 0 6 222222
30 0 6 222222
31 0 6 222222
20 1 6 446622
20 2 6 446622
20 3 6 446622
20 4 6 446622
20 5 6 446622
20 6 6 446622
20 7 6 446622
20 8 6 446622
20 9 6 446622
20 10 6 446622
20 11 6 446622
20 12 6 446622
20 13 6 446622
20 14 6 446622
20 15 6 446622
16 0 7 222222
17 0 7 222222
18 0 7 222222
19 0 7 222222
20 0 7 222222
21 0 7 222222
24 0 7 222222
25 0 7 222222
26 0 7 222222
27 0 7 222222
28 0 7 222222
29 0 7 222222
30 0 7 222222
31 0 7 222222
20 1 7 446622
20 2 7 446622
20 3 7 446622
20 4 7 446622
20 5 7 446622
20 6 7 446622
20 7 7 446622
20 8 7 446622
20 9 7 446622
20 10 7 446622
20 11 7 446622
20 12 7 446622
20 13 7 446622
20 14 7 446622
20 15 7 446622
16 0 8 222222
17 0 8 222222
18 0 8 222222
19 0 8 222222
20 0 8 222222
21 0 8 222222
22 0 8 222222
23 0 8 222222
24 0 8 222222
25 0 8 222222
26 0 8 222222
27 0 8 222222
28 0 8 222222
29 0 8 222222
30 0 8 222222
31 0 8 222222
20 1 8 446622
20 2 8 446622
20 3 8 446622
20 4 8 446622
20 5 8 446622
20 6 8 446622
20 7 8 446622
20 8 8 446622
20 9 8 446622
20 10 8 446622
20 11 8 446622
20 12 8 446622
20 13 8 446622
20 14 8 446622
20 15 8 446622
16 0 9 222222
17 0 9 222222
18 0 9 222222
19 0 9 222222
20 0 9 222222
21 0 9 222222
22 0 9 222222
23 0 9 222222
24 0 9 222222
25 0 9 222222
26 0 9 222222
27 0 9 222222
28 0 9 222222
29 0 9 222222
30 0 9 222222
31 0 9 222222
20 1 9 446622
20 2 9 446622
20 3 9 446622
20 4 9 446622
20 5 9 446622
20 6 9 446622
20 7 9 446622
20 8 9 446622
20 9 9 446622
20 10 9 446622
20 11 9 446622
20 12 9 446622
20 13 9 446622
20 14 9 446622
20 15 9 446622
32 0 0 222222
33 0 0 222222
34 0 0 222222
35 0 0 222222
36 0 0 222222
37 0 0 222222
38 0 0 222222
39 0 0 222222
40 0 0 222222
41 0 0 222222
42 0 0 222222
43 0 0 222222
44 0 0 222222
45 0 0 222222
46 0 0 222222
47 0 0 222222
40 1 0 446622
40 2 0 446622
40 3 0 446622
40 4 0 446622
40 5 0 446622
40 6 0 446622
40 7 0 446622
40 8 0 446622
40 9 0 446622
40 10 0 446622
40 11 0 446622
40 12 0 446622
40 13 0 446622
40 14 0 446622
40 15 0 446622
32 0 1 222222
33 0 1 222222
34 0 1 222222
35 0 1 222222
36 0 1 222222
37 0 1 222222
38 0 1 222222
39 0 1 222222
40 0 1 222222
41 0 1 222222
42 0 1 222222
43 0 1 222222
44 0 1 222222
45 0 1 222222
46 0 1 222222
47 0 1 222222
40 1 1 446622
40 2 1 446622
40 3 1 446622
40 4 1 446622
40 5 1 446622
40 6 1 446622
40 7 1 446622
40 8 1 446622
40 9 1 446622
40 10 1 446622
40 11 1 446622
40 12 1 446622
40 13 1 446622
40 14 1 446622
40 15 1 446622
32 0 2 222222
33 0 2 222222
34 0 2 222222
35 0 2 222222
36 0 2 222222
37 0 2 222222
38 0 2 222222
39 0 2 222222
40 0 2 222222
41 0 2 222222
42 0 2 222222
43 0 2 222222
44 0 2 222222
45 0 2 222222
46 0 2 222222
47 0 2 222222
40 1 2 446622
40 2 2 446622
40 3 2 446622
40 4 2 446622
40 5 2 446622
40 6 2 446622
40 7 2 446622
40 8 2 446622
40 9 2 446622
40 10 2 446622
40 11 2 446622
40 12 2 446622
40 13 2 446622
40 14 2 446622
40 15 2 446622
32 0 3 222222
33 0 3 222222
34 0 3 222222
37 0 3 222222
38 0 3 222222
39 0 3 222222
40 0 3 222222
41 0 3 222222
42 0 3 222222
43 0 3 222222
44 0 3 222222
45 0 3 222222
46 0 3 222222
47 0 3 222222
40 1 3 446622
40 2 3 446622
40 3 3 446622
40 4 3 446622
40 5 3 446622
40 6 3 446622
40 7 3 446622
40 8 3 446622
40 9 3 446622
40 10 3 446622
40 11 3 446622
40 12 3 446622
40 13 3 446622
40 14 3 446622
40 15 3 446622
32 0 4 222222
33 0 4 222222
34 0 4 222222
37 0 4 222222
38 0 4 222222
39 0 4 222222
40 0 4 222222
41 0 4 222222
42 0 4 222222
43 0 4 222222
44 0 4 222222
45 0 4 222222
46 0 4 222222
47 0 4 222222
40 1 4 446622
40 2 4 446622
40 3 4 446622
40 4 4 446622
40 5 4 446622
40 6 4 446622
40 7 4 446622
40 8 4 446622
40 9 4 446622
40 10 4 446622
40 11 4 446622
40 12 4 446622
40 13 4 446622
40 14 4 446622
40 15 4 446622
32 0 5 222222
33 0 5 222222
34 0 5 222222
37 0 5 222222
38 0 5 222222
39 0 5 222222
40 0 5 222222
41 0 5 222222
42 0 5 222222
43 0 5 222222
44 0 5 222222
45 0 5 222222
46 0 5 222222
47 0 5 222222
40 1 5 446622
40 2 5 446622
40 3 5 446622
40 4 5 446622
40 5 5 446622
40 6 5 446622
40 7 5 446622
40 8 5 446622
40 9 5 446622
40 10 5 446622
40 11 5 446622
40 12 5 446622
40 13 5 446622
40 14 5 446622
40 15 5 446622
32 0 6 222222
33 0 6 222222
34 0 6 222222
37 0 6 222222
38 0 6 222222
39 0 6 222222
40 0 6 222222
41 0 6 222222
42 0 6 222222
43 0 6 222222
44 0 6 222222
45 0 6 222222
46 0 6 222222
47 0 6 222222
40 1 6 446622
40 2 6 446622
40 3 6 446622
40 4 6 446622
40 5 6 446622
40 6 6 446622
40 7 6 446622
40 8 6 446622
40 9 6 446622
40 10 6 446622
40 11 6 446622
40 12 6 446622
40 13 6 446622
40 14 6 446622
40 15 6 446622
32 0 7 222222
33 0 7 222222
34 0 7 222222
37 0 7 222222
38 0 7 222222
39 0 7 222222
40 0 7 222222
41 0 7 222222
42 0 7 222222
43 0 7 222222
44 0 7 222222
45 0 7 222222
46 0 7 222222
47 0 7 222222
40 1 7 446622
40 2 7 446622
40 3 7 446622
40 4 7 446622
40 5 7 446622
40 6 7 446622
40 7 7 446622
40 8 7 446622
40 9 7 446622
40 10 7 446622
40 11 7 446622
40 12 7 446622
40 13 7 446622
40 14 7 446622
40 15 7 446622
32 0 8 222222
33 0 8 222222
34 0 8 222222
35 0 8 222222
36 0 8 222222
37 0 8 222222
38 0 8 222222
39 0 8 222222
40 0 8 222222
41 0 8 222222
42 0 8 222222
43 0 8 222222
44 0 8 222222
45 0 8 222222
46 0 8 222222
47 0 8 222222
40 1 8 446622
40 2 8 446622
40 3 8 446622
40 4 8 446622
40 5 8 446622
40 6 8 446622
40 7 8 446622
40 8 8 446622
40 9 8 446622
40 10 8 446622
40 11 8 446622
40 12 8 446622
40 13 8 446622
40 14 8 446622
40 15 8 446622
32 0 9 222222
33 0 9 222222
34 0 9 222222
35 0 9 222222
36 0 9 222222
37 0 9 222222
38 0 9 222222
39 0 9 222222
40 0 9 222222
41 0 9 222222
42 0 9 222222
43 0 9 222222
44 0 9 222222
45 0 9 222222
46 0 9 222222
47 0 9 222222
40 1 9 446622
40 2 9 446622
40 3 9 446622
40 4 9 446622
40 5 9 446622
40 6 9 446622
40 7 9 446622
40 8 9 446622
40 9 9 446622
40 10 9 446622
40 11 9 446622
40 12 9 446622
40 13 9 446622
40 14 9 446622
40 15 9 446622
48 0 0 222222
49 0 0 222222
50 0 0 222222
51 0 0 222222
52 0 0 222222
53 0 0 222222
54 0 0 222222
55 0 0 222222
56 0 0 222222
57 0 0 222222
58 0 0 222222
59 0 0 222222
60 0 0 222222
61 0 0 222222
62 0 0 222222
63 0 0 222222
60 1 0 446622
60 2 0 446622
60 3 0 446622
60 4 0 446622
60 5 0 446622
60 6 0 446622
60 7 0 446622
60 8 0 446622
60 9 0 446622
60 10 0 446622
60 11 0 446622
60 12 0 446622
60 13 0 446622
60 14 0 446622
60 15 0 446622
48 0 1 222222
49 0 1 222222
50 0 1 222222
51 0 1 222222
52 0 1 222222
53 0 1 222222
54 0 1 222222
55 0 1 222222
56 0 1 222222
57 0 1 222222
58 0 1 222222
59 0 1 222222
60 0 1 222222
61 0 1 222222
62 0 1 222222
63 0 1 222222
60 1 1 446622
60 2 1 446622
60 3 1 446622
60 4 1 446622
60 5 1 446622
60 6 1 446622
60 7 1 446622
60 8 1 446622
60 9 1 446622
60 10 1 446622
60 11 1 446622
60 12 1 446622
60 13 1 446622
60 14 1 446622
60 15 1 446622
48 0 2 222222
49 0 2 222222
50 0 2 222222
51 0 2 222222
52 0 2 222222
53 0 2 222222
54 0 2 222222
55 0 2 222222
56 0 2 222222
57 0 2 222222
58 0 2 222222
59 0 2 222222
60 0 2 222222
61 0 2 222222
62 0 2 222222
63 0 2 222222
60 1 2 446622
60 2 2 446622
60 3 2 446622
60 4 2 446622
60 5 2 446622
60 6 2 446622
60 7 2 446622
60 8 2 446622
60 9 2 446622
60 10 2 446622
60 11 2 446622
60 12 2 446622
60 13 2 446622
60 14 2 446622
60 15 2 446622
48 0 3 222222
49 0 3 222222
50 0 3 222222
51 0 3 222222
52 0 3 222222
53 0 3 222222
54 0 3 222222
57 0 3 222222
58 0 3 222222
59 0 3 222222
60 0 3 222222
61 0 3 222222
62 0 3 222222
63 0 3 222222
60 1 3 446622
60 2 3 446622
60 3 3 446622
60 4 3 446622
60 5 3 446622
60 6 3 446622
60 7 3 446622
60 8 3 446622
60 9 3 446622
60 10 3 446622
60 11 3 446622
60 12 3 446622
60 13 3 446622
60 14 3 446622
60 15 3 446622
48 0 4 222222
49 0 4 222222
50 0 4 222222
51 0 4 222222
52 0 4 222222
53 0 4 222222
54 0 4 222222
57 0 4 222222
58 0 4 222222
59 0 4 222222
60 0 4 222222
61 0 4 222222
62 0 4 222222
63 0 4 222222
60 1 4 446622
60 2 4 446622
60 3 4 446622
60 4 4 446622
60 5 4 446622
60 6 4 446622
60 7 4 446622
60 8 4 446622
60 9 4 446622
60 10 4 446622
60 11 4 446622
60 12 4 446622
60 13 4 446622
60 14 4 446622
60 15 4 446622
48 0 5 222222
49 0 5 222222
50 0 5 222222
51 0 5 222222
52 0 5 222222
53 0 5 222222
54 0 5 222222
57 0 5 222222
58 0 5 222222
59 0 5 222222
60 0 5 222222
61 0 5 222222
62 0 5 222222
63 0 5 222222
60 1 5 446622
60 2 5 446622
60 3 5 446622
60 4 5 446622
60 5 5 446622
60 6 5 446622
60 7 5 446622
60 8 5 446622
60 9 5 446622
60 10 5 446622
60 11 5 446622
60 12 5 446622
60 13 5 446622
60 14 5 446622
60 15 5 446622
48 0 6 222222
49 0 6 222222
50 0 6 222222
51 0 6 222222
52 0 6 222222
53 0 6 222222
54 0 6 222222
57 0 6 222222
58 0 6 222222
59 0 6 222222
60 0 6 222222
61 0 6 222222
62 0 6 222222
63 0 6 222222
60 1 6 446622
60 2 6 446622
60 3 6 446622
60 4 6 446622
60 5 6 446622
60 6 6 446622
60 7 6 446622
60 8 6 446622
60 9 6 446622
60 10 6 446622
60 11 6 446622
60 12 6 446622
60 13 6 446622
60 14 6 446622
60 15 6 446622
48 0 7 222222
49 0 7 222222
50 0 7 222222
51 0 7 222222
52 0 7 222222
53 0 7 222222
54 0 7 222222
57 0 7 222222
58 0 7 222222
59 0 7 222222
60 0 7 222222
61 0 7 222222
62 0 7 222222
63 0 7 222222
60 1 7 446622
60 2 7 446622
60 3 7 446622
60 4 7 446622
60 5 7 446622
60 6 7 446622
60 7 7 446622
60 8 7 446622
60 9 7 446622
60 10 7 446622
60 11 7 446622
60 12 7 446622
60 13 7 446622
60 14 7 446622
60 15 7 446622
48 0 8 222222
49 0 8 222222
50 0 8 222222
51 0 8 222222
52 0 8 222222
53 0 8 222222
54 0 8 222222
55 0 8 222222
56 0 8 222222
57 0 8 222222
58 0 8 222222
59 0 8 222222
60 0 8 222222
61 0 8 222222
62 0 8 222222
63 0 8 222222
60 1 8 446622
60 2 8 446622
60 3 8 446622
60 4 8 446622
60 5 8 446622
60 6 8 446622
60 7 8 446622
60 8 8 446622
60 9 8 446622
60 10 8 446622
60 11 8 446622
60 12 8 446622
60 13 8 446622
60 14 8 446622
60 15 8 446622
48 0 9 222222
49 0 9 222222
50 0 9 222222
51 0 9 222222
52 0 9 222222
53 0 9 222222
54 0 9 222222
55 0 9 222222
56 0 9 222222
57 0 9 222222
58 0 9 222222
59 0 9 222222
60 0 9 222222
61 0 9 222222
62 0 9 222222
63 0 9 222222
60 1 9 446622
60 2 9 446622
60 3 9 446622
60 4 9 446622
60 5 9 446622
60 6 9 446622
60 7 9 446622
60 8 9 446622
60 9 9 446622
60 10 9 446622
60 11 9 446622
60 12 9 446622
60 13 9 446622
60 14 9 446622
60 15 9 446622
64 0 0 222222
65 0 0 222222
66 0 0 222222
67 0 0 222222
68 0 0 222222
69 0 0 222222
70 0 0 222222
71 0 0 222222
72 0 0 222222
73 0 0 222222
74 0 0 222222
75 0 0 222222
76 0 0 222222
77 0 0 222222
78 0 0 222222
79 0 0 222222
79 1 0 116622
79 2 0 116622
79 3 0 116622
79 4 0 116622
79 5 0 116622
79 6 0 116622
79 7 0 116622
79 8 0 116622
79 9 0 116622
79 10 0 116622
79 11 0 116622
79 12 0 116622
79 13 0 116622
79 14 0 116622
79 15 0 116622
64 0 1 222222
65 0 1 222222
66 0 1 222222
67 0 1 222222
68 0 1 222222
69 0 1 222222
70 0 1 222222
71 0 1 222222
72 0 1 222222
73 0 1 222222
74 0 1 222222
75 0 1 222222
76 0 1 222222
77 0 1 222222
78 0 1 222222
79 0 1 222222
79 1 1 116622
79 2 1 116622
79 3 1 116622
79 4 1 116622
79 5 1 116622
79 6 1 116622
79 7 1 116622
79 8 1 116622
79 9 1 116622
79 10 1 116622
79 11 1 116622
79 12 1 116622
79 13 1 116622
79 14 1 116622
79 15 1 116622
64 0 2 222222
65 0 2 222222
66 0 2 222222
67 0 2 222222
68 0 2 222222
69 0 2 222222
70 0 2 222222
71 0 2 222222
72 0 2 222222
73 0 2 222222
74 0 2 222222
75 0 2 222222
76 0 2 222222
77 0 2 222222
78 0 2 222222
79 0 2 222222
79 1 2 116622
79 2 2 116622
79 3 2 116622
79 4 2 116622
79 5 2 116622
79 6 2 116622
79 7 2 116622
79 8 2 116622
79 9 2 116622
79 10 2 116622
79 11 2 116622
79 12 2 116622
79 13 2 116622
79 14 2 116622
79 15 2 116622
66 0 3 222222
67 0 3 222222
68 0 3 222222
69 0 3 222222
70 0 3 222222
71 0 3 222222
72 0 3 222222
73 0 3 222222
76 0 3 222222
77 0 3 222222
78 0 3 222222
79 0 3 222222
79 1 3 116622
79 2 3 116622
79 3 3 116622
79 4 3 116622
79 5 3 116622
79 6 3 116622
79 7 3 116622
79 8 3 116622
79 9 3 116622
79 10 3 116622
79 11 3 116622
79 12 3 116622
79 13 3 116622
79 14 3 116622
79 15 3 116622
66 0 4 222222
67 0 4 222222
68 0 4 222222
69 0 4 222222
70 0 4 222222
71 0 4 222222
72 0 4 222222
73 0 4 222222
76 0 4 222222
77 0 4 222222
78 0 4 222222
79 0 4 222222
79 1 4 116622
79 2 4 116622
79 3 4 116622
79 4 4 116622
79 5 4 116622
79 6 4 116622
79 7 4 116622
79 8 4 116622
79 9 4 116622
79 10 4 116622
79 11 4 116622
79 12 4 116622
79 13 4 116622
79 14 4 116622
79 15 4 116622
66 0 5 222222
67 0 5 222222
68 0 5 222222
69 0 5 222222
70 0 5 222222
71 0 5 222222
72 0 5 222222
73 0 5 222222
76 0 5 222222
77 0 5 222222
78 0 5 222222
79 0 5 222222
79 1 5 116622
79 2 5 116622
79 3 5 116622
79 4 5 116622
79 5 5 116622
79 6 5 116622
79 7 5 116622
79 8 5 116622
79 9 5 116622
79 10 5 116622
79 11 5 116622
79 12 5 116622
79 13 5 116622
79 14 5 116622
79 15 5 116622
66 0 6 222222
67 0 6 222222
68 0 6 222222
69 0 6 222222
70 0 6 222222
71 0 6 222222
72 0 6 222222
73 0 6 222222
76 0 6 222222
77 0 6 222222
78 0 6 222222
79 0 6 222222
79 1 6 116622
79 2 6 116622
79 3 6 116622
79 4 6 116622
79 5 6 116622
79 6 6 116622
79 7 6 116622
79 8 6 116622
79 9 6 116622
79 10 6 116622
79 11 6 116622
79 12 6 116622
79 13 6 116622
79 14 6 116622
79 15 6 116622
66 0 7 222222
67 0 7 222222
68 0 7 222222
69 0 7 222222
70 0 7 222222
71 0 7 222222
72 0 7 222222
73 0 7 222222
76 0 7 222222
77 0 7 222222
78 0 7 222222
79 0 7 222222
79 1 7 116622
79 2 7 116622
79 3 7 116622
79 4 7 116622
79 5 7 116622
79 6 7 116622
79 7 7 116622
79 8 7 116622
79 9 7 116622
79 10 7 116622
79 11 7 116622
79 12 7 116622
79 13 7 116622
79 14 7 116622
79 15 7 116622
64 0 8 222222
65 0 8 222222
66 0 8 222222
67 0 8 222222
68 0 8 222222
69 0 8 222222
70 0 8 222222
71 0 8 222222
72 0 8 222222
73 0 8 222222
74 0 8 222222
75 0 8 222222
76 0 8 222222
77 0 8 222222
78 0 8 222222
79 0 8 222222
79 1 8 116622
79 2 8 116622
79 3 8 116622
79 4 8 116622
79 5 8 116622
79 6 8 116622
79 7 8 116622
79 8 8 116622
79 9 8 116622
79 10 8 116622
79 11 8 116622
79 12 8 116622
79 13 8 116622
79 14 8 116622
79 15 8 116622
64 0 9 222222
65 0 9 222222
66 0 9 222222
67 0 9 222222
68 0 9 222222
69 0 9 222222
70 0 9 222222
71 0 9 222222
72 0 9 222222
73 0 9 222222
74 0 9 222222
75 0 9 222222
76 0 9 222222
77 0 9 222222
78 0 9 222222
79 0 9 222222
79 1 9 116622
79 2 9 116622
79 3 9 116622
79 4 9 116622
79 5 9 116622
79 6 9 116622
79 7 9 116622
79 8 9 116622
79 9 9 116622
79 10 9 116622
79 11 9 116622
79 12 9 116622
79 13 9 116622
79 14 9 116622
79 15 9 116622
0 16 0 442222
0 17 0 442222
0 18 0 442222
0 19 0 442222
1 19 0 11bb22
6 19 0 11bb22
7 19 0 11bb22
8 19 0 11bb22
9 19 0 11bb22
10 19 0 11bb22
11 19 0 11bb22
12 19 0 11bb22
13 19 0 11bb22
14 19 0 11bb22
15 19 0 11bb22
0 20 0 442222
0 21 0 442222
0 22 0 442222
0 23 0 442222
0 24 0 442222
0 25 0 442222
0 26 0 442222
0 27 0 442222
0 28 0 442222
1 28 0 aabb22
2 28 0 aabb22
3 28 0 aabb22
4 28 0 aabb22
5 28 0 aabb22
6 28 0 aabb22
7 28 0 aabb22
8 28 0 aabb22
9 28 0 aabb22
10 28 0 aabb22
11 28 0 aabb22
12 28 0 aabb22
13 28 0 aabb22
14 28 0 aabb22
0 29 0 442222
0 30 0 442222
0 31 0 442222
0 16 1 442222
0 17 1 442222
0 18 1 442222
0 19 1 442222
1 19 1 11bb22
6 19 1 11bb22
7 19 1 11bb22
8 19 1 11bb22
9 19 1 11bb22
10 19 1 11bb22
11 19 1 11bb22
12 19 1 11bb22
13 19 1 11bb22
14 19 1 11bb22
15 19 1 11bb22
0 20 1 442222
0 21 1 442222
0 22 1 442222
0 23 1 442222
0 24 1 442222
0 25 1 442222
0 26 1 442222
0 27 1 442222
0 28 1 442222
1 28 1 aabb22
2 28 1 aabb22
3 28 1 aabb22
4 28 1 aabb22
5 28 1 aabb22
6 28 1 aabb22
7 28 1 aabb22
8 28 1 aabb22
9 28 1 aabb22
10 28 1 aabb22
11 28 1 aabb22
12 28 1 aabb22
13 28 1 aabb22
14 28 1 aabb22
0 29 1 442222
0 30 1 442222
0 31 1 442222
0 16 2 442222
0 17 2 442222
0 18 2 442222
0 19 2 442222
1 19 2 11bb22
6 19 2 11bb22
7 19 2 11bb22
8 19 2 11bb22
9 19 2 11bb22
10 19 2 11bb22
11 19 2 11bb22
12 19 2 11bb22
13 19 2 11bb22
14 19 2 11bb22
15 19 2 11bb22
0 20 2 442222
0 21 2 442222
0 22 2 442222
0 23 2 442222
0 24 2 442222
0 25 2 442222
0 26 2 442222
0 27 2 442222
0 28 2 442222
1 28 2 aabb22
2 28 2 aabb22
3 28 2 aabb22
4 28 2 aabb22
5 28 2 aabb22
6 28 2 aabb22
7 28 2 aabb22
8 28 2 aabb22
9 28 2 aabb22
10 28 2 aabb22
11 28 2 aabb22
12 28 2 aabb22
13 28 2 aabb22
14 28 2 aabb22
0 29 2 442222
0 30 2 442222
0 31 2 442222
0 16 3 442222
0 17 3 442222
0 18 3 442222
0 19 3 442222
1 19 3 11bb22
6 19 3 11bb22
7 19 3 11bb22
8 19 3 11bb22
9 19 3 11bb22
10 19 3 11bb22
11 19 3 11bb22
12 19 3 11bb22
13 19 3 11bb22
14 19 3 11bb22
15 19 3 11bb22
0 20 3 442222
0 21 3 442222
0 22 3 442222
0 23 3 442222
0 24 3 442222
0 25 3 442222
0 26 3 442222
0 27 3 442222
0 28 3 442222
1 28 3 aabb22
2 28 3 aabb22
3 28 3 aabb22
4 28 3 aabb22
5 28 3 aabb22
6 28 3 aabb22
7 28 3 aabb22
8 28 3 aabb22
9 28 3 aabb22
10 28 3 aabb22
11 28 3 aabb22
12 28 3 aabb22
13 28 3 aabb22
14 28 3 aabb22
0 29 3 442222
0 30 3 442222
0 31 3 442222
0 16 4 442222
0 17 4 442222
0 18 4 442222
0 19 4 442222
1 19 4 11bb22
6 19 4 11bb22
7 19 4 11bb22
8 19 4 11bb22
9 19 4 11bb22
10 19 4 11bb22
11 19 4 11bb22
12 19 4 11bb22
13 19 4 11bb22
14 19 4 11bb22
15 19 4 11bb22
0 20 4 442222
0 21 4 442222
0 22 4 442222
0 23 4 442222
0 24 4 442222
0 25 4 442222
0 26 4 442222
0 27 4 442222
0 28 4 442222
1 28 4 aabb22
2 28 4 aabb22
3 28 4 aabb22
4 28 4 aabb22
5 28 4 aabb22
6 28 4 aabb22
7 28 4 aabb22
8 28 4 aabb22
9 28 4 aabb22
10 28 4 aabb22
11 28 4 aabb22
12 28 4 aabb22
13 28 4 aabb22
14 28 4 aabb22
0 29 4 442222
0 30 4 442222
0 31 4 442222
0 16 5 442222
0 17 5 442222
0 18 5 442222
0 19 5 442222
1 19 5 11bb22
6 19 5 11bb22
7 19 5 11bb22
8 19 5 11bb22
9 19 5 11bb22
10 19 5 11bb22
11 19 5 11bb22
12 19 5 11bb22
13 19 5 11bb22
14 19 5 11bb22
15 19 5 11bb22
0 20 5 442222
0 21 5 442222
0 22 5 442222
0 23 5 442222
0 24 5 442222
0 25 5 442222
0 26 5 442222
0 27 5 442222
0 28 5 442222
1 28 5 aabb22
2 28 5 aabb22
3 28 5 aabb22
4 28 5 aabb22
5 28 5 aabb22
6 28 5 aabb22
7 28 5 aabb22
8 28 5 aabb22
9 28 5 aabb22
10 28 5 aabb22
11 28 5 aabb22
12 28 5 aabb22
13 28 5 aabb22
14 28 5 aabb22
0 29 5 442222
0 30 5 442222
0 31 5 442222
0 16 6 442222
0 17 6 442222
0 18 6 442222
0 19 6 442222
1 19 6 11bb22
6 19 6 11bb22
7 19 6 11bb22
8 19 6 11bb22
9 19 6 11bb22
10 19 6 11bb22
11 19 6 11bb22
12 19 6 11bb22
13 19 6 11bb22
14 19 6 11bb22
15 19 6 11bb22
0 20 6 442222
0 21 6 442222
0 22 6 442222
0 23 6 442222
0 24 6 442222
0 25 6 442222
0 26 6 442222
0 27 6 442222
0 28 6 442222
1 28 6 aabb22
2 28 6 aabb22
3 28 6 aabb22
4 28 6 aabb22
5 28 6 aabb22
6 28 6 aabb22
7 28 6 aabb22
8 28 6 aabb22
9 28 6 aabb22
10 28 6 aabb22
11 28 6 aabb22
12 28 6 aabb22
13 28 6 aabb22
14 28 6 aabb22
0 29 6 442222
0 30 6 442222
0 31 6 442222
0 16 7 442222
0 17 7 442222
0 18 7 442222
0 19 7 442222
1 19 7 11bb22
2 19 7 11bb22
3 19 7 11bb22
4 19 7 11bb22
5 19 7 11bb22
6 19 7 11bb22
7 19 7 11bb22
8 19 7 11bb22
9 19 7 11bb22
10 19 7 11bb22
11 19 7 11bb22
12 19 7 11bb22
13 19 7 11bb22
14 19 7 11bb22
15 19 7 11bb22
0 20 7 442222
0 21 7 442222
0 22 7 442222
0 23 7 442222
0 24 7 442222
0 25 7 442222
0 26 7 442222
0 27 7 442222
0 28 7 442222
1 28 7 aabb22
2 28 7 aabb22
3 28 7 aabb22
4 28 7 aabb22
5 28 7 aabb22
6 28 7 aabb22
7 28 7 aabb22
8 28 7 aabb22
9 28 7 aabb22
10 28 7 aabb22
11 28 7 aabb22
12 28 7 aabb22
13 28 7 aabb22
14 28 7 aabb22
15 28 7 aabb22
0 29 7 442222
0 30 7 442222
0 31 7 442222
0 16 8 442222
0 17 8 442222
0 18 8 442222
0 19 8 442222
1 19 8 11bb22
2 19 8 11bb22
3 19 8 11bb22
4 19 8 11bb22
5 19 8 11bb22
6 19 8 11bb22
7 19 8 11bb22
8 19 8 11bb22
9 19 8 11bb22
10 19 8 11bb22
11 19 8 11bb22
12 19 8 11bb22
13 19 8 11bb22
14 19 8 11bb22
15 19 8 11bb22
0 20 8 442222
0 21 8 442222
0 22 8 442222
0 23 8 442222
0 24 8 442222
0 25 8 442222
0 26 8 442222
0 27 8 442222
0 28 8 442222
1 28 8 aabb22
2 28 8 aabb22
3 28 8 aabb22
4 28 8 aabb22
5 28 8 aabb22
6 28 8 aabb22
7 28 8 aabb22
8 28 8 aabb22
9 28 8 aabb22
10 28 8 aabb22
11 28 8 aabb22
12 28 8 aabb22
13 28 8 aabb22
14 28 8 aabb22
15 28 8 aabb22
0 29 8 442222
0 30 8 442222
0 31 8 442222
0 16 9 442222
0 17 9 442222
0 18 9 442222
0 19 9 442222
1 19 9 11bb22
2 19 9 11bb22
3 19 9 11bb22
4 19 9 11bb22
5 19 9 11bb22
6 19 9 11bb22
7 19 9 11bb22
8 19 9 11bb22
9 19 9 11bb22
10 19 9 11bb22
11 19 9 11bb22
12 19 9 11bb22
13 19 9 11bb22
14 19 9 11bb22
15 19 9 11bb22
0 20 9 442222
0 21 9 442222
0 22 9 442222
0 23 9 442222
0 24 9 442222
0 25 9 442222
0 26 9 442222
0 27 9 442222
0 28 9 442222
1 28 9 aabb22
2 28 9 aabb22
3 28 9 aabb22
4 28 9 aabb22
5 28 9 aabb22
6 28 9 aabb22
7 28 9 aabb22
8 28 9 aabb22
9 28 9 aabb22
10 28 9 aabb22
11 28 9 aabb22
12 28 9 aabb22
13 28 9 aabb22
14 28 9 aabb22
15 28 9 aabb22
0 29 9 442222
0 30 9 442222
0 31 9 442222
0 32 0 442222
0 33 0 442222
0 34 0 442222
1 34 0 aabb22
2 34 0 aabb22
3 34 0 aabb22
6 34 0 aabb22
7 34 0 aabb22
8 34 0 aabb22
9 34 0 aabb22
10 34 0 aabb22
13 34 0 aabb22
14 34 0 aabb22
15 34 0 aabb22
0 35 0 442222
8 35 0 aabb22
15 35 0 aabb22
0 36 0 442222
8 36 0 aabb22
15 36 0 aabb22
0 37 0 442222
8 37 0 aabb22
15 37 0 aabb22
0 38 0 442222
8 38 0 aabb22
15 38 0 aabb22
0 39 0 442222
8 39 0 aabb22
15 39 0 aabb22
0 40 0 442222
8 40 0 aabb22
15 40 0 aabb22
0 41 0 442222
8 41 0 aabb22
15 41 0 aabb22
0 42 0 442222
8 42 0 aabb22
15 42 0 aabb22
0 43 0 442222
8 43 0 aabb22
15 43 0 aabb22
0 44 0 442222
8 44 0 aabb22
15 44 0 aabb22
0 45 0 442222
8 45 0 aabb22
15 45 0 aabb22
0 46 0 442222
8 46 0 aabb22
15 46 0 aabb22
0 47 0 00bb2f
1 47 0 00bb2f
2 47 0 00bb2f
3 47 0 00bb2f
4 47 0 00bb2f
5 47 0 00bb2f
6 47 0 00bb2f
7 47 0 00bb2f
8 47 0 00bb2f
9 47 0 00bb2f
10 47 0 00bb2f
11 47 0 00bb2f
12 47 0 00bb2f
13 47 0 00bb2f
14 47 0 00bb2f
15 47 0 00bb2f
0 32 1 442222
0 33 1 442222
0 34 1 442222
1 34 1 aabb22
2 34 1 aabb22
3 34 1 aabb22
6 34 1 aabb22
7 34 1 aabb22
8 34 1 aabb22
9 34 1 aabb22
10 34 1 aabb22
13 34 1 aabb22
14 34 1 aabb22
15 34 1 aabb22
0 35 1 442222
8 35 1 aabb22
15 35 1 aabb22
0 36 1 442222
8 36 1 aabb22
15 36 1 aabb22
0 37 1 442222
8 37 1 aabb22
15 37 1 aabb22
0 38 1 442222
8 38 1 aabb22
15 38 1 aabb22
0 39 1 442222
8 39 1 aabb22
15 39 1 aabb22
0 40 1 442222
8 40 1 aabb22
15 40 1 aabb22
0 41 1 442222
8 41 1 aabb22
15 41 1 aabb22
0 42 1 442222
8 42 1 aabb22
15 42 1 aabb22
0 43 1 442222
8 43 1 aabb22
15 43 1 aabb22
0 44 1 442222
8 44 1 aabb22
15 44 1 aabb22
0 45 1 442222
8 45 1 aabb22
15 45 1 aabb22
0 46 1 442222
8 46 1 aabb22
15 46 1 aabb22
0 47 1 00bb2f
1 47 1 00bb2f
2 47 1 00bb2f
3 47 1 00bb2f
4 47 1 00bb2f
5 47 1 00bb2f
6 47 1 00bb2f
7 47 1 00bb2f
8 47 1 00bb2f
9 47 1 00bb2f
10 47 1 00bb2f
11 47 1 00bb2f
12 47 1 00bb2f
13 47 1 00bb2f
14 47 1 00bb2f
15 47 1 00bb2f
0 32 2 442222
0 33 2 442222
0 34 2 442222
1 34 2 aabb22
2 34 2 aabb22
3 34 2 aabb22
6 34 2 aabb22
7 34 2 aabb22
8 34 2 aabb22
9 34 2 aabb22
10 34 2 aabb22
13 34 2 aabb22
14 34 2 aabb22
15 34 2 aabb22
0 35 2 442222
8 35 2 aabb22
15 35 2 aabb22
0 36 2 442222
8 36 2 aabb22
15 36 2 aabb22
0 37 2 442222
8 37 2 aabb22
15 37 2 aabb22
0 38 2 442222
8 38 2 aabb22
15 38 2 aabb22
0 39 2 442222
8 39 2 aabb22
15 39 2 aabb22
0 40 2 442222
8 40 2 aabb22
15 40 2 aabb22
0 41 2 442222
8 41 2 aabb22
15 41 2 aabb22
0 42 2 442222
8 42 2 aabb22
15 42 2 aabb22
0 43 2 442222
8 43 2 aabb22
15 43 2 aabb22
0 44 2 442222
8 44 2 aabb22
15 44 2 aabb22
0 45 2 442222
8 45 2 aabb22
15 45 2 aabb22
0 46 2 442222
8 46 2 aabb22
15 46 2 aabb22
0 47 2 00bb2f
1 47 2 00bb2f
2 47 2 00bb2f
3 47 2 00bb2f
4 47 2 00bb2f
5 47 2 00bb2f
6 47 2 00bb2f
7 47 2 00bb2f
8 47 2 00bb2f
9 47 2 00bb2f
10 47 2 00bb2f
11 47 2 00bb2f
12 47 2 00bb2f
13 47 2 00bb2f
14 47 2 00bb2f
15 47 2 00bb2f
0 32 3 442222
0 33 3 442222
0 34 3 442222
1 34 3 aabb22
2 34 3 aabb22
3 34 3 aabb22
6 34 3 aabb22
7 34 3 aabb22
8 34 3 aabb22
9 34 3 aabb22
10 34 3 aabb22
13 34 3 aabb22
14 34 3 aabb22
15 34 3 aabb22
0 35 3 442222
8 35 3 aabb22
15 35 3 aabb22
0 36 3 442222
8 36 3 aabb22
15 36 3 aabb22
0 37 3 442222
8 37 3 aabb22
15 37 3 aabb22
0 38 3 442222
8 38 3 aabb22
15 38 3 aabb22
0 39 3 442222
8 39 3 aabb22
15 39 3 aabb22
0 40 3 442222
8 40 3 aabb22
15 40 3 aabb22
0 41 3 442222
8 41 3 aabb22
15 41 3 aabb22
0 42 3 442222
8 42 3 aabb22
15 42 3 aabb22
0 43 3 442222
8 43 3 aabb22
15 43 3 aabb22
0 44 3 442222
8 44 3 aabb22
15 44 3 aabb22
0 45 3 442222
8 45 3 aabb22
15 45 3 aabb22
0 46 3 442222
8 46 3 aabb22
15 46 3 aabb22
0 47 3 00bb2f
1 47 3 00bb2f
2 47 3 00bb2f
3 47 3 00bb2f
6 47 3 00bb2f
7 47 3 00bb2f
8 47 3 00bb2f
9 47 3 00bb2f
10 47 3 00bb2f
13 47 3 00bb2f
14 47 3 00bb2f
15 47 3 00bb2f
0 32 4 442222
0 33 4 442222
0 34 4 442222
1 34 4 aabb22
2 34 4 aabb22
3 34 4 aabb22
6 34 4 aabb22
7 34 4 aabb22
8 34 4 aabb22
9 34 4 aabb22
10 34 4 aabb22
13 34 4 aabb22
14 34 4 aabb22
15 34 4 aabb22
0 35 4 442222
8 35 4 aabb22
15 35 4 aabb22
0 36 4 442222
8 36 4 aabb22
15 36 4 aabb22
0 37 4 442222
8 37 4 aabb22
15 37 4 aabb22
0 38 4 442222
8 38 4 aabb22
15 38 4 aabb22
0 39 4 442222
8 39 4 aabb22
15 39 4 aabb22
0 40 4 442222
8 40 4 aabb22
15 40 4 aabb22
0 41 4 442222
8 41 4 aabb22
15 41 4 aabb22
0 42 4 442222
8 42 4 aabb22
15 42 4 aabb22
0 43 4 442222
8 43 4 aabb22
15 43 4 aabb22
0 44 4 442222
8 44 4 aabb22
15 44 4 aabb22
0 45 4 442222
8 45 4 aabb22
15 45 4 aabb22
0 46 4 442222
8 46 4 aabb22
15 46 4 aabb22
0 47 4 00bb2f
1 47 4 00bb2f
2 47 4 00bb2f
3 47 4 00bb2f
6 47 4 00bb2f
7 47 4 00bb2f
8 47 4 00bb2f
9 47 4 00bb2f
10 47 4 00bb2f
13 47 4 00bb2f
14 47 4 00bb2f
15 47 4 00bb2f
0 32 5 442222
0 33 5 442222
0 34 5 442222
1 34 5 aabb22
2 34 5 aabb22
3 34 5 aabb22
6 34 5 aabb22
7 34 5 aabb22
8 34 5 aabb22
9 34 5 aabb22
10 34 5 aabb22
13 34 5 aabb22
14 34 5 aabb22
15 34 5 aabb22
0 35 5 442222
8 35 5 aabb22
15 35 5 aabb22
0 36 5 442222
8 36 5 aabb22
15 36 5 aabb22
0 37 5 442222
8 37 5 aabb22
15 37 5 aabb22
0 38 5 442222
8 38 5 aabb22
15 38 5 aabb22
0 39 5 442222
8 39 5 aabb22
15 39 5 aabb22
0 40 5 442222
8 40 5 aabb22
15 40 5 aabb22
0 41 5 442222
8 41 5 aabb22
15 41 5 aabb22
0 42 5 442222
8 42 5 aabb22
15 42 5 aabb22
0 43 5 442222
8 43 5 aabb22
15 43 5 aabb22
0 44 5 442222
8 44 5 aabb22
15 44 5 aabb22
0 45 5 442222
8 45 5 aabb22
15 45 5 aabb22
0 46 5 442222
8 46 5 aabb22
15 46 5 aabb22
0 47 5 00bb2f
1 47 5 00bb2f
2 47 5 00bb2f
3 47 5 00bb2f
6 47 5 00bb2f
7 47 5 00bb2f
8 47 5 00bb2f
9 47 5 00bb2f
10 47 5 00bb2f
13 47 5 00bb2f
14 47 5 00bb2f
15 47 5 00bb2f
0 32 6 442222
0 33 6 442222
0 34 6 442222
1 34 6 aabb22
2 34 6 aabb22
3 34 6 aabb22
6 34 6 aabb22
7 34 6 aabb22
8 34 6 aabb22
9 34 6 aabb22
10 34 6 aabb22
13 34 6 aabb22
14 34 6 aabb22
15 34 6 aabb22
0 35 6 442222
8 35 6 aabb22
15 35 6 aabb22
0 36 6 442222
8 36 6 aabb22
15 36 6 aabb22
0 37 6 442222
8 37 6 aabb22
15 37 6 aabb22
0 38 6 442222
8 38 6 aabb22
15 38 6 aabb22
0 39 6 442222
8 39 6 aabb22
15 39 6 aabb22
0 40 6 442222
8 40 6 aabb22
15 40 6 aabb22
0 41 6 442222
8 41 6 aabb22
15 41 6 aabb22
0 42 6 442222
8 42 6 aabb22
15 42 6 aabb22
0 43 6 442222
8 43 6 aabb22
15 43 6 aabb22
0 44 6 442222
8 44 6 aabb22
15 44 6 aabb22
0 45 6 442222
8 45 6 aabb22
15 45 6 aabb22
0 46 6 442222
8 46 6 aabb22
15 46 6 aabb22
0 47 6 00bb2f
1 47 6 00bb2f
2 47 6 00bb2f
3 47 6 00bb2f
6 47 6 00bb2f
7 47 6 00bb2f
8 47 6 00bb2f
9 47 6 00bb2f
10 47 6 00bb2f
13 47 6 00bb2f
14 47 6 00bb2f
15 47 6 00bb2f
0 32 7 442222
0 33 7 442222
0 34 7 442222
1 34 7 aabb22
2 34 7 aabb22
3 34 7 aabb22
4 34 7 aabb22
5 34 7 aabb22
6 34 7 aabb22
7 34 7 aabb22
8 34 7 aabb22
9 34 7 aabb22
10 34 7 aabb22
11 34 7 aabb22
12 34 7 aabb22
13 34 7 aabb22
14 34 7 aabb22
15 34 7 aabb22
0 35 7 442222
8 35 7 aabb22
15 35 7 aabb22
0 36 7 442222
8 36 7 aabb22
15 36 7 aabb22
0 37 7 442222
8 37 7 aabb22
15 37 7 aabb22
0 38 7 442222
8 38 7 aabb22
15 38 7 aabb22
0 39 7 442222
8 39 7 aabb22
15 39 7 aabb22
0 40 7 442222
8 40 7 aabb22
15 40 7 aabb22
0 41 7 442222
8 41 7 aabb22
15 41 7 aabb22
0 42 7 442222
8 42 7 aabb22
15 42 7 aabb22
0 43 7 442222
8 43 7 aabb22
15 43 7 aabb22
0 44 7 442222
8 44 7 aabb22
15 44 7 aabb22
0 45 7 442222
8 45 7 aabb22
15 45 7 aabb22
0 46 7 442222
8 46 7 aabb22
15 46 7 aabb22
0 47 7 00bb2f
1 47 7 00bb2f
2 47 7 00bb2f
3 47 7 00bb2f
4 47 7 00bb2f
5 47 7 00bb2f
6 47 7 00bb2f
7 47 7 00bb2f
8 47 7 00bb2f
9 47 7 00bb2f
10 47 7 00bb2f
11 47 7 00bb2f
12 47 7 00bb2f
13 47 7 00bb2f
14 47 7 00bb2f
15 47 7 00bb2f
0 32 8 442222
0 33 8 442222
0 34 8 442222
1 34 8 aabb22
2 34 8 aabb22
3 34 8 aabb22
4 34 8 aabb22
5 34 8 aabb22
6 34 8 aabb22
7 34 8 aabb22
8 34 8 aabb22
9 34 8 aabb22
10 34 8 aabb22
11 34 8 aabb22
12 34 8 aabb22
13 34 8 aabb22
14 34 8 aabb22
15 34 8 aabb22
0 35 8 442222
8 35 8 aabb22
15 35 8 aabb22
0 36 8 442222
8 36 8 aabb22
15 36 8 aabb22
0 37 8 442222
8 37 8 aabb22
15 37 8 aabb22
0 38 8 442222
8 38 8 aabb22
15 38 8 aabb22
0 39 8 442222
8 39 8 aabb22
15 39 8 aabb22
0 40 8 442222
8 40 8 aabb22
15 40 8 aabb22
0 41 8 442222
8 41 8 aabb22
15 41 8 aabb22
0 42 8 442222
8 42 8 aabb22
15 42 8 aabb22
0 43 8 442222
8 43 8 aabb22
15 43 8 aabb22
0 44 8 442222
8 44 8 aabb22
15 44 8 aabb22
0 45 8 442222
8 45 8 aabb22
15 45 8 aabb22
0 46 8 442222
8 46 8 aabb22
15 46 8 aabb22
0 47 8 00bb2f
1 47 8 00bb2f
2 47 8 00bb2f
3 47 8 00bb2f
4 47 8 00bb2f
5 47 8 00bb2f
6 47 8 00bb2f
7 47 8 00bb2f
8 47 8 00bb2f
9 47 8 00bb2f
10 47 8 00bb2f
11 47 8 00bb2f
12 47 8 00bb2f
13 47 8 00bb2f
14 47 8 00bb2f
15 47 8 00bb2f
0 32 9 442222
0 33 9 442222
0 34 9 442222
1 34 9 aabb22
2 34 9 aabb22
3 34 9 aabb22
4 34 9 aabb22
5 34 9 aabb22
6 34 9 aabb22
7 34 9 aabb22
8 34 9 aabb22
9 34 9 aabb22
10 34 9 aabb22
11 34 9 aabb22
12 34 9 aabb22
13 34 9 aabb22
14 34 9 aabb22
15 34 9 aabb22
0 35 9 442222
8 35 9 aabb22
15 35 9 aabb22
0 36 9 442222
8 36 9 aabb22
15 36 9 aabb22
0 37 9 442222
8 37 9 aabb22
15 37 9 aabb22
0 38 9 442222
8 38 9 aabb22
15 38 9 aabb22
0 39 9 442222
8 39 9 aabb22
15 39 9 aabb22
0 40 9 442222
8 40 9 aabb22
15 40 9 aabb22
0 41 9 442222
8 41 9 aabb22
15 41 9 aabb22
0 42 9 442222
8 42 9 aabb22
15 42 9 aabb22
0 43 9 442222
8 43 9 aabb22
15 43 9 aabb22
0 44 9 442222
8 44 9 aabb22
15 44 9 aabb22
0 45 9 442222
8 45 9 aabb22
15 45 9 aabb22
0 46 9 442222
8 46 9 aabb22
15 46 9 aabb22
0 47 9 00bb2f
1 47 9 00bb2f
2 47 9 00bb2f
3 47 9 00bb2f
4 47 9 00bb2f
5 47 9 00bb2f
6 47 9 00bb2f
7 47 9 00bb2f
8 47 9 00bb2f
9 47 9 00bb2f
10 47 9 00bb2f
11 47 9 00bb2f
12 47 9 00bb2f
13 47 9 00bb2f
14 47 9 00bb2f
15 47 9 00bb2f
20 16 0 446622
20 17 0 446622
20 18 0 446622
16 19 0 11bb22
17 19 0 11bb22
18 19 0 11bb22
19 19 0 11bb22
20 19 0 11bb22
21 19 0 11bb22
26 19 0 11bb22
27 19 0 11bb22
28 19 0 11bb22
29 19 0 11bb22
30 19 0 11bb22
31 19 0 11bb22
18 28 0 aabb22
19 28 0 aabb22
20 28 0 aabb22
21 28 0 aabb22
22 28 0 aabb22
23 28 0 aabb22
23 29 0 aabb22
23 30 0 aabb22
23 31 0 aabb22
20 16 1 446622
20 17 1 446622
20 18 1 446622
16 19 1 11bb22
17 19 1 11bb22
18 19 1 11bb22
19 19 1 11bb22
20 19 1 11bb22
21 19 1 11bb22
26 19 1 11bb22
27 19 1 11bb22
28 19 1 11bb22
29 19 1 11bb22
30 19 1 11bb22
31 19 1 11bb22
18 28 1 aabb22
19 28 1 aabb22
20 28 1 aabb22
21 28 1 aabb22
22 28 1 aabb22
23 28 1 aabb22
23 29 1 aabb22
23 30 1 aabb22
23 31 1 aabb22
20 16 2 446622
20 17 2 446622
20 18 2 446622
16 19 2 11bb22
17 19 2 11bb22
18 19 2 11bb22
19 19 2 11bb22
20 19 2 11bb22
21 19 2 11bb22
26 19 2 11bb22
27 19 2 11bb22
28 19 2 11bb22
29 19 2 11bb22
30 19 2 11bb22
31 19 2 11bb22
18 28 2 aabb22
19 28 2 aabb22
20 28 2 aabb22
21 28 2 aabb22
22 28 2 aabb22
23 28 2 aabb22
23 29 2 aabb22
23 30 2 aabb22
23 31 2 aabb22
20 16 3 446622
20 17 3 446622
20 18 3 446622
16 19 3 11bb22
17 19 3 11bb22
18 19 3 11bb22
19 19 3 11bb22
20 19 3 11bb22
21 19 3 11bb22
26 19 3 11bb22
27 19 3 11bb22
28 19 3 11bb22
29 19 3 11bb22
30 19 3 11bb22
31 19 3 11bb22
18 28 3 aabb22
19 28 3 aabb22
20 28 3 aabb22
21 28 3 aabb22
22 28 3 aabb22
23 28 3 aabb22
23 29 3 aabb22
23 30 3 aabb22
23 31 3 aabb22
20 16 4 446622
20 17 4 446622
20 18 4 446622
16 19 4 11bb22
17 19 4 11bb22
18 19 4 11bb22
19 19 4 11bb22
20 19 4 11bb22
21 19 4 11bb22
26 19 4 11bb22
27 19 4 11bb22
28 19 4 11bb22
29 19 4 11bb22
30 19 4 11bb22
31 19 4 11bb22
18 28 4 aabb22
19 28 4 aabb22
20 28 4 aabb22
21 28 4 aabb22
22 28 4 aabb22
23 28 4 aabb22
23 29 4 aabb22
23 30 4 aabb22
23 31 4 aabb22
20 16 5 446622
20 17 5 446622
20 18 5 446622
16 19 5 11bb22
17 19 5 11bb22
18 19 5 11bb22
19 19 5 11bb22
20 19 5 11bb22
21 19 5 11bb22
26 19 5 11bb22
27 19 5 11bb22
28 19 5 11bb22
29 19 5 11bb22
30 19 5 11bb22
31 19 5 11bb22
18 28 5 aabb22
19 28 5 aabb22
20 28 5 aabb22
21 28 5 aabb22
22 28 5 aabb22
23 28 5 aabb22
23 29 5 aabb22
23 30 5 aabb22
23 31 5 aabb22
20 16 6 446622
20 17 6 446622
20 18 6 446622
16 19 6 11bb22
17 19 6 11bb22
18 19 6 11bb22
19 19 6 11bb22
20 19 6 11bb22
21 19 6 11bb22
26 19 6 11bb22
27 19 6 11bb22
28 19 6 11bb22
29 19 6 11bb22
30 19 6 11bb22
31 19 6 11bb22
18 28 6 aabb22
19 28 6 aabb22
20 28 6 aabb22
21 28 6 aabb22
22 28 6 aabb22
23 28 6 aabb22
23 29 6 aabb22
23 30 6 aabb22
23 31 6 aabb22
20 16 7 446622
20 17 7 446622
20 18 7 446622
16 19 7 11bb22
17 19 7 11bb22
18 19 7 11bb22
19 19 7 11bb22
20 19 7 11bb22
21 19 7 11bb22
22 19 7 11bb22
23 19 7 11bb22
24 19 7 11bb22
25 19 7 11bb22
26 19 7 11bb22
27 19 7 11bb22
28 19 7 11bb22
29 19 7 11bb22
30 19 7 11bb22
31 19 7 11bb22
16 28 7 aabb22
17 28 7 aabb22
18 28 7 aabb22
19 28 7 aabb22
20 28 7 aabb22
21 28 7 aabb22
22 28 7 aabb22
23 28 7 aabb22
23 29 7 aabb22
23 30 7 aabb22
23 31 7 aabb22
20 16 8 446622
20 17 8 446622
20 18 8 446622
16 19 8 11bb22
17 19 8 11bb22
18 19 8 11bb22
19 19 8 11bb22
20 19 8 11bb22
21 19 8 11bb22
22 19 8 11bb22
23 19 8 11bb22
24 19 8 11bb22
25 19 8 11bb22
26 19 8 11bb22
27 19 8 11bb22
28 19 8 11bb22
29 19 8 11bb22
30 19 8 11bb22
31 19 8 11bb22
16 28 8 aabb22
17 28 8 aabb22
18 28 8 aabb22
19 28 8 aabb22
20 28 8 aabb22
21 28 8 aabb22
22 28 8 aabb22
23 28 8 aabb22
23 29 8 aabb22
23 30 8 aabb22
23 31 8 aabb22
20 16 9 446622
20 17 9 446622
20 18 9 446622
16 19 9 11bb22
17 19 9 11bb22
18 19 9 11bb22
19 19 9 11bb22
20 19 9 11bb22
21 19 9 11bb22
22 19 9 11bb22
23 19 9 11bb22
24 19 9 11bb22
25 19 9 11bb22
26 19 9 11bb22
27 19 9 11bb22
28 19 9 11bb22
29 19 9 11bb22
30 19 9 11bb22
31 19 9 11bb22
16 28 9 aabb22
17 28 9 aabb22
18 28 9 aabb22
19 28 9 aabb22
20 28 9 aabb22
21 28 9 aabb22
22 28 9 aabb22
23 28 9 aabb22
23 29 9 aabb22
23 30 9 aabb22
23 31 9 aabb22
40 16 0 446622
40 17 0 446622
40 18 0 446622
32 19 0 11bb22
33 19 0 11bb22
34 19 0 11bb22
35 19 0 11bb22
36 19 0 11bb22
37 19 0 11bb22
38 19 0 11bb22
39 19 0 11bb22
40 19 0 11bb22
41 19 0 11bb22
42 19 0 11bb22
43 19 0 11bb22
44 19 0 11bb22
45 19 0 11bb22
46 19 0 11bb22
47 19 0 11bb22
40 16 1 446622
40 17 1 446622
40 18 1 446622
32 19 1 11bb22
33 19 1 11bb22
34 19 1 11bb22
35 19 1 11bb22
36 19 1 11bb22
37 19 1 11bb22
38 19 1 11bb22
39 19 1 11bb22
40 19 1 11bb22
41 19 1 11bb22
42 19 1 11bb22
43 19 1 11bb22
44 19 1 11bb22
45 19 1 11bb22
46 19 1 11bb22
47 19 1 11bb22
40 16 2 446622
40 17 2 446622
40 18 2 446622
32 19 2 11bb22
33 19 2 11bb22
34 19 2 11bb22
35 19 2 11bb22
36 19 2 11bb22
37 19 2 11bb22
38 19 2 11bb22
39 19 2 11bb22
40 19 2 11bb22
41 19 2 11bb22
42 19 2 11bb22
43 19 2 11bb22
44 19 2 11bb22
45 19 2 11bb22
46 19 2 11bb22
47 19 2 11bb22
40 16 3 446622
40 17 3 446622
40 18 3 446622
32 19 3 11bb22
33 19 3 11bb22
34 19 3 11bb22
35 19 3 11bb22
36 19 3 11bb22
37 19 3 11bb22
38 19 3 11bb22
39 19 3 11bb22
40 19 3 11bb22
41 19 3 11bb22
42 19 3 11bb22
43 19 3 11bb22
44 19 3 11bb22
45 19 3 11bb22
46 19 3 11bb22
47 19 3 11bb22
40 16 4 446622
40 17 4 446622
40 18 4 446622
32 19 4 11bb22
33 19 4 11bb22
34 19 4 11bb22
35 19 4 11bb22
36 19 4 11bb22
37 19 4 11bb22
38 19 4 11bb22
39 19 4 11bb22
40 19 4 11bb22
41 19 4 11bb22
42 19 4 11bb22
43 19 4 11bb22
44 19 4 11bb22
45 19 4 11bb22
46 19 4 11bb22
47 19 4 11bb22
40 16 5 446622
40 17 5 446622
40 18 5 446622
32 19 5 11bb22
33 19 5 11bb22
34 19 5 11bb22
35 19 5 11bb22
36 19 5 11bb22
37 19 5 11bb22
38 19 5 11bb22
39 19 5 11bb22
40 19 5 11bb22
41 19 5 11bb22
42 19 5 11bb22
43 19 5 11bb22
44 19 5 11bb22
45 19 5 11bb22
46 19 5 11bb22
47 19 5 11bb22
40 16 6 446622
40 17 6 446622
40 18 6 446622
32 19 6 11bb22
33 19 6 11bb22
34 19 6 11bb22
35 19 6 11bb22
36 19 6 11bb22
37 19 6 11bb22
38 19 6 11bb22
39 19 6 11bb22
40 19 6 11bb22
41 19 6 11bb22
42 19 6 11bb22
43 19 6 11bb22
44 19 6 11bb22
45 19 6 11bb22
46 19 6 11bb22
47 19 6 11bb22
40 16 7 446622
40 17 7 446622
40 18 7 446622
32 19 7 11bb22
33 19 7 11bb22
34 19 7 11bb22
35 19 7 11bb22
36 19 7 11bb22
37 19 7 11bb22
38 19 7 11bb22
39 19 7 11bb22
40 19 7 11bb22
41 19 7 11bb22
42 19 7 11bb22
43 19 7 11bb22
44 19 7 11bb22
45 19 7 11bb22
46 19 7 11bb22
47 19 7 11bb22
40 16 8 446622
40 17 8 446622
40 18 8 446622
32 19 8 11bb22
33 19 8 11bb22
34 19 8 11bb22
35 19 8 11bb22
36 19 8 11bb22
37 19 8 11bb22
38 19 8 11bb22
39 19 8 11bb22
40 19 8 11bb22
41 19 8 11bb22
42 19 8 11bb22
43 19 8 11bb22
44 19 8 11bb22
45 19 8 11bb22
46 19 8 11bb22
47 19 8 11bb22
40 16 9 446622
40 17 9 446622
40 18 9 446622
32 19 9 11bb22
33 19 9 11bb22
34 19 9 11bb22
35 19 9 11bb22
36 19 9 11bb22
37 19 9 11bb22
38 19 9 11bb22
39 19 9 11bb22
40 19 9 11bb22
41 19 9 11bb22
42 19 9 11bb22
43 19 9 11bb22
44 19 9 11bb22
45 19 9 11bb22
46 19 9 11bb22
47 19 9 11bb22
60 16 0 446622
60 17 0 446622
60 18 0 446622
48 19 0 11bb22
49 19 0 11bb22
50 19 0 11bb22
51 19 0 11bb22
52 19 0 11bb22
53 19 0 11bb22
54 19 0 11bb22
59 19 0 11bb22
60 19 0 11bb22
61 19 0 11bb22
62 19 0 11bb22
63 19 0 11bb22
56 28 0 aabb22
57 28 0 aabb22
58 28 0 aabb22
59 28 0 aabb22
60 28 0 aabb22
61 28 0 aabb22
62 28 0 aabb22
63 28 0 aabb22
56 29 0 aabb22
56 30 0 aabb22
56 31 0 aabb22
60 16 1 446622
60 17 1 446622
60 18 1 446622
48 19 1 11bb22
49 19 1 11bb22
50 19 1 11bb22
51 19 1 11bb22
52 19 1 11bb22
53 19 1 11bb22
54 19 1 11bb22
59 19 1 11bb22
60 19 1 11bb22
61 19 1 11bb22
62 19 1 11bb22
63 19 1 11bb22
56 28 1 aabb22
57 28 1 aabb22
58 28 1 aabb22
59 28 1 aabb22
60 28 1 aabb22
61 28 1 aabb22
62 28 1 aabb22
63 28 1 aabb22
56 29 1 aabb22
56 30 1 aabb22
56 31 1 aabb22
60 16 2 446622
60 17 2 446622
60 18 2 446622
48 19 2 11bb22
49 19 2 11bb22
50 19 2 11bb22
51 19 2 11bb22
52 19 2 11bb22
53 19 2 11bb22
54 19 2 11bb22
59 19 2 11bb22
60 19 2 11bb22
61 19 2 11bb22
62 19 2 11bb22
63 19 2 11bb22
56 28 2 aabb22
57 28 2 aabb22
58 28 2 aabb22
59 28 2 aabb22
60 28 2 aabb22
61 28 2 aabb22
62 28 2 aabb22
63 28 2 aabb22
56 29 2 aabb22
56 30 2 aabb22
56 31 2 aabb22
60 16 3 446622
60 17 3 446622
60 18 3 446622
48 19 3 11bb22
49 19 3 11bb22
50 19 3 11bb22
51 19 3 11bb22
52 19 3 11bb22
53 19 3 11bb22
54 19 3 11bb22
59 19 3 11bb22
60 19 3 11bb22
61 19 3 11bb22
62 19 3 11bb22
63 19 3 11bb22
56 28 3 aabb22
57 28 3 aabb22
58 28 3 aabb22
59 28 3 aabb22
60 28 3 aabb22
61 28 3 aabb22
62 28 3 aabb22
63 28 3 aabb22
56 29 3 aabb22
56 30 3 aabb22
56 31 3 aabb22
60 16 4 446622
60 17 4 446622
60 18 4 446622
48 19 4 11bb22
49 19 4 11bb22
50 19 4 11bb22
51 19 4 11bb22
52 19 4 11bb22
53 19 4 11bb22
54 19 4 11bb22
59 19 4 11bb22
60 19 4 11bb22
61 19 4 11bb22
62 19 4 11bb22
63 19 4 11bb22
56 28 4 aabb22
57 28 4 aabb22
58 28 4 aabb22
59 28 4 aabb22
60 28 4 aabb22
61 28 4 aabb22
62 28 4 aabb22
63 28 4 aabb22
56 29 4 aabb22
56 30 4 aabb22
56 31 4 aabb22
60 16 5 446622
60 17 5 446622
60 18 5 446622
48 19 5 11bb22
49 19 5 11bb22
50 19 5 11bb22
51 19 5 11bb22
52 19 5 11bb22
53 19 5 11bb22
54 19 5 11bb22
59 19 5 11bb22
60 19 5 11bb22
61 19 5 11bb22
62 19 5 11bb22
63 19 5 11bb22
56 28 5 aabb22
57 28 5 aabb22
58 28 5 aabb22
59 28 5 aabb22
60 28 5 aabb22
61 28 5 aabb22
62 28 5 aabb22
63 28 5 aabb22
56 29 5 aabb22
56 30 5 aabb22
56 31 5 aabb22
60 16 6 446622
60 17 6 446622
60 18 6 446622
48 19 6 11bb22
49 19 6 11bb22
50 19 6 11bb22
51 19 6 11bb22
52 19 6 11bb22
53 19 6 11bb22
54 19 6 11bb22
59 19 6 11bb22
60 19 6 11bb22
61 19 6 11bb22
62 19 6 11bb22
63 19 6 11bb22
56 28 6 aabb22
57 28 6 aabb22
58 28 6 aabb22
59 28 6 aabb22
60 28 6 aabb22
61 28 6 aabb22
62 28 6 aabb22
63 28 6 aabb22
56 29 6 aabb22
56 30 6 aabb22
56 31 6 aabb22
60 16 7 446622
60 17 7 446622
60 18 7 446622
48 19 7 11bb22
49 19 7 11bb22
50 19 7 11bb22
51 19 7 11bb22
52 19 7 11bb22
53 19 7 11bb22
54 19 7 11bb22
55 19 7 11bb22
56 19 7 11bb22
57 19 7 11bb22
58 19 7 11bb22
59 19 7 11bb22
60 19 7 11bb22
61 19 7 11bb22
62 19 7 11bb22
63 19 7 11bb22
56 28 7 aabb22
57 28 7 aabb22
58 28 7 aabb22
59 28 7 aabb22
60 28 7 aabb22
61 28 7 aabb22
62 28 7 aabb22
63 28 7 aabb22
56 29 7 aabb22
56 30 7 aabb22
56 31 7 aabb22
60 16 8 446622
60 17 8 446622
60 18 8 446622
48 19 8 11bb22
49 19 8 11bb22
50 19 8 11bb22
51 19 8 11bb22
52 19 8 11bb22
53 19 8 11bb22
54 19 8 11bb22
55 19 8 11bb22
56 19 8 11bb22
57 19 8 11bb22
58 19 8 11bb22
59 19 8 11bb22
60 19 8 11bb22
61 19 8 11bb22
62 19 8 11bb22
63 19 8 11bb22
56 28 8 aabb22
57 28 8 aabb22
58 28 8 aabb22
59 28 8 aabb22
60 28 8 aabb22
61 28 8 aabb22
62 28 8 aabb22
63 28 8 aabb22
56 29 8 aabb22
56 30 8 aabb22
56 31 8 aabb22
60 16 9 446622
60 17 9 446622
60 18 9 446622
48 19 9 11bb22
49 19 9 11bb22
50 19 9 11bb22
51 19 9 11bb22
52 19 9 11bb22
53 19 9 11bb22
54 19 9 11bb22
55 19 9 11bb22
56 19 9 11bb22
57 19 9 11bb22
58 19 9 11bb22
59 19 9 11bb22
60 19 9 11bb22
61 19 9 11bb22
62 19 9 11bb22
63 19 9 11bb22
56 28 9 aabb22
57 28 9 aabb22
58 28 9 aabb22
59 28 9 aabb22
60 28 9 aabb22
61 28 9 aabb22
62 28 9 aabb22
63 28 9 aabb22
56 29 9 aabb22
56 30 9 aabb22
56 31 9 aabb22
79 16 0 116622
79 17 0 116622
79 18 0 116622
64 19 0 11bb22
65 19 0 11bb22
66 19 0 11bb22
67 19 0 11bb22
68 19 0 11bb22
69 19 0 11bb22
70 19 0 11bb22
71 19 0 11bb22
72 19 0 11bb22
73 19 0 11bb22
78 19 0 11bb22
79 19 0 116622
79 20 0 116622
79 21 0 116622
79 22 0 116622
79 23 0 116622
79 24 0 116622
79 25 0 116622
79 26 0 116622
79 27 0 116622
64 28 0 aabb22
65 28 0 aabb22
66 28 0 aabb22
67 28 0 aabb22
68 28 0 aabb22
69 28 0 aabb22
70 28 0 aabb22
74 28 0 aabb22
75 28 0 aabb22
76 28 0 aabb22
77 28 0 aabb22
78 28 0 aabb22
79 28 0 116622
79 29 0 116622
79 30 0 116622
79 31 0 116622
79 16 1 116622
79 17 1 116622
79 18 1 116622
64 19 1 11bb22
65 19 1 11bb22
66 19 1 11bb22
67 19 1 11bb22
68 19 1 11bb22
69 19 1 11bb22
70 19 1 11bb22
71 19 1 11bb22
72 19 1 11bb22
73 19 1 11bb22
78 19 1 11bb22
79 19 1 116622
79 20 1 116622
79 21 1 116622
79 22 1 116622
79 23 1 116622
79 24 1 116622
79 25 1 116622
79 26 1 116622
79 27 1 116622
64 28 1 aabb22
65 28 1 aabb22
66 28 1 aabb22
67 28 1 aabb22
68 28 1 aabb22
69 28 1 aabb22
70 28 1 aabb22
74 28 1 aabb22
75 28 1 aabb22
76 28 1 aabb22
77 28 1 aabb22
78 28 1 aabb22
79 28 1 116622
79 29 1 116622
79 30 1 116622
79 31 1 116622
79 16 2 116622
79 17 2 116622
79 18 2 116622
64 19 2 11bb22
65 19 2 11bb22
66 19 2 11bb22
67 19 2 11bb22
68 19 2 11bb22
69 19 2 11bb22
70 19 2 11bb22
71 19 2 11bb22
72 19 2 11bb22
73 19 2 11bb22
78 19 2 11bb22
79 19 2 116622
79 20 2 116622
79 21 2 116622
79 22 2 116622
79 23 2 116622
79 24 2 116622
79 25 2 116622
79 26 2 116622
79 27 2 116622
64 28 2 aabb22
65 28 2 aabb22
66 28 2 aabb22
67 28 2 aabb22
68 28 2 aabb22
69 28 2 aabb22
70 28 2 aabb22
74 28 2 aabb22
75 28 2 aabb22
76 28 2 aabb22
77 28 2 aabb22
78 28 2 aabb22
79 28 2 116622
79 29 2 116622
79 30 2 116622
79 31 2 116622
79 16 3 116622
79 17 3 116622
79 18 3 116622
64 19 3 11bb22
65 19 3 11bb22
66 19 3 11bb22
67 19 3 11bb22
68 19 3 11bb22
69 19 3 11bb22
70 19 3 11bb22
71 19 3 11bb22
72 19 3 11bb22
73 19 3 11bb22
78 19 3 11bb22
79 19 3 116622
79 20 3 116622
79 21 3 116622
79 22 3 116622
79 23 3 116622
79 24 3 116622
79 25 3 116622
79 26 3 116622
79 27 3 116622
64 28 3 aabb22
65 28 3 aabb22
66 28 3 aabb22
67 28 3 aabb22
68 28 3 aabb22
69 28 3 aabb22
70 28 3 aabb22
74 28 3 aabb22
75 28 3 aabb22
76 28 3 aabb22
77 28 3 aabb22
78 28 3 aabb22
79 28 3 116622
79 29 3 116622
79 30 3 116622
79 31 3 116622
79 16 4 116622
79 17 4 116622
79 18 4 116622
64 19 4 11bb22
65 19 4 11bb22
66 19 4 11bb22
67 19 4 11bb22
68 19 4 11bb22
69 19 4 11bb22
70 19 4 11bb22
71 19 4 11bb22
72 19 4 11bb22
73 19 4 11bb22
78 19 4 11bb22
79 19 4 116622
79 20 4 116622
79 21 4 116622
79 22 4 116622
79 23 4 116622
79 24 4 116622
79 25 4 116622
79 26 4 116622
79 27 4 116622
64 28 4 aabb22
65 28 4 aabb22
66 28 4 aabb22
67 28 4 aabb22
68 28 4 aabb22
69 28 4 aabb22
70 28 4 aabb22
74 28 4 aabb22
75 28 4 aabb22
76 28 4 aabb22
77 28 4 aabb22
78 28 4 aabb22
79 28 4 116622
79 29 4 116622
79 30 4 116622
79 31 4 116622
79 16 5 116622
79 17 5 116622
79 18 5 116622
64 19 5 11bb22
65 19 5 11bb22
66 19 5 11bb22
67 19 5 11bb22
68 19 5 11bb22
69 19 5 11bb22
70 19 5 11bb22
71 19 5 11bb22
72 19 5 11bb22
73 19 5 11bb22
78 19 5 11bb22
79 19 5 116622
79 20 5 116622
79 21 5 116622
79 22 5 116622
79 23 5 116622
79 24 5 116622
79 25 5 116622
79 26 5 116622
79 27 5 116622
64 28 5 aabb22
65 28 5 aabb22
66 28 5 aabb22
67 28 5 aabb22
68 28 5 aabb22
69 28 5 aabb22
70 28 5 aabb22
74 28 5 aabb22
75 28 5 aabb22
76 28 5 aabb22
77 28 5 aabb22
78 28 5 aabb22
79 28 5 116622
79 29 5 116622
79 30 5 116622
79 31 5 116622
79 16 6 116622
79 17 6 116622
79 18 6 116622
64 19 6 11bb22
65 19 6 11bb22
66 19 6 11bb22
67 19 6 11bb22
68 19 6 11bb22
69 19 6 11bb22
70 19 6 11bb22
71 19 6 11bb22
72 19 6 11bb22
73 19 6 11bb22
78 19 6 11bb22
79 19 6 116622
79 20 6 116622
79 21 6 116622
79 22 6 116622
79 23 6 116622
79 24 6 116622
79 25 6 116622
79 26 6 116622
79 27 6 116622
64 28 6 aabb22
65 28 6 aabb22
66 28 6 aabb22
67 28 6 aabb22
68 28 6 aabb22
69 28 6 aabb22
70 28 6 aabb22
74 28 6 aabb22
75 28 6 aabb22
76 28 6 aabb22
77 28 6 aabb22
78 28 6 aabb22
79 28 6 116622
79 29 6 116622
79 30 6 116622
79 31 6 116622
79 16 7 116622
79 17 7 116622
79 18 7 116622
64 19 7 11bb22
65 19 7 11bb22
66 19 7 11bb22
67 19 7 11bb22
68 19 7 11bb22
69 19 7 11bb22
70 19 7 11bb22
71 19 7 11bb22
72 19 7 11bb22
73 19 7 11bb22
74 19 7 11bb22
75 19 7 11bb22
76 19 7 11bb22
77 19 7 11bb22
78 19 7 11bb22
79 19 7 116622
79 20 7 116622
79 21 7 116622
79 22 7 116622
79 23 7 116622
79 24 7 116622
79 25 7 116622
79 26 7 116622
79 27 7 116622
64 28 7 aabb22
65 28 7 aabb22
66 28 7 aabb22
67 28 7 aabb22
68 28 7 aabb22
69 28 7 aabb22
70 28 7 aabb22
71 28 7 aabb22
72 28 7 aabb22
73 28 7 aabb22
74 28 7 aabb22
75 28 7 aabb22
76 28 7 aabb22
77 28 7 aabb22
78 28 7 aabb22
79 28 7 116622
79 29 7 116622
79 30 7 116622
79 31 7 116622
79 16 8 116622
79 17 8 116622
79 18 8 116622
64 19 8 11bb22
65 19 8 11bb22
66 19 8 11bb22
67 19 8 11bb22
68 19 8 11bb22
69 19 8 11bb22
70 19 8 11bb22
71 19 8 11bb22
72 19 8 11bb22
73 19 8 11bb22
74 19 8 11bb22
75 19 8 11bb22
76 19 8 11bb22
77 19 8 11bb22
78 19 8 11bb22
79 19 8 116622
79 20 8 116622
79 21 8 116622
79 22 8 116622
79 23 8 116622
79 24 8 116622
79 25 8 116622
79 26 8 116622
79 27 8 116622
64 28 8 aabb22
65 28 8 aabb22
66 28 8 aabb22
67 28 8 aabb22
68 28 8 aabb22
69 28 8 aabb22
70 28 8 aabb22
71 28 8 aabb22
72 28 8 aabb22
73 28 8 aabb22
74 28 8 aabb22
75 28 8 aabb22
76 28 8 aabb22
77 28 8 aabb22
78 28 8 aabb22
79 28 8 116622
79 29 8 116622
79 30 8 116622
79 31 8 116622
79 16 9 116622
79 17 9 116622
79 18 9 116622
64 19 9 11bb22
65 19 9 11bb22
66 19 9 11bb22
67 19 9 11bb22
68 19 9 11bb22
69 19 9 11bb22
70 19 9 11bb22
71 19 9 11bb22
72 19 9 11bb22
73 19 9 11bb22
74 19 9 11bb22
75 19 9 11bb22
76 19 9 11bb22
77 19 9 11bb22
78 19 9 11bb22
79 19 9 116622
79 20 9 116622
79 21 9 116622
79 22 9 116622
79 23 9 116622
79 24 9 116622
79 25 9 116622
79 26 9 116622
79 27 9 116622
64 28 9 aabb22
65 28 9 aabb22
66 28 9 aabb22
67 28 9 aabb22
68 28 9 aabb22
69 28 9 aabb22
70 28 9 aabb22
71 28 9 aabb22
72 28 9 aabb22
73 28 9 aabb22
74 28 9 aabb22
75 28 9 aabb22
76 28 9 aabb22
77 28 9 aabb22
78 28 9 aabb22
79 28 9 116622
79 29 9 116622
79 30 9 116622
79 31 9 116622
79 32 0 116622
79 33 0 116622
64 34 0 aabb22
65 34 0 aabb22
66 34 0 aabb22
67 34 0 aabb22
68 34 0 aabb22
69 34 0 aabb22
74 34 0 aabb22
75 34 0 aabb22
76 34 0 aabb22
77 34 0 aabb22
78 34 0 aabb22
79 34 0 116622
64 35 0 aabb2f
79 35 0 116622
64 36 0 aabb2f
79 36 0 116622
64 37 0 aabb2f
79 37 0 116622
64 38 0 aabb2f
79 38 0 116622
64 39 0 aabb2f
79 39 0 116622
64 40 0 aabb2f
79 40 0 116622
64 41 0 aabb2f
79 41 0 116622
64 42 0 aabb2f
79 42 0 116622
64 43 0 aabb2f
79 43 0 116622
64 44 0 aabb2f
79 44 0 116622
64 45 0 aabb2f
79 45 0 116622
64 46 0 aabb2f
79 46 0 116622
64 47 0 00bb2f
65 47 0 00bb2f
66 47 0 00bb2f
67 47 0 00bb2f
68 47 0 00bb2f
69 47 0 00bb2f
70 47 0 00bb2f
71 47 0 00bb2f
72 47 0 00bb2f
73 47 0 00bb2f
74 47 0 00bb2f
75 47 0 00bb2f
76 47 0 00bb2f
77 47 0 00bb2f
78 47 0 00bb2f
79 47 0 00bb2f
79 32 1 116622
79 33 1 116622
64 34 1 aabb22
65 34 1 aabb22
66 34 1 aabb22
67 34 1 aabb22
68 34 1 aabb22
69 34 1 aabb22
74 34 1 aabb22
75 34 1 aabb22
76 34 1 aabb22
77 34 1 aabb22
78 34 1 aabb22
79 34 1 116622
64 35 1 aabb2f
79 35 1 116622
64 36 1 aabb2f
79 36 1 116622
64 37 1 aabb2f
79 37 1 116622
64 38 1 aabb2f
79 38 1 116622
64 39 1 aabb2f
79 39 1 116622
64 40 1 aabb2f
79 40 1 116622
64 41 1 aabb2f
79 41 1 116622
64 42 1 aabb2f
79 42 1 116622
64 43 1 aabb2f
79 43 1 116622
64 44 1 aabb2f
79 44 1 116622
64 45 1 aabb2f
79 45 1 116622
64 46 1 aabb2f
79 46 1 116622
64 47 1 00bb2f
65 47 1 00bb2f
66 47 1 00bb2f
67 47 1 00bb2f
68 47 1 00bb2f
69 47 1 00bb2f
70 47 1 00bb2f
71 47 1 00bb2f
72 47 1 00bb2f
73 47 1 00bb2f
74 47 1 00bb2f
75 47 1 00bb2f
76 47 1 00bb2f
77 47 1 00bb2f
78 47 1 00bb2f
79 47 1 00bb2f
79 32 2 116622
79 33 2 116622
64 34 2 aabb22
65 34 2 aabb22
66 34 2 aabb22
67 34 2 aabb22
68 34 2 aabb22
69 34 2 aabb22
74 34 2 aabb22
75 34 2 aabb22
76 34 2 aabb22
77 34 2 aabb22
78 34 2 aabb22
79 34 2 116622
64 35 2 aabb2f
79 35 2 116622
64 36 2 aabb2f
79 36 2 116622
64 37 2 aabb2f
79 37 2 116622
64 38 2 aabb2f
79 38 2 116622
64 39 2 aabb2f
79 39 2 116622
64 40 2 aabb2f
79 40 2 116622
64 41 2 aabb2f
79 41 2 116622
64 42 2 aabb2f
79 42 2 116622
64 43 2 aabb2f
79 43 2 116622
64 44 2 aabb2f
79 44 2 116622
64 45 2 aabb2f
79 45 2 116622
64 46 2 aabb2f
79 46 2 116622
64 47 2 00bb2f
65 47 2 00bb2f
66 47 2 00bb2f
67 47 2 00bb2f
68 47 2 00bb2f
69 47 2 00bb2f
70 47 2 00bb2f
71 47 2 00bb2f
72 47 2 00bb2f
73 47 2 00bb2f
74 47 2 00bb2f
75 47 2 00bb2f
76 47 2 00bb2f
77 47 2 00bb2f
78 47 2 00bb2f
79 47 2 00bb2f
79 32 3 116622
79 33 3 116622
64 34 3 aabb22
65 34 3 aabb22
66 34 3 aabb22
67 34 3 aabb22
68 34 3 aabb22
69 34 3 aabb22
74 34 3 aabb22
75 34 3 aabb22
76 34 3 aabb22
77 34 3 aabb22
78 34 3 aabb22
79 34 3 116622
64 35 3 aabb2f
79 35 3 116622
64 36 3 aabb2f
79 36 3 116622
64 37 3 aabb2f
79 37 3 116622
64 38 3 aabb2f
79 38 3 116622
64 39 3 aabb2f
79 39 3 116622
64 40 3 aabb2f
79 40 3 116622
64 41 3 aabb2f
64 42 3 aabb2f
64 43 3 aabb2f
64 44 3 aabb2f
79 44 3 116622
64 45 3 aabb2f
79 45 3 116622
64 46 3 aabb2f
79 46 3 116622
64 47 3 00bb2f
65 47 3 00bb2f
66 47 3 00bb2f
67 47 3 00bb2f
72 47 3 00bb2f
73 47 3 00bb2f
74 47 3 00bb2f
75 47 3 00bb2f
76 47 3 00bb2f
77 47 3 00bb2f
78 47 3 00bb2f
79 47 3 00bb2f
79 32 4 116622
79 33 4 116622
64 34 4 aabb22
65 34 4 aabb22
66 34 4 aabb22
67 34 4 aabb22
68 34 4 aabb22
69 34 4 aabb22
74 34 4 aabb22
75 34 4 aabb22
76 34 4 aabb22
77 34 4 aabb22
78 34 4 aabb22
79 34 4 116622
64 35 4 aabb2f
79 35 4 116622
64 36 4 aabb2f
79 36 4 116622
64 37 4 aabb2f
79 37 4 116622
64 38 4 aabb2f
79 38 4 116622
64 39 4 aabb2f
79 39 4 116622
64 40 4 aabb2f
79 40 4 116622
64 41 4 aabb2f
64 42 4 aabb2f
64 43 4 aabb2f
64 44 4 aabb2f
79 44 4 116622
64 45 4 aabb2f
79 45 4 116622
64 46 4 aabb2f
79 46 4 116622
64 47 4 00bb2f
65 47 4 00bb2f
66 47 4 00bb2f
67 47 4 00bb2f
72 47 4 00bb2f
73 47 4 00bb2f
74 47 4 00bb2f
75 47 4 00bb2f
76 47 4 00bb2f
77 47 4 00bb2f
78 47 4 00bb2f
79 47 4 00bb2f
79 32 5 116622
79 33 5 116622
64 34 5 aabb22
65 34 5 aabb22
66 34 5 aabb22
67 34 5 aabb22
68 34 5 aabb22
69 34 5 aabb22
74 34 5 aabb22
75 34 5 aabb22
76 34 5 aabb22
77 34 5 aabb22
78 34 5 aabb22
79 34 5 116622
64 35 5 aabb2f
79 35 5 116622
64 36 5 aabb2f
79 36 5 116622
64 37 5 aabb2f
79 37 5 116622
64 38 5 aabb2f
79 38 5 116622
64 39 5 aabb2f
79 39 5 116622
64 40 5 aabb2f
79 40 5 116622
64 41 5 aabb2f
64 42 5 aabb2f
64 43 5 aabb2f
64 44 5 aabb2f
79 44 5 116622
64 45 5 aabb2f
79 45 5 116622
64 46 5 aabb2f
79 46 5 116622
64 47 5 00bb2f
65 47 5 00bb2f
66 47 5 00bb2f
67 47 5 00bb2f
72 47 5 00bb2f
73 47 5 00bb2f
74 47 5 00bb2f
75 47 5 00bb2f
76 47 5 00bb2f
77 47 5 00bb2f
78 47 5 00bb2f
79 47 5 00bb2f
79 32 6 116622
79 33 6 116622
64 34 6 aabb22
65 34 6 aabb22
66 34 6 aabb22
67 34 6 aabb22
68 34 6 aabb22
69 34 6 aabb22
74 34 6 aabb22
75 34 6 aabb22
76 34 6 aabb22
77 34 6 aabb22
78 34 6 aabb22
79 34 6 116622
64 35 6 aabb2f
79 35 6 116622
64 36 6 aabb2f
79 36 6 116622
64 37 6 aabb2f
79 37 6 116622
64 38 6 aabb2f
79 38 6 116622
64 39 6 aabb2f
79 39 6 116622
64 40 6 aabb2f
79 40 6 116622
64 41 6 aabb2f
64 42 6 aabb2f
64 43 6 aabb2f
64 44 6 aabb2f
79 44 6 116622
64 45 6 aabb2f
79 45 6 116622
64 46 6 aabb2f
79 46 6 116622
64 47 6 00bb2f
65 47 6 00bb2f
66 47 6 00bb2f
67 47 6 00bb2f
72 47 6 00bb2f
73 47 6 00bb2f
74 47 6 00bb2f
75 47 6 00bb2f
76 47 6 00bb2f
77 47 6 00bb2f
78 47 6 00bb2f
79 47 6 00bb2f
79 32 7 116622
79 33 7 116622
64 34 7 aabb22
65 34 7 aabb22
66 34 7 aabb22
67 34 7 aabb22
68 34 7 aabb22
69 34 7 aabb22
70 34 7 aabb22
71 34 7 aabb22
72 34 7 aabb22
73 34 7 aabb22
74 34 7 aabb22
75 34 7 aabb22
76 34 7 aabb22
77 34 7 aabb22
78 34 7 aabb22
79 34 7 116622
64 35 7 aabb2f
79 35 7 116622
64 36 7 aabb2f
79 36 7 116622
64 37 7 aabb2f
79 37 7 116622
64 38 7 aabb2f
79 38 7 116622
64 39 7 aabb2f
79 39 7 116622
64 40 7 aabb2f
79 40 7 116622
64 41 7 aabb2f
64 42 7 aabb2f
64 43 7 aabb2f
64 44 7 aabb2f
79 44 7 116622
64 45 7 aabb2f
79 45 7 116622
64 46 7 aabb2f
79 46 7 116622
64 47 7 00bb2f
65 47 7 00bb2f
66 47 7 00bb2f
67 47 7 00bb2f
68 47 7 00bb2f
69 47 7 00bb2f
70 47 7 00bb2f
71 47 7 00bb2f
72 47 7 00bb2f
73 47 7 00bb2f
74 47 7 00bb2f
75 47 7 00bb2f
76 47 7 00bb2f
77 47 7 00bb2f
78 47 7 00bb2f
79 47 7 00bb2f
79 32 8 116622
79 33 8 116622
64 34 8 aabb22
65 34 8 aabb22
66 34 8 aabb22
67 34 8 aabb22
68 34 8 aabb22
69 34 8 aabb22
70 34 8 aabb22
71 34 8 aabb22
72 34 8 aabb22
73 34 8 aabb22
74 34 8 aabb22
75 34 8 aabb22
76 34 8 aabb22
77 34 8 aabb22
78 34 8 aabb22
79 34 8 116622
64 35 8 aabb2f
79 35 8 116622
64 36 8 aabb2f
79 36 8 116622
64 37 8 aabb2f
79 37 8 116622
64 38 8 aabb2f
79 38 8 116622
64 39 8 aabb2f
79 39 8 116622
64 40 8 aabb2f
79 40 8 116622
64 41 8 aabb2f
79 41 8 116622
64 42 8 aabb2f
79 42 8 116622
64 43 8 aabb2f
79 43 8 116622
64 44 8 aabb2f
79 44 8 116622
64 45 8 aabb2f
79 45 8 116622
64 46 8 aabb2f
79 46 8 116622
64 47 8 00bb2f
65 47 8 00bb2f
66 47 8 00bb2f
67 47 8 00bb2f
68 47 8 00bb2f
69 47 8 00bb2f
70 47 8 00bb2f
71 47 8 00bb2f
72 47 8 00bb2f
73 47 8 00bb2f
74 47 8 00bb2f
75 47 8 00bb2f
76 47 8 00bb2f
77 47 8 00bb2f
78 47 8 00bb2f
79 47 8 00bb2f
79 32 9 116622
79 33 9 116622
64 34 9 aabb22
65 34 9 aabb22
66 34 9 aabb22
67 34 9 aabb22
68 34 9 aabb22
69 34 9 aabb22
70 34 9 aabb22
71 34 9 aabb22
72 34 9 aabb22
73 34 9 aabb22
74 34 9 aabb22
75 34 9 aabb22
76 34 9 aabb22
77 34 9 aabb22
78 34 9 aabb22
79 34 9 116622
64 35 9 aabb2f
79 35 9 116622
64 36 9 aabb2f
79 36 9 116622
64 37 9 aabb2f
79 37 9 116622
64 38 9 aabb2f
79 38 9 116622
64 39 9 aabb2f
79 39 9 116622
64 40 9 aabb2f
79 40 9 116622
64 41 9 aabb2f
79 41 9 116622
64 42 9 aabb2f
79 42 9 116622
64 43 9 aabb2f
79 43 9 116622
64 44 9 aabb2f
79 44 9 116622
64 45 9 aabb2f
79 45 9 116622
64 46 9 aabb2f
79 46 9 116622
64 47 9 00bb2f
65 47 9 00bb2f
66 47 9 00bb2f
67 47 9 00bb2f
68 47 9 00bb2f
69 47 9 00bb2f
70 47 9 00bb2f
71 47 9 00bb2f
72 47 9 00bb2f
73 47 9 00bb2f
74 47 9 00bb2f
75 47 9 00bb2f
76 47 9 00bb2f
77 47 9 00bb2f
78 47 9 00bb2f
79 47 9 00bb2f
23 32 0 aabb22
23 33 0 aabb22
16 34 0 aabb22
17 34 0 aabb22
20 34 0 aabb22
21 34 0 aabb22
22 34 0 aabb22
23 34 0 aabb22
23 35 0 aabb22
23 36 0 aabb22
23 37 0 aabb22
23 38 0 aabb22
23 39 0 aabb22
23 40 0 aabb22
23 41 0 aabb22
23 42 0 aabb22
23 43 0 aabb22
23 44 0 aabb22
23 45 0 aabb22
23 46 0 aabb22
16 47 0 00bb2f
17 47 0 00bb2f
18 47 0 00bb2f
19 47 0 00bb2f
20 47 0 00bb2f
21 47 0 00bb2f
22 47 0 00bb2f
23 47 0 00bb2f
24 47 0 00bb2f
25 47 0 00bb2f
26 47 0 00bb2f
27 47 0 00bb2f
28 47 0 00bb2f
29 47 0 00bb2f
30 47 0 00bb2f
31 47 0 00bb2f
23 32 1 aabb22
23 33 1 aabb22
16 34 1 aabb22
17 34 1 aabb22
20 34 1 aabb22
21 34 1 aabb22
22 34 1 aabb22
23 34 1 aabb22
23 35 1 aabb22
23 36 1 aabb22
23 37 1 aabb22
23 38 1 aabb22
23 39 1 aabb22
23 40 1 aabb22
23 41 1 aabb22
23 42 1 aabb22
23 43 1 aabb22
23 44 1 aabb22
23 45 1 aabb22
23 46 1 aabb22
16 47 1 00bb2f
17 47 1 00bb2f
18 47 1 00bb2f
19 47 1 00bb2f
20 47 1 00bb2f
21 47 1 00bb2f
22 47 1 00bb2f
23 47 1 00bb2f
24 47 1 00bb2f
25 47 1 00bb2f
26 47 1 00bb2f
27 47 1 00bb2f
28 47 1 00bb2f
29 47 1 00bb2f
30 47 1 00bb2f
31 47 1 00bb2f
23 32 2 aabb22
23 33 2 aabb22
16 34 2 aabb22
17 34 2 aabb22
20 34 2 aabb22
21 34 2 aabb22
22 34 2 aabb22
23 34 2 aabb22
23 35 2 aabb22
23 36 2 aabb22
23 37 2 aabb22
23 38 2 aabb22
23 39 2 aabb22
23 40 2 aabb22
23 41 2 aabb22
23 42 2 aabb22
23 43 2 aabb22
23 44 2 aabb22
23 45 2 aabb22
23 46 2 aabb22
16 47 2 00bb2f
17 47 2 00bb2f
18 47 2 00bb2f
19 47 2 00bb2f
20 47 2 00bb2f
21 47 2 00bb2f
22 47 2 00bb2f
23 47 2 00bb2f
24 47 2 00bb2f
25 47 2 00bb2f
26 47 2 00bb2f
27 47 2 00bb2f
28 47 2 00bb2f
29 47 2 00bb2f
30 47 2 00bb2f
31 47 2 00bb2f
23 32 3 aabb22
23 33 3 aabb22
16 34 3 aabb22
17 34 3 aabb22
20 34 3 aabb22
21 34 3 aabb22
22 34 3 aabb22
23 34 3 aabb22
23 35 3 aabb22
23 36 3 aabb22
23 37 3 aabb22
23 38 3 aabb22
23 39 3 aabb22
23 40 3 aabb22
23 41 3 aabb22
23 42 3 aabb22
23 43 3 aabb22
23 44 3 aabb22
23 45 3 aabb22
23 46 3 aabb22
16 47 3 00bb2f
17 47 3 00bb2f
20 47 3 00bb2f
21 47 3 00bb2f
22 47 3 00bb2f
23 47 3 00bb2f
24 47 3 00bb2f
25 47 3 00bb2f
26 47 3 00bb2f
27 47 3 00bb2f
28 47 3 00bb2f
29 47 3 00bb2f
30 47 3 00bb2f
31 47 3 00bb2f
23 32 4 aabb22
23 33 4 aabb22
16 34 4 aabb22
17 34 4 aabb22
20 34 4 aabb22
21 34 4 aabb22
22 34 4 aabb22
23 34 4 aabb22
23 35 4 aabb22
23 36 4 aabb22
23 37 4 aabb22
23 38 4 aabb22
23 39 4 aabb22
23 40 4 aabb22
23 41 4 aabb22
23 42 4 aabb22
23 43 4 aabb22
23 44 4 aabb22
23 45 4 aabb22
23 46 4 aabb22
16 47 4 00bb2f
17 47 4 00bb2f
20 47 4 00bb2f
21 47 4 00bb2f
22 47 4 00bb2f
23 47 4 00bb2f
24 47 4 00bb2f
25 47 4 00bb2f
26 47 4 00bb2f
27 47 4 00bb2f
28 47 4 00bb2f
29 47 4 00bb2f
30 47 4 00bb2f
31 47 4 00bb2f
23 32 5 aabb22
23 33 5 aabb22
16 34 5 aabb22
17 34 5 aabb22
20 34 5 aabb22
21 34 5 aabb22
22 34 5 aabb22
23 34 5 aabb22
23 35 5 aabb22
23 36 5 aabb22
23 37 5 aabb22
23 38 5 aabb22
23 39 5 aabb22
23 40 5 aabb22
23 41 5 aabb22
23 42 5 aabb22
23 43 5 aabb22
23 44 5 aabb22
23 45 5 aabb22
23 46 5 aabb22
16 47 5 00bb2f
17 47 5 00bb2f
20 47 5 00bb2f
21 47 5 00bb2f
22 47 5 00bb2f
23 47 5 00bb2f
24 47 5 00bb2f
25 47 5 00bb2f
26 47 5 00bb2f
27 47 5 00bb2f
28 47 5 00bb2f
29 47 5 00bb2f
30 47 5 00bb2f
31 47 5 00bb2f
23 32 6 aabb22
23 33 6 aabb22
16 34 6 aabb22
17 34 6 aabb22
20 34 6 aabb22
21 34 6 aabb22
22 34 6 aabb22
23 34 6 aabb22
23 35 6 aabb22
23 36 6 aabb22
23 37 6 aabb22
23 38 6 aabb22
23 39 6 aabb22
23 40 6 aabb22
23 41 6 aabb22
23 42 6 aabb22
23 43 6 aabb22
23 44 6 aabb22
23 45 6 aabb22
23 46 6 aabb22
16 47 6 00bb2f
17 47 6 00bb2f
20 47 6 00bb2f
21 47 6 00bb2f
22 47 6 00bb2f
23 47 6 00bb2f
24 47 6 00bb2f
25 47 6 00bb2f
26 47 6 00bb2f
27 47 6 00bb2f
28 47 6 00bb2f
29 47 6 00bb2f
30 47 6 00bb2f
31 47 6 00bb2f
23 32 7 aabb22
23 33 7 aabb22
16 34 7 aabb22
17 34 7 aabb22
18 34 7 aabb22
19 34 7 aabb22
20 34 7 aabb22
21 34 7 aabb22
22 34 7 aabb22
23 34 7 aabb22
23 35 7 aabb22
23 36 7 aabb22
23 37 7 aabb22
23 38 7 aabb22
23 39 7 aabb22
23 40 7 aabb22
23 41 7 aabb22
23 42 7 aabb22
23 43 7 aabb22
23 44 7 aabb22
23 45 7 aabb22
23 46 7 aabb22
16 47 7 00bb2f
17 47 7 00bb2f
18 47 7 00bb2f
19 47 7 00bb2f
20 47 7 00bb2f
21 47 7 00bb2f
22 47 7 00bb2f
23 47 7 00bb2f
24 47 7 00bb2f
25 47 7 00bb2f
26 47 7 00bb2f
27 47 7 00bb2f
28 47 7 00bb2f
29 47 7 00bb2f
30 47 7 00bb2f
31 47 7 00bb2f
23 32 8 aabb22
23 33 8 aabb22
16 34 8 aabb22
17 34 8 aabb22
18 34 8 aabb22
19 34 8 aabb22
20 34 8 aabb22
21 34 8 aabb22
22 34 8 aabb22
23 34 8 aabb22
23 35 8 aabb22
23 36 8 aabb22
23 37 8 aabb22
23 38 8 aabb22
23 39 8 aabb22
23 40 8 aabb22
23 41 8 aabb22
23 42 8 aabb22
23 43 8 aabb22
23 44 8 aabb22
23 45 8 aabb22
23 46 8 aabb22
16 47 8 00bb2f
17 47 8 00bb2f
18 47 8 00bb2f
19 47 8 00bb2f
20 47 8 00bb2f
21 47 8 00bb2f
22 47 8 00bb2f
23 47 8 00bb2f
24 47 8 00bb2f
25 47 8 00bb2f
26 47 8 00bb2f
27 47 8 00bb2f
28 47 8 00bb2f
29 47 8 00bb2f
30 47 8 00bb2f
31 47 8 00bb2f
23 32 9 aabb22
23 33 9 aabb22
16 34 9 aabb22
17 34 9 aabb22
18 34 9 aabb22
19 34 9 aabb22
20 34 9 aabb22
21 34 9 aabb22
22 34 9 aabb22
23 34 9 aabb22
23 35 9 aabb22
23 36 9 aabb22
23 37 9 aabb22
23 38 9 aabb22
23 39 9 aabb22
23 40 9 aabb22
23 41 9 aabb22
23 42 9 aabb22
23 43 9 aabb22
23 44 9 aabb22
23 45 9 aabb22
23 46 9 aabb22
16 47 9 00bb2f
17 47 9 00bb2f
18 47 9 00bb2f
19 47 9 00bb2f
20 47 9 00bb2f
21 47 9 00bb2f
22 47 9 00bb2f
23 47 9 00bb2f
24 47 9 00bb2f
25 47 9 00bb2f
26 47 9 00bb2f
27 47 9 00bb2f
28 47 9 00bb2f
29 47 9 00bb2f
30 47 9 00bb2f
31 47 9 00bb2f
56 32 0 aabb22
56 33 0 aabb22
56 34 0 aabb22
57 34 0 aabb22
58 34 0 aabb22
59 34 0 aabb22
62 34 0 aabb22
63 34 0 aabb22
56 35 0 aabb22
50 36 0 007700
51 36 0 007700
52 36 0 007700
53 36 0 007700
54 36 0 007700
55 36 0 007700
56 36 0 aabb22
55 37 0 007700
56 37 0 aabb22
55 38 0 007700
56 38 0 aabb22
55 39 0 007700
56 39 0 aabb22
55 40 0 007700
56 40 0 aabb22
55 41 0 007700
56 41 0 aabb22
55 42 0 007700
56 42 0 aabb22
55 43 0 007700
56 43 0 aabb22
55 44 0 007700
56 44 0 aabb22
55 45 0 007700
56 45 0 aabb22
48 46 0 007700
49 46 0 007700
50 46 0 007700
51 46 0 007700
52 46 0 007700
53 46 0 007700
54 46 0 007700
55 46 0 007700
56 46 0 aabb22
48 47 0 00bb2f
49 47 0 00bb2f
50 47 0 00bb2f
51 47 0 00bb2f
52 47 0 00bb2f
53 47 0 00bb2f
54 47 0 00bb2f
55 47 0 00bb2f
56 47 0 00bb2f
57 47 0 00bb2f
58 47 0 00bb2f
59 47 0 00bb2f
60 47 0 00bb2f
61 47 0 00bb2f
62 47 0 00bb2f
63 47 0 00bb2f
56 32 1 aabb22
56 33 1 aabb22
56 34 1 aabb22
57 34 1 aabb22
58 34 1 aabb22
59 34 1 aabb22
62 34 1 aabb22
63 34 1 aabb22
56 35 1 aabb22
50 36 1 007700
51 36 1 007700
52 36 1 007700
53 36 1 007700
54 36 1 007700
55 36 1 007700
56 36 1 aabb22
55 37 1 007700
56 37 1 aabb22
55 38 1 007700
56 38 1 aabb22
55 39 1 007700
56 39 1 aabb22
55 40 1 007700
56 40 1 aabb22
55 41 1 007700
56 41 1 aabb22
55 42 1 007700
56 42 1 aabb22
55 43 1 007700
56 43 1 aabb22
55 44 1 007700
56 44 1 aabb22
55 45 1 007700
56 45 1 aabb22
48 46 1 007700
49 46 1 007700
50 46 1 007700
51 46 1 007700
52 46 1 007700
53 46 1 007700
54 46 1 007700
55 46 1 007700
56 46 1 aabb22
48 47 1 00bb2f
49 47 1 00bb2f
50 47 1 00bb2f
51 47 1 00bb2f
52 47 1 00bb2f
53 47 1 00bb2f
54 47 1 00bb2f
55 47 1 00bb2f
56 47 1 00bb2f
57 47 1 00bb2f
58 47 1 00bb2f
59 47 1 00bb2f
60 47 1 00bb2f
61 47 1 00bb2f
62 47 1 00bb2f
63 47 1 00bb2f
56 32 2 aabb22
56 33 2 aabb22
56 34 2 aabb22
57 34 2 aabb22
58 34 2 aabb22
59 34 2 aabb22
62 34 2 aabb22
63 34 2 aabb22
56 35 2 aabb22
50 36 2 007700
51 36 2 007700
52 36 2 007700
53 36 2 007700
54 36 2 007700
55 36 2 007700
56 36 2 aabb22
55 37 2 007700
56 37 2 aabb22
55 38 2 007700
56 38 2 aabb22
55 39 2 007700
56 39 2 aabb22
55 40 2 007700
56 40 2 aabb22
55 41 2 007700
56 41 2 aabb22
55 42 2 007700
56 42 2 aabb22
55 43 2 007700
56 43 2 aabb22
55 44 2 007700
56 44 2 aabb22
55 45 2 007700
56 45 2 aabb22
48 46 2 007700
49 46 2 007700
50 46 2 007700
51 46 2 007700
52 46 2 007700
53 46 2 007700
54 46 2 007700
55 46 2 007700
56 46 2 aabb22
48 47 2 00bb2f
49 47 2 00bb2f
50 47 2 00bb2f
51 47 2 00bb2f
52 47 2 00bb2f
53 47 2 00bb2f
54 47 2 00bb2f
55 47 2 00bb2f
56 47 2 00bb2f
57 47 2 00bb2f
58 47 2 00bb2f
59 47 2 00bb2f
60 47 2 00bb2f
61 47 2 00bb2f
62 47 2 00bb2f
63 47 2 00bb2f
56 32 3 aabb22
56 33 3 aabb22
56 34 3 aabb22
57 34 3 aabb22
58 34 3 aabb22
59 34 3 aabb22
62 34 3 aabb22
63 34 3 aabb22
56 35 3 aabb22
50 36 3 007700
51 36 3 007700
52 36 3 007700
53 36 3 007700
54 36 3 007700
55 36 3 007700
56 36 3 aabb22
55 37 3 007700
56 37 3 aabb22
55 38 3 007700
56 38 3 aabb22
55 39 3 007700
56 39 3 aabb22
55 40 3 007700
56 40 3 aabb22
55 41 3 007700
56 41 3 aabb22
55 42 3 007700
56 42 3 aabb22
55 43 3 007700
56 43 3 aabb22
55 44 3 007700
56 44 3 aabb22
55 45 3 007700
56 45 3 aabb22
48 46 3 007700
49 46 3 007700
50 46 3 007700
51 46 3 007700
52 46 3 007700
53 46 3 007700
54 46 3 007700
55 46 3 007700
56 46 3 aabb22
48 47 3 00bb2f
49 47 3 00bb2f
50 47 3 00bb2f
51 47 3 00bb2f
52 47 3 00bb2f
53 47 3 00bb2f
54 47 3 00bb2f
55 47 3 00bb2f
56 47 3 00bb2f
57 47 3 00bb2f
58 47 3 00bb2f
59 47 3 00bb2f
62 47 3 00bb2f
63 47 3 00bb2f
56 32 4 aabb22
56 33 4 aabb22
56 34 4 aabb22
57 34 4 aabb22
58 34 4 aabb22
59 34 4 aabb22
62 34 4 aabb22
63 34 4 aabb22
56 35 4 aabb22
50 36 4 007700
51 36 4 007700
52 36 4 007700
53 36 4 007700
54 36 4 007700
55 36 4 007700
56 36 4 aabb22
55 37 4 007700
56 37 4 aabb22
55 38 4 007700
56 38 4 aabb22
55 39 4 007700
56 39 4 aabb22
55 40 4 007700
56 40 4 aabb22
55 41 4 007700
56 41 4 aabb22
55 42 4 007700
56 42 4 aabb22
55 43 4 007700
56 43 4 aabb22
55 44 4 007700
56 44 4 aabb22
55 45 4 007700
56 45 4 aabb22
48 46 4 007700
49 46 4 007700
50 46 4 007700
51 46 4 007700
52 46 4 007700
53 46 4 007700
54 46 4 007700
55 46 4 007700
56 46 4 aabb22
48 47 4 00bb2f
49 47 4 00bb2f
50 47 4 00bb2f
51 47 4 00bb2f
52 47 4 00bb2f
53 47 4 00bb2f
54 47 4 00bb2f
55 47 4 00bb2f
56 47 4 00bb2f
57 47 4 00bb2f
58 47 4 00bb2f
59 47 4 00bb2f
62 47 4 00bb2f
63 47 4 00bb2f
56 32 5 aabb22
56 33 5 aabb22
56 34 5 aabb22
57 34 5 aabb22
58 34 5 aabb22
59 34 5 aabb22
62 34 5 aabb22
63 34 5 aabb22
56 35 5 aabb22
50 36 5 007700
51 36 5 007700
52 36 5 007700
53 36 5 007700
54 36 5 007700
55 36 5 007700
56 36 5 aabb22
55 37 5 007700
56 37 5 aabb22
55 38 5 007700
56 38 5 aabb22
55 39 5 007700
56 39 5 aabb22
55 40 5 007700
56 40 5 aabb22
55 41 5 007700
56 41 5 aabb22
55 42 5 007700
56 42 5 aabb22
55 43 5 007700
56 43 5 aabb22
55 44 5 007700
56 44 5 aabb22
55 45 5 007700
56 45 5 aabb22
48 46 5 007700
49 46 5 007700
50 46 5 007700
51 46 5 007700
52 46 5 007700
53 46 5 007700
54 46 5 007700
55 46 5 007700
56 46 5 aabb22
48 47 5 00bb2f
49 47 5 00bb2f
50 47 5 00bb2f
51 47 5 00bb2f
52 47 5 00bb2f
53 47 5 00bb2f
54 47 5 00bb2f
55 47 5 00bb2f
56 47 5 00bb2f
57 47 5 00bb2f
58 47 5 00bb2f
59 47 5 00bb2f
62 47 5 00bb2f
63 47 5 00bb2f
56 32 6 aabb22
56 33 6 aabb22
56 34 6 aabb22
57 34 6 aabb22
58 34 6 aabb22
59 34 6 aabb22
62 34 6 aabb22
63 34 6 aabb22
56 35 6 aabb22
50 36 6 007700
51 36 6 007700
52 36 6 007700
53 36 6 007700
54 36 6 007700
55 36 6 007700
56 36 6 aabb22
55 37 6 007700
56 37 6 aabb22
55 38 6 007700
56 38 6 aabb22
55 39 6 007700
56 39 6 aabb22
55 40 6 007700
56 40 6 aabb22
55 41 6 007700
56 41 6 aabb22
55 42 6 007700
56 42 6 aabb22
55 43 6 007700
56 43 6 aabb22
55 44 6 007700
56 44 6 aabb22
55 45 6 007700
56 45 6 aabb22
48 46 6 007700
49 46 6 007700
50 46 6 007700
51 46 6 007700
52 46 6 007700
53 46 6 007700
54 46 6 007700
55 46 6 007700
56 46 6 aabb22
48 47 6 00bb2f
49 47 6 00bb2f
50 47 6 00bb2f
51 47 6 00bb2f
52 47 6 00bb2f
53 47 6 00bb2f
54 47 6 00bb2f
55 47 6 00bb2f
56 47 6 00bb2f
57 47 6 00bb2f
58 47 6 00bb2f
59 47 6 00bb2f
62 47 6 00bb2f
63 47 6 00bb2f
56 32 7 aabb22
56 33 7 aabb22
56 34 7 aabb22
57 34 7 aabb22
58 34 7 aabb22
59 34 7 aabb22
60 34 7 aabb22
61 34 7 aabb22
62 34 7 aabb22
63 34 7 aabb22
56 35 7 aabb22
48 36 7 007700
49 36 7 007700
50 36 7 007700
51 36 7 007700
52 36 7 007700
53 36 7 007700
54 36 7 007700
55 36 7 007700
56 36 7 aabb22
55 37 7 007700
56 37 7 aabb22
55 38 7 007700
56 38 7 aabb22
55 39 7 007700
56 39 7 aabb22
55 40 7 007700
56 40 7 aabb22
55 41 7 007700
56 41 7 aabb22
55 42 7 007700
56 42 7 aabb22
55 43 7 007700
56 43 7 aabb22
55 44 7 007700
56 44 7 aabb22
55 45 7 007700
56 45 7 aabb22
48 46 7 007700
49 46 7 007700
50 46 7 007700
51 46 7 007700
52 46 7 007700
53 46 7 007700
54 46 7 007700
55 46 7 007700
56 46 7 aabb22
48 47 7 00bb2f
49 47 7 00bb2f
50 47 7 00bb2f
51 47 7 00bb2f
52 47 7 00bb2f
53 47 7 00bb2f
54 47 7 00bb2f
55 47 7 00bb2f
56 47 7 00bb2f
57 47 7 00bb2f
58 47 7 00bb2f
59 47 7 00bb2f
60 47 7 00bb2f
61 47 7 00bb2f
62 47 7 00bb2f
63 47 7 00bb2f
56 32 8 aabb22
56 33 8 aabb22
56 34 8 aabb22
57 34 8 aabb22
58 34 8 aabb22
59 34 8 aabb22
60 34 8 aabb22
61 34 8 aabb22
62 34 8 aabb22
63 34 8 aabb22
56 35 8 aabb22
48 36 8 007700
49 36 8 007700
50 36 8 007700
51 36 8 007700
52 36 8 007700
53 36 8 007700
54 36 8 007700
55 36 8 007700
56 36 8 aabb22
55 37 8 007700
56 37 8 aabb22
55 38 8 007700
56 38 8 aabb22
55 39 8 007700
56 39 8 aabb22
55 40 8 007700
56 40 8 aabb22
55 41 8 007700
56 41 8 aabb22
55 42 8 007700
56 42 8 aabb22
55 43 8 007700
56 43 8 aabb22
55 44 8 007700
56 44 8 aabb22
55 45 8 007700
56 45 8 aabb22
48 46 8 007700
49 46 8 007700
50 46 8 007700
51 46 8 007700
52 46 8 007700
53 46 8 007700
54 46 8 007700
55 46 8 007700
56 46 8 aabb22
48 47 8 00bb2f
49 47 8 00bb2f
50 47 8 00bb2f
51 47 8 00bb2f
52 47 8 00bb2f
53 47 8 00bb2f
54 47 8 00bb2f
55 47 8 00bb2f
56 47 8 00bb2f
57 47 8 00bb2f
58 47 8 00bb2f
59 47 8 00bb2f
60 47 8 00bb2f
61 47 8 00bb2f
62 47 8 00bb2f
63 47 8 00bb2f
56 32 9 aabb22
56 33 9 aabb22
56 34 9 aabb22
57 34 9 aabb22
58 34 9 aabb22
59 34 9 aabb22
60 34 9 aabb22
61 34 9 aabb22
62 34 9 aabb22
63 34 9 aabb22
56 35 9 aabb22
48 36 9 007700
49 36 9 007700
50 36 9 007700
51 36 9 007700
52 36 9 007700
53 36 9 007700
54 36 9 007700
55 36 9 007700
56 36 9 aabb22
55 37 9 007700
56 37 9 aabb22
55 38 9 007700
56 38 9 aabb22
55 39 9 007700
56 39 9 aabb22
55 40 9 007700
56 40 9 aabb22
55 41 9 007700
56 41 9 aabb22
55 42 9 007700
56 42 9 aabb22
55 43 9 007700
56 43 9 aabb22
55 44 9 007700
56 44 9 aabb22
55 45 9 007700
56 45 9 aabb22
48 46 9 007700
49 46 9 007700
50 46 9 007700
51 46 9 007700
52 46 9 007700
53 46 9 007700
54 46 9 007700
55 46 9 007700
56 46 9 aabb22
48 47 9 00bb2f
49 47 9 00bb2f
50 47 9 00bb2f
51 47 9 00bb2f
52 47 9 00bb2f
53 47 9 00bb2f
54 47 9 00bb2f
55 47 9 00bb2f
56 47 9 00bb2f
57 47 9 00bb2f
58 47 9 00bb2f
59 47 9 00bb2f
60 47 9 00bb2f
61 47 9 00bb2f
62 47 9 00bb2f
63 47 9 00bb2f
46 36 0 007700
47 36 0 007700
39 37 0 0077aa
40 37 0 0077aa
46 37 0 aa77aa
47 37 0 007700
39 38 0 0077aa
40 38 0 0077aa
46 38 0 aa77aa
47 38 0 007700
39 39 0 0077aa
40 39 0 0077aa
46 39 0 aa77aa
47 39 0 007700
39 40 0 0077aa
40 40 0 0077aa
46 40 0 aa77aa
47 40 0 007700
39 41 0 0077aa
40 41 0 0077aa
46 41 0 aa77aa
47 41 0 007700
39 42 0 0077aa
40 42 0 0077aa
46 42 0 aa77aa
47 42 0 007700
39 43 0 0077aa
40 43 0 0077aa
46 43 0 aa77aa
47 43 0 007700
46 44 0 aa77aa
47 44 0 007700
46 45 0 aa77aa
47 45 0 007700
46 46 0 aa77aa
47 46 0 007700
32 47 0 00bb2f
33 47 0 00bb2f
34 47 0 00bb2f
35 47 0 00bb2f
36 47 0 00bb2f
37 47 0 00bb2f
38 47 0 00bb2f
39 47 0 00bb2f
40 47 0 00bb2f
41 47 0 00bb2f
42 47 0 00bb2f
43 47 0 00bb2f
44 47 0 00bb2f
45 47 0 00bb2f
46 47 0 00bb2f
47 47 0 00bb2f
46 36 1 007700
47 36 1 007700
39 37 1 0077aa
40 37 1 0077aa
46 37 1 aa77aa
47 37 1 007700
39 38 1 0077aa
40 38 1 0077aa
46 38 1 aa77aa
47 38 1 007700
39 39 1 0077aa
40 39 1 0077aa
46 39 1 aa77aa
47 39 1 007700
39 40 1 0077aa
40 40 1 0077aa
46 40 1 aa77aa
47 40 1 007700
39 41 1 0077aa
40 41 1 0077aa
46 41 1 aa77aa
47 41 1 007700
39 42 1 0077aa
40 42 1 0077aa
46 42 1 aa77aa
47 42 1 007700
39 43 1 0077aa
40 43 1 0077aa
46 43 1 aa77aa
47 43 1 007700
46 44 1 aa77aa
47 44 1 007700
46 45 1 aa77aa
47 45 1 007700
46 46 1 aa77aa
47 46 1 007700
32 47 1 00bb2f
33 47 1 00bb2f
34 47 1 00bb2f
35 47 1 00bb2f
36 47 1 00bb2f
37 47 1 00bb2f
38 47 1 00bb2f
39 47 1 00bb2f
40 47 1 00bb2f
41 47 1 00bb2f
42 47 1 00bb2f
43 47 1 00bb2f
44 47 1 00bb2f
45 47 1 00bb2f
46 47 1 00bb2f
47 47 1 00bb2f
46 36 2 007700
47 36 2 007700
39 37 2 0077aa
40 37 2 0077aa
46 37 2 aa77aa
47 37 2 007700
39 38 2 0077aa
40 38 2 0077aa
46 38 2 aa77aa
47 38 2 007700
39 39 2 0077aa
40 39 2 0077aa
46 39 2 aa77aa
47 39 2 007700
39 40 2 0077aa
40 40 2 0077aa
46 40 2 aa77aa
47 40 2 007700
39 41 2 0077aa
40 41 2 0077aa
46 41 2 aa77aa
47 41 2 007700
39 42 2 0077aa
40 42 2 0077aa
46 42 2 aa77aa
47 42 2 007700
39 43 2 0077aa
40 43 2 0077aa
46 43 2 aa77aa
47 43 2 007700
46 44 2 aa77aa
47 44 2 007700
46 45 2 aa77aa
47 45 2 007700
46 46 2 aa77aa
47 46 2 007700
32 47 2 00bb2f
33 47 2 00bb2f
34 47 2 00bb2f
35 47 2 00bb2f
36 47 2 00bb2f
37 47 2 00bb2f
38 47 2 00bb2f
39 47 2 00bb2f
40 47 2 00bb2f
41 47 2 00bb2f
42 47 2 00bb2f
43 47 2 00bb2f
44 47 2 00bb2f
45 47 2 00bb2f
46 47 2 00bb2f
47 47 2 00bb2f
46 36 3 007700
47 36 3 007700
39 37 3 0077aa
40 37 3 0077aa
46 37 3 aa77aa
47 37 3 007700
39 38 3 0077aa
40 38 3 0077aa
46 38 3 aa77aa
47 38 3 007700
39 39 3 0077aa
40 39 3 0077aa
46 39 3 aa77aa
47 39 3 007700
39 40 3 0077aa
40 40 3 0077aa
46 40 3 aa77aa
47 40 3 007700
39 41 3 0077aa
40 41 3 0077aa
46 41 3 aa77aa
47 41 3 007700
39 42 3 0077aa
40 42 3 0077aa
46 42 3 aa77aa
47 42 3 007700
39 43 3 0077aa
40 43 3 0077aa
46 43 3 aa77aa
47 43 3 007700
46 44 3 aa77aa
47 44 3 007700
46 45 3 aa77aa
47 45 3 007700
46 46 3 aa77aa
47 46 3 007700
32 47 3 00bb2f
33 47 3 00bb2f
34 47 3 00bb2f
35 47 3 00bb2f
36 47 3 00bb2f
37 47 3 00bb2f
38 47 3 00bb2f
39 47 3 00bb2f
40 47 3 00bb2f
41 47 3 00bb2f
42 47 3 00bb2f
43 47 3 00bb2f
44 47 3 00bb2f
45 47 3 00bb2f
46 47 3 00bb2f
47 47 3 00bb2f
46 36 4 007700
47 36 4 007700
39 37 4 0077aa
40 37 4 0077aa
46 37 4 aa77aa
47 37 4 007700
39 38 4 0077aa
40 38 4 0077aa
46 38 4 aa77aa
47 38 4 007700
39 39 4 0077aa
40 39 4 0077aa
46 39 4 aa77aa
47 39 4 007700
39 40 4 0077aa
40 40 4 0077aa
46 40 4 aa77aa
47 40 4 007700
39 41 4 0077aa
40 41 4 0077aa
46 41 4 aa77aa
47 41 4 007700
39 42 4 0077aa
40 42 4 0077aa
46 42 4 aa77aa
47 42 4 007700
39 43 4 0077aa
40 43 4 0077aa
46 43 4 aa77aa
47 43 4 007700
46 44 4 aa77aa
47 44 4 007700
46 45 4 aa77aa
47 45 4 007700
46 46 4 aa77aa
47 46 4 007700
32 47 4 00bb2f
33 47 4 00bb2f
34 47 4 00bb2f
35 47 4 00bb2f
36 47 4 00bb2f
37 47 4 00bb2f
38 47 4 00bb2f
39 47 4 00bb2f
40 47 4 00bb2f
41 47 4 00bb2f
42 47 4 00bb2f
43 47 4 00bb2f
44 47 4 00bb2f
45 47 4 00bb2f
46 47 4 00bb2f
47 47 4 00bb2f
46 36 5 007700
47 36 5 007700
39 37 5 0077aa
40 37 5 0077aa
46 37 5 aa77aa
47 37 5 007700
39 38 5 0077aa
40 38 5 0077aa
46 38 5 aa77aa
47 38 5 007700
39 39 5 0077aa
40 39 5 0077aa
46 39 5 aa77aa
47 39 5 007700
39 40 5 0077aa
40 40 5 0077aa
46 40 5 aa77aa
47 40 5 007700
39 41 5 0077aa
40 41 5 0077aa
46 41 5 aa77aa
47 41 5 007700
39 42 5 0077aa
40 42 5 0077aa
46 42 5 aa77aa
47 42 5 007700
39 43 5 0077aa
40 43 5 0077aa
46 43 5 aa77aa
47 43 5 007700
46 44 5 aa77aa
47 44 5 007700
46 45 5 aa77aa
47 45 5 007700
46 46 5 aa77aa
47 46 5 007700
32 47 5 00bb2f
33 47 5 00bb2f
34 47 5 00bb2f
35 47 5 00bb2f
36 47 5 00bb2f
37 47 5 00bb2f
38 47 5 00bb2f
39 47 5 00bb2f
40 47 5 00bb2f
41 47 5 00bb2f
42 47 5 00bb2f
43 47 5 00bb2f
44 47 5 00bb2f
45 47 5 00bb2f
46 47 5 00bb2f
47 47 5 00bb2f
46 36 6 007700
47 36 6 007700
39 37 6 0077aa
40 37 6 0077aa
46 37 6 aa77aa
47 37 6 007700
39 38 6 0077aa
40 38 6 0077aa
46 38 6 aa77aa
47 38 6 007700
39 39 6 0077aa
40 39 6 0077aa
46 39 6 aa77aa
47 39 6 007700
39 40 6 0077aa
40 40 6 0077aa
46 40 6 aa77aa
47 40 6 007700
39 41 6 0077aa
40 41 6 0077aa
46 41 6 aa77aa
47 41 6 007700
39 42 6 0077aa
40 42 6 0077aa
46 42 6 aa77aa
47 42 6 007700
39 43 6 0077aa
40 43 6 0077aa
46 43 6 aa77aa
47 43 6 007700
46 44 6 aa77aa
47 44 6 007700
46 45 6 aa77aa
47 45 6 007700
46 46 6 aa77aa
47 46 6 007700
32 47 6 00bb2f
33 47 6 00bb2f
34 47 6 00bb2f
35 47 6 00bb2f
36 47 6 00bb2f
37 47 6 00bb2f
38 47 6 00bb2f
39 47 6 00bb2f
40 47 6 00bb2f
41 47 6 00bb2f
42 47 6 00bb2f
43 47 6 00bb2f
44 47 6 00bb2f
45 47 6 00bb2f
46 47 6 00bb2f
47 47 6 00bb2f
46 36 7 007700
47 36 7 007700
39 37 7 0077aa
40 37 7 0077aa
46 37 7 aa77aa
47 37 7 007700
39 38 7 0077aa
40 38 7 0077aa
46 38 7 aa77aa
47 38 7 007700
39 39 7 0077aa
40 39 7 0077aa
46 39 7 aa77aa
47 39 7 007700
39 40 7 0077aa
40 40 7 0077aa
46 40 7 aa77aa
47 40 7 007700
39 41 7 0077aa
40 41 7 0077aa
46 41 7 aa77aa
47 41 7 007700
39 42 7 0077aa
40 42 7 0077aa
46 42 7 aa77aa
47 42 7 007700
39 43 7 0077aa
40 43 7 0077aa
46 43 7 aa77aa
47 43 7 007700
46 44 7 aa77aa
47 44 7 007700
46 45 7 aa77aa
47 45 7 007700
46 46 7 aa77aa
47 46 7 007700
32 47 7 00bb2f
33 47 7 00bb2f
34 47 7 00bb2f
35 47 7 00bb2f
36 47 7 00bb2f
37 47 7 00bb2f
38 47 7 00bb2f
39 47 7 00bb2f
40 47 7 00bb2f
41 47 7 00bb2f
42 47 7 00bb2f
43 47 7 00bb2f
44 47 7 00bb2f
45 47 7 00bb2f
46 47 7 00bb2f
47 47 7 00bb2f
46 36 8 007700
47 36 8 007700
39 37 8 0077aa
40 37 8 0077aa
46 37 8 aa77aa
47 37 8 007700
39 38 8 0077aa
40 38 8 0077aa
46 38 8 aa77aa
47 38 8 007700
39 39 8 0077aa
40 39 8 0077aa
46 39 8 aa77aa
47 39 8 007700
39 40 8 0077aa
40 40 8 0077aa
46 40 8 aa77aa
47 40 8 007700
39 41 8 0077aa
40 41 8 0077aa
46 41 8 aa77aa
47 41 8 007700
39 42 8 0077aa
40 42 8 0077aa
46 42 8 aa77aa
47 42 8 007700
39 43 8 0077aa
40 43 8 0077aa
46 43 8 aa77aa
47 43 8 007700
46 44 8 aa77aa
47 44 8 007700
46 45 8 aa77aa
47 45 8 007700
46 46 8 aa77aa
47 46 8 007700
32 47 8 00bb2f
33 47 8 00bb2f
34 47 8 00bb2f
35 47 8 00bb2f
36 47 8 00bb2f
37 47 8 00bb2f
38 47 8 00bb2f
39 47 8 00bb2f
40 47 8 00bb2f
41 47 8 00bb2f
42 47 8 00bb2f
43 47 8 00bb2f
44 47 8 00bb2f
45 47 8 00bb2f
46 47 8 00bb2f
47 47 8 00bb2f
46 36 9 007700
47 36 9 007700
39 37 9 0077aa
40 37 9 0077aa
46 37 9 aa77aa
47 37 9 007700
39 38 9 0077aa
40 38 9 0077aa
46 38 9 aa77aa
47 38 9 007700
39 39 9 0077aa
40 39 9 0077aa
46 39 9 aa77aa
47 39 9 007700
39 40 9 0077aa
40 40 9 0077aa
46 40 9 aa77aa
47 40 9 007700
39 41 9 0077aa
40 41 9 0077aa
46 41 9 aa77aa
47 41 9 007700
39 42 9 0077aa
40 42 9 0077aa
46 42 9 aa77aa
47 42 9 007700
39 43 9 0077aa
40 43 9 0077aa
46 43 9 aa77aa
47 43 9 007700
46 44 9 aa77aa
47 44 9 007700
46 45 9 aa77aa
47 45 9 007700
46 46 9 aa77aa
47 46 9 007700
32 47 9 00bb2f
33 47 9 00bb2f
34 47 9 00bb2f
35 47 9 00bb2f
36 47 9 00bb2f
37 47 9 00bb2f
38 47 9 00bb2f
39 47 9 00bb2f
40 47 9 00bb2f
41 47 9 00bb2f
42 47 9 00bb2f
43 47 9 00bb2f
44 47 9 00bb2f
45 47 9 00bb2f
46 47 9 00bb2f
47 47 9 00bb2f
